[META]
version=2.0
spawnOnBlockType=1,2,3
spawnSunlight=True
spawnDarkness=True
spawnWater=False
spawnLava=False
underFill=True
randomRotation=True
dig=True
tree=False
branch=False
needsFoundation=True
rarity=999
collisionPercentage=0
spawnElevationMin=14
spawnElevationMax=60
spawnInBiome=Caverns
spawnAboveGround=False
spawnUnderGround=True
collisionBlockType=All
groupId=
diggingBranch=false
branchLimit=6
groupFrequencyMin=1
groupFrequencyMax=5
groupSeperationMin=0
groupSeperationMax=5
[DATA]
0,0,0:121
-1,0,0:121
-1,-1,0:121
0,-1,0:121
1,-1,0:121
1,0,0:121
1,1,0:121
0,1,0:121
-1,1,0:121
0,2,0:121
-2,0,0:121
0,-2,0:121
2,0,0:121
-1,-1,1:121
0,-1,1:121
1,-1,1:121
1,0,1:121
1,1,1:121
0,1,1:121
-1,1,1:121
-1,0,1:121
0,0,1:121
0,0,2:121
-1,0,2:121
1,0,2:121
0,-1,2:121
0,1,2:121
0,0,3:121
0,0,4:121
0,0,5:121
0,0,6:121
0,0,7:121
0,0,8:20
0,0,9:20
0,0,10:20
0,0,11:20
0,0,12:20
0,0,13:20
0,0,14:121
0,0,15:121
0,0,16:121
0,0,17:121
0,-1,17:121
-1,0,17:121
1,0,17:121
0,1,17:121
0,0,18:121
0,-1,18:121
-1,0,18:121
0,1,18:121
1,0,18:121
0,0,19:121
0,-1,19:121
0,1,19:121
-1,0,19:121
1,0,19:121
0,0,20:121
0,-1,20:121
-1,0,20:121
0,1,20:121
1,0,20:121
1,-1,20:121
-1,-1,20:121
-1,1,20:121
1,1,20:121
0,0,21:121
-1,0,21:121
0,-1,21:121
0,1,21:121
1,0,21:121
-1,-1,21:121
1,-1,21:121
1,1,21:121
-1,1,21:121
0,-2,21:121
0,2,21:121
-2,0,21:121
2,0,21:121
-1,0,22:121
-1,-1,22:121
0,-1,22:121
1,-1,22:121
1,0,22:121
1,1,22:121
0,1,22:121
0,0,22:121
-1,1,22:121
0,-2,22:121
-2,0,22:121
0,2,22:121
2,0,22:121
-1,0,23:121
-1,-1,23:121
0,-1,23:121
1,-1,23:121
1,0,23:121
1,1,23:121
0,1,23:121
-1,1,23:121
-2,0,23:121
0,-2,23:121
2,0,23:121
0,2,23:121
0,0,23:121
-1,0,24:121
-1,-1,24:121
0,-1,24:121
1,-1,24:121
1,0,24:121
2,0,24:121
1,1,24:121
0,1,24:121
0,2,24:121
-1,1,24:121
-2,0,24:121
0,0,24:121
0,-2,24:121
0,-2,25:121
0,-1,25:121
0,0,25:121
0,1,25:121
0,2,25:121
-1,1,25:121
1,1,25:121
1,0,25:121
2,0,25:121
1,-1,25:121
-1,0,25:121
-2,0,25:121
-1,-1,25:121
0,-2,26:1
0,-3,26:1
-1,-2,26:1
-1,-1,26:1
-2,-1,26:1
-1,0,26:1
-2,0,26:1
-3,0,26:1
-2,1,26:1
-1,1,26:1
-1,2,26:1
0,2,26:1
0,3,26:1
1,2,26:1
1,1,26:1
2,1,26:1
2,0,26:1
3,0,26:1
2,-1,26:1
1,-1,26:1
1,-2,26:1
0,-1,26:1
0,0,26:1
0,1,26:1
1,0,26:1
0,-3,27:1
0,-2,27:1
0,-1,27:1
0,0,27:1
0,1,27:1
0,2,27:1
0,3,27:1
-1,2,27:1
1,2,27:1
-2,1,27:1
-1,1,27:1
1,1,27:1
2,1,27:1
-3,0,27:1
-2,0,27:1
-1,0,27:1
1,0,27:1
2,0,27:1
3,0,27:1
-2,-1,27:1
-1,-1,27:1
1,-1,27:1
2,-1,27:1
-1,-2,27:1
1,-2,27:1
0,-4,28:1
0,-3,28:1
0,-2,28:1
0,-1,28:1
0,0,28:1
0,1,28:1
0,2,28:1
0,3,28:1
0,4,28:1
-1,3,28:1
1,3,28:1
-2,2,28:1
-1,2,28:1
1,2,28:1
2,2,28:1
-3,1,28:1
-2,1,28:1
-1,1,28:1
1,1,28:1
2,1,28:1
3,1,28:1
-4,0,28:1
-3,0,28:1
-2,0,28:1
-1,0,28:1
1,0,28:1
2,0,28:1
3,0,28:1
4,0,28:1
-1,-3,28:1
-1,-2,28:1
-2,-2,28:1
-3,-1,28:1
-2,-1,28:1
-1,-1,28:1
1,-1,28:1
2,-1,28:1
3,-1,28:1
2,-2,28:1
1,-2,28:1
1,-3,28:1
