[META]
version=2.0
spawnOnBlockType=13
spawnSunlight=True
spawnDarkness=False
spawnWater=False
spawnLava=False
underFill=True
randomRotation=True
dig=True
tree=False
branch=False
needsFoundation=True
rarity=1
collisionPercentage=2
spawnElevationMin=0
spawnElevationMax=128
spawnInBiome=Flat
[DATA]
-3,-6,0:98.0
9,-6,0:98.3
-3,-2,0:98.1
9,-2,0:98.2
-3,-6,1:98.3
-2,-6,1:98.3
8,-6,1:98.1
9,-6,1:98.1
-3,-2,1:98.2
-2,-2,1:98.1
8,-2,1:98.1
9,-2,1:98.0
-3,-6,2:98.3
-2,-6,2:98.0
-1,-6,2:98.2
7,-6,2:98.1
8,-6,2:98.0
9,-6,2:98.2
-3,-2,2:98.0
-2,-2,2:98.3
-1,-2,2:98.0
7,-2,2:98.2
8,-2,2:98.0
9,-2,2:98.1
-3,-6,3:98.3
-2,-6,3:98.0
-1,-6,3:98.3
0,-6,3:98.1
6,-6,3:98.2
7,-6,3:98.1
8,-6,3:98.3
9,-6,3:98.3
-3,-2,3:98.3
-2,-2,3:98.0
-1,-2,3:98.3
0,-2,3:98.0
6,-2,3:98.0
7,-2,3:98.2
8,-2,3:98.3
9,-2,3:98.2
-3,-6,4:98.2
-2,-6,4:98.1
-1,-6,4:98.1
0,-6,4:98.2
1,-6,4:98.0
2,-6,4:98.1
3,-6,4:98.3
4,-6,4:98.3
5,-6,4:98.1
6,-6,4:98.2
7,-6,4:98.3
8,-6,4:98.0
9,-6,4:98.3
-3,-5,4:98.0
-2,-5,4:98.3
-1,-5,4:98.3
0,-5,4:98.3
1,-5,4:98.0
2,-5,4:98.0
3,-5,4:98.1
4,-5,4:98.2
5,-5,4:98.3
6,-5,4:98.0
7,-5,4:98.2
8,-5,4:98.1
9,-5,4:98.3
-3,-4,4:98.0
-2,-4,4:98.0
-1,-4,4:98.2
0,-4,4:98.3
1,-4,4:98.1
2,-4,4:98.1
3,-4,4:98.0
4,-4,4:98.0
5,-4,4:98.1
6,-4,4:98.1
7,-4,4:98.1
8,-4,4:98.0
9,-4,4:98.0
-3,-3,4:98.2
-2,-3,4:98.1
-1,-3,4:98.1
0,-3,4:98.0
1,-3,4:98.1
2,-3,4:98.1
3,-3,4:98.3
4,-3,4:98.3
5,-3,4:98.2
6,-3,4:98.2
7,-3,4:98.1
8,-3,4:98.0
9,-3,4:98.2
-3,-2,4:98.2
-2,-2,4:98.0
-1,-2,4:98.3
0,-2,4:98.0
1,-2,4:98.2
2,-2,4:98.1
3,-2,4:98.0
4,-2,4:98.1
5,-2,4:98.2
6,-2,4:98.1
7,-2,4:98.3
8,-2,4:98.3
9,-2,4:98.3
3,-2,5:54.2
-3,-1,5:48
-2,-1,5:4
-1,-1,5:4
0,-1,5:4
1,-1,5:48
2,-1,5:48
3,-1,5:4
4,-1,5:4
5,-1,5:4
6,-1,5:1
7,-1,5:48
8,-1,5:1
9,-1,5:48
