[META]
version=2.0
spawnOnBlockType=9
spawnSunlight=True
spawnDarkness=True
spawnWater=True
spawnLava=False
underFill=True
randomRotation=True
dig=True
tree=False
branch=False
needsFoundation=True
rarity=999
collisionPercentage=15
spawnElevationMin=55
spawnElevationMax=68
spawnInBiome=TropicalOcean
spawnAboveGround=False
spawnUnderGround=False
collisionBlockType=All
groupId=
diggingBranch=false
branchLimit=6
groupFrequencyMin=1
groupFrequencyMax=5
groupSeperationMin=0
groupSeperationMax=5
[DATA]
-3,-1,-28:35.4
-1,-1,-28:35.2
-2,0,-28:35.4
0,0,-28:35.5
1,0,-28:35.5
0,-1,-28:35.3
-3,-1,-29:24.0
-1,-1,-29:24.0
-2,0,-29:24.0
0,0,-29:24.0
1,0,-29:24.0
0,-2,-29:24.0
0,-1,-29:35.1
-3,0,-29:35.1
0,-3,-29:35.3
1,-2,-29:35.5
-4,-1,-29:35.5
2,0,-29:35.13
-3,-2,-29:35.14
-1,0,-29:35.14
-2,-1,-29:35.4
-1,-2,-29:35.4
0,1,-29:35.4
-3,-1,-30:12
-2,-1,-30:12
-1,-1,-30:12
0,-1,-30:12
-2,0,-30:12
-1,0,-30:12
0,0,-30:12
1,0,-30:12
0,-2,-30:12
-1,1,-30:12
0,1,-30:12
-1,-2,-30:12
1,-1,-30:12
-2,-2,-30:12
0,-3,-30:12
1,-2,-30:12
2,-1,-30:12
-3,-1,-27:35.8
-2,0,-27:35.4
-1,-1,-27:35.1
0,0,-27:35.1
1,0,-27:35.8
