[META]
version=2.0
spawnOnBlockType=3,12
spawnSunlight=True
spawnDarkness=True
spawnWater=False
spawnLava=False
underFill=True
randomRotation=True
dig=True
tree=False
branch=False
needsFoundation=True
rarity=40
collisionPercentage=5
spawnElevationMin=0
spawnElevationMax=150
spawnInBiome=DesertPlain
[DATA]
0,1,0:17.0
0,4,0:31.0
3,3,0:31.0
0,2,0:31.0
1,1,0:31.0
2,-1,0:31.0
-2,-1,0:31.0
-2,2,0:31.0
-2,2,-1:3
1,1,-1:3
-2,-1,-1:3
3,3,-1:3
0,4,-1:3
2,-1,-1:3
0,2,-1:3
0,1,-1:3
0,1,1:17.0
0,1,2:17.0
-1,1,2:17.0
-1,1,3:17.0
-1,1,4:17.0
-1,1,5:17.0
-1,0,5:17.0
0,0,5:17.0
0,-1,5:17.0
-1,0,6:17.0
-2,0,6:17.0
0,-1,6:17.0
1,-1,6:17.0
-1,2,6:17.0
-1,3,6:17.0
-2,0,7:17.0
-2,-1,7:17.0
-1,1,7:17.0
-1,2,7:17.0
0,2,7:17.0
1,-1,7:17.0
1,-2,7:17.0
-2,3,7:17.0
-2,4,7:17.0
-2,-2,8:17.0
0,2,8:17.0
1,-2,8:17.0
2,-2,8:17.0
-2,4,8:17.0
-2,-3,9:17.0
1,2,9:17.0
1,3,9:17.0
2,-2,9:17.0
3,-2,9:17.0
-2,4,9:17.0
-3,4,9:17.0
3,-2,10:17.0
1,3,10:17.0
-2,-4,10:17.0
-3,-4,10:17.0
-3,4,10:17.0
-3,5,10:17.0
-3,-4,11:17.0
4,-2,11:17.0
2,3,11:17.0
-3,5,11:17.0
