[META]
version=2.0
spawnOnBlockType=2,3
spawnSunlight=True
spawnDarkness=True
spawnWater=False
spawnLava=False
underFill=False
randomRotation=True
dig=True
tree=True
branch=False
needsFoundation=True
rarity=30
collisionPercentage=2
spawnElevationMin=0
spawnElevationMax=220
spawnInBiome=WoWForest
[DATA]
-2,-3,-2:17
-2,-2,-2:17.0
2,-2,-2:17.0
-4,-1,-2:17
-5,0,-2:17
-4,0,-2:17.0
-2,0,-2:17.0
0,0,-2:17.0
2,1,-2:17.0
-2,2,-2:17.0
0,2,-2:17.0
0,4,-2:17.0
-2,-2,-1:17.0
0,-2,-1:17.0
2,-2,-1:17
1,-1,-1:17.0
2,-1,-1:17
3,-1,-1:17
-4,0,-1:17.0
-2,0,-1:17.0
0,0,-1:17.0
2,1,-1:17.0
3,1,-1:17
-5,2,-1:17
-4,2,-1:17.0
-2,2,-1:17.0
0,2,-1:17.0
1,3,-1:17.0
2,3,-1:17
-4,4,-1:17
-3,4,-1:17.0
0,4,-1:17.0
1,4,-1:17
-3,5,-1:17
0,5,-1:17
-4,-2,0:17
-3,-2,0:17
-2,-2,0:17.0
-1,-2,0:17
0,-2,0:17
-3,-1,0:17.0
-2,-1,0:17.0
-1,-1,0:17.0
0,-1,0:17.0
1,-1,0:17.0
-4,0,0:17.0
-3,0,0:17.0
-2,0,0:17.0
-1,0,0:17.0
0,0,0:17.0
1,0,0:17.0
2,0,0:17
-4,1,0:17.0
-3,1,0:17.0
-2,1,0:17.0
-1,1,0:17.0
0,1,0:17.0
1,1,0:17.0
2,1,0:17
-4,2,0:17
-3,2,0:17.0
-2,2,0:17.0
-1,2,0:17.0
0,2,0:17.0
1,2,0:17.0
-3,3,0:17.0
-2,3,0:17.0
-1,3,0:17.0
0,3,0:17.0
1,3,0:17
-3,4,0:17
-2,4,0:17
-1,4,0:17
0,4,0:17
-2,-2,1:17.0
-3,-1,1:17.0
-2,-1,1:17.0
-1,-1,1:17.0
0,-1,1:17.0
1,-1,1:17.0
-4,0,1:17.0
-3,0,1:17.0
-2,0,1:17.0
-1,0,1:17.0
0,0,1:17.0
1,0,1:17.0
-4,1,1:17.0
-3,1,1:17.0
-2,1,1:17.0
-1,1,1:17.0
0,1,1:17.0
1,1,1:17.0
-3,2,1:17.0
-2,2,1:17.0
-1,2,1:17.0
0,2,1:17.0
1,2,1:17.0
-3,3,1:17.0
-2,3,1:17.0
-1,3,1:17.0
0,3,1:17.0
-3,-1,2:17.0
-2,-1,2:17.0
-1,-1,2:17.0
0,-1,2:17.0
-3,0,2:17.0
-2,0,2:17.0
-1,0,2:17.0
0,0,2:17.0
1,0,2:17.0
-3,1,2:17.0
-2,1,2:17.0
-1,1,2:17.0
0,1,2:17.0
1,1,2:17.0
-3,2,2:17.0
-2,2,2:17.0
-1,2,2:17.0
0,2,2:17.0
-2,3,2:17.0
-1,3,2:17.0
0,3,2:17.0
-4,-3,3:18
-3,-3,3:18
-4,-2,3:18
-2,-1,3:17.0
-1,-1,3:17.0
0,-1,3:17.0
-3,0,3:17.0
-2,0,3:17.0
-1,0,3:17.0
0,0,3:17.0
-3,1,3:17.0
-2,1,3:17.0
-1,1,3:17.0
0,1,3:17.0
1,1,3:17.0
-3,2,3:17.0
-2,2,3:17.0
-1,2,3:17.0
0,2,3:17.0
-2,3,3:17.0
-1,3,3:17.0
-3,-7,4:18
-1,-7,4:18
-3,-6,4:18
-1,-6,4:18
-4,-5,4:18
-3,-5,4:18
1,-5,4:18
2,-5,4:18
-6,-4,4:18
-5,-4,4:18
-4,-4,4:18
1,-4,4:18
2,-4,4:18
3,-4,4:18
4,-4,4:18
-8,-3,4:18
-7,-3,4:18
-6,-3,4:18
-5,-3,4:18
-4,-3,4:18
-3,-3,4:18
-2,-3,4:18
-1,-3,4:18
0,-3,4:18
1,-3,4:18
-4,-2,4:18
-3,-2,4:18
1,-2,4:18
2,-2,4:18
5,-2,4:18
-8,-1,4:18
-4,-1,4:18
-2,-1,4:17.0
-1,-1,4:17.0
0,-1,4:17.0
2,-1,4:18
5,-1,4:18
-8,0,4:18
-5,0,4:18
-3,0,4:17.0
-2,0,4:17.0
-1,0,4:17.0
0,0,4:17.0
2,0,4:18
3,0,4:18
4,0,4:18
5,0,4:18
-7,1,4:18
-5,1,4:18
-3,1,4:17.0
-2,1,4:17.0
-1,1,4:17.0
0,1,4:17.0
1,1,4:17.0
3,1,4:18
5,1,4:18
-7,2,4:18
-4,2,4:18
-3,2,4:17.0
-2,2,4:17.0
-1,2,4:17.0
0,2,4:17.0
2,2,4:18
-4,3,4:18
1,3,4:18
2,3,4:18
6,3,4:18
-4,4,4:18
-3,4,4:18
-2,4,4:18
-1,4,4:18
0,4,4:18
1,4,4:18
2,5,4:18
3,5,4:18
-7,6,4:18
-6,6,4:18
-4,6,4:18
-3,6,4:18
2,6,4:18
-3,7,4:18
-2,7,4:18
1,7,4:18
-3,-7,5:18
-2,-7,5:18
-3,-6,5:18
-2,-6,5:18
-1,-6,5:18
-4,-5,5:18
-3,-5,5:18
-2,-5,5:17
-1,-5,5:18
0,-5,5:18
-5,-4,5:18
-4,-4,5:18
-3,-4,5:18
-2,-4,5:17
0,-4,5:17
1,-4,5:18
2,-4,5:18
3,-4,5:18
4,-4,5:18
-8,-3,5:18
-7,-3,5:18
-6,-3,5:18
-5,-3,5:18
-4,-3,5:18
-2,-3,5:18
-1,-3,5:18
0,-3,5:18
1,-3,5:18
2,-3,5:17
3,-3,5:18
4,-3,5:18
5,-3,5:18
-8,-2,5:18
-7,-2,5:18
-6,-2,5:17
-4,-2,5:17
-3,-2,5:18
-2,-2,5:18
-1,-2,5:18
0,-2,5:18
1,-2,5:18
2,-2,5:17
3,-2,5:17
4,-2,5:18
5,-2,5:18
-8,-1,5:18
-7,-1,5:18
-6,-1,5:17
-4,-1,5:18
-3,-1,5:18
-2,-1,5:17.0
-1,-1,5:17.0
0,-1,5:17.0
1,-1,5:18
2,-1,5:18
3,-1,5:17
4,-1,5:18
-7,0,5:18
-6,0,5:17
-5,0,5:18
-4,0,5:18
-3,0,5:17.0
-2,0,5:17.0
-1,0,5:17.0
0,0,5:17.0
2,0,5:18
4,0,5:18
-7,1,5:18
-6,1,5:18
-4,1,5:18
-3,1,5:17.0
-2,1,5:17.0
-1,1,5:17.0
0,1,5:17.0
1,1,5:17.0
2,1,5:18
4,1,5:18
5,1,5:18
-6,2,5:18
-4,2,5:18
-3,2,5:17.0
-2,2,5:17.0
-1,2,5:17.0
0,2,5:17.0
1,2,5:18
2,2,5:18
4,2,5:18
5,2,5:18
-7,3,5:18
-6,3,5:18
-4,3,5:18
-3,3,5:18
-2,3,5:18
-1,3,5:18
0,3,5:18
1,3,5:18
4,3,5:17
5,3,5:18
6,3,5:18
-7,4,5:18
-6,4,5:18
-5,4,5:18
-4,4,5:17
-3,4,5:18
-2,4,5:18
-1,4,5:18
0,4,5:18
1,4,5:18
2,4,5:18
3,4,5:18
4,4,5:18
5,4,5:18
6,4,5:18
-7,5,5:18
-6,5,5:18
-5,5,5:17
-4,5,5:18
-3,5,5:18
1,5,5:18
2,5,5:18
3,5,5:18
-7,6,5:18
-6,6,5:18
-5,6,5:18
-4,6,5:18
-3,6,5:18
-2,6,5:18
0,6,5:17
1,6,5:18
2,6,5:18
-2,7,5:18
-1,7,5:18
0,7,5:18
1,7,5:18
-1,8,5:18
0,8,5:18
-2,-6,6:18
-3,-5,6:18
-2,-5,6:18
-1,-5,6:18
-3,-4,6:18
-2,-4,6:18
-1,-4,6:18
0,-4,6:18
-4,-3,6:18
-3,-3,6:18
-2,-3,6:17
-1,-3,6:18
0,-3,6:17
1,-3,6:18
2,-3,6:18
3,-3,6:18
4,-3,6:18
-7,-2,6:18
-6,-2,6:18
-5,-2,6:18
-4,-2,6:18
-3,-2,6:18
-2,-2,6:18
-1,-2,6:18
0,-2,6:17
1,-2,6:18
3,-2,6:18
4,-2,6:18
-7,-1,6:18
-6,-1,6:18
-4,-1,6:17
-3,-1,6:18
-2,-1,6:17.0
-1,-1,6:17.0
0,-1,6:17.0
1,-1,6:18
2,-1,6:17
3,-1,6:18
4,-1,6:18
-6,0,6:18
-5,0,6:17
-4,0,6:18
-3,0,6:17.0
-2,0,6:17.0
-1,0,6:17.0
0,0,6:17.0
1,0,6:17
2,0,6:18
3,0,6:18
-6,1,6:18
-5,1,6:18
-4,1,6:18
-3,1,6:17.0
-2,1,6:17.0
-1,1,6:17.0
0,1,6:17.0
1,1,6:18
2,1,6:18
3,1,6:18
4,1,6:18
-6,2,6:18
-5,2,6:18
-4,2,6:17
-3,2,6:18
-2,2,6:17.0
-1,2,6:17.0
0,2,6:17.0
1,2,6:18
2,2,6:17
3,2,6:17
4,2,6:18
-6,3,6:18
-5,3,6:17
-4,3,6:18
-3,3,6:18
-2,3,6:18
-1,3,6:18
0,3,6:18
2,3,6:17
3,3,6:18
4,3,6:18
5,3,6:18
-6,4,6:18
-5,4,6:17
-4,4,6:18
-3,4,6:18
-1,4,6:17
0,4,6:17
1,4,6:18
2,4,6:18
3,4,6:18
4,4,6:18
-6,5,6:18
-5,5,6:18
-4,5,6:18
-3,5,6:18
-2,5,6:18
-1,5,6:17
0,5,6:18
1,5,6:18
-2,6,6:18
-1,6,6:18
0,6,6:18
1,6,6:18
-1,7,6:18
0,7,6:18
-2,-4,7:18
-1,-4,7:18
-3,-3,7:18
-2,-3,7:18
-1,-3,7:18
0,-3,7:18
1,-3,7:18
2,-3,7:18
-5,-2,7:18
-4,-2,7:18
-3,-2,7:18
-2,-2,7:18
-1,-2,7:18
0,-2,7:18
1,-2,7:18
2,-2,7:18
3,-2,7:18
-6,-1,7:18
-5,-1,7:18
-4,-1,7:18
-3,-1,7:18
-2,-1,7:18
-1,-1,7:18
0,-1,7:18
2,-1,7:18
3,-1,7:18
-6,0,7:18
-5,0,7:18
-4,0,7:17
-3,0,7:18
-2,0,7:17.0
-1,0,7:17.0
0,0,7:17.0
1,0,7:18
2,0,7:18
3,0,7:18
-5,1,7:18
-4,1,7:18
-3,1,7:18
-2,1,7:17.0
-1,1,7:17.0
0,1,7:17.0
1,1,7:18
2,1,7:18
3,1,7:18
-5,2,7:18
-4,2,7:18
-3,2,7:18
-2,2,7:17.0
-1,2,7:17.0
0,2,7:18
2,2,7:18
3,2,7:18
-5,3,7:18
-4,3,7:18
-3,3,7:18
-2,3,7:18
-1,3,7:17
0,3,7:18
1,3,7:18
2,3,7:18
3,3,7:18
4,3,7:18
-6,4,7:18
-5,4,7:18
-4,4,7:18
-3,4,7:18
-2,4,7:18
-1,4,7:18
0,4,7:18
1,4,7:18
-2,5,7:18
-1,5,7:18
0,5,7:18
1,5,7:18
-1,6,7:18
0,6,7:18
-2,-5,8:18
-1,-5,8:18
-2,-4,8:18
-1,-4,8:18
-3,-3,8:18
-2,-3,8:17
-1,-3,8:18
0,-3,8:18
1,-3,8:18
2,-3,8:18
3,-3,8:18
4,-3,8:18
-6,-2,8:18
-5,-2,8:18
-4,-2,8:18
-3,-2,8:18
-2,-2,8:18
-1,-2,8:18
0,-2,8:18
1,-2,8:17
2,-2,8:18
3,-2,8:18
4,-2,8:18
-7,-1,8:18
-6,-1,8:18
-4,-1,8:17
-3,-1,8:18
-2,-1,8:18
-1,-1,8:18
0,-1,8:18
1,-1,8:18
2,-1,8:17
3,-1,8:18
-6,0,8:18
-5,0,8:18
-4,0,8:18
-3,0,8:18
-2,0,8:17.0
-1,0,8:17.0
0,0,8:18
1,0,8:18
2,0,8:18
-5,1,8:18
-4,1,8:18
-3,1,8:18
-2,1,8:18
-1,1,8:17.0
0,1,8:18
2,1,8:18
3,1,8:18
-5,2,8:18
-4,2,8:18
-3,2,8:18
-2,2,8:17.0
-1,2,8:18
0,2,8:18
1,2,8:18
2,2,8:17
3,2,8:18
4,2,8:18
-5,3,8:18
-4,3,8:18
-3,3,8:18
-2,3,8:18
-1,3,8:18
0,3,8:18
1,3,8:18
2,3,8:18
3,3,8:18
4,3,8:18
5,3,8:18
-6,4,8:18
-5,4,8:18
-4,4,8:18
-3,4,8:18
-2,4,8:18
-1,4,8:18
0,4,8:18
1,4,8:18
-6,5,8:18
-2,5,8:18
-1,5,8:18
0,5,8:18
-1,6,8:18
0,6,8:18
-1,7,8:18
0,7,8:18
-2,-5,9:18
-2,-4,9:18
-1,-4,9:18
-2,-3,9:18
-1,-3,9:18
-3,-2,9:18
-2,-2,9:17
-1,-2,9:18
0,-2,9:18
1,-2,9:18
2,-2,9:18
3,-2,9:18
-6,-1,9:18
-5,-1,9:18
-4,-1,9:18
-3,-1,9:18
-2,-1,9:17
-1,-1,9:18
0,-1,9:18
1,-1,9:17
2,-1,9:18
-5,0,9:18
-4,0,9:18
-3,0,9:17
-2,0,9:18
-1,0,9:18
0,0,9:18
1,0,9:17
2,0,9:18
-4,1,9:18
-3,1,9:17.0
-2,1,9:18
-1,1,9:17.0
0,1,9:18
1,1,9:17
2,1,9:18
-4,2,9:18
-3,2,9:18
-2,2,9:18
-1,2,9:18
0,2,9:18
1,2,9:18
3,2,9:18
-5,3,9:18
-4,3,9:18
-3,3,9:17.0
-2,3,9:18
-1,3,9:18
0,3,9:18
1,3,9:18
2,3,9:18
3,3,9:18
4,3,9:18
-5,4,9:18
-4,4,9:18
-3,4,9:18
-2,4,9:18
-1,4,9:18
0,4,9:18
-1,5,9:18
0,5,9:18
-1,6,9:18
0,6,9:18
-2,-4,10:18
-1,-4,10:18
0,-4,10:18
-2,-3,10:18
-1,-3,10:18
1,-3,10:18
-2,-2,10:18
-1,-2,10:18
1,-2,10:18
2,-2,10:18
-5,-1,10:18
-4,-1,10:18
-3,-1,10:18
-2,-1,10:18
-1,-1,10:17
0,-1,10:18
1,-1,10:18
2,-1,10:18
-5,0,10:18
-4,0,10:18
-3,0,10:18
-2,0,10:17.0
-1,0,10:18
0,0,10:17.0
1,0,10:18
-6,1,10:18
-5,1,10:18
-4,1,10:18
-3,1,10:18
-2,1,10:17.0
-1,1,10:17.0
0,1,10:17.0
1,1,10:18
2,1,10:18
3,1,10:18
-4,2,10:18
-3,2,10:18
-2,2,10:17.0
-1,2,10:17.0
0,2,10:17.0
1,2,10:18
2,2,10:18
3,2,10:18
-5,3,10:18
-4,3,10:18
-3,3,10:17
-2,3,10:18
-1,3,10:17
0,3,10:18
1,3,10:18
2,3,10:18
3,3,10:18
-5,4,10:18
-4,4,10:18
-3,4,10:18
-1,4,10:17
0,4,10:18
2,4,10:18
-3,5,10:18
-1,5,10:18
0,5,10:18
1,5,10:18
-1,-4,11:18
-4,-3,11:18
-3,-3,11:18
-2,-3,11:18
-1,-3,11:18
0,-3,11:18
1,-3,11:18
-5,-2,11:18
-4,-2,11:18
-3,-2,11:17
-2,-2,11:18
-1,-2,11:18
1,-2,11:18
2,-2,11:18
3,-2,11:18
-5,-1,11:18
-4,-1,11:18
-3,-1,11:18
-2,-1,11:18
-1,-1,11:18
0,-1,11:18
1,-1,11:17
2,-1,11:18
3,-1,11:18
-5,0,11:18
-4,0,11:18
-3,0,11:18
-2,0,11:17.0
-1,0,11:17.0
0,0,11:17.0
1,0,11:18
3,0,11:18
-5,1,11:18
-3,1,11:18
-2,1,11:17.0
-1,1,11:17.0
0,1,11:17.0
1,1,11:18
2,1,11:18
3,1,11:18
-5,2,11:18
-3,2,11:18
-2,2,11:18
-1,2,11:17.0
0,2,11:18
1,2,11:18
2,2,11:18
3,2,11:18
-5,3,11:18
-4,3,11:18
-3,3,11:18
-2,3,11:18
-1,3,11:18
0,3,11:18
1,3,11:17
2,3,11:18
3,3,11:18
-4,4,11:18
-3,4,11:18
-1,4,11:18
0,4,11:18
1,4,11:18
2,4,11:18
-3,5,11:18
-2,5,11:18
-1,5,11:18
0,5,11:18
-1,6,11:18
-2,-3,12:18
-1,-3,12:18
-5,-2,12:18
-4,-2,12:18
-3,-2,12:18
-2,-2,12:18
-1,-2,12:18
0,-2,12:18
1,-2,12:18
2,-2,12:18
-5,-1,12:18
-4,-1,12:18
-3,-1,12:17
-2,-1,12:18
-1,-1,12:18
1,-1,12:18
2,-1,12:18
3,-1,12:18
-5,0,12:18
-4,0,12:18
-3,0,12:17
-2,0,12:18
-1,0,12:18
0,0,12:18
1,0,12:18
2,0,12:18
-5,1,12:18
-4,1,12:18
-3,1,12:18
-2,1,12:18
-1,1,12:17.0
0,1,12:18
1,1,12:18
2,1,12:18
-4,2,12:18
-3,2,12:18
-2,2,12:18
-1,2,12:18
0,2,12:18
1,2,12:18
2,2,12:18
-4,3,12:18
-3,3,12:18
-1,3,12:18
1,3,12:18
2,3,12:18
-3,4,12:18
-2,4,12:18
-1,4,12:18
0,4,12:18
1,4,12:18
-2,5,12:18
-1,5,12:18
-3,-2,13:18
-2,-2,13:18
-1,-2,13:18
0,-2,13:18
1,-2,13:18
-4,-1,13:18
-3,-1,13:18
-2,-1,13:18
-1,-1,13:17.0
0,-1,13:18
1,-1,13:18
2,-1,13:18
-4,0,13:18
-3,0,13:18
-2,0,13:17.0
-1,0,13:18
0,0,13:17.0
1,0,13:18
2,0,13:18
-4,1,13:18
-3,1,13:18
-2,1,13:18
-1,1,13:17.0
0,1,13:17.0
1,1,13:18
2,1,13:18
-4,2,13:18
-3,2,13:18
-2,2,13:17.0
-1,2,13:17.0
1,2,13:18
-3,3,13:18
-2,3,13:18
-1,3,13:18
0,3,13:18
1,3,13:18
-3,4,13:18
-2,4,13:18
-1,4,13:18
0,4,13:18
-1,-3,14:18
-3,-2,14:18
-2,-2,14:18
-1,-2,14:18
0,-2,14:18
-4,-1,14:18
-3,-1,14:18
-2,-1,14:18
-1,-1,14:18
0,-1,14:18
1,-1,14:18
2,-1,14:18
-4,0,14:18
-3,0,14:18
-2,0,14:17.0
-1,0,14:17.0
0,0,14:18
1,0,14:18
2,0,14:18
-4,1,14:18
-3,1,14:18
-2,1,14:17.0
-1,1,14:17.0
0,1,14:17.0
1,1,14:18
2,1,14:18
-4,2,14:18
-3,2,14:18
-2,2,14:18
-1,2,14:17.0
0,2,14:18
1,2,14:18
2,2,14:18
-4,3,14:18
-3,3,14:18
-2,3,14:18
-1,3,14:18
0,3,14:18
1,3,14:18
-2,4,14:18
-1,4,14:18
0,4,14:18
-2,-2,15:18
-1,-2,15:18
-3,-1,15:18
-2,-1,15:18
-1,-1,15:18
0,-1,15:18
1,-1,15:18
-3,0,15:18
-2,0,15:18
-1,0,15:18
0,0,15:18
1,0,15:18
-4,1,15:18
-3,1,15:18
-2,1,15:18
-1,1,15:17.0
0,1,15:18
-4,2,15:18
-3,2,15:18
-2,2,15:18
-1,2,15:18
0,2,15:18
1,2,15:18
-3,3,15:18
-2,3,15:18
-1,3,15:18
0,3,15:18
-3,-1,16:18
-2,-1,16:18
-1,-1,16:18
0,-1,16:18
-3,0,16:18
-2,0,16:18
-1,0,16:17.0
0,0,16:18
1,0,16:18
-4,1,16:18
-3,1,16:18
-2,1,16:17.0
-1,1,16:17.0
0,1,16:18
1,1,16:18
-3,2,16:18
-2,2,16:18
-1,2,16:18
0,2,16:18
1,2,16:18
-3,3,16:18
-2,3,16:18
-1,3,16:18
0,3,16:18
-2,-1,17:18
-1,-1,17:18
0,-1,17:18
-3,0,17:18
-2,0,17:18
-1,0,17:18
0,0,17:18
1,0,17:18
-3,1,17:18
-2,1,17:18
-1,1,17:17.0
0,1,17:18
-3,2,17:18
-2,2,17:18
-1,2,17:18
0,2,17:18
-2,3,17:18
-1,3,17:18
0,3,17:18
-2,-1,18:18
-1,-1,18:18
-2,0,18:18
-1,0,18:18
0,0,18:18
-3,1,18:18
-2,1,18:18
-1,1,18:17.0
0,1,18:18
-2,2,18:18
-1,2,18:18
0,2,18:18
-1,3,18:18
-2,0,19:18
-1,0,19:18
0,0,19:18
-3,1,19:18
-2,1,19:18
-1,1,19:17.0
0,1,19:18
-2,2,19:18
-1,2,19:18
-2,0,20:18
-1,0,20:18
-2,1,20:18
-1,1,20:18
0,1,20:18
-1,2,20:18
-2,0,21:18
-1,0,21:18
-2,1,21:18
-1,1,21:18
0,1,21:18
-1,0,22:18
-2,1,22:18
-1,1,22:18
-1,1,23:18
