[META]
version=2.0
spawnOnBlockType=2,3
spawnSunlight=True
spawnDarkness=True
spawnWater=False
spawnLava=False
underFill=False
randomRotation=True
dig=True
tree=True
branch=False
needsFoundation=True
rarity=30
collisionPercentage=2
spawnElevationMin=0
spawnElevationMax=220
spawnInBiome=WoWForest
[DATA]
-1,-2,0:17.0
0,-2,0:17.0
1,-2,0:17.0
-2,-1,0:17.0
-1,-1,0:17.0
2,-1,0:17.0
-2,0,0:17.0
2,0,0:17.0
-1,1,0:17.0
1,1,0:17.0
2,1,0:17.0
0,2,0:17.0
2,-3,1:18
-3,-2,1:18
-1,-2,1:17.0
0,-2,1:17.0
1,-2,1:17.0
3,-2,1:18
-4,-1,1:18
-1,-1,1:17.0
0,-1,1:17.0
1,-1,1:17.0
2,-1,1:17.0
-4,0,1:18
-1,0,1:17.0
0,0,1:17.0
1,0,1:17.0
2,0,1:17.0
-4,1,1:18
-1,1,1:17.0
0,1,1:17.0
1,1,1:17.0
2,1,1:17.0
3,1,1:18
-4,2,1:18
0,2,1:17.0
-4,-6,2:18
-3,-6,2:18
-2,-6,2:18
-1,-6,2:18
0,-6,2:18
1,-6,2:18
2,-6,2:18
3,-6,2:18
4,-6,2:18
-4,-5,2:18
-3,-5,2:17
-1,-5,2:18
0,-5,2:18
3,-5,2:18
4,-5,2:18
-4,-4,2:18
0,-4,2:18
1,-4,2:18
3,-4,2:18
4,-4,2:18
-5,-3,2:18
-4,-3,2:18
-2,-3,2:18
-1,-3,2:18
0,-3,2:18
1,-3,2:18
2,-3,2:18
3,-3,2:17
4,-3,2:18
5,-3,2:18
-6,-2,2:18
-5,-2,2:18
-4,-2,2:18
-3,-2,2:18
-2,-2,2:18
-1,-2,2:17.0
0,-2,2:17.0
1,-2,2:17.0
2,-2,2:18
3,-2,2:18
5,-2,2:18
6,-2,2:18
-7,-1,2:18
-6,-1,2:18
-5,-1,2:18
-4,-1,2:18
-3,-1,2:18
-1,-1,2:17.0
0,-1,2:17.0
1,-1,2:17.0
2,-1,2:17.0
3,-1,2:18
4,-1,2:18
5,-1,2:17
6,-1,2:18
7,-1,2:18
-7,0,2:18
-6,0,2:18
-5,0,2:17
-4,0,2:18
-3,0,2:18
-1,0,2:17.0
0,0,2:17.0
1,0,2:17.0
2,0,2:17.0
3,0,2:18
6,0,2:18
7,0,2:18
-7,1,2:18
-6,1,2:18
-5,1,2:18
-3,1,2:18
-1,1,2:17.0
0,1,2:17.0
1,1,2:17.0
2,1,2:17.0
3,1,2:18
5,1,2:18
-3,2,2:18
-2,2,2:18
2,2,2:18
3,2,2:18
4,2,2:18
5,2,2:18
-4,3,2:18
-2,3,2:18
-1,3,2:18
0,3,2:18
1,3,2:18
2,3,2:18
4,3,2:18
5,3,2:18
-4,4,2:18
-2,4,2:18
-1,4,2:18
1,4,2:18
3,4,2:18
4,4,2:18
-4,5,2:18
-3,5,2:17
-2,5,2:18
-1,5,2:18
0,5,2:18
1,5,2:18
2,5,2:18
3,5,2:18
4,5,2:18
-3,6,2:18
-2,6,2:18
3,6,2:18
-4,-6,3:18
-3,-6,3:18
2,-6,3:18
3,-6,3:18
-4,-5,3:18
-3,-5,3:18
-2,-5,3:18
-1,-5,3:18
0,-5,3:18
1,-5,3:18
2,-5,3:18
3,-5,3:18
-4,-4,3:18
-3,-4,3:17.0
-2,-4,3:18
-1,-4,3:18
0,-4,3:18
2,-4,3:17
3,-4,3:18
4,-4,3:18
-4,-3,3:18
-3,-3,3:18
-2,-3,3:17
-1,-3,3:18
0,-3,3:17
1,-3,3:18
2,-3,3:17
3,-3,3:18
4,-3,3:18
-5,-2,3:18
-4,-2,3:18
-3,-2,3:18
-2,-2,3:18
-1,-2,3:18
0,-2,3:17.0
1,-2,3:18
2,-2,3:18
3,-2,3:18
4,-2,3:18
5,-2,3:18
-6,-1,3:18
-5,-1,3:18
-4,-1,3:18
-3,-1,3:18
-2,-1,3:18
-1,-1,3:17.0
0,-1,3:17.0
1,-1,3:17.0
2,-1,3:18
3,-1,3:18
4,-1,3:17
5,-1,3:18
6,-1,3:18
7,-1,3:18
-7,0,3:18
-6,0,3:18
-5,0,3:18
-4,0,3:17
-3,0,3:17
-2,0,3:18
-1,0,3:17.0
0,0,3:17.0
1,0,3:17.0
2,0,3:18
3,0,3:18
4,0,3:18
5,0,3:18
6,0,3:18
-6,1,3:18
-3,1,3:18
-2,1,3:18
-1,1,3:17.0
0,1,3:17.0
1,1,3:17.0
2,1,3:18
4,1,3:18
5,1,3:18
-4,2,3:18
-3,2,3:18
-2,2,3:18
-1,2,3:17
0,2,3:18
1,2,3:18
2,2,3:17
3,2,3:18
4,2,3:18
-4,3,3:18
-3,3,3:18
-2,3,3:17
-1,3,3:18
0,3,3:18
1,3,3:17
2,3,3:18
3,3,3:17
4,3,3:18
-3,4,3:18
-2,4,3:17
-1,4,3:18
0,4,3:18
1,4,3:18
2,4,3:18
3,4,3:18
4,4,3:18
-3,5,3:18
-2,5,3:18
-1,5,3:18
2,5,3:18
3,5,3:18
4,5,3:18
-3,6,3:18
-3,-5,4:18
-2,-5,4:18
2,-5,4:18
3,-5,4:18
-3,-4,4:18
-2,-4,4:18
-1,-4,4:18
0,-4,4:18
1,-4,4:18
2,-4,4:18
3,-4,4:18
-3,-3,4:18
-1,-3,4:17
0,-3,4:18
1,-3,4:17
2,-3,4:18
3,-3,4:18
-4,-2,4:18
-3,-2,4:18
-2,-2,4:18
-1,-2,4:18
0,-2,4:18
1,-2,4:18
2,-2,4:18
3,-2,4:18
4,-2,4:18
-5,-1,4:18
-4,-1,4:18
-3,-1,4:18
-2,-1,4:18
-1,-1,4:17.0
0,-1,4:17.0
1,-1,4:17.0
2,-1,4:18
3,-1,4:18
4,-1,4:18
5,-1,4:18
-6,0,4:18
-5,0,4:18
-4,0,4:18
-3,0,4:18
-2,0,4:17
-1,0,4:17.0
0,0,4:17.0
1,0,4:17.0
2,0,4:18
3,0,4:17
4,0,4:18
5,0,4:18
-4,1,4:18
-3,1,4:18
-2,1,4:18
-1,1,4:17.0
0,1,4:17.0
1,1,4:17.0
2,1,4:18
3,1,4:18
4,1,4:18
-3,2,4:18
-2,2,4:17
-1,2,4:18
0,2,4:18
1,2,4:18
2,2,4:18
3,2,4:18
-3,3,4:18
-2,3,4:18
-1,3,4:18
0,3,4:18
1,3,4:18
2,3,4:18
3,3,4:18
-3,4,4:18
-2,4,4:18
-1,4,4:18
1,4,4:18
2,4,4:18
3,4,4:18
-2,-5,5:18
2,-5,5:18
3,-5,5:18
-3,-4,5:18
-2,-4,5:18
-1,-4,5:18
0,-4,5:18
1,-4,5:18
2,-4,5:18
3,-4,5:18
-3,-3,5:18
-2,-3,5:18
-1,-3,5:18
0,-3,5:18
1,-3,5:18
2,-3,5:18
3,-3,5:18
-4,-2,5:18
-3,-2,5:18
-2,-2,5:18
-1,-2,5:18
0,-2,5:18
1,-2,5:17
2,-2,5:18
3,-2,5:18
4,-2,5:18
-5,-1,5:18
-4,-1,5:17
-3,-1,5:17
-2,-1,5:18
-1,-1,5:18
0,-1,5:17.0
1,-1,5:17.0
2,-1,5:18
3,-1,5:17
4,-1,5:17
5,-1,5:18
6,-1,5:18
-5,0,5:18
-4,0,5:18
-3,0,5:18
-2,0,5:18
-1,0,5:17.0
0,0,5:17.0
1,0,5:17.0
2,0,5:17
3,0,5:18
4,0,5:18
5,0,5:18
-4,1,5:18
-3,1,5:18
-2,1,5:18
-1,1,5:18
0,1,5:17.0
1,1,5:18
2,1,5:18
3,1,5:18
-3,2,5:18
-2,2,5:18
-1,2,5:18
0,2,5:17
1,2,5:18
2,2,5:18
3,2,5:18
-3,3,5:18
-2,3,5:18
-1,3,5:18
0,3,5:18
1,3,5:18
2,3,5:18
3,3,5:18
-3,4,5:18
-2,4,5:18
-1,4,5:18
2,4,5:18
3,4,5:18
-2,5,5:18
2,-5,6:18
-3,-4,6:18
-2,-4,6:18
-1,-4,6:18
1,-4,6:18
2,-4,6:18
-3,-3,6:18
-2,-3,6:17
-1,-3,6:18
0,-3,6:18
1,-3,6:18
2,-3,6:18
-2,-2,6:18
-1,-2,6:17
0,-2,6:18
1,-2,6:18
2,-2,6:18
3,-2,6:18
-5,-1,6:18
-4,-1,6:18
-3,-1,6:18
-2,-1,6:17
-1,-1,6:18
0,-1,6:17.0
1,-1,6:17.0
2,-1,6:17
3,-1,6:17
4,-1,6:18
5,-1,6:18
-5,0,6:18
-4,0,6:18
-3,0,6:18
-2,0,6:18
-1,0,6:18
0,0,6:17.0
1,0,6:17.0
2,0,6:18
3,0,6:18
4,0,6:18
5,0,6:18
-4,1,6:18
-3,1,6:18
-2,1,6:18
-1,1,6:18
0,1,6:18
1,1,6:18
2,1,6:18
3,1,6:18
-2,2,6:18
-1,2,6:18
0,2,6:18
1,2,6:18
2,2,6:17
3,2,6:18
-2,3,6:18
-1,3,6:18
0,3,6:18
1,3,6:18
2,3,6:18
3,3,6:18
-2,4,6:18
-1,4,6:18
2,4,6:18
3,4,6:18
-2,-4,7:18
-1,-4,7:18
1,-4,7:18
2,-4,7:18
-2,-3,7:18
-1,-3,7:18
0,-3,7:18
1,-3,7:18
2,-3,7:18
-2,-2,7:18
0,-2,7:18
1,-2,7:17
2,-2,7:18
4,-2,7:18
-3,-1,7:18
-2,-1,7:18
-1,-1,7:17.0
0,-1,7:17.0
1,-1,7:17.0
2,-1,7:17
3,-1,7:18
4,-1,7:18
-4,0,7:18
-3,0,7:18
-2,0,7:18
-1,0,7:17.0
0,0,7:17.0
1,0,7:17.0
2,0,7:18
3,0,7:18
4,0,7:18
5,0,7:18
-2,1,7:18
-1,1,7:18
0,1,7:17.0
1,1,7:17.0
2,1,7:18
4,1,7:18
-3,2,7:18
-2,2,7:17
-1,2,7:18
0,2,7:18
1,2,7:18
2,2,7:18
-3,3,7:18
-2,3,7:18
-1,3,7:18
1,3,7:18
2,3,7:18
-2,4,7:18
0,-5,8:18
-2,-4,8:18
-1,-4,8:18
0,-4,8:18
1,-4,8:18
2,-4,8:18
3,-4,8:18
-3,-3,8:18
-2,-3,8:18
-1,-3,8:18
0,-3,8:17
1,-3,8:18
3,-3,8:18
-4,-2,8:18
-3,-2,8:18
-2,-2,8:18
-1,-2,8:18
0,-2,8:18
1,-2,8:18
2,-2,8:18
3,-2,8:18
4,-2,8:18
-4,-1,8:18
-3,-1,8:17
-2,-1,8:18
-1,-1,8:18
0,-1,8:17.0
1,-1,8:17.0
2,-1,8:18
3,-1,8:18
4,-1,8:18
-4,0,8:18
-3,0,8:18
-2,0,8:18
-1,0,8:17.0
0,0,8:17.0
1,0,8:17.0
2,0,8:18
3,0,8:18
4,0,8:18
-4,1,8:18
-3,1,8:18
-1,1,8:18
0,1,8:17.0
1,1,8:18
2,1,8:18
3,1,8:18
4,1,8:18
-3,2,8:18
-2,2,8:18
-1,2,8:18
0,2,8:18
1,2,8:18
2,2,8:18
3,2,8:18
-2,3,8:18
-1,3,8:18
0,3,8:17
1,3,8:18
2,3,8:18
3,3,8:18
-1,4,8:18
0,4,8:18
1,4,8:18
2,4,8:18
0,-4,9:18
-2,-3,9:18
-1,-3,9:18
0,-3,9:18
1,-3,9:18
2,-3,9:18
3,-3,9:18
-3,-2,9:18
-2,-2,9:18
-1,-2,9:18
0,-2,9:17
1,-2,9:18
2,-2,9:17.0
3,-2,9:18
-4,-1,9:18
-3,-1,9:18
-2,-1,9:17
-1,-1,9:18
0,-1,9:17.0
1,-1,9:17.0
2,-1,9:18
3,-1,9:18
-4,0,9:18
-3,0,9:18
-2,0,9:18
-1,0,9:18
0,0,9:17.0
1,0,9:18
2,0,9:18
3,0,9:18
-3,1,9:18
-2,1,9:18
-1,1,9:18
0,1,9:18
1,1,9:18
2,1,9:18
3,1,9:18
-2,2,9:18
-1,2,9:18
0,2,9:17
1,2,9:18
2,2,9:18
3,2,9:18
-1,3,9:18
0,3,9:18
1,3,9:18
2,3,9:18
-1,-3,10:18
0,-3,10:18
1,-3,10:18
2,-3,10:18
-2,-2,10:18
-1,-2,10:18
0,-2,10:18
1,-2,10:18
2,-2,10:18
3,-2,10:18
-3,-1,10:18
-2,-1,10:18
-1,-1,10:17.0
0,-1,10:17.0
1,-1,10:17.0
2,-1,10:18
3,-1,10:18
-3,0,10:18
-2,0,10:18
-1,0,10:17.0
0,0,10:17.0
1,0,10:18
2,0,10:17
3,0,10:18
-3,1,10:18
-2,1,10:18
-1,1,10:18
0,1,10:17.0
1,1,10:18
2,1,10:18
3,1,10:18
-2,2,10:18
-1,2,10:18
0,2,10:18
1,2,10:18
2,2,10:18
0,3,10:18
1,3,10:18
-1,-3,11:18
0,-3,11:18
1,-3,11:18
-2,-2,11:18
-1,-2,11:18
0,-2,11:18
1,-2,11:18
2,-2,11:18
-3,-1,11:18
-2,-1,11:18
-1,-1,11:18
0,-1,11:17.0
1,-1,11:17.0
2,-1,11:18
3,-1,11:18
-3,0,11:18
-2,0,11:18
-1,0,11:18
0,0,11:17.0
1,0,11:17.0
2,0,11:18
3,0,11:18
-2,1,11:18
-1,1,11:17
0,1,11:18
1,1,11:18
2,1,11:18
-2,2,11:18
-1,2,11:18
0,2,11:18
1,2,11:18
2,2,11:18
-2,-2,12:18
-1,-2,12:18
0,-2,12:18
1,-2,12:18
2,-2,12:18
-2,-1,12:18
-1,-1,12:18
0,-1,12:17.0
1,-1,12:18
2,-1,12:18
-2,0,12:18
-1,0,12:18
0,0,12:17.0
1,0,12:18
2,0,12:18
-2,1,12:18
-1,1,12:18
0,1,12:18
1,1,12:18
2,1,12:18
-1,2,12:18
0,2,12:18
1,2,12:18
-2,-2,13:18
-1,-2,13:18
0,-2,13:18
1,-2,13:18
2,-2,13:18
-2,-1,13:18
-1,-1,13:18
0,-1,13:18
1,-1,13:18
2,-1,13:18
-2,0,13:18
-1,0,13:18
0,0,13:17.0
1,0,13:18
2,0,13:18
-2,1,13:18
-1,1,13:18
0,1,13:18
1,1,13:18
2,1,13:18
0,2,13:18
1,2,13:18
-1,-2,14:18
0,-2,14:18
1,-2,14:18
-1,-1,14:18
0,-1,14:18
1,-1,14:18
2,-1,14:18
-2,0,14:18
-1,0,14:18
0,0,14:17.0
1,0,14:18
2,0,14:18
-1,1,14:18
0,1,14:18
1,1,14:18
2,1,14:18
1,-2,15:18
-1,-1,15:18
0,-1,15:18
1,-1,15:18
-1,0,15:18
0,0,15:17.0
1,0,15:18
2,0,15:18
0,1,15:18
1,1,15:18
-1,-1,16:18
0,-1,16:18
1,-1,16:18
-1,0,16:18
0,0,16:17.0
1,0,16:18
0,1,16:18
0,-1,17:18
1,-1,17:18
-1,0,17:18
0,0,17:17.0
1,0,17:18
0,-1,18:18
0,0,18:18
1,0,18:18
0,-1,19:18
0,0,19:18
