[META]
version=2.0
spawnOnBlockType=2,79,78,1
spawnSunlight=True
spawnDarkness=True
spawnWater=False
spawnLava=False
underFill=True
randomRotation=True
dig=True
tree=False
branch=False
needsFoundation=True
rarity=50
collisionPercentage=2
spawnElevationMin=0
spawnElevationMax=256
spawnInBiome=TheArctic
[DATA]
0,0,0:35.8
-1,0,-1:35.8
0,-1,-1:35.8
1,0,-1:35.8
0,1,-1:35.8
0,0,-1:35.8
0,0,1:35.8
0,0,2:35.8
3,-1,2:20
-2,-1,2:20
-2,3,2:20
1,3,2:20
0,0,3:35.8
-1,0,3:35.8
-1,-1,3:35.8
-2,-1,3:35.8
0,1,3:35.8
1,1,3:35.8
2,1,3:35.8
2,2,3:35.8
2,0,3:35.8
3,-1,3:35.8
2,-1,3:35.8
1,3,3:35.8
2,3,3:35.8
-1,2,3:35.8
-2,2,3:35.8
-2,3,3:35.8
0,0,4:35.8
-3,-2,4:20
1,-3,4:20
3,1,4:20
-2,2,4:20
0,0,5:35.8
0,-1,5:35.8
1,-2,5:35.8
0,-2,5:35.8
0,1,5:35.8
-1,1,5:35.8
-1,2,5:35.8
1,0,5:35.8
-1,-1,5:35.8
-2,-1,5:35.8
-2,-2,5:35.8
-3,-2,5:35.8
2,0,5:35.8
2,1,5:35.8
3,1,5:35.8
-2,2,5:35.8
1,-3,5:35.8
0,0,6:35.8
0,0,7:35.8
0,0,8:35.8
-1,0,8:35.8
0,-1,8:35.8
0,1,8:35.8
1,0,8:35.8
-2,0,8:20
0,-2,8:20
0,2,8:20
2,0,8:20
0,0,9:35.8
