[META]
version=2.0
spawnOnBlockType=2,13
spawnSunlight=True
spawnDarkness=True
spawnWater=True
spawnLava=False
underFill=True
randomRotation=True
dig=True
tree=True
branch=False
needsFoundation=True
rarity=180
collisionPercentage=8
spawnElevationMin=0
spawnElevationMax=200
spawnInBiome=ErodedCreekBorder
[DATA]
0,0,0:17.3
1,0,0:17.3
-1,1,-1:17.3
0,0,-1:17.3
1,0,-1:17.3
0,-1,-1:17.3
-1,-1,-1:17.3
2,1,-1:17.3
1,0,1:17.3
1,-1,1:17.3
0,-1,1:17.3
-1,-1,1:17.3
-1,-2,1:17.3
1,-1,2:17.3
2,-1,2:17.3
2,0,2:17.3
3,0,2:17.3
4,0,2:17.3
2,-1,3:17.3
3,-1,3:18.2
2,0,3:18.2
2,1,3:18.2
3,1,3:18.2
3,2,3:18.2
3,-2,3:18.2
4,-2,3:18.2
4,-3,3:18.2
1,-1,3:18.2
1,-2,3:18.2
0,-2,3:18.2
2,-1,4:17.3
2,-2,4:18.2
1,-1,4:18.2
2,-3,4:18.2
2,-4,4:18.2
1,0,4:18.2
0,0,4:18.2
2,-1,5:17.3
3,-1,5:17.3
2,-4,5:18.2
1,-4,5:18.2
1,0,5:18.2
1,1,5:18.2
2,1,5:18.2
2,2,5:18.2
4,-1,5:18.2
3,-1,6:17.3
2,-1,6:18.2
3,0,6:18.2
2,-2,6:18.2
1,-2,6:18.2
3,-1,7:17.3
3,-2,7:17.3
4,-2,7:18.2
2,-1,7:18.2
5,-2,7:18.2
6,-2,7:18.2
6,-3,7:18.2
5,-1,7:18.2
1,-1,7:18.2
1,0,7:18.2
0,0,7:18.2
1,1,7:18.2
3,-3,7:18.2
3,-2,8:17.3
2,-2,8:17.3
2,-3,8:17.3
1,-3,8:17.3
1,-4,8:18.2
0,-3,8:18.2
1,-2,8:18.2
3,-1,8:18.2
1,-5,8:18.2
2,-5,8:18.2
2,-6,8:18.2
-1,-3,8:18.2
-1,-2,8:18.2
-2,-3,8:18.2
-2,-4,8:18.2
3,0,8:18.2
3,1,8:18.2
4,1,8:18.2
3,2,8:18.2
3,-6,8:18.2
3,-2,9:17.3
3,-1,9:17.3
3,0,9:17.3
4,0,9:17.3
5,0,9:18.2
3,1,9:18.2
4,-2,9:18.2
2,-2,9:18.2
2,-3,9:18.2
2,0,9:18.2
6,0,9:18.2
6,1,9:18.2
7,0,9:18.2
3,2,9:18.2
2,2,9:18.2
2,3,9:18.2
1,0,9:18.2
5,-2,9:18.2
5,-3,9:18.2
2,-4,9:18.2
3,-4,9:18.2
3,-2,10:17.3
4,-2,10:17.3
4,-3,10:17.3
3,-1,10:18.2
3,0,10:18.2
4,0,10:18.2
5,0,10:18.2
4,1,10:18.2
5,-3,10:18.2
2,-2,10:18.2
1,-2,10:18.2
0,-2,10:18.2
0,-3,10:18.2
-1,-3,10:18.2
0,-1,10:18.2
6,-3,10:18.2
6,-4,10:18.2
4,-3,11:17.3
4,-4,11:17.3
5,-4,11:17.3
3,-4,11:17.3
3,-5,11:17.3
4,-2,11:18.2
3,-2,11:18.2
4,-1,11:18.2
5,-1,11:18.2
6,-4,11:18.2
2,-5,11:18.2
1,-5,11:18.2
1,-4,11:18.2
0,-5,11:18.2
1,-6,11:18.2
6,-5,11:18.2
7,-4,11:18.2
6,-1,11:18.2
4,-3,12:17.3
4,-2,12:17.3
3,-2,12:17.3
3,-1,12:17.3
2,-1,12:17.3
3,-5,12:18.2
5,-4,12:18.2
3,-4,12:18.2
4,-4,12:18.2
3,-6,12:18.2
5,-3,12:18.2
6,-1,12:18.2
6,0,12:18.2
0,-5,12:18.2
4,-4,13:18.2
4,-3,13:18.2
4,-2,13:18.2
5,-2,13:18.2
3,-2,13:18.2
2,-2,13:18.2
3,-1,13:18.2
3,0,13:18.2
2,-1,13:18.2
3,1,13:18.2
2,1,13:18.2
3,2,13:18.2
4,2,13:18.2
6,-1,13:18.2
7,-1,13:18.2
-1,-5,13:18.2
0,-5,13:18.2
0,-6,13:18.2
0,-4,13:18.2
1,-5,13:18.2
4,-2,14:18.2
4,-4,14:18.2
3,0,14:18.2
2,-2,14:18.2
