[META]
version=2.0
spawnOnBlockType=2,3
spawnSunlight=True
spawnDarkness=True
spawnWater=False
spawnLava=False
underFill=False
randomRotation=True
dig=True
tree=True
branch=False
needsFoundation=True
rarity=30
collisionPercentage=2
spawnElevationMin=0
spawnElevationMax=220
spawnInBiome=WoWForest,TallForest
[DATA]
-1,-1,0:17.0
0,-1,0:17.0
-2,0,0:17.0
-1,0,0:17.0
0,0,0:17.0
1,0,0:17.0
-2,1,0:17.0
-1,1,0:17.0
0,1,0:17.0
1,1,0:17.0
-2,2,0:17.0
-1,2,0:17.0
0,2,0:17.0
1,2,0:17.0
0,3,0:17.0
1,5,0:18
-1,-4,-2:17
-1,-3,-2:17
0,-3,-2:17
-3,-2,-2:17
-1,-2,-2:17
3,-2,-2:17
-4,-1,-2:17
-3,-1,-2:17
-2,-1,-2:17
-1,-1,-2:17.0
0,-1,-2:17.0
1,-1,-2:17
3,-1,-2:17
-3,0,-2:17
-2,0,-2:17.0
-1,0,-2:17.0
1,0,-2:17.0
2,0,-2:17
-4,1,-2:17
-3,1,-2:17
-2,1,-2:17.0
-1,1,-2:17.0
1,1,-2:17.0
2,1,-2:17
3,1,-2:17
4,1,-2:17
-3,2,-2:17
-2,2,-2:17.0
-1,2,-2:17.0
1,2,-2:17.0
-2,3,-2:17.0
0,3,-2:17.0
2,3,-2:17
3,3,-2:17
-4,4,-2:17
-3,4,-2:17
-2,4,-2:17
-1,4,-2:17.0
2,4,-2:17
-3,5,-2:17
0,5,-2:17.0
-1,6,-2:17
0,6,-2:17
1,6,-2:17
0,7,-2:17
1,-2,-1:17
-1,-1,-1:17.0
0,-1,-1:17.0
1,-1,-1:17
2,-1,-1:17
-2,0,-1:17.0
-1,0,-1:17.0
0,0,-1:17.0
1,0,-1:17.0
-3,1,-1:17
-2,1,-1:17.0
-1,1,-1:17.0
0,1,-1:17.0
1,1,-1:17.0
-2,2,-1:17.0
-1,2,-1:17.0
0,2,-1:17.0
1,2,-1:17.0
2,2,-1:17
-2,3,-1:17
-1,3,-1:17
0,3,-1:17.0
1,3,-1:17
-1,4,-1:17
0,4,-1:17
0,5,-1:17
-1,-1,1:17.0
0,-1,1:17.0
-2,0,1:17.0
-1,0,1:17.0
0,0,1:17.0
1,0,1:17.0
-2,1,1:17.0
-1,1,1:17.0
0,1,1:17.0
1,1,1:17.0
-1,2,1:17.0
0,2,1:17.0
1,2,1:18
2,2,1:18
0,3,1:18
1,3,1:18
2,3,1:18
-1,4,1:18
0,4,1:18
1,4,1:18
2,4,1:18
1,5,1:18
-1,-1,2:17.0
0,-1,2:17.0
-2,0,2:17.0
-1,0,2:17.0
0,0,2:17.0
1,0,2:17.0
-1,1,2:17.0
0,1,2:17.0
1,1,2:17.0
-1,2,2:17.0
0,2,2:17.0
1,2,2:18
2,2,2:18
0,3,2:18
1,3,2:18
2,3,2:18
0,4,2:18
1,4,2:18
2,4,2:18
-1,-1,3:17.0
0,-1,3:17.0
-1,0,3:17.0
0,0,3:17.0
1,0,3:17.0
-1,1,3:17.0
0,1,3:17.0
1,1,3:17.0
-1,2,3:17.0
0,2,3:17.0
-1,0,4:17.0
0,0,4:17.0
1,0,4:17.0
-1,1,4:17.0
0,1,4:17.0
1,1,4:17.0
0,2,4:17.0
-1,0,5:17.0
0,0,5:17.0
-1,1,5:17.0
0,1,5:17.0
-1,0,6:17.0
0,0,6:17.0
-1,1,6:17.0
0,1,6:17.0
-1,0,7:17.0
0,0,7:17.0
-1,1,7:17.0
0,1,7:17.0
1,-3,8:18
-1,0,8:17.0
0,0,8:17.0
1,0,8:17.0
-1,1,8:17.0
0,1,8:17.0
1,1,8:17.0
0,2,8:17.0
3,2,8:18
-1,4,8:18
0,-4,9:18
0,-3,9:18
1,-3,9:18
2,-3,9:18
-4,-2,9:18
-3,-2,9:18
0,-2,9:18
1,-2,9:18
2,-2,9:18
-3,-1,9:18
-2,-1,9:18
0,-1,9:18
1,-1,9:18
-5,0,9:18
-4,0,9:18
-3,0,9:18
-2,0,9:18
-1,0,9:17.0
0,0,9:17.0
1,0,9:17.0
-1,1,9:17.0
0,1,9:17.0
1,1,9:17.0
2,1,9:18
3,1,9:18
4,1,9:18
-1,2,9:18
0,2,9:17.0
1,2,9:17.0
2,2,9:18
3,2,9:18
-2,3,9:18
-1,3,9:18
0,3,9:18
3,3,9:18
4,3,9:18
-3,4,9:18
-2,4,9:18
-1,4,9:18
0,4,9:18
4,4,9:18
-1,5,9:18
0,5,9:18
-1,-5,10:18
-1,-4,10:18
-4,-3,10:18
-3,-3,10:18
-1,-3,10:18
0,-3,10:18
2,-3,10:18
3,-3,10:18
-4,-2,10:17.0
-3,-2,10:18
-2,-2,10:18
-1,-2,10:18
0,-2,10:18
1,-2,10:17.0
2,-2,10:18
-4,-1,10:18
-3,-1,10:17
-2,-1,10:18
-1,-1,10:18
0,-1,10:17.0
1,-1,10:18
2,-1,10:17.0
-4,0,10:18
-3,0,10:17.0
-2,0,10:17.0
-1,0,10:17.0
0,0,10:17.0
1,0,10:18
2,0,10:18
3,0,10:18
4,0,10:18
-5,1,10:18
-4,1,10:18
-3,1,10:18
-2,1,10:18
-1,1,10:17.0
0,1,10:17.0
1,1,10:17.0
2,1,10:18
-2,2,10:17.0
-1,2,10:18
0,2,10:18
1,2,10:18
2,2,10:18
-3,3,10:18
-2,3,10:17.0
-1,3,10:17.0
0,3,10:18
1,3,10:17
2,3,10:18
3,3,10:18
-4,4,10:18
-3,4,10:18
-2,4,10:18
0,4,10:18
1,4,10:17
2,4,10:17
3,4,10:18
4,4,10:18
0,5,10:18
1,5,10:18
1,6,10:18
-4,-4,11:18
-2,-4,11:18
-4,-3,11:18
-3,-3,11:18
-2,-3,11:18
-1,-3,11:18
3,-3,11:18
4,-3,11:18
-5,-2,11:18
-4,-2,11:17.0
-2,-2,11:18
-1,-2,11:17
0,-2,11:17.0
1,-2,11:18
2,-2,11:18
3,-2,11:18
-2,-1,11:18
-1,-1,11:17
0,-1,11:18
1,-1,11:18
2,-1,11:18
3,-1,11:18
4,-1,11:18
5,-1,11:18
-4,0,11:18
-3,0,11:17.0
-2,0,11:17.0
-1,0,11:17.0
0,0,11:17.0
1,0,11:18
2,0,11:18
3,0,11:18
-3,1,11:18
-2,1,11:18
-1,1,11:17.0
0,1,11:17.0
1,1,11:18
2,1,11:17.0
-6,2,11:18
-5,2,11:18
-4,2,11:18
-3,2,11:17
-2,2,11:18
-1,2,11:18
0,2,11:18
1,2,11:18
2,2,11:17.0
-4,3,11:18
-3,3,11:18
-2,3,11:18
-1,3,11:17.0
0,3,11:17.0
1,3,11:18
2,3,11:18
-4,4,11:18
1,4,11:18
2,4,11:18
3,4,11:18
1,5,11:18
2,5,11:18
3,5,11:18
1,6,11:18
-4,-5,12:18
-3,-5,12:18
-4,-4,12:18
-3,-4,12:18
-2,-4,12:18
-4,-3,12:18
-3,-3,12:18
-2,-3,12:18
-1,-3,12:18
0,-3,12:17.0
4,-3,12:18
-5,-2,12:18
-4,-2,12:17.0
-3,-2,12:18
-2,-2,12:18
-1,-2,12:18
0,-2,12:18
1,-2,12:18
2,-2,12:18
3,-2,12:18
4,-2,12:18
5,-2,12:18
-5,-1,12:18
-4,-1,12:18
-3,-1,12:18
-2,-1,12:18
-1,-1,12:18
0,-1,12:18
1,-1,12:18
2,-1,12:18
3,-1,12:18
4,-1,12:18
5,-1,12:18
-3,0,12:18
-2,0,12:18
-1,0,12:17.0
0,0,12:17.0
1,0,12:18
2,0,12:18
3,0,12:18
-3,1,12:18
-2,1,12:18
-1,1,12:17.0
0,1,12:17.0
1,1,12:18
2,1,12:18
3,1,12:17.0
-6,2,12:18
-5,2,12:18
-4,2,12:17
-3,2,12:18
-2,2,12:18
-1,2,12:18
0,2,12:18
1,2,12:18
2,2,12:18
3,2,12:17.0
-6,3,12:18
-5,3,12:18
-4,3,12:18
-3,3,12:18
-2,3,12:18
-1,3,12:18
0,3,12:18
1,3,12:18
2,3,12:18
-5,4,12:18
-4,4,12:18
-1,4,12:17.0
0,4,12:18
1,4,12:18
2,4,12:18
2,5,12:18
3,5,12:18
2,6,12:18
-4,-6,13:18
-3,-6,13:18
-4,-5,13:18
-3,-5,13:18
-2,-5,13:18
-4,-4,13:18
-3,-4,13:17
-2,-4,13:18
-1,-4,13:18
0,-4,13:18
-4,-3,13:18
-3,-3,13:18
-2,-3,13:17
-1,-3,13:18
0,-3,13:18
1,-3,13:18
2,-3,13:18
3,-3,13:18
4,-3,13:18
5,-3,13:18
6,-3,13:18
-4,-2,13:18
-3,-2,13:18
-2,-2,13:17
-1,-2,13:18
0,-2,13:18
1,-2,13:18
2,-2,13:18
3,-2,13:18
4,-2,13:18
5,-2,13:18
-4,-1,13:18
-3,-1,13:18
-2,-1,13:17
-1,-1,13:17
2,-1,13:18
3,-1,13:18
4,-1,13:18
-4,0,13:18
-3,0,13:18
-1,0,13:17.0
1,0,13:17
2,0,13:18
3,0,13:18
4,0,13:18
-5,1,13:18
-4,1,13:18
-3,1,13:18
-1,1,13:17.0
0,1,13:17.0
3,1,13:18
4,1,13:18
-5,2,13:18
-4,2,13:18
-3,2,13:18
-2,2,13:18
1,2,13:17.0
2,2,13:18
3,2,13:18
4,2,13:17.0
-6,3,13:18
-5,3,13:18
-4,3,13:18
-3,3,13:18
-2,3,13:18
-1,3,13:18
0,3,13:18
1,3,13:18
2,3,13:18
3,3,13:18
-7,4,13:18
-6,4,13:18
-5,4,13:18
-4,4,13:18
-3,4,13:18
-2,4,13:18
-1,4,13:18
0,4,13:18
1,4,13:18
2,4,13:18
3,4,13:18
-1,5,13:17.0
0,5,13:18
1,5,13:18
2,5,13:18
3,5,13:18
2,6,13:18
3,6,13:18
-3,-6,14:18
-2,-6,14:18
-1,-6,14:18
-5,-5,14:18
-4,-5,14:18
-2,-5,14:18
-1,-5,14:18
0,-5,14:18
3,-5,14:18
-5,-4,14:18
-4,-4,14:18
-1,-4,14:18
0,-4,14:18
1,-4,14:18
2,-4,14:18
3,-4,14:18
4,-4,14:18
5,-4,14:18
6,-4,14:18
-5,-3,14:18
-3,-3,14:18
-2,-3,14:18
-1,-3,14:18
0,-3,14:18
1,-3,14:18
2,-3,14:17
3,-3,14:18
4,-3,14:18
5,-3,14:18
6,-3,14:18
-5,-2,14:18
-4,-2,14:18
-3,-2,14:18
-2,-2,14:18
2,-2,14:17
3,-2,14:17
4,-2,14:17
5,-2,14:18
6,-2,14:18
-5,-1,14:18
-4,-1,14:18
-2,-1,14:17.0
2,-1,14:17
3,-1,14:18
4,-1,14:18
5,-1,14:18
-6,0,14:18
-5,0,14:18
-4,0,14:18
-1,0,14:17.0
2,0,14:17
3,0,14:18
4,0,14:18
5,0,14:18
-6,1,14:18
-5,1,14:18
-4,1,14:18
-1,1,14:17.0
0,1,14:17.0
3,1,14:17.0
4,1,14:18
5,1,14:18
-6,2,14:18
-5,2,14:18
-4,2,14:18
-3,2,14:18
-2,2,14:17.0
1,2,14:17.0
3,2,14:18
4,2,14:18
-7,3,14:18
-6,3,14:18
-4,3,14:17.0
-3,3,14:17
1,3,14:17.0
2,3,14:18
3,3,14:18
4,3,14:18
-7,4,14:18
-6,4,14:18
-5,4,14:18
-4,4,14:18
-3,4,14:18
-2,4,14:18
-1,4,14:18
0,4,14:18
1,4,14:18
2,4,14:17.0
3,4,14:18
4,4,14:18
-6,5,14:18
-5,5,14:18
-4,5,14:18
-3,5,14:18
-2,5,14:18
-1,5,14:17.0
0,5,14:18
1,5,14:18
2,5,14:17.0
3,5,14:18
4,5,14:18
-1,6,14:18
0,6,14:18
1,6,14:18
2,6,14:18
3,6,14:18
4,6,14:18
0,7,14:18
1,7,14:18
2,7,14:18
4,7,14:18
-4,-6,15:18
-3,-6,15:18
-2,-6,15:18
-5,-5,15:18
-4,-5,15:18
-3,-5,15:18
-2,-5,15:18
-1,-5,15:18
0,-5,15:18
1,-5,15:18
2,-5,15:18
-5,-4,15:18
-4,-4,15:18
-3,-4,15:18
-2,-4,15:18
-1,-4,15:18
0,-4,15:18
1,-4,15:18
2,-4,15:18
3,-4,15:18
4,-4,15:18
5,-4,15:18
-5,-3,15:18
-4,-3,15:18
-3,-3,15:18
-2,-3,15:18
2,-3,15:18
3,-3,15:18
5,-3,15:17.0
6,-3,15:18
-5,-2,15:18
-4,-2,15:18
-3,-2,15:17.0
-2,-2,15:18
3,-2,15:18
4,-2,15:18
6,-2,15:18
-6,-1,15:18
-5,-1,15:18
-4,-1,15:17
-3,-1,15:18
4,-1,15:18
5,-1,15:18
6,-1,15:18
-6,0,15:18
-5,0,15:18
-4,0,15:18
-1,0,15:17.0
3,0,15:17
4,0,15:18
5,0,15:18
6,0,15:18
-6,1,15:18
-5,1,15:18
-4,1,15:17
-1,1,15:17.0
0,1,15:17.0
3,1,15:17.0
4,1,15:18
5,1,15:18
-7,2,15:18
-6,2,15:18
-5,2,15:18
-4,2,15:17
-3,2,15:18
4,2,15:18
5,2,15:18
-7,3,15:18
-5,3,15:18
-4,3,15:18
2,3,15:17.0
3,3,15:18
4,3,15:18
5,3,15:18
-7,4,15:18
-6,4,15:18
-5,4,15:17
-4,4,15:17
-3,4,15:18
2,4,15:18
3,4,15:18
4,4,15:18
5,4,15:18
-6,5,15:18
-5,5,15:18
-4,5,15:18
-3,5,15:18
-2,5,15:18
-1,5,15:18
0,5,15:18
1,5,15:18
2,5,15:18
3,5,15:18
4,5,15:18
-3,6,15:18
-2,6,15:18
-1,6,15:18
0,6,15:17.0
1,6,15:18
2,6,15:17.0
3,6,15:18
4,6,15:18
0,7,15:18
1,7,15:18
2,7,15:18
-4,-6,16:18
-2,-6,16:18
-1,-6,16:18
-4,-5,16:18
-3,-5,16:18
-2,-5,16:18
-1,-5,16:18
0,-5,16:18
-5,-4,16:18
-4,-4,16:17
-3,-4,16:18
-2,-4,16:17
-1,-4,16:17
0,-4,16:18
1,-4,16:18
2,-4,16:18
3,-4,16:18
4,-4,16:18
5,-4,16:18
-5,-3,16:18
-4,-3,16:17
-3,-3,16:18
-2,-3,16:17.0
-1,-3,16:18
2,-3,16:18
3,-3,16:18
4,-3,16:18
5,-3,16:18
6,-3,16:18
-5,-2,16:18
-4,-2,16:18
4,-2,16:18
5,-2,16:18
6,-2,16:18
-5,-1,16:18
-4,-1,16:18
-1,-1,16:17
4,-1,16:18
5,-1,16:18
6,-1,16:18
-6,0,16:18
-5,0,16:18
-4,0,16:18
-1,0,16:17.0
4,0,16:17.0
5,0,16:18
6,0,16:18
-6,1,16:18
-5,1,16:18
-4,1,16:18
-3,1,16:17
-2,1,16:17
-1,1,16:17.0
3,1,16:17
4,1,16:18
5,1,16:18
-7,2,16:18
-6,2,16:18
-5,2,16:17
-4,2,16:18
-3,2,16:18
-2,2,16:18
0,2,16:17.0
3,2,16:17
4,2,16:17
5,2,16:18
-7,3,16:18
-6,3,16:18
-5,3,16:18
-3,3,16:17.0
3,3,16:18
4,3,16:18
5,3,16:18
-7,4,16:18
-6,4,16:18
-5,4,16:18
-4,4,16:18
-3,4,16:17
3,4,16:17
4,4,16:18
5,4,16:18
-5,5,16:18
-4,5,16:18
-3,5,16:18
-2,5,16:18
-1,5,16:18
1,5,16:18
2,5,16:18
3,5,16:17
4,5,16:18
-4,6,16:18
-3,6,16:18
-2,6,16:18
-1,6,16:18
0,6,16:18
1,6,16:18
2,6,16:18
3,6,16:18
4,6,16:18
0,7,16:18
1,7,16:18
2,7,16:18
-4,-5,17:18
-3,-5,17:18
-2,-5,17:18
-1,-5,17:18
0,-5,17:18
1,-5,17:18
2,-5,17:18
-5,-4,17:18
-4,-4,17:18
-3,-4,17:18
-2,-4,17:18
-1,-4,17:18
0,-4,17:17.0
1,-4,17:18
2,-4,17:18
3,-4,17:18
-5,-3,17:18
-4,-3,17:18
-3,-3,17:18
-2,-3,17:18
-1,-3,17:17
0,-3,17:17
1,-3,17:18
2,-3,17:17
3,-3,17:18
4,-3,17:18
5,-3,17:18
-5,-2,17:18
-4,-2,17:18
-1,-2,17:17
0,-2,17:17
1,-2,17:17
3,-2,17:18
4,-2,17:18
5,-2,17:18
-5,-1,17:18
-4,-1,17:18
0,-1,17:17
4,-1,17:18
5,-1,17:18
6,-1,17:18
-6,0,17:18
-5,0,17:18
-4,0,17:17
-1,0,17:17.0
0,0,17:17
1,0,17:17
4,0,17:18
5,0,17:18
6,0,17:18
-6,1,17:18
-5,1,17:18
-4,1,17:18
-1,1,17:17.0
4,1,17:18
5,1,17:18
-7,2,17:18
-6,2,17:18
-5,2,17:18
-4,2,17:18
-2,2,17:17.0
3,2,17:17.0
4,2,17:18
5,2,17:18
-6,3,17:18
-5,3,17:18
-4,3,17:18
-3,3,17:17.0
-2,3,17:18
-1,3,17:17
1,3,17:17.0
3,3,17:18
4,3,17:18
5,3,17:18
-6,4,17:18
-5,4,17:18
-4,4,17:17
-3,4,17:18
-2,4,17:18
-1,4,17:17
2,4,17:18
3,4,17:18
4,4,17:18
5,4,17:18
-4,5,17:18
-3,5,17:18
-2,5,17:18
-1,5,17:18
0,5,17:17
1,5,17:18
2,5,17:18
3,5,17:18
4,5,17:18
-4,6,17:18
-3,6,17:18
-2,6,17:18
-1,6,17:18
0,6,17:18
1,6,17:18
2,6,17:18
3,6,17:18
-1,7,17:18
0,7,17:18
-3,-5,18:18
0,-5,18:18
1,-5,18:18
2,-5,18:18
-4,-4,18:18
-3,-4,18:18
-2,-4,18:18
-1,-4,18:18
0,-4,18:18
1,-4,18:18
2,-4,18:18
-4,-3,18:18
-3,-3,18:18
-2,-3,18:18
-1,-3,18:18
0,-3,18:18
1,-3,18:18
2,-3,18:18
3,-3,18:18
4,-3,18:18
-6,-2,18:18
-5,-2,18:18
-4,-2,18:18
-3,-2,18:18
3,-2,18:18
4,-2,18:18
5,-2,18:18
-6,-1,18:18
-5,-1,18:18
-4,-1,18:17
4,-1,18:18
-6,0,18:18
-5,0,18:18
-4,0,18:18
-3,0,18:17
-2,0,18:17
-1,0,18:17.0
2,0,18:17.0
3,0,18:17
4,0,18:17
5,0,18:18
6,0,18:18
-6,1,18:18
-5,1,18:18
-4,1,18:18
-1,1,18:17.0
3,1,18:18
4,1,18:18
5,1,18:18
-5,2,18:18
-4,2,18:18
-2,2,18:17.0
0,2,18:17.0
3,2,18:17.0
4,2,18:17
5,2,18:18
-6,3,18:18
-5,3,18:18
-4,3,18:18
-3,3,18:17.0
-2,3,18:18
3,3,18:18
4,3,18:18
5,3,18:18
-5,4,18:18
-4,4,18:18
-3,4,18:18
-2,4,18:17
-1,4,18:18
2,4,18:17.0
3,4,18:18
5,4,18:18
-3,5,18:18
-2,5,18:17
-1,5,18:18
0,5,18:18
1,5,18:18
2,5,18:18
3,5,18:18
-3,6,18:18
-2,6,18:18
-1,6,18:18
0,6,18:18
1,6,18:18
2,6,18:18
3,6,18:18
-2,7,18:18
-1,7,18:18
0,-5,19:18
1,-5,19:18
-4,-4,19:18
-3,-4,19:18
-2,-4,19:18
-1,-4,19:18
-4,-3,19:18
-3,-3,19:18
-2,-3,19:18
-1,-3,19:18
0,-3,19:18
1,-3,19:18
2,-3,19:18
3,-3,19:18
4,-3,19:18
-6,-2,19:18
-5,-2,19:18
-4,-2,19:18
-3,-2,19:18
1,-2,19:18
2,-2,19:18
3,-2,19:18
4,-2,19:18
-6,-1,19:18
-5,-1,19:18
-4,-1,19:18
-3,-1,19:18
-1,-1,19:17
3,-1,19:18
4,-1,19:18
-6,0,19:18
-5,0,19:18
-4,0,19:18
-3,0,19:18
-1,0,19:17.0
2,0,19:17.0
3,0,19:18
4,0,19:18
5,0,19:18
-5,1,19:18
-4,1,19:18
-3,1,19:17
-1,1,19:17.0
3,1,19:18
4,1,19:18
5,1,19:18
-5,2,19:18
-4,2,19:18
0,2,19:17.0
2,2,19:18
3,2,19:17.0
4,2,19:18
5,2,19:18
-5,3,19:18
-4,3,19:18
-3,3,19:17.0
-2,3,19:18
2,3,19:18
3,3,19:18
4,3,19:18
5,3,19:18
-5,4,19:18
-4,4,19:18
-3,4,19:18
-2,4,19:18
-1,4,19:18
0,4,19:18
1,4,19:18
2,4,19:17.0
3,4,19:18
-3,5,19:18
0,5,19:18
1,5,19:18
2,5,19:18
3,5,19:18
0,6,19:18
-2,5,19:18.0
-1,5,19:18.0
-1,6,19:18.0
-2,6,19:18.0
-2,-4,20:18
-4,-3,20:18
-3,-3,20:18
-2,-3,20:18
-1,-3,20:18
3,-3,20:18
-3,-2,20:18
-2,-2,20:18
-1,-2,20:18
0,-2,20:18
1,-2,20:18
2,-2,20:18
3,-2,20:18
-3,-1,20:18
-1,-1,20:17.0
2,-1,20:17.0
3,-1,20:18
4,-1,20:18
-5,0,20:18
-4,0,20:18
-3,0,20:18
-1,0,20:17.0
2,0,20:18
3,0,20:18
4,0,20:18
-4,1,20:18
-3,1,20:18
2,1,20:18
3,1,20:18
5,1,20:18
-5,2,20:18
-4,2,20:18
1,2,20:17.0
2,2,20:18
3,2,20:18
4,2,20:18
5,2,20:18
-4,3,20:18
-3,3,20:18
-2,3,20:18
-1,3,20:18
0,3,20:17
1,3,20:18
2,3,20:18
-4,4,20:18
-1,4,20:18
0,4,20:18
1,4,20:18
2,4,20:17.0
3,4,20:18
1,5,20:18
2,5,20:18
-3,4,20:18.0
-2,4,20:18.0
-2,5,20:18.0
-1,5,20:18.0
-2,-4,21:18
-2,-3,21:18
2,-3,21:18
3,-3,21:18
-4,-2,21:18
-3,-2,21:18
-2,-2,21:17
-1,-2,21:18
0,-2,21:18
1,-2,21:18
2,-2,21:18
3,-2,21:18
-3,-1,21:18
-2,-1,21:17
0,-1,21:18
1,-1,21:18
2,-1,21:18
3,-1,21:18
4,-1,21:18
-3,0,21:18
-1,0,21:17.0
2,0,21:18
4,0,21:18
-3,1,21:18
2,1,21:18
-5,2,21:18
-4,2,21:18
-3,2,21:18
-2,2,21:18
-1,2,21:18
1,2,21:18
2,2,21:18
-4,3,21:18
-3,3,21:18
-2,3,21:18
-1,3,21:18
0,3,21:18
1,3,21:18
2,3,21:18
-4,4,21:18
0,4,21:18
1,4,21:18
2,4,21:18
3,4,21:18
0,5,21:18
1,5,21:18
-1,4,21:18.0
-1,-4,22:18
-1,-3,22:18
2,-3,22:18
-4,-2,22:18
-3,-2,22:18
-2,-2,22:18
-1,-2,22:18
2,-2,22:18
-2,-1,22:18
-1,-1,22:18
0,-1,22:18
1,-1,22:18
2,-1,22:18
-2,0,22:18
-1,0,22:17.0
1,0,22:18
2,0,22:18
3,0,22:18
4,0,22:18
-5,1,22:18
-4,1,22:18
-3,1,22:18
-2,1,22:17
-1,1,22:17.0
1,1,22:18
-4,2,22:18
-3,2,22:18
-2,2,22:18
-1,2,22:18
0,2,22:17.0
1,2,22:18
-3,3,22:18
-2,3,22:18
-1,3,22:18
0,3,22:18
1,3,22:17.0
2,3,22:18
3,3,22:18
-3,4,22:18
-2,4,22:18
0,4,22:18
1,4,22:18
0,5,22:18
-1,-3,23:18
-1,-2,23:18
1,-2,23:18
-3,-1,23:18
-2,-1,23:18
-1,-1,23:18
0,-1,23:18
1,-1,23:18
-2,0,23:18
-1,0,23:18
0,0,23:18
1,0,23:18
2,0,23:18
3,0,23:18
-4,1,23:18
-3,1,23:18
-2,1,23:18
-1,1,23:17
0,1,23:17
1,1,23:18
3,1,23:18
-2,2,23:18
-1,2,23:18
0,2,23:18
1,2,23:18
2,2,23:18
-2,3,23:18
0,3,23:18
1,3,23:18
2,3,23:18
0,4,23:18
-1,-2,24:18
0,-2,24:18
-2,-1,24:18
-1,-1,24:18
0,-1,24:18
1,-1,24:18
-3,0,24:18
-2,0,24:18
-1,0,24:18
0,0,24:18
1,0,24:18
-3,1,24:18
-2,1,24:18
-1,1,24:18
0,1,24:18
1,1,24:18
2,1,24:18
-2,2,24:18
-1,2,24:18
0,2,24:18
1,2,24:18
-2,3,24:18
-1,3,24:18
0,3,24:18
-1,4,24:18
-1,0,25:18
0,0,25:18
-1,1,25:18
0,1,25:18
