[META]
version=2.0
spawnOnBlockType=13
spawnSunlight=True
spawnDarkness=False
spawnWater=False
spawnLava=False
underFill=True
randomRotation=True
dig=True
tree=False
branch=False
needsFoundation=True
rarity=2
collisionPercentage=2
spawnElevationMin=0
spawnElevationMax=128
spawnInBiome=Flat
[DATA]
-6,-8,0:98.2
-5,-8,0:48
-4,-8,0:98.1
5,-8,0:98.2
-6,-7,0:98.1
-5,-7,0:98.0
-4,-7,0:98.0
5,-7,0:98.2
5,-6,0:98.0
5,-5,0:98.2
5,-4,0:98.1
5,-3,0:98.1
5,-2,0:98.1
-6,-1,0:98.0
-5,-1,0:98.1
-4,-1,0:98.2
5,-1,0:98.0
-6,0,0:98.0
-5,0,0:1
-4,0,0:98.1
4,0,0:54.4
5,0,0:98.2
-6,1,0:98.1
-5,1,0:98.1
-4,1,0:98.2
-3,1,0:98.0
-2,1,0:98.1
-1,1,0:98.0
0,1,0:98.1
1,1,0:98.1
2,1,0:98.1
3,1,0:98.1
4,1,0:98.1
5,1,0:98.2
-10,2,0:98.1
-9,2,0:98.1
-8,2,0:98.2
-7,2,0:98.2
-6,2,0:98.2
-5,2,0:98.1
-4,2,0:98.2
-3,2,0:98.2
-2,2,0:98.0
-1,2,0:98.0
0,2,0:98.2
1,2,0:98.1
2,2,0:98.2
3,2,0:98.2
4,2,0:98.2
5,2,0:98.0
-10,3,0:98.1
-9,3,0:4
-8,3,0:4
-7,3,0:1
-6,3,0:48
-5,3,0:4
-4,3,0:1
-3,3,0:1
-2,3,0:4
-1,3,0:4
0,3,0:4
1,3,0:4
2,3,0:48
3,3,0:4
4,3,0:48
5,3,0:98.2
-10,4,0:98.2
-9,4,0:4
-8,4,0:118.0
-7,4,0:43.0
-6,4,0:43.0
-5,4,0:68.5
-4,4,0:43.0
-3,4,0:35.15
-2,4,0:35.15
-1,4,0:43.0
4,4,0:4
5,4,0:98.1
-10,5,0:98.1
-9,5,0:42
-8,5,0:71.0
-6,5,0:107.3
1,5,0:98.2
2,5,0:98.0
3,5,0:98.2
4,5,0:4
5,5,0:98.0
-10,6,0:98.0
-9,6,0:5.0
-8,6,0:96.3
-6,6,0:43.0
-5,6,0:68.5
1,6,0:98.1
4,6,0:1
5,6,0:98.2
-10,7,0:98.0
-9,7,0:43.0
-8,7,0:43.0
-7,7,0:43.0
-6,7,0:43.0
-5,7,0:68.5
-4,7,0:47
-3,7,0:53.2
-2,7,0:53.2
-1,7,0:47
1,7,0:98.0
4,7,0:48
5,7,0:98.2
-10,8,0:98.0
-9,8,0:68.3
-8,8,0:68.3
-7,8,0:68.3
-6,8,0:68.3
1,8,0:98.0
2,8,0:43.0
3,8,0:43.0
4,8,0:1
5,8,0:98.1
-10,9,0:98.2
-9,9,0:18
1,9,0:98.1
4,9,0:1
5,9,0:98.2
-10,10,0:98.1
-9,10,0:1
4,10,0:4
5,10,0:98.0
-10,11,0:98.1
-9,11,0:98.2
-8,11,0:64.1
-7,11,0:98.2
-6,11,0:1
-5,11,0:4
-4,11,0:47
-3,11,0:47
-2,11,0:98.2
-1,11,0:64.1
0,11,0:98.1
1,11,0:48
2,11,0:48
3,11,0:4
4,11,0:48
5,11,0:98.0
-10,12,0:98.1
-9,12,0:98.2
-7,12,0:98.2
-6,12,0:98.0
-5,12,0:98.0
-4,12,0:98.2
-3,12,0:98.1
-2,12,0:98.0
0,12,0:98.2
1,12,0:98.2
2,12,0:98.1
3,12,0:98.2
4,12,0:98.1
5,12,0:98.2
-6,-8,1:1
-5,-8,1:4
-4,-8,1:48
5,-8,1:1
-6,-7,1:48
-5,-7,1:4
-4,-7,1:1
5,-7,1:4
5,-6,1:4
5,-5,1:48
5,-4,1:48
5,-3,1:4
5,-2,1:4
-6,-1,1:48
-5,-1,1:48
-4,-1,1:48
5,-1,1:4
-6,0,1:48
-5,0,1:48
-4,0,1:48
5,0,1:1
-6,1,1:1
-5,1,1:4
-4,1,1:48
-3,1,1:48
-2,1,1:48
-1,1,1:4
0,1,1:48
1,1,1:1
2,1,1:4
3,1,1:1
4,1,1:4
5,1,1:4
-9,3,1:98.1
-8,3,1:1
-7,3,1:1
-6,3,1:48
-5,3,1:4
-4,3,1:48
-3,3,1:48
-2,3,1:48
-1,3,1:48
0,3,1:4
1,3,1:48
2,3,1:4
3,3,1:48
4,3,1:98.2
-9,4,1:48
-8,4,1:69.3
-7,4,1:70
-6,4,1:70
-4,4,1:43.0
-3,4,1:35.15
-2,4,1:35.15
-1,4,1:43.0
4,4,1:1
-10,5,1:4
-9,5,1:42
-8,5,1:71.11
1,5,1:98.0
2,5,1:98.1
3,5,1:98.0
4,5,1:1
-10,6,1:102
-6,6,1:70
1,6,1:98.1
4,6,1:48
-10,7,1:102
-9,7,1:70
-8,7,1:70
-7,7,1:70
-6,7,1:70
1,7,1:98.0
2,7,1:43.0
3,7,1:43.0
4,7,1:4
-10,8,1:102
1,8,1:98.1
4,8,1:48
-10,9,1:4
-9,9,1:18
4,9,1:4
-9,10,1:4
4,10,1:48
-9,11,1:98.1
-8,11,1:64.11
-7,11,1:98.0
-6,11,1:4
-5,11,1:4
-4,11,1:47
-3,11,1:47
-2,11,1:98.1
-1,11,1:64.11
0,11,1:98.2
1,11,1:4
2,11,1:1
3,11,1:4
4,11,1:98.0
-6,12,1:48
-5,12,1:4
-4,12,1:48
-3,12,1:1
-2,12,1:98.1
0,12,1:98.1
1,12,1:1
2,12,1:1
3,12,1:48
4,12,1:4
5,12,1:48
-6,-8,2:1
-5,-8,2:4
-4,-8,2:4
5,-8,2:48
-6,-7,2:4
-5,-7,2:48
-4,-7,2:4
5,-7,2:48
-5,-6,2:5.1
5,-6,2:1
-5,-5,2:5.1
5,-5,2:48
-5,-4,2:5.1
5,-4,2:48
-5,-3,2:5.1
5,-3,2:1
-5,-2,2:5.1
5,-2,2:48
-6,-1,2:48
-5,-1,2:4
-4,-1,2:48
5,-1,2:1
-6,0,2:1
-5,0,2:4
-4,0,2:1
5,0,2:1
-6,1,2:4
-5,1,2:48
-4,1,2:48
-3,1,2:48
-2,1,2:4
-1,1,2:1
0,1,2:4
1,1,2:1
2,1,2:4
3,1,2:4
4,1,2:48
5,1,2:48
-9,3,2:98.2
-8,3,2:1
-7,3,2:1
-6,3,2:1
-5,3,2:4
-4,3,2:1
-3,3,2:48
-2,3,2:48
-1,3,2:48
0,3,2:1
1,3,2:48
2,3,2:48
3,3,2:48
4,3,2:98.0
-9,4,2:48
-5,4,2:76.3
-4,4,2:44.5
-3,4,2:44.5
-2,4,2:44.5
-1,4,2:44.5
0,4,2:76.3
4,4,2:1
-10,5,2:4
1,5,2:98.2
2,5,2:98.1
3,5,2:98.1
4,5,2:48
-10,6,2:102
1,6,2:98.1
2,6,2:43.0
3,6,2:43.0
4,6,2:1
-10,7,2:102
1,7,2:98.2
4,7,2:1
-10,8,2:102
4,8,2:48
-10,9,2:4
-9,9,2:18
4,9,2:48
-9,10,2:48
-6,10,2:76.4
3,10,2:76.2
4,10,2:48
-9,11,2:98.2
-8,11,2:98.0
-7,11,2:98.2
-6,11,2:1
-5,11,2:4
-4,11,2:47
-3,11,2:47
-2,11,2:98.0
-1,11,2:98.1
0,11,2:98.2
1,11,2:4
2,11,2:48
3,11,2:1
4,11,2:98.2
-6,12,2:48
-5,12,2:4
-4,12,2:1
-3,12,2:1
-2,12,2:98.2
-1,12,2:98.2
0,12,2:98.1
1,12,2:48
2,12,2:1
3,12,2:48
4,12,2:48
5,12,2:4
-6,-8,3:1
-5,-8,3:4
-4,-8,3:4
5,-8,3:48
-6,-7,3:48
-5,-7,3:48
-4,-7,3:48
5,-7,3:4
-6,-6,3:4
-5,-6,3:5.1
-4,-6,3:48
5,-6,3:48
-6,-5,3:4
-5,-5,3:5.1
-4,-5,3:1
5,-5,3:4
-6,-4,3:4
-5,-4,3:5.1
-4,-4,3:4
5,-4,3:48
-6,-3,3:4
-5,-3,3:5.1
-4,-3,3:48
5,-3,3:4
-6,-2,3:48
-5,-2,3:5.1
-4,-2,3:48
5,-2,3:48
-6,-1,3:1
-5,-1,3:1
-4,-1,3:1
5,-1,3:48
-6,0,3:1
-5,0,3:1
-4,0,3:4
5,0,3:4
-6,1,3:48
-5,1,3:1
-4,1,3:4
-3,1,3:1
-2,1,3:4
-1,1,3:1
0,1,3:48
1,1,3:1
2,1,3:4
3,1,3:48
4,1,3:4
5,1,3:4
-9,3,3:98.0
-8,3,3:48
-7,3,3:48
-6,3,3:4
-5,3,3:1
-4,3,3:1
-3,3,3:1
-2,3,3:1
-1,3,3:48
0,3,3:48
1,3,3:4
2,3,3:4
3,3,3:1
4,3,3:98.2
-9,4,3:48
4,4,3:48
-10,5,3:4
1,5,3:98.0
2,5,3:43.0
3,5,3:43.0
4,5,3:1
-10,6,3:102
1,6,3:98.1
4,6,3:48
-10,7,3:102
4,7,3:48
-10,8,3:102
4,8,3:48
-10,9,3:4
-9,9,3:18
4,9,3:4
-9,10,3:48
4,10,3:48
-9,11,3:98.1
-8,11,3:4
-7,11,3:1
-6,11,3:1
-5,11,3:4
-4,11,3:4
-3,11,3:1
-2,11,3:1
-1,11,3:1
0,11,3:4
1,11,3:4
2,11,3:4
3,11,3:1
4,11,3:98.2
-6,12,3:1
-5,12,3:48
-4,12,3:48
-3,12,3:4
-2,12,3:4
-1,12,3:4
0,12,3:48
1,12,3:1
2,12,3:4
3,12,3:1
4,12,3:48
5,12,3:4
-6,-8,4:98.1
-5,-8,4:98.2
-4,-8,4:98.1
-3,-8,4:98.1
-2,-8,4:98.1
-1,-8,4:98.1
0,-8,4:98.1
1,-8,4:98.1
2,-8,4:98.1
3,-8,4:98.2
4,-8,4:98.0
5,-8,4:98.0
-6,-7,4:98.1
-5,-7,4:98.1
-4,-7,4:98.2
-3,-7,4:98.1
-2,-7,4:98.0
-1,-7,4:98.2
0,-7,4:98.1
1,-7,4:98.2
2,-7,4:98.2
3,-7,4:98.1
4,-7,4:98.0
5,-7,4:98.2
-6,-6,4:98.0
-5,-6,4:98.1
-4,-6,4:98.1
-3,-6,4:98.0
-2,-6,4:98.2
-1,-6,4:98.2
0,-6,4:98.2
1,-6,4:98.0
2,-6,4:98.0
3,-6,4:98.0
4,-6,4:98.0
5,-6,4:98.0
-6,-5,4:98.2
-5,-5,4:98.2
-4,-5,4:98.1
-3,-5,4:98.0
-2,-5,4:98.2
-1,-5,4:98.2
0,-5,4:98.2
1,-5,4:98.0
2,-5,4:98.2
3,-5,4:98.2
4,-5,4:98.0
5,-5,4:98.2
-6,-4,4:98.1
-5,-4,4:98.1
-4,-4,4:98.0
-3,-4,4:98.1
-2,-4,4:98.2
-1,-4,4:98.1
0,-4,4:98.1
1,-4,4:98.2
2,-4,4:98.0
3,-4,4:98.0
4,-4,4:98.0
5,-4,4:98.0
-6,-3,4:98.2
-5,-3,4:98.1
-4,-3,4:98.0
-3,-3,4:98.1
-2,-3,4:98.0
-1,-3,4:98.0
0,-3,4:98.0
1,-3,4:98.0
2,-3,4:98.2
3,-3,4:98.1
4,-3,4:98.1
5,-3,4:98.1
-6,-2,4:98.2
-5,-2,4:98.0
-4,-2,4:98.0
-3,-2,4:98.0
-2,-2,4:98.0
-1,-2,4:98.0
0,-2,4:98.2
1,-2,4:98.1
2,-2,4:98.2
3,-2,4:98.2
4,-2,4:98.0
5,-2,4:98.2
-6,-1,4:98.1
-5,-1,4:98.2
-4,-1,4:98.2
-3,-1,4:98.1
-2,-1,4:98.1
-1,-1,4:98.2
0,-1,4:98.0
1,-1,4:98.0
2,-1,4:98.0
3,-1,4:98.0
4,-1,4:98.2
5,-1,4:98.1
-6,0,4:98.1
-5,0,4:98.0
-4,0,4:98.0
-3,0,4:98.1
-2,0,4:98.1
-1,0,4:98.1
0,0,4:98.0
1,0,4:98.1
2,0,4:98.0
3,0,4:98.1
4,0,4:98.0
5,0,4:98.2
-6,1,4:98.0
-5,1,4:98.1
-4,1,4:98.2
-3,1,4:98.0
-2,1,4:98.1
-1,1,4:98.0
0,1,4:98.0
1,1,4:98.1
2,1,4:98.1
3,1,4:98.2
4,1,4:98.2
5,1,4:98.0
-9,3,4:98.0
-8,3,4:48
-7,3,4:48
-6,3,4:1
-5,3,4:48
-4,3,4:1
-3,3,4:4
-2,3,4:48
-1,3,4:4
0,3,4:4
1,3,4:4
2,3,4:4
3,3,4:1
4,3,4:98.1
-9,4,4:48
-8,4,4:5.1
-7,4,4:5.1
-6,4,4:5.1
-5,4,4:5.1
-4,4,4:5.1
-3,4,4:5.1
-2,4,4:5.1
-1,4,4:5.1
0,4,4:5.1
1,4,4:5.1
2,4,4:5.1
3,4,4:5.1
4,4,4:1
-10,5,4:4
-9,5,4:4
-8,5,4:5.1
-7,5,4:5.1
-6,5,4:5.1
-5,5,4:5.1
-4,5,4:5.1
-3,5,4:5.1
-2,5,4:5.1
-1,5,4:5.1
0,5,4:5.1
1,5,4:5.1
4,5,4:48
-10,6,4:4
-9,6,4:5.1
-8,6,4:5.1
-7,6,4:5.1
-6,6,4:5.1
-5,6,4:5.1
-4,6,4:5.1
-3,6,4:5.1
-2,6,4:5.1
-1,6,4:5.1
0,6,4:5.1
1,6,4:5.1
4,6,4:1
-10,7,4:4
-9,7,4:5.1
-8,7,4:5.1
-7,7,4:5.1
-6,7,4:5.1
-5,7,4:5.1
-4,7,4:5.1
-3,7,4:5.1
-2,7,4:5.1
-1,7,4:5.1
0,7,4:5.1
1,7,4:5.1
4,7,4:1
-10,8,4:4
-9,8,4:5.1
-8,8,4:5.1
-7,8,4:5.1
-6,8,4:5.1
-5,8,4:5.1
-4,8,4:5.1
-3,8,4:5.1
-2,8,4:5.1
-1,8,4:5.1
0,8,4:5.1
1,8,4:5.1
2,8,4:5.1
3,8,4:5.1
4,8,4:1
-10,9,4:4
-9,9,4:48
-8,9,4:5.1
-7,9,4:5.1
-6,9,4:5.1
-5,9,4:5.1
-4,9,4:5.1
-3,9,4:5.1
-2,9,4:5.1
-1,9,4:5.1
0,9,4:5.1
1,9,4:5.1
2,9,4:5.1
3,9,4:5.1
4,9,4:4
-9,10,4:1
-8,10,4:5.1
-7,10,4:5.1
-6,10,4:5.1
-5,10,4:5.1
-4,10,4:5.1
-3,10,4:5.1
-2,10,4:5.1
-1,10,4:5.1
0,10,4:5.1
1,10,4:5.1
2,10,4:5.1
3,10,4:5.1
4,10,4:1
-9,11,4:98.1
-8,11,4:4
-7,11,4:48
-6,11,4:4
-5,11,4:48
-4,11,4:1
-3,11,4:1
-2,11,4:4
-1,11,4:1
0,11,4:1
1,11,4:48
2,11,4:48
3,11,4:4
4,11,4:98.2
-6,12,4:98.1
-5,12,4:98.2
-4,12,4:98.1
-3,12,4:98.1
-2,12,4:98.1
-1,12,4:98.2
0,12,4:98.1
1,12,4:98.0
2,12,4:98.2
3,12,4:98.1
4,12,4:98.0
5,12,4:98.0
5,-8,5:1
-10,2,5:108.2
-9,2,5:108.2
-8,2,5:108.2
-7,2,5:108.2
-6,2,5:108.2
-5,2,5:108.2
-4,2,5:108.2
-3,2,5:108.2
-2,2,5:108.2
-1,2,5:108.2
0,2,5:108.2
1,2,5:108.2
2,2,5:108.2
3,2,5:108.2
4,2,5:108.2
5,2,5:108.2
-9,3,5:98.1
-8,3,5:4
-7,3,5:4
-6,3,5:1
-5,3,5:48
-4,3,5:4
-3,3,5:4
-2,3,5:48
-1,3,5:48
0,3,5:48
1,3,5:48
2,3,5:1
3,3,5:48
4,3,5:98.2
-9,4,5:48
4,4,5:1
-10,5,5:4
-9,5,5:1
4,5,5:4
-10,6,5:102
-7,6,5:44.0
-6,6,5:44.0
-5,6,5:44.0
4,6,5:48
-10,7,5:102
-8,7,5:44.0
-5,7,5:44.0
4,7,5:1
-10,8,5:102
-7,8,5:44.0
-6,8,5:44.0
-5,8,5:44.0
4,8,5:1
-10,9,5:4
-9,9,5:48
4,9,5:4
-9,10,5:48
4,10,5:4
-9,11,5:98.2
-8,11,5:48
-7,11,5:48
-6,11,5:1
-5,11,5:48
-4,11,5:1
-3,11,5:4
-2,11,5:48
-1,11,5:48
0,11,5:4
1,11,5:1
2,11,5:1
3,11,5:4
4,11,5:98.1
-10,12,5:108.3
-9,12,5:108.3
-8,12,5:108.3
-7,12,5:108.3
-6,12,5:108.3
-5,12,5:108.3
-4,12,5:108.3
-3,12,5:108.3
-2,12,5:108.3
-1,12,5:108.3
0,12,5:108.3
1,12,5:108.3
2,12,5:108.3
3,12,5:108.3
4,12,5:108.3
5,12,5:108.3
5,-8,6:1
-10,3,6:108.2
-9,3,6:108.2
-8,3,6:108.2
-7,3,6:108.2
-6,3,6:108.2
-5,3,6:108.2
-4,3,6:108.2
-3,3,6:108.2
-2,3,6:108.2
-1,3,6:108.2
0,3,6:108.2
1,3,6:108.2
2,3,6:108.2
3,3,6:108.2
4,3,6:108.2
5,3,6:108.2
-9,4,6:98.2
-8,4,6:98.0
-7,4,6:98.1
-6,4,6:98.0
-5,4,6:98.0
-4,4,6:98.1
-3,4,6:98.2
-2,4,6:98.0
-1,4,6:98.1
0,4,6:98.0
1,4,6:98.0
2,4,6:98.0
3,4,6:98.1
4,4,6:98.0
-10,5,6:4
-9,5,6:98.0
4,5,6:98.1
-10,6,6:102
4,6,6:98.2
-10,7,6:102
4,7,6:98.2
-10,8,6:102
4,8,6:98.2
-10,9,6:4
-9,9,6:98.2
4,9,6:98.2
-9,10,6:98.0
-8,10,6:98.2
-7,10,6:98.2
-6,10,6:98.1
-5,10,6:98.1
-4,10,6:98.2
-3,10,6:98.1
-2,10,6:98.0
-1,10,6:98.0
0,10,6:98.2
1,10,6:98.0
2,10,6:98.0
3,10,6:98.1
4,10,6:98.2
-10,11,6:108.3
-9,11,6:108.3
-8,11,6:108.3
-7,11,6:108.3
-6,11,6:108.3
-5,11,6:108.3
-4,11,6:108.3
-3,11,6:108.3
-2,11,6:108.3
-1,11,6:108.3
0,11,6:108.3
1,11,6:108.3
2,11,6:108.3
3,11,6:108.3
4,11,6:108.3
5,11,6:108.3
5,-8,7:1
-10,4,7:108.2
-9,4,7:108.2
-8,4,7:108.2
-7,4,7:108.2
-6,4,7:108.2
-5,4,7:108.2
-4,4,7:108.2
-3,4,7:108.2
-2,4,7:108.2
-1,4,7:108.2
0,4,7:108.2
1,4,7:108.2
2,4,7:108.2
3,4,7:108.2
4,4,7:108.2
5,4,7:108.2
-9,5,7:98.1
-8,5,7:98.2
-7,5,7:98.2
-6,5,7:98.1
-5,5,7:98.1
-4,5,7:98.2
-3,5,7:98.0
-2,5,7:98.0
-1,5,7:98.2
0,5,7:98.2
1,5,7:98.1
2,5,7:98.0
3,5,7:98.2
4,5,7:98.0
-10,6,7:4
-9,6,7:98.2
4,6,7:98.1
-10,7,7:4
-9,7,7:98.2
4,7,7:98.0
-10,8,7:4
-9,8,7:98.2
4,8,7:98.0
-9,9,7:98.2
-8,9,7:98.2
-7,9,7:98.1
-6,9,7:98.0
-5,9,7:98.0
-4,9,7:98.1
-3,9,7:98.0
-2,9,7:98.2
-1,9,7:98.0
0,9,7:98.2
1,9,7:98.1
2,9,7:98.0
3,9,7:98.1
4,9,7:98.2
-10,10,7:108.3
-9,10,7:108.3
-8,10,7:108.3
-7,10,7:108.3
-6,10,7:108.3
-5,10,7:108.3
-4,10,7:108.3
-3,10,7:108.3
-2,10,7:108.3
-1,10,7:108.3
0,10,7:108.3
1,10,7:108.3
2,10,7:108.3
3,10,7:108.3
4,10,7:108.3
5,10,7:108.3
5,-8,8:1
-10,5,8:108.2
-9,5,8:108.2
-8,5,8:108.2
-7,5,8:108.2
-6,5,8:108.2
-5,5,8:108.2
-4,5,8:108.2
-3,5,8:108.2
-2,5,8:108.2
-1,5,8:108.2
0,5,8:108.2
1,5,8:108.2
2,5,8:108.2
3,5,8:108.2
4,5,8:108.2
5,5,8:108.2
-9,6,8:98.0
-8,6,8:98.0
-7,6,8:98.0
-6,6,8:98.0
-5,6,8:98.0
-4,6,8:98.1
-3,6,8:98.0
-2,6,8:98.0
-1,6,8:98.2
0,6,8:98.0
1,6,8:98.1
2,6,8:98.2
3,6,8:98.0
4,6,8:98.2
-9,7,8:98.1
-8,7,8:76.1
3,7,8:76.2
4,7,8:98.2
-9,8,8:98.2
-8,8,8:98.0
-7,8,8:98.0
-6,8,8:98.1
-5,8,8:98.1
-4,8,8:98.2
-3,8,8:98.2
-2,8,8:98.1
-1,8,8:98.2
0,8,8:98.2
1,8,8:98.1
2,8,8:98.0
3,8,8:98.2
4,8,8:98.2
-10,9,8:108.3
-9,9,8:108.3
-8,9,8:108.3
-7,9,8:108.3
-6,9,8:108.3
-5,9,8:108.3
-4,9,8:108.3
-3,9,8:108.3
-2,9,8:108.3
-1,9,8:108.3
0,9,8:108.3
1,9,8:108.3
2,9,8:108.3
3,9,8:108.3
4,9,8:108.3
5,9,8:108.3
5,-8,9:1
-10,6,9:108.2
-9,6,9:108.2
-8,6,9:108.2
-7,6,9:108.2
-6,6,9:108.2
-5,6,9:108.2
-4,6,9:108.2
-3,6,9:108.2
-2,6,9:108.2
-1,6,9:108.2
0,6,9:108.2
1,6,9:108.2
2,6,9:108.2
3,6,9:108.2
4,6,9:108.2
5,6,9:108.2
-9,7,9:98.1
-8,7,9:98.0
-7,7,9:98.2
-6,7,9:98.0
-5,7,9:98.2
-4,7,9:98.0
-3,7,9:98.1
-2,7,9:98.1
-1,7,9:98.0
0,7,9:98.0
1,7,9:98.0
2,7,9:98.1
3,7,9:98.2
4,7,9:98.1
-10,8,9:108.3
-9,8,9:108.3
-8,8,9:108.3
-7,8,9:108.3
-6,8,9:108.3
-5,8,9:108.3
-4,8,9:108.3
-3,8,9:108.3
-2,8,9:108.3
-1,8,9:108.3
0,8,9:108.3
1,8,9:108.3
2,8,9:108.3
3,8,9:108.3
4,8,9:108.3
5,8,9:108.3
5,-8,10:1
-10,7,10:44.4
-9,7,10:44.4
-8,7,10:44.4
-7,7,10:44.4
-6,7,10:44.4
-5,7,10:44.4
-4,7,10:44.4
-3,7,10:44.4
-2,7,10:44.4
-1,7,10:44.4
0,7,10:44.4
1,7,10:44.4
2,7,10:44.4
3,7,10:44.4
4,7,10:44.4
5,7,10:44.4
