[META]
version=2.0
spawnOnBlockType=8,9,79
spawnSunlight=True
spawnDarkness=True
spawnWater=True
spawnLava=False
underFill=False
randomRotation=True
dig=True
tree=False
branch=False
needsFoundation=True
rarity=200
collisionPercentage=50
spawnElevationMin=40
spawnElevationMax=100
spawnInBiome=FrozenOcean
[DATA]
2,-5,0:79
1,-5,0:79
0,-5,0:79
-1,-5,0:79
-2,-5,0:79
-3,-5,0:79
-3,-4,0:79
-4,-4,0:79
-5,-4,0:79
-5,-3,0:79
-6,-3,0:79
-7,-3,0:79
-7,-2,0:79
-8,-2,0:79
-8,-1,0:79
-8,0,0:79
-8,1,0:79
-8,2,0:79
-8,3,0:79
-7,3,0:79
-7,4,0:79
-7,5,0:79
-7,6,0:79
-6,6,0:79
-6,7,0:79
-5,7,0:79
-5,8,0:79
-4,8,0:79
-4,9,0:79
-3,9,0:79
-3,10,0:79
-2,10,0:79
-1,10,0:79
0,10,0:79
1,9,0:79
2,9,0:79
3,8,0:79
4,8,0:79
4,7,0:79
5,7,0:79
6,7,0:79
6,6,0:79
7,6,0:79
8,6,0:79
8,5,0:79
9,5,0:79
9,4,0:79
9,3,0:79
10,3,0:79
10,2,0:79
11,2,0:79
11,1,0:79
11,0,0:79
12,0,0:79
12,-1,0:79
12,-2,0:79
13,-2,0:79
12,-3,0:79
12,-4,0:79
11,-4,0:79
11,-5,0:79
10,-5,0:79
10,-6,0:79
9,-6,0:79
8,-6,0:79
8,-7,0:79
7,-7,0:79
6,-7,0:79
5,-7,0:79
4,-7,0:79
3,-7,0:79
2,-7,0:79
1,-7,0:79
0,-7,0:79
-1,-7,0:79
-2,-7,0:79
-3,-7,0:79
-3,-6,0:79
-4,-6,0:79
-4,-5,0:79
-6,-2,0:79
-6,-4,0:79
-5,-5,0:79
-2,-6,0:79
1,-8,0:79
2,-8,0:79
3,-8,0:79
4,-8,0:79
7,-6,0:79
8,-5,0:79
8,-4,0:79
8,-3,0:79
8,-2,0:79
7,-2,0:79
7,-1,0:79
7,0,0:79
7,1,0:79
7,2,0:79
6,3,0:79
6,4,0:79
5,4,0:79
5,5,0:79
4,5,0:79
4,6,0:79
7,4,0:79
7,3,0:79
8,2,0:79
9,1,0:79
9,0,0:79
10,0,0:79
10,-1,0:79
10,-2,0:79
11,-2,0:79
11,-3,0:79
10,-3,0:79
8,1,0:79
8,0,0:79
9,-1,0:79
9,-2,0:79
9,-3,0:79
10,-4,0:79
8,-1,0:79
9,-4,0:79
9,-5,0:79
6,1,0:79
6,2,0:79
5,3,0:79
4,4,0:79
3,6,0:79
3,7,0:79
2,7,0:79
2,8,0:79
1,8,0:79
0,9,0:79
-1,9,0:79
-1,8,0:79
-1,7,0:79
0,7,0:79
0,6,0:79
-2,7,0:79
-2,8,0:79
-3,8,0:79
-2,6,0:79
-1,6,0:79
-1,5,0:79
0,4,0:79
0,3,0:79
1,3,0:79
1,2,0:79
2,2,0:79
2,1,0:79
2,0,0:79
1,0,0:79
1,1,0:79
0,1,0:79
-1,1,0:79
-2,2,0:79
-3,2,0:79
-3,1,0:79
-2,1,0:79
-2,0,0:79
-1,-1,0:79
0,-2,0:79
1,-3,0:79
1,-4,0:79
2,-4,0:79
2,-6,0:79
3,-6,0:79
1,-6,0:79
-2,-4,0:79
-1,-8,0:79
0,-8,0:79
1,-9,0:79
2,-9,0:79
5,-8,0:79
4,-6,0:79
3,-5,0:79
3,-4,0:79
2,-3,0:79
1,-2,0:79
3,-3,0:79
4,-4,0:79
5,-5,0:79
5,-4,0:79
4,-3,0:79
3,-2,0:79
3,-1,0:79
2,-1,0:79
4,-1,0:79
4,-2,0:79
5,-2,0:79
5,-3,0:79
6,-3,0:79
6,-4,0:79
4,0,0:79
3,1,0:79
2,3,0:79
3,2,0:79
4,2,0:79
4,1,0:79
5,1,0:79
5,0,0:79
3,3,0:79
3,4,0:79
2,4,0:79
2,5,0:79
1,5,0:79
1,6,0:79
-3,6,0:79
-4,6,0:79
-4,5,0:79
-3,4,0:79
-3,3,0:79
-4,2,0:79
-4,3,0:79
-5,3,0:79
-5,4,0:79
-6,4,0:79
-6,3,0:79
-5,2,0:79
-5,1,0:79
-5,0,0:79
-5,-1,0:79
-6,0,0:79
-6,1,0:79
-7,1,0:79
-7,2,0:79
-6,-1,0:79
-7,0,0:79
-5,-2,0:79
-3,-3,0:79
-4,-3,0:79
-4,-2,0:79
-1,-6,0:79
0,-6,0:79
-1,-4,0:79
-2,-3,0:79
-3,-2,0:79
-4,-1,0:79
-4,0,0:79
-4,1,0:79
-3,0,0:79
-3,-1,0:79
-2,-1,0:79
-2,-2,0:79
-1,-3,0:79
0,-3,0:79
-1,0,0:79
0,-1,0:79
1,-1,0:79
4,-5,0:79
5,-6,0:79
6,-6,0:79
6,-5,0:79
7,-4,0:79
3,5,0:79
2,6,0:79
-2,9,0:79
-1,4,0:79
-1,3,0:79
-2,4,0:79
-3,5,0:79
-2,3,0:79
-1,2,0:79
0,0,0:79
2,-2,0:79
7,-5,0:79
-1,-3,-1:79
-2,-3,-1:79
-3,-2,-1:79
-4,-1,-1:79
-4,0,-1:79
-4,1,-1:79
-4,2,-1:79
-4,3,-1:79
-3,3,-1:79
-2,3,-1:79
-2,4,-1:79
-1,4,-1:79
-1,5,-1:79
-1,6,-1:79
0,5,-1:79
1,5,-1:79
2,5,-1:79
2,4,-1:79
3,4,-1:79
4,4,-1:79
4,3,-1:79
5,3,-1:79
5,2,-1:79
5,1,-1:79
6,1,-1:79
6,0,-1:79
6,-1,-1:79
7,-1,-1:79
7,-2,-1:79
7,-3,-1:79
6,-3,-1:79
6,-4,-1:79
5,-4,-1:79
5,-5,-1:79
4,-5,-1:79
4,-6,-1:79
3,-6,-1:79
3,-5,-1:79
2,-5,-1:79
1,-5,-1:79
1,-4,-1:79
0,-4,-1:79
0,-3,-1:79
-1,-2,-1:79
-2,-2,-1:79
-2,-1,-1:79
-3,-1,-1:79
-3,0,-1:79
-1,-1,-1:79
0,-2,-1:79
1,-3,-1:79
2,-3,-1:79
3,-3,-1:79
4,-3,-1:79
5,-3,-1:79
5,-2,-1:79
5,-1,-1:79
4,-1,-1:79
4,0,-1:79
3,1,-1:79
2,1,-1:79
2,2,-1:79
1,2,-1:79
1,3,-1:79
0,3,-1:79
-1,3,-1:79
-1,2,-1:79
0,1,-1:79
0,0,-1:79
1,0,-1:79
2,-1,-1:79
2,-2,-1:79
3,-2,-1:79
4,-4,-1:79
3,-4,-1:79
2,-4,-1:79
1,-2,-1:79
0,-1,-1:79
-1,0,-1:79
-1,1,-1:79
-2,1,-1:79
-3,1,-1:79
-2,0,-1:79
-2,2,-1:79
1,1,-1:79
2,0,-1:79
3,-1,-1:79
4,-2,-1:79
3,2,-1:79
3,3,-1:79
2,3,-1:79
7,0,-1:79
5,0,-1:79
6,-2,-1:79
4,1,-1:79
4,2,-1:79
1,4,-1:79
0,4,-1:79
1,-1,-1:79
3,0,-1:79
-3,2,-1:79
-2,5,-1:79
-2,6,-1:79
-3,6,-1:79
-3,5,-1:79
-3,4,-1:79
-4,4,-1:79
-5,2,-1:79
-5,1,-1:79
-5,0,-1:79
-5,-1,-1:79
-4,-2,-1:79
-3,-3,-1:79
-2,-4,-1:79
-1,-5,-1:79
0,-5,-1:79
6,2,-1:79
6,3,-1:79
5,4,-1:79
4,5,-1:79
3,5,-1:79
2,6,-1:79
1,6,-1:79
0,6,-1:79
0,2,-1:79
-3,-3,-2:79
-4,-3,-2:79
-4,-2,-2:79
-4,-1,-2:79
-4,0,-2:79
-3,1,-2:79
-3,2,-2:79
-3,3,-2:79
-2,3,-2:79
-2,4,-2:79
-1,4,-2:79
0,4,-2:79
1,4,-2:79
2,4,-2:79
3,4,-2:79
4,4,-2:79
5,4,-2:79
5,3,-2:79
6,3,-2:79
6,2,-2:79
7,2,-2:79
7,1,-2:79
7,0,-2:79
6,0,-2:79
6,-1,-2:79
6,-2,-2:79
6,-3,-2:79
6,-4,-2:79
5,-5,-2:79
4,-5,-2:79
3,-5,-2:79
3,-6,-2:79
2,-6,-2:79
1,-6,-2:79
1,-5,-2:79
0,-5,-2:79
0,-4,-2:79
-1,-4,-2:79
-2,-4,-2:79
-2,-3,-2:79
-3,-2,-2:79
-3,-1,-2:79
-2,-1,-2:79
-1,-1,-2:79
0,-1,-2:79
1,-1,-2:79
2,-1,-2:79
3,-1,-2:79
4,-1,-2:79
4,0,-2:79
4,1,-2:79
3,1,-2:79
2,2,-2:79
1,2,-2:79
0,3,-2:79
-1,3,-2:79
-2,5,-2:79
-3,5,-2:79
-3,6,-2:79
-2,6,-2:79
-2,7,-2:79
-1,7,-2:79
0,7,-2:79
0,6,-2:79
1,6,-2:79
1,5,-2:79
2,5,-2:79
4,3,-2:79
4,2,-2:79
5,1,-2:79
5,0,-2:79
5,-1,-2:79
5,-2,-2:79
4,-2,-2:79
4,-3,-2:79
4,-4,-2:79
2,-5,-2:79
-1,-5,-2:79
-5,0,-2:79
-5,1,-2:79
-6,2,-2:79
-6,1,-2:79
-1,-2,-2:79
0,-2,-2:79
1,-3,-2:79
2,-3,-2:79
3,-3,-2:79
5,-3,-2:79
6,1,-2:79
3,2,-2:79
2,3,-2:79
1,3,-2:79
-1,2,-2:79
-1,1,-2:79
0,1,-2:79
1,0,-2:79
2,0,-2:79
3,-2,-2:79
2,-4,-2:79
1,-4,-2:79
0,-3,-2:79
-1,0,-2:79
-2,2,-2:79
-4,3,-2:79
-4,2,-2:79
-4,1,-2:79
-5,2,-2:79
-5,3,-2:79
-5,4,-2:79
-4,4,-2:79
-4,5,-2:79
-1,5,-2:79
0,5,-2:79
0,0,-2:79
2,-2,-2:79
1,-2,-2:79
-2,0,-2:79
-2,1,-2:79
0,2,-2:79
2,1,-2:79
3,0,-2:79
5,2,-2:79
3,3,-2:79
3,5,-2:79
2,6,-2:79
4,5,-2:79
6,4,-2:79
7,3,-2:79
7,-1,-2:79
5,-4,-2:79
-4,-4,-3:79
-5,-4,-3:79
-6,-3,-3:79
-6,-2,-3:79
-7,-2,-3:79
-6,-1,-3:79
-5,-1,-3:79
-5,0,-3:79
-5,1,-3:79
-5,2,-3:79
-5,3,-3:79
-5,4,-3:79
-4,4,-3:79
-4,5,-3:79
-3,5,-3:79
-2,5,-3:79
-2,6,-3:79
-1,6,-3:79
0,6,-3:79
1,6,-3:79
2,6,-3:79
3,6,-3:79
4,6,-3:79
5,6,-3:79
5,5,-3:79
6,5,-3:79
7,5,-3:79
7,4,-3:79
8,4,-3:79
8,3,-3:79
8,2,-3:79
8,1,-3:79
8,0,-3:79
8,-1,-3:79
8,-2,-3:79
8,-3,-3:79
8,-4,-3:79
8,-5,-3:79
7,-5,-3:79
6,-6,-3:79
5,-6,-3:79
5,-7,-3:79
4,-7,-3:79
3,-7,-3:79
2,-7,-3:79
1,-7,-3:79
0,-7,-3:79
0,-6,-3:79
-1,-6,-3:79
-2,-5,-3:79
-3,-4,-3:79
-3,-3,-3:79
-3,-2,-3:79
-3,-1,-3:79
-3,0,-3:79
-4,0,-3:79
-4,1,-3:79
-4,2,-3:79
-3,1,-3:79
-2,0,-3:79
-1,0,-3:79
-1,-1,-3:79
0,-1,-3:79
0,-2,-3:79
1,-2,-3:79
1,-3,-3:79
2,-3,-3:79
2,-4,-3:79
3,-4,-3:79
3,-5,-3:79
4,-5,-3:79
5,-5,-3:79
6,-5,-3:79
6,-4,-3:79
6,-3,-3:79
6,-2,-3:79
6,-1,-3:79
6,0,-3:79
6,1,-3:79
5,1,-3:79
5,2,-3:79
4,2,-3:79
4,3,-3:79
3,3,-3:79
3,4,-3:79
2,4,-3:79
1,4,-3:79
0,4,-3:79
0,5,-3:79
-1,5,-3:79
-3,6,-3:79
-3,7,-3:79
-3,8,-3:79
-2,8,-3:79
-1,8,-3:79
-1,7,-3:79
0,7,-3:79
1,7,-3:79
-4,6,-3:79
-5,5,-3:79
-6,2,-3:79
-6,1,-3:79
-7,1,-3:79
-6,0,-3:79
-4,-1,-3:79
-2,-2,-3:79
-1,-3,-3:79
0,-3,-3:79
1,-4,-3:79
5,-4,-3:79
5,-2,-3:79
4,-2,-3:79
4,-1,-3:79
3,-1,-3:79
3,0,-3:79
2,1,-3:79
2,2,-3:79
1,2,-3:79
1,3,-3:79
-2,4,-3:79
-2,3,-3:79
-3,3,-3:79
-3,2,-3:79
-2,2,-3:79
-2,1,-3:79
-1,1,-3:79
0,0,-3:79
1,0,-3:79
2,-1,-3:79
5,-3,-3:79
4,-4,-3:79
2,-5,-3:79
1,-5,-3:79
0,-4,-3:79
-1,-4,-3:79
-2,-3,-3:79
-4,-2,-3:79
-5,-2,-3:79
-5,-3,-3:79
-4,-3,-3:79
-3,-5,-3:79
-2,-6,-3:79
1,-6,-3:79
2,-6,-3:79
6,2,-3:79
6,3,-3:79
6,4,-3:79
4,5,-3:79
5,4,-3:79
7,3,-3:79
9,2,-3:79
9,1,-3:79
9,0,-3:79
10,0,-3:79
9,-1,-3:79
7,-1,-3:79
5,-1,-3:79
4,0,-3:79
4,1,-3:79
5,3,-3:79
4,4,-3:79
2,5,-3:79
1,5,-3:79
3,5,-3:79
0,3,-3:79
0,2,-3:79
1,1,-3:79
3,1,-3:79
-1,3,-3:79
-1,4,-3:79
2,0,-3:79
7,-4,-3:79
7,-3,-3:79
7,0,-3:79
7,1,-3:79
7,2,-3:79
3,2,-3:79
0,1,-3:79
-3,-5,-4:79
-4,-5,-4:79
-4,-4,-4:79
-5,-4,-4:79
-6,-4,-4:79
-6,-3,-4:79
-7,-3,-4:79
-7,-2,-4:79
-7,-1,-4:79
-8,-1,-4:79
-8,0,-4:79
-8,1,-4:79
-8,2,-4:79
-8,3,-4:79
-7,3,-4:79
-7,4,-4:79
-6,4,-4:79
-5,4,-4:79
-5,5,-4:79
-4,5,-4:79
-4,6,-4:79
-3,6,-4:79
-3,7,-4:79
-2,7,-4:79
-2,8,-4:79
-1,8,-4:79
0,8,-4:79
1,8,-4:79
2,8,-4:79
2,7,-4:79
3,7,-4:79
4,7,-4:79
4,6,-4:79
5,6,-4:79
5,5,-4:79
6,5,-4:79
6,4,-4:79
7,4,-4:79
7,3,-4:79
8,3,-4:79
8,2,-4:79
7,2,-4:79
7,1,-4:79
7,0,-4:79
7,-1,-4:79
7,-2,-4:79
7,-3,-4:79
6,-4,-4:79
5,-4,-4:79
4,-4,-4:79
4,-5,-4:79
3,-5,-4:79
2,-5,-4:79
2,-6,-4:79
1,-6,-4:79
0,-6,-4:79
-1,-6,-4:79
-2,-5,-4:79
-3,-4,-4:79
-1,-5,-4:79
2,-7,-4:79
3,-7,-4:79
4,-7,-4:79
5,-6,-4:79
6,-6,-4:79
6,-5,-4:79
7,-5,-4:79
7,-4,-4:79
8,-1,-4:79
8,0,-4:79
8,1,-4:79
8,4,-4:79
8,5,-4:79
7,5,-4:79
6,6,-4:79
3,6,-4:79
2,6,-4:79
1,6,-4:79
1,7,-4:79
0,7,-4:79
-1,7,-4:79
-1,6,-4:79
-2,6,-4:79
-2,5,-4:79
-2,4,-4:79
-2,3,-4:79
-1,3,-4:79
-1,2,-4:79
0,2,-4:79
0,1,-4:79
1,1,-4:79
2,0,-4:79
2,-1,-4:79
3,-1,-4:79
3,-2,-4:79
3,-3,-4:79
3,-4,-4:79
2,-4,-4:79
2,-3,-4:79
1,-3,-4:79
0,-3,-4:79
0,-2,-4:79
-1,-2,-4:79
-1,-1,-4:79
-2,-1,-4:79
-2,0,-4:79
-3,0,-4:79
-4,1,-4:79
-5,1,-4:79
-5,0,-4:79
-5,-1,-4:79
-4,-1,-4:79
-4,-2,-4:79
-3,-2,-4:79
-3,-3,-4:79
-2,-3,-4:79
-2,-4,-4:79
-1,-4,-4:79
0,-4,-4:79
0,-5,-4:79
1,-5,-4:79
-6,1,-4:79
-6,0,-4:79
-6,-1,-4:79
-5,-2,-4:79
-4,-3,-4:79
-5,-3,-4:79
-6,-2,-4:79
-7,0,-4:79
-7,1,-4:79
-6,2,-4:79
-6,3,-4:79
-5,3,-4:79
-4,3,-4:79
-4,4,-4:79
-3,4,-4:79
-1,4,-4:79
0,4,-4:79
1,4,-4:79
1,5,-4:79
2,5,-4:79
3,4,-4:79
3,3,-4:79
4,3,-4:79
4,2,-4:79
4,1,-4:79
5,0,-4:79
5,-1,-4:79
5,-2,-4:79
6,-2,-4:79
6,-1,-4:79
6,0,-4:79
6,1,-4:79
5,1,-4:79
5,2,-4:79
5,3,-4:79
6,2,-4:79
8,-2,-4:79
8,-3,-4:79
8,-4,-4:79
9,-3,-4:79
9,-2,-4:79
9,-1,-4:79
9,0,-4:79
9,1,-4:79
9,2,-4:79
9,3,-4:79
9,4,-4:79
7,6,-4:79
5,7,-4:79
4,8,-4:79
3,8,-4:79
-3,5,-4:79
2,1,-4:79
3,0,-4:79
4,-1,-4:79
4,-2,-4:79
3,1,-4:79
3,2,-4:79
2,2,-4:79
2,3,-4:79
2,4,-4:79
0,5,-4:79
-1,5,-4:79
-3,3,-4:79
-3,2,-4:79
-2,2,-4:79
-2,1,-4:79
-1,1,-4:79
-1,0,-4:79
-1,-6,-5:79
-2,-6,-5:79
-3,-6,-5:79
-4,-6,-5:79
-5,-6,-5:79
-5,-5,-5:79
-6,-5,-5:79
-6,-4,-5:79
-7,-4,-5:79
-8,-4,-5:79
-8,-3,-5:79
-9,-3,-5:79
-9,-2,-5:79
-10,-2,-5:79
-10,-1,-5:79
-10,0,-5:79
-10,1,-5:79
-9,1,-5:79
-8,2,-5:79
-8,3,-5:79
-8,1,-5:79
-8,0,-5:79
-9,0,-5:79
-9,-1,-5:79
-8,-1,-5:79
-8,-2,-5:79
-7,-2,-5:79
-6,-2,-5:79
-6,-3,-5:79
-5,-3,-5:79
-4,-3,-5:79
-4,-4,-5:79
-3,-4,-5:79
-3,-5,-5:79
-2,-5,-5:79
-1,-5,-5:79
0,-5,-5:79
1,-5,-5:79
2,-5,-5:79
2,-6,-5:79
2,-7,-5:79
3,-7,-5:79
3,-8,-5:79
4,-8,-5:79
5,-8,-5:79
5,-7,-5:79
6,-7,-5:79
6,-6,-5:79
6,-5,-5:79
5,-5,-5:79
5,-6,-5:79
4,-6,-5:79
4,-5,-5:79
3,-5,-5:79
3,-6,-5:79
4,-7,-5:79
0,-6,-5:79
1,-6,-5:79
2,-4,-5:79
1,-4,-5:79
1,-3,-5:79
1,-2,-5:79
1,-1,-5:79
0,-1,-5:79
0,0,-5:79
0,1,-5:79
0,2,-5:79
0,3,-5:79
0,4,-5:79
-1,5,-5:79
-1,6,-5:79
-1,7,-5:79
0,8,-5:79
0,9,-5:79
1,9,-5:79
1,10,-5:79
2,10,-5:79
3,10,-5:79
4,10,-5:79
5,9,-5:79
6,9,-5:79
6,8,-5:79
7,8,-5:79
7,7,-5:79
7,6,-5:79
7,5,-5:79
8,5,-5:79
8,4,-5:79
9,4,-5:79
9,3,-5:79
10,3,-5:79
11,3,-5:79
11,2,-5:79
12,2,-5:79
12,1,-5:79
11,1,-5:79
11,0,-5:79
10,0,-5:79
10,-1,-5:79
11,-1,-5:79
11,-2,-5:79
11,-3,-5:79
10,-4,-5:79
9,-4,-5:79
8,-4,-5:79
8,-5,-5:79
7,-5,-5:79
9,-3,-5:79
9,-2,-5:79
9,-1,-5:79
10,1,-5:79
9,2,-5:79
10,2,-5:79
11,4,-5:79
11,5,-5:79
11,6,-5:79
12,6,-5:79
10,6,-5:79
9,6,-5:79
8,6,-5:79
8,7,-5:79
9,5,-5:79
10,5,-5:79
10,4,-5:79
8,3,-5:79
7,3,-5:79
6,3,-5:79
5,4,-5:79
4,4,-5:79
4,5,-5:79
3,5,-5:79
2,5,-5:79
1,5,-5:79
1,4,-5:79
2,4,-5:79
2,3,-5:79
3,3,-5:79
3,2,-5:79
4,2,-5:79
4,1,-5:79
5,1,-5:79
5,0,-5:79
5,-1,-5:79
6,-1,-5:79
6,-2,-5:79
6,-3,-5:79
7,-3,-5:79
5,-3,-5:79
5,-2,-5:79
4,-2,-5:79
4,-1,-5:79
3,-1,-5:79
2,-1,-5:79
2,0,-5:79
3,-2,-5:79
4,-3,-5:79
5,-4,-5:79
6,-4,-5:79
3,-3,-5:79
4,-4,-5:79
3,-4,-5:79
2,-3,-5:79
0,-2,-5:79
-1,-1,-5:79
-1,0,-5:79
-2,1,-5:79
-3,1,-5:79
-3,2,-5:79
-4,2,-5:79
-4,1,-5:79
-5,1,-5:79
-6,1,-5:79
-7,1,-5:79
-7,2,-5:79
-8,4,-5:79
-7,4,-5:79
-7,5,-5:79
-7,6,-5:79
-6,6,-5:79
-5,6,-5:79
-5,7,-5:79
-4,7,-5:79
-4,8,-5:79
-3,8,-5:79
-2,8,-5:79
-1,8,-5:79
-1,9,-5:79
-1,10,-5:79
-2,10,-5:79
-3,10,-5:79
-4,10,-5:79
-4,9,-5:79
-5,9,-5:79
-5,8,-5:79
-6,8,-5:79
-6,7,-5:79
-7,7,-5:79
-8,6,-5:79
-8,5,-5:79
-9,5,-5:79
-9,4,-5:79
-9,3,-5:79
-6,0,-5:79
-5,0,-5:79
-4,-1,-5:79
-3,-2,-5:79
-2,-2,-5:79
-2,-3,-5:79
-1,-3,-5:79
0,-4,-5:79
0,-3,-5:79
-1,-2,-5:79
-2,-1,-5:79
-3,0,-5:79
-5,2,-5:79
-4,0,-5:79
-3,-1,-5:79
2,-2,-5:79
2,1,-5:79
2,2,-5:79
1,2,-5:79
-1,3,-5:79
-1,4,-5:79
-2,4,-5:79
-3,4,-5:79
-4,4,-5:79
-3,5,-5:79
-4,5,-5:79
-5,5,-5:79
-5,4,-5:79
-5,3,-5:79
-4,3,-5:79
-6,4,-5:79
-6,3,-5:79
-6,2,-5:79
-2,0,-5:79
-4,6,-5:79
-3,6,-5:79
-2,5,-5:79
0,5,-5:79
3,4,-5:79
1,6,-5:79
0,7,-5:79
1,7,-5:79
2,7,-5:79
3,6,-5:79
4,6,-5:79
3,7,-5:79
2,8,-5:79
4,7,-5:79
5,7,-5:79
5,6,-5:79
4,8,-5:79
3,8,-5:79
2,9,-5:79
3,9,-5:79
5,8,-5:79
6,7,-5:79
6,6,-5:79
6,5,-5:79
7,4,-5:79
8,2,-5:79
8,1,-5:79
8,0,-5:79
7,0,-5:79
6,0,-5:79
6,1,-5:79
7,-1,-5:79
7,-2,-5:79
8,-2,-5:79
8,-3,-5:79
10,-3,-5:79
10,-2,-5:79
7,-4,-5:79
3,1,-5:79
4,0,-5:79
3,0,-5:79
1,1,-5:79
-1,2,-5:79
-2,3,-5:79
-3,3,-5:79
-3,-3,-5:79
-5,-4,-5:79
-7,-1,-5:79
-7,0,-5:79
-9,2,-5:79
-7,3,-5:79
-3,7,-5:79
-2,7,-5:79
-3,9,-5:79
-2,9,-5:79
1,3,-5:79
5,2,-5:79
-4,-4,-6:79
-5,-4,-6:79
-5,-3,-6:79
-6,-3,-6:79
-6,-2,-6:79
-6,-1,-6:79
-7,-1,-6:79
-7,0,-6:79
-7,1,-6:79
-7,2,-6:79
-7,3,-6:79
-6,3,-6:79
-6,4,-6:79
-6,5,-6:79
-5,5,-6:79
-5,6,-6:79
-4,6,-6:79
-4,7,-6:79
-3,7,-6:79
-2,7,-6:79
-2,8,-6:79
-1,8,-6:79
0,8,-6:79
1,8,-6:79
2,8,-6:79
3,8,-6:79
4,8,-6:79
5,8,-6:79
5,7,-6:79
6,7,-6:79
7,7,-6:79
7,6,-6:79
8,5,-6:79
8,4,-6:79
9,3,-6:79
9,2,-6:79
9,1,-6:79
9,0,-6:79
9,-1,-6:79
8,-1,-6:79
8,-2,-6:79
7,-2,-6:79
7,-3,-6:79
6,-3,-6:79
6,-4,-6:79
5,-4,-6:79
4,-4,-6:79
3,-4,-6:79
3,-5,-6:79
2,-5,-6:79
1,-5,-6:79
0,-5,-6:79
-1,-5,-6:79
-2,-5,-6:79
-2,-4,-6:79
-3,-4,-6:79
-3,-3,-6:79
-4,-3,-6:79
-1,-4,-6:79
0,-4,-6:79
2,-4,-6:79
1,-3,-6:79
0,-3,-6:79
0,-2,-6:79
1,-2,-6:79
2,-2,-6:79
3,-2,-6:79
3,-1,-6:79
2,-1,-6:79
1,-1,-6:79
0,-1,-6:79
0,0,-6:79
1,0,-6:79
2,0,-6:79
3,0,-6:79
4,0,-6:79
5,0,-6:79
6,0,-6:79
5,1,-6:79
4,1,-6:79
3,1,-6:79
2,1,-6:79
2,2,-6:79
1,2,-6:79
2,3,-6:79
3,3,-6:79
4,3,-6:79
5,3,-6:79
5,4,-6:79
4,4,-6:79
3,4,-6:79
2,4,-6:79
1,4,-6:79
1,5,-6:79
2,5,-6:79
3,5,-6:79
3,6,-6:79
2,6,-6:79
1,6,-6:79
0,6,-6:79
0,7,-6:79
1,7,-6:79
-1,7,-6:79
-3,6,-6:79
-4,5,-6:79
-4,4,-6:79
-5,4,-6:79
-5,3,-6:79
-5,2,-6:79
-5,1,-6:79
-5,0,-6:79
-4,0,-6:79
-4,-1,-6:79
-4,-2,-6:79
-3,-2,-6:79
-5,-1,-6:79
-6,0,-6:79
-6,1,-6:79
-6,2,-6:79
-5,-2,-6:79
-2,-3,-6:79
-2,-2,-6:79
-2,-1,-6:79
-2,0,-6:79
-2,1,-6:79
-3,1,-6:79
-3,2,-6:79
-3,3,-6:79
-3,4,-6:79
-3,5,-6:79
-2,5,-6:79
-2,4,-6:79
-2,3,-6:79
-1,3,-6:79
-1,2,-6:79
-1,1,-6:79
-1,0,-6:79
-1,-1,-6:79
-1,4,-6:79
-1,5,-6:79
0,4,-6:79
0,3,-6:79
1,3,-6:79
1,1,-6:79
0,5,-6:79
0,2,-6:79
0,1,-6:79
-1,6,-6:79
-2,6,-6:79
-4,3,-6:79
-4,2,-6:79
-3,0,-6:79
-1,-2,-6:79
-1,-3,-6:79
-4,1,-6:79
-3,-1,-6:79
-2,2,-6:79
1,-4,-6:79
5,-3,-6:79
6,-2,-6:79
7,-1,-6:79
7,0,-6:79
8,0,-6:79
8,1,-6:79
7,1,-6:79
5,-1,-6:79
4,-1,-6:79
2,-3,-6:79
3,-3,-6:79
4,-3,-6:79
5,-2,-6:79
6,-1,-6:79
4,-2,-6:79
7,2,-6:79
7,3,-6:79
7,4,-6:79
6,4,-6:79
6,5,-6:79
5,5,-6:79
5,6,-6:79
5,2,-6:79
6,2,-6:79
6,1,-6:79
4,2,-6:79
3,2,-6:79
8,2,-6:79
8,3,-6:79
4,7,-6:79
3,7,-6:79
2,7,-6:79
4,6,-6:79
4,5,-6:79
6,3,-6:79
7,5,-6:79
6,6,-6:79
-3,-3,-7:79
-3,-2,-7:79
-4,-2,-7:79
-3,-1,-7:79
-3,0,-7:79
-2,0,-7:79
-2,1,-7:79
-1,1,-7:79
-1,2,-7:79
-2,2,-7:79
-2,3,-7:79
-3,3,-7:79
-2,4,-7:79
-3,4,-7:79
-4,4,-7:79
-4,3,-7:79
-4,2,-7:79
-3,1,-7:79
-4,0,-7:79
-4,1,-7:79
-1,4,-7:79
0,4,-7:79
0,5,-7:79
1,5,-7:79
1,6,-7:79
2,6,-7:79
2,5,-7:79
3,5,-7:79
3,4,-7:79
4,4,-7:79
4,3,-7:79
4,2,-7:79
5,2,-7:79
5,1,-7:79
5,0,-7:79
4,0,-7:79
4,-1,-7:79
3,-1,-7:79
3,-2,-7:79
2,-2,-7:79
2,-3,-7:79
1,-3,-7:79
0,-3,-7:79
-1,-3,-7:79
-1,-4,-7:79
-2,-3,-7:79
-2,-2,-7:79
-2,-1,-7:79
-1,-1,-7:79
0,-1,-7:79
1,-1,-7:79
2,-1,-7:79
4,1,-7:79
3,1,-7:79
3,2,-7:79
2,3,-7:79
2,4,-7:79
1,4,-7:79
1,3,-7:79
2,2,-7:79
3,0,-7:79
0,-2,-7:79
1,-2,-7:79
-1,0,-7:79
0,2,-7:79
1,2,-7:79
0,3,-7:79
1,1,-7:79
0,1,-7:79
0,0,-7:79
1,0,-7:79
2,0,-7:79
2,1,-7:79
3,3,-7:79
-1,3,-7:79
-3,2,-7:79
-1,-2,-7:79
0,-2,-8:79
-1,-2,-8:79
-1,-1,-8:79
-2,-1,-8:79
-2,0,-8:79
-3,0,-8:79
-3,1,-8:79
-3,2,-8:79
-2,2,-8:79
-1,2,-8:79
-1,3,-8:79
0,3,-8:79
1,3,-8:79
1,2,-8:79
2,2,-8:79
2,1,-8:79
2,0,-8:79
2,-1,-8:79
1,-2,-8:79
0,-1,-8:79
1,-1,-8:79
1,0,-8:79
1,1,-8:79
0,1,-8:79
-1,1,-8:79
-2,1,-8:79
-1,0,-8:79
0,0,-8:79
0,2,-8:79
0,-2,-9:79
0,-1,-9:79
-1,-1,-9:79
-1,0,-9:79
-1,1,-9:79
0,1,-9:79
1,1,-9:79
1,0,-9:79
1,-1,-9:79
0,0,-9:79
-5,-4,1:79
-5,-3,1:79
-6,-3,1:79
-6,-2,1:79
-6,-1,1:79
-7,-1,1:79
-7,0,1:79
-7,1,1:79
-7,2,1:79
-7,3,1:79
-6,4,1:79
-6,5,1:79
-5,5,1:79
-5,6,1:79
-5,7,1:79
-4,7,1:79
-4,8,1:79
-3,8,1:79
-2,8,1:79
-2,9,1:79
-1,9,1:79
0,9,1:79
0,8,1:79
1,8,1:79
2,8,1:79
2,7,1:79
3,7,1:79
3,6,1:79
4,6,1:79
5,6,1:79
5,5,1:79
6,5,1:79
6,4,1:79
7,4,1:79
7,3,1:79
8,3,1:79
8,2,1:79
9,2,1:79
10,1,1:79
11,1,1:79
11,0,1:79
11,-1,1:79
11,-2,1:79
10,-2,1:79
9,-3,1:79
9,-4,1:79
8,-4,1:79
8,-5,1:79
7,-5,1:79
6,-5,1:79
6,-6,1:79
5,-6,1:79
4,-6,1:79
3,-6,1:79
3,-7,1:79
2,-7,1:79
1,-7,1:79
0,-7,1:79
0,-6,1:79
-1,-6,1:79
-2,-6,1:79
-2,-5,1:79
-3,-5,1:79
-4,-4,1:79
-4,-3,1:79
-3,-3,1:79
-2,-3,1:79
-1,-3,1:79
0,-3,1:79
1,-3,1:79
2,-3,1:79
3,-3,1:79
4,-3,1:79
4,-2,1:79
5,-2,1:79
5,-1,1:79
5,0,1:79
5,1,1:79
5,2,1:79
5,3,1:79
6,3,1:79
7,5,1:79
8,4,1:79
8,1,1:79
8,0,1:79
8,-1,1:79
7,-1,1:79
7,-2,1:79
6,-2,1:79
5,-3,1:79
1,-4,1:79
0,-4,1:79
0,-5,1:79
1,-5,1:79
1,-6,1:79
2,-6,1:79
-1,-5,1:79
-1,-4,1:79
-2,-4,1:79
-3,-4,1:79
-5,-2,1:79
-5,-1,1:79
-5,0,1:79
-6,0,1:79
-6,1,1:79
-6,2,1:79
-6,3,1:79
-5,4,1:79
-4,4,1:79
-4,5,1:79
-3,5,1:79
-2,5,1:79
-2,6,1:79
-1,6,1:79
0,6,1:79
0,5,1:79
1,5,1:79
2,5,1:79
2,4,1:79
3,4,1:79
4,3,1:79
4,4,1:79
3,5,1:79
2,6,1:79
1,6,1:79
0,7,1:79
-1,7,1:79
-2,7,1:79
-3,7,1:79
-3,6,1:79
-4,6,1:79
-4,3,1:79
-4,2,1:79
-4,1,1:79
-4,0,1:79
-3,-1,1:79
-2,-2,1:79
-1,-2,1:79
2,-2,1:79
2,-1,1:79
2,0,1:79
1,1,1:79
0,1,1:79
0,2,1:79
-1,2,1:79
-2,2,1:79
-3,2,1:79
-4,-1,1:79
-3,-2,1:79
2,-5,1:79
3,-5,1:79
4,-5,1:79
4,-4,1:79
5,-4,1:79
6,-4,1:79
6,-3,1:79
7,-3,1:79
8,-3,1:79
8,-2,1:79
9,-2,1:79
9,-1,1:79
9,0,1:79
10,0,1:79
10,-1,1:79
7,1,1:79
6,2,1:79
4,2,1:79
3,3,1:79
3,2,1:79
4,1,1:79
4,0,1:79
3,0,1:79
1,0,1:79
-1,3,1:79
-2,3,1:79
-2,4,1:79
-3,4,1:79
-3,3,1:79
-3,1,1:79
-2,0,1:79
-2,-1,1:79
-1,-1,1:79
0,-1,1:79
0,-2,1:79
1,-2,1:79
1,-1,1:79
0,0,1:79
-1,1,1:79
-5,3,1:79
-5,1,1:79
-3,0,1:79
2,3,1:79
1,4,1:79
0,4,1:79
-1,5,1:79
-1,4,1:79
1,3,1:79
2,2,1:79
3,1,1:79
4,-1,1:79
6,0,1:79
6,-1,1:79
-2,-3,2:79
-3,-3,2:79
-4,-3,2:79
-4,-2,2:79
-5,-2,2:79
-5,-1,2:79
-5,0,2:79
-5,1,2:79
-5,2,2:79
-5,3,2:79
-5,4,2:79
-5,5,2:79
-4,5,2:79
-4,6,2:79
-3,6,2:79
-3,7,2:79
-2,7,2:79
-2,8,2:79
-1,8,2:79
0,8,2:79
1,8,2:79
1,7,2:79
2,7,2:79
2,6,2:79
3,6,2:79
3,5,2:79
4,5,2:79
5,5,2:79
5,4,2:79
6,4,2:79
6,3,2:79
7,3,2:79
7,2,2:79
8,2,2:79
8,1,2:79
9,1,2:79
9,0,2:79
10,0,2:79
10,-1,2:79
9,-1,2:79
9,-2,2:79
8,-2,2:79
8,-3,2:79
7,-3,2:79
7,-4,2:79
6,-4,2:79
5,-5,2:79
4,-5,2:79
4,-6,2:79
3,-6,2:79
2,-6,2:79
1,-6,2:79
0,-6,2:79
0,-5,2:79
-1,-5,2:79
-2,-5,2:79
-2,-4,2:79
-3,-4,2:79
-3,-2,2:79
-4,-1,2:79
-6,0,2:79
-6,1,2:79
-6,2,2:79
-4,2,2:79
-4,1,2:79
-3,1,2:79
-2,1,2:79
-2,0,2:79
-1,0,2:79
0,0,2:79
0,-1,2:79
1,-1,2:79
2,-1,2:79
2,-2,2:79
3,-2,2:79
4,-2,2:79
5,-2,2:79
5,-1,2:79
4,0,2:79
3,0,2:79
3,1,2:79
2,1,2:79
2,2,2:79
1,2,2:79
1,3,2:79
0,3,2:79
-1,4,2:79
-2,4,2:79
-2,5,2:79
-3,5,2:79
-4,7,2:79
-5,7,2:79
-6,8,2:79
-6,7,2:79
-5,6,2:79
-4,4,2:79
-4,3,2:79
-3,3,2:79
-3,2,2:79
-1,-1,2:79
0,-2,2:79
1,-3,2:79
1,-4,2:79
2,-4,2:79
0,-3,2:79
-1,-2,2:79
-2,-2,2:79
-2,-1,2:79
-3,-1,2:79
-1,-3,2:79
-1,-4,2:79
0,-4,2:79
1,-5,2:79
2,-5,2:79
3,-5,2:79
3,-4,2:79
2,-3,2:79
1,0,2:79
0,1,2:79
-1,2,2:79
-2,3,2:79
-3,4,2:79
-1,3,2:79
0,4,2:79
-1,5,2:79
-2,6,2:79
-1,6,2:79
0,5,2:79
1,5,2:79
1,4,2:79
2,4,2:79
2,5,2:79
1,6,2:79
0,6,2:79
0,7,2:79
-1,7,2:79
3,4,2:79
3,3,2:79
4,3,2:79
4,2,2:79
5,2,2:79
5,1,2:79
6,1,2:79
6,0,2:79
7,-1,2:79
7,-2,2:79
7,0,2:79
6,-1,2:79
5,0,2:79
4,1,2:79
4,-1,2:79
6,-2,2:79
6,-3,2:79
7,-5,2:79
5,-4,2:79
5,-3,2:79
4,-3,2:79
3,-3,2:79
4,-4,2:79
-1,1,2:79
-2,2,2:79
-3,0,2:79
2,0,2:79
3,2,2:79
2,3,2:79
4,4,2:79
5,3,2:79
6,2,2:79
7,1,2:79
8,0,2:79
8,-1,2:79
1,1,2:79
-6,4,2:79
-6,3,2:79
-7,3,2:79
-7,4,2:79
-7,5,2:79
-6,5,2:79
-4,0,3:79
-5,0,3:79
-5,1,3:79
-6,2,3:79
-6,3,3:79
-6,4,3:79
-5,5,3:79
-4,5,3:79
-3,6,3:79
-2,6,3:79
-1,6,3:79
-1,5,3:79
0,5,3:79
1,5,3:79
2,5,3:79
3,4,3:79
4,4,3:79
4,3,3:79
5,3,3:79
5,2,3:79
6,2,3:79
7,2,3:79
7,1,3:79
7,0,3:79
7,-1,3:79
7,-2,3:79
6,-3,3:79
5,-3,3:79
5,-4,3:79
4,-4,3:79
3,-4,3:79
2,-4,3:79
2,-5,3:79
1,-5,3:79
1,-4,3:79
0,-4,3:79
-1,-4,3:79
-1,-3,3:79
-2,-3,3:79
-3,-2,3:79
-4,-2,3:79
-4,-1,3:79
-4,1,3:79
-3,0,3:79
-3,-1,3:79
-2,-1,3:79
-2,-2,3:79
-1,-2,3:79
0,-3,3:79
1,-3,3:79
3,-3,3:79
4,-3,3:79
4,-2,3:79
5,-2,3:79
5,-1,3:79
4,-1,3:79
4,0,3:79
4,1,3:79
3,1,3:79
3,2,3:79
2,2,3:79
1,3,3:79
0,3,3:79
0,4,3:79
-1,4,3:79
-2,4,3:79
-2,5,3:79
-3,5,3:79
-4,6,3:79
-4,4,3:79
-5,4,3:79
-5,3,3:79
-5,2,3:79
-4,2,3:79
-3,1,3:79
-2,0,3:79
-1,0,3:79
-1,-1,3:79
0,-1,3:79
1,-1,3:79
2,-2,3:79
3,-2,3:79
2,-1,3:79
1,0,3:79
0,0,3:79
-1,1,3:79
-2,2,3:79
-3,2,3:79
-3,3,3:79
-4,3,3:79
-2,1,3:79
0,-2,3:79
1,-2,3:79
3,-1,3:79
5,0,3:79
6,0,3:79
6,-1,3:79
6,1,3:79
5,1,3:79
4,2,3:79
3,3,3:79
2,3,3:79
2,4,3:79
1,4,3:79
-3,4,3:79
-2,3,3:79
-1,3,3:79
0,2,3:79
1,2,3:79
1,1,3:79
2,1,3:79
3,0,3:79
2,0,3:79
0,1,3:79
-1,2,3:79
2,-3,3:79
0,-3,4:79
0,-2,4:79
-1,-2,4:79
-2,-2,4:79
-2,-1,4:79
-3,-1,4:79
-3,0,4:79
-4,0,4:79
-5,0,4:79
-5,1,4:79
-5,2,4:79
-5,3,4:79
-4,3,4:79
-4,4,4:79
-3,4,4:79
-3,5,4:79
-2,5,4:79
-1,5,4:79
0,5,4:79
1,5,4:79
2,5,4:79
2,4,4:79
3,4,4:79
4,4,4:79
4,3,4:79
5,3,4:79
5,2,4:79
6,1,4:79
6,0,4:79
6,-1,4:79
6,-2,4:79
6,-3,4:79
5,-3,4:79
4,-4,4:79
3,-4,4:79
2,-4,4:79
1,-4,4:79
1,-3,4:79
1,-2,4:79
2,-2,4:79
3,-2,4:79
4,-2,4:79
5,-2,4:79
4,-1,4:79
3,-1,4:79
3,0,4:79
2,0,4:79
1,0,4:79
1,1,4:79
0,1,4:79
-1,1,4:79
-1,2,4:79
-2,2,4:79
-2,1,4:79
-1,0,4:79
0,0,4:79
1,-1,4:79
-3,2,4:79
-3,1,4:79
-2,0,4:79
-4,1,4:79
-4,2,4:79
-1,-1,4:79
0,-1,4:79
-2,3,4:79
-2,4,4:79
-1,4,4:79
0,3,4:79
1,3,4:79
2,3,4:79
3,3,4:79
1,4,4:79
4,2,4:79
4,1,4:79
5,1,4:79
5,0,4:79
3,2,4:79
2,2,4:79
1,2,4:79
2,1,4:79
0,2,4:79
-1,3,4:79
4,-3,4:79
3,-3,4:79
2,-3,4:79
-1,-3,4:79
-2,-3,4:79
-2,-4,4:79
-1,-4,4:79
0,-4,4:79
-3,-2,4:79
-4,-1,4:79
5,-1,4:79
4,0,4:79
3,1,4:79
-3,3,4:79
2,-5,4:79
3,-5,4:79
4,-5,4:79
5,-4,4:79
0,-2,5:79
-1,-2,5:79
-1,-1,5:79
-2,-1,5:79
-2,0,5:79
-3,0,5:79
-3,1,5:79
-4,1,5:79
-4,2,5:79
-5,2,5:79
-5,3,5:79
-4,3,5:79
-3,3,5:79
-3,4,5:79
-2,4,5:79
-1,4,5:79
0,4,5:79
1,4,5:79
2,4,5:79
2,3,5:79
3,3,5:79
3,2,5:79
3,1,5:79
4,1,5:79
4,0,5:79
5,0,5:79
5,-1,5:79
5,-2,5:79
5,-3,5:79
4,-3,5:79
4,-4,5:79
3,-4,5:79
2,-4,5:79
1,-4,5:79
1,-3,5:79
0,-3,5:79
1,-2,5:79
2,-2,5:79
2,-3,5:79
3,-3,5:79
4,-2,5:79
4,-1,5:79
3,-1,5:79
2,-1,5:79
2,0,5:79
1,0,5:79
0,1,5:79
-1,1,5:79
-2,1,5:79
-2,2,5:79
-3,2,5:79
-1,0,5:79
0,0,5:79
0,-1,5:79
1,-1,5:79
1,1,5:79
0,2,5:79
-1,3,5:79
0,3,5:79
1,3,5:79
2,2,5:79
-2,5,5:79
-1,5,5:79
0,5,5:79
2,1,5:79
3,0,5:79
-1,2,5:79
-2,3,5:79
-1,0,6:79
-2,0,6:79
-3,0,6:79
-3,1,6:79
-4,1,6:79
-4,2,6:79
-4,3,6:79
-3,3,6:79
-3,4,6:79
-2,4,6:79
-1,4,6:79
-1,3,6:79
-1,2,6:79
0,2,6:79
0,1,6:79
-1,1,6:79
-2,1,6:79
-3,2,6:79
0,0,6:79
0,3,6:79
-2,3,6:79
-2,2,6:79
3,0,6:79
3,-1,6:79
3,-2,6:79
4,-2,6:79
5,-2,6:79
5,-1,6:79
4,-1,6:79
4,0,6:79
5,0,6:79
0,-3,6:79
1,-3,6:79
1,-4,6:79
0,-2,6:79
4,-1,7:79
4,-2,7:79
5,-2,7:79
5,-1,7:79
6,-1,7:79
4,0,7:79
5,1,7:79
6,1,7:79
6,0,7:79
5,0,7:79
-2,2,7:79
-3,2,7:79
-4,2,7:79
-4,3,7:79
-3,3,7:79
-2,3,7:79
-1,3,7:79
-1,2,7:79
-1,1,7:79
-2,1,7:79
-3,1,7:79
-2,0,7:79
0,-3,7:79
0,-4,7:79
1,-4,7:79
1,-3,7:79
0,-3,8:79
4,-1,8:79
5,-1,8:79
5,0,8:79
6,0,8:79
6,1,8:79
-2,2,8:79
-3,2,8:79
-3,3,8:79
-2,3,8:79
-2,1,8:79
-3,2,9:79
-2,2,9:79
-2,3,9:79
