[META]
version=2.0
spawnOnBlockType=3,2,12,1
spawnSunlight=True
spawnDarkness=True
spawnWater=False
spawnLava=False
underFill=True
randomRotation=True
dig=True
tree=False
branch=False
needsFoundation=True
rarity=1
collisionPercentage=2
spawnElevationMin=0
spawnElevationMax=128
spawnInBiome=Grassland
spawnAboveGround=False
spawnUnderGround=False
collisionBlockType=All
groupId=
diggingBranch=false
branchLimit=6
groupFrequencyMin=1
groupFrequencyMax=5
groupSeperationMin=0
groupSeperationMax=5
[DATA]
-1,-1,0:86.0
0,-1,0:86.3
1,-1,0:86.0
-1,0,0:86.3
0,0,0:86.2
1,0,0:86.2
-1,1,0:86.2
0,1,0:86.2
1,1,0:86.2
-1,-2,1:86.0
0,-2,1:86.0
1,-2,1:86.0
-2,-1,1:86.3
-1,-1,1:86.3
2,-1,1:86.1
-2,0,1:86.3
-1,0,1:86.2
2,0,1:86.1
-2,1,1:86.3
-1,1,1:86.2
0,1,1:86.2
1,1,1:86.1
2,1,1:86.1
-1,2,1:86.2
0,2,1:86.2
1,2,1:86.2
0,-1,1:86.2
0,0,1:86.2
1,0,1:86.2
1,-1,1:86.2
-1,-2,2:86.0
0,-2,2:86.0
1,-2,2:86.0
-2,-1,2:86.3
-1,-1,2:86.3
0,-1,2:86.2
1,-1,2:86.2
2,-1,2:86.1
-2,0,2:86.3
-1,0,2:86.3
0,0,2:86.2
1,0,2:86.2
2,0,2:86.1
-2,1,2:86.3
-1,1,2:86.2
0,1,2:86.2
1,1,2:86.1
2,1,2:86.1
-1,2,2:86.2
0,2,2:86.2
1,2,2:86.2
-1,-1,3:86.0
0,-1,3:86.0
1,-1,3:86.1
2,-1,3:106.2
-1,0,3:18
0,0,3:17.0
1,0,3:86.2
2,0,3:106.2
-1,1,3:86.3
0,1,3:86.2
1,1,3:86.2
0,2,3:106.4
0,-1,4:106.1
0,0,4:17.0
1,0,4:106.2
0,1,4:18
0,2,4:106.4
0,-2,5:17.0
0,-1,5:17.0
