[META]
version=2.0
spawnOnBlockType=10,11
spawnSunlight=True
spawnDarkness=True
spawnWater=False
spawnLava=True
underFill=True
randomRotation=True
dig=True
tree=False
branch=False
needsFoundation=True
rarity=240
collisionPercentage=40
spawnElevationMin=68
spawnElevationMax=175
spawnInBiome=Vulcano
[DATA]
-1,0,0:10.8
0,0,0:10.8
1,0,0:10.8
0,-1,0:10.8
1,-1,0:10.8
-1,-1,0:10.8
-1,-2,0:10.8
0,-2,0:10.8
1,-2,0:10.8
2,-3,0:10.8
-2,-1,0:10.8
1,1,0:10.8
2,0,0:10.8
-2,-4,0:10.8
0,-3,0:10.8
-3,-1,0:10.8
-3,0,0:10.8
-1,1,0:10.8
-1,2,0:10.8
-2,2,0:10.8
2,-4,0:10.8
3,-4,0:10.8
-2,-3,0:10.8
-3,-5,0:10.8
3,0,0:10.8
3,1,0:10.8
0,-2,1:10.8
0,-1,1:10.8
1,0,1:10.8
-1,-1,1:10.8
-2,-3,1:10.8
-2,-4,1:10.8
3,1,1:10.8
2,-4,1:10.8
-1,2,1:10.8
-3,-1,1:10.8
0,-1,2:10.8
-3,-1,2:10.8
-2,-4,2:10.8
2,-4,2:10.8
0,-2,2:10.8
-1,-1,2:10.8
1,0,2:10.8
3,1,2:10.8
-1,2,2:10.8
0,-1,3:10.8
-1,-1,3:10.8
0,-2,3:10.8
2,-4,3:10.8
-1,2,3:10.8
-2,-4,3:10.8
3,1,3:10.8
3,1,4:10.8
0,-1,4:10.8
-1,2,4:10.8
2,-4,4:10.8
0,-1,5:10.8
0,-1,6:10.8
0,-1,7:10.8
0,-2,7:10.8
-1,0,7:10.8
-1,0,8:10.8
0,-2,8:10.8
1,-1,8:10.8
