[META]
version=2.0
spawnOnBlockType=2,3
spawnSunlight=True
spawnDarkness=True
spawnWater=False
spawnLava=False
underFill=True
randomRotation=True
dig=True
tree=True
branch=False
needsFoundation=True
rarity=35
collisionPercentage=10
spawnElevationMin=0
spawnElevationMax=220
spawnInBiome=WoWForest,TallForest
[DATA]
-2,-9,0:17.0
-1,-9,0:17.0
0,-9,0:17.0
-3,-8,0:17.0
-2,-8,0:17.0
-1,-8,0:17.0
0,-8,0:17.0
1,-8,0:17.0
2,-8,0:17.0
3,-8,0:17.0
4,-8,0:17.0
-4,-7,0:17.0
-3,-7,0:17.0
-2,-7,0:17.0
-1,-7,0:17.0
0,-7,0:17.0
1,-7,0:17.0
2,-7,0:17.0
3,-7,0:17.0
4,-7,0:17.0
5,-7,0:17.0
6,-7,0:17.0
7,-7,0:17.0
-5,-6,0:17.0
-4,-6,0:17.0
-3,-6,0:17.0
-2,-6,0:17.0
-1,-6,0:17.0
0,-6,0:17.0
1,-6,0:17.0
2,-6,0:17.0
3,-6,0:17.0
4,-6,0:17.0
5,-6,0:17.0
6,-6,0:17.0
7,-6,0:17.0
-6,-5,0:17.0
-5,-5,0:17.0
-4,-5,0:17.0
-3,-5,0:17.0
-2,-5,0:17.0
-1,-5,0:17.0
0,-5,0:17.0
1,-5,0:17.0
2,-5,0:17.0
3,-5,0:17.0
4,-5,0:17.0
5,-5,0:17.0
6,-5,0:17.0
7,-5,0:17.0
-7,-4,0:17.0
-6,-4,0:17.0
-5,-4,0:17.0
-4,-4,0:17.0
-3,-4,0:17.0
-2,-4,0:17.0
-1,-4,0:17.0
0,-4,0:17.0
1,-4,0:17.0
2,-4,0:17.0
3,-4,0:17.0
4,-4,0:17.0
5,-4,0:17.0
6,-4,0:17.0
7,-4,0:17.0
8,-4,0:17.0
-8,-3,0:17.0
-7,-3,0:17.0
-6,-3,0:17.0
-5,-3,0:17.0
-4,-3,0:17.0
-3,-3,0:17.0
-2,-3,0:17.0
-1,-3,0:17.0
0,-3,0:17.0
1,-3,0:17.0
2,-3,0:17.0
3,-3,0:17.0
4,-3,0:17.0
5,-3,0:17.0
6,-3,0:17.0
7,-3,0:17.0
8,-3,0:17.0
-8,-2,0:17.0
-7,-2,0:17.0
-6,-2,0:17.0
-5,-2,0:17.0
-4,-2,0:17.0
-3,-2,0:17.0
-2,-2,0:17.0
-1,-2,0:17.0
0,-2,0:17.0
1,-2,0:17.0
2,-2,0:17.0
3,-2,0:17.0
4,-2,0:17.0
5,-2,0:17.0
6,-2,0:17.0
7,-2,0:17.0
8,-2,0:17.0
-8,-1,0:17.0
-7,-1,0:17.0
-6,-1,0:17.0
-5,-1,0:17.0
-4,-1,0:17.0
-3,-1,0:17.0
-2,-1,0:17.0
-1,-1,0:17.0
0,-1,0:17.0
1,-1,0:17.0
2,-1,0:17.0
3,-1,0:17.0
4,-1,0:17.0
5,-1,0:17.0
6,-1,0:17.0
7,-1,0:17.0
8,-1,0:17.0
-8,0,0:17.0
-7,0,0:17.0
-6,0,0:17.0
-5,0,0:17.0
-4,0,0:17.0
-3,0,0:17.0
-2,0,0:17.0
-1,0,0:17.0
0,0,0:17.0
1,0,0:17.0
2,0,0:17.0
3,0,0:17.0
4,0,0:17.0
5,0,0:17.0
6,0,0:17.0
7,0,0:17.0
8,0,0:17.0
9,0,0:17.0
-7,1,0:17.0
-6,1,0:17.0
-5,1,0:17.0
-4,1,0:17.0
-3,1,0:17.0
-2,1,0:17.0
-1,1,0:17.0
0,1,0:17.0
1,1,0:17.0
2,1,0:17.0
3,1,0:17.0
4,1,0:17.0
5,1,0:17.0
6,1,0:17.0
7,1,0:17.0
8,1,0:17.0
9,1,0:17.0
-7,2,0:17.0
-6,2,0:17.0
-5,2,0:17.0
-4,2,0:17.0
-3,2,0:17.0
-2,2,0:17.0
-1,2,0:17.0
0,2,0:17.0
1,2,0:17.0
2,2,0:17.0
3,2,0:17.0
4,2,0:17.0
5,2,0:17.0
6,2,0:17.0
7,2,0:17.0
8,2,0:17.0
9,2,0:17.0
-7,3,0:17.0
-6,3,0:17.0
-5,3,0:17.0
-4,3,0:17.0
-3,3,0:17.0
-2,3,0:17.0
-1,3,0:17.0
0,3,0:17.0
1,3,0:17.0
2,3,0:17.0
3,3,0:17.0
4,3,0:17.0
5,3,0:17.0
6,3,0:17.0
7,3,0:17.0
8,3,0:17.0
-6,4,0:17.0
-5,4,0:17.0
-4,4,0:17.0
-3,4,0:17.0
-2,4,0:17.0
-1,4,0:17.0
0,4,0:17.0
1,4,0:17.0
2,4,0:17.0
3,4,0:17.0
4,4,0:17.0
5,4,0:17.0
6,4,0:17.0
7,4,0:17.0
8,4,0:17.0
-6,5,0:17.0
-5,5,0:17.0
-4,5,0:17.0
-3,5,0:17.0
-2,5,0:17.0
-1,5,0:17.0
0,5,0:17.0
1,5,0:17.0
2,5,0:17.0
3,5,0:17.0
4,5,0:17.0
5,5,0:17.0
6,5,0:17.0
7,5,0:17.0
-6,6,0:17.0
-5,6,0:17.0
-4,6,0:17.0
-3,6,0:17.0
-2,6,0:17.0
-1,6,0:17.0
0,6,0:17.0
1,6,0:17.0
2,6,0:17.0
3,6,0:17.0
4,6,0:17.0
5,6,0:17.0
6,6,0:17.0
-5,7,0:17.0
-4,7,0:17.0
-3,7,0:17.0
-2,7,0:17.0
-1,7,0:17.0
0,7,0:17.0
1,7,0:17.0
2,7,0:17.0
3,7,0:17.0
4,7,0:17.0
5,7,0:17.0
-3,8,0:17.0
-2,8,0:17.0
-1,8,0:17.0
0,8,0:17.0
1,8,0:17.0
2,8,0:17.0
3,8,0:17.0
4,8,0:17.0
0,9,0:17.0
1,9,0:17.0
2,9,0:17.0
3,9,0:17.0
4,9,0:17.0
-3,-8,1:17.0
-2,-8,1:17.0
-1,-8,1:17.0
0,-8,1:17.0
1,-8,1:17.0
2,-8,1:17.0
3,-8,1:17.0
-4,-7,1:17.0
-3,-7,1:17.0
-2,-7,1:17.0
-1,-7,1:17.0
0,-7,1:17.0
3,-7,1:17.0
4,-7,1:17.0
5,-7,1:17.0
6,-7,1:17.0
-5,-6,1:17.0
-4,-6,1:17.0
-3,-6,1:17.0
-2,-6,1:17.0
-1,-6,1:17.0
1,-6,1:17.0
2,-6,1:17.0
3,-6,1:17.0
4,-6,1:17.0
6,-6,1:17.0
7,-6,1:17.0
-6,-5,1:17.0
-5,-5,1:17.0
-3,-5,1:17.0
-2,-5,1:17.0
0,-5,1:17.0
2,-5,1:17.0
3,-5,1:17.0
5,-5,1:17.0
7,-5,1:17.0
-6,-4,1:17.0
-5,-4,1:17.0
-4,-4,1:17.0
-2,-4,1:17.0
-1,-4,1:17.0
0,-4,1:17.0
2,-4,1:17.0
3,-4,1:17.0
4,-4,1:17.0
5,-4,1:17.0
6,-4,1:17.0
7,-4,1:17.0
-7,-3,1:17.0
-6,-3,1:17.0
-5,-3,1:17.0
-4,-3,1:17.0
-3,-3,1:17.0
-2,-3,1:17.0
-1,-3,1:17.0
0,-3,1:17.0
1,-3,1:17.0
2,-3,1:17.0
4,-3,1:17.0
5,-3,1:17.0
6,-3,1:17.0
8,-3,1:17.0
-8,-2,1:17.0
-7,-2,1:17.0
-6,-2,1:17.0
-5,-2,1:17.0
-4,-2,1:17.0
-3,-2,1:17.0
-2,-2,1:17.0
1,-2,1:17.0
2,-2,1:17.0
3,-2,1:17.0
4,-2,1:17.0
5,-2,1:17.0
6,-2,1:17.0
7,-2,1:17.0
8,-2,1:17.0
-8,-1,1:17.0
-7,-1,1:17.0
-6,-1,1:17.0
-5,-1,1:17.0
-2,-1,1:17.0
-1,-1,1:17.0
1,-1,1:17.0
2,-1,1:17.0
3,-1,1:17.0
4,-1,1:17.0
6,-1,1:17.0
7,-1,1:17.0
8,-1,1:17.0
-7,0,1:17.0
-4,0,1:17.0
-3,0,1:17.0
-2,0,1:17.0
-1,0,1:17.0
1,0,1:17.0
3,0,1:17.0
4,0,1:17.0
5,0,1:17.0
6,0,1:17.0
7,0,1:17.0
8,0,1:17.0
9,0,1:17.0
-7,1,1:17.0
-6,1,1:17.0
-5,1,1:17.0
-3,1,1:17.0
-2,1,1:17.0
0,1,1:17.0
1,1,1:17.0
3,1,1:17.0
4,1,1:17.0
6,1,1:17.0
7,1,1:17.0
8,1,1:17.0
9,1,1:17.0
-7,2,1:17.0
-6,2,1:17.0
-5,2,1:17.0
-4,2,1:17.0
-3,2,1:17.0
-2,2,1:17.0
0,2,1:17.0
1,2,1:17.0
2,2,1:17.0
3,2,1:17.0
4,2,1:17.0
5,2,1:17.0
6,2,1:17.0
7,2,1:17.0
8,2,1:17.0
9,2,1:17.0
-7,3,1:17.0
-6,3,1:17.0
-5,3,1:17.0
-4,3,1:17.0
-3,3,1:17.0
-1,3,1:17.0
0,3,1:17.0
1,3,1:17.0
2,3,1:17.0
4,3,1:17.0
5,3,1:17.0
6,3,1:17.0
7,3,1:17.0
8,3,1:17.0
-6,4,1:17.0
-4,4,1:17.0
-3,4,1:17.0
-2,4,1:17.0
-1,4,1:17.0
3,4,1:17.0
5,4,1:17.0
7,4,1:17.0
-6,5,1:17.0
-5,5,1:17.0
-4,5,1:17.0
-3,5,1:17.0
-2,5,1:17.0
-1,5,1:17.0
0,5,1:17.0
1,5,1:17.0
2,5,1:17.0
3,5,1:17.0
5,5,1:17.0
6,5,1:17.0
7,5,1:17.0
-5,6,1:17.0
-4,6,1:17.0
-3,6,1:17.0
-2,6,1:17.0
-1,6,1:17.0
1,6,1:17.0
2,6,1:17.0
4,6,1:17.0
5,6,1:17.0
6,6,1:17.0
-5,7,1:17.0
-4,7,1:17.0
-3,7,1:17.0
-2,7,1:17.0
-1,7,1:17.0
0,7,1:17.0
2,7,1:17.0
3,7,1:17.0
5,7,1:17.0
-2,8,1:17.0
-1,8,1:17.0
0,8,1:17.0
1,8,1:17.0
2,8,1:17.0
3,8,1:17.0
4,8,1:17.0
1,9,1:17.0
2,9,1:17.0
3,9,1:17.0
4,9,1:17.0
2,-7,1:17.0
1,-7,1:17.0
0,-6,1:17.0
1,-5,1:17.0
1,-4,1:17.0
-1,-5,1:17.0
-3,-4,1:17.0
-4,-5,1:17.0
-1,-2,1:17.0
0,-2,1:17.0
0,-1,1:17.0
0,0,1:17.0
-1,1,1:17.0
-3,-1,1:17.0
-4,-1,1:17.0
-5,0,1:17.0
-6,0,1:17.0
-4,1,1:17.0
-5,4,1:17.0
-2,3,1:17.0
-1,2,1:17.0
0,4,1:17.0
1,4,1:17.0
2,4,1:17.0
4,4,1:17.0
6,4,1:17.0
4,5,1:17.0
3,6,1:17.0
4,7,1:17.0
1,7,1:17.0
0,6,1:17.0
3,3,1:17.0
2,1,1:17.0
2,0,1:17.0
5,1,1:17.0
5,-1,1:17.0
3,-3,1:17.0
4,-5,1:17.0
5,-6,1:17.0
6,-5,1:17.0
7,-3,1:17.0
-3,-8,2:17.0
-2,-8,2:17.0
-1,-8,2:17.0
0,-8,2:17.0
1,-8,2:17.0
2,-8,2:17.0
-3,-7,2:17.0
-2,-7,2:17.0
-1,-7,2:17.0
0,-7,2:17.0
1,-7,2:17.0
2,-7,2:17.0
3,-7,2:17.0
4,-7,2:17.0
5,-7,2:17.0
6,-7,2:17.0
-4,-6,2:17.0
-3,-6,2:17.0
-2,-6,2:17.0
-1,-6,2:17.0
0,-6,2:17.0
1,-6,2:17.0
2,-6,2:17.0
3,-6,2:17.0
4,-6,2:17.0
6,-6,2:17.0
-5,-5,2:17.0
-3,-5,2:17.0
-2,-5,2:17.0
0,-5,2:17.0
2,-5,2:17.0
3,-5,2:17.0
5,-5,2:17.0
6,-5,2:17.0
7,-5,2:17.0
-6,-4,2:17.0
-5,-4,2:17.0
-4,-4,2:17.0
-2,-4,2:17.0
-1,-4,2:17.0
0,-4,2:17.0
2,-4,2:17.0
3,-4,2:17.0
4,-4,2:17.0
5,-4,2:17.0
6,-4,2:17.0
7,-4,2:17.0
-7,-3,2:17.0
-6,-3,2:17.0
-5,-3,2:17.0
-4,-3,2:17.0
-3,-3,2:17.0
-2,-3,2:17.0
-1,-3,2:17.0
0,-3,2:17.0
1,-3,2:17.0
2,-3,2:17.0
4,-3,2:17.0
5,-3,2:17.0
6,-3,2:17.0
7,-3,2:17.0
-8,-2,2:17.0
-7,-2,2:17.0
-6,-2,2:17.0
-5,-2,2:17.0
-4,-2,2:17.0
-3,-2,2:17.0
-2,-2,2:17.0
1,-2,2:17.0
2,-2,2:17.0
3,-2,2:17.0
4,-2,2:17.0
5,-2,2:17.0
6,-2,2:17.0
7,-2,2:17.0
8,-2,2:17.0
-8,-1,2:17.0
-7,-1,2:17.0
-6,-1,2:17.0
-5,-1,2:17.0
-2,-1,2:17.0
-1,-1,2:17.0
1,-1,2:17.0
2,-1,2:17.0
3,-1,2:17.0
4,-1,2:17.0
6,-1,2:17.0
7,-1,2:17.0
8,-1,2:17.0
-7,0,2:17.0
-6,0,2:17.0
-4,0,2:17.0
-3,0,2:17.0
-2,0,2:17.0
-1,0,2:17.0
1,0,2:17.0
3,0,2:17.0
4,0,2:17.0
5,0,2:17.0
6,0,2:17.0
7,0,2:17.0
8,0,2:17.0
9,0,2:17.0
-7,1,2:17.0
-6,1,2:17.0
-5,1,2:17.0
-3,1,2:17.0
-2,1,2:17.0
0,1,2:17.0
1,1,2:17.0
3,1,2:17.0
4,1,2:17.0
6,1,2:17.0
7,1,2:17.0
8,1,2:17.0
9,1,2:17.0
-7,2,2:17.0
-6,2,2:17.0
-5,2,2:17.0
-4,2,2:17.0
-3,2,2:17.0
-2,2,2:17.0
0,2,2:17.0
1,2,2:17.0
2,2,2:17.0
3,2,2:17.0
4,2,2:17.0
5,2,2:17.0
6,2,2:17.0
7,2,2:17.0
8,2,2:17.0
-6,3,2:17.0
-5,3,2:17.0
-4,3,2:17.0
-3,3,2:17.0
-1,3,2:17.0
0,3,2:17.0
1,3,2:17.0
2,3,2:17.0
4,3,2:17.0
5,3,2:17.0
6,3,2:17.0
7,3,2:17.0
8,3,2:17.0
-6,4,2:17.0
-5,4,2:17.0
-4,4,2:17.0
-3,4,2:17.0
-2,4,2:17.0
-1,4,2:17.0
3,4,2:17.0
5,4,2:17.0
7,4,2:17.0
-5,5,2:17.0
-4,5,2:17.0
-3,5,2:17.0
-2,5,2:17.0
-1,5,2:17.0
0,5,2:17.0
1,5,2:17.0
2,5,2:17.0
3,5,2:17.0
5,5,2:17.0
6,5,2:17.0
-5,6,2:17.0
-4,6,2:17.0
-3,6,2:17.0
-2,6,2:17.0
-1,6,2:17.0
0,6,2:17.0
1,6,2:17.0
2,6,2:17.0
4,6,2:17.0
5,6,2:17.0
6,6,2:17.0
-4,7,2:17.0
-3,7,2:17.0
-2,7,2:17.0
-1,7,2:17.0
0,7,2:17.0
2,7,2:17.0
3,7,2:17.0
4,7,2:17.0
5,7,2:17.0
-1,8,2:17.0
0,8,2:17.0
1,8,2:17.0
2,8,2:17.0
3,8,2:17.0
4,8,2:17.0
3,9,2:17.0
-4,-5,2:17.0
-3,-4,2:17.0
-1,-5,2:17.0
1,-5,2:17.0
1,-4,2:17.0
5,-6,2:17.0
4,-5,2:17.0
3,-3,2:17.0
5,-1,2:17.0
5,1,2:17.0
2,0,2:17.0
2,1,2:17.0
0,-1,2:17.0
0,-2,2:17.0
-1,-2,2:17.0
0,0,2:17.0
-3,-1,2:17.0
-4,-1,2:17.0
-5,0,2:17.0
-4,1,2:17.0
-1,1,2:17.0
-1,2,2:17.0
-2,3,2:17.0
0,4,2:17.0
1,4,2:17.0
2,4,2:17.0
3,3,2:17.0
4,4,2:17.0
4,5,2:17.0
6,4,2:17.0
3,6,2:17.0
1,7,2:17.0
-2,-8,3:17.0
-3,-7,3:17.0
-2,-7,3:17.0
-1,-7,3:17.0
0,-7,3:17.0
1,-7,3:17.0
2,-7,3:17.0
3,-7,3:17.0
4,-7,3:17.0
5,-7,3:17.0
-4,-6,3:17.0
-3,-6,3:17.0
-2,-6,3:17.0
-1,-6,3:17.0
0,-6,3:17.0
1,-6,3:17.0
2,-6,3:17.0
3,-6,3:17.0
4,-6,3:17.0
6,-6,3:17.0
-5,-5,3:17.0
-4,-5,3:17.0
-3,-5,3:17.0
-2,-5,3:17.0
-1,-5,3:17.0
0,-5,3:17.0
1,-5,3:17.0
2,-5,3:17.0
3,-5,3:17.0
4,-5,3:17.0
5,-5,3:17.0
6,-5,3:17.0
-5,-4,3:17.0
-4,-4,3:17.0
-3,-4,3:17.0
-2,-4,3:17.0
-1,-4,3:17.0
0,-4,3:17.0
2,-4,3:17.0
3,-4,3:17.0
4,-4,3:17.0
5,-4,3:17.0
6,-4,3:17.0
7,-4,3:17.0
-6,-3,3:17.0
-5,-3,3:17.0
-4,-3,3:17.0
-3,-3,3:17.0
-2,-3,3:17.0
-1,-3,3:17.0
0,-3,3:17.0
1,-3,3:17.0
2,-3,3:17.0
4,-3,3:17.0
5,-3,3:17.0
6,-3,3:17.0
7,-3,3:17.0
-7,-2,3:17.0
-6,-2,3:17.0
-5,-2,3:17.0
-4,-2,3:17.0
-3,-2,3:17.0
-2,-2,3:17.0
1,-2,3:17.0
2,-2,3:17.0
3,-2,3:17.0
4,-2,3:17.0
5,-2,3:17.0
6,-2,3:17.0
7,-2,3:17.0
8,-2,3:17.0
-8,-1,3:17.0
-7,-1,3:17.0
-6,-1,3:17.0
-5,-1,3:17.0
-2,-1,3:17.0
-1,-1,3:17.0
1,-1,3:17.0
2,-1,3:17.0
3,-1,3:17.0
4,-1,3:17.0
6,-1,3:17.0
7,-1,3:17.0
8,-1,3:17.0
-7,0,3:17.0
-6,0,3:17.0
-5,0,3:17.0
-4,0,3:17.0
-3,0,3:17.0
-2,0,3:17.0
-1,0,3:17.0
1,0,3:17.0
3,0,3:17.0
4,0,3:17.0
5,0,3:17.0
6,0,3:17.0
7,0,3:17.0
8,0,3:17.0
-7,1,3:17.0
-6,1,3:17.0
-5,1,3:17.0
-3,1,3:17.0
-2,1,3:17.0
0,1,3:17.0
1,1,3:17.0
3,1,3:17.0
4,1,3:17.0
6,1,3:17.0
7,1,3:17.0
8,1,3:17.0
9,1,3:17.0
-6,2,3:17.0
-5,2,3:17.0
-4,2,3:17.0
-3,2,3:17.0
-2,2,3:17.0
0,2,3:17.0
1,2,3:17.0
2,2,3:17.0
3,2,3:17.0
4,2,3:17.0
5,2,3:17.0
6,2,3:17.0
7,2,3:17.0
8,2,3:17.0
-6,3,3:17.0
-5,3,3:17.0
-4,3,3:17.0
-3,3,3:17.0
-1,3,3:17.0
0,3,3:17.0
1,3,3:17.0
2,3,3:17.0
4,3,3:17.0
5,3,3:17.0
6,3,3:17.0
7,3,3:17.0
-5,4,3:17.0
-4,4,3:17.0
-3,4,3:17.0
-2,4,3:17.0
-1,4,3:17.0
3,4,3:17.0
5,4,3:17.0
6,4,3:17.0
7,4,3:17.0
-5,5,3:17.0
-4,5,3:17.0
-3,5,3:17.0
-2,5,3:17.0
-1,5,3:17.0
0,5,3:17.0
1,5,3:17.0
2,5,3:17.0
3,5,3:17.0
4,5,3:17.0
5,5,3:17.0
6,5,3:17.0
-5,6,3:17.0
-4,6,3:17.0
-3,6,3:17.0
-2,6,3:17.0
-1,6,3:17.0
0,6,3:17.0
1,6,3:17.0
2,6,3:17.0
3,6,3:17.0
4,6,3:17.0
5,6,3:17.0
-4,7,3:17.0
-3,7,3:17.0
-2,7,3:17.0
-1,7,3:17.0
0,7,3:17.0
1,7,3:17.0
2,7,3:17.0
3,7,3:17.0
4,7,3:17.0
5,7,3:17.0
0,8,3:17.0
1,8,3:17.0
2,8,3:17.0
3,8,3:17.0
4,8,3:17.0
-1,-2,3:17.0
0,-2,3:17.0
0,-1,3:17.0
0,0,3:17.0
-1,1,3:17.0
-3,-1,3:17.0
-4,-1,3:17.0
-4,1,3:17.0
-1,2,3:17.0
-2,3,3:17.0
0,4,3:17.0
1,4,3:17.0
2,4,3:17.0
4,4,3:17.0
3,3,3:17.0
2,1,3:17.0
2,0,3:17.0
5,1,3:17.0
5,-1,3:17.0
3,-3,3:17.0
1,-4,3:17.0
5,-6,3:17.0
-2,-7,4:17.0
-1,-7,4:17.0
0,-7,4:17.0
1,-7,4:17.0
2,-7,4:17.0
-3,-6,4:17.0
-2,-6,4:17.0
-1,-6,4:17.0
0,-6,4:17.0
1,-6,4:17.0
2,-6,4:17.0
3,-6,4:17.0
4,-6,4:17.0
5,-6,4:17.0
6,-6,4:17.0
-4,-5,4:17.0
-3,-5,4:17.0
-2,-5,4:17.0
-1,-5,4:17.0
0,-5,4:17.0
1,-5,4:17.0
2,-5,4:17.0
3,-5,4:17.0
4,-5,4:17.0
5,-5,4:17.0
6,-5,4:17.0
-5,-4,4:17.0
-4,-4,4:17.0
-3,-4,4:17.0
-2,-4,4:17.0
-1,-4,4:17.0
0,-4,4:17.0
2,-4,4:17.0
3,-4,4:17.0
4,-4,4:17.0
5,-4,4:17.0
6,-4,4:17.0
-6,-3,4:17.0
-5,-3,4:17.0
-4,-3,4:17.0
-3,-3,4:17.0
-2,-3,4:17.0
-1,-3,4:17.0
0,-3,4:17.0
1,-3,4:17.0
2,-3,4:17.0
4,-3,4:17.0
5,-3,4:17.0
6,-3,4:17.0
7,-3,4:17.0
-6,-2,4:17.0
-5,-2,4:17.0
-4,-2,4:17.0
-3,-2,4:17.0
-2,-2,4:17.0
1,-2,4:17.0
2,-2,4:17.0
3,-2,4:17.0
4,-2,4:17.0
5,-2,4:17.0
6,-2,4:17.0
7,-2,4:17.0
-6,-1,4:17.0
-5,-1,4:17.0
-4,-1,4:17.0
-2,-1,4:17.0
-1,-1,4:17.0
1,-1,4:17.0
2,-1,4:17.0
3,-1,4:17.0
4,-1,4:17.0
6,-1,4:17.0
7,-1,4:17.0
-6,0,4:17.0
-5,0,4:17.0
-4,0,4:17.0
-3,0,4:17.0
-2,0,4:17.0
-1,0,4:17.0
1,0,4:17.0
3,0,4:17.0
4,0,4:17.0
5,0,4:17.0
6,0,4:17.0
7,0,4:17.0
8,0,4:17.0
-6,1,4:17.0
-5,1,4:17.0
-4,1,4:17.0
-3,1,4:17.0
-2,1,4:17.0
0,1,4:17.0
1,1,4:17.0
3,1,4:17.0
4,1,4:17.0
6,1,4:17.0
7,1,4:17.0
8,1,4:17.0
-6,2,4:17.0
-5,2,4:17.0
-4,2,4:17.0
-3,2,4:17.0
-2,2,4:17.0
0,2,4:17.0
1,2,4:17.0
2,2,4:17.0
3,2,4:17.0
4,2,4:17.0
5,2,4:17.0
6,2,4:17.0
7,2,4:17.0
8,2,4:17.0
-5,3,4:17.0
-4,3,4:17.0
-3,3,4:17.0
-1,3,4:17.0
0,3,4:17.0
1,3,4:17.0
2,3,4:17.0
4,3,4:17.0
5,3,4:17.0
6,3,4:17.0
7,3,4:17.0
-5,4,4:17.0
-4,4,4:17.0
-3,4,4:17.0
-2,4,4:17.0
-1,4,4:17.0
3,4,4:17.0
4,4,4:17.0
5,4,4:17.0
6,4,4:17.0
-4,5,4:17.0
-3,5,4:17.0
-2,5,4:17.0
-1,5,4:17.0
0,5,4:17.0
1,5,4:17.0
2,5,4:17.0
3,5,4:17.0
4,5,4:17.0
5,5,4:17.0
6,5,4:17.0
-4,6,4:17.0
-3,6,4:17.0
-2,6,4:17.0
-1,6,4:17.0
0,6,4:17.0
1,6,4:17.0
2,6,4:17.0
3,6,4:17.0
4,6,4:17.0
5,6,4:17.0
-2,7,4:17.0
-1,7,4:17.0
0,7,4:17.0
1,7,4:17.0
2,7,4:17.0
3,7,4:17.0
4,7,4:17.0
2,8,4:17.0
3,8,4:17.0
4,8,4:17.0
1,-4,4:17.0
3,-3,4:17.0
5,-1,4:17.0
5,1,4:17.0
2,1,4:17.0
2,0,4:17.0
0,-1,4:17.0
0,-2,4:17.0
-1,-2,4:17.0
-3,-1,4:17.0
0,0,4:17.0
-1,1,4:17.0
-1,2,4:17.0
-2,3,4:17.0
0,4,4:17.0
1,4,4:17.0
2,4,4:17.0
3,3,4:17.0
-2,-6,5:17.0
-1,-6,5:17.0
0,-6,5:17.0
1,-6,5:17.0
2,-6,5:17.0
3,-6,5:17.0
4,-6,5:17.0
5,-6,5:17.0
-3,-5,5:17.0
-2,-5,5:17.0
-1,-5,5:17.0
0,-5,5:17.0
1,-5,5:17.0
2,-5,5:17.0
3,-5,5:17.0
4,-5,5:17.0
5,-5,5:17.0
-4,-4,5:17.0
-3,-4,5:17.0
-2,-4,5:17.0
-1,-4,5:17.0
0,-4,5:17.0
1,-4,5:17.0
2,-4,5:17.0
3,-4,5:17.0
4,-4,5:17.0
5,-4,5:17.0
6,-4,5:17.0
-5,-3,5:17.0
-4,-3,5:17.0
-3,-3,5:17.0
-2,-3,5:17.0
-1,-3,5:17.0
0,-3,5:17.0
1,-3,5:17.0
2,-3,5:17.0
4,-3,5:17.0
5,-3,5:17.0
6,-3,5:17.0
-5,-2,5:17.0
-4,-2,5:17.0
-3,-2,5:17.0
-2,-2,5:17.0
1,-2,5:17.0
2,-2,5:17.0
3,-2,5:17.0
4,-2,5:17.0
5,-2,5:17.0
6,-2,5:17.0
7,-2,5:17.0
-6,-1,5:17.0
-5,-1,5:17.0
-4,-1,5:17.0
-3,-1,5:17.0
-2,-1,5:17.0
-1,-1,5:17.0
1,-1,5:17.0
2,-1,5:17.0
3,-1,5:17.0
4,-1,5:17.0
5,-1,5:17.0
6,-1,5:17.0
7,-1,5:17.0
-6,0,5:17.0
-5,0,5:17.0
-4,0,5:17.0
-3,0,5:17.0
-2,0,5:17.0
-1,0,5:17.0
1,0,5:17.0
3,0,5:17.0
4,0,5:17.0
5,0,5:17.0
6,0,5:17.0
7,0,5:17.0
-6,1,5:17.0
-5,1,5:17.0
-4,1,5:17.0
-3,1,5:17.0
-2,1,5:17.0
0,1,5:17.0
1,1,5:17.0
3,1,5:17.0
4,1,5:17.0
5,1,5:17.0
6,1,5:17.0
7,1,5:17.0
-5,2,5:17.0
-4,2,5:17.0
-3,2,5:17.0
-2,2,5:17.0
0,2,5:17.0
1,2,5:17.0
2,2,5:17.0
3,2,5:17.0
4,2,5:17.0
5,2,5:17.0
6,2,5:17.0
7,2,5:17.0
-5,3,5:17.0
-4,3,5:17.0
-3,3,5:17.0
-2,3,5:17.0
-1,3,5:17.0
0,3,5:17.0
1,3,5:17.0
2,3,5:17.0
4,3,5:17.0
5,3,5:17.0
6,3,5:17.0
-4,4,5:17.0
-3,4,5:17.0
-2,4,5:17.0
-1,4,5:17.0
0,4,5:17.0
3,4,5:17.0
4,4,5:17.0
5,4,5:17.0
6,4,5:17.0
-4,5,5:17.0
-3,5,5:17.0
-2,5,5:17.0
-1,5,5:17.0
0,5,5:17.0
1,5,5:17.0
2,5,5:17.0
3,5,5:17.0
4,5,5:17.0
5,5,5:17.0
-3,6,5:17.0
-2,6,5:17.0
-1,6,5:17.0
0,6,5:17.0
1,6,5:17.0
2,6,5:17.0
3,6,5:17.0
4,6,5:17.0
0,7,5:17.0
1,7,5:17.0
2,7,5:17.0
3,7,5:17.0
4,7,5:17.0
-1,-2,5:17.0
0,-2,5:17.0
0,-1,5:17.0
0,0,5:17.0
-1,1,5:17.0
-1,2,5:17.0
1,4,5:17.0
2,4,5:17.0
3,3,5:17.0
2,1,5:17.0
2,0,5:17.0
3,-3,5:17.0
-2,-5,6:17.0
-1,-5,6:17.0
0,-5,6:17.0
1,-5,6:17.0
2,-5,6:17.0
3,-5,6:17.0
4,-5,6:17.0
5,-5,6:17.0
-3,-4,6:17.0
-2,-4,6:17.0
-1,-4,6:17.0
0,-4,6:17.0
1,-4,6:17.0
2,-4,6:17.0
3,-4,6:17.0
4,-4,6:17.0
5,-4,6:17.0
-4,-3,6:17.0
-3,-3,6:17.0
-2,-3,6:17.0
-1,-3,6:17.0
0,-3,6:17.0
1,-3,6:17.0
2,-3,6:17.0
4,-3,6:17.0
5,-3,6:17.0
6,-3,6:17.0
-5,-2,6:17.0
-4,-2,6:17.0
-3,-2,6:17.0
-2,-2,6:17.0
1,-2,6:17.0
2,-2,6:17.0
3,-2,6:17.0
4,-2,6:17.0
5,-2,6:17.0
6,-2,6:17.0
-5,-1,6:17.0
-4,-1,6:17.0
-3,-1,6:17.0
-2,-1,6:17.0
-1,-1,6:17.0
1,-1,6:17.0
2,-1,6:17.0
3,-1,6:17.0
4,-1,6:17.0
5,-1,6:17.0
6,-1,6:17.0
-5,0,6:17.0
-4,0,6:17.0
-3,0,6:17.0
-2,0,6:17.0
-1,0,6:17.0
1,0,6:17.0
3,0,6:17.0
4,0,6:17.0
5,0,6:17.0
6,0,6:17.0
7,0,6:17.0
-5,1,6:17.0
-4,1,6:17.0
-3,1,6:17.0
-2,1,6:17.0
0,1,6:17.0
1,1,6:17.0
3,1,6:17.0
4,1,6:17.0
5,1,6:17.0
6,1,6:17.0
7,1,6:17.0
-5,2,6:17.0
-4,2,6:17.0
-3,2,6:17.0
-2,2,6:17.0
0,2,6:17.0
1,2,6:17.0
2,2,6:17.0
3,2,6:17.0
4,2,6:17.0
5,2,6:17.0
6,2,6:17.0
-4,3,6:17.0
-3,3,6:17.0
-2,3,6:17.0
-1,3,6:17.0
0,3,6:17.0
1,3,6:17.0
2,3,6:17.0
4,3,6:17.0
5,3,6:17.0
6,3,6:17.0
-3,4,6:17.0
-2,4,6:17.0
-1,4,6:17.0
0,4,6:17.0
1,4,6:17.0
2,4,6:17.0
3,4,6:17.0
4,4,6:17.0
5,4,6:17.0
-3,5,6:17.0
-2,5,6:17.0
-1,5,6:17.0
0,5,6:17.0
1,5,6:17.0
2,5,6:17.0
3,5,6:17.0
4,5,6:17.0
5,5,6:17.0
-2,6,6:17.0
-1,6,6:17.0
0,6,6:17.0
1,6,6:17.0
2,6,6:17.0
3,6,6:17.0
4,6,6:17.0
-1,-2,6:17.0
0,-2,6:17.0
0,-1,6:17.0
0,0,6:17.0
-1,1,6:17.0
-1,2,6:17.0
2,1,6:17.0
2,0,6:17.0
3,-3,6:17.0
3,3,6:17.0
-2,-5,7:17.0
-1,-5,7:17.0
0,-5,7:17.0
1,-5,7:17.0
2,-5,7:17.0
3,-5,7:17.0
4,-5,7:17.0
-3,-4,7:17.0
-2,-4,7:17.0
-1,-4,7:17.0
0,-4,7:17.0
1,-4,7:17.0
2,-4,7:17.0
3,-4,7:17.0
4,-4,7:17.0
5,-4,7:17.0
-3,-3,7:17.0
-2,-3,7:17.0
-1,-3,7:17.0
0,-3,7:17.0
1,-3,7:17.0
2,-3,7:17.0
4,-3,7:17.0
5,-3,7:17.0
-4,-2,7:17.0
-3,-2,7:17.0
-2,-2,7:17.0
1,-2,7:17.0
2,-2,7:17.0
3,-2,7:17.0
4,-2,7:17.0
5,-2,7:17.0
-4,-1,7:17.0
-3,-1,7:17.0
-2,-1,7:17.0
-1,-1,7:17.0
1,-1,7:17.0
2,-1,7:17.0
3,-1,7:17.0
4,-1,7:17.0
5,-1,7:17.0
6,-1,7:17.0
-5,0,7:17.0
-4,0,7:17.0
-3,0,7:17.0
-2,0,7:17.0
-1,0,7:17.0
1,0,7:17.0
3,0,7:17.0
4,0,7:17.0
5,0,7:17.0
6,0,7:17.0
-5,1,7:17.0
-4,1,7:17.0
-3,1,7:17.0
-2,1,7:17.0
0,1,7:17.0
1,1,7:17.0
3,1,7:17.0
4,1,7:17.0
5,1,7:17.0
6,1,7:17.0
-4,2,7:17.0
-3,2,7:17.0
-2,2,7:17.0
0,2,7:17.0
1,2,7:17.0
2,2,7:17.0
3,2,7:17.0
4,2,7:17.0
5,2,7:17.0
6,2,7:17.0
-3,3,7:17.0
-2,3,7:17.0
-1,3,7:17.0
0,3,7:17.0
1,3,7:17.0
2,3,7:17.0
4,3,7:17.0
5,3,7:17.0
-3,4,7:17.0
-2,4,7:17.0
-1,4,7:17.0
0,4,7:17.0
1,4,7:17.0
2,4,7:17.0
3,4,7:17.0
4,4,7:17.0
5,4,7:17.0
-2,5,7:17.0
-1,5,7:17.0
0,5,7:17.0
1,5,7:17.0
2,5,7:17.0
3,5,7:17.0
4,5,7:17.0
-1,-2,7:17.0
0,-2,7:17.0
0,-1,7:17.0
0,0,7:17.0
-1,1,7:17.0
-1,2,7:17.0
2,1,7:17.0
2,0,7:17.0
3,3,7:17.0
3,-3,7:17.0
-2,-5,8:17.0
-1,-5,8:17.0
0,-5,8:17.0
1,-5,8:17.0
2,-5,8:17.0
3,-5,8:17.0
-2,-4,8:17.0
-1,-4,8:17.0
0,-4,8:17.0
1,-4,8:17.0
2,-4,8:17.0
3,-4,8:17.0
4,-4,8:17.0
-3,-3,8:17.0
-2,-3,8:17.0
-1,-3,8:17.0
0,-3,8:17.0
1,-3,8:17.0
2,-3,8:17.0
3,-3,8:17.0
4,-3,8:17.0
5,-3,8:17.0
-4,-2,8:17.0
-3,-2,8:17.0
-2,-2,8:17.0
1,-2,8:17.0
2,-2,8:17.0
3,-2,8:17.0
4,-2,8:17.0
5,-2,8:17.0
-4,-1,8:17.0
-3,-1,8:17.0
-2,-1,8:17.0
-1,-1,8:17.0
1,-1,8:17.0
2,-1,8:17.0
3,-1,8:17.0
4,-1,8:17.0
5,-1,8:17.0
6,-1,8:17.0
-5,0,8:17.0
-4,0,8:17.0
-3,0,8:17.0
-2,0,8:17.0
-1,0,8:17.0
1,0,8:17.0
3,0,8:17.0
4,0,8:17.0
5,0,8:17.0
6,0,8:17.0
-4,1,8:17.0
-3,1,8:17.0
-2,1,8:17.0
0,1,8:17.0
1,1,8:17.0
3,1,8:17.0
4,1,8:17.0
5,1,8:17.0
6,1,8:17.0
-4,2,8:17.0
-3,2,8:17.0
-2,2,8:17.0
0,2,8:17.0
1,2,8:17.0
2,2,8:17.0
3,2,8:17.0
4,2,8:17.0
5,2,8:17.0
6,2,8:17.0
-3,3,8:17.0
-2,3,8:17.0
-1,3,8:17.0
0,3,8:17.0
1,3,8:17.0
2,3,8:17.0
3,3,8:17.0
4,3,8:17.0
5,3,8:17.0
-3,4,8:17.0
-2,4,8:17.0
-1,4,8:17.0
0,4,8:17.0
1,4,8:17.0
2,4,8:17.0
3,4,8:17.0
4,4,8:17.0
-2,5,8:17.0
-1,5,8:17.0
0,5,8:17.0
1,5,8:17.0
2,5,8:17.0
3,5,8:17.0
4,5,8:17.0
-1,-2,8:17.0
0,-2,8:17.0
0,-1,8:17.0
0,0,8:17.0
-1,1,8:17.0
-1,2,8:17.0
2,1,8:17.0
2,0,8:17.0
-1,-5,9:17.0
0,-5,9:17.0
1,-5,9:17.0
2,-5,9:17.0
3,-5,9:17.0
-2,-4,9:17.0
-1,-4,9:17.0
0,-4,9:17.0
1,-4,9:17.0
2,-4,9:17.0
3,-4,9:17.0
4,-4,9:17.0
-3,-3,9:17.0
-2,-3,9:17.0
-1,-3,9:17.0
0,-3,9:17.0
1,-3,9:17.0
2,-3,9:17.0
3,-3,9:17.0
4,-3,9:17.0
5,-3,9:17.0
-4,-2,9:17.0
-3,-2,9:17.0
-2,-2,9:17.0
1,-2,9:17.0
2,-2,9:17.0
3,-2,9:17.0
4,-2,9:17.0
5,-2,9:17.0
-4,-1,9:17.0
-3,-1,9:17.0
-2,-1,9:17.0
-1,-1,9:17.0
1,-1,9:17.0
2,-1,9:17.0
3,-1,9:17.0
4,-1,9:17.0
5,-1,9:17.0
6,-1,9:17.0
-4,0,9:17.0
-3,0,9:17.0
-2,0,9:17.0
-1,0,9:17.0
1,0,9:17.0
3,0,9:17.0
4,0,9:17.0
5,0,9:17.0
6,0,9:17.0
-4,1,9:17.0
-3,1,9:17.0
-2,1,9:17.0
0,1,9:17.0
1,1,9:17.0
3,1,9:17.0
4,1,9:17.0
5,1,9:17.0
6,1,9:17.0
-4,2,9:17.0
-3,2,9:17.0
-2,2,9:17.0
0,2,9:17.0
1,2,9:17.0
2,2,9:17.0
3,2,9:17.0
4,2,9:17.0
5,2,9:17.0
-3,3,9:17.0
-2,3,9:17.0
-1,3,9:17.0
0,3,9:17.0
1,3,9:17.0
2,3,9:17.0
3,3,9:17.0
4,3,9:17.0
5,3,9:17.0
-3,4,9:17.0
-2,4,9:17.0
-1,4,9:17.0
0,4,9:17.0
1,4,9:17.0
2,4,9:17.0
3,4,9:17.0
4,4,9:17.0
-2,5,9:17.0
-1,5,9:17.0
0,5,9:17.0
1,5,9:17.0
2,5,9:17.0
3,5,9:17.0
-1,-2,9:17.0
0,-2,9:17.0
0,-1,9:17.0
0,0,9:17.0
2,0,9:17.0
2,1,9:17.0
-1,1,9:17.0
-1,2,9:17.0
-1,-5,10:17.0
0,-5,10:17.0
1,-5,10:17.0
2,-5,10:17.0
3,-5,10:17.0
-2,-4,10:17.0
-1,-4,10:17.0
0,-4,10:17.0
1,-4,10:17.0
2,-4,10:17.0
3,-4,10:17.0
4,-4,10:17.0
-3,-3,10:17.0
-2,-3,10:17.0
-1,-3,10:17.0
0,-3,10:17.0
1,-3,10:17.0
2,-3,10:17.0
3,-3,10:17.0
4,-3,10:17.0
-4,-2,10:17.0
-3,-2,10:17.0
-2,-2,10:17.0
-1,-2,10:17.0
0,-2,10:17.0
1,-2,10:17.0
2,-2,10:17.0
3,-2,10:17.0
4,-2,10:17.0
5,-2,10:17.0
-4,-1,10:17.0
-3,-1,10:17.0
-2,-1,10:17.0
-1,-1,10:17.0
0,-1,10:17.0
1,-1,10:17.0
2,-1,10:17.0
3,-1,10:17.0
4,-1,10:17.0
5,-1,10:17.0
-4,0,10:17.0
-3,0,10:17.0
-2,0,10:17.0
-1,0,10:17.0
0,0,10:17.0
1,0,10:17.0
2,0,10:17.0
3,0,10:17.0
4,0,10:17.0
5,0,10:17.0
6,0,10:17.0
-4,1,10:17.0
-3,1,10:17.0
-2,1,10:17.0
-1,1,10:17.0
0,1,10:17.0
1,1,10:17.0
2,1,10:17.0
3,1,10:17.0
4,1,10:17.0
5,1,10:17.0
-4,2,10:17.0
-3,2,10:17.0
-2,2,10:17.0
-1,2,10:17.0
0,2,10:17.0
1,2,10:17.0
2,2,10:17.0
3,2,10:17.0
4,2,10:17.0
5,2,10:17.0
-3,3,10:17.0
-2,3,10:17.0
-1,3,10:17.0
0,3,10:17.0
1,3,10:17.0
2,3,10:17.0
3,3,10:17.0
4,3,10:17.0
-2,4,10:17.0
-1,4,10:17.0
0,4,10:17.0
1,4,10:17.0
2,4,10:17.0
3,4,10:17.0
4,4,10:17.0
-1,5,10:17.0
0,5,10:17.0
1,5,10:17.0
2,5,10:17.0
0,-5,11:17.0
1,-5,11:17.0
2,-5,11:17.0
-2,-4,11:17.0
-1,-4,11:17.0
0,-4,11:17.0
1,-4,11:17.0
2,-4,11:17.0
3,-4,11:17.0
4,-4,11:17.0
-3,-3,11:17.0
-2,-3,11:17.0
-1,-3,11:17.0
0,-3,11:17.0
1,-3,11:17.0
2,-3,11:17.0
3,-3,11:17.0
4,-3,11:17.0
-4,-2,11:17.0
-3,-2,11:17.0
-2,-2,11:17.0
-1,-2,11:17.0
0,-2,11:17.0
1,-2,11:17.0
2,-2,11:17.0
3,-2,11:17.0
4,-2,11:17.0
5,-2,11:17.0
-4,-1,11:17.0
-3,-1,11:17.0
-2,-1,11:17.0
-1,-1,11:17.0
0,-1,11:17.0
1,-1,11:17.0
2,-1,11:17.0
3,-1,11:17.0
4,-1,11:17.0
5,-1,11:17.0
-4,0,11:17.0
-3,0,11:17.0
-2,0,11:17.0
-1,0,11:17.0
0,0,11:17.0
1,0,11:17.0
2,0,11:17.0
3,0,11:17.0
4,0,11:17.0
5,0,11:17.0
-4,1,11:17.0
-3,1,11:17.0
-2,1,11:17.0
-1,1,11:17.0
0,1,11:17.0
1,1,11:17.0
2,1,11:17.0
3,1,11:17.0
4,1,11:17.0
5,1,11:17.0
-4,2,11:17.0
-3,2,11:17.0
-2,2,11:17.0
-1,2,11:17.0
0,2,11:17.0
1,2,11:17.0
2,2,11:17.0
3,2,11:17.0
4,2,11:17.0
5,2,11:17.0
-3,3,11:17.0
-2,3,11:17.0
-1,3,11:17.0
0,3,11:17.0
1,3,11:17.0
2,3,11:17.0
3,3,11:17.0
4,3,11:17.0
-2,4,11:17.0
-1,4,11:17.0
0,4,11:17.0
1,4,11:17.0
2,4,11:17.0
3,4,11:17.0
4,4,11:17.0
1,5,11:17.0
0,-5,12:17.0
1,-5,12:17.0
2,-5,12:17.0
-2,-4,12:17.0
-1,-4,12:17.0
0,-4,12:17.0
1,-4,12:17.0
2,-4,12:17.0
3,-4,12:17.0
-3,-3,12:17.0
-2,-3,12:17.0
-1,-3,12:17.0
0,-3,12:17.0
1,-3,12:17.0
2,-3,12:17.0
3,-3,12:17.0
4,-3,12:17.0
-4,-2,12:17.0
-3,-2,12:17.0
-2,-2,12:17.0
-1,-2,12:17.0
0,-2,12:17.0
1,-2,12:17.0
2,-2,12:17.0
3,-2,12:17.0
4,-2,12:17.0
5,-2,12:17.0
-4,-1,12:17.0
-3,-1,12:17.0
-2,-1,12:17.0
-1,-1,12:17.0
0,-1,12:17.0
1,-1,12:17.0
2,-1,12:17.0
3,-1,12:17.0
4,-1,12:17.0
5,-1,12:17.0
-4,0,12:17.0
-3,0,12:17.0
-2,0,12:17.0
-1,0,12:17.0
0,0,12:17.0
1,0,12:17.0
2,0,12:17.0
3,0,12:17.0
4,0,12:17.0
5,0,12:17.0
-4,1,12:17.0
-3,1,12:17.0
-2,1,12:17.0
-1,1,12:17.0
0,1,12:17.0
1,1,12:17.0
2,1,12:17.0
3,1,12:17.0
4,1,12:17.0
5,1,12:17.0
-3,2,12:17.0
-2,2,12:17.0
-1,2,12:17.0
0,2,12:17.0
1,2,12:17.0
2,2,12:17.0
3,2,12:17.0
4,2,12:17.0
5,2,12:17.0
-3,3,12:17.0
-2,3,12:17.0
-1,3,12:17.0
0,3,12:17.0
1,3,12:17.0
2,3,12:17.0
3,3,12:17.0
4,3,12:17.0
-1,4,12:17.0
0,4,12:17.0
1,4,12:17.0
2,4,12:17.0
3,4,12:17.0
1,-5,13:17.0
-2,-4,13:17.0
-1,-4,13:17.0
0,-4,13:17.0
1,-4,13:17.0
2,-4,13:17.0
3,-4,13:17.0
-3,-3,13:17.0
-2,-3,13:17.0
-1,-3,13:17.0
0,-3,13:17.0
1,-3,13:17.0
2,-3,13:17.0
3,-3,13:17.0
4,-3,13:17.0
-3,-2,13:17.0
-2,-2,13:17.0
-1,-2,13:17.0
0,-2,13:17.0
1,-2,13:17.0
2,-2,13:17.0
3,-2,13:17.0
4,-2,13:17.0
-4,-1,13:17.0
-3,-1,13:17.0
-2,-1,13:17.0
-1,-1,13:17.0
0,-1,13:17.0
1,-1,13:17.0
2,-1,13:17.0
3,-1,13:17.0
4,-1,13:17.0
5,-1,13:17.0
-4,0,13:17.0
-3,0,13:17.0
-2,0,13:17.0
-1,0,13:17.0
0,0,13:17.0
1,0,13:17.0
2,0,13:17.0
3,0,13:17.0
4,0,13:17.0
5,0,13:17.0
-4,1,13:17.0
-3,1,13:17.0
-2,1,13:17.0
-1,1,13:17.0
0,1,13:17.0
1,1,13:17.0
2,1,13:17.0
3,1,13:17.0
4,1,13:17.0
-3,2,13:17.0
-2,2,13:17.0
-1,2,13:17.0
0,2,13:17.0
1,2,13:17.0
2,2,13:17.0
3,2,13:17.0
4,2,13:17.0
-2,3,13:17.0
-1,3,13:17.0
0,3,13:17.0
1,3,13:17.0
2,3,13:17.0
3,3,13:17.0
4,3,13:17.0
-1,4,13:17.0
0,4,13:17.0
1,4,13:17.0
2,4,13:17.0
-1,-4,14:17.0
0,-4,14:17.0
1,-4,14:17.0
2,-4,14:17.0
-3,-3,14:17.0
-2,-3,14:17.0
-1,-3,14:17.0
0,-3,14:17.0
1,-3,14:17.0
2,-3,14:17.0
3,-3,14:17.0
4,-3,14:17.0
-3,-2,14:17.0
-2,-2,14:17.0
-1,-2,14:17.0
0,-2,14:17.0
1,-2,14:17.0
2,-2,14:17.0
3,-2,14:17.0
4,-2,14:17.0
-3,-1,14:17.0
-2,-1,14:17.0
-1,-1,14:17.0
0,-1,14:17.0
1,-1,14:17.0
2,-1,14:17.0
3,-1,14:17.0
4,-1,14:17.0
-3,0,14:17.0
-2,0,14:17.0
-1,0,14:17.0
0,0,14:17.0
1,0,14:17.0
2,0,14:17.0
3,0,14:17.0
4,0,14:17.0
-4,1,14:17.0
-3,1,14:17.0
-2,1,14:17.0
-1,1,14:17.0
0,1,14:17.0
1,1,14:17.0
2,1,14:17.0
3,1,14:17.0
4,1,14:17.0
-3,2,14:17.0
-2,2,14:17.0
-1,2,14:17.0
0,2,14:17.0
1,2,14:17.0
2,2,14:17.0
3,2,14:17.0
4,2,14:17.0
-2,3,14:17.0
-1,3,14:17.0
0,3,14:17.0
1,3,14:17.0
2,3,14:17.0
3,3,14:17.0
-1,4,14:17.0
0,4,14:17.0
1,4,14:17.0
-1,-4,15:17.0
0,-4,15:17.0
1,-4,15:17.0
2,-4,15:17.0
-3,-3,15:17.0
-2,-3,15:17.0
-1,-3,15:17.0
0,-3,15:17.0
1,-3,15:17.0
2,-3,15:17.0
3,-3,15:17.0
-3,-2,15:17.0
-2,-2,15:17.0
-1,-2,15:17.0
0,-2,15:17.0
1,-2,15:17.0
2,-2,15:17.0
3,-2,15:17.0
4,-2,15:17.0
-3,-1,15:17.0
-1,-1,15:17.0
0,-1,15:17.0
1,-1,15:17.0
2,-1,15:17.0
3,-1,15:17.0
4,-1,15:17.0
-3,0,15:17.0
-1,0,15:17.0
0,0,15:17.0
1,0,15:17.0
2,0,15:17.0
3,0,15:17.0
4,0,15:17.0
-3,1,15:17.0
0,1,15:17.0
1,1,15:17.0
2,1,15:17.0
3,1,15:17.0
4,1,15:17.0
-4,2,15:17.0
-3,2,15:17.0
-2,2,15:17.0
0,2,15:17.0
1,2,15:17.0
2,2,15:17.0
3,2,15:17.0
4,2,15:17.0
-2,3,15:17.0
-1,3,15:17.0
0,3,15:17.0
1,3,15:17.0
2,3,15:17.0
3,3,15:17.0
-1,4,15:17.0
0,4,15:17.0
-2,-1,15:17.0
-2,0,15:17.0
-2,1,15:17.0
-1,1,15:17.0
-1,2,15:17.0
0,-4,16:17.0
1,-4,16:17.0
-3,-3,16:17.0
-2,-3,16:17.0
-1,-3,16:17.0
1,-3,16:17.0
2,-3,16:17.0
-4,-2,16:17.0
-3,-2,16:17.0
2,-2,16:17.0
3,-2,16:17.0
4,-2,16:17.0
-4,-1,16:17.0
-3,-1,16:17.0
4,-1,16:17.0
-3,0,16:17.0
3,0,16:17.0
4,0,16:17.0
-3,1,16:17.0
3,1,16:17.0
-4,2,16:17.0
-3,2,16:17.0
3,2,16:17.0
-2,3,16:17.0
-1,3,16:17.0
0,3,16:17.0
1,3,16:17.0
2,3,16:17.0
3,3,16:17.0
-1,4,16:17.0
0,4,16:17.0
0,5,16:17.0
0,-3,16:17.0
0,-2,16:17.0
1,-2,16:17.0
1,-1,16:17.0
2,-1,16:17.0
3,-1,16:17.0
2,0,16:17.0
2,1,16:17.0
1,1,16:17.0
1,2,16:17.0
2,2,16:17.0
1,0,16:17.0
0,0,16:17.0
0,-1,16:17.0
-1,-1,16:17.0
-1,-2,16:17.0
-2,-2,16:17.0
-2,-1,16:17.0
-2,0,16:17.0
-1,0,16:17.0
-1,1,16:17.0
-1,2,16:17.0
0,2,16:17.0
0,1,16:17.0
-2,1,16:17.0
-2,2,16:17.0
-1,-4,17:17.0
0,-4,17:17.0
-2,-3,17:17.0
-1,-3,17:17.0
0,-3,17:17.0
1,-3,17:17.0
-4,-2,17:17.0
-3,-2,17:17.0
-2,-2,17:17.0
1,-2,17:17.0
2,-2,17:17.0
3,-2,17:17.0
-5,-1,17:17.0
-4,-1,17:17.0
-3,-1,17:17.0
3,-1,17:17.0
-3,0,17:17.0
3,0,17:17.0
-3,1,17:17.0
3,1,17:17.0
-4,2,17:17.0
-3,2,17:17.0
3,2,17:17.0
-4,3,17:17.0
-3,3,17:17.0
-2,3,17:17.0
0,3,17:17.0
1,3,17:17.0
2,3,17:17.0
3,3,17:17.0
-2,4,17:17.0
-1,4,17:17.0
0,4,17:17.0
0,5,17:17.0
-1,-2,17:17.0
0,-2,17:17.0
1,-1,17:17.0
2,-1,17:17.0
2,0,17:17.0
2,1,17:17.0
2,2,17:17.0
1,2,17:17.0
0,2,17:17.0
-1,2,17:17.0
-1,3,17:17.0
-2,2,17:17.0
-2,1,17:17.0
-2,0,17:17.0
-2,-1,17:17.0
-1,-1,17:17.0
0,-1,17:17.0
1,0,17:17.0
1,1,17:17.0
0,1,17:17.0
-1,1,17:17.0
-1,0,17:17.0
0,0,17:17.0
-1,-4,18:17.0
-2,-3,18:17.0
-1,-3,18:17.0
0,-3,18:17.0
-3,-2,18:17.0
-2,-2,18:17.0
0,-2,18:17.0
1,-2,18:17.0
2,-2,18:17.0
3,-2,18:17.0
-5,-1,18:17.0
-4,-1,18:17.0
1,-1,18:17.0
3,-1,18:17.0
-5,0,18:17.0
-4,0,18:17.0
-3,0,18:17.0
3,0,18:17.0
-3,1,18:17.0
2,1,18:17.0
3,1,18:17.0
-4,2,18:17.0
-3,2,18:17.0
3,2,18:17.0
-5,3,18:17.0
-4,3,18:17.0
-3,3,18:17.0
-2,3,18:17.0
0,3,18:17.0
1,3,18:17.0
2,3,18:17.0
3,3,18:17.0
-5,4,18:17.0
-4,4,18:17.0
-2,4,18:17.0
-1,4,18:17.0
0,4,18:17.0
-1,5,18:17.0
0,5,18:17.0
0,6,18:17.0
-1,-2,18:17.0
-1,-1,18:17.0
-2,-1,18:17.0
-3,-1,18:17.0
0,-1,18:17.0
2,-1,18:17.0
2,0,18:17.0
1,0,18:17.0
0,0,18:17.0
-1,0,18:17.0
-2,0,18:17.0
-2,1,18:17.0
-1,1,18:17.0
0,1,18:17.0
1,1,18:17.0
2,2,18:17.0
1,2,18:17.0
0,2,18:17.0
-1,2,18:17.0
-2,2,18:17.0
-1,3,18:17.0
-2,-4,19:17.0
-1,-4,19:17.0
-2,-3,19:17.0
-1,-3,19:17.0
2,-3,19:17.0
-3,-2,19:17.0
-2,-2,19:17.0
-1,-2,19:17.0
0,-2,19:17.0
1,-2,19:17.0
2,-2,19:17.0
-5,-1,19:17.0
-4,-1,19:17.0
-3,-1,19:17.0
0,-1,19:17.0
1,-1,19:17.0
2,-1,19:17.0
-6,0,19:17.0
-5,0,19:17.0
2,0,19:17.0
-6,1,19:17.0
-5,1,19:17.0
-4,1,19:17.0
-3,1,19:17.0
2,1,19:17.0
-4,2,19:17.0
-3,2,19:17.0
3,2,19:17.0
-5,3,19:17.0
-4,3,19:17.0
0,3,19:17.0
1,3,19:17.0
2,3,19:17.0
3,3,19:17.0
-5,4,19:17.0
-4,4,19:17.0
-3,4,19:17.0
-2,4,19:17.0
0,4,19:17.0
-1,5,19:17.0
0,5,19:17.0
1,5,19:17.0
0,6,19:17.0
1,6,19:17.0
-2,-1,19:17.0
-1,-1,19:17.0
-1,0,19:17.0
0,0,19:17.0
1,0,19:17.0
-2,0,19:17.0
-3,0,19:17.0
-4,0,19:17.0
-2,1,19:17.0
-1,1,19:17.0
0,1,19:17.0
1,1,19:17.0
1,2,19:17.0
2,2,19:17.0
0,2,19:17.0
-1,2,19:17.0
-2,2,19:17.0
-1,3,19:17.0
-1,4,19:17.0
-2,3,19:17.0
-3,3,19:17.0
-3,-5,20:17.0
-2,-5,20:17.0
-3,-4,20:17.0
-2,-4,20:17.0
2,-4,20:17.0
-3,-3,20:17.0
-2,-3,20:17.0
1,-3,20:17.0
2,-3,20:17.0
-3,-2,20:17.0
-1,-2,20:17.0
0,-2,20:17.0
1,-2,20:17.0
2,-2,20:17.0
-5,-1,20:17.0
-4,-1,20:17.0
-3,-1,20:17.0
-2,-1,20:17.0
-1,-1,20:17.0
0,-1,20:17.0
2,-1,20:17.0
-7,0,20:17.0
-6,0,20:17.0
-5,0,20:17.0
-4,0,20:17.0
-3,0,20:17.0
-2,0,20:17.0
2,0,20:17.0
-6,1,20:17.0
-5,1,20:17.0
-4,1,20:17.0
-3,1,20:17.0
-2,1,20:17.0
-1,1,20:17.0
2,1,20:17.0
-4,2,20:17.0
-3,2,20:17.0
-2,2,20:17.0
-1,2,20:17.0
2,2,20:17.0
3,2,20:17.0
-4,3,20:17.0
-3,3,20:17.0
-2,3,20:17.0
-1,3,20:17.0
0,3,20:17.0
1,3,20:17.0
2,3,20:17.0
3,3,20:17.0
4,3,20:17.0
5,3,20:17.0
-5,4,20:17.0
-4,4,20:17.0
-3,4,20:17.0
-2,4,20:17.0
-1,4,20:17.0
0,4,20:17.0
1,4,20:17.0
4,4,20:17.0
5,4,20:17.0
-5,5,20:17.0
-4,5,20:17.0
-3,5,20:17.0
-2,5,20:17.0
-1,5,20:17.0
1,5,20:17.0
-5,6,20:17.0
-1,6,20:17.0
0,6,20:17.0
1,6,20:17.0
0,7,20:17.0
1,7,20:17.0
2,7,20:17.0
1,8,20:17.0
2,8,20:17.0
-2,-2,20:17.0
-1,0,20:17.0
0,0,20:17.0
1,0,20:17.0
1,-1,20:17.0
1,1,20:17.0
0,1,20:17.0
0,2,20:17.0
1,2,20:17.0
0,5,20:17.0
-4,-7,21:17.0
-3,-7,21:17.0
-5,-6,21:18.0
-4,-6,21:17.0
-3,-6,21:17.0
-5,-5,21:18.0
-4,-5,21:17.0
-3,-5,21:17.0
-2,-5,21:17.0
3,-5,21:17.0
-5,-4,21:18.0
-4,-4,21:17.0
-3,-4,21:17.0
-2,-4,21:17.0
2,-4,21:17.0
-4,-3,21:17.0
-3,-3,21:17.0
-2,-3,21:17.0
0,-3,21:17.0
1,-3,21:17.0
2,-3,21:17.0
-3,-2,21:17.0
-2,-2,21:17.0
-1,-2,21:17.0
0,-2,21:17.0
2,-2,21:17.0
-8,-1,21:17.0
-7,-1,21:17.0
-6,-1,21:17.0
-5,-1,21:17.0
-2,-1,21:17.0
-1,-1,21:17.0
0,-1,21:17.0
1,-1,21:17.0
2,-1,21:17.0
-8,0,21:17.0
-7,0,21:17.0
-5,0,21:17.0
-4,0,21:17.0
-1,0,21:17.0
0,0,21:17.0
1,0,21:17.0
2,0,21:17.0
-7,1,21:17.0
-6,1,21:17.0
-5,1,21:17.0
-4,1,21:17.0
-1,1,21:17.0
0,1,21:17.0
1,1,21:17.0
2,1,21:17.0
3,1,21:17.0
-5,2,21:17.0
-4,2,21:17.0
-2,2,21:17.0
-1,2,21:17.0
0,2,21:17.0
1,2,21:17.0
2,2,21:17.0
3,2,21:17.0
4,2,21:17.0
-4,3,21:17.0
-2,3,21:17.0
-1,3,21:17.0
0,3,21:17.0
1,3,21:17.0
2,3,21:17.0
3,3,21:17.0
5,3,21:17.0
-4,4,21:17.0
-3,4,21:17.0
-1,4,21:17.0
0,4,21:17.0
1,4,21:17.0
6,4,21:17.0
7,4,21:17.0
-5,5,21:17.0
-4,5,21:17.0
-3,5,21:17.0
-2,5,21:17.0
0,5,21:17.0
1,5,21:17.0
2,5,21:17.0
-6,6,21:17.0
-5,6,21:17.0
-4,6,21:17.0
-3,6,21:17.0
0,6,21:17.0
1,6,21:17.0
2,6,21:17.0
-6,7,21:17.0
-5,7,21:17.0
0,7,21:17.0
1,7,21:17.0
2,7,21:17.0
1,8,21:17.0
2,8,21:17.0
3,8,21:17.0
2,9,21:17.0
3,9,21:17.0
3,10,21:17.0
-5,-10,22:17.0
-5,-9,22:17.0
-4,-9,22:17.0
-5,-8,22:17.0
-4,-8,22:17.0
-5,-7,22:17.0
-4,-7,22:17.0
-3,-7,22:17.0
3,-7,22:17.0
-6,-6,22:18.0
-5,-6,22:17.0
-4,-6,22:17.0
-3,-6,22:17.0
2,-6,22:17.0
3,-6,22:17.0
-6,-5,22:18.0
-5,-5,22:18.0
-4,-5,22:17.0
-3,-5,22:17.0
1,-5,22:17.0
2,-5,22:17.0
3,-5,22:17.0
-6,-4,22:18.0
-5,-4,22:18.0
-4,-4,22:18.0
-3,-4,22:17.0
-2,-4,22:18.0
1,-4,22:17.0
2,-4,22:17.0
3,-4,22:17.0
1,-3,22:17.0
2,-3,22:17.0
3,-3,22:17.0
-8,-2,22:17.0
-7,-2,22:17.0
1,-2,22:17.0
2,-2,22:17.0
-10,-1,22:17.0
-9,-1,22:17.0
-8,-1,22:17.0
-7,-1,22:17.0
-6,-1,22:17.0
1,-1,22:17.0
-9,0,22:17.0
-8,0,22:17.0
-7,0,22:17.0
-6,0,22:17.0
1,0,22:17.0
2,0,22:17.0
0,1,22:17.0
1,1,22:17.0
2,1,22:17.0
4,1,22:17.0
-5,2,22:17.0
-4,2,22:18.0
-1,2,22:17.0
0,2,22:17.0
1,2,22:17.0
2,2,22:17.0
3,2,22:17.0
4,2,22:17.0
5,2,22:17.0
6,2,22:17.0
-6,3,22:18.0
-4,3,22:18.0
-1,3,22:17.0
0,3,22:17.0
1,3,22:17.0
3,3,22:17.0
4,3,22:17.0
5,3,22:17.0
6,3,22:17.0
7,3,22:17.0
-6,4,22:18.0
-5,4,22:18.0
4,4,22:17.0
5,4,22:17.0
6,4,22:17.0
7,4,22:17.0
8,4,22:17.0
4,5,22:18.0
5,5,22:18.0
-4,6,22:17.0
-3,6,22:17.0
2,6,22:17.0
-5,7,22:17.0
-4,7,22:17.0
-3,7,22:17.0
2,7,22:17.0
3,7,22:17.0
-6,8,22:17.0
-5,8,22:17.0
-4,8,22:17.0
-3,8,22:17.0
1,8,22:17.0
2,8,22:17.0
3,8,22:17.0
5,8,22:18.0
-6,9,22:17.0
-5,9,22:17.0
1,9,22:17.0
2,9,22:17.0
3,9,22:17.0
4,9,22:17.0
5,9,22:18.0
2,10,22:17.0
3,10,22:17.0
4,10,22:17.0
5,10,22:18.0
3,11,22:17.0
4,11,22:17.0
4,12,22:17.0
-6,-11,23:17.0
-5,-11,23:17.0
-7,-10,23:18.0
-6,-10,23:17.0
-5,-10,23:17.0
7,-10,23:18.0
9,-10,23:18.0
-8,-9,23:18.0
-7,-9,23:18.0
-6,-9,23:17.0
-5,-9,23:17.0
-4,-9,23:17.0
-3,-9,23:18.0
4,-9,23:17.0
7,-9,23:18.0
8,-9,23:18.0
-5,-8,23:17.0
-4,-8,23:17.0
-3,-8,23:18.0
-2,-8,23:18.0
3,-8,23:17.0
4,-8,23:17.0
5,-8,23:18.0
6,-8,23:17.0
9,-8,23:18.0
-6,-7,23:18.0
-5,-7,23:18.0
-4,-7,23:17.0
-3,-7,23:18.0
-2,-7,23:18.0
2,-7,23:17.0
3,-7,23:17.0
4,-7,23:17.0
5,-7,23:17.0
6,-7,23:17.0
7,-7,23:17.0
-5,-6,23:18.0
-4,-6,23:18.0
-3,-6,23:18.0
1,-6,23:17.0
2,-6,23:17.0
3,-6,23:17.0
4,-6,23:17.0
5,-6,23:18.0
7,-6,23:17.0
-5,-5,23:18.0
-4,-5,23:18.0
-3,-5,23:18.0
1,-5,23:17.0
2,-5,23:17.0
3,-5,23:17.0
-4,-4,23:18.0
-3,-4,23:18.0
2,-4,23:17.0
3,-4,23:17.0
-11,-2,23:17.0
-10,-2,23:17.0
-9,-2,23:17.0
-8,-2,23:17.0
-7,-2,23:17.0
-11,-1,23:17.0
-10,-1,23:17.0
-9,-1,23:17.0
-8,-1,23:17.0
-7,-1,23:17.0
-6,-1,23:17.0
-9,0,23:17.0
-8,0,23:17.0
1,0,23:17.0
2,0,23:17.0
6,0,23:18.0
7,0,23:18.0
-6,1,23:18.0
1,1,23:17.0
2,1,23:17.0
6,1,23:18.0
-6,2,23:18.0
-5,2,23:18.0
-4,2,23:18.0
-3,2,23:18.0
0,2,23:17.0
1,2,23:17.0
5,2,23:17.0
6,2,23:17.0
7,2,23:17.0
8,2,23:18.0
-6,3,23:18.0
-5,3,23:17.0
-4,3,23:18.0
0,3,23:17.0
3,3,23:18.0
4,3,23:18.0
5,3,23:17.0
6,3,23:17.0
7,3,23:17.0
8,3,23:17.0
-6,4,23:18.0
-5,4,23:18.0
-4,4,23:18.0
-3,4,23:18.0
3,4,23:18.0
4,4,23:18.0
5,4,23:17.0
6,4,23:17.0
7,4,23:17.0
8,4,23:17.0
9,4,23:17.0
10,4,23:17.0
-6,5,23:18.0
-5,5,23:18.0
-4,5,23:18.0
4,5,23:18.0
5,5,23:18.0
6,5,23:18.0
7,5,23:18.0
8,5,23:18.0
9,5,23:17.0
10,5,23:17.0
5,6,23:18.0
8,6,23:18.0
10,6,23:18.0
-5,7,23:17.0
-4,7,23:17.0
5,7,23:18.0
10,7,23:18.0
-9,8,23:18.0
-8,8,23:18.0
-7,8,23:18.0
-5,8,23:17.0
-4,8,23:17.0
2,8,23:18.0
3,8,23:18.0
4,8,23:18.0
5,8,23:18.0
6,8,23:18.0
-6,9,23:17.0
-5,9,23:17.0
-4,9,23:17.0
1,9,23:17.0
2,9,23:18.0
3,9,23:17.0
4,9,23:17.0
5,9,23:18.0
6,9,23:18.0
-9,10,23:18.0
-7,10,23:18.0
-6,10,23:17.0
-5,10,23:17.0
-4,10,23:17.0
2,10,23:18.0
3,10,23:17.0
4,10,23:17.0
5,10,23:18.0
6,10,23:18.0
-6,11,23:17.0
3,11,23:17.0
4,11,23:17.0
5,11,23:17.0
6,11,23:18.0
4,12,23:17.0
5,12,23:17.0
6,12,23:18.0
8,12,23:18.0
9,12,23:18.0
4,13,23:17.0
5,13,23:17.0
8,13,23:18.0
9,13,23:18.0
3,14,23:17.0
6,14,23:17.0
7,14,23:18.0
8,14,23:18.0
9,14,23:18.0
-5,-15,24:18.0
-4,-15,24:18.0
-6,-14,24:18.0
-5,-14,24:18.0
-4,-14,24:18.0
-7,-13,24:17.0
-6,-13,24:17.0
-5,-13,24:18.0
-4,-13,24:18.0
-8,-12,24:18.0
-6,-12,24:17.0
1,-12,24:18.0
3,-12,24:18.0
-9,-11,24:18.0
-8,-11,24:18.0
-7,-11,24:18.0
-6,-11,24:17.0
-5,-11,24:17.0
1,-11,24:18.0
8,-11,24:18.0
9,-11,24:18.0
-8,-10,24:18.0
-7,-10,24:17.0
-6,-10,24:17.0
-5,-10,24:17.0
1,-10,24:18.0
2,-10,24:18.0
3,-10,24:18.0
4,-10,24:17.0
7,-10,24:18.0
8,-10,24:18.0
9,-10,24:18.0
10,-10,24:18.0
-9,-9,24:18.0
-8,-9,24:18.0
-7,-9,24:18.0
-6,-9,24:18.0
-5,-9,24:18.0
3,-9,24:17.0
4,-9,24:17.0
5,-9,24:18.0
6,-9,24:18.0
7,-9,24:18.0
8,-9,24:18.0
9,-9,24:18.0
10,-9,24:18.0
-8,-8,24:18.0
-7,-8,24:18.0
-6,-8,24:18.0
-4,-8,24:17.0
-3,-8,24:18.0
2,-8,24:17.0
3,-8,24:17.0
4,-8,24:17.0
5,-8,24:18.0
6,-8,24:18.0
7,-8,24:17.0
8,-8,24:18.0
9,-8,24:18.0
10,-8,24:18.0
-4,-7,24:18.0
2,-7,24:17.0
3,-7,24:17.0
4,-7,24:17.0
5,-7,24:18.0
6,-7,24:18.0
9,-7,24:18.0
-5,-6,24:18.0
-4,-6,24:18.0
-3,-6,24:18.0
-1,-6,24:18.0
2,-6,24:18.0
3,-6,24:18.0
4,-6,24:18.0
5,-6,24:18.0
6,-6,24:18.0
7,-6,24:17.0
0,-5,24:17.0
1,-5,24:17.0
3,-5,24:18.0
-1,-4,24:18.0
1,-4,24:18.0
-12,-3,24:17.0
-11,-3,24:17.0
-10,-3,24:17.0
-13,-2,24:17.0
-12,-2,24:17.0
-11,-2,24:17.0
-10,-2,24:17.0
-9,-2,24:17.0
-8,-2,24:17.0
-7,-2,24:17.0
-11,-1,24:17.0
-10,-1,24:17.0
-9,-1,24:17.0
2,-1,24:17.0
3,-1,24:17.0
6,-1,24:18.0
8,-1,24:18.0
-11,0,24:17.0
-10,0,24:17.0
1,0,24:17.0
2,0,24:17.0
3,0,24:17.0
5,0,24:18.0
6,0,24:18.0
7,0,24:18.0
8,0,24:18.0
-11,1,24:17.0
2,1,24:17.0
5,1,24:18.0
6,1,24:18.0
7,1,24:17.0
8,1,24:18.0
9,1,24:18.0
-6,2,24:18.0
-5,2,24:18.0
-4,2,24:18.0
0,2,24:17.0
5,2,24:18.0
6,2,24:18.0
7,2,24:17.0
8,2,24:18.0
9,2,24:18.0
-6,3,24:18.0
-5,3,24:17.0
-4,3,24:18.0
0,3,24:17.0
5,3,24:18.0
6,3,24:18.0
7,3,24:18.0
8,3,24:17.0
9,3,24:17.0
10,3,24:17.0
-6,4,24:18.0
-5,4,24:18.0
-4,4,24:18.0
0,4,24:17.0
4,4,24:18.0
6,4,24:18.0
7,4,24:17.0
8,4,24:17.0
9,4,24:17.0
10,4,24:17.0
11,4,24:17.0
5,5,24:18.0
6,5,24:18.0
7,5,24:18.0
8,5,24:18.0
9,5,24:17.0
10,5,24:17.0
11,5,24:17.0
12,5,24:17.0
7,6,24:18.0
8,6,24:18.0
9,6,24:17.0
10,6,24:18.0
11,6,24:18.0
-9,7,24:18.0
7,7,24:18.0
8,7,24:18.0
9,7,24:18.0
10,7,24:18.0
11,7,24:18.0
-10,8,24:18.0
-9,8,24:18.0
-8,8,24:18.0
-7,8,24:18.0
3,8,24:18.0
4,8,24:18.0
5,8,24:18.0
8,8,24:18.0
9,8,24:18.0
10,8,24:18.0
-10,9,24:18.0
-9,9,24:18.0
-8,9,24:17.0
-7,9,24:17.0
-6,9,24:17.0
-5,9,24:17.0
-4,9,24:18.0
1,9,24:17.0
3,9,24:18.0
4,9,24:18.0
5,9,24:18.0
-10,10,24:18.0
-9,10,24:17.0
-8,10,24:17.0
-7,10,24:18.0
-6,10,24:17.0
-5,10,24:17.0
-4,10,24:17.0
1,10,24:17.0
6,10,24:18.0
-9,11,24:18.0
-8,11,24:18.0
-6,11,24:17.0
-5,11,24:17.0
-4,11,24:17.0
4,11,24:18.0
5,11,24:18.0
6,11,24:18.0
7,11,24:18.0
9,11,24:18.0
-7,12,24:17.0
-6,12,24:17.0
-5,12,24:17.0
3,12,24:18.0
4,12,24:18.0
5,12,24:17.0
6,12,24:18.0
7,12,24:18.0
8,12,24:18.0
9,12,24:18.0
10,12,24:18.0
3,13,24:18.0
4,13,24:18.0
5,13,24:17.0
6,13,24:17.0
7,13,24:17.0
8,13,24:17.0
9,13,24:18.0
10,13,24:18.0
4,14,24:18.0
5,14,24:17.0
6,14,24:17.0
7,14,24:18.0
8,14,24:18.0
9,14,24:18.0
10,14,24:18.0
3,15,24:17.0
5,15,24:18.0
6,15,24:17.0
7,15,24:17.0
8,15,24:18.0
9,15,24:18.0
6,16,24:18.0
7,16,24:17.0
5,17,24:18.0
6,17,24:18.0
7,17,24:18.0
8,17,24:18.0
7,18,24:18.0
9,18,24:18.0
8,19,24:18.0
10,19,24:18.0
11,19,24:18.0
8,20,24:18.0
9,20,24:18.0
-9,-18,25:18.0
-8,-18,25:18.0
-7,-18,25:18.0
-5,-18,25:18.0
-9,-17,25:18.0
-8,-17,25:17.0
-7,-17,25:18.0
-5,-17,25:18.0
-9,-16,25:18.0
-7,-16,25:17.0
-6,-16,25:18.0
-5,-16,25:18.0
-8,-15,25:18.0
-7,-15,25:17.0
-6,-15,25:18.0
-5,-15,25:18.0
-4,-15,25:18.0
-10,-14,25:18.0
-9,-14,25:18.0
-8,-14,25:18.0
-7,-14,25:17.0
-6,-14,25:18.0
-5,-14,25:17.0
-4,-14,25:18.0
-3,-14,25:18.0
-10,-13,25:18.0
-9,-13,25:18.0
-8,-13,25:18.0
-7,-13,25:17.0
-6,-13,25:17.0
-5,-13,25:18.0
-4,-13,25:18.0
-3,-13,25:18.0
1,-13,25:18.0
2,-13,25:18.0
3,-13,25:18.0
-10,-12,25:18.0
-9,-12,25:18.0
-8,-12,25:18.0
-6,-12,25:17.0
-5,-12,25:18.0
0,-12,25:18.0
1,-12,25:18.0
2,-12,25:18.0
3,-12,25:18.0
4,-12,25:18.0
5,-12,25:17.0
-8,-11,25:18.0
-6,-11,25:17.0
0,-11,25:18.0
1,-11,25:18.0
2,-11,25:17.0
3,-11,25:18.0
4,-11,25:17.0
5,-11,25:17.0
7,-11,25:18.0
8,-11,25:18.0
9,-11,25:18.0
-8,-10,25:18.0
-7,-10,25:17.0
-6,-10,25:18.0
0,-10,25:18.0
1,-10,25:18.0
2,-10,25:17.0
3,-10,25:17.0
4,-10,25:17.0
5,-10,25:17.0
6,-10,25:18.0
7,-10,25:18.0
8,-10,25:18.0
9,-10,25:18.0
-8,-9,25:18.0
-7,-9,25:18.0
-6,-9,25:18.0
-4,-9,25:18.0
-3,-9,25:18.0
-2,-9,25:18.0
1,-9,25:18.0
2,-9,25:18.0
4,-9,25:17.0
6,-9,25:18.0
7,-9,25:18.0
8,-9,25:17.0
9,-9,25:18.0
-4,-8,25:17.0
4,-8,25:18.0
5,-8,25:18.0
6,-8,25:18.0
7,-8,25:18.0
8,-8,25:18.0
9,-8,25:18.0
-4,-7,25:18.0
-3,-7,25:18.0
-1,-7,25:18.0
0,-7,25:18.0
1,-7,25:18.0
3,-7,25:18.0
4,-7,25:18.0
5,-7,25:18.0
7,-7,25:18.0
8,-7,25:18.0
9,-7,25:18.0
-2,-6,25:18.0
-1,-6,25:18.0
0,-6,25:18.0
1,-6,25:18.0
2,-6,25:18.0
3,-6,25:18.0
4,-6,25:18.0
5,-6,25:18.0
7,-6,25:17.0
8,-6,25:18.0
9,-6,25:18.0
10,-6,25:18.0
-2,-5,25:18.0
-1,-5,25:18.0
0,-5,25:17.0
1,-5,25:18.0
9,-5,25:18.0
10,-5,25:18.0
-2,-4,25:18.0
-1,-4,25:18.0
0,-4,25:18.0
1,-4,25:18.0
8,-4,25:18.0
10,-4,25:18.0
-14,-3,25:17.0
-13,-3,25:17.0
-12,-3,25:17.0
-11,-3,25:17.0
-7,-3,25:17.0
0,-3,25:18.0
1,-3,25:18.0
3,-3,25:18.0
4,-3,25:18.0
5,-3,25:18.0
-13,-2,25:17.0
-12,-2,25:17.0
-11,-2,25:17.0
-10,-2,25:17.0
-7,-2,25:17.0
5,-2,25:18.0
2,-1,25:17.0
3,-1,25:17.0
5,-1,25:18.0
2,0,25:17.0
3,0,25:17.0
-12,1,25:18.0
-11,1,25:17.0
-10,1,25:18.0
-6,1,25:18.0
-5,1,25:18.0
7,1,25:17.0
8,1,25:18.0
12,1,25:18.0
-12,2,25:18.0
-11,2,25:18.0
-10,2,25:18.0
-7,2,25:18.0
-6,2,25:18.0
-5,2,25:18.0
6,2,25:18.0
7,2,25:18.0
8,2,25:18.0
11,2,25:18.0
12,2,25:17.0
13,2,25:18.0
-12,3,25:18.0
-11,3,25:18.0
-7,3,25:18.0
-6,3,25:17.0
-5,3,25:17.0
-4,3,25:17.0
0,3,25:17.0
12,3,25:17.0
-8,4,25:18.0
-7,4,25:18.0
-6,4,25:18.0
-5,4,25:18.0
-4,4,25:18.0
0,4,25:17.0
1,4,25:18.0
10,4,25:17.0
11,4,25:17.0
12,4,25:17.0
-7,5,25:18.0
1,5,25:18.0
8,5,25:18.0
10,5,25:17.0
11,5,25:17.0
12,5,25:17.0
13,5,25:17.0
1,6,25:18.0
2,6,25:18.0
9,6,25:17.0
8,7,25:18.0
9,7,25:18.0
10,7,25:18.0
-8,8,25:18.0
-4,8,25:18.0
-9,9,25:18.0
-8,9,25:18.0
-7,9,25:18.0
-6,9,25:18.0
-5,9,25:18.0
-4,9,25:18.0
-11,10,25:18.0
-10,10,25:18.0
-9,10,25:17.0
-8,10,25:18.0
-7,10,25:18.0
-6,10,25:18.0
-5,10,25:17.0
-4,10,25:18.0
-3,10,25:18.0
0,10,25:18.0
1,10,25:17.0
2,10,25:18.0
-12,11,25:18.0
-10,11,25:17.0
-9,11,25:17.0
-7,11,25:18.0
-6,11,25:17.0
-5,11,25:17.0
-4,11,25:18.0
-3,11,25:18.0
1,11,25:18.0
2,11,25:18.0
4,11,25:18.0
5,11,25:18.0
6,11,25:18.0
7,11,25:18.0
8,11,25:18.0
10,11,25:18.0
-11,12,25:18.0
-10,12,25:18.0
-6,12,25:17.0
-5,12,25:17.0
0,12,25:18.0
1,12,25:18.0
4,12,25:18.0
5,12,25:18.0
6,12,25:18.0
7,12,25:18.0
8,12,25:18.0
9,12,25:18.0
11,12,25:18.0
-8,13,25:18.0
-7,13,25:17.0
-6,13,25:17.0
-5,13,25:17.0
4,13,25:18.0
5,13,25:18.0
6,13,25:18.0
7,13,25:18.0
8,13,25:17.0
9,13,25:18.0
10,13,25:18.0
11,13,25:18.0
-8,14,25:18.0
-7,14,25:17.0
-6,14,25:17.0
5,14,25:18.0
6,14,25:18.0
7,14,25:18.0
8,14,25:18.0
9,14,25:18.0
10,14,25:18.0
11,14,25:18.0
-8,15,25:18.0
-7,15,25:18.0
-6,15,25:18.0
3,15,25:17.0
4,15,25:18.0
5,15,25:18.0
6,15,25:18.0
7,15,25:17.0
8,15,25:18.0
9,15,25:18.0
3,16,25:18.0
5,16,25:18.0
6,16,25:18.0
7,16,25:17.0
8,16,25:17.0
9,16,25:18.0
10,16,25:18.0
11,16,25:18.0
12,16,25:18.0
4,17,25:18.0
5,17,25:18.0
6,17,25:17.0
7,17,25:18.0
8,17,25:17.0
9,17,25:18.0
10,17,25:18.0
11,17,25:18.0
5,18,25:18.0
6,18,25:18.0
7,18,25:18.0
8,18,25:17.0
9,18,25:18.0
10,18,25:18.0
11,18,25:18.0
7,19,25:18.0
8,19,25:18.0
9,19,25:18.0
10,19,25:18.0
11,19,25:18.0
12,19,25:18.0
8,20,25:18.0
9,20,25:18.0
10,20,25:18.0
11,20,25:18.0
9,21,25:18.0
10,21,25:18.0
-11,-20,26:18.0
-10,-20,26:18.0
-11,-19,26:18.0
-9,-19,26:18.0
-7,-19,26:18.0
-9,-18,26:18.0
-8,-18,26:18.0
-7,-18,26:18.0
-6,-18,26:18.0
-5,-18,26:18.0
-10,-17,26:18.0
-9,-17,26:18.0
-8,-17,26:17.0
-7,-17,26:18.0
-6,-17,26:17.0
-5,-17,26:18.0
-4,-17,26:18.0
-10,-16,26:18.0
-9,-16,26:18.0
-8,-16,26:18.0
-7,-16,26:18.0
-6,-16,26:18.0
-5,-16,26:18.0
-4,-16,26:18.0
1,-16,26:18.0
2,-16,26:18.0
9,-16,26:18.0
-10,-15,26:18.0
-9,-15,26:18.0
-8,-15,26:18.0
-7,-15,26:18.0
-6,-15,26:18.0
-5,-15,26:18.0
-4,-15,26:18.0
1,-15,26:18.0
3,-15,26:18.0
4,-15,26:18.0
5,-15,26:18.0
8,-15,26:18.0
9,-15,26:18.0
-11,-14,26:18.0
-10,-14,26:18.0
-9,-14,26:18.0
-8,-14,26:17.0
-7,-14,26:18.0
-5,-14,26:17.0
-4,-14,26:18.0
3,-14,26:18.0
5,-14,26:18.0
6,-14,26:17.0
8,-14,26:17.0
9,-14,26:17.0
10,-14,26:18.0
-11,-13,26:18.0
-10,-13,26:18.0
-9,-13,26:17.0
-8,-13,26:18.0
-7,-13,26:18.0
-6,-13,26:18.0
-5,-13,26:18.0
3,-13,26:18.0
4,-13,26:18.0
5,-13,26:17.0
6,-13,26:17.0
7,-13,26:17.0
8,-13,26:17.0
10,-13,26:18.0
-10,-12,26:18.0
-9,-12,26:18.0
-8,-12,26:18.0
-7,-12,26:18.0
1,-12,26:18.0
2,-12,26:18.0
3,-12,26:18.0
4,-12,26:17.0
5,-12,26:17.0
6,-12,26:17.0
-9,-11,26:18.0
-8,-11,26:18.0
-7,-11,26:18.0
1,-11,26:18.0
2,-11,26:17.0
3,-11,26:18.0
5,-11,26:17.0
-9,-10,26:18.0
-8,-10,26:18.0
-7,-10,26:17.0
-3,-10,26:18.0
-2,-10,26:18.0
1,-10,26:18.0
2,-10,26:18.0
3,-10,26:18.0
6,-10,26:17.0
9,-10,26:18.0
-9,-9,26:18.0
-7,-9,26:18.0
-5,-9,26:18.0
-4,-9,26:18.0
-3,-9,26:18.0
-2,-9,26:18.0
-1,-9,26:18.0
7,-9,26:18.0
8,-9,26:18.0
9,-9,26:18.0
-5,-8,26:18.0
-4,-8,26:18.0
-3,-8,26:17.0
-2,-8,26:18.0
-1,-8,26:18.0
7,-8,26:18.0
8,-8,26:18.0
-5,-7,26:18.0
-4,-7,26:18.0
-3,-7,26:18.0
-2,-7,26:18.0
-1,-7,26:18.0
8,-7,26:18.0
9,-7,26:18.0
10,-7,26:18.0
-4,-6,26:18.0
0,-6,26:18.0
1,-6,26:18.0
7,-6,26:18.0
8,-6,26:18.0
9,-6,26:18.0
10,-6,26:18.0
-1,-5,26:18.0
0,-5,26:17.0
1,-5,26:18.0
7,-5,26:18.0
8,-5,26:17.0
9,-5,26:18.0
10,-5,26:18.0
11,-5,26:18.0
-16,-4,26:17.0
-15,-4,26:17.0
-14,-4,26:17.0
-13,-4,26:17.0
4,-4,26:18.0
5,-4,26:18.0
7,-4,26:18.0
8,-4,26:18.0
9,-4,26:18.0
10,-4,26:18.0
-16,-3,26:18.0
-15,-3,26:17.0
-14,-3,26:17.0
-13,-3,26:17.0
-7,-3,26:17.0
-6,-3,26:17.0
2,-3,26:18.0
3,-3,26:18.0
4,-3,26:18.0
5,-3,26:18.0
8,-3,26:18.0
9,-3,26:18.0
10,-3,26:18.0
-16,-2,26:18.0
-15,-2,26:18.0
-13,-2,26:17.0
-10,-2,26:17.0
-7,-2,26:17.0
2,-2,26:18.0
3,-2,26:17.0
4,-2,26:17.0
5,-2,26:18.0
-16,-1,26:18.0
-15,-1,26:18.0
-14,-1,26:18.0
2,-1,26:17.0
3,-1,26:17.0
4,-1,26:17.0
5,-1,26:18.0
6,-1,26:18.0
-12,0,26:18.0
-11,0,26:18.0
3,0,26:17.0
4,0,26:18.0
5,0,26:18.0
-13,1,26:18.0
-12,1,26:18.0
-11,1,26:17.0
-10,1,26:18.0
-9,1,26:18.0
7,1,26:17.0
8,1,26:17.0
12,1,26:18.0
-13,2,26:18.0
-12,2,26:18.0
-11,2,26:17.0
-10,2,26:18.0
-9,2,26:18.0
-6,2,26:18.0
-5,2,26:18.0
11,2,26:18.0
12,2,26:17.0
13,2,26:18.0
-13,3,26:18.0
-12,3,26:18.0
-11,3,26:18.0
-10,3,26:18.0
-7,3,26:18.0
-6,3,26:17.0
-4,3,26:17.0
2,3,26:18.0
12,3,26:18.0
-12,4,26:18.0
-11,4,26:18.0
-10,4,26:18.0
-7,4,26:18.0
-4,4,26:17.0
-1,4,26:18.0
0,4,26:17.0
1,4,26:18.0
2,4,26:18.0
3,4,26:18.0
13,4,26:17.0
-1,5,26:18.0
0,5,26:17.0
1,5,26:17.0
2,5,26:18.0
3,5,26:18.0
12,5,26:17.0
13,5,26:17.0
14,5,26:17.0
15,5,26:17.0
0,6,26:18.0
1,6,26:18.0
2,6,26:18.0
3,6,26:18.0
8,6,26:18.0
9,6,26:17.0
14,6,26:17.0
15,6,26:17.0
17,6,26:18.0
0,7,26:18.0
1,7,26:18.0
9,7,26:17.0
10,7,26:18.0
13,7,26:18.0
14,7,26:18.0
16,7,26:18.0
17,7,26:18.0
19,7,26:18.0
9,8,26:18.0
10,8,26:18.0
13,8,26:18.0
14,8,26:18.0
16,8,26:18.0
18,8,26:18.0
19,8,26:18.0
-12,9,26:18.0
-11,9,26:18.0
-10,9,26:18.0
-6,9,26:18.0
-4,9,26:18.0
0,9,26:18.0
2,9,26:18.0
15,9,26:18.0
17,9,26:18.0
18,9,26:18.0
-13,10,26:18.0
-12,10,26:18.0
-11,10,26:18.0
-10,10,26:18.0
-6,10,26:18.0
-5,10,26:18.0
-4,10,26:18.0
-1,10,26:18.0
0,10,26:18.0
1,10,26:17.0
2,10,26:18.0
3,10,26:18.0
8,10,26:18.0
9,10,26:18.0
-13,11,26:18.0
-12,11,26:18.0
-11,11,26:17.0
-10,11,26:17.0
-6,11,26:18.0
-5,11,26:17.0
-4,11,26:18.0
-1,11,26:18.0
0,11,26:18.0
1,11,26:17.0
2,11,26:18.0
6,11,26:18.0
7,11,26:18.0
8,11,26:18.0
9,11,26:18.0
10,11,26:18.0
11,11,26:18.0
-13,12,26:18.0
-12,12,26:18.0
-11,12,26:18.0
-10,12,26:18.0
-9,12,26:18.0
-8,12,26:18.0
-6,12,26:18.0
0,12,26:18.0
1,12,26:18.0
2,12,26:18.0
3,12,26:18.0
6,12,26:18.0
7,12,26:18.0
8,12,26:18.0
9,12,26:18.0
10,12,26:18.0
11,12,26:18.0
12,12,26:18.0
-11,13,26:18.0
-10,13,26:18.0
-9,13,26:18.0
-8,13,26:18.0
-7,13,26:18.0
-6,13,26:17.0
-5,13,26:18.0
0,13,26:18.0
1,13,26:18.0
2,13,26:18.0
5,13,26:18.0
6,13,26:18.0
7,13,26:18.0
8,13,26:17.0
9,13,26:17.0
10,13,26:18.0
11,13,26:18.0
12,13,26:18.0
-8,14,26:18.0
-7,14,26:17.0
-6,14,26:17.0
-5,14,26:17.0
-4,14,26:17.0
-2,14,26:18.0
-1,14,26:18.0
3,14,26:18.0
6,14,26:18.0
7,14,26:18.0
8,14,26:18.0
9,14,26:18.0
10,14,26:18.0
11,14,26:18.0
-9,15,26:18.0
-8,15,26:18.0
-7,15,26:17.0
-6,15,26:17.0
-5,15,26:18.0
-3,15,26:18.0
-1,15,26:18.0
2,15,26:18.0
3,15,26:17.0
4,15,26:18.0
5,15,26:18.0
6,15,26:18.0
8,15,26:18.0
9,15,26:18.0
10,15,26:18.0
11,15,26:18.0
12,15,26:18.0
-8,16,26:18.0
-7,16,26:17.0
-6,16,26:18.0
-5,16,26:18.0
-3,16,26:18.0
-2,16,26:18.0
5,16,26:18.0
7,16,26:18.0
8,16,26:18.0
9,16,26:17.0
10,16,26:18.0
11,16,26:18.0
12,16,26:18.0
13,16,26:18.0
-6,17,26:18.0
4,17,26:18.0
5,17,26:18.0
6,17,26:17.0
7,17,26:18.0
9,17,26:18.0
10,17,26:18.0
11,17,26:18.0
12,17,26:18.0
5,18,26:18.0
7,18,26:18.0
8,18,26:17.0
9,18,26:18.0
10,18,26:18.0
11,18,26:18.0
12,18,26:18.0
6,19,26:18.0
7,19,26:18.0
8,19,26:18.0
9,19,26:17.0
10,19,26:18.0
11,19,26:18.0
12,19,26:18.0
13,19,26:18.0
6,20,26:18.0
7,20,26:18.0
8,20,26:18.0
9,20,26:18.0
10,20,26:18.0
11,20,26:18.0
12,20,26:18.0
7,21,26:18.0
8,21,26:18.0
9,21,26:18.0
10,21,26:18.0
11,21,26:18.0
8,22,26:18.0
9,22,26:18.0
10,22,26:18.0
9,23,26:18.0
-9,-22,27:18.0
-11,-21,27:18.0
-10,-21,27:18.0
-9,-21,27:18.0
-8,-21,27:18.0
-12,-20,27:18.0
-11,-20,27:18.0
-10,-20,27:18.0
-9,-20,27:18.0
-8,-20,27:18.0
-7,-20,27:18.0
-12,-19,27:18.0
-11,-19,27:18.0
-10,-19,27:18.0
-9,-19,27:18.0
-7,-19,27:18.0
-12,-18,27:18.0
-11,-18,27:18.0
-9,-18,27:17.0
-8,-18,27:18.0
-7,-18,27:18.0
-6,-18,27:18.0
-5,-18,27:18.0
-4,-18,27:18.0
3,-18,27:18.0
-11,-17,27:18.0
-9,-17,27:18.0
-8,-17,27:17.0
-7,-17,27:18.0
-6,-17,27:17.0
-5,-17,27:18.0
-4,-17,27:18.0
-3,-17,27:18.0
1,-17,27:18.0
2,-17,27:18.0
7,-17,27:17.0
8,-17,27:18.0
10,-17,27:18.0
-12,-16,27:18.0
-11,-16,27:18.0
-10,-16,27:18.0
-8,-16,27:18.0
-7,-16,27:18.0
-6,-16,27:18.0
-5,-16,27:18.0
-4,-16,27:18.0
-3,-16,27:18.0
0,-16,27:18.0
1,-16,27:18.0
2,-16,27:18.0
3,-16,27:18.0
4,-16,27:18.0
5,-16,27:18.0
6,-16,27:17.0
7,-16,27:17.0
9,-16,27:18.0
10,-16,27:18.0
11,-16,27:18.0
-10,-15,27:18.0
-8,-15,27:18.0
-4,-15,27:18.0
-3,-15,27:18.0
-2,-15,27:18.0
0,-15,27:18.0
1,-15,27:18.0
2,-15,27:18.0
3,-15,27:18.0
4,-15,27:18.0
5,-15,27:18.0
6,-15,27:17.0
7,-15,27:18.0
8,-15,27:18.0
9,-15,27:18.0
10,-15,27:18.0
11,-15,27:18.0
12,-15,27:18.0
-10,-14,27:18.0
-9,-14,27:18.0
-8,-14,27:18.0
-7,-14,27:18.0
-5,-14,27:17.0
-3,-14,27:18.0
-1,-14,27:18.0
1,-14,27:18.0
2,-14,27:18.0
3,-14,27:18.0
4,-14,27:17.0
5,-14,27:18.0
6,-14,27:17.0
8,-14,27:18.0
9,-14,27:17.0
10,-14,27:18.0
11,-14,27:18.0
12,-14,27:18.0
-10,-13,27:18.0
-9,-13,27:17.0
-8,-13,27:18.0
2,-13,27:18.0
3,-13,27:18.0
4,-13,27:18.0
5,-13,27:18.0
7,-13,27:18.0
8,-13,27:18.0
9,-13,27:18.0
10,-13,27:18.0
11,-13,27:18.0
12,-13,27:18.0
-9,-12,27:18.0
-8,-12,27:18.0
-7,-12,27:18.0
3,-12,27:18.0
4,-12,27:18.0
5,-12,27:18.0
8,-12,27:18.0
9,-12,27:18.0
10,-12,27:18.0
11,-12,27:18.0
-10,-11,27:18.0
-9,-11,27:18.0
-8,-11,27:18.0
-7,-11,27:18.0
2,-11,27:17.0
-10,-10,27:18.0
-9,-10,27:18.0
-8,-10,27:17.0
-7,-10,27:18.0
-6,-10,27:18.0
6,-10,27:17.0
-10,-9,27:18.0
-9,-9,27:18.0
-8,-9,27:18.0
-7,-9,27:18.0
-4,-9,27:18.0
-3,-9,27:18.0
-2,-9,27:18.0
-9,-8,27:18.0
-8,-8,27:18.0
-7,-8,27:18.0
-4,-8,27:18.0
-3,-8,27:17.0
-2,-8,27:18.0
-4,-7,27:18.0
-3,-7,27:18.0
-2,-7,27:18.0
8,-7,27:18.0
-14,-6,27:18.0
8,-6,27:18.0
9,-6,27:18.0
10,-6,27:18.0
-14,-5,27:18.0
-13,-5,27:18.0
-12,-5,27:18.0
0,-5,27:17.0
7,-5,27:18.0
8,-5,27:18.0
9,-5,27:17.0
10,-5,27:18.0
-17,-4,27:17.0
-16,-4,27:17.0
-15,-4,27:17.0
-14,-4,27:18.0
-13,-4,27:17.0
8,-4,27:18.0
9,-4,27:18.0
10,-4,27:18.0
11,-4,27:18.0
-17,-3,27:18.0
-16,-3,27:18.0
-15,-3,27:17.0
-14,-3,27:18.0
-13,-3,27:18.0
-6,-3,27:17.0
3,-3,27:17.0
4,-3,27:18.0
5,-3,27:18.0
9,-3,27:18.0
10,-3,27:18.0
-17,-2,27:18.0
-16,-2,27:17.0
-15,-2,27:17.0
-14,-2,27:18.0
-13,-2,27:18.0
-10,-2,27:17.0
3,-2,27:17.0
4,-2,27:17.0
-17,-1,27:18.0
-16,-1,27:18.0
-15,-1,27:18.0
-14,-1,27:18.0
-13,-1,27:18.0
2,-1,27:18.0
3,-1,27:17.0
4,-1,27:17.0
5,-1,27:18.0
-16,0,27:18.0
-15,0,27:18.0
-14,0,27:18.0
1,0,27:18.0
2,0,27:18.0
3,0,27:18.0
11,0,27:18.0
12,0,27:18.0
13,0,27:18.0
-12,1,27:18.0
-11,1,27:18.0
-10,1,27:18.0
1,1,27:18.0
2,1,27:18.0
3,1,27:18.0
8,1,27:17.0
11,1,27:18.0
12,1,27:18.0
13,1,27:18.0
-12,2,27:18.0
-11,2,27:17.0
-10,2,27:18.0
12,2,27:17.0
-12,3,27:18.0
-11,3,27:18.0
-10,3,27:18.0
-6,3,27:17.0
-5,3,27:18.0
-3,3,27:18.0
16,3,27:18.0
17,3,27:18.0
18,3,27:18.0
-11,4,27:18.0
-9,4,27:18.0
-5,4,27:18.0
-4,4,27:17.0
-2,4,27:18.0
0,4,27:18.0
1,4,27:18.0
2,4,27:18.0
16,4,27:18.0
17,4,27:18.0
18,4,27:18.0
19,4,27:18.0
-11,5,27:18.0
-10,5,27:18.0
-5,5,27:18.0
-4,5,27:18.0
-3,5,27:18.0
0,5,27:18.0
1,5,27:17.0
2,5,27:17.0
3,5,27:18.0
4,5,27:18.0
13,5,27:18.0
14,5,27:18.0
15,5,27:17.0
16,5,27:17.0
17,5,27:18.0
18,5,27:18.0
19,5,27:18.0
-3,6,27:18.0
-2,6,27:18.0
0,6,27:18.0
1,6,27:18.0
2,6,27:17.0
3,6,27:18.0
12,6,27:18.0
13,6,27:18.0
14,6,27:18.0
15,6,27:17.0
16,6,27:17.0
17,6,27:18.0
18,6,27:18.0
19,6,27:18.0
20,6,27:18.0
0,7,27:18.0
1,7,27:18.0
2,7,27:18.0
3,7,27:18.0
4,7,27:18.0
8,7,27:18.0
9,7,27:17.0
12,7,27:18.0
13,7,27:18.0
14,7,27:18.0
15,7,27:18.0
16,7,27:18.0
17,7,27:18.0
18,7,27:18.0
19,7,27:18.0
1,8,27:18.0
2,8,27:18.0
3,8,27:18.0
9,8,27:18.0
13,8,27:18.0
14,8,27:18.0
15,8,27:18.0
16,8,27:18.0
17,8,27:18.0
18,8,27:18.0
19,8,27:18.0
9,9,27:18.0
10,9,27:18.0
14,9,27:18.0
15,9,27:18.0
16,9,27:18.0
17,9,27:18.0
18,9,27:18.0
-11,10,27:18.0
-10,10,27:18.0
0,10,27:18.0
1,10,27:18.0
7,10,27:18.0
8,10,27:18.0
9,10,27:18.0
10,10,27:18.0
11,10,27:18.0
15,10,27:18.0
16,10,27:18.0
17,10,27:18.0
18,10,27:18.0
-12,11,27:18.0
-11,11,27:17.0
-10,11,27:18.0
-5,11,27:17.0
0,11,27:18.0
1,11,27:17.0
6,11,27:18.0
7,11,27:18.0
8,11,27:18.0
9,11,27:18.0
10,11,27:18.0
11,11,27:18.0
-12,12,27:18.0
-10,12,27:18.0
0,12,27:18.0
1,12,27:18.0
6,12,27:18.0
7,12,27:18.0
8,12,27:18.0
9,12,27:18.0
10,12,27:18.0
11,12,27:18.0
12,12,27:18.0
-8,13,27:18.0
-7,13,27:18.0
-6,13,27:18.0
-2,13,27:18.0
-1,13,27:18.0
6,13,27:18.0
7,13,27:18.0
8,13,27:18.0
9,13,27:17.0
10,13,27:18.0
11,13,27:18.0
12,13,27:18.0
13,13,27:18.0
-8,14,27:18.0
-7,14,27:18.0
-6,14,27:18.0
-4,14,27:18.0
-3,14,27:17.0
-2,14,27:17.0
-1,14,27:18.0
0,14,27:18.0
4,14,27:17.0
7,14,27:18.0
8,14,27:18.0
9,14,27:18.0
10,14,27:18.0
11,14,27:18.0
12,14,27:18.0
-8,15,27:18.0
-7,15,27:17.0
-6,15,27:17.0
-4,15,27:18.0
-3,15,27:18.0
-2,15,27:17.0
-1,15,27:18.0
0,15,27:18.0
2,15,27:17.0
6,15,27:18.0
7,15,27:18.0
8,15,27:18.0
9,15,27:18.0
10,15,27:18.0
11,15,27:18.0
12,15,27:18.0
13,15,27:18.0
-7,16,27:17.0
-6,16,27:17.0
-4,16,27:18.0
-3,16,27:18.0
-2,16,27:18.0
-1,16,27:18.0
0,16,27:18.0
5,16,27:18.0
7,16,27:18.0
8,16,27:18.0
9,16,27:18.0
10,16,27:17.0
11,16,27:18.0
12,16,27:18.0
13,16,27:18.0
14,16,27:18.0
-7,17,27:17.0
-6,17,27:17.0
-3,17,27:18.0
-1,17,27:18.0
4,17,27:18.0
5,17,27:17.0
6,17,27:17.0
7,17,27:18.0
8,17,27:18.0
9,17,27:18.0
10,17,27:18.0
11,17,27:18.0
12,17,27:18.0
13,17,27:18.0
-8,18,27:18.0
-7,18,27:18.0
-6,18,27:18.0
5,18,27:18.0
6,18,27:18.0
7,18,27:18.0
8,18,27:18.0
9,18,27:18.0
10,18,27:18.0
11,18,27:18.0
12,18,27:18.0
-6,19,27:18.0
-5,19,27:18.0
6,19,27:18.0
7,19,27:18.0
8,19,27:18.0
9,19,27:17.0
10,19,27:18.0
11,19,27:18.0
12,19,27:18.0
-7,20,27:18.0
-6,20,27:18.0
-5,20,27:18.0
6,20,27:18.0
7,20,27:18.0
8,20,27:18.0
9,20,27:18.0
10,20,27:18.0
11,20,27:18.0
12,20,27:18.0
13,20,27:18.0
-10,21,27:18.0
-7,21,27:18.0
-6,21,27:18.0
-5,21,27:18.0
6,21,27:18.0
7,21,27:18.0
8,21,27:18.0
9,21,27:18.0
10,21,27:18.0
11,21,27:18.0
12,21,27:18.0
-7,22,27:18.0
8,22,27:18.0
9,22,27:18.0
10,22,27:18.0
11,22,27:18.0
-9,23,27:18.0
10,23,27:18.0
-11,-22,28:18.0
-10,-22,28:18.0
-9,-22,28:18.0
-8,-22,28:18.0
-7,-22,28:18.0
-12,-21,28:18.0
-11,-21,28:18.0
-10,-21,28:18.0
-9,-21,28:18.0
-8,-21,28:18.0
-6,-21,28:18.0
7,-21,28:18.0
-13,-20,28:18.0
-12,-20,28:18.0
-11,-20,28:18.0
-10,-20,28:18.0
-9,-20,28:18.0
-8,-20,28:18.0
-7,-20,28:18.0
-6,-20,28:18.0
7,-20,28:18.0
-13,-19,28:18.0
-12,-19,28:18.0
-11,-19,28:18.0
-10,-19,28:18.0
-9,-19,28:18.0
-8,-19,28:17.0
-7,-19,28:18.0
-6,-19,28:18.0
-4,-19,28:18.0
3,-19,28:18.0
6,-19,28:18.0
7,-19,28:18.0
-13,-18,28:18.0
-12,-18,28:18.0
-11,-18,28:18.0
-10,-18,28:18.0
-9,-18,28:17.0
-8,-18,28:18.0
-7,-18,28:18.0
-6,-18,28:18.0
-5,-18,28:18.0
-4,-18,28:18.0
-3,-18,28:18.0
-2,-18,28:18.0
1,-18,28:18.0
2,-18,28:18.0
3,-18,28:18.0
6,-18,28:18.0
7,-18,28:18.0
-12,-17,28:18.0
-11,-17,28:18.0
-10,-17,28:17.0
-9,-17,28:18.0
-8,-17,28:18.0
-7,-17,28:18.0
-6,-17,28:18.0
-5,-17,28:17.0
-4,-17,28:18.0
-3,-17,28:18.0
-2,-17,28:18.0
-1,-17,28:18.0
0,-17,28:18.0
1,-17,28:18.0
2,-17,28:18.0
3,-17,28:18.0
7,-17,28:17.0
8,-17,28:18.0
9,-17,28:18.0
10,-17,28:18.0
11,-17,28:18.0
-13,-16,28:18.0
-12,-16,28:18.0
-11,-16,28:17.0
-10,-16,28:18.0
-7,-16,28:18.0
-6,-16,28:18.0
-5,-16,28:18.0
-4,-16,28:18.0
-3,-16,28:18.0
-2,-16,28:18.0
-1,-16,28:18.0
0,-16,28:18.0
1,-16,28:18.0
2,-16,28:18.0
3,-16,28:18.0
4,-16,28:18.0
8,-16,28:18.0
9,-16,28:18.0
10,-16,28:18.0
11,-16,28:18.0
-12,-15,28:18.0
-11,-15,28:18.0
-10,-15,28:18.0
-9,-15,28:18.0
-6,-15,28:18.0
-5,-15,28:18.0
-4,-15,28:18.0
-3,-15,28:18.0
-2,-15,28:18.0
-1,-15,28:18.0
0,-15,28:18.0
1,-15,28:18.0
2,-15,28:18.0
3,-15,28:17.0
4,-15,28:18.0
5,-15,28:18.0
6,-15,28:18.0
7,-15,28:18.0
8,-15,28:18.0
9,-15,28:18.0
10,-15,28:18.0
11,-15,28:18.0
12,-15,28:18.0
-10,-14,28:18.0
-6,-14,28:18.0
-4,-14,28:17.0
-3,-14,28:18.0
-2,-14,28:18.0
-1,-14,28:18.0
0,-14,28:18.0
1,-14,28:18.0
2,-14,28:18.0
3,-14,28:18.0
4,-14,28:18.0
6,-14,28:17.0
7,-14,28:18.0
8,-14,28:18.0
9,-14,28:17.0
10,-14,28:18.0
11,-14,28:18.0
12,-14,28:18.0
-10,-13,28:18.0
-9,-13,28:17.0
-5,-13,28:18.0
-4,-13,28:18.0
-3,-13,28:18.0
1,-13,28:18.0
3,-13,28:18.0
7,-13,28:18.0
8,-13,28:18.0
9,-13,28:18.0
10,-13,28:18.0
11,-13,28:18.0
12,-13,28:18.0
-11,-12,28:18.0
-9,-12,28:18.0
7,-12,28:18.0
9,-12,28:18.0
10,-12,28:18.0
-10,-11,28:18.0
-9,-11,28:18.0
-8,-11,28:18.0
-7,-11,28:18.0
2,-11,28:17.0
6,-11,28:18.0
9,-11,28:18.0
-9,-10,28:18.0
-8,-10,28:17.0
-7,-10,28:18.0
5,-10,28:18.0
6,-10,28:17.0
7,-10,28:18.0
6,-9,28:18.0
-3,-8,28:18.0
-2,-8,28:17.0
-13,-7,28:18.0
-12,-7,28:18.0
-2,-7,28:18.0
-1,-7,28:18.0
-15,-6,28:18.0
-14,-6,28:18.0
-13,-6,28:18.0
-12,-6,28:18.0
-11,-6,28:18.0
-3,-6,28:18.0
-2,-6,28:18.0
-1,-6,28:18.0
8,-6,28:18.0
-18,-5,28:17.0
-17,-5,28:17.0
-15,-5,28:18.0
-14,-5,28:18.0
-13,-5,28:17.0
-12,-5,28:18.0
-11,-5,28:18.0
-6,-5,28:18.0
-5,-5,28:18.0
-4,-5,28:18.0
0,-5,28:17.0
8,-5,28:18.0
9,-5,28:18.0
10,-5,28:18.0
-17,-4,28:17.0
-14,-4,28:18.0
-13,-4,28:18.0
-12,-4,28:18.0
-11,-4,28:18.0
-6,-4,28:18.0
-5,-4,28:18.0
-4,-4,28:18.0
3,-4,28:17.0
8,-4,28:18.0
9,-4,28:18.0
10,-4,28:18.0
-15,-3,28:18.0
-14,-3,28:18.0
-13,-3,28:18.0
-12,-3,28:18.0
-6,-3,28:17.0
-5,-3,28:18.0
-4,-3,28:18.0
3,-3,28:18.0
5,-3,28:18.0
6,-3,28:17.0
-16,-2,28:17.0
-10,-2,28:17.0
-9,-2,28:18.0
-8,-2,28:18.0
1,-2,28:18.0
2,-2,28:18.0
3,-2,28:18.0
4,-2,28:17.0
5,-2,28:17.0
6,-2,28:17.0
12,-2,28:18.0
-16,-1,28:18.0
-15,-1,28:18.0
-14,-1,28:18.0
-8,-1,28:18.0
0,-1,28:18.0
1,-1,28:18.0
2,-1,28:18.0
3,-1,28:17.0
4,-1,28:17.0
11,-1,28:18.0
12,-1,28:18.0
13,-1,28:18.0
-16,0,28:18.0
-10,0,28:18.0
0,0,28:18.0
1,0,28:18.0
2,0,28:17.0
3,0,28:18.0
4,0,28:18.0
8,0,28:18.0
10,0,28:18.0
11,0,28:18.0
12,0,28:18.0
13,0,28:18.0
14,0,28:18.0
-7,1,28:18.0
-6,1,28:18.0
-5,1,28:18.0
1,1,28:18.0
2,1,28:18.0
3,1,28:18.0
4,1,28:18.0
8,1,28:17.0
9,1,28:18.0
10,1,28:18.0
11,1,28:18.0
12,1,28:17.0
13,1,28:18.0
14,1,28:18.0
17,1,28:18.0
-11,2,28:17.0
-10,2,28:18.0
-7,2,28:18.0
-4,2,28:18.0
-3,2,28:18.0
1,2,28:18.0
2,2,28:18.0
3,2,28:18.0
7,2,28:17.0
8,2,28:18.0
10,2,28:18.0
11,2,28:18.0
12,2,28:17.0
13,2,28:18.0
14,2,28:18.0
15,2,28:18.0
16,2,28:18.0
17,2,28:18.0
18,2,28:18.0
-12,3,28:18.0
-11,3,28:18.0
-10,3,28:18.0
-9,3,28:18.0
-8,3,28:18.0
-7,3,28:18.0
-6,3,28:17.0
-5,3,28:18.0
-4,3,28:18.0
-3,3,28:18.0
-2,3,28:18.0
11,3,28:18.0
12,3,28:18.0
15,3,28:18.0
16,3,28:18.0
17,3,28:18.0
18,3,28:18.0
19,3,28:18.0
-12,4,28:18.0
-11,4,28:18.0
-10,4,28:18.0
-9,4,28:18.0
-8,4,28:18.0
-7,4,28:18.0
-5,4,28:18.0
-4,4,28:17.0
-3,4,28:17.0
-2,4,28:18.0
-1,4,28:18.0
14,4,28:18.0
15,4,28:18.0
16,4,28:18.0
17,4,28:18.0
18,4,28:18.0
19,4,28:18.0
20,4,28:18.0
-11,5,28:18.0
-10,5,28:18.0
-9,5,28:18.0
-8,5,28:18.0
-6,5,28:18.0
-5,5,28:18.0
-4,5,28:18.0
-3,5,28:17.0
-2,5,28:18.0
-1,5,28:18.0
1,5,28:18.0
2,5,28:18.0
3,5,28:18.0
4,5,28:18.0
13,5,28:18.0
14,5,28:18.0
15,5,28:18.0
16,5,28:18.0
17,5,28:17.0
18,5,28:18.0
19,5,28:18.0
20,5,28:18.0
-11,6,28:18.0
-8,6,28:18.0
-7,6,28:18.0
-5,6,28:18.0
-4,6,28:18.0
-3,6,28:18.0
-2,6,28:18.0
-1,6,28:18.0
1,6,28:18.0
2,6,28:17.0
3,6,28:18.0
4,6,28:18.0
13,6,28:18.0
14,6,28:18.0
15,6,28:18.0
16,6,28:18.0
17,6,28:18.0
18,6,28:18.0
19,6,28:18.0
20,6,28:18.0
-4,7,28:18.0
-3,7,28:18.0
-2,7,28:18.0
1,7,28:18.0
2,7,28:18.0
3,7,28:18.0
9,7,28:17.0
10,7,28:17.0
12,7,28:18.0
13,7,28:18.0
14,7,28:18.0
15,7,28:17.0
16,7,28:18.0
17,7,28:17.0
18,7,28:18.0
19,7,28:18.0
20,7,28:18.0
21,7,28:18.0
2,8,28:18.0
3,8,28:18.0
9,8,28:17.0
12,8,28:18.0
13,8,28:18.0
14,8,28:18.0
15,8,28:18.0
16,8,28:18.0
17,8,28:18.0
18,8,28:18.0
19,8,28:18.0
20,8,28:18.0
21,8,28:18.0
-12,9,28:18.0
8,9,28:18.0
9,9,28:17.0
10,9,28:18.0
12,9,28:18.0
13,9,28:18.0
14,9,28:18.0
15,9,28:18.0
16,9,28:18.0
17,9,28:18.0
18,9,28:18.0
19,9,28:18.0
20,9,28:18.0
-12,10,28:18.0
-11,10,28:18.0
-5,10,28:18.0
-4,10,28:18.0
-1,10,28:18.0
1,10,28:18.0
7,10,28:18.0
8,10,28:18.0
9,10,28:18.0
10,10,28:18.0
11,10,28:18.0
12,10,28:18.0
14,10,28:18.0
15,10,28:18.0
16,10,28:18.0
17,10,28:18.0
18,10,28:18.0
-12,11,28:18.0
-11,11,28:17.0
-6,11,28:18.0
-5,11,28:17.0
-4,11,28:18.0
-1,11,28:18.0
0,11,28:18.0
1,11,28:17.0
6,11,28:18.0
7,11,28:18.0
8,11,28:18.0
9,11,28:18.0
10,11,28:18.0
11,11,28:18.0
12,11,28:18.0
15,11,28:18.0
18,11,28:18.0
-6,12,28:18.0
-5,12,28:18.0
-4,12,28:18.0
-1,12,28:18.0
6,12,28:18.0
7,12,28:18.0
8,12,28:18.0
9,12,28:18.0
10,12,28:18.0
11,12,28:18.0
12,12,28:18.0
13,12,28:18.0
5,13,28:17.0
6,13,28:18.0
7,13,28:18.0
8,13,28:18.0
9,13,28:17.0
10,13,28:17.0
11,13,28:18.0
12,13,28:18.0
13,13,28:18.0
-8,14,28:18.0
-2,14,28:18.0
-1,14,28:18.0
5,14,28:18.0
6,14,28:18.0
7,14,28:18.0
8,14,28:18.0
9,14,28:18.0
10,14,28:18.0
11,14,28:18.0
12,14,28:18.0
13,14,28:18.0
-12,15,28:18.0
-11,15,28:18.0
-10,15,28:18.0
-9,15,28:18.0
-7,15,28:18.0
-3,15,28:18.0
-2,15,28:17.0
-1,15,28:17.0
0,15,28:18.0
2,15,28:17.0
3,15,28:18.0
6,15,28:18.0
7,15,28:18.0
8,15,28:18.0
9,15,28:18.0
10,15,28:18.0
11,15,28:18.0
12,15,28:18.0
13,15,28:18.0
-12,16,28:18.0
-11,16,28:18.0
-10,16,28:18.0
-9,16,28:17.0
-8,16,28:17.0
-7,16,28:18.0
-2,16,28:18.0
-1,16,28:18.0
0,16,28:18.0
1,16,28:18.0
2,16,28:18.0
4,16,28:18.0
6,16,28:18.0
7,16,28:18.0
8,16,28:18.0
9,16,28:18.0
10,16,28:17.0
11,16,28:18.0
12,16,28:18.0
13,16,28:18.0
14,16,28:18.0
-12,17,28:18.0
-11,17,28:18.0
-10,17,28:18.0
-9,17,28:18.0
-8,17,28:18.0
-7,17,28:18.0
-2,17,28:18.0
-1,17,28:18.0
1,17,28:18.0
2,17,28:18.0
3,17,28:18.0
4,17,28:18.0
5,17,28:17.0
7,17,28:18.0
8,17,28:18.0
9,17,28:18.0
10,17,28:18.0
11,17,28:18.0
12,17,28:18.0
13,17,28:18.0
-11,18,28:18.0
-8,18,28:18.0
-7,18,28:17.0
-6,18,28:17.0
-5,18,28:18.0
2,18,28:18.0
3,18,28:18.0
7,18,28:17.0
8,18,28:18.0
9,18,28:18.0
10,18,28:18.0
11,18,28:18.0
12,18,28:18.0
-8,19,28:18.0
-7,19,28:17.0
-6,19,28:18.0
-5,19,28:18.0
-3,19,28:18.0
6,19,28:18.0
7,19,28:18.0
8,19,28:18.0
9,19,28:18.0
10,19,28:18.0
11,19,28:18.0
12,19,28:18.0
13,19,28:18.0
-11,20,28:18.0
-10,20,28:18.0
-9,20,28:18.0
-7,20,28:18.0
-6,20,28:18.0
-5,20,28:18.0
-4,20,28:18.0
5,20,28:18.0
6,20,28:18.0
7,20,28:18.0
8,20,28:18.0
9,20,28:18.0
10,20,28:17.0
11,20,28:18.0
12,20,28:18.0
-10,21,28:18.0
-9,21,28:18.0
-8,21,28:18.0
-7,21,28:18.0
-6,21,28:18.0
-5,21,28:18.0
-4,21,28:18.0
7,21,28:18.0
8,21,28:18.0
9,21,28:18.0
10,21,28:18.0
11,21,28:18.0
12,21,28:18.0
13,21,28:18.0
-10,22,28:18.0
-9,22,28:18.0
-8,22,28:18.0
-7,22,28:18.0
-6,22,28:18.0
-5,22,28:18.0
7,22,28:18.0
8,22,28:18.0
9,22,28:18.0
10,22,28:18.0
11,22,28:18.0
-10,23,28:18.0
-9,23,28:18.0
-8,23,28:18.0
-7,23,28:18.0
-6,23,28:18.0
9,23,28:18.0
10,23,28:18.0
11,23,28:18.0
-9,24,28:18.0
-8,24,28:18.0
-7,24,28:18.0
-11,-23,29:18.0
-10,-23,29:18.0
-12,-22,29:18.0
-11,-22,29:18.0
-10,-22,29:18.0
-9,-22,29:18.0
-8,-22,29:18.0
-13,-21,29:18.0
-12,-21,29:18.0
-11,-21,29:18.0
-10,-21,29:18.0
-9,-21,29:18.0
-8,-21,29:18.0
-7,-21,29:18.0
7,-21,29:18.0
-14,-20,29:18.0
-13,-20,29:18.0
-12,-20,29:18.0
-11,-20,29:18.0
-10,-20,29:18.0
-9,-20,29:18.0
-8,-20,29:18.0
-7,-20,29:18.0
-6,-20,29:18.0
-5,-20,29:18.0
6,-20,29:18.0
7,-20,29:18.0
8,-20,29:18.0
-14,-19,29:18.0
-13,-19,29:18.0
-12,-19,29:18.0
-11,-19,29:18.0
-10,-19,29:17.0
-9,-19,29:18.0
-8,-19,29:18.0
-7,-19,29:18.0
-6,-19,29:18.0
-5,-19,29:18.0
1,-19,29:18.0
2,-19,29:18.0
5,-19,29:18.0
6,-19,29:18.0
7,-19,29:18.0
8,-19,29:18.0
9,-19,29:18.0
-13,-18,29:18.0
-12,-18,29:18.0
-11,-18,29:18.0
-10,-18,29:18.0
-9,-18,29:17.0
-8,-18,29:18.0
-7,-18,29:18.0
-6,-18,29:18.0
-5,-18,29:18.0
-4,-18,29:18.0
-3,-18,29:18.0
0,-18,29:18.0
1,-18,29:18.0
2,-18,29:18.0
3,-18,29:18.0
4,-18,29:18.0
5,-18,29:18.0
6,-18,29:18.0
7,-18,29:18.0
8,-18,29:18.0
9,-18,29:18.0
10,-18,29:18.0
-13,-17,29:18.0
-12,-17,29:18.0
-11,-17,29:18.0
-10,-17,29:18.0
-9,-17,29:18.0
-8,-17,29:18.0
-7,-17,29:18.0
-6,-17,29:18.0
-5,-17,29:18.0
-4,-17,29:18.0
-3,-17,29:18.0
-2,-17,29:18.0
-1,-17,29:18.0
0,-17,29:18.0
1,-17,29:18.0
2,-17,29:18.0
3,-17,29:18.0
5,-17,29:18.0
6,-17,29:18.0
7,-17,29:17.0
8,-17,29:18.0
9,-17,29:18.0
10,-17,29:18.0
11,-17,29:18.0
-12,-16,29:18.0
-11,-16,29:18.0
-10,-16,29:18.0
-7,-16,29:18.0
-6,-16,29:18.0
-5,-16,29:18.0
-4,-16,29:18.0
-3,-16,29:18.0
-2,-16,29:18.0
-1,-16,29:18.0
0,-16,29:18.0
1,-16,29:18.0
2,-16,29:18.0
3,-16,29:18.0
6,-16,29:18.0
7,-16,29:18.0
8,-16,29:18.0
9,-16,29:18.0
10,-16,29:18.0
11,-16,29:18.0
12,-16,29:18.0
-13,-15,29:18.0
-12,-15,29:18.0
-11,-15,29:18.0
-10,-15,29:18.0
-6,-15,29:18.0
-5,-15,29:18.0
-4,-15,29:18.0
-3,-15,29:18.0
-2,-15,29:18.0
-1,-15,29:18.0
0,-15,29:18.0
1,-15,29:18.0
2,-15,29:17.0
3,-15,29:18.0
4,-15,29:18.0
6,-15,29:18.0
7,-15,29:18.0
8,-15,29:18.0
9,-15,29:18.0
10,-15,29:18.0
11,-15,29:18.0
12,-15,29:18.0
13,-15,29:18.0
-14,-14,29:18.0
-11,-14,29:18.0
-10,-14,29:18.0
-9,-14,29:18.0
-8,-14,29:18.0
-7,-14,29:18.0
-6,-14,29:18.0
-5,-14,29:18.0
-4,-14,29:17.0
-3,-14,29:18.0
-2,-14,29:18.0
-1,-14,29:18.0
0,-14,29:18.0
1,-14,29:18.0
2,-14,29:18.0
7,-14,29:18.0
8,-14,29:18.0
9,-14,29:18.0
10,-14,29:17.0
11,-14,29:18.0
12,-14,29:18.0
-14,-13,29:18.0
-13,-13,29:18.0
-12,-13,29:18.0
-11,-13,29:18.0
-10,-13,29:18.0
-9,-13,29:18.0
-8,-13,29:18.0
-7,-13,29:18.0
-6,-13,29:18.0
-5,-13,29:18.0
-4,-13,29:18.0
-3,-13,29:18.0
-2,-13,29:18.0
-1,-13,29:18.0
0,-13,29:18.0
1,-13,29:18.0
6,-13,29:17.0
7,-13,29:18.0
8,-13,29:18.0
9,-13,29:18.0
10,-13,29:18.0
11,-13,29:18.0
12,-13,29:18.0
13,-13,29:18.0
-12,-12,29:18.0
-11,-12,29:18.0
-10,-12,29:17.0
-9,-12,29:18.0
-8,-12,29:18.0
-4,-12,29:18.0
-3,-12,29:18.0
7,-12,29:18.0
8,-12,29:18.0
9,-12,29:18.0
10,-12,29:18.0
11,-12,29:18.0
12,-12,29:18.0
-12,-11,29:18.0
-11,-11,29:18.0
-10,-11,29:18.0
-9,-11,29:18.0
-8,-11,29:18.0
-7,-11,29:17.0
2,-11,29:17.0
6,-11,29:18.0
9,-11,29:18.0
10,-11,29:18.0
11,-11,29:18.0
-11,-10,29:18.0
-10,-10,29:18.0
-8,-10,29:17.0
-2,-10,29:18.0
-1,-10,29:18.0
0,-10,29:18.0
5,-10,29:18.0
6,-10,29:17.0
7,-10,29:18.0
-8,-9,29:17.0
-3,-9,29:18.0
-2,-9,29:18.0
0,-9,29:18.0
6,-9,29:18.0
-15,-8,29:18.0
-14,-8,29:18.0
-4,-8,29:18.0
-3,-8,29:18.0
-2,-8,29:17.0
-1,-8,29:18.0
0,-8,29:18.0
-22,-7,29:18.0
-21,-7,29:18.0
-20,-7,29:18.0
-14,-7,29:18.0
-13,-7,29:18.0
-4,-7,29:18.0
-3,-7,29:18.0
-2,-7,29:18.0
-1,-7,29:18.0
0,-7,29:18.0
2,-7,29:18.0
-21,-6,29:18.0
-20,-6,29:17.0
-19,-6,29:17.0
-17,-6,29:17.0
-15,-6,29:18.0
-14,-6,29:18.0
-13,-6,29:17.0
-12,-6,29:18.0
-6,-6,29:18.0
-4,-6,29:18.0
-3,-6,29:18.0
-2,-6,29:18.0
-1,-6,29:18.0
0,-6,29:18.0
1,-6,29:18.0
2,-6,29:18.0
3,-6,29:18.0
-22,-5,29:18.0
-20,-5,29:18.0
-19,-5,29:17.0
-14,-5,29:18.0
-12,-5,29:18.0
-8,-5,29:18.0
-7,-5,29:18.0
-6,-5,29:18.0
-5,-5,29:18.0
-4,-5,29:18.0
-3,-5,29:18.0
-1,-5,29:18.0
3,-5,29:17.0
8,-5,29:18.0
9,-5,29:18.0
-20,-4,29:18.0
-19,-4,29:18.0
-18,-4,29:18.0
-13,-4,29:17.0
-8,-4,29:18.0
-7,-4,29:18.0
-6,-4,29:18.0
-5,-4,29:17.0
-4,-4,29:18.0
-3,-4,29:18.0
7,-4,29:18.0
8,-4,29:18.0
9,-4,29:18.0
10,-4,29:18.0
-20,-3,29:18.0
-19,-3,29:18.0
-18,-3,29:18.0
-10,-3,29:18.0
-6,-3,29:17.0
-5,-3,29:18.0
-4,-3,29:18.0
-3,-3,29:18.0
4,-3,29:18.0
6,-3,29:17.0
7,-3,29:17.0
9,-3,29:18.0
10,-3,29:18.0
12,-3,29:18.0
-16,-2,29:17.0
-11,-2,29:18.0
-10,-2,29:17.0
-9,-2,29:18.0
-8,-2,29:18.0
-7,-2,29:18.0
-5,-2,29:18.0
-4,-2,29:18.0
4,-2,29:17.0
5,-2,29:18.0
8,-2,29:18.0
9,-2,29:18.0
11,-2,29:18.0
12,-2,29:18.0
-16,-1,29:18.0
-15,-1,29:18.0
-10,-1,29:18.0
-9,-1,29:17.0
-8,-1,29:18.0
-7,-1,29:18.0
1,-1,29:18.0
3,-1,29:18.0
4,-1,29:18.0
8,-1,29:18.0
10,-1,29:18.0
11,-1,29:18.0
12,-1,29:18.0
13,-1,29:18.0
14,-1,29:18.0
-16,0,29:18.0
-11,0,29:18.0
-10,0,29:18.0
-9,0,29:18.0
-8,0,29:18.0
-7,0,29:18.0
-6,0,29:18.0
-5,0,29:18.0
2,0,29:17.0
3,0,29:18.0
7,0,29:18.0
8,0,29:18.0
9,0,29:18.0
10,0,29:18.0
11,0,29:18.0
12,0,29:18.0
13,0,29:18.0
14,0,29:18.0
-11,1,29:18.0
-10,1,29:18.0
-9,1,29:18.0
-8,1,29:18.0
-7,1,29:18.0
-6,1,29:18.0
-5,1,29:18.0
-4,1,29:18.0
1,1,29:18.0
8,1,29:18.0
9,1,29:17.0
10,1,29:18.0
11,1,29:18.0
12,1,29:17.0
13,1,29:18.0
14,1,29:18.0
16,1,29:18.0
17,1,29:18.0
-13,2,29:18.0
-12,2,29:18.0
-11,2,29:17.0
-10,2,29:18.0
-9,2,29:18.0
-8,2,29:18.0
-7,2,29:18.0
-6,2,29:17.0
-5,2,29:18.0
7,2,29:17.0
8,2,29:18.0
9,2,29:18.0
10,2,29:18.0
11,2,29:18.0
12,2,29:18.0
16,2,29:18.0
17,2,29:18.0
18,2,29:18.0
-13,3,29:18.0
-12,3,29:18.0
-11,3,29:18.0
-10,3,29:18.0
-9,3,29:18.0
-8,3,29:18.0
-7,3,29:18.0
-6,3,29:18.0
-5,3,29:18.0
-4,3,29:18.0
-3,3,29:18.0
6,3,29:18.0
7,3,29:18.0
8,3,29:18.0
9,3,29:18.0
10,3,29:18.0
14,3,29:18.0
15,3,29:18.0
16,3,29:18.0
17,3,29:18.0
18,3,29:18.0
19,3,29:18.0
-13,4,29:18.0
-12,4,29:18.0
-11,4,29:18.0
-10,4,29:18.0
-9,4,29:18.0
-8,4,29:18.0
-7,4,29:17.0
-6,4,29:18.0
-5,4,29:18.0
-4,4,29:18.0
-3,4,29:18.0
-2,4,29:18.0
3,4,29:18.0
6,4,29:18.0
7,4,29:18.0
8,4,29:18.0
14,4,29:18.0
15,4,29:18.0
16,4,29:18.0
17,4,29:18.0
18,4,29:18.0
19,4,29:18.0
20,4,29:18.0
-12,5,29:18.0
-11,5,29:18.0
-10,5,29:18.0
-9,5,29:18.0
-8,5,29:18.0
-7,5,29:18.0
-6,5,29:18.0
-5,5,29:18.0
-4,5,29:18.0
-3,5,29:17.0
-2,5,29:18.0
2,5,29:17.0
3,5,29:17.0
4,5,29:18.0
13,5,29:18.0
14,5,29:18.0
15,5,29:18.0
16,5,29:18.0
17,5,29:17.0
18,5,29:18.0
19,5,29:18.0
20,5,29:18.0
-11,6,29:18.0
-9,6,29:18.0
-8,6,29:18.0
-7,6,29:18.0
-5,6,29:18.0
-4,6,29:18.0
-3,6,29:18.0
-2,6,29:18.0
1,6,29:18.0
2,6,29:17.0
3,6,29:18.0
4,6,29:18.0
11,6,29:17.0
12,6,29:18.0
13,6,29:18.0
14,6,29:18.0
15,6,29:18.0
16,6,29:18.0
17,6,29:18.0
18,6,29:18.0
19,6,29:18.0
20,6,29:18.0
-8,7,29:18.0
-7,7,29:18.0
-6,7,29:18.0
1,7,29:18.0
2,7,29:18.0
3,7,29:17.0
4,7,29:18.0
10,7,29:17.0
12,7,29:18.0
13,7,29:18.0
14,7,29:18.0
15,7,29:17.0
16,7,29:18.0
17,7,29:18.0
18,7,29:18.0
19,7,29:18.0
20,7,29:18.0
21,7,29:18.0
-11,8,29:18.0
-10,8,29:18.0
1,8,29:18.0
2,8,29:18.0
3,8,29:18.0
4,8,29:18.0
5,8,29:18.0
10,8,29:18.0
12,8,29:18.0
13,8,29:18.0
14,8,29:18.0
15,8,29:18.0
16,8,29:18.0
17,8,29:18.0
18,8,29:17.0
19,8,29:18.0
20,8,29:18.0
21,8,29:18.0
-12,9,29:18.0
-11,9,29:18.0
-10,9,29:18.0
-6,9,29:18.0
-5,9,29:18.0
-4,9,29:18.0
-1,9,29:18.0
1,9,29:18.0
2,9,29:18.0
3,9,29:18.0
4,9,29:18.0
8,9,29:18.0
9,9,29:17.0
10,9,29:18.0
11,9,29:18.0
12,9,29:18.0
13,9,29:18.0
14,9,29:18.0
15,9,29:18.0
16,9,29:18.0
17,9,29:18.0
18,9,29:18.0
19,9,29:18.0
20,9,29:18.0
-13,10,29:18.0
-12,10,29:17.0
-11,10,29:18.0
-7,10,29:18.0
-6,10,29:18.0
-5,10,29:18.0
-4,10,29:17.0
-3,10,29:18.0
-2,10,29:18.0
-1,10,29:18.0
0,10,29:18.0
1,10,29:18.0
4,10,29:18.0
5,10,29:18.0
6,10,29:18.0
7,10,29:18.0
8,10,29:18.0
9,10,29:18.0
10,10,29:18.0
11,10,29:18.0
12,10,29:18.0
14,10,29:18.0
15,10,29:18.0
16,10,29:18.0
17,10,29:18.0
18,10,29:18.0
19,10,29:18.0
20,10,29:18.0
-12,11,29:18.0
-11,11,29:17.0
-7,11,29:18.0
-6,11,29:18.0
-5,11,29:17.0
-4,11,29:18.0
-2,11,29:18.0
-1,11,29:18.0
0,11,29:17.0
1,11,29:18.0
4,11,29:18.0
5,11,29:18.0
6,11,29:18.0
7,11,29:18.0
8,11,29:18.0
9,11,29:18.0
10,11,29:18.0
11,11,29:18.0
12,11,29:18.0
15,11,29:18.0
18,11,29:18.0
19,11,29:18.0
-13,12,29:18.0
-12,12,29:18.0
-7,12,29:18.0
-6,12,29:18.0
-5,12,29:17.0
-4,12,29:18.0
-2,12,29:18.0
-1,12,29:18.0
0,12,29:18.0
1,12,29:18.0
2,12,29:17.0
4,12,29:18.0
5,12,29:18.0
6,12,29:17.0
7,12,29:18.0
8,12,29:18.0
9,12,29:18.0
10,12,29:18.0
11,12,29:18.0
12,12,29:18.0
13,12,29:18.0
-13,13,29:18.0
-12,13,29:18.0
-11,13,29:18.0
-10,13,29:18.0
-9,13,29:18.0
-8,13,29:18.0
-6,13,29:18.0
-4,13,29:18.0
-3,13,29:18.0
-1,13,29:18.0
0,13,29:18.0
5,13,29:18.0
6,13,29:18.0
7,13,29:18.0
8,13,29:18.0
9,13,29:18.0
10,13,29:17.0
11,13,29:18.0
12,13,29:18.0
13,13,29:18.0
-13,14,29:18.0
-12,14,29:18.0
-11,14,29:18.0
-10,14,29:18.0
-9,14,29:18.0
-8,14,29:18.0
-7,14,29:18.0
-6,14,29:18.0
-3,14,29:18.0
-2,14,29:18.0
-1,14,29:18.0
0,14,29:18.0
1,14,29:18.0
4,14,29:18.0
5,14,29:18.0
6,14,29:18.0
7,14,29:18.0
8,14,29:18.0
9,14,29:18.0
10,14,29:18.0
11,14,29:18.0
12,14,29:18.0
13,14,29:18.0
-13,15,29:18.0
-12,15,29:18.0
-11,15,29:18.0
-10,15,29:18.0
-9,15,29:18.0
-8,15,29:18.0
-7,15,29:18.0
-6,15,29:18.0
-4,15,29:18.0
-3,15,29:18.0
-2,15,29:18.0
-1,15,29:17.0
0,15,29:18.0
1,15,29:18.0
2,15,29:17.0
3,15,29:18.0
4,15,29:18.0
5,15,29:18.0
6,15,29:18.0
7,15,29:18.0
8,15,29:18.0
9,15,29:18.0
10,15,29:18.0
11,15,29:18.0
12,15,29:18.0
13,15,29:18.0
14,15,29:18.0
-14,16,29:18.0
-13,16,29:18.0
-12,16,29:18.0
-11,16,29:18.0
-10,16,29:17.0
-9,16,29:18.0
-8,16,29:18.0
-7,16,29:18.0
-6,16,29:18.0
-5,16,29:18.0
-4,16,29:18.0
-3,16,29:18.0
-2,16,29:18.0
-1,16,29:18.0
0,16,29:18.0
1,16,29:18.0
2,16,29:18.0
3,16,29:18.0
4,16,29:18.0
5,16,29:18.0
6,16,29:18.0
7,16,29:18.0
8,16,29:18.0
9,16,29:18.0
10,16,29:18.0
11,16,29:17.0
12,16,29:18.0
13,16,29:18.0
-13,17,29:18.0
-12,17,29:18.0
-11,17,29:18.0
-10,17,29:18.0
-9,17,29:18.0
-8,17,29:18.0
-7,17,29:18.0
-6,17,29:18.0
-5,17,29:18.0
-3,17,29:18.0
-2,17,29:18.0
-1,17,29:18.0
0,17,29:18.0
1,17,29:18.0
2,17,29:18.0
3,17,29:18.0
4,17,29:18.0
5,17,29:17.0
6,17,29:18.0
7,17,29:18.0
8,17,29:18.0
9,17,29:18.0
10,17,29:18.0
11,17,29:18.0
12,17,29:18.0
13,17,29:18.0
14,17,29:18.0
-12,18,29:18.0
-11,18,29:18.0
-10,18,29:18.0
-9,18,29:18.0
-8,18,29:18.0
-7,18,29:18.0
-6,18,29:18.0
-5,18,29:17.0
-4,18,29:18.0
-3,18,29:18.0
2,18,29:18.0
3,18,29:18.0
4,18,29:18.0
5,18,29:18.0
7,18,29:18.0
8,18,29:18.0
9,18,29:18.0
10,18,29:18.0
11,18,29:18.0
12,18,29:18.0
13,18,29:18.0
-11,19,29:18.0
-10,19,29:18.0
-9,19,29:18.0
-8,19,29:18.0
-7,19,29:18.0
-6,19,29:18.0
-5,19,29:18.0
-4,19,29:18.0
-3,19,29:18.0
3,19,29:18.0
6,19,29:18.0
7,19,29:18.0
8,19,29:17.0
9,19,29:18.0
10,19,29:18.0
11,19,29:18.0
12,19,29:18.0
-12,20,29:18.0
-11,20,29:18.0
-10,20,29:18.0
-9,20,29:18.0
-8,20,29:17.0
-7,20,29:17.0
-6,20,29:18.0
-5,20,29:18.0
-4,20,29:18.0
-3,20,29:18.0
5,20,29:18.0
6,20,29:18.0
7,20,29:18.0
8,20,29:18.0
9,20,29:18.0
10,20,29:18.0
11,20,29:18.0
12,20,29:18.0
-12,21,29:18.0
-11,21,29:18.0
-10,21,29:18.0
-9,21,29:18.0
-8,21,29:17.0
-7,21,29:18.0
-6,21,29:18.0
-5,21,29:18.0
-4,21,29:18.0
-3,21,29:18.0
7,21,29:18.0
8,21,29:18.0
9,21,29:18.0
10,21,29:18.0
11,21,29:18.0
12,21,29:18.0
-11,22,29:18.0
-10,22,29:18.0
-9,22,29:18.0
-8,22,29:18.0
-7,22,29:18.0
-6,22,29:18.0
-5,22,29:18.0
-4,22,29:18.0
7,22,29:18.0
9,22,29:18.0
10,22,29:18.0
-11,23,29:18.0
-10,23,29:18.0
-9,23,29:18.0
-8,23,29:18.0
-7,23,29:18.0
-6,23,29:18.0
-5,23,29:18.0
-10,24,29:18.0
-9,24,29:18.0
-8,24,29:18.0
-7,24,29:18.0
-6,24,29:18.0
-9,25,29:18.0
-8,25,29:18.0
-12,-23,30:18.0
-11,-23,30:18.0
-10,-23,30:18.0
-13,-22,30:18.0
-12,-22,30:18.0
-11,-22,30:18.0
-10,-22,30:18.0
-9,-22,30:18.0
-8,-22,30:18.0
7,-22,30:18.0
-14,-21,30:18.0
-13,-21,30:18.0
-12,-21,30:18.0
-11,-21,30:18.0
-10,-21,30:18.0
-9,-21,30:18.0
-8,-21,30:18.0
-7,-21,30:18.0
6,-21,30:18.0
7,-21,30:18.0
8,-21,30:18.0
-15,-20,30:18.0
-14,-20,30:18.0
-13,-20,30:18.0
-12,-20,30:18.0
-11,-20,30:17.0
-10,-20,30:18.0
-9,-20,30:18.0
-8,-20,30:18.0
-7,-20,30:18.0
-6,-20,30:18.0
1,-20,30:18.0
5,-20,30:18.0
6,-20,30:18.0
7,-20,30:18.0
8,-20,30:18.0
9,-20,30:18.0
-14,-19,30:18.0
-13,-19,30:18.0
-12,-19,30:18.0
-11,-19,30:18.0
-10,-19,30:18.0
-9,-19,30:18.0
-8,-19,30:18.0
-7,-19,30:18.0
-6,-19,30:18.0
-5,-19,30:18.0
0,-19,30:18.0
1,-19,30:18.0
2,-19,30:18.0
4,-19,30:18.0
5,-19,30:18.0
6,-19,30:18.0
7,-19,30:18.0
8,-19,30:18.0
9,-19,30:18.0
10,-19,30:18.0
-13,-18,30:18.0
-12,-18,30:18.0
-11,-18,30:18.0
-10,-18,30:18.0
-9,-18,30:17.0
-8,-18,30:18.0
-7,-18,30:18.0
-6,-18,30:18.0
-5,-18,30:18.0
-4,-18,30:18.0
-3,-18,30:18.0
-1,-18,30:18.0
0,-18,30:18.0
1,-18,30:18.0
2,-18,30:18.0
3,-18,30:18.0
4,-18,30:18.0
5,-18,30:18.0
6,-18,30:18.0
7,-18,30:17.0
8,-18,30:18.0
9,-18,30:18.0
10,-18,30:18.0
-13,-17,30:18.0
-12,-17,30:18.0
-11,-17,30:18.0
-10,-17,30:18.0
-9,-17,30:18.0
-8,-17,30:18.0
-7,-17,30:18.0
-6,-17,30:18.0
-5,-17,30:18.0
-4,-17,30:18.0
-3,-17,30:18.0
-2,-17,30:18.0
-1,-17,30:18.0
0,-17,30:18.0
1,-17,30:18.0
2,-17,30:18.0
3,-17,30:18.0
4,-17,30:18.0
5,-17,30:18.0
6,-17,30:18.0
7,-17,30:18.0
8,-17,30:18.0
9,-17,30:18.0
10,-17,30:18.0
11,-17,30:18.0
-13,-16,30:18.0
-12,-16,30:18.0
-11,-16,30:18.0
-10,-16,30:18.0
-9,-16,30:18.0
-8,-16,30:18.0
-7,-16,30:18.0
-6,-16,30:18.0
-5,-16,30:18.0
-4,-16,30:18.0
-3,-16,30:18.0
-2,-16,30:18.0
-1,-16,30:18.0
0,-16,30:18.0
1,-16,30:17.0
2,-16,30:18.0
3,-16,30:18.0
4,-16,30:18.0
5,-16,30:18.0
6,-16,30:18.0
7,-16,30:18.0
8,-16,30:18.0
9,-16,30:18.0
10,-16,30:18.0
11,-16,30:18.0
12,-16,30:18.0
-14,-15,30:18.0
-13,-15,30:18.0
-12,-15,30:18.0
-11,-15,30:18.0
-10,-15,30:18.0
-9,-15,30:18.0
-8,-15,30:18.0
-7,-15,30:18.0
-6,-15,30:18.0
-5,-15,30:18.0
-4,-15,30:18.0
-3,-15,30:18.0
-2,-15,30:18.0
-1,-15,30:18.0
0,-15,30:18.0
1,-15,30:18.0
2,-15,30:18.0
3,-15,30:18.0
4,-15,30:18.0
7,-15,30:18.0
8,-15,30:18.0
9,-15,30:18.0
10,-15,30:18.0
11,-15,30:18.0
12,-15,30:18.0
13,-15,30:18.0
-15,-14,30:18.0
-14,-14,30:18.0
-13,-14,30:18.0
-12,-14,30:18.0
-11,-14,30:18.0
-10,-14,30:18.0
-9,-14,30:18.0
-8,-14,30:18.0
-7,-14,30:18.0
-6,-14,30:18.0
-5,-14,30:18.0
-4,-14,30:18.0
-3,-14,30:17.0
-2,-14,30:18.0
-1,-14,30:18.0
0,-14,30:18.0
1,-14,30:18.0
2,-14,30:18.0
3,-14,30:18.0
4,-14,30:18.0
5,-14,30:18.0
7,-14,30:18.0
8,-14,30:18.0
9,-14,30:18.0
10,-14,30:17.0
11,-14,30:18.0
12,-14,30:18.0
-15,-13,30:18.0
-14,-13,30:18.0
-13,-13,30:18.0
-12,-13,30:18.0
-11,-13,30:17.0
-10,-13,30:18.0
-9,-13,30:18.0
-8,-13,30:18.0
-7,-13,30:18.0
-6,-13,30:18.0
-5,-13,30:18.0
-4,-13,30:18.0
-3,-13,30:18.0
-2,-13,30:18.0
-1,-13,30:18.0
0,-13,30:18.0
1,-13,30:18.0
2,-13,30:18.0
4,-13,30:18.0
5,-13,30:18.0
6,-13,30:17.0
7,-13,30:18.0
8,-13,30:18.0
9,-13,30:18.0
10,-13,30:18.0
11,-13,30:18.0
12,-13,30:18.0
13,-13,30:18.0
-14,-12,30:18.0
-12,-12,30:18.0
-10,-12,30:18.0
-9,-12,30:18.0
-8,-12,30:18.0
-7,-12,30:18.0
-6,-12,30:18.0
-5,-12,30:18.0
3,-12,30:18.0
7,-12,30:18.0
8,-12,30:18.0
9,-12,30:18.0
10,-12,30:18.0
11,-12,30:18.0
12,-12,30:18.0
-15,-11,30:18.0
-14,-11,30:18.0
-13,-11,30:18.0
-12,-11,30:18.0
-11,-11,30:17.0
-10,-11,30:18.0
-9,-11,30:18.0
-8,-11,30:18.0
-7,-11,30:17.0
-6,-11,30:18.0
-2,-11,30:18.0
0,-11,30:18.0
2,-11,30:17.0
9,-11,30:18.0
10,-11,30:18.0
11,-11,30:18.0
-18,-10,30:18.0
-17,-10,30:18.0
-14,-10,30:18.0
-13,-10,30:18.0
-3,-10,30:18.0
-2,-10,30:18.0
-1,-10,30:18.0
0,-10,30:18.0
1,-10,30:18.0
7,-10,30:17.0
-19,-9,30:18.0
-18,-9,30:18.0
-17,-9,30:18.0
-16,-9,30:18.0
-14,-9,30:18.0
-13,-9,30:18.0
-12,-9,30:18.0
-8,-9,30:17.0
-3,-9,30:18.0
-2,-9,30:18.0
-1,-9,30:17.0
0,-9,30:18.0
6,-9,30:18.0
-22,-8,30:18.0
-21,-8,30:18.0
-20,-8,30:18.0
-19,-8,30:18.0
-18,-8,30:18.0
-17,-8,30:18.0
-16,-8,30:18.0
-15,-8,30:18.0
-14,-8,30:18.0
-13,-8,30:18.0
-12,-8,30:18.0
-3,-8,30:18.0
-2,-8,30:18.0
-1,-8,30:18.0
0,-8,30:18.0
1,-8,30:18.0
5,-8,30:18.0
6,-8,30:18.0
8,-8,30:18.0
-23,-7,30:18.0
-22,-7,30:18.0
-21,-7,30:18.0
-20,-7,30:18.0
-19,-7,30:18.0
-18,-7,30:18.0
-17,-7,30:18.0
-16,-7,30:18.0
-15,-7,30:18.0
-14,-7,30:18.0
-13,-7,30:17.0
-12,-7,30:18.0
-11,-7,30:18.0
-4,-7,30:18.0
-3,-7,30:18.0
-2,-7,30:17.0
-1,-7,30:18.0
0,-7,30:18.0
6,-7,30:18.0
7,-7,30:18.0
8,-7,30:18.0
-23,-6,30:18.0
-22,-6,30:18.0
-21,-6,30:17.0
-20,-6,30:18.0
-19,-6,30:18.0
-18,-6,30:18.0
-17,-6,30:17.0
-15,-6,30:18.0
-14,-6,30:18.0
-13,-6,30:18.0
-12,-6,30:18.0
-8,-6,30:18.0
-7,-6,30:18.0
-4,-6,30:18.0
-3,-6,30:18.0
-2,-6,30:18.0
-1,-6,30:18.0
2,-6,30:17.0
6,-6,30:18.0
7,-6,30:18.0
8,-6,30:18.0
9,-6,30:18.0
-23,-5,30:18.0
-22,-5,30:18.0
-21,-5,30:18.0
-20,-5,30:18.0
-19,-5,30:18.0
-18,-5,30:18.0
-17,-5,30:18.0
-16,-5,30:18.0
-15,-5,30:18.0
-14,-5,30:18.0
-13,-5,30:18.0
-12,-5,30:18.0
-9,-5,30:18.0
-8,-5,30:18.0
-7,-5,30:18.0
-6,-5,30:18.0
-5,-5,30:18.0
-3,-5,30:18.0
-1,-5,30:18.0
1,-5,30:18.0
2,-5,30:18.0
3,-5,30:18.0
6,-5,30:18.0
7,-5,30:18.0
8,-5,30:18.0
9,-5,30:18.0
10,-5,30:18.0
-22,-4,30:18.0
-21,-4,30:18.0
-20,-4,30:18.0
-19,-4,30:17.0
-18,-4,30:18.0
-17,-4,30:18.0
-16,-4,30:18.0
-15,-4,30:18.0
-14,-4,30:18.0
-13,-4,30:18.0
-9,-4,30:18.0
-8,-4,30:18.0
-7,-4,30:17.0
-6,-4,30:18.0
-5,-4,30:17.0
4,-4,30:18.0
6,-4,30:18.0
7,-4,30:18.0
8,-4,30:18.0
9,-4,30:18.0
10,-4,30:18.0
-21,-3,30:18.0
-20,-3,30:18.0
-19,-3,30:18.0
-18,-3,30:18.0
-17,-3,30:18.0
-16,-3,30:18.0
-15,-3,30:18.0
-14,-3,30:18.0
-13,-3,30:17.0
-12,-3,30:18.0
-10,-3,30:17.0
-8,-3,30:18.0
-7,-3,30:18.0
-6,-3,30:17.0
-5,-3,30:18.0
-4,-3,30:18.0
4,-3,30:18.0
5,-3,30:18.0
6,-3,30:18.0
7,-3,30:17.0
8,-3,30:18.0
9,-3,30:18.0
10,-3,30:18.0
11,-3,30:18.0
12,-3,30:18.0
-20,-2,30:18.0
-19,-2,30:18.0
-18,-2,30:18.0
-17,-2,30:18.0
-16,-2,30:17.0
-15,-2,30:18.0
-14,-2,30:18.0
-10,-2,30:18.0
-8,-2,30:18.0
-7,-2,30:18.0
3,-2,30:18.0
4,-2,30:17.0
5,-2,30:18.0
6,-2,30:18.0
7,-2,30:18.0
8,-2,30:18.0
9,-2,30:18.0
10,-2,30:18.0
11,-2,30:18.0
12,-2,30:18.0
13,-2,30:18.0
-17,-1,30:18.0
-16,-1,30:17.0
-15,-1,30:18.0
-10,-1,30:18.0
-9,-1,30:17.0
4,-1,30:18.0
5,-1,30:18.0
7,-1,30:18.0
8,-1,30:18.0
9,-1,30:18.0
10,-1,30:18.0
11,-1,30:18.0
12,-1,30:18.0
13,-1,30:18.0
14,-1,30:18.0
-16,0,30:18.0
-11,0,30:18.0
-10,0,30:18.0
-9,0,30:18.0
1,0,30:17.0
2,0,30:17.0
3,0,30:18.0
8,0,30:18.0
9,0,30:18.0
10,0,30:18.0
11,0,30:18.0
12,0,30:18.0
13,0,30:18.0
14,0,30:18.0
15,0,30:18.0
17,0,30:18.0
-14,1,30:18.0
-13,1,30:18.0
-12,1,30:18.0
-11,1,30:18.0
-10,1,30:18.0
-9,1,30:18.0
-8,1,30:18.0
-7,1,30:18.0
-6,1,30:18.0
-5,1,30:18.0
6,1,30:18.0
7,1,30:18.0
8,1,30:18.0
9,1,30:17.0
10,1,30:18.0
11,1,30:18.0
12,1,30:17.0
13,1,30:18.0
14,1,30:18.0
15,1,30:18.0
16,1,30:18.0
17,1,30:18.0
18,1,30:18.0
-14,2,30:18.0
-13,2,30:18.0
-12,2,30:18.0
-11,2,30:17.0
-10,2,30:18.0
-9,2,30:18.0
-8,2,30:18.0
-7,2,30:18.0
-6,2,30:17.0
-5,2,30:18.0
4,2,30:18.0
5,2,30:18.0
6,2,30:18.0
7,2,30:18.0
8,2,30:18.0
9,2,30:18.0
10,2,30:18.0
11,2,30:18.0
12,2,30:18.0
13,2,30:18.0
14,2,30:18.0
15,2,30:18.0
16,2,30:18.0
17,2,30:18.0
18,2,30:18.0
19,2,30:18.0
-14,3,30:18.0
-13,3,30:18.0
-12,3,30:18.0
-11,3,30:18.0
-10,3,30:18.0
-9,3,30:18.0
-8,3,30:18.0
-7,3,30:18.0
-6,3,30:18.0
-5,3,30:18.0
3,3,30:18.0
4,3,30:18.0
5,3,30:18.0
6,3,30:18.0
7,3,30:17.0
8,3,30:18.0
9,3,30:18.0
11,3,30:18.0
14,3,30:18.0
15,3,30:18.0
16,3,30:18.0
17,3,30:18.0
18,3,30:18.0
19,3,30:18.0
20,3,30:18.0
-13,4,30:18.0
-12,4,30:18.0
-11,4,30:18.0
-10,4,30:18.0
-9,4,30:18.0
-8,4,30:18.0
-7,4,30:17.0
-6,4,30:18.0
-5,4,30:18.0
-2,4,30:18.0
3,4,30:17.0
4,4,30:18.0
6,4,30:18.0
7,4,30:18.0
8,4,30:18.0
9,4,30:18.0
13,4,30:18.0
14,4,30:18.0
15,4,30:18.0
16,4,30:18.0
17,4,30:17.0
18,4,30:18.0
19,4,30:18.0
20,4,30:18.0
-12,5,30:18.0
-11,5,30:18.0
-10,5,30:18.0
-9,5,30:18.0
-8,5,30:18.0
-7,5,30:18.0
-6,5,30:18.0
-5,5,30:18.0
-4,5,30:18.0
-3,5,30:17.0
-2,5,30:18.0
-1,5,30:18.0
7,5,30:18.0
11,5,30:18.0
12,5,30:18.0
13,5,30:18.0
14,5,30:18.0
15,5,30:18.0
16,5,30:18.0
17,5,30:18.0
18,5,30:18.0
19,5,30:18.0
20,5,30:18.0
-11,6,30:18.0
-10,6,30:18.0
-9,6,30:18.0
-8,6,30:18.0
-7,6,30:18.0
-6,6,30:18.0
-5,6,30:18.0
-2,6,30:18.0
2,6,30:18.0
5,6,30:18.0
6,6,30:18.0
7,6,30:18.0
10,6,30:18.0
11,6,30:17.0
12,6,30:18.0
13,6,30:18.0
14,6,30:18.0
15,6,30:18.0
16,6,30:18.0
17,6,30:18.0
18,6,30:18.0
19,6,30:18.0
20,6,30:18.0
-8,7,30:18.0
-7,7,30:18.0
-5,7,30:18.0
2,7,30:18.0
3,7,30:17.0
4,7,30:17.0
5,7,30:18.0
6,7,30:18.0
9,7,30:18.0
10,7,30:18.0
11,7,30:18.0
12,7,30:18.0
13,7,30:18.0
14,7,30:18.0
15,7,30:18.0
16,7,30:18.0
17,7,30:18.0
18,7,30:18.0
19,7,30:18.0
20,7,30:18.0
21,7,30:18.0
-13,8,30:18.0
-12,8,30:18.0
-11,8,30:18.0
-10,8,30:18.0
-3,8,30:18.0
2,8,30:18.0
3,8,30:17.0
4,8,30:18.0
7,8,30:18.0
8,8,30:18.0
9,8,30:18.0
10,8,30:18.0
11,8,30:18.0
12,8,30:18.0
13,8,30:18.0
14,8,30:18.0
15,8,30:17.0
16,8,30:18.0
17,8,30:18.0
18,8,30:17.0
19,8,30:18.0
20,8,30:18.0
21,8,30:18.0
-14,9,30:18.0
-13,9,30:18.0
-12,9,30:18.0
-11,9,30:18.0
-10,9,30:18.0
-9,9,30:18.0
-3,9,30:18.0
1,9,30:18.0
2,9,30:18.0
4,9,30:18.0
5,9,30:18.0
6,9,30:18.0
7,9,30:18.0
8,9,30:18.0
9,9,30:18.0
10,9,30:18.0
11,9,30:18.0
12,9,30:18.0
13,9,30:18.0
14,9,30:18.0
15,9,30:18.0
16,9,30:18.0
17,9,30:18.0
18,9,30:18.0
19,9,30:18.0
20,9,30:18.0
21,9,30:18.0
-13,10,30:18.0
-12,10,30:17.0
-11,10,30:18.0
-10,10,30:18.0
-9,10,30:18.0
-6,10,30:18.0
-5,10,30:18.0
-4,10,30:17.0
-3,10,30:18.0
-1,10,30:18.0
1,10,30:18.0
2,10,30:18.0
3,10,30:18.0
4,10,30:18.0
5,10,30:18.0
6,10,30:18.0
7,10,30:18.0
8,10,30:18.0
9,10,30:17.0
10,10,30:18.0
11,10,30:18.0
12,10,30:18.0
13,10,30:18.0
14,10,30:18.0
15,10,30:18.0
16,10,30:18.0
17,10,30:18.0
18,10,30:18.0
19,10,30:18.0
20,10,30:18.0
-14,11,30:18.0
-13,11,30:18.0
-12,11,30:18.0
-11,11,30:18.0
-10,11,30:18.0
-6,11,30:18.0
-5,11,30:18.0
-4,11,30:18.0
-1,11,30:18.0
0,11,30:17.0
1,11,30:18.0
2,11,30:18.0
3,11,30:18.0
4,11,30:18.0
5,11,30:18.0
6,11,30:18.0
7,11,30:18.0
8,11,30:18.0
9,11,30:18.0
10,11,30:18.0
11,11,30:18.0
12,11,30:18.0
14,11,30:18.0
15,11,30:18.0
16,11,30:18.0
17,11,30:18.0
18,11,30:18.0
19,11,30:18.0
-13,12,30:18.0
-12,12,30:18.0
-11,12,30:18.0
-10,12,30:18.0
-6,12,30:18.0
-5,12,30:17.0
-1,12,30:18.0
1,12,30:18.0
2,12,30:18.0
4,12,30:18.0
5,12,30:18.0
6,12,30:17.0
7,12,30:18.0
8,12,30:18.0
9,12,30:18.0
10,12,30:18.0
11,12,30:18.0
12,12,30:18.0
15,12,30:18.0
-13,13,30:18.0
-12,13,30:18.0
-11,13,30:18.0
-9,13,30:18.0
-4,13,30:18.0
-2,13,30:18.0
-1,13,30:18.0
1,13,30:18.0
2,13,30:18.0
3,13,30:17.0
4,13,30:18.0
5,13,30:18.0
6,13,30:18.0
7,13,30:18.0
8,13,30:18.0
9,13,30:18.0
10,13,30:18.0
11,13,30:18.0
12,13,30:18.0
13,13,30:18.0
-14,14,30:18.0
-13,14,30:18.0
-12,14,30:18.0
-11,14,30:18.0
-10,14,30:18.0
-9,14,30:18.0
-8,14,30:18.0
-7,14,30:18.0
-4,14,30:18.0
-3,14,30:18.0
-2,14,30:18.0
-1,14,30:18.0
0,14,30:18.0
2,14,30:18.0
3,14,30:18.0
4,14,30:18.0
5,14,30:18.0
6,14,30:18.0
7,14,30:18.0
8,14,30:18.0
9,14,30:18.0
10,14,30:18.0
11,14,30:18.0
12,14,30:18.0
-14,15,30:18.0
-13,15,30:18.0
-12,15,30:18.0
-11,15,30:18.0
-10,15,30:18.0
-9,15,30:18.0
-8,15,30:18.0
-7,15,30:18.0
-6,15,30:18.0
-5,15,30:18.0
-4,15,30:18.0
-3,15,30:18.0
-2,15,30:18.0
-1,15,30:17.0
0,15,30:18.0
1,15,30:18.0
2,15,30:18.0
3,15,30:18.0
4,15,30:18.0
5,15,30:18.0
6,15,30:18.0
7,15,30:18.0
9,15,30:18.0
10,15,30:18.0
11,15,30:18.0
12,15,30:18.0
13,15,30:18.0
-14,16,30:18.0
-13,16,30:18.0
-12,16,30:18.0
-11,16,30:18.0
-10,16,30:17.0
-9,16,30:18.0
-8,16,30:18.0
-7,16,30:18.0
-6,16,30:18.0
-5,16,30:18.0
-4,16,30:18.0
-3,16,30:18.0
-2,16,30:18.0
-1,16,30:18.0
0,16,30:18.0
1,16,30:18.0
2,16,30:18.0
3,16,30:17.0
4,16,30:18.0
5,16,30:18.0
6,16,30:18.0
7,16,30:18.0
8,16,30:18.0
9,16,30:18.0
10,16,30:18.0
11,16,30:18.0
12,16,30:18.0
13,16,30:18.0
14,16,30:18.0
-14,17,30:18.0
-13,17,30:18.0
-12,17,30:18.0
-11,17,30:18.0
-10,17,30:18.0
-9,17,30:18.0
-8,17,30:18.0
-7,17,30:18.0
-6,17,30:18.0
-5,17,30:18.0
-4,17,30:18.0
-3,17,30:18.0
-2,17,30:18.0
-1,17,30:18.0
0,17,30:18.0
1,17,30:18.0
2,17,30:18.0
3,17,30:18.0
4,17,30:18.0
5,17,30:18.0
6,17,30:18.0
8,17,30:18.0
9,17,30:18.0
10,17,30:18.0
11,17,30:18.0
12,17,30:18.0
13,17,30:18.0
-13,18,30:18.0
-12,18,30:18.0
-11,18,30:18.0
-10,18,30:18.0
-9,18,30:18.0
-8,18,30:18.0
-7,18,30:18.0
-6,18,30:18.0
-5,18,30:17.0
-4,18,30:18.0
-3,18,30:18.0
-2,18,30:18.0
-1,18,30:18.0
0,18,30:18.0
1,18,30:18.0
2,18,30:18.0
3,18,30:18.0
4,18,30:18.0
7,18,30:18.0
8,18,30:18.0
9,18,30:18.0
10,18,30:18.0
11,18,30:18.0
12,18,30:18.0
-12,19,30:18.0
-11,19,30:18.0
-9,19,30:18.0
-8,19,30:18.0
-7,19,30:18.0
-6,19,30:18.0
-5,19,30:18.0
-4,19,30:18.0
-3,19,30:18.0
-2,19,30:18.0
-1,19,30:18.0
2,19,30:18.0
3,19,30:18.0
4,19,30:18.0
5,19,30:18.0
6,19,30:18.0
7,19,30:18.0
8,19,30:18.0
9,19,30:18.0
10,19,30:18.0
11,19,30:18.0
-12,20,30:18.0
-11,20,30:18.0
-10,20,30:18.0
-9,20,30:17.0
-8,20,30:17.0
-7,20,30:18.0
-6,20,30:17.0
-5,20,30:18.0
-4,20,30:18.0
-3,20,30:18.0
6,20,30:18.0
7,20,30:18.0
8,20,30:18.0
9,20,30:18.0
10,20,30:18.0
11,20,30:18.0
12,20,30:18.0
-12,21,30:18.0
-11,21,30:18.0
-10,21,30:18.0
-9,21,30:18.0
-8,21,30:18.0
-7,21,30:18.0
-6,21,30:18.0
-5,21,30:18.0
-4,21,30:18.0
-3,21,30:18.0
7,21,30:18.0
9,21,30:18.0
10,21,30:18.0
11,21,30:18.0
-12,22,30:18.0
-11,22,30:18.0
-10,22,30:18.0
-9,22,30:18.0
-8,22,30:17.0
-7,22,30:18.0
-6,22,30:18.0
-5,22,30:18.0
-4,22,30:18.0
-3,22,30:18.0
-12,23,30:18.0
-11,23,30:18.0
-10,23,30:18.0
-9,23,30:18.0
-8,23,30:18.0
-7,23,30:18.0
-6,23,30:18.0
-5,23,30:18.0
-4,23,30:18.0
-11,24,30:18.0
-10,24,30:18.0
-9,24,30:18.0
-8,24,30:18.0
-7,24,30:18.0
-6,24,30:18.0
-5,24,30:18.0
-10,25,30:18.0
-9,25,30:18.0
-8,25,30:18.0
-7,25,30:18.0
-8,26,30:18.0
-11,-23,31:18.0
-12,-22,31:18.0
-11,-22,31:18.0
-10,-22,31:18.0
-9,-22,31:18.0
-8,-22,31:18.0
-7,-22,31:18.0
7,-22,31:18.0
-13,-21,31:18.0
-12,-21,31:18.0
-11,-21,31:18.0
-10,-21,31:18.0
-9,-21,31:18.0
-8,-21,31:18.0
-7,-21,31:18.0
-6,-21,31:18.0
6,-21,31:18.0
7,-21,31:18.0
8,-21,31:18.0
-14,-20,31:18.0
-13,-20,31:18.0
-12,-20,31:18.0
-11,-20,31:18.0
-10,-20,31:18.0
-9,-20,31:18.0
-8,-20,31:18.0
-7,-20,31:18.0
-6,-20,31:18.0
5,-20,31:18.0
6,-20,31:18.0
7,-20,31:18.0
8,-20,31:18.0
9,-20,31:18.0
-13,-19,31:18.0
-12,-19,31:18.0
-11,-19,31:18.0
-10,-19,31:18.0
-9,-19,31:18.0
-8,-19,31:17.0
-7,-19,31:18.0
-6,-19,31:18.0
-5,-19,31:18.0
-3,-19,31:18.0
1,-19,31:18.0
4,-19,31:18.0
5,-19,31:18.0
6,-19,31:18.0
7,-19,31:18.0
8,-19,31:18.0
9,-19,31:18.0
10,-19,31:18.0
-13,-18,31:18.0
-12,-18,31:18.0
-11,-18,31:18.0
-10,-18,31:18.0
-9,-18,31:18.0
-8,-18,31:18.0
-7,-18,31:18.0
-6,-18,31:18.0
-5,-18,31:18.0
-4,-18,31:18.0
-3,-18,31:18.0
-2,-18,31:18.0
0,-18,31:18.0
1,-18,31:18.0
2,-18,31:18.0
3,-18,31:18.0
4,-18,31:18.0
5,-18,31:18.0
6,-18,31:18.0
7,-18,31:17.0
8,-18,31:18.0
9,-18,31:18.0
10,-18,31:18.0
-14,-17,31:18.0
-13,-17,31:18.0
-12,-17,31:18.0
-11,-17,31:18.0
-10,-17,31:17.0
-9,-17,31:18.0
-8,-17,31:18.0
-7,-17,31:18.0
-6,-17,31:18.0
-5,-17,31:18.0
-4,-17,31:18.0
-3,-17,31:18.0
-2,-17,31:18.0
-1,-17,31:18.0
0,-17,31:18.0
1,-17,31:18.0
2,-17,31:18.0
3,-17,31:18.0
4,-17,31:18.0
5,-17,31:18.0
6,-17,31:17.0
7,-17,31:18.0
8,-17,31:18.0
9,-17,31:18.0
10,-17,31:18.0
11,-17,31:18.0
-13,-16,31:18.0
-12,-16,31:18.0
-11,-16,31:18.0
-10,-16,31:18.0
-9,-16,31:18.0
-8,-16,31:18.0
-7,-16,31:18.0
-6,-16,31:18.0
-5,-16,31:18.0
-4,-16,31:18.0
-3,-16,31:18.0
-2,-16,31:18.0
-1,-16,31:18.0
0,-16,31:18.0
1,-16,31:18.0
2,-16,31:18.0
3,-16,31:18.0
4,-16,31:18.0
5,-16,31:18.0
7,-16,31:18.0
8,-16,31:18.0
9,-16,31:18.0
10,-16,31:18.0
11,-16,31:18.0
-15,-15,31:18.0
-14,-15,31:18.0
-13,-15,31:18.0
-12,-15,31:18.0
-11,-15,31:18.0
-10,-15,31:18.0
-9,-15,31:18.0
-8,-15,31:18.0
-7,-15,31:18.0
-6,-15,31:18.0
-5,-15,31:18.0
-4,-15,31:18.0
-3,-15,31:17.0
-2,-15,31:18.0
-1,-15,31:18.0
0,-15,31:18.0
1,-15,31:18.0
2,-15,31:18.0
3,-15,31:18.0
4,-15,31:18.0
5,-15,31:18.0
6,-15,31:18.0
7,-15,31:18.0
8,-15,31:18.0
9,-15,31:18.0
10,-15,31:18.0
11,-15,31:18.0
12,-15,31:18.0
-14,-14,31:18.0
-13,-14,31:18.0
-12,-14,31:17.0
-11,-14,31:18.0
-10,-14,31:18.0
-9,-14,31:18.0
-8,-14,31:18.0
-7,-14,31:18.0
-6,-14,31:18.0
-5,-14,31:18.0
-4,-14,31:18.0
-3,-14,31:18.0
-2,-14,31:18.0
-1,-14,31:18.0
0,-14,31:18.0
1,-14,31:18.0
2,-14,31:18.0
3,-14,31:18.0
4,-14,31:18.0
5,-14,31:18.0
6,-14,31:18.0
7,-14,31:18.0
8,-14,31:18.0
9,-14,31:18.0
10,-14,31:18.0
11,-14,31:18.0
12,-14,31:18.0
13,-14,31:18.0
-15,-13,31:18.0
-14,-13,31:18.0
-13,-13,31:18.0
-12,-13,31:18.0
-11,-13,31:18.0
-10,-13,31:18.0
-9,-13,31:18.0
-8,-13,31:18.0
-7,-13,31:18.0
-6,-13,31:18.0
-5,-13,31:18.0
-4,-13,31:18.0
-3,-13,31:18.0
-2,-13,31:18.0
-1,-13,31:18.0
0,-13,31:18.0
1,-13,31:18.0
2,-13,31:18.0
3,-13,31:18.0
4,-13,31:18.0
5,-13,31:18.0
6,-13,31:17.0
7,-13,31:18.0
8,-13,31:18.0
9,-13,31:18.0
10,-13,31:18.0
11,-13,31:18.0
12,-13,31:18.0
-14,-12,31:18.0
-13,-12,31:18.0
-12,-12,31:18.0
-11,-12,31:18.0
-10,-12,31:18.0
-9,-12,31:18.0
-8,-12,31:18.0
-7,-12,31:18.0
-6,-12,31:18.0
-5,-12,31:18.0
-4,-12,31:18.0
-3,-12,31:18.0
-2,-12,31:18.0
1,-12,31:18.0
3,-12,31:17.0
4,-12,31:18.0
5,-12,31:18.0
6,-12,31:18.0
7,-12,31:18.0
8,-12,31:18.0
9,-12,31:18.0
10,-12,31:18.0
11,-12,31:18.0
-18,-11,31:18.0
-17,-11,31:18.0
-15,-11,31:18.0
-14,-11,31:18.0
-10,-11,31:18.0
-9,-11,31:18.0
-8,-11,31:18.0
-7,-11,31:17.0
-6,-11,31:18.0
-5,-11,31:18.0
-4,-11,31:18.0
-2,-11,31:18.0
-1,-11,31:18.0
2,-11,31:17.0
4,-11,31:18.0
5,-11,31:18.0
6,-11,31:18.0
7,-11,31:18.0
8,-11,31:18.0
9,-11,31:18.0
10,-11,31:18.0
-19,-10,31:18.0
-18,-10,31:18.0
-17,-10,31:18.0
-16,-10,31:18.0
-15,-10,31:18.0
-14,-10,31:18.0
-12,-10,31:17.0
-10,-10,31:18.0
-9,-10,31:18.0
-7,-10,31:18.0
-2,-10,31:18.0
-1,-10,31:18.0
0,-10,31:18.0
5,-10,31:18.0
7,-10,31:17.0
8,-10,31:18.0
-20,-9,31:18.0
-19,-9,31:18.0
-18,-9,31:18.0
-17,-9,31:18.0
-16,-9,31:18.0
-15,-9,31:18.0
-14,-9,31:18.0
-13,-9,31:18.0
-12,-9,31:18.0
-11,-9,31:18.0
-10,-9,31:18.0
-9,-9,31:18.0
-8,-9,31:17.0
-6,-9,31:18.0
-3,-9,31:18.0
-2,-9,31:18.0
-1,-9,31:17.0
4,-9,31:18.0
5,-9,31:18.0
6,-9,31:18.0
7,-9,31:17.0
8,-9,31:18.0
9,-9,31:18.0
-23,-8,31:18.0
-22,-8,31:18.0
-20,-8,31:18.0
-19,-8,31:18.0
-18,-8,31:18.0
-17,-8,31:18.0
-16,-8,31:18.0
-15,-8,31:18.0
-14,-8,31:18.0
-13,-8,31:18.0
-12,-8,31:18.0
-11,-8,31:18.0
-10,-8,31:18.0
-9,-8,31:18.0
-7,-8,31:18.0
-5,-8,31:18.0
-2,-8,31:18.0
-1,-8,31:18.0
0,-8,31:18.0
5,-8,31:18.0
6,-8,31:18.0
7,-8,31:18.0
8,-8,31:18.0
-22,-7,31:18.0
-21,-7,31:18.0
-20,-7,31:18.0
-19,-7,31:18.0
-18,-7,31:18.0
-17,-7,31:17.0
-16,-7,31:18.0
-15,-7,31:18.0
-14,-7,31:17.0
-13,-7,31:18.0
-12,-7,31:17.0
-11,-7,31:18.0
-8,-7,31:18.0
-7,-7,31:18.0
-6,-7,31:18.0
-4,-7,31:18.0
-3,-7,31:18.0
-2,-7,31:17.0
0,-7,31:18.0
1,-7,31:17.0
2,-7,31:18.0
4,-7,31:18.0
5,-7,31:18.0
6,-7,31:18.0
7,-7,31:18.0
8,-7,31:18.0
9,-7,31:18.0
-24,-6,31:18.0
-23,-6,31:18.0
-22,-6,31:18.0
-21,-6,31:17.0
-20,-6,31:18.0
-19,-6,31:18.0
-18,-6,31:18.0
-17,-6,31:18.0
-16,-6,31:18.0
-15,-6,31:18.0
-14,-6,31:18.0
-13,-6,31:18.0
-12,-6,31:18.0
-11,-6,31:18.0
-7,-6,31:18.0
-6,-6,31:18.0
-5,-6,31:18.0
-3,-6,31:18.0
-2,-6,31:18.0
-1,-6,31:18.0
1,-6,31:18.0
2,-6,31:18.0
3,-6,31:18.0
4,-6,31:18.0
6,-6,31:18.0
7,-6,31:18.0
8,-6,31:18.0
9,-6,31:18.0
-24,-5,31:18.0
-23,-5,31:18.0
-22,-5,31:18.0
-21,-5,31:18.0
-20,-5,31:18.0
-19,-5,31:18.0
-18,-5,31:18.0
-17,-5,31:18.0
-16,-5,31:18.0
-15,-5,31:18.0
-14,-5,31:18.0
-13,-5,31:18.0
-12,-5,31:18.0
-8,-5,31:17.0
-7,-5,31:18.0
-6,-5,31:18.0
1,-5,31:18.0
2,-5,31:18.0
3,-5,31:18.0
5,-5,31:18.0
6,-5,31:18.0
7,-5,31:18.0
8,-5,31:18.0
9,-5,31:18.0
10,-5,31:18.0
-23,-4,31:18.0
-22,-4,31:18.0
-21,-4,31:18.0
-20,-4,31:18.0
-19,-4,31:17.0
-18,-4,31:18.0
-17,-4,31:18.0
-16,-4,31:18.0
-15,-4,31:18.0
-14,-4,31:18.0
-13,-4,31:18.0
-12,-4,31:18.0
-11,-4,31:18.0
-7,-4,31:18.0
1,-4,31:18.0
2,-4,31:18.0
3,-4,31:18.0
4,-4,31:18.0
5,-4,31:18.0
6,-4,31:18.0
7,-4,31:18.0
8,-4,31:18.0
9,-4,31:18.0
10,-4,31:18.0
11,-4,31:18.0
12,-4,31:18.0
-22,-3,31:18.0
-21,-3,31:18.0
-20,-3,31:18.0
-19,-3,31:18.0
-18,-3,31:18.0
-17,-3,31:18.0
-16,-3,31:18.0
-15,-3,31:18.0
-14,-3,31:18.0
-13,-3,31:18.0
-12,-3,31:18.0
-11,-3,31:18.0
-10,-3,31:17.0
-8,-3,31:18.0
-7,-3,31:18.0
-6,-3,31:17.0
-3,-3,31:18.0
-1,-3,31:18.0
1,-3,31:18.0
2,-3,31:18.0
3,-3,31:18.0
4,-3,31:18.0
5,-3,31:18.0
6,-3,31:18.0
7,-3,31:18.0
8,-3,31:17.0
9,-3,31:18.0
10,-3,31:18.0
11,-3,31:18.0
12,-3,31:18.0
13,-3,31:18.0
-21,-2,31:18.0
-20,-2,31:18.0
-19,-2,31:18.0
-18,-2,31:18.0
-17,-2,31:18.0
-16,-2,31:18.0
-15,-2,31:18.0
-14,-2,31:18.0
-13,-2,31:18.0
-12,-2,31:17.0
-10,-2,31:18.0
-5,-2,31:17.0
-3,-2,31:18.0
-2,-2,31:18.0
2,-2,31:18.0
3,-2,31:18.0
4,-2,31:17.0
5,-2,31:18.0
6,-2,31:18.0
7,-2,31:18.0
8,-2,31:18.0
9,-2,31:18.0
10,-2,31:18.0
11,-2,31:18.0
12,-2,31:18.0
13,-2,31:18.0
14,-2,31:18.0
-20,-1,31:18.0
-19,-1,31:18.0
-18,-1,31:18.0
-16,-1,31:17.0
-15,-1,31:18.0
-14,-1,31:18.0
-12,-1,31:18.0
-11,-1,31:18.0
-3,-1,31:18.0
-2,-1,31:18.0
1,-1,31:18.0
2,-1,31:18.0
3,-1,31:18.0
4,-1,31:18.0
5,-1,31:18.0
6,-1,31:18.0
7,-1,31:18.0
8,-1,31:18.0
9,-1,31:18.0
10,-1,31:18.0
11,-1,31:18.0
12,-1,31:18.0
13,-1,31:18.0
14,-1,31:18.0
15,-1,31:18.0
-17,0,31:18.0
-16,0,31:18.0
-13,0,31:18.0
-12,0,31:18.0
-11,0,31:18.0
-10,0,31:18.0
-8,0,31:17.0
0,0,31:17.0
1,0,31:18.0
2,0,31:17.0
3,0,31:18.0
4,0,31:18.0
5,0,31:18.0
6,0,31:18.0
8,0,31:17.0
9,0,31:18.0
10,0,31:18.0
11,0,31:18.0
12,0,31:17.0
13,0,31:18.0
14,0,31:18.0
15,0,31:18.0
16,0,31:18.0
18,0,31:18.0
-15,1,31:18.0
-14,1,31:18.0
-13,1,31:18.0
-12,1,31:18.0
-11,1,31:18.0
-10,1,31:18.0
-9,1,31:18.0
-8,1,31:18.0
-6,1,31:18.0
1,1,31:18.0
2,1,31:18.0
3,1,31:18.0
4,1,31:18.0
5,1,31:18.0
6,1,31:18.0
8,1,31:18.0
9,1,31:18.0
10,1,31:17.0
11,1,31:18.0
12,1,31:18.0
13,1,31:18.0
14,1,31:18.0
16,1,31:18.0
17,1,31:18.0
18,1,31:18.0
19,1,31:18.0
-14,2,31:18.0
-13,2,31:18.0
-12,2,31:17.0
-11,2,31:18.0
-10,2,31:18.0
-9,2,31:18.0
-8,2,31:18.0
-7,2,31:18.0
-6,2,31:17.0
-5,2,31:18.0
3,2,31:18.0
5,2,31:18.0
6,2,31:18.0
7,2,31:18.0
9,2,31:18.0
10,2,31:18.0
11,2,31:18.0
12,2,31:18.0
13,2,31:17.0
15,2,31:18.0
16,2,31:18.0
17,2,31:18.0
18,2,31:18.0
19,2,31:18.0
20,2,31:18.0
-15,3,31:18.0
-14,3,31:18.0
-13,3,31:18.0
-12,3,31:18.0
-11,3,31:18.0
-10,3,31:17.0
-9,3,31:18.0
-8,3,31:18.0
-7,3,31:18.0
-6,3,31:18.0
-5,3,31:18.0
-4,3,31:18.0
-1,3,31:18.0
4,3,31:17.0
5,3,31:18.0
7,3,31:17.0
8,3,31:18.0
12,3,31:18.0
15,3,31:18.0
16,3,31:17.0
17,3,31:18.0
18,3,31:18.0
19,3,31:18.0
20,3,31:18.0
21,3,31:18.0
-14,4,31:18.0
-13,4,31:18.0
-12,4,31:18.0
-11,4,31:18.0
-10,4,31:18.0
-9,4,31:18.0
-8,4,31:18.0
-7,4,31:17.0
-6,4,31:18.0
-5,4,31:18.0
-4,4,31:18.0
-2,4,31:18.0
-1,4,31:18.0
0,4,31:18.0
1,4,31:18.0
3,4,31:17.0
4,4,31:18.0
5,4,31:18.0
6,4,31:18.0
7,4,31:18.0
8,4,31:18.0
11,4,31:18.0
13,4,31:18.0
14,4,31:18.0
15,4,31:18.0
16,4,31:18.0
17,4,31:18.0
18,4,31:17.0
19,4,31:18.0
20,4,31:18.0
-13,5,31:18.0
-12,5,31:18.0
-11,5,31:18.0
-10,5,31:18.0
-9,5,31:18.0
-8,5,31:18.0
-7,5,31:18.0
-6,5,31:18.0
-5,5,31:18.0
-4,5,31:18.0
-3,5,31:17.0
-2,5,31:17.0
-1,5,31:18.0
0,5,31:18.0
1,5,31:18.0
4,5,31:18.0
5,5,31:18.0
6,5,31:18.0
7,5,31:18.0
10,5,31:18.0
11,5,31:18.0
12,5,31:18.0
13,5,31:18.0
14,5,31:18.0
15,5,31:18.0
16,5,31:18.0
17,5,31:18.0
18,5,31:18.0
19,5,31:18.0
20,5,31:18.0
21,5,31:18.0
-12,6,31:18.0
-11,6,31:18.0
-10,6,31:18.0
-9,6,31:18.0
-8,6,31:18.0
-7,6,31:18.0
-6,6,31:18.0
-5,6,31:18.0
-4,6,31:18.0
-3,6,31:18.0
-1,6,31:18.0
0,6,31:18.0
4,6,31:18.0
5,6,31:18.0
6,6,31:17.0
7,6,31:18.0
8,6,31:18.0
9,6,31:18.0
10,6,31:18.0
11,6,31:17.0
12,6,31:18.0
13,6,31:18.0
14,6,31:18.0
15,6,31:18.0
16,6,31:18.0
17,6,31:18.0
18,6,31:18.0
19,6,31:18.0
-13,7,31:18.0
-12,7,31:18.0
-11,7,31:18.0
-10,7,31:18.0
-8,7,31:18.0
-7,7,31:18.0
-6,7,31:18.0
-5,7,31:18.0
-4,7,31:18.0
4,7,31:17.0
5,7,31:17.0
6,7,31:18.0
7,7,31:18.0
8,7,31:18.0
9,7,31:18.0
10,7,31:18.0
11,7,31:18.0
12,7,31:18.0
13,7,31:18.0
14,7,31:17.0
15,7,31:18.0
16,7,31:18.0
17,7,31:18.0
18,7,31:18.0
19,7,31:18.0
20,7,31:18.0
-14,8,31:18.0
-13,8,31:18.0
-12,8,31:18.0
-11,8,31:18.0
-10,8,31:18.0
-7,8,31:18.0
-6,8,31:18.0
-4,8,31:18.0
-3,8,31:18.0
0,8,31:18.0
1,8,31:18.0
2,8,31:18.0
5,8,31:18.0
6,8,31:18.0
7,8,31:18.0
8,8,31:18.0
9,8,31:18.0
10,8,31:18.0
11,8,31:18.0
12,8,31:18.0
13,8,31:18.0
14,8,31:18.0
15,8,31:18.0
16,8,31:18.0
17,8,31:18.0
18,8,31:18.0
19,8,31:18.0
20,8,31:18.0
21,8,31:18.0
-14,9,31:18.0
-13,9,31:18.0
-12,9,31:18.0
-11,9,31:18.0
-10,9,31:18.0
-9,9,31:18.0
-8,9,31:18.0
-7,9,31:18.0
-6,9,31:18.0
-3,9,31:17.0
-2,9,31:18.0
-1,9,31:18.0
0,9,31:18.0
1,9,31:18.0
2,9,31:18.0
3,9,31:17.0
5,9,31:18.0
6,9,31:18.0
7,9,31:18.0
8,9,31:18.0
9,9,31:18.0
10,9,31:18.0
11,9,31:18.0
12,9,31:18.0
13,9,31:18.0
14,9,31:18.0
15,9,31:18.0
16,9,31:18.0
17,9,31:18.0
18,9,31:18.0
19,9,31:18.0
20,9,31:18.0
-14,10,31:18.0
-13,10,31:18.0
-12,10,31:17.0
-11,10,31:18.0
-10,10,31:18.0
-9,10,31:18.0
-8,10,31:18.0
-7,10,31:18.0
-6,10,31:18.0
-5,10,31:18.0
-4,10,31:17.0
-3,10,31:18.0
-2,10,31:18.0
-1,10,31:18.0
0,10,31:18.0
1,10,31:18.0
2,10,31:18.0
3,10,31:18.0
4,10,31:18.0
5,10,31:18.0
6,10,31:18.0
7,10,31:18.0
8,10,31:18.0
9,10,31:17.0
10,10,31:18.0
11,10,31:18.0
12,10,31:18.0
13,10,31:18.0
14,10,31:18.0
15,10,31:18.0
16,10,31:18.0
17,10,31:18.0
18,10,31:18.0
19,10,31:18.0
-15,11,31:18.0
-14,11,31:18.0
-13,11,31:18.0
-12,11,31:18.0
-11,11,31:18.0
-10,11,31:18.0
-9,11,31:18.0
-8,11,31:18.0
-7,11,31:18.0
-4,11,31:18.0
-3,11,31:18.0
-2,11,31:18.0
-1,11,31:18.0
0,11,31:18.0
