[META]
version=2.0
spawnOnBlockType=1,2,3,12,13
spawnSunlight=True
spawnDarkness=True
spawnWater=False
spawnLava=False
underFill=True
randomRotation=True
dig=True
tree=False
branch=False
needsFoundation=True
rarity=999
collisionPercentage=100
spawnElevationMin=0
spawnElevationMax=256
spawnInBiome=TallForest
[DATA]
5,-21,0:17.1
5,-11,0:17.1
5,-10,0:17.1
5,-9,0:17.1
5,-8,0:17.1
5,-7,0:17.1
5,-6,0:17.1
5,-5,0:17.1
5,-4,0:17.1
6,-22,0:17.1
6,-21,0:17.1
6,-20,0:17.1
6,-12,0:17.1
6,-11,0:17.1
6,-10,0:17.1
6,-9,0:17.1
6,-8,0:17.1
6,-7,0:17.1
6,-6,0:17.1
6,-5,0:17.1
6,-4,0:17.1
7,-22,0:17.1
7,-21,0:17.1
7,-20,0:17.1
7,-19,0:17.1
7,-13,0:17.1
7,-12,0:17.1
7,-11,0:17.1
7,-10,0:17.1
7,-9,0:17.1
7,-8,0:17.1
7,-7,0:17.1
7,-6,0:17.1
7,-5,0:17.1
7,-4,0:17.1
8,-22,0:17.1
8,-21,0:17.1
8,-20,0:17.1
8,-19,0:17.1
8,-18,0:17.1
8,-17,0:17.1
8,-16,0:17.1
8,-15,0:17.1
8,-14,0:17.1
8,-13,0:17.1
8,-12,0:17.1
8,-11,0:17.1
8,-10,0:17.1
8,-9,0:17.1
8,-8,0:17.1
8,-7,0:17.1
8,-6,0:17.1
8,-5,0:17.1
8,-4,0:17.1
9,-23,0:17.1
9,-22,0:17.1
9,-21,0:17.1
9,-20,0:17.1
9,-19,0:17.1
9,-18,0:17.1
9,-17,0:17.1
9,-16,0:17.1
9,-15,0:17.1
9,-14,0:17.1
9,-13,0:17.1
9,-12,0:17.1
9,-11,0:17.1
9,-10,0:17.1
9,-9,0:17.1
9,-8,0:17.1
9,-7,0:17.1
9,-6,0:17.1
9,-5,0:17.1
9,-4,0:17.1
9,-3,0:17.1
10,-24,0:17.1
10,-23,0:17.1
10,-22,0:17.1
10,-21,0:17.1
10,-20,0:17.1
10,-19,0:17.1
10,-18,0:17.1
10,-17,0:17.1
10,-16,0:17.1
10,-15,0:17.1
10,-14,0:17.1
10,-13,0:17.1
10,-12,0:17.1
10,-11,0:17.1
10,-10,0:17.1
10,-9,0:17.1
10,-8,0:17.1
10,-7,0:17.1
10,-6,0:17.1
10,-5,0:17.1
10,-4,0:17.1
10,-3,0:17.1
10,-2,0:17.1
11,-25,0:17.1
11,-24,0:17.1
11,-23,0:17.1
11,-22,0:17.1
11,-21,0:17.1
11,-20,0:17.1
11,-19,0:17.1
11,-18,0:17.1
11,-17,0:17.1
11,-16,0:17.1
11,-15,0:17.1
11,-14,0:17.1
11,-13,0:17.1
11,-12,0:17.1
11,-11,0:17.1
11,-10,0:17.1
11,-9,0:17.1
11,-8,0:17.1
11,-7,0:17.1
11,-6,0:17.1
11,-5,0:17.1
11,-4,0:17.1
11,-3,0:17.1
11,-2,0:17.1
11,-1,0:17.1
12,-26,0:17.1
12,-25,0:17.1
12,-24,0:17.1
12,-23,0:17.1
12,-22,0:17.1
12,-21,0:17.1
12,-20,0:17.1
12,-19,0:17.1
12,-18,0:17.1
12,-17,0:17.1
12,-16,0:17.1
12,-15,0:17.1
12,-14,0:17.1
12,-13,0:17.1
12,-12,0:17.1
12,-11,0:17.1
12,-10,0:17.1
12,-9,0:17.1
12,-8,0:17.1
12,-7,0:17.1
12,-6,0:17.1
12,-5,0:17.1
12,-4,0:17.1
12,-3,0:17.1
12,-2,0:17.1
12,-1,0:17.1
12,0,0:17.1
13,-31,0:17.1
13,-30,0:17.1
13,-29,0:17.1
13,-28,0:17.1
13,-27,0:17.1
13,-26,0:17.1
13,-25,0:17.1
13,-24,0:17.1
13,-23,0:17.1
13,-22,0:17.1
13,-21,0:17.1
13,-20,0:17.1
13,-19,0:17.1
13,-18,0:17.1
13,-17,0:17.1
13,-16,0:17.1
13,-15,0:17.1
13,-14,0:17.1
13,-13,0:17.1
13,-12,0:17.1
13,-11,0:17.1
13,-10,0:17.1
13,-9,0:17.1
13,-8,0:17.1
13,-7,0:17.1
13,-6,0:17.1
13,-5,0:17.1
13,-4,0:17.1
13,-3,0:17.1
13,-2,0:17.1
13,-1,0:17.1
13,0,0:17.1
13,1,0:17.1
13,2,0:17.1
14,-32,0:17.1
14,-31,0:17.1
14,-30,0:17.1
14,-29,0:17.1
14,-28,0:17.1
14,-27,0:17.1
14,-26,0:17.1
14,-25,0:17.1
14,-24,0:17.1
14,-23,0:17.1
14,-22,0:17.1
14,-21,0:17.1
14,-20,0:17.1
14,-19,0:17.1
14,-18,0:17.1
14,-17,0:17.1
14,-16,0:17.1
14,-15,0:17.1
14,-14,0:17.1
14,-13,0:17.1
14,-12,0:17.1
14,-11,0:17.1
14,-10,0:17.1
14,-9,0:17.1
14,-8,0:17.1
14,-7,0:17.1
14,-6,0:17.1
14,-5,0:17.1
14,-4,0:17.1
14,-3,0:17.1
14,-2,0:17.1
14,-1,0:17.1
14,0,0:17.1
14,1,0:17.1
15,-33,0:17.1
15,-32,0:17.1
15,-31,0:17.1
15,-30,0:17.1
15,-29,0:17.1
15,-28,0:17.1
15,-27,0:17.1
15,-26,0:17.1
15,-25,0:17.1
15,-24,0:17.1
15,-23,0:17.1
15,-22,0:17.1
15,-21,0:17.1
15,-20,0:17.1
15,-19,0:17.1
15,-18,0:17.1
15,-17,0:17.1
15,-16,0:17.1
15,-15,0:17.1
15,-14,0:17.1
15,-13,0:17.1
15,-12,0:17.1
15,-11,0:17.1
15,-10,0:17.1
15,-9,0:17.1
15,-8,0:17.1
15,-7,0:17.1
15,-6,0:17.1
15,-5,0:17.1
15,-4,0:17.1
15,-3,0:17.1
15,-2,0:17.1
15,-1,0:17.1
15,0,0:17.1
16,-34,0:17.1
16,-33,0:17.1
16,-32,0:17.1
16,-31,0:17.1
16,-30,0:17.1
16,-29,0:17.1
16,-28,0:17.1
16,-27,0:17.1
16,-26,0:17.1
16,-25,0:17.1
16,-24,0:17.1
16,-23,0:17.1
16,-22,0:17.1
16,-21,0:17.1
16,-20,0:17.1
16,-19,0:17.1
16,-18,0:17.1
16,-17,0:17.1
16,-16,0:17.1
16,-15,0:17.1
16,-14,0:17.1
16,-13,0:17.1
16,-12,0:17.1
16,-11,0:17.1
16,-10,0:17.1
16,-9,0:17.1
16,-8,0:17.1
16,-7,0:17.1
16,-6,0:17.1
16,-5,0:17.1
16,-4,0:17.1
16,-3,0:17.1
16,-2,0:17.1
16,-1,0:17.1
17,-35,0:17.1
17,-34,0:17.1
17,-33,0:17.1
17,-32,0:17.1
17,-31,0:17.1
17,-30,0:17.1
17,-29,0:17.1
17,-28,0:17.1
17,-27,0:17.1
17,-26,0:17.1
17,-25,0:17.1
17,-24,0:17.1
17,-23,0:17.1
17,-22,0:17.1
17,-21,0:17.1
17,-20,0:17.1
17,-19,0:17.1
17,-18,0:17.1
17,-17,0:17.1
17,-16,0:17.1
17,-15,0:17.1
17,-14,0:17.1
17,-13,0:17.1
17,-12,0:17.1
17,-11,0:17.1
17,-10,0:17.1
17,-9,0:17.1
17,-8,0:17.1
17,-7,0:17.1
17,-6,0:17.1
17,-5,0:17.1
17,-4,0:17.1
17,-3,0:17.1
17,-2,0:17.1
18,-36,0:17.1
18,-35,0:17.1
18,-34,0:17.1
18,-33,0:17.1
18,-32,0:17.1
18,-31,0:17.1
18,-30,0:17.1
18,-29,0:17.1
18,-28,0:17.1
18,-27,0:17.1
18,-26,0:17.1
18,-25,0:17.1
18,-24,0:17.1
18,-23,0:17.1
18,-22,0:17.1
18,-21,0:17.1
18,-20,0:17.1
18,-19,0:17.1
18,-18,0:17.1
18,-17,0:17.1
18,-16,0:17.1
18,-15,0:17.1
18,-14,0:17.1
18,-13,0:17.1
18,-12,0:17.1
18,-11,0:17.1
18,-10,0:17.1
18,-9,0:17.1
18,-8,0:17.1
18,-7,0:17.1
18,-6,0:17.1
18,-5,0:17.1
18,-4,0:17.1
18,-3,0:17.1
18,-2,0:17.1
19,-37,0:17.1
19,-36,0:17.1
19,-35,0:17.1
19,-34,0:17.1
19,-33,0:17.1
19,-32,0:17.1
19,-31,0:17.1
19,-30,0:17.1
19,-29,0:17.1
19,-28,0:17.1
19,-27,0:17.1
19,-26,0:17.1
19,-25,0:17.1
19,-24,0:17.1
19,-23,0:17.1
19,-22,0:17.1
19,-21,0:17.1
19,-20,0:17.1
19,-19,0:17.1
19,-18,0:17.1
19,-17,0:17.1
19,-16,0:17.1
19,-15,0:17.1
19,-14,0:17.1
19,-13,0:17.1
19,-12,0:17.1
19,-11,0:17.1
19,-10,0:17.1
19,-9,0:17.1
19,-8,0:17.1
19,-7,0:17.1
19,-6,0:17.1
19,-5,0:17.1
19,-4,0:17.1
19,-3,0:17.1
19,-2,0:17.1
20,-38,0:17.1
20,-37,0:17.1
20,-36,0:17.1
20,-35,0:17.1
20,-34,0:17.1
20,-33,0:17.1
20,-32,0:17.1
20,-31,0:17.1
20,-30,0:17.1
20,-29,0:17.1
20,-28,0:17.1
20,-27,0:17.1
20,-26,0:17.1
20,-25,0:17.1
20,-24,0:17.1
20,-23,0:17.1
20,-22,0:17.1
20,-21,0:17.1
20,-20,0:17.1
20,-19,0:17.1
20,-18,0:17.1
20,-17,0:17.1
20,-16,0:17.1
20,-15,0:17.1
20,-14,0:17.1
20,-13,0:17.1
20,-12,0:17.1
20,-11,0:17.1
20,-10,0:17.1
20,-9,0:17.1
20,-8,0:17.1
20,-7,0:17.1
20,-6,0:17.1
20,-5,0:17.1
20,-4,0:17.1
20,-3,0:17.1
20,-2,0:17.1
21,-39,0:17.1
21,-38,0:17.1
21,-37,0:17.1
21,-36,0:17.1
21,-35,0:17.1
21,-34,0:17.1
21,-33,0:17.1
21,-32,0:17.1
21,-31,0:17.1
21,-30,0:17.1
21,-29,0:17.1
21,-28,0:17.1
21,-27,0:17.1
21,-26,0:17.1
21,-25,0:17.1
21,-24,0:17.1
21,-23,0:17.1
21,-22,0:17.1
21,-21,0:17.1
21,-20,0:17.1
21,-19,0:17.1
21,-18,0:17.1
21,-17,0:17.1
21,-16,0:17.1
21,-15,0:17.1
21,-14,0:17.1
21,-13,0:17.1
21,-12,0:17.1
21,-11,0:17.1
21,-10,0:17.1
21,-9,0:17.1
21,-8,0:17.1
21,-7,0:17.1
21,-6,0:17.1
21,-5,0:17.1
21,-4,0:17.1
21,-3,0:17.1
21,-2,0:17.1
22,-39,0:17.1
22,-38,0:17.1
22,-37,0:17.1
22,-36,0:17.1
22,-35,0:17.1
22,-34,0:17.1
22,-33,0:17.1
22,-32,0:17.1
22,-31,0:17.1
22,-30,0:17.1
22,-29,0:17.1
22,-28,0:17.1
22,-27,0:17.1
22,-26,0:17.1
22,-25,0:17.1
22,-24,0:17.1
22,-23,0:17.1
22,-22,0:17.1
22,-21,0:17.1
22,-20,0:17.1
22,-19,0:17.1
22,-18,0:17.1
22,-17,0:17.1
22,-16,0:17.1
22,-15,0:17.1
22,-14,0:17.1
22,-13,0:17.1
22,-12,0:17.1
22,-11,0:17.1
22,-10,0:17.1
22,-9,0:17.1
22,-8,0:17.1
22,-7,0:17.1
22,-6,0:17.1
22,-5,0:17.1
22,-4,0:17.1
22,-3,0:17.1
22,-2,0:17.1
22,-1,0:17.1
23,-39,0:17.1
23,-38,0:17.1
23,-37,0:17.1
23,-36,0:17.1
23,-35,0:17.1
23,-34,0:17.1
23,-33,0:17.1
23,-32,0:17.1
23,-31,0:17.1
23,-30,0:17.1
23,-29,0:17.1
23,-28,0:17.1
23,-27,0:17.1
23,-26,0:17.1
23,-25,0:17.1
23,-24,0:17.1
23,-23,0:17.1
23,-22,0:17.1
23,-21,0:17.1
23,-20,0:17.1
23,-19,0:17.1
23,-18,0:17.1
23,-17,0:17.1
23,-16,0:17.1
23,-15,0:17.1
23,-14,0:17.1
23,-13,0:17.1
23,-12,0:17.1
23,-11,0:17.1
23,-10,0:17.1
23,-9,0:17.1
23,-8,0:17.1
23,-7,0:17.1
23,-6,0:17.1
23,-5,0:17.1
23,-4,0:17.1
23,-3,0:17.1
23,-2,0:17.1
23,-1,0:17.1
23,0,0:17.1
24,-39,0:17.1
24,-38,0:17.1
24,-37,0:17.1
24,-36,0:17.1
24,-35,0:17.1
24,-34,0:17.1
24,-33,0:17.1
24,-32,0:17.1
24,-31,0:17.1
24,-30,0:17.1
24,-29,0:17.1
24,-28,0:17.1
24,-27,0:17.1
24,-26,0:17.1
24,-25,0:17.1
24,-24,0:17.1
24,-23,0:17.1
24,-22,0:17.1
24,-21,0:17.1
24,-20,0:17.1
24,-19,0:17.1
24,-18,0:17.1
24,-17,0:17.1
24,-16,0:17.1
24,-15,0:17.1
24,-14,0:17.1
24,-13,0:17.1
24,-12,0:17.1
24,-11,0:17.1
24,-10,0:17.1
24,-9,0:17.1
24,-8,0:17.1
24,-7,0:17.1
24,-6,0:17.1
24,-5,0:17.1
24,-4,0:17.1
24,-3,0:17.1
24,-2,0:17.1
24,-1,0:17.1
24,0,0:17.1
24,1,0:17.1
25,-40,0:17.1
25,-39,0:17.1
25,-38,0:17.1
25,-37,0:17.1
25,-36,0:17.1
25,-35,0:17.1
25,-34,0:17.1
25,-33,0:17.1
25,-32,0:17.1
25,-31,0:17.1
25,-30,0:17.1
25,-29,0:17.1
25,-28,0:17.1
25,-27,0:17.1
25,-26,0:17.1
25,-25,0:17.1
25,-24,0:17.1
25,-23,0:17.1
25,-22,0:17.1
25,-21,0:17.1
25,-20,0:17.1
25,-19,0:17.1
25,-18,0:17.1
25,-17,0:17.1
25,-16,0:17.1
25,-15,0:17.1
25,-14,0:17.1
25,-13,0:17.1
25,-12,0:17.1
25,-11,0:17.1
25,-10,0:17.1
25,-9,0:17.1
25,-8,0:17.1
25,-7,0:17.1
25,-6,0:17.1
25,-5,0:17.1
25,-4,0:17.1
25,-3,0:17.1
25,-2,0:17.1
25,-1,0:17.1
25,0,0:17.1
25,1,0:17.1
25,2,0:17.1
26,-41,0:17.1
26,-40,0:17.1
26,-39,0:17.1
26,-38,0:17.1
26,-37,0:17.1
26,-36,0:17.1
26,-35,0:17.1
26,-34,0:17.1
26,-33,0:17.1
26,-32,0:17.1
26,-31,0:17.1
26,-30,0:17.1
26,-29,0:17.1
26,-28,0:17.1
26,-27,0:17.1
26,-26,0:17.1
26,-25,0:17.1
26,-24,0:17.1
26,-23,0:17.1
26,-22,0:17.1
26,-21,0:17.1
26,-20,0:17.1
26,-19,0:17.1
26,-18,0:17.1
26,-17,0:17.1
26,-16,0:17.1
26,-15,0:17.1
26,-14,0:17.1
26,-13,0:17.1
26,-12,0:17.1
26,-11,0:17.1
26,-10,0:17.1
26,-9,0:17.1
26,-8,0:17.1
26,-7,0:17.1
26,-6,0:17.1
26,-5,0:17.1
26,-4,0:17.1
26,-3,0:17.1
26,-2,0:17.1
26,-1,0:17.1
26,0,0:17.1
26,1,0:17.1
26,2,0:17.1
27,-42,0:17.1
27,-41,0:17.1
27,-40,0:17.1
27,-39,0:17.1
27,-38,0:17.1
27,-37,0:17.1
27,-36,0:17.1
27,-35,0:17.1
27,-34,0:17.1
27,-33,0:17.1
27,-32,0:17.1
27,-31,0:17.1
27,-30,0:17.1
27,-29,0:17.1
27,-28,0:17.1
27,-27,0:17.1
27,-26,0:17.1
27,-25,0:17.1
27,-24,0:17.1
27,-23,0:17.1
27,-22,0:17.1
27,-21,0:17.1
27,-20,0:17.1
27,-19,0:17.1
27,-18,0:17.1
27,-17,0:17.1
27,-16,0:17.1
27,-15,0:17.1
27,-14,0:17.1
27,-13,0:17.1
27,-12,0:17.1
27,-11,0:17.1
27,-10,0:17.1
27,-9,0:17.1
27,-8,0:17.1
27,-7,0:17.1
27,-6,0:17.1
27,-5,0:17.1
27,-4,0:17.1
27,-3,0:17.1
27,-2,0:17.1
27,-1,0:17.1
27,0,0:17.1
27,1,0:17.1
27,2,0:17.1
28,-43,0:17.1
28,-42,0:17.1
28,-41,0:17.1
28,-40,0:17.1
28,-39,0:17.1
28,-38,0:17.1
28,-37,0:17.1
28,-36,0:17.1
28,-35,0:17.1
28,-34,0:17.1
28,-33,0:17.1
28,-32,0:17.1
28,-31,0:17.1
28,-30,0:17.1
28,-29,0:17.1
28,-28,0:17.1
28,-27,0:17.1
28,-26,0:17.1
28,-25,0:17.1
28,-24,0:17.1
28,-23,0:17.1
28,-22,0:17.1
28,-21,0:17.1
28,-20,0:17.1
28,-19,0:17.1
28,-18,0:17.1
28,-17,0:17.1
28,-16,0:17.1
28,-15,0:17.1
28,-14,0:17.1
28,-13,0:17.1
28,-12,0:17.1
28,-11,0:17.1
28,-10,0:17.1
28,-9,0:17.1
28,-8,0:17.1
28,-7,0:17.1
28,-6,0:17.1
28,-5,0:17.1
28,-4,0:17.1
28,-3,0:17.1
28,-2,0:17.1
28,-1,0:17.1
28,0,0:17.1
28,1,0:17.1
28,2,0:17.1
28,3,0:17.1
29,-42,0:17.1
29,-41,0:17.1
29,-40,0:17.1
29,-39,0:17.1
29,-38,0:17.1
29,-37,0:17.1
29,-36,0:17.1
29,-35,0:17.1
29,-34,0:17.1
29,-33,0:17.1
29,-32,0:17.1
29,-31,0:17.1
29,-30,0:17.1
29,-29,0:17.1
29,-28,0:17.1
29,-27,0:17.1
29,-26,0:17.1
29,-25,0:17.1
29,-24,0:17.1
29,-23,0:17.1
29,-22,0:17.1
29,-21,0:17.1
29,-20,0:17.1
29,-19,0:17.1
29,-18,0:17.1
29,-17,0:17.1
29,-16,0:17.1
29,-15,0:17.1
29,-14,0:17.1
29,-13,0:17.1
29,-12,0:17.1
29,-11,0:17.1
29,-10,0:17.1
29,-9,0:17.1
29,-8,0:17.1
29,-7,0:17.1
29,-6,0:17.1
29,-5,0:17.1
29,-4,0:17.1
29,-3,0:17.1
29,-2,0:17.1
29,-1,0:17.1
29,0,0:17.1
29,1,0:17.1
29,2,0:17.1
29,3,0:17.1
30,-41,0:17.1
30,-40,0:17.1
30,-39,0:17.1
30,-38,0:17.1
30,-37,0:17.1
30,-36,0:17.1
30,-35,0:17.1
30,-34,0:17.1
30,-33,0:17.1
30,-32,0:17.1
30,-31,0:17.1
30,-30,0:17.1
30,-29,0:17.1
30,-28,0:17.1
30,-27,0:17.1
30,-26,0:17.1
30,-25,0:17.1
30,-24,0:17.1
30,-23,0:17.1
30,-22,0:17.1
30,-21,0:17.1
30,-20,0:17.1
30,-19,0:17.1
30,-18,0:17.1
30,-17,0:17.1
30,-16,0:17.1
30,-15,0:17.1
30,-14,0:17.1
30,-13,0:17.1
30,-12,0:17.1
30,-11,0:17.1
30,-10,0:17.1
30,-9,0:17.1
30,-8,0:17.1
30,-7,0:17.1
30,-6,0:17.1
30,-5,0:17.1
30,-4,0:17.1
30,-3,0:17.1
30,-2,0:17.1
30,-1,0:17.1
30,0,0:17.1
30,1,0:17.1
30,2,0:17.1
31,-40,0:17.1
31,-39,0:17.1
31,-38,0:17.1
31,-37,0:17.1
31,-36,0:17.1
31,-35,0:17.1
31,-34,0:17.1
31,-33,0:17.1
31,-32,0:17.1
31,-31,0:17.1
31,-30,0:17.1
31,-29,0:17.1
31,-28,0:17.1
31,-27,0:17.1
31,-26,0:17.1
31,-25,0:17.1
31,-24,0:17.1
31,-23,0:17.1
31,-22,0:17.1
31,-21,0:17.1
31,-20,0:17.1
31,-19,0:17.1
31,-18,0:17.1
31,-17,0:17.1
31,-16,0:17.1
31,-15,0:17.1
31,-14,0:17.1
31,-13,0:17.1
31,-12,0:17.1
31,-11,0:17.1
31,-10,0:17.1
31,-9,0:17.1
31,-8,0:17.1
31,-7,0:17.1
31,-6,0:17.1
31,-5,0:17.1
31,-4,0:17.1
31,-3,0:17.1
31,-2,0:17.1
31,-1,0:17.1
31,0,0:17.1
31,1,0:17.1
32,-38,0:17.1
32,-37,0:17.1
32,-36,0:17.1
32,-35,0:17.1
32,-34,0:17.1
32,-33,0:17.1
32,-32,0:17.1
32,-31,0:17.1
32,-30,0:17.1
32,-29,0:17.1
32,-28,0:17.1
32,-27,0:17.1
32,-26,0:17.1
32,-25,0:17.1
32,-24,0:17.1
32,-23,0:17.1
32,-22,0:17.1
32,-21,0:17.1
32,-20,0:17.1
32,-19,0:17.1
32,-18,0:17.1
32,-17,0:17.1
32,-16,0:17.1
32,-15,0:17.1
32,-14,0:17.1
32,-13,0:17.1
32,-12,0:17.1
32,-11,0:17.1
32,-10,0:17.1
32,-9,0:17.1
32,-8,0:17.1
32,-7,0:17.1
32,-6,0:17.1
32,-5,0:17.1
32,-4,0:17.1
32,-3,0:17.1
32,-2,0:17.1
32,-1,0:17.1
32,0,0:17.1
33,-37,0:17.1
33,-36,0:17.1
33,-35,0:17.1
33,-34,0:17.1
33,-33,0:17.1
33,-32,0:17.1
33,-31,0:17.1
33,-30,0:17.1
33,-29,0:17.1
33,-28,0:17.1
33,-27,0:17.1
33,-26,0:17.1
33,-25,0:17.1
33,-24,0:17.1
33,-23,0:17.1
33,-22,0:17.1
33,-21,0:17.1
33,-20,0:17.1
33,-19,0:17.1
33,-18,0:17.1
33,-17,0:17.1
33,-16,0:17.1
33,-15,0:17.1
33,-14,0:17.1
33,-13,0:17.1
33,-12,0:17.1
33,-11,0:17.1
33,-10,0:17.1
33,-9,0:17.1
33,-8,0:17.1
33,-7,0:17.1
33,-6,0:17.1
33,-5,0:17.1
33,-4,0:17.1
33,-3,0:17.1
33,-2,0:17.1
33,-1,0:17.1
33,0,0:17.1
34,-36,0:17.1
34,-35,0:17.1
34,-34,0:17.1
34,-33,0:17.1
34,-32,0:17.1
34,-31,0:17.1
34,-30,0:17.1
34,-29,0:17.1
34,-28,0:89
34,-27,0:89
34,-26,0:89
34,-25,0:89
34,-24,0:89
34,-23,0:17.1
34,-22,0:17.1
34,-21,0:17.1
34,-20,0:17.1
34,-19,0:17.1
34,-18,0:17.1
34,-17,0:17.1
34,-16,0:17.1
34,-15,0:17.1
34,-14,0:17.1
34,-13,0:17.1
34,-12,0:17.1
34,-11,0:17.1
34,-10,0:17.1
34,-9,0:17.1
34,-8,0:17.1
34,-7,0:17.1
34,-6,0:17.1
34,-5,0:17.1
34,-4,0:17.1
34,-3,0:17.1
34,-2,0:17.1
34,-1,0:17.1
34,0,0:17.1
35,-35,0:17.1
35,-34,0:17.1
35,-33,0:17.1
35,-32,0:17.1
35,-31,0:17.1
35,-30,0:17.1
35,-29,0:89
35,-28,0:89
35,-27,0:89
35,-26,0:89
35,-25,0:89
35,-24,0:89
35,-23,0:89
35,-22,0:17.1
35,-21,0:17.1
35,-20,0:17.1
35,-19,0:17.1
35,-18,0:17.1
35,-17,0:17.1
35,-16,0:17.1
35,-15,0:17.1
35,-14,0:17.1
35,-13,0:17.1
35,-12,0:17.1
35,-11,0:17.1
35,-10,0:17.1
35,-9,0:17.1
35,-8,0:17.1
35,-7,0:17.1
35,-6,0:17.1
35,-5,0:17.1
35,-4,0:17.1
35,-3,0:17.1
35,-2,0:17.1
35,-1,0:17.1
35,0,0:17.1
36,-34,0:17.1
36,-33,0:17.1
36,-32,0:17.1
36,-31,0:17.1
36,-30,0:89
36,-29,0:89
36,-28,0:89
36,-27,0:89
36,-26,0:89
36,-25,0:89
36,-24,0:89
36,-23,0:89
36,-22,0:89
36,-21,0:17.1
36,-20,0:17.1
36,-19,0:17.1
36,-18,0:17.1
36,-17,0:17.1
36,-16,0:17.1
36,-15,0:17.1
36,-14,0:17.1
36,-13,0:17.1
36,-12,0:17.1
36,-11,0:17.1
36,-10,0:17.1
36,-9,0:17.1
36,-8,0:17.1
36,-7,0:17.1
36,-6,0:17.1
36,-5,0:17.1
36,-4,0:17.1
36,-3,0:17.1
36,-2,0:17.1
36,-1,0:17.1
36,0,0:17.1
37,-34,0:17.1
37,-33,0:17.1
37,-32,0:17.1
37,-31,0:89
37,-30,0:89
37,-29,0:89
37,-28,0:89
37,-27,0:89
37,-26,0:89
37,-25,0:89
37,-24,0:89
37,-23,0:89
37,-22,0:89
37,-21,0:89
37,-20,0:17.1
37,-19,0:17.1
37,-18,0:17.1
37,-17,0:17.1
37,-16,0:17.1
37,-15,0:17.1
37,-14,0:17.1
37,-13,0:17.1
37,-12,0:17.1
37,-11,0:17.1
37,-10,0:17.1
37,-9,0:17.1
37,-8,0:17.1
37,-7,0:17.1
37,-6,0:17.1
37,-5,0:17.1
37,-4,0:17.1
37,-3,0:17.1
37,-2,0:17.1
37,-1,0:17.1
37,0,0:17.1
37,1,0:17.1
38,-19,0:17.1
38,-18,0:17.1
38,-17,0:17.1
38,-16,0:17.1
38,-15,0:17.1
38,-14,0:17.1
38,-13,0:17.1
38,-12,0:17.1
38,-11,0:17.1
38,-10,0:17.1
38,-9,0:17.1
38,-8,0:17.1
38,-7,0:17.1
38,-6,0:17.1
38,-5,0:17.1
38,-4,0:17.1
38,-3,0:17.1
38,-2,0:17.1
38,-1,0:17.1
38,0,0:17.1
38,1,0:17.1
38,2,0:17.1
39,-19,0:17.1
39,-18,0:17.1
39,-17,0:17.1
39,-16,0:17.1
39,-15,0:17.1
39,-14,0:17.1
39,-13,0:17.1
39,-12,0:17.1
39,-11,0:17.1
39,-10,0:17.1
39,-9,0:17.1
39,-8,0:17.1
39,-7,0:17.1
39,-6,0:17.1
39,-5,0:17.1
39,-4,0:17.1
39,-3,0:17.1
39,-2,0:17.1
39,-1,0:17.1
39,0,0:17.1
39,1,0:17.1
39,2,0:17.1
40,-19,0:17.1
40,-18,0:17.1
40,-17,0:17.1
40,-16,0:17.1
40,-15,0:17.1
40,-14,0:17.1
40,-13,0:17.1
40,-12,0:17.1
40,-11,0:17.1
40,-10,0:17.1
40,-9,0:17.1
40,-8,0:17.1
40,-7,0:17.1
40,-6,0:17.1
40,-5,0:17.1
40,-4,0:17.1
40,-3,0:17.1
40,-2,0:17.1
40,-1,0:17.1
40,0,0:17.1
40,1,0:17.1
41,-19,0:17.1
41,-18,0:17.1
41,-17,0:17.1
41,-16,0:17.1
41,-15,0:17.1
41,-14,0:17.1
41,-13,0:17.1
41,-12,0:17.1
41,-11,0:17.1
41,-10,0:17.1
41,-9,0:17.1
41,-8,0:17.1
41,-7,0:17.1
41,-6,0:17.1
41,-5,0:17.1
41,-4,0:17.1
41,-3,0:17.1
41,-2,0:17.1
41,-1,0:17.1
41,0,0:17.1
42,-19,0:17.1
42,-18,0:17.1
42,-17,0:17.1
42,-16,0:17.1
42,-15,0:17.1
42,-14,0:17.1
42,-13,0:17.1
42,-12,0:17.1
42,-11,0:17.1
42,-10,0:17.1
42,-9,0:17.1
42,-8,0:17.1
42,-7,0:17.1
42,-6,0:17.1
42,-5,0:17.1
42,-4,0:17.1
42,-3,0:17.1
42,-2,0:17.1
42,-1,0:17.1
43,-20,0:17.1
43,-19,0:17.1
43,-18,0:17.1
43,-17,0:17.1
43,-16,0:17.1
43,-15,0:17.1
43,-14,0:17.1
43,-13,0:17.1
43,-12,0:17.1
43,-11,0:17.1
43,-10,0:17.1
43,-9,0:17.1
43,-8,0:17.1
43,-7,0:17.1
43,-6,0:17.1
43,-5,0:17.1
43,-4,0:17.1
43,-3,0:17.1
43,-2,0:17.1
44,-21,0:17.1
44,-20,0:17.1
44,-19,0:17.1
44,-18,0:17.1
44,-17,0:17.1
44,-16,0:17.1
44,-15,0:17.1
44,-14,0:17.1
44,-13,0:17.1
44,-12,0:17.1
44,-11,0:17.1
44,-10,0:17.1
44,-9,0:17.1
44,-8,0:17.1
44,-7,0:17.1
44,-6,0:17.1
44,-5,0:17.1
44,-4,0:17.1
44,-3,0:17.1
44,-2,0:17.1
45,-21,0:17.1
45,-20,0:17.1
45,-19,0:17.1
45,-18,0:17.1
45,-17,0:17.1
45,-16,0:17.1
45,-15,0:17.1
45,-14,0:17.1
45,-13,0:17.1
45,-12,0:17.1
45,-11,0:17.1
45,-10,0:17.1
45,-9,0:17.1
45,-8,0:17.1
45,-7,0:17.1
45,-6,0:17.1
45,-5,0:17.1
45,-4,0:17.1
45,-3,0:17.1
45,-2,0:17.1
46,-20,0:17.1
46,-19,0:17.1
46,-18,0:17.1
46,-17,0:17.1
46,-16,0:17.1
46,-15,0:17.1
46,-14,0:17.1
46,-13,0:17.1
46,-12,0:17.1
46,-11,0:17.1
46,-10,0:17.1
46,-9,0:17.1
46,-8,0:17.1
46,-7,0:17.1
46,-6,0:17.1
46,-5,0:17.1
46,-4,0:17.1
46,-3,0:17.1
46,-2,0:17.1
47,-16,0:17.1
47,-15,0:17.1
47,-14,0:17.1
47,-13,0:17.1
47,-12,0:17.1
47,-11,0:17.1
47,-10,0:17.1
47,-9,0:17.1
47,-8,0:17.1
47,-7,0:17.1
47,-6,0:17.1
47,-5,0:17.1
47,-4,0:17.1
47,-3,0:17.1
48,-15,0:17.1
48,-14,0:17.1
48,-13,0:17.1
48,-12,0:17.1
48,-11,0:17.1
48,-10,0:17.1
48,-9,0:17.1
48,-8,0:17.1
48,-7,0:17.1
48,-6,0:17.1
48,-5,0:17.1
48,-4,0:17.1
49,-14,0:17.1
49,-13,0:17.1
49,-12,0:17.1
49,-11,0:17.1
49,-10,0:17.1
49,-9,0:17.1
49,-8,0:17.1
49,-7,0:17.1
49,-6,0:17.1
49,-5,0:17.1
50,-13,0:17.1
50,-12,0:17.1
50,-11,0:17.1
50,-10,0:17.1
50,-9,0:17.1
50,-8,0:17.1
50,-7,0:17.1
50,-6,0:17.1
51,-12,0:17.1
-1,-10,1:17.1
-1,-9,1:17.1
-1,-8,1:17.1
0,-12,1:17.1
0,-11,1:17.1
0,-10,1:17.1
0,-9,1:17.1
0,-8,1:17.1
0,-7,1:17.1
0,-6,1:17.1
1,-13,1:17.1
1,-12,1:17.1
1,-11,1:17.1
1,-10,1:17.1
1,-9,1:17.1
1,-8,1:17.1
1,-7,1:17.1
1,-6,1:17.1
1,-5,1:17.1
2,-24,1:17.1
2,-23,1:17.1
2,-22,1:17.1
2,-21,1:17.1
2,-20,1:17.1
2,-14,1:17.1
2,-13,1:17.1
2,-12,1:17.1
2,-11,1:17.1
2,-10,1:17.1
2,-9,1:17.1
2,-8,1:17.1
2,-7,1:17.1
2,-6,1:17.1
2,-5,1:17.1
2,-4,1:17.1
3,-25,1:17.1
3,-24,1:17.1
3,-23,1:17.1
3,-22,1:17.1
3,-21,1:17.1
3,-20,1:17.1
3,-19,1:17.1
3,-18,1:17.1
3,-15,1:17.1
3,-14,1:17.1
3,-13,1:17.1
3,-12,1:17.1
3,-11,1:17.1
3,-10,1:17.1
3,-9,1:17.1
3,-8,1:17.1
3,-7,1:17.1
3,-6,1:17.1
3,-5,1:17.1
3,-4,1:17.1
3,-3,1:17.1
4,-26,1:17.1
4,-25,1:17.1
4,-24,1:17.1
4,-23,1:17.1
4,-22,1:17.1
4,-21,1:17.1
4,-20,1:17.1
4,-19,1:17.1
4,-18,1:17.1
4,-17,1:17.1
4,-16,1:17.1
4,-15,1:17.1
4,-14,1:17.1
4,-13,1:17.1
4,-12,1:17.1
4,-11,1:17.1
4,-10,1:17.1
4,-9,1:17.1
4,-8,1:17.1
4,-7,1:17.1
4,-6,1:17.1
4,-5,1:17.1
4,-4,1:17.1
4,-3,1:17.1
4,-2,1:17.1
5,-27,1:17.1
5,-26,1:17.1
5,-25,1:17.1
5,-24,1:17.1
5,-23,1:17.1
5,-22,1:17.1
5,-21,1:17.1
5,-20,1:17.1
5,-19,1:17.1
5,-18,1:17.1
5,-17,1:17.1
5,-16,1:17.1
5,-15,1:17.1
5,-14,1:17.1
5,-13,1:17.1
5,-12,1:17.1
5,-11,1:17.1
5,-10,1:17.1
5,-9,1:17.1
5,-8,1:17.1
5,-7,1:17.1
5,-6,1:17.1
5,-5,1:17.1
5,-4,1:17.1
5,-3,1:17.1
5,-2,1:17.1
5,-1,1:17.1
6,-27,1:17.1
6,-26,1:17.1
6,-25,1:17.1
6,-24,1:17.1
6,-23,1:17.1
6,-22,1:17.1
6,-21,1:17.1
6,-20,1:17.1
6,-19,1:17.1
6,-18,1:17.1
6,-17,1:17.1
6,-16,1:17.1
6,-15,1:17.1
6,-14,1:17.1
6,-13,1:17.1
6,-12,1:17.1
6,-11,1:17.1
6,-10,1:17.1
6,-9,1:17.1
6,-8,1:17.1
6,-7,1:17.1
6,-6,1:17.1
6,-5,1:17.1
6,-4,1:17.1
6,-3,1:17.1
6,-2,1:17.1
6,-1,1:17.1
7,-27,1:17.1
7,-26,1:17.1
7,-25,1:17.1
7,-24,1:17.1
7,-23,1:17.1
7,-22,1:17.1
7,-21,1:17.1
7,-20,1:17.1
7,-19,1:17.1
7,-18,1:17.1
7,-17,1:17.1
7,-16,1:17.1
7,-15,1:17.1
7,-14,1:17.1
7,-13,1:17.1
7,-12,1:17.1
7,-11,1:17.1
7,-10,1:17.1
7,-9,1:17.1
7,-8,1:17.1
7,-7,1:17.1
7,-6,1:17.1
7,-5,1:17.1
7,-4,1:17.1
7,-3,1:17.1
7,-2,1:17.1
7,-1,1:17.1
8,-29,1:17.1
8,-28,1:17.1
8,-27,1:17.1
8,-26,1:17.1
8,-25,1:17.1
8,-24,1:17.1
8,-23,1:17.1
8,-22,1:17.1
8,-21,1:17.1
8,-20,1:17.1
8,-19,1:17.1
8,-18,1:17.1
8,-17,1:17.1
8,-16,1:17.1
8,-15,1:17.1
8,-14,1:17.1
8,-13,1:17.1
8,-12,1:17.1
8,-11,1:17.1
8,-10,1:17.1
8,-9,1:17.1
8,-8,1:17.1
8,-7,1:17.1
8,-6,1:17.1
8,-5,1:17.1
8,-4,1:17.1
8,-3,1:17.1
8,-2,1:17.1
8,-1,1:17.1
9,-30,1:17.1
9,-29,1:17.1
9,-28,1:17.1
9,-27,1:17.1
9,-26,1:17.1
9,-25,1:17.1
9,-24,1:17.1
9,-23,1:17.1
9,-22,1:17.1
9,-21,1:17.1
9,-20,1:17.1
9,-19,1:17.1
9,-18,1:17.1
9,-17,1:17.1
9,-16,1:17.1
9,-15,1:17.1
9,-14,1:17.1
9,-13,1:17.1
9,-12,1:17.1
9,-11,1:17.1
9,-10,1:17.1
9,-9,1:17.1
9,-8,1:17.1
9,-7,1:17.1
9,-6,1:17.1
9,-5,1:17.1
9,-4,1:17.1
9,-3,1:17.1
9,-2,1:17.1
9,-1,1:17.1
10,-31,1:17.1
10,-30,1:17.1
10,-29,1:17.1
10,-28,1:17.1
10,-27,1:17.1
10,-26,1:17.1
10,-25,1:17.1
10,-24,1:17.1
10,-23,1:17.1
10,-22,1:17.1
10,-21,1:17.1
10,-20,1:17.1
10,-19,1:17.1
10,-18,1:17.1
10,-17,1:17.1
10,-16,1:17.1
10,-15,1:17.1
10,-14,1:17.1
10,-13,1:17.1
10,-12,1:17.1
10,-11,1:17.1
10,-10,1:17.1
10,-9,1:17.1
10,-8,1:17.1
10,-7,1:17.1
10,-6,1:17.1
10,-5,1:17.1
10,-4,1:17.1
10,-3,1:17.1
10,-2,1:17.1
10,-1,1:17.1
11,-32,1:17.1
11,-31,1:17.1
11,-30,1:17.1
11,-29,1:17.1
11,-28,1:17.1
11,-27,1:17.1
11,-26,1:17.1
11,-25,1:17.1
11,-24,1:17.1
11,-23,1:17.1
11,-22,1:17.1
11,-21,1:17.1
11,-20,1:17.1
11,-19,1:17.1
11,-18,1:17.1
11,-17,1:17.1
11,-16,1:17.1
11,-15,1:17.1
11,-14,1:17.1
11,-13,1:17.1
11,-12,1:17.1
11,-11,1:17.1
11,-10,1:17.1
11,-9,1:17.1
11,-8,1:17.1
11,-7,1:17.1
11,-6,1:17.1
11,-5,1:17.1
11,-4,1:17.1
11,-3,1:17.1
11,-2,1:17.1
11,-1,1:17.1
11,0,1:17.1
12,-32,1:17.1
12,-31,1:17.1
12,-30,1:17.1
12,-29,1:17.1
12,-28,1:17.1
12,-27,1:17.1
12,-26,1:17.1
12,-25,1:17.1
12,-24,1:17.1
12,-23,1:17.1
12,-22,1:17.1
12,-21,1:17.1
12,-20,1:17.1
12,-19,1:17.1
12,-18,1:17.1
12,-17,1:17.1
12,-16,1:17.1
12,-15,1:17.1
12,-14,1:17.1
12,-13,1:17.1
12,-12,1:17.1
12,-11,1:17.1
12,-10,1:17.1
12,-9,1:17.1
12,-8,1:17.1
12,-7,1:17.1
12,-6,1:17.1
12,-5,1:17.1
12,-4,1:17.1
12,-3,1:17.1
12,-2,1:17.1
12,-1,1:17.1
12,0,1:17.1
12,1,1:17.1
13,-32,1:17.1
13,-31,1:17.1
13,-30,1:17.1
13,-29,1:17.1
13,-28,1:17.1
13,-27,1:17.1
13,-26,1:17.1
13,-25,1:17.1
13,-24,1:17.1
13,-23,1:17.1
13,-22,1:17.1
13,-21,1:17.1
13,-20,1:17.1
13,-19,1:17.1
13,-18,1:17.1
13,-17,1:17.1
13,-16,1:17.1
13,-15,1:17.1
13,-14,1:17.1
13,-13,1:17.1
13,-12,1:17.1
13,-11,1:17.1
13,-10,1:17.1
13,-9,1:17.1
13,-8,1:17.1
13,-7,1:17.1
13,-6,1:17.1
13,-5,1:17.1
13,-4,1:17.1
13,-3,1:17.1
13,-2,1:17.1
13,-1,1:17.1
13,0,1:17.1
13,1,1:17.1
13,2,1:17.1
14,-33,1:17.1
14,-32,1:17.1
14,-31,1:17.1
14,-30,1:17.1
14,-29,1:17.1
14,-28,1:17.1
14,-27,1:17.1
14,-26,1:17.1
14,-25,1:17.1
14,-24,1:17.1
14,-23,1:17.1
14,-22,1:17.1
14,-21,1:17.1
14,-20,1:17.1
14,-19,1:17.1
14,-18,1:17.1
14,-17,1:17.1
14,-16,1:17.1
14,-15,1:17.1
14,-14,1:17.1
14,-13,1:17.1
14,-12,1:17.1
14,-11,1:17.1
14,-10,1:17.1
14,-9,1:17.1
14,-8,1:17.1
14,-7,1:17.1
14,-6,1:17.1
14,-5,1:17.1
14,-4,1:17.1
14,-3,1:17.1
14,-2,1:17.1
14,-1,1:17.1
14,0,1:17.1
14,1,1:17.1
14,2,1:17.1
15,-34,1:17.1
15,-33,1:17.1
15,-32,1:17.1
15,-31,1:17.1
15,-30,1:17.1
15,-29,1:17.1
15,-28,1:17.1
15,-27,1:17.1
15,-26,1:17.1
15,-25,1:17.1
15,-24,1:17.1
15,-23,1:17.1
15,-22,1:17.1
15,-21,1:17.1
15,-20,1:17.1
15,-19,1:17.1
15,-18,1:17.1
15,-17,1:17.1
15,-16,1:17.1
15,-15,1:17.1
15,-14,1:17.1
15,-13,1:17.1
15,-12,1:17.1
15,-11,1:17.1
15,-10,1:17.1
15,-9,1:17.1
15,-8,1:17.1
15,-7,1:17.1
15,-6,1:17.1
15,-5,1:17.1
15,-4,1:17.1
15,-3,1:17.1
15,-2,1:17.1
15,-1,1:17.1
15,0,1:17.1
15,1,1:17.1
15,2,1:17.1
15,3,1:17.1
16,-35,1:17.1
16,-34,1:17.1
16,-33,1:17.1
16,-32,1:17.1
16,-31,1:17.1
16,-30,1:17.1
16,-29,1:17.1
16,-28,1:17.1
16,-27,1:17.1
16,-26,1:17.1
16,-25,1:17.1
16,-24,1:17.1
16,-23,1:17.1
16,-22,1:17.1
16,-21,1:17.1
16,-20,1:17.1
16,-19,1:17.1
16,-18,1:17.1
16,-17,1:17.1
16,-16,1:17.1
16,-15,1:17.1
16,-14,1:17.1
16,-13,1:17.1
16,-12,1:17.1
16,-11,1:17.1
16,-10,1:17.1
16,-9,1:17.1
16,-8,1:17.1
16,-7,1:17.1
16,-6,1:17.1
16,-5,1:17.1
16,-4,1:17.1
16,-3,1:17.1
16,-2,1:17.1
16,-1,1:17.1
16,0,1:17.1
16,1,1:17.1
16,2,1:17.1
16,3,1:17.1
17,-36,1:17.1
17,-35,1:17.1
17,-34,1:17.1
17,-33,1:17.1
17,-32,1:17.1
17,-31,1:17.1
17,-30,1:17.1
17,-29,1:17.1
17,-28,1:17.1
17,-27,1:17.1
17,-26,1:17.1
17,-25,1:17.1
17,-24,1:17.1
17,-23,1:17.1
17,-22,1:17.1
17,-21,1:17.1
17,-20,1:17.1
17,-19,1:17.1
17,-18,1:17.1
17,-17,1:17.1
17,-16,1:17.1
17,-15,1:17.1
17,-14,1:17.1
17,-13,1:17.1
17,-12,1:17.1
17,-11,1:17.1
17,-10,1:17.1
17,-9,1:17.1
17,-8,1:17.1
17,-7,1:17.1
17,-6,1:17.1
17,-5,1:17.1
17,-4,1:17.1
17,-3,1:17.1
17,-2,1:17.1
17,-1,1:17.1
17,0,1:17.1
17,1,1:17.1
17,2,1:17.1
17,3,1:17.1
17,4,1:17.1
18,-37,1:17.1
18,-36,1:17.1
18,-35,1:17.1
18,-34,1:17.1
18,-33,1:17.1
18,-32,1:17.1
18,-31,1:17.1
18,-30,1:17.1
18,-29,1:17.1
18,-28,1:17.1
18,-27,1:17.1
18,-26,1:17.1
18,-25,1:17.1
18,-24,1:17.1
18,-23,1:17.1
18,-22,1:17.1
18,-21,1:17.1
18,-20,1:17.1
18,-19,1:17.1
18,-18,1:17.1
18,-17,1:17.1
18,-16,1:17.1
18,-15,1:17.1
18,-14,1:17.1
18,-13,1:17.1
18,-12,1:17.1
18,-11,1:17.1
18,-10,1:17.1
18,-9,1:17.1
18,-8,1:17.1
18,-7,1:17.1
18,-6,1:17.1
18,-5,1:17.1
18,-4,1:17.1
18,-3,1:17.1
18,-2,1:17.1
18,-1,1:17.1
18,0,1:17.1
18,1,1:17.1
18,2,1:17.1
18,3,1:17.1
18,4,1:17.1
19,-37,1:17.1
19,-36,1:17.1
19,-35,1:17.1
19,-34,1:17.1
19,-33,1:17.1
19,-32,1:17.1
19,-31,1:17.1
19,-30,1:17.1
19,-29,1:17.1
19,-28,1:17.1
19,-27,1:17.1
19,-26,1:17.1
19,-25,1:17.1
19,-24,1:17.1
19,-23,1:17.1
19,-22,1:17.1
19,-21,1:17.1
19,-20,1:17.1
19,-19,1:17.1
19,-18,1:17.1
19,-17,1:17.1
19,-16,1:17.1
19,-15,1:17.1
19,-14,1:17.1
19,-13,1:17.1
19,-12,1:17.1
19,-11,1:17.1
19,-10,1:17.1
19,-9,1:17.1
19,-8,1:17.1
19,-7,1:17.1
19,-6,1:17.1
19,-5,1:17.1
19,-4,1:17.1
19,-3,1:17.1
19,-2,1:17.1
19,-1,1:17.1
19,0,1:17.1
19,1,1:17.1
19,2,1:17.1
19,3,1:17.1
19,4,1:17.1
20,-39,1:17.1
20,-38,1:17.1
20,-37,1:17.1
20,-36,1:17.1
20,-35,1:17.1
20,-34,1:17.1
20,-33,1:17.1
20,-32,1:17.1
20,-31,1:17.1
20,-30,1:17.1
20,-29,1:17.1
20,-28,1:17.1
20,-27,1:17.1
20,-26,1:17.1
20,-25,1:17.1
20,-24,1:17.1
20,-23,1:17.1
20,-22,1:17.1
20,-21,1:17.1
20,-20,1:17.1
20,-19,1:17.1
20,-18,1:17.1
20,-17,1:17.1
20,-16,1:17.1
20,-15,1:17.1
20,-14,1:17.1
20,-13,1:17.1
20,-12,1:17.1
20,-11,1:17.1
20,-10,1:17.1
20,-9,1:17.1
20,-8,1:17.1
20,-7,1:17.1
20,-6,1:17.1
20,-5,1:17.1
20,-4,1:17.1
20,-3,1:17.1
20,-2,1:17.1
20,-1,1:17.1
20,0,1:17.1
20,1,1:17.1
20,2,1:17.1
20,3,1:17.1
20,4,1:17.1
21,-40,1:17.1
21,-39,1:17.1
21,-38,1:17.1
21,-37,1:17.1
21,-36,1:17.1
21,-35,1:17.1
21,-34,1:17.1
21,-33,1:17.1
21,-32,1:17.1
21,-31,1:17.1
21,-30,1:17.1
21,-29,1:17.1
21,-28,1:17.1
21,-27,1:17.1
21,-26,1:17.1
21,-25,1:17.1
21,-24,1:17.1
21,-23,1:17.1
21,-22,1:17.1
21,-21,1:17.1
21,-20,1:17.1
21,-19,1:17.1
21,-18,1:17.1
21,-17,1:17.1
21,-16,1:17.1
21,-15,1:17.1
21,-14,1:17.1
21,-13,1:17.1
21,-12,1:17.1
21,-11,1:17.1
21,-10,1:17.1
21,-9,1:17.1
21,-8,1:17.1
21,-7,1:17.1
21,-6,1:17.1
21,-5,1:17.1
21,-4,1:17.1
21,-3,1:17.1
21,-2,1:17.1
21,-1,1:17.1
21,0,1:17.1
21,1,1:17.1
21,2,1:17.1
21,3,1:17.1
21,4,1:17.1
22,-41,1:17.1
22,-40,1:17.1
22,-39,1:17.1
22,-38,1:17.1
22,-37,1:17.1
22,-36,1:17.1
22,-35,1:17.1
22,-34,1:17.1
22,-33,1:17.1
22,-32,1:17.1
22,-31,1:17.1
22,-30,1:17.1
22,-29,1:17.1
22,-28,1:17.1
22,-27,1:17.1
22,-26,1:17.1
22,-25,1:17.1
22,-24,1:17.1
22,-23,1:17.1
22,-22,1:17.1
22,-21,1:17.1
22,-20,1:17.1
22,-19,1:17.1
22,-18,1:17.1
22,-17,1:17.1
22,-16,1:17.1
22,-15,1:17.1
22,-14,1:17.1
22,-13,1:17.1
22,-12,1:17.1
22,-11,1:17.1
22,-10,1:17.1
22,-9,1:17.1
22,-8,1:17.1
22,-7,1:17.1
22,-6,1:17.1
22,-5,1:17.1
22,-4,1:17.1
22,-3,1:17.1
22,-2,1:17.1
22,-1,1:17.1
22,0,1:17.1
22,1,1:17.1
22,2,1:17.1
22,3,1:17.1
22,4,1:17.1
23,-42,1:17.1
23,-41,1:17.1
23,-40,1:17.1
23,-39,1:17.1
23,-38,1:17.1
23,-37,1:17.1
23,-36,1:17.1
23,-35,1:17.1
23,-34,1:17.1
23,-33,1:17.1
23,-32,1:17.1
23,-31,1:17.1
23,-30,1:17.1
23,-29,1:17.1
23,-28,1:17.1
23,-27,1:17.1
23,-26,1:17.1
23,-25,1:17.1
23,-24,1:17.1
23,-23,1:17.1
23,-22,1:17.1
23,-21,1:17.1
23,-20,1:17.1
23,-19,1:17.1
23,-18,1:17.1
23,-17,1:17.1
23,-16,1:17.1
23,-15,1:17.1
23,-14,1:17.1
23,-13,1:17.1
23,-12,1:17.1
23,-11,1:17.1
23,-10,1:17.1
23,-9,1:17.1
23,-8,1:17.1
23,-7,1:17.1
23,-6,1:17.1
23,-5,1:17.1
23,-4,1:17.1
23,-3,1:17.1
23,-2,1:17.1
23,-1,1:17.1
23,0,1:17.1
23,1,1:17.1
23,2,1:17.1
23,3,1:17.1
23,4,1:17.1
23,5,1:17.1
24,-42,1:17.1
24,-41,1:17.1
24,-40,1:17.1
24,-39,1:17.1
24,-38,1:17.1
24,-37,1:17.1
24,-36,1:17.1
24,-35,1:17.1
24,-34,1:17.1
24,-33,1:17.1
24,-32,1:17.1
24,-31,1:17.1
24,-30,1:17.1
24,-29,1:17.1
24,-28,1:17.1
24,-27,1:17.1
24,-26,1:17.1
24,-25,1:17.1
24,-24,1:17.1
24,-23,1:17.1
24,-22,1:17.1
24,-21,1:17.1
24,-20,1:17.1
24,-19,1:17.1
24,-18,1:17.1
24,-17,1:17.1
24,-16,1:17.1
24,-15,1:17.1
24,-14,1:17.1
24,-13,1:17.1
24,-12,1:17.1
24,-11,1:17.1
24,-10,1:17.1
24,-9,1:17.1
24,-8,1:17.1
24,-7,1:17.1
24,-6,1:17.1
24,-5,1:17.1
24,-4,1:17.1
24,-3,1:17.1
24,-2,1:17.1
24,-1,1:17.1
24,0,1:17.1
24,1,1:17.1
24,2,1:17.1
24,3,1:17.1
24,4,1:17.1
24,5,1:17.1
25,-42,1:17.1
25,-41,1:17.1
25,-40,1:17.1
25,-39,1:17.1
25,-38,1:17.1
25,-37,1:17.1
25,-36,1:17.1
25,-35,1:17.1
25,-34,1:17.1
25,-33,1:17.1
25,-32,1:17.1
25,-31,1:17.1
25,-30,1:17.1
25,-29,1:17.1
25,-28,1:17.1
25,-27,1:17.1
25,-26,1:17.1
25,-25,1:17.1
25,-24,1:17.1
25,-23,1:17.1
25,-22,1:17.1
25,-21,1:17.1
25,-20,1:17.1
25,-19,1:17.1
25,-18,1:17.1
25,-17,1:17.1
25,-16,1:17.1
25,-15,1:17.1
25,-14,1:17.1
25,-13,1:17.1
25,-12,1:17.1
25,-11,1:17.1
25,-10,1:17.1
25,-9,1:17.1
25,-8,1:17.1
25,-7,1:17.1
25,-6,1:17.1
25,-5,1:17.1
25,-4,1:17.1
25,-3,1:17.1
25,-2,1:17.1
25,-1,1:17.1
25,0,1:17.1
25,1,1:17.1
25,2,1:17.1
25,3,1:17.1
25,4,1:17.1
25,5,1:17.1
26,-43,1:17.1
26,-42,1:17.1
26,-41,1:17.1
26,-40,1:17.1
26,-39,1:17.1
26,-38,1:17.1
26,-37,1:17.1
26,-36,1:17.1
26,-35,1:17.1
26,-34,1:17.1
26,-33,1:17.1
26,-32,1:17.1
26,-31,1:17.1
26,-30,1:17.1
26,-29,1:17.1
26,-28,1:17.1
26,-27,1:17.1
26,-26,1:17.1
26,-25,1:17.1
26,-24,1:17.1
26,-23,1:17.1
26,-22,1:17.1
26,-21,1:17.1
26,-20,1:17.1
26,-19,1:17.1
26,-18,1:17.1
26,-17,1:17.1
26,-16,1:17.1
26,-15,1:17.1
26,-14,1:17.1
26,-13,1:17.1
26,-12,1:17.1
26,-11,1:17.1
26,-10,1:17.1
26,-9,1:17.1
26,-8,1:17.1
26,-7,1:17.1
26,-6,1:17.1
26,-5,1:17.1
26,-4,1:17.1
26,-3,1:17.1
26,-2,1:17.1
26,-1,1:17.1
26,0,1:17.1
26,1,1:17.1
26,2,1:17.1
26,3,1:17.1
26,4,1:17.1
26,5,1:17.1
27,-43,1:17.1
27,-42,1:17.1
27,-41,1:17.1
27,-40,1:17.1
27,-39,1:17.1
27,-38,1:17.1
27,-37,1:17.1
27,-36,1:17.1
27,-35,1:17.1
27,-34,1:17.1
27,-33,1:17.1
27,-32,1:17.1
27,-31,1:17.1
27,-30,1:17.1
27,-29,1:17.1
27,-28,1:17.1
27,-27,1:17.1
27,-26,1:17.1
27,-25,1:17.1
27,-24,1:17.1
27,-23,1:17.1
27,-22,1:17.1
27,-21,1:17.1
27,-20,1:17.1
27,-19,1:17.1
27,-18,1:17.1
27,-17,1:17.1
27,-16,1:17.1
27,-15,1:17.1
27,-14,1:17.1
27,-13,1:17.1
27,-12,1:17.1
27,-11,1:17.1
27,-10,1:17.1
27,-9,1:17.1
27,-8,1:17.1
27,-7,1:17.1
27,-6,1:17.1
27,-5,1:17.1
27,-4,1:17.1
27,-3,1:17.1
27,-2,1:17.1
27,-1,1:17.1
27,0,1:17.1
27,1,1:17.1
27,2,1:17.1
27,3,1:17.1
27,4,1:17.1
27,5,1:17.1
28,-43,1:17.1
28,-42,1:17.1
28,-41,1:17.1
28,-40,1:17.1
28,-39,1:17.1
28,-38,1:17.1
28,-37,1:17.1
28,-36,1:17.1
28,-35,1:17.1
28,-34,1:17.1
28,-33,1:17.1
28,-32,1:17.1
28,-31,1:17.1
28,-30,1:17.1
28,-29,1:17.1
28,-28,1:17.1
28,-27,1:17.1
28,-26,1:17.1
28,-25,1:17.1
28,-24,1:17.1
28,-23,1:17.1
28,-22,1:17.1
28,-21,1:17.1
28,-20,1:17.1
28,-19,1:17.1
28,-18,1:17.1
28,-17,1:17.1
28,-16,1:17.1
28,-15,1:17.1
28,-14,1:17.1
28,-13,1:17.1
28,-12,1:17.1
28,-11,1:17.1
28,-10,1:17.1
28,-9,1:17.1
28,-8,1:17.1
28,-7,1:17.1
28,-6,1:17.1
28,-5,1:17.1
28,-4,1:17.1
28,-3,1:17.1
28,-2,1:17.1
28,-1,1:17.1
28,0,1:17.1
28,1,1:17.1
28,2,1:17.1
28,3,1:17.1
28,4,1:17.1
29,-42,1:17.1
29,-41,1:17.1
29,-40,1:17.1
29,-39,1:17.1
29,-38,1:17.1
29,-37,1:17.1
29,-36,1:17.1
29,-35,1:17.1
29,-34,1:17.1
29,-33,1:17.1
29,-32,1:17.1
29,-31,1:17.1
29,-30,1:17.1
29,-29,1:17.1
29,-28,1:17.1
29,-27,1:17.1
29,-26,1:17.1
29,-25,1:17.1
29,-24,1:17.1
29,-23,1:17.1
29,-22,1:17.1
29,-21,1:17.1
29,-20,1:17.1
29,-19,1:17.1
29,-18,1:17.1
29,-17,1:17.1
29,-16,1:17.1
29,-15,1:17.1
29,-14,1:17.1
29,-13,1:17.1
29,-12,1:17.1
29,-11,1:17.1
29,-10,1:17.1
29,-9,1:17.1
29,-8,1:17.1
29,-7,1:17.1
29,-6,1:17.1
29,-5,1:17.1
29,-4,1:17.1
29,-3,1:17.1
29,-2,1:17.1
29,-1,1:17.1
29,0,1:17.1
29,1,1:17.1
29,2,1:17.1
29,3,1:17.1
29,4,1:17.1
30,-42,1:17.1
30,-41,1:17.1
30,-40,1:17.1
30,-39,1:17.1
30,-38,1:17.1
30,-37,1:17.1
30,-36,1:17.1
30,-35,1:17.1
30,-34,1:17.1
30,-33,1:17.1
30,-32,1:17.1
30,-31,1:17.1
30,-30,1:17.1
30,-29,1:17.1
30,-28,1:17.1
30,-27,1:17.1
30,-26,1:17.1
30,-25,1:17.1
30,-24,1:17.1
30,-23,1:17.1
30,-22,1:17.1
30,-21,1:17.1
30,-20,1:17.1
30,-19,1:17.1
30,-18,1:17.1
30,-17,1:17.1
30,-16,1:17.1
30,-15,1:17.1
30,-14,1:17.1
30,-13,1:17.1
30,-12,1:17.1
30,-11,1:17.1
30,-10,1:17.1
30,-9,1:17.1
30,-8,1:17.1
30,-7,1:17.1
30,-6,1:17.1
30,-5,1:17.1
30,-4,1:17.1
30,-3,1:17.1
30,-2,1:17.1
30,-1,1:17.1
30,0,1:17.1
30,1,1:17.1
30,2,1:17.1
30,3,1:17.1
31,-41,1:17.1
31,-40,1:17.1
31,-39,1:17.1
31,-38,1:17.1
31,-37,1:17.1
31,-36,1:17.1
31,-35,1:17.1
31,-34,1:17.1
31,-33,1:17.1
31,-32,1:17.1
31,-31,1:17.1
31,-30,1:17.1
31,-29,1:17.1
31,-28,1:17.1
31,-27,1:17.1
31,-26,1:17.1
31,-25,1:17.1
31,-24,1:17.1
31,-23,1:17.1
31,-22,1:17.1
31,-21,1:17.1
31,-20,1:17.1
31,-19,1:17.1
31,-18,1:17.1
31,-17,1:17.1
31,-16,1:17.1
31,-15,1:17.1
31,-14,1:17.1
31,-13,1:17.1
31,-12,1:17.1
31,-11,1:17.1
31,-10,1:17.1
31,-9,1:17.1
31,-8,1:17.1
31,-7,1:17.1
31,-6,1:17.1
31,-5,1:17.1
31,-4,1:17.1
31,-3,1:17.1
31,-2,1:17.1
31,-1,1:17.1
31,0,1:17.1
31,1,1:17.1
31,2,1:17.1
31,3,1:17.1
32,-40,1:17.1
32,-39,1:17.1
32,-38,1:17.1
32,-37,1:17.1
32,-36,1:17.1
32,-35,1:17.1
32,-34,1:17.1
32,-33,1:17.1
32,-32,1:17.1
32,-31,1:17.1
32,-30,1:17.1
32,-29,1:17.1
32,-28,1:17.1
32,-27,1:17.1
32,-26,1:17.1
32,-25,1:17.1
32,-24,1:17.1
32,-23,1:17.1
32,-22,1:17.1
32,-21,1:17.1
32,-20,1:17.1
32,-19,1:17.1
32,-18,1:17.1
32,-17,1:17.1
32,-16,1:17.1
32,-15,1:17.1
32,-14,1:17.1
32,-13,1:17.1
32,-12,1:17.1
32,-11,1:17.1
32,-10,1:17.1
32,-9,1:17.1
32,-8,1:17.1
32,-7,1:17.1
32,-6,1:17.1
32,-5,1:17.1
32,-4,1:17.1
32,-3,1:17.1
32,-2,1:17.1
32,-1,1:17.1
32,0,1:17.1
32,1,1:17.1
32,2,1:17.1
33,-40,1:17.1
33,-39,1:17.1
33,-38,1:17.1
33,-37,1:17.1
33,-36,1:17.1
33,-35,1:17.1
33,-34,1:17.1
33,-33,1:17.1
33,-32,1:17.1
33,-31,1:17.1
33,-30,1:17.1
33,-29,1:17.1
33,-28,1:17.1
33,-27,1:17.1
33,-26,1:17.1
33,-25,1:17.1
33,-24,1:17.1
33,-23,1:17.1
33,-22,1:17.1
33,-21,1:17.1
33,-20,1:17.1
33,-19,1:17.1
33,-18,1:17.1
33,-17,1:17.1
33,-16,1:17.1
33,-15,1:17.1
33,-14,1:17.1
33,-13,1:17.1
33,-12,1:17.1
33,-11,1:17.1
33,-10,1:17.1
33,-9,1:17.1
33,-8,1:17.1
33,-7,1:17.1
33,-6,1:17.1
33,-5,1:17.1
33,-4,1:17.1
33,-3,1:17.1
33,-2,1:17.1
33,-1,1:17.1
33,0,1:17.1
33,1,1:17.1
33,2,1:17.1
34,-39,1:17.1
34,-38,1:17.1
34,-37,1:17.1
34,-36,1:17.1
34,-35,1:17.1
34,-34,1:17.1
34,-33,1:17.1
34,-32,1:17.1
34,-31,1:17.1
34,-30,1:17.1
34,-29,1:17.1
34,-28,1:17.1
34,-27,1:17.1
34,-26,1:17.1
34,-25,1:17.1
34,-24,1:17.1
34,-23,1:17.1
34,-22,1:17.1
34,-21,1:17.1
34,-20,1:17.1
34,-19,1:17.1
34,-18,1:17.1
34,-17,1:17.1
34,-16,1:17.1
34,-15,1:17.1
34,-14,1:17.1
34,-13,1:17.1
34,-12,1:17.1
34,-11,1:17.1
34,-10,1:17.1
34,-9,1:17.1
34,-8,1:17.1
34,-7,1:17.1
34,-6,1:17.1
34,-5,1:17.1
34,-4,1:17.1
34,-3,1:17.1
34,-2,1:17.1
34,-1,1:17.1
34,0,1:17.1
34,1,1:17.1
35,-38,1:17.1
35,-37,1:17.1
35,-36,1:17.1
35,-35,1:17.1
35,-34,1:17.1
35,-33,1:17.1
35,-32,1:17.1
35,-31,1:17.1
35,-30,1:17.1
35,-29,1:17.1
35,-28,1:17.1
35,-27,1:17.1
35,-26,1:17.1
35,-25,1:17.1
35,-24,1:17.1
35,-23,1:17.1
35,-22,1:17.1
35,-21,1:17.1
35,-20,1:17.1
35,-19,1:17.1
35,-18,1:17.1
35,-17,1:17.1
35,-16,1:17.1
35,-15,1:17.1
35,-14,1:17.1
35,-13,1:17.1
35,-12,1:17.1
35,-11,1:17.1
35,-10,1:17.1
35,-9,1:17.1
35,-8,1:17.1
35,-7,1:17.1
35,-6,1:17.1
35,-5,1:17.1
35,-4,1:17.1
35,-3,1:17.1
35,-2,1:17.1
35,-1,1:17.1
35,0,1:17.1
35,1,1:17.1
35,2,1:17.1
36,-38,1:17.1
36,-37,1:17.1
36,-36,1:17.1
36,-35,1:17.1
36,-34,1:17.1
36,-33,1:17.1
36,-32,1:17.1
36,-31,1:17.1
36,-30,1:17.1
36,-29,1:17.1
36,-28,1:17.1
36,-27,1:17.1
36,-26,1:17.1
36,-25,1:17.1
36,-24,1:17.1
36,-23,1:17.1
36,-22,1:17.1
36,-21,1:17.1
36,-20,1:17.1
36,-19,1:17.1
36,-18,1:17.1
36,-17,1:17.1
36,-16,1:17.1
36,-15,1:17.1
36,-14,1:17.1
36,-13,1:17.1
36,-12,1:17.1
36,-11,1:17.1
36,-10,1:17.1
36,-9,1:17.1
36,-8,1:17.1
36,-7,1:17.1
36,-6,1:17.1
36,-5,1:17.1
36,-4,1:17.1
36,-3,1:17.1
36,-2,1:17.1
36,-1,1:17.1
36,0,1:17.1
36,1,1:17.1
36,2,1:17.1
37,-37,1:17.1
37,-36,1:17.1
37,-35,1:17.1
37,-34,1:17.1
37,-33,1:17.1
37,-32,1:17.1
37,-31,1:17.1
37,-30,1:17.1
37,-29,1:17.1
37,-28,1:17.1
37,-27,1:17.1
37,-26,1:17.1
37,-25,1:17.1
37,-24,1:17.1
37,-23,1:17.1
37,-22,1:17.1
37,-21,1:17.1
37,-20,1:17.1
37,-19,1:17.1
37,-18,1:17.1
37,-17,1:17.1
37,-16,1:17.1
37,-15,1:17.1
37,-14,1:17.1
37,-13,1:17.1
37,-12,1:17.1
37,-11,1:17.1
37,-10,1:17.1
37,-9,1:17.1
37,-8,1:17.1
37,-7,1:17.1
37,-6,1:17.1
37,-5,1:17.1
37,-4,1:17.1
37,-3,1:17.1
37,-2,1:17.1
37,-1,1:17.1
37,0,1:17.1
37,1,1:17.1
37,2,1:17.1
37,3,1:17.1
38,-37,1:17.1
38,-36,1:17.1
38,-35,1:17.1
38,-34,1:17.1
38,-33,1:17.1
38,-32,1:17.1
38,-31,1:17.1
38,-30,1:17.1
38,-29,1:17.1
38,-28,1:17.1
38,-27,1:17.1
38,-26,1:17.1
38,-25,1:17.1
38,-24,1:17.1
38,-23,1:17.1
38,-22,1:17.1
38,-21,1:17.1
38,-20,1:17.1
38,-19,1:17.1
38,-18,1:17.1
38,-17,1:17.1
38,-16,1:17.1
38,-15,1:17.1
38,-14,1:17.1
38,-13,1:17.1
38,-12,1:17.1
38,-11,1:17.1
38,-10,1:17.1
38,-9,1:17.1
38,-8,1:17.1
38,-7,1:17.1
38,-6,1:17.1
38,-5,1:17.1
38,-4,1:17.1
38,-3,1:17.1
38,-2,1:17.1
38,-1,1:17.1
38,0,1:17.1
38,1,1:17.1
38,2,1:17.1
38,3,1:17.1
39,-36,1:17.1
39,-35,1:17.1
39,-34,1:17.1
39,-33,1:17.1
39,-32,1:17.1
39,-31,1:17.1
39,-30,1:17.1
39,-29,1:17.1
39,-28,1:17.1
39,-27,1:17.1
39,-26,1:17.1
39,-25,1:17.1
39,-24,1:17.1
39,-23,1:17.1
39,-22,1:17.1
39,-21,1:17.1
39,-20,1:17.1
39,-19,1:17.1
39,-18,1:17.1
39,-17,1:17.1
39,-16,1:17.1
39,-15,1:17.1
39,-14,1:17.1
39,-13,1:17.1
39,-12,1:17.1
39,-11,1:17.1
39,-10,1:17.1
39,-9,1:17.1
39,-8,1:17.1
39,-7,1:17.1
39,-6,1:17.1
39,-5,1:17.1
39,-4,1:17.1
39,-3,1:17.1
39,-2,1:17.1
39,-1,1:17.1
39,0,1:17.1
39,1,1:17.1
39,2,1:17.1
39,3,1:17.1
40,-35,1:17.1
40,-34,1:17.1
40,-33,1:17.1
40,-32,1:17.1
40,-31,1:17.1
40,-30,1:17.1
40,-29,1:17.1
40,-28,1:17.1
40,-27,1:17.1
40,-26,1:17.1
40,-25,1:17.1
40,-24,1:17.1
40,-23,1:17.1
40,-22,1:17.1
40,-21,1:17.1
40,-20,1:17.1
40,-19,1:17.1
40,-18,1:17.1
40,-17,1:17.1
40,-16,1:17.1
40,-15,1:17.1
40,-14,1:17.1
40,-13,1:17.1
40,-12,1:17.1
40,-11,1:17.1
40,-10,1:17.1
40,-9,1:17.1
40,-8,1:17.1
40,-7,1:17.1
40,-6,1:17.1
40,-5,1:17.1
40,-4,1:17.1
40,-3,1:17.1
40,-2,1:17.1
40,-1,1:17.1
40,0,1:17.1
40,1,1:17.1
40,2,1:17.1
40,3,1:17.1
41,-33,1:17.1
41,-32,1:17.1
41,-31,1:17.1
41,-30,1:17.1
41,-29,1:17.1
41,-28,1:17.1
41,-27,1:17.1
41,-24,1:17.1
41,-23,1:17.1
41,-22,1:17.1
41,-21,1:17.1
41,-20,1:17.1
41,-19,1:17.1
41,-18,1:17.1
41,-17,1:17.1
41,-16,1:17.1
41,-15,1:17.1
41,-14,1:17.1
41,-13,1:17.1
41,-12,1:17.1
41,-11,1:17.1
41,-10,1:17.1
41,-9,1:17.1
41,-8,1:17.1
41,-7,1:17.1
41,-6,1:17.1
41,-5,1:17.1
41,-4,1:17.1
41,-3,1:17.1
41,-2,1:17.1
41,-1,1:17.1
41,0,1:17.1
41,1,1:17.1
41,2,1:17.1
41,3,1:17.1
42,-23,1:17.1
42,-22,1:17.1
42,-21,1:17.1
42,-20,1:17.1
42,-19,1:17.1
42,-18,1:17.1
42,-17,1:17.1
42,-16,1:17.1
42,-15,1:17.1
42,-14,1:17.1
42,-13,1:17.1
42,-12,1:17.1
42,-11,1:17.1
42,-10,1:17.1
42,-9,1:17.1
42,-8,1:17.1
42,-7,1:17.1
42,-6,1:17.1
42,-5,1:17.1
42,-4,1:17.1
42,-3,1:17.1
42,-2,1:17.1
42,-1,1:17.1
42,0,1:17.1
42,1,1:17.1
42,2,1:17.1
43,-23,1:17.1
43,-22,1:17.1
43,-21,1:17.1
43,-20,1:17.1
43,-19,1:17.1
43,-18,1:17.1
43,-17,1:17.1
43,-16,1:17.1
43,-15,1:17.1
43,-14,1:17.1
43,-13,1:17.1
43,-12,1:17.1
43,-11,1:17.1
43,-10,1:17.1
43,-9,1:17.1
43,-8,1:17.1
43,-7,1:17.1
43,-6,1:17.1
43,-5,1:17.1
43,-4,1:17.1
43,-3,1:17.1
43,-2,1:17.1
43,-1,1:17.1
43,0,1:17.1
43,1,1:17.1
43,2,1:17.1
44,-22,1:17.1
44,-21,1:17.1
44,-20,1:17.1
44,-19,1:17.1
44,-18,1:17.1
44,-17,1:17.1
44,-16,1:17.1
44,-15,1:17.1
44,-14,1:17.1
44,-13,1:17.1
44,-12,1:17.1
44,-11,1:17.1
44,-10,1:17.1
44,-9,1:17.1
44,-8,1:17.1
44,-7,1:17.1
44,-6,1:17.1
44,-5,1:17.1
44,-4,1:17.1
44,-3,1:17.1
44,-2,1:17.1
44,-1,1:17.1
44,0,1:17.1
44,1,1:17.1
45,-21,1:17.1
45,-20,1:17.1
45,-19,1:17.1
45,-18,1:17.1
45,-17,1:17.1
45,-16,1:17.1
45,-15,1:17.1
45,-14,1:17.1
45,-13,1:17.1
45,-12,1:17.1
45,-11,1:17.1
45,-10,1:17.1
45,-9,1:17.1
45,-8,1:17.1
45,-7,1:17.1
45,-6,1:17.1
45,-5,1:17.1
45,-4,1:17.1
45,-3,1:17.1
45,-2,1:17.1
45,-1,1:17.1
45,0,1:17.1
45,1,1:17.1
46,-20,1:17.1
46,-19,1:17.1
46,-18,1:17.1
46,-17,1:17.1
46,-16,1:17.1
46,-15,1:17.1
46,-14,1:17.1
46,-13,1:17.1
46,-12,1:17.1
46,-11,1:17.1
46,-10,1:17.1
46,-9,1:17.1
46,-8,1:17.1
46,-7,1:17.1
46,-6,1:17.1
46,-5,1:17.1
46,-4,1:17.1
46,-3,1:17.1
46,-2,1:17.1
46,-1,1:17.1
46,0,1:17.1
47,-20,1:17.1
47,-19,1:17.1
47,-18,1:17.1
47,-17,1:17.1
47,-16,1:17.1
47,-15,1:17.1
47,-14,1:17.1
47,-13,1:17.1
47,-12,1:17.1
47,-11,1:17.1
47,-10,1:17.1
47,-9,1:17.1
47,-8,1:17.1
47,-7,1:17.1
47,-6,1:17.1
47,-5,1:17.1
47,-4,1:17.1
47,-3,1:17.1
47,-2,1:17.1
47,-1,1:17.1
48,-19,1:17.1
48,-18,1:17.1
48,-17,1:17.1
48,-16,1:17.1
48,-15,1:17.1
48,-14,1:17.1
48,-13,1:17.1
48,-12,1:17.1
48,-11,1:17.1
48,-10,1:17.1
48,-9,1:17.1
48,-8,1:17.1
48,-7,1:17.1
48,-6,1:17.1
48,-5,1:17.1
48,-4,1:17.1
48,-3,1:17.1
48,-2,1:17.1
49,-18,1:17.1
49,-17,1:17.1
49,-16,1:17.1
49,-15,1:17.1
49,-14,1:17.1
49,-13,1:17.1
49,-12,1:17.1
49,-11,1:17.1
49,-10,1:17.1
49,-9,1:17.1
49,-8,1:17.1
49,-7,1:17.1
49,-6,1:17.1
49,-5,1:17.1
49,-4,1:17.1
49,-3,1:17.1
50,-17,1:17.1
50,-16,1:17.1
50,-15,1:17.1
50,-14,1:17.1
50,-13,1:17.1
50,-12,1:17.1
50,-11,1:17.1
50,-10,1:17.1
50,-9,1:17.1
50,-8,1:17.1
50,-7,1:17.1
50,-6,1:17.1
50,-5,1:17.1
50,-4,1:17.1
51,-16,1:17.1
51,-15,1:17.1
51,-14,1:17.1
51,-13,1:17.1
51,-12,1:17.1
51,-11,1:17.1
51,-10,1:17.1
51,-9,1:17.1
51,-8,1:17.1
51,-7,1:17.1
51,-6,1:17.1
51,-5,1:17.1
52,-15,1:17.1
52,-14,1:17.1
52,-13,1:17.1
52,-12,1:17.1
52,-11,1:17.1
52,-10,1:17.1
52,-9,1:17.1
52,-8,1:17.1
52,-7,1:17.1
52,-6,1:17.1
52,-5,1:17.1
52,-4,1:17.1
53,-12,1:17.1
53,-11,1:17.1
53,-10,1:17.1
-8,-18,2:17.1
-7,-17,2:17.1
-6,-17,2:17.1
-5,-17,2:17.1
-4,-17,2:17.1
-3,-17,2:17.1
-2,-16,2:17.1
-1,-16,2:17.1
-1,-10,2:17.1
-1,-9,2:17.1
-1,-8,2:17.1
0,-16,2:17.1
0,-12,2:17.1
0,-11,2:17.1
0,-10,2:17.1
0,-9,2:17.1
0,-8,2:17.1
0,-7,2:17.1
0,-6,2:17.1
1,-16,2:17.1
1,-14,2:17.1
1,-13,2:17.1
1,-12,2:17.1
1,-11,2:17.1
1,-10,2:17.1
1,-9,2:17.1
1,-8,2:17.1
1,-7,2:17.1
1,-6,2:17.1
1,-5,2:17.1
2,-16,2:17.1
2,-15,2:17.1
2,-14,2:17.1
2,-13,2:17.1
2,-12,2:17.1
2,-11,2:17.1
2,-10,2:17.1
2,-9,2:17.1
2,-8,2:17.1
2,-7,2:17.1
2,-6,2:17.1
2,-5,2:17.1
3,-22,2:17.1
3,-21,2:17.1
3,-20,2:17.1
3,-19,2:17.1
3,-18,2:17.1
3,-16,2:17.1
3,-15,2:17.1
3,-14,2:17.1
3,-13,2:17.1
3,-12,2:17.1
3,-11,2:17.1
3,-10,2:17.1
3,-9,2:17.1
3,-8,2:17.1
3,-7,2:17.1
3,-6,2:17.1
3,-5,2:17.1
3,-4,2:17.1
3,-3,2:17.1
4,-25,2:17.1
4,-24,2:17.1
4,-23,2:17.1
4,-22,2:17.1
4,-21,2:17.1
4,-20,2:17.1
4,-19,2:17.1
4,-18,2:17.1
4,-17,2:17.1
4,-16,2:17.1
4,-15,2:17.1
4,-14,2:17.1
4,-13,2:17.1
4,-12,2:17.1
4,-11,2:17.1
4,-10,2:17.1
4,-9,2:17.1
4,-8,2:17.1
4,-7,2:17.1
4,-6,2:17.1
4,-5,2:17.1
4,-4,2:17.1
4,-3,2:17.1
4,-2,2:17.1
5,-26,2:17.1
5,-25,2:17.1
5,-24,2:17.1
5,-23,2:17.1
5,-22,2:17.1
5,-21,2:17.1
5,-20,2:17.1
5,-19,2:17.1
5,-18,2:17.1
5,-17,2:17.1
5,-16,2:17.1
5,-15,2:17.1
5,-14,2:17.1
5,-13,2:17.1
5,-12,2:17.1
5,-11,2:17.1
5,-10,2:17.1
5,-9,2:17.1
5,-8,2:17.1
5,-7,2:17.1
5,-6,2:17.1
5,-5,2:17.1
5,-4,2:17.1
5,-3,2:17.1
5,-2,2:17.1
5,-1,2:17.1
6,-27,2:17.1
6,-26,2:17.1
6,-25,2:17.1
6,-24,2:17.1
6,-23,2:17.1
6,-22,2:17.1
6,-21,2:17.1
6,-20,2:17.1
6,-19,2:17.1
6,-18,2:17.1
6,-17,2:17.1
6,-16,2:17.1
6,-15,2:17.1
6,-14,2:17.1
6,-13,2:17.1
6,-12,2:17.1
6,-11,2:17.1
6,-10,2:17.1
6,-9,2:17.1
6,-8,2:17.1
6,-7,2:17.1
6,-6,2:17.1
6,-5,2:17.1
6,-4,2:17.1
6,-3,2:17.1
6,-2,2:17.1
6,-1,2:17.1
7,-27,2:17.1
7,-26,2:17.1
7,-25,2:17.1
7,-24,2:17.1
7,-23,2:17.1
7,-22,2:17.1
7,-21,2:17.1
7,-20,2:17.1
7,-19,2:17.1
7,-18,2:17.1
7,-17,2:17.1
7,-16,2:17.1
7,-15,2:17.1
7,-14,2:17.1
7,-13,2:17.1
7,-12,2:17.1
7,-11,2:17.1
7,-10,2:17.1
7,-9,2:17.1
7,-8,2:17.1
7,-7,2:17.1
7,-6,2:17.1
7,-5,2:17.1
7,-4,2:17.1
7,-3,2:17.1
7,-2,2:17.1
7,-1,2:17.1
8,-27,2:17.1
8,-26,2:17.1
8,-25,2:17.1
8,-24,2:17.1
8,-23,2:17.1
8,-22,2:17.1
8,-21,2:17.1
8,-20,2:17.1
8,-19,2:17.1
8,-18,2:17.1
8,-17,2:17.1
8,-16,2:17.1
8,-15,2:17.1
8,-14,2:17.1
8,-13,2:17.1
8,-12,2:17.1
8,-11,2:17.1
8,-10,2:17.1
8,-9,2:17.1
8,-8,2:17.1
8,-7,2:17.1
8,-6,2:17.1
8,-5,2:17.1
8,-4,2:17.1
8,-3,2:17.1
8,-2,2:17.1
8,-1,2:17.1
9,-29,2:17.1
9,-28,2:17.1
9,-27,2:17.1
9,-26,2:17.1
9,-25,2:17.1
9,-24,2:17.1
9,-23,2:17.1
9,-22,2:17.1
9,-21,2:17.1
9,-20,2:17.1
9,-19,2:17.1
9,-18,2:17.1
9,-17,2:17.1
9,-16,2:17.1
9,-15,2:17.1
9,-14,2:17.1
9,-13,2:17.1
9,-12,2:17.1
9,-11,2:17.1
9,-10,2:17.1
9,-9,2:17.1
9,-8,2:17.1
9,-7,2:17.1
9,-6,2:17.1
9,-5,2:17.1
9,-4,2:17.1
9,-3,2:17.1
9,-2,2:17.1
9,-1,2:17.1
10,-30,2:17.1
10,-29,2:17.1
10,-28,2:17.1
10,-27,2:17.1
10,-26,2:17.1
10,-25,2:17.1
10,-24,2:17.1
10,-23,2:17.1
10,-22,2:17.1
10,-21,2:17.1
10,-20,2:17.1
10,-19,2:17.1
10,-18,2:17.1
10,-17,2:17.1
10,-16,2:17.1
10,-15,2:17.1
10,-14,2:17.1
10,-13,2:17.1
10,-12,2:17.1
10,-11,2:17.1
10,-10,2:17.1
10,-9,2:17.1
10,-8,2:17.1
10,-7,2:17.1
10,-6,2:17.1
10,-5,2:17.1
10,-4,2:17.1
10,-3,2:17.1
10,-2,2:17.1
10,-1,2:17.1
11,-31,2:17.1
11,-30,2:17.1
11,-29,2:17.1
11,-28,2:17.1
11,-27,2:17.1
11,-26,2:17.1
11,-25,2:17.1
11,-24,2:17.1
11,-23,2:17.1
11,-22,2:17.1
11,-21,2:17.1
11,-20,2:17.1
11,-19,2:17.1
11,-18,2:17.1
11,-17,2:17.1
11,-16,2:17.1
11,-15,2:17.1
11,-14,2:17.1
11,-13,2:17.1
11,-12,2:17.1
11,-11,2:17.1
11,-10,2:17.1
11,-9,2:17.1
11,-8,2:17.1
11,-7,2:17.1
11,-6,2:17.1
11,-5,2:17.1
11,-4,2:17.1
11,-3,2:17.1
11,-2,2:17.1
11,-1,2:17.1
11,0,2:17.1
12,-32,2:17.1
12,-31,2:17.1
12,-30,2:17.1
12,-29,2:17.1
12,-28,2:17.1
12,-27,2:17.1
12,-26,2:17.1
12,-25,2:17.1
12,-24,2:17.1
12,-23,2:17.1
12,-22,2:17.1
12,-21,2:17.1
12,-20,2:17.1
12,-19,2:17.1
12,-18,2:17.1
12,-17,2:17.1
12,-16,2:17.1
12,-15,2:17.1
12,-14,2:17.1
12,-13,2:17.1
12,-12,2:17.1
12,-11,2:17.1
12,-10,2:17.1
12,-9,2:17.1
12,-8,2:17.1
12,-7,2:17.1
12,-6,2:17.1
12,-5,2:17.1
12,-4,2:17.1
12,-3,2:17.1
12,-2,2:17.1
12,-1,2:17.1
12,0,2:17.1
12,1,2:17.1
13,-32,2:17.1
13,-31,2:17.1
13,-30,2:17.1
13,-29,2:17.1
13,-28,2:17.1
13,-27,2:17.1
13,-26,2:17.1
13,-25,2:17.1
13,-24,2:17.1
13,-23,2:17.1
13,-22,2:17.1
13,-21,2:17.1
13,-20,2:17.1
13,-19,2:17.1
13,-18,2:17.1
13,-17,2:17.1
13,-16,2:17.1
13,-15,2:17.1
13,-14,2:17.1
13,-13,2:17.1
13,-12,2:17.1
13,-11,2:17.1
13,-10,2:17.1
13,-9,2:17.1
13,-8,2:17.1
13,-7,2:17.1
13,-6,2:17.1
13,-5,2:17.1
13,-4,2:17.1
13,-3,2:17.1
13,-2,2:17.1
13,-1,2:17.1
13,0,2:17.1
13,1,2:17.1
13,2,2:17.1
14,-33,2:17.1
14,-32,2:17.1
14,-31,2:17.1
14,-30,2:17.1
14,-29,2:17.1
14,-28,2:17.1
14,-27,2:17.1
14,-26,2:17.1
14,-25,2:17.1
14,-24,2:17.1
14,-23,2:17.1
14,-22,2:17.1
14,-21,2:17.1
14,-20,2:17.1
14,-19,2:17.1
14,-18,2:17.1
14,-17,2:17.1
14,-16,2:17.1
14,-15,2:17.1
14,-14,2:17.1
14,-13,2:17.1
14,-12,2:17.1
14,-11,2:17.1
14,-10,2:17.1
14,-9,2:17.1
14,-8,2:17.1
14,-7,2:17.1
14,-6,2:17.1
14,-5,2:17.1
14,-4,2:17.1
14,-3,2:17.1
14,-2,2:17.1
14,-1,2:17.1
14,0,2:17.1
14,1,2:17.1
14,2,2:17.1
15,-34,2:17.1
15,-33,2:17.1
15,-32,2:17.1
15,-31,2:17.1
15,-30,2:17.1
15,-29,2:17.1
15,-28,2:17.1
15,-27,2:17.1
15,-26,2:17.1
15,-25,2:17.1
15,-24,2:17.1
15,-23,2:17.1
15,-22,2:17.1
15,-21,2:17.1
15,-20,2:17.1
15,-19,2:17.1
15,-18,2:17.1
15,-17,2:17.1
15,-16,2:17.1
15,-15,2:17.1
15,-14,2:17.1
15,-13,2:17.1
15,-12,2:17.1
15,-11,2:17.1
15,-10,2:17.1
15,-9,2:17.1
15,-8,2:17.1
15,-7,2:17.1
15,-6,2:17.1
15,-5,2:17.1
15,-4,2:17.1
15,-3,2:17.1
15,-2,2:17.1
15,-1,2:17.1
15,0,2:17.1
15,1,2:17.1
15,2,2:17.1
15,3,2:17.1
16,-36,2:17.1
16,-35,2:17.1
16,-34,2:17.1
16,-33,2:17.1
16,-32,2:17.1
16,-31,2:17.1
16,-30,2:17.1
16,-29,2:17.1
16,-28,2:17.1
16,-27,2:17.1
16,-26,2:17.1
16,-25,2:17.1
16,-24,2:17.1
16,-23,2:17.1
16,-22,2:17.1
16,-21,2:17.1
16,-20,2:17.1
16,-19,2:17.1
16,-18,2:17.1
16,-17,2:17.1
16,-16,2:17.1
16,-15,2:17.1
16,-14,2:17.1
16,-13,2:17.1
16,-12,2:17.1
16,-11,2:17.1
16,-10,2:17.1
16,-9,2:17.1
16,-8,2:17.1
16,-7,2:17.1
16,-6,2:17.1
16,-5,2:17.1
16,-4,2:17.1
16,-3,2:17.1
16,-2,2:17.1
16,-1,2:17.1
16,0,2:17.1
16,1,2:17.1
16,2,2:17.1
16,3,2:17.1
17,-36,2:17.1
17,-35,2:17.1
17,-34,2:17.1
17,-33,2:17.1
17,-32,2:17.1
17,-31,2:17.1
17,-30,2:17.1
17,-29,2:17.1
17,-28,2:17.1
17,-27,2:17.1
17,-26,2:17.1
17,-25,2:17.1
17,-24,2:17.1
17,-23,2:17.1
17,-22,2:17.1
17,-21,2:17.1
17,-20,2:17.1
17,-19,2:17.1
17,-18,2:17.1
17,-17,2:17.1
17,-16,2:17.1
17,-15,2:17.1
17,-14,2:17.1
17,-13,2:17.1
17,-12,2:17.1
17,-11,2:17.1
17,-10,2:17.1
17,-9,2:17.1
17,-8,2:17.1
17,-7,2:17.1
17,-6,2:17.1
17,-5,2:17.1
17,-4,2:17.1
17,-3,2:17.1
17,-2,2:17.1
17,-1,2:17.1
17,0,2:17.1
17,1,2:17.1
17,2,2:17.1
17,3,2:17.1
17,4,2:17.1
18,-37,2:17.1
18,-36,2:17.1
18,-35,2:17.1
18,-34,2:17.1
18,-33,2:17.1
18,-32,2:17.1
18,-31,2:17.1
18,-30,2:17.1
18,-29,2:17.1
18,-28,2:17.1
18,-27,2:17.1
18,-26,2:17.1
18,-25,2:17.1
18,-24,2:17.1
18,-23,2:17.1
18,-22,2:17.1
18,-21,2:17.1
18,-20,2:17.1
18,-19,2:17.1
18,-18,2:17.1
18,-17,2:17.1
18,-16,2:17.1
18,-15,2:17.1
18,-14,2:17.1
18,-13,2:17.1
18,-12,2:17.1
18,-11,2:17.1
18,-10,2:17.1
18,-9,2:17.1
18,-8,2:17.1
18,-7,2:17.1
18,-6,2:17.1
18,-5,2:17.1
18,-4,2:17.1
18,-3,2:17.1
18,-2,2:17.1
18,-1,2:17.1
18,0,2:17.1
18,1,2:17.1
18,2,2:17.1
18,3,2:17.1
18,4,2:17.1
19,-38,2:17.1
19,-37,2:17.1
19,-36,2:17.1
19,-35,2:17.1
19,-34,2:17.1
19,-33,2:17.1
19,-32,2:17.1
19,-31,2:17.1
19,-30,2:17.1
19,-29,2:17.1
19,-28,2:17.1
19,-27,2:17.1
19,-26,2:17.1
19,-25,2:17.1
19,-24,2:17.1
19,-23,2:17.1
19,-22,2:17.1
19,-21,2:17.1
19,-20,2:17.1
19,-19,2:17.1
19,-18,2:17.1
19,-17,2:17.1
19,-16,2:17.1
19,-15,2:17.1
19,-14,2:17.1
19,-13,2:17.1
19,-12,2:17.1
19,-11,2:17.1
19,-10,2:17.1
19,-9,2:17.1
19,-8,2:17.1
19,-7,2:17.1
19,-6,2:17.1
19,-5,2:17.1
19,-4,2:17.1
19,-3,2:17.1
19,-2,2:17.1
19,-1,2:17.1
19,0,2:17.1
19,1,2:17.1
19,2,2:17.1
19,3,2:17.1
19,4,2:17.1
20,-38,2:17.1
20,-37,2:17.1
20,-36,2:17.1
20,-35,2:17.1
20,-34,2:17.1
20,-33,2:17.1
20,-32,2:17.1
20,-31,2:17.1
20,-30,2:17.1
20,-29,2:17.1
20,-28,2:17.1
20,-27,2:17.1
20,-26,2:17.1
20,-25,2:17.1
20,-24,2:17.1
20,-23,2:17.1
20,-22,2:17.1
20,-21,2:17.1
20,-20,2:17.1
20,-19,2:17.1
20,-18,2:17.1
20,-17,2:17.1
20,-16,2:17.1
20,-15,2:17.1
20,-14,2:17.1
20,-13,2:17.1
20,-12,2:17.1
20,-11,2:17.1
20,-10,2:17.1
20,-9,2:17.1
20,-8,2:17.1
20,-7,2:17.1
20,-6,2:17.1
20,-5,2:17.1
20,-4,2:17.1
20,-3,2:17.1
20,-2,2:17.1
20,-1,2:17.1
20,0,2:17.1
20,1,2:17.1
20,2,2:17.1
20,3,2:17.1
20,4,2:17.1
21,-39,2:17.1
21,-38,2:17.1
21,-37,2:17.1
21,-36,2:17.1
21,-35,2:17.1
21,-34,2:17.1
21,-33,2:17.1
21,-32,2:17.1
21,-31,2:17.1
21,-30,2:17.1
21,-29,2:17.1
21,-28,2:17.1
21,-27,2:17.1
21,-26,2:17.1
21,-25,2:17.1
21,-24,2:17.1
21,-23,2:17.1
21,-22,2:17.1
21,-21,2:17.1
21,-20,2:17.1
21,-19,2:17.1
21,-18,2:17.1
21,-17,2:17.1
21,-16,2:17.1
21,-15,2:17.1
21,-14,2:17.1
21,-13,2:17.1
21,-12,2:17.1
21,-11,2:17.1
21,-10,2:17.1
21,-9,2:17.1
21,-8,2:17.1
21,-7,2:17.1
21,-6,2:17.1
21,-5,2:17.1
21,-4,2:17.1
21,-3,2:17.1
21,-2,2:17.1
21,-1,2:17.1
21,0,2:17.1
21,1,2:17.1
21,2,2:17.1
21,3,2:17.1
21,4,2:17.1
22,-40,2:17.1
22,-39,2:17.1
22,-38,2:17.1
22,-37,2:17.1
22,-36,2:17.1
22,-35,2:17.1
22,-34,2:17.1
22,-33,2:17.1
22,-32,2:17.1
22,-31,2:17.1
22,-30,2:17.1
22,-29,2:17.1
22,-28,2:17.1
22,-27,2:17.1
22,-26,2:17.1
22,-25,2:17.1
22,-24,2:17.1
22,-23,2:17.1
22,-22,2:17.1
22,-21,2:17.1
22,-20,2:17.1
22,-19,2:17.1
22,-18,2:17.1
22,-17,2:17.1
22,-16,2:17.1
22,-15,2:17.1
22,-14,2:17.1
22,-13,2:17.1
22,-12,2:17.1
22,-11,2:17.1
22,-10,2:17.1
22,-9,2:17.1
22,-8,2:17.1
22,-7,2:17.1
22,-6,2:17.1
22,-5,2:17.1
22,-4,2:17.1
22,-3,2:17.1
22,-2,2:17.1
22,-1,2:17.1
22,0,2:17.1
22,1,2:17.1
22,2,2:17.1
22,3,2:17.1
22,4,2:17.1
23,-41,2:17.1
23,-40,2:17.1
23,-39,2:17.1
23,-38,2:17.1
23,-37,2:17.1
23,-36,2:17.1
23,-35,2:17.1
23,-34,2:17.1
23,-33,2:17.1
23,-32,2:17.1
23,-31,2:17.1
23,-30,2:17.1
23,-29,2:17.1
23,-28,2:17.1
23,-27,2:17.1
23,-26,2:17.1
23,-25,2:17.1
23,-24,2:17.1
23,-23,2:17.1
23,-22,2:17.1
23,-21,2:17.1
23,-20,2:17.1
23,-19,2:17.1
23,-18,2:17.1
23,-17,2:17.1
23,-16,2:17.1
23,-15,2:17.1
23,-14,2:17.1
23,-13,2:17.1
23,-12,2:17.1
23,-11,2:17.1
23,-10,2:17.1
23,-9,2:17.1
23,-8,2:17.1
23,-7,2:17.1
23,-6,2:17.1
23,-5,2:17.1
23,-4,2:17.1
23,-3,2:17.1
23,-2,2:17.1
23,-1,2:17.1
23,0,2:17.1
23,1,2:17.1
23,2,2:17.1
23,3,2:17.1
23,4,2:17.1
23,5,2:17.1
24,-42,2:17.1
24,-41,2:17.1
24,-40,2:17.1
24,-39,2:17.1
24,-38,2:17.1
24,-37,2:17.1
24,-36,2:17.1
24,-35,2:17.1
24,-34,2:17.1
24,-33,2:17.1
24,-32,2:17.1
24,-31,2:17.1
24,-30,2:17.1
24,-29,2:17.1
24,-28,2:17.1
24,-27,2:17.1
24,-26,2:17.1
24,-25,2:17.1
24,-24,2:17.1
24,-23,2:17.1
24,-22,2:17.1
24,-21,2:17.1
24,-20,2:17.1
24,-19,2:17.1
24,-18,2:17.1
24,-17,2:17.1
24,-16,2:17.1
24,-15,2:17.1
24,-14,2:17.1
24,-13,2:17.1
24,-12,2:17.1
24,-11,2:17.1
24,-10,2:17.1
24,-9,2:17.1
24,-8,2:17.1
24,-7,2:17.1
24,-6,2:17.1
24,-5,2:17.1
24,-4,2:17.1
24,-3,2:17.1
24,-2,2:17.1
24,-1,2:17.1
24,0,2:17.1
24,1,2:17.1
24,2,2:17.1
24,3,2:17.1
24,4,2:17.1
24,5,2:17.1
25,-43,2:17.1
25,-42,2:17.1
25,-41,2:17.1
25,-40,2:17.1
25,-39,2:17.1
25,-38,2:17.1
25,-37,2:17.1
25,-36,2:17.1
25,-35,2:17.1
25,-34,2:17.1
25,-33,2:17.1
25,-32,2:17.1
25,-31,2:17.1
25,-30,2:17.1
25,-29,2:17.1
25,-28,2:17.1
25,-27,2:17.1
25,-26,2:17.1
25,-25,2:17.1
25,-24,2:17.1
25,-23,2:17.1
25,-22,2:17.1
25,-21,2:17.1
25,-20,2:17.1
25,-19,2:17.1
25,-18,2:17.1
25,-17,2:17.1
25,-16,2:17.1
25,-15,2:17.1
25,-14,2:17.1
25,-13,2:17.1
25,-12,2:17.1
25,-11,2:17.1
25,-10,2:17.1
25,-9,2:17.1
25,-8,2:17.1
25,-7,2:17.1
25,-6,2:17.1
25,-5,2:17.1
25,-4,2:17.1
25,-3,2:17.1
25,-2,2:17.1
25,-1,2:17.1
25,0,2:17.1
25,1,2:17.1
25,2,2:17.1
25,3,2:17.1
25,4,2:17.1
25,5,2:17.1
26,-43,2:17.1
26,-42,2:17.1
26,-41,2:17.1
26,-40,2:17.1
26,-39,2:17.1
26,-38,2:17.1
26,-37,2:17.1
26,-36,2:17.1
26,-35,2:17.1
26,-34,2:17.1
26,-33,2:17.1
26,-32,2:17.1
26,-31,2:17.1
26,-30,2:17.1
26,-29,2:17.1
26,-28,2:17.1
26,-27,2:17.1
26,-26,2:17.1
26,-25,2:17.1
26,-24,2:17.1
26,-23,2:17.1
26,-22,2:17.1
26,-21,2:17.1
26,-20,2:17.1
26,-19,2:17.1
26,-18,2:17.1
26,-17,2:17.1
26,-16,2:17.1
26,-15,2:17.1
26,-14,2:17.1
26,-13,2:17.1
26,-12,2:17.1
26,-11,2:17.1
26,-10,2:17.1
26,-9,2:17.1
26,-8,2:17.1
26,-7,2:17.1
26,-6,2:17.1
26,-5,2:17.1
26,-4,2:17.1
26,-3,2:17.1
26,-2,2:17.1
26,-1,2:17.1
26,0,2:17.1
26,1,2:17.1
26,2,2:17.1
26,3,2:17.1
26,4,2:17.1
26,5,2:17.1
27,-43,2:17.1
27,-42,2:17.1
27,-41,2:17.1
27,-40,2:17.1
27,-39,2:17.1
27,-38,2:17.1
27,-37,2:17.1
27,-36,2:17.1
27,-35,2:17.1
27,-34,2:17.1
27,-33,2:17.1
27,-32,2:17.1
27,-31,2:17.1
27,-30,2:17.1
27,-29,2:17.1
27,-28,2:17.1
27,-27,2:17.1
27,-26,2:17.1
27,-25,2:17.1
27,-24,2:17.1
27,-23,2:17.1
27,-22,2:17.1
27,-21,2:17.1
27,-20,2:17.1
27,-19,2:17.1
27,-18,2:17.1
27,-17,2:17.1
27,-16,2:17.1
27,-15,2:17.1
27,-14,2:17.1
27,-13,2:17.1
27,-12,2:17.1
27,-11,2:17.1
27,-10,2:17.1
27,-9,2:17.1
27,-8,2:17.1
27,-7,2:17.1
27,-6,2:17.1
27,-5,2:17.1
27,-4,2:17.1
27,-3,2:17.1
27,-2,2:17.1
27,-1,2:17.1
27,0,2:17.1
27,1,2:17.1
27,2,2:17.1
27,3,2:17.1
27,4,2:17.1
27,5,2:17.1
28,-43,2:17.1
28,-42,2:17.1
28,-41,2:17.1
28,-40,2:17.1
28,-39,2:17.1
28,-38,2:17.1
28,-37,2:17.1
28,-36,2:17.1
28,-35,2:17.1
28,-34,2:17.1
28,-33,2:17.1
28,-32,2:17.1
28,-31,2:17.1
28,-30,2:17.1
28,-29,2:17.1
28,-28,2:17.1
28,-27,2:17.1
28,-26,2:17.1
28,-25,2:17.1
28,-24,2:17.1
28,-23,2:17.1
28,-22,2:17.1
28,-21,2:17.1
28,-20,2:17.1
28,-19,2:17.1
28,-18,2:17.1
28,-17,2:17.1
28,-16,2:17.1
28,-15,2:17.1
28,-14,2:17.1
28,-13,2:17.1
28,-12,2:17.1
28,-11,2:17.1
28,-10,2:17.1
28,-9,2:17.1
28,-8,2:17.1
28,-7,2:17.1
28,-6,2:17.1
28,-5,2:17.1
28,-4,2:17.1
28,-3,2:17.1
28,-2,2:17.1
28,-1,2:17.1
28,0,2:17.1
28,1,2:17.1
28,2,2:17.1
28,3,2:17.1
28,4,2:17.1
29,-43,2:17.1
29,-42,2:17.1
29,-41,2:17.1
29,-40,2:17.1
29,-39,2:17.1
29,-38,2:17.1
29,-37,2:17.1
29,-36,2:17.1
29,-35,2:17.1
29,-34,2:17.1
29,-33,2:17.1
29,-32,2:17.1
29,-31,2:17.1
29,-30,2:17.1
29,-29,2:17.1
29,-28,2:17.1
29,-27,2:17.1
29,-26,2:17.1
29,-25,2:17.1
29,-24,2:17.1
29,-23,2:17.1
29,-22,2:17.1
29,-21,2:17.1
29,-20,2:17.1
29,-19,2:17.1
29,-18,2:17.1
29,-17,2:17.1
29,-16,2:17.1
29,-15,2:17.1
29,-14,2:17.1
29,-13,2:17.1
29,-12,2:17.1
29,-11,2:17.1
29,-10,2:17.1
29,-9,2:17.1
29,-8,2:17.1
29,-7,2:17.1
29,-6,2:17.1
29,-5,2:17.1
29,-4,2:17.1
29,-3,2:17.1
29,-2,2:17.1
29,-1,2:17.1
29,0,2:17.1
29,1,2:17.1
29,2,2:17.1
29,3,2:17.1
29,4,2:17.1
30,-42,2:17.1
30,-41,2:17.1
30,-40,2:17.1
30,-39,2:17.1
30,-38,2:17.1
30,-37,2:17.1
30,-36,2:17.1
30,-35,2:17.1
30,-34,2:17.1
30,-33,2:17.1
30,-32,2:17.1
30,-31,2:17.1
30,-30,2:17.1
30,-29,2:17.1
30,-28,2:17.1
30,-27,2:17.1
30,-26,2:17.1
30,-25,2:17.1
30,-24,2:17.1
30,-23,2:17.1
30,-22,2:17.1
30,-21,2:17.1
30,-20,2:17.1
30,-19,2:17.1
30,-18,2:17.1
30,-17,2:17.1
30,-16,2:17.1
30,-15,2:17.1
30,-14,2:17.1
30,-13,2:17.1
30,-12,2:17.1
30,-11,2:17.1
30,-10,2:17.1
30,-9,2:17.1
30,-8,2:17.1
30,-7,2:17.1
30,-6,2:17.1
30,-5,2:17.1
30,-4,2:17.1
30,-3,2:17.1
30,-2,2:17.1
30,-1,2:17.1
30,0,2:17.1
30,1,2:17.1
30,2,2:17.1
30,3,2:17.1
31,-41,2:17.1
31,-40,2:17.1
31,-39,2:17.1
31,-38,2:17.1
31,-37,2:17.1
31,-36,2:17.1
31,-35,2:17.1
31,-34,2:17.1
31,-33,2:17.1
31,-32,2:17.1
31,-31,2:17.1
31,-30,2:17.1
31,-29,2:17.1
31,-28,2:17.1
31,-27,2:17.1
31,-26,2:17.1
31,-25,2:17.1
31,-24,2:17.1
31,-23,2:17.1
31,-22,2:17.1
31,-21,2:17.1
31,-20,2:17.1
31,-19,2:17.1
31,-18,2:17.1
31,-17,2:17.1
31,-16,2:17.1
31,-15,2:17.1
31,-14,2:17.1
31,-13,2:17.1
31,-12,2:17.1
31,-11,2:17.1
31,-10,2:17.1
31,-9,2:17.1
31,-8,2:17.1
31,-7,2:17.1
31,-6,2:17.1
31,-5,2:17.1
31,-4,2:17.1
31,-3,2:17.1
31,-2,2:17.1
31,-1,2:17.1
31,0,2:17.1
31,1,2:17.1
31,2,2:17.1
31,3,2:17.1
32,-40,2:17.1
32,-39,2:17.1
32,-38,2:17.1
32,-37,2:17.1
32,-36,2:17.1
32,-35,2:17.1
32,-34,2:17.1
32,-33,2:17.1
32,-32,2:17.1
32,-31,2:17.1
32,-30,2:17.1
32,-29,2:17.1
32,-28,2:17.1
32,-27,2:17.1
32,-26,2:17.1
32,-25,2:17.1
32,-24,2:17.1
32,-23,2:17.1
32,-22,2:17.1
32,-21,2:17.1
32,-20,2:17.1
32,-19,2:17.1
32,-18,2:17.1
32,-17,2:17.1
32,-16,2:17.1
32,-15,2:17.1
32,-14,2:17.1
32,-13,2:17.1
32,-12,2:17.1
32,-11,2:17.1
32,-10,2:17.1
32,-9,2:17.1
32,-8,2:17.1
32,-7,2:17.1
32,-6,2:17.1
32,-5,2:17.1
32,-4,2:17.1
32,-3,2:17.1
32,-2,2:17.1
32,-1,2:17.1
32,0,2:17.1
32,1,2:17.1
32,2,2:17.1
33,-40,2:17.1
33,-39,2:17.1
33,-38,2:17.1
33,-37,2:17.1
33,-36,2:17.1
33,-35,2:17.1
33,-34,2:17.1
33,-33,2:17.1
33,-32,2:17.1
33,-31,2:17.1
33,-30,2:17.1
33,-29,2:17.1
33,-28,2:17.1
33,-27,2:17.1
33,-26,2:17.1
33,-25,2:17.1
33,-24,2:17.1
33,-23,2:17.1
33,-22,2:17.1
33,-21,2:17.1
33,-20,2:17.1
33,-19,2:17.1
33,-18,2:17.1
33,-17,2:17.1
33,-16,2:17.1
33,-15,2:17.1
33,-14,2:17.1
33,-13,2:17.1
33,-12,2:17.1
33,-11,2:17.1
33,-10,2:17.1
33,-9,2:17.1
33,-8,2:17.1
33,-7,2:17.1
33,-6,2:17.1
33,-5,2:17.1
33,-4,2:17.1
33,-3,2:17.1
33,-2,2:17.1
33,-1,2:17.1
33,0,2:17.1
33,1,2:17.1
33,2,2:17.1
34,-39,2:17.1
34,-38,2:17.1
34,-37,2:17.1
34,-36,2:17.1
34,-35,2:17.1
34,-34,2:17.1
34,-33,2:17.1
34,-32,2:17.1
34,-31,2:17.1
34,-30,2:17.1
34,-29,2:17.1
34,-28,2:17.1
34,-27,2:17.1
34,-26,2:17.1
34,-25,2:17.1
34,-24,2:17.1
34,-23,2:17.1
34,-22,2:17.1
34,-21,2:17.1
34,-20,2:17.1
34,-19,2:17.1
34,-18,2:17.1
34,-17,2:17.1
34,-16,2:17.1
34,-15,2:17.1
34,-14,2:17.1
34,-13,2:17.1
34,-12,2:17.1
34,-11,2:17.1
34,-10,2:17.1
34,-9,2:17.1
34,-8,2:17.1
34,-7,2:17.1
34,-6,2:17.1
34,-5,2:17.1
34,-4,2:17.1
34,-3,2:17.1
34,-2,2:17.1
34,-1,2:17.1
34,0,2:17.1
34,1,2:17.1
34,2,2:17.1
35,-38,2:17.1
35,-37,2:17.1
35,-36,2:17.1
35,-35,2:17.1
35,-34,2:17.1
35,-33,2:17.1
35,-32,2:17.1
35,-31,2:17.1
35,-30,2:17.1
35,-29,2:17.1
35,-28,2:17.1
35,-27,2:17.1
35,-26,2:17.1
35,-25,2:17.1
35,-24,2:17.1
35,-23,2:17.1
35,-22,2:17.1
35,-21,2:17.1
35,-20,2:17.1
35,-19,2:17.1
35,-18,2:17.1
35,-17,2:17.1
35,-16,2:17.1
35,-15,2:17.1
35,-14,2:17.1
35,-13,2:17.1
35,-12,2:17.1
35,-11,2:17.1
35,-10,2:17.1
35,-9,2:17.1
35,-8,2:17.1
35,-7,2:17.1
35,-6,2:17.1
35,-5,2:17.1
35,-4,2:17.1
35,-3,2:17.1
35,-2,2:17.1
35,-1,2:17.1
35,0,2:17.1
35,1,2:17.1
36,-38,2:17.1
36,-37,2:17.1
36,-36,2:17.1
36,-35,2:17.1
36,-34,2:17.1
36,-33,2:17.1
36,-32,2:17.1
36,-31,2:17.1
36,-30,2:17.1
36,-29,2:17.1
36,-28,2:17.1
36,-27,2:17.1
36,-26,2:17.1
36,-25,2:17.1
36,-24,2:17.1
36,-23,2:17.1
36,-22,2:17.1
36,-21,2:17.1
36,-20,2:17.1
36,-19,2:17.1
36,-18,2:17.1
36,-17,2:17.1
36,-16,2:17.1
36,-15,2:17.1
36,-14,2:17.1
36,-13,2:17.1
36,-12,2:17.1
36,-11,2:17.1
36,-10,2:17.1
36,-9,2:17.1
36,-8,2:17.1
36,-7,2:17.1
36,-6,2:17.1
36,-5,2:17.1
36,-4,2:17.1
36,-3,2:17.1
36,-2,2:17.1
36,-1,2:17.1
36,0,2:17.1
36,1,2:17.1
36,2,2:17.1
37,-37,2:17.1
37,-36,2:17.1
37,-35,2:17.1
37,-34,2:17.1
37,-33,2:17.1
37,-32,2:17.1
37,-31,2:17.1
37,-30,2:17.1
37,-29,2:17.1
37,-28,2:17.1
37,-27,2:17.1
37,-26,2:17.1
37,-25,2:17.1
37,-24,2:17.1
37,-23,2:17.1
37,-22,2:17.1
37,-21,2:17.1
37,-20,2:17.1
37,-19,2:17.1
37,-18,2:17.1
37,-17,2:17.1
37,-16,2:17.1
37,-15,2:17.1
37,-14,2:17.1
37,-13,2:17.1
37,-12,2:17.1
37,-11,2:17.1
37,-10,2:17.1
37,-9,2:17.1
37,-8,2:17.1
37,-7,2:17.1
37,-6,2:17.1
37,-5,2:17.1
37,-4,2:17.1
37,-3,2:17.1
37,-2,2:17.1
37,-1,2:17.1
37,0,2:17.1
37,1,2:17.1
37,2,2:17.1
38,-37,2:17.1
38,-36,2:17.1
38,-35,2:17.1
38,-34,2:17.1
38,-33,2:17.1
38,-32,2:17.1
38,-31,2:17.1
38,-30,2:17.1
38,-29,2:17.1
38,-28,2:17.1
38,-27,2:17.1
38,-26,2:17.1
38,-25,2:17.1
38,-24,2:17.1
38,-23,2:17.1
38,-22,2:17.1
38,-21,2:17.1
38,-20,2:17.1
38,-19,2:17.1
38,-18,2:17.1
38,-17,2:17.1
38,-16,2:17.1
38,-15,2:17.1
38,-14,2:17.1
38,-13,2:17.1
38,-12,2:17.1
38,-11,2:17.1
38,-10,2:17.1
38,-9,2:17.1
38,-8,2:17.1
38,-7,2:17.1
38,-6,2:17.1
38,-5,2:17.1
38,-4,2:17.1
38,-3,2:17.1
38,-2,2:17.1
38,-1,2:17.1
38,0,2:17.1
38,1,2:17.1
38,2,2:17.1
39,-36,2:17.1
39,-35,2:17.1
39,-34,2:17.1
39,-33,2:17.1
39,-32,2:17.1
39,-31,2:17.1
39,-30,2:17.1
39,-29,2:17.1
39,-28,2:17.1
39,-27,2:17.1
39,-26,2:17.1
39,-25,2:17.1
39,-24,2:17.1
39,-23,2:17.1
39,-22,2:17.1
39,-21,2:17.1
39,-20,2:17.1
39,-19,2:17.1
39,-18,2:17.1
39,-17,2:17.1
39,-16,2:17.1
39,-15,2:17.1
39,-14,2:17.1
39,-13,2:17.1
39,-12,2:17.1
39,-11,2:17.1
39,-10,2:17.1
39,-9,2:17.1
39,-8,2:17.1
39,-7,2:17.1
39,-6,2:17.1
39,-5,2:17.1
39,-4,2:17.1
39,-3,2:17.1
39,-2,2:17.1
39,-1,2:17.1
39,0,2:17.1
39,1,2:17.1
39,2,2:17.1
40,-35,2:17.1
40,-34,2:17.1
40,-33,2:17.1
40,-32,2:17.1
40,-31,2:17.1
40,-30,2:17.1
40,-29,2:17.1
40,-28,2:17.1
40,-27,2:17.1
40,-26,2:17.1
40,-25,2:17.1
40,-23,2:17.1
40,-22,2:17.1
40,-21,2:17.1
40,-20,2:17.1
40,-19,2:17.1
40,-18,2:17.1
40,-17,2:17.1
40,-16,2:17.1
40,-15,2:17.1
40,-14,2:17.1
40,-13,2:17.1
40,-12,2:17.1
40,-11,2:17.1
40,-10,2:17.1
40,-9,2:17.1
40,-8,2:17.1
40,-7,2:17.1
40,-6,2:17.1
40,-5,2:17.1
40,-4,2:17.1
40,-3,2:17.1
40,-2,2:17.1
40,-1,2:17.1
40,0,2:17.1
40,1,2:17.1
40,2,2:17.1
41,-33,2:17.1
41,-32,2:17.1
41,-31,2:17.1
41,-30,2:17.1
41,-29,2:17.1
41,-28,2:17.1
41,-27,2:17.1
41,-23,2:17.1
41,-22,2:17.1
41,-21,2:17.1
41,-20,2:17.1
41,-19,2:17.1
41,-18,2:17.1
41,-17,2:17.1
41,-16,2:17.1
41,-15,2:17.1
41,-14,2:17.1
41,-13,2:17.1
41,-12,2:17.1
41,-11,2:17.1
41,-10,2:17.1
41,-9,2:17.1
41,-8,2:17.1
41,-7,2:17.1
41,-6,2:17.1
41,-5,2:17.1
41,-4,2:17.1
41,-3,2:17.1
41,-2,2:17.1
41,-1,2:17.1
41,0,2:17.1
41,1,2:17.1
42,-23,2:17.1
42,-22,2:17.1
42,-21,2:17.1
42,-20,2:17.1
42,-19,2:17.1
42,-18,2:17.1
42,-17,2:17.1
42,-16,2:17.1
42,-15,2:17.1
42,-14,2:17.1
42,-13,2:17.1
42,-12,2:17.1
42,-11,2:17.1
42,-10,2:17.1
42,-9,2:17.1
42,-8,2:17.1
42,-7,2:17.1
42,-6,2:17.1
42,-5,2:17.1
42,-4,2:17.1
42,-3,2:17.1
42,-2,2:17.1
42,-1,2:17.1
42,0,2:17.1
42,1,2:17.1
43,-22,2:17.1
43,-21,2:17.1
43,-20,2:17.1
43,-19,2:17.1
43,-18,2:17.1
43,-17,2:17.1
43,-16,2:17.1
43,-15,2:17.1
43,-14,2:17.1
43,-13,2:17.1
43,-12,2:17.1
43,-11,2:17.1
43,-10,2:17.1
43,-9,2:17.1
43,-8,2:17.1
43,-7,2:17.1
43,-6,2:17.1
43,-5,2:17.1
43,-4,2:17.1
43,-3,2:17.1
43,-2,2:17.1
43,-1,2:17.1
43,0,2:17.1
44,-22,2:17.1
44,-21,2:17.1
44,-20,2:17.1
44,-19,2:17.1
44,-18,2:17.1
44,-17,2:17.1
44,-16,2:17.1
44,-15,2:17.1
44,-14,2:17.1
44,-13,2:17.1
44,-12,2:17.1
44,-11,2:17.1
44,-10,2:17.1
44,-9,2:17.1
44,-8,2:17.1
44,-7,2:17.1
44,-6,2:17.1
44,-5,2:17.1
44,-4,2:17.1
44,-3,2:17.1
44,-2,2:17.1
44,-1,2:17.1
44,0,2:17.1
45,-21,2:17.1
45,-20,2:17.1
45,-19,2:17.1
45,-18,2:17.1
45,-17,2:17.1
45,-16,2:17.1
45,-15,2:17.1
45,-14,2:17.1
45,-13,2:17.1
45,-12,2:17.1
45,-11,2:17.1
45,-10,2:17.1
45,-9,2:17.1
45,-8,2:17.1
45,-7,2:17.1
45,-6,2:17.1
45,-5,2:17.1
45,-4,2:17.1
45,-3,2:17.1
45,-2,2:17.1
45,-1,2:17.1
45,0,2:17.1
46,-21,2:17.1
46,-20,2:17.1
46,-19,2:17.1
46,-18,2:17.1
46,-17,2:17.1
46,-16,2:17.1
46,-15,2:17.1
46,-14,2:17.1
46,-13,2:17.1
46,-12,2:17.1
46,-11,2:17.1
46,-10,2:17.1
46,-9,2:17.1
46,-8,2:17.1
46,-7,2:17.1
46,-6,2:17.1
46,-5,2:17.1
46,-4,2:17.1
46,-3,2:17.1
46,-2,2:17.1
46,-1,2:17.1
47,-20,2:17.1
47,-19,2:17.1
47,-18,2:17.1
47,-17,2:17.1
47,-16,2:17.1
47,-15,2:17.1
47,-14,2:17.1
47,-13,2:17.1
47,-12,2:17.1
47,-11,2:17.1
47,-10,2:17.1
47,-9,2:17.1
47,-8,2:17.1
47,-7,2:17.1
47,-6,2:17.1
47,-5,2:17.1
47,-4,2:17.1
47,-3,2:17.1
47,-2,2:17.1
47,-1,2:17.1
48,-19,2:17.1
48,-18,2:17.1
48,-17,2:17.1
48,-16,2:17.1
48,-15,2:17.1
48,-14,2:17.1
48,-13,2:17.1
48,-12,2:17.1
48,-11,2:17.1
48,-10,2:17.1
48,-9,2:17.1
48,-8,2:17.1
48,-7,2:17.1
48,-6,2:17.1
48,-5,2:17.1
48,-4,2:17.1
48,-3,2:17.1
48,-2,2:17.1
49,-18,2:17.1
49,-17,2:17.1
49,-16,2:17.1
49,-15,2:17.1
49,-14,2:17.1
49,-13,2:17.1
49,-12,2:17.1
49,-11,2:17.1
49,-10,2:17.1
49,-9,2:17.1
49,-8,2:17.1
49,-7,2:17.1
49,-6,2:17.1
49,-5,2:17.1
49,-4,2:17.1
49,-3,2:17.1
50,-17,2:17.1
50,-16,2:17.1
50,-15,2:17.1
50,-14,2:17.1
50,-13,2:17.1
50,-12,2:17.1
50,-11,2:17.1
50,-10,2:17.1
50,-9,2:17.1
50,-8,2:17.1
50,-7,2:17.1
50,-6,2:17.1
50,-5,2:17.1
-1,-11,3:17.1
-1,-10,3:17.1
-1,-9,3:17.1
0,-13,3:17.1
0,-12,3:17.1
0,-11,3:17.1
0,-10,3:17.1
0,-9,3:17.1
0,-8,3:17.1
0,-7,3:17.1
1,-14,3:17.1
1,-13,3:17.1
1,-12,3:17.1
1,-11,3:17.1
1,-10,3:17.1
1,-9,3:17.1
1,-8,3:17.1
1,-7,3:17.1
1,-6,3:17.1
2,-14,3:17.1
2,-13,3:17.1
2,-12,3:17.1
2,-11,3:17.1
2,-10,3:17.1
2,-9,3:17.1
2,-8,3:17.1
2,-7,3:17.1
2,-6,3:17.1
3,-22,3:17.1
3,-21,3:17.1
3,-20,3:17.1
3,-19,3:17.1
3,-18,3:17.1
3,-15,3:17.1
3,-14,3:17.1
3,-13,3:17.1
3,-12,3:17.1
3,-11,3:17.1
3,-10,3:17.1
3,-9,3:17.1
3,-8,3:17.1
3,-7,3:17.1
3,-6,3:17.1
3,-5,3:17.1
3,-4,3:17.1
4,-25,3:17.1
4,-24,3:17.1
4,-23,3:17.1
4,-22,3:17.1
4,-21,3:17.1
4,-20,3:17.1
4,-19,3:17.1
4,-18,3:17.1
4,-17,3:17.1
4,-16,3:17.1
4,-15,3:17.1
4,-14,3:17.1
4,-13,3:17.1
4,-12,3:17.1
4,-11,3:17.1
4,-10,3:17.1
4,-9,3:17.1
4,-8,3:17.1
4,-7,3:17.1
4,-6,3:17.1
4,-5,3:17.1
4,-4,3:17.1
4,-3,3:17.1
5,-26,3:17.1
5,-25,3:17.1
5,-24,3:17.1
5,-23,3:17.1
5,-22,3:17.1
5,-21,3:17.1
5,-20,3:17.1
5,-19,3:17.1
5,-18,3:17.1
5,-17,3:17.1
5,-16,3:17.1
5,-15,3:17.1
5,-14,3:17.1
5,-13,3:17.1
5,-12,3:17.1
5,-11,3:17.1
5,-10,3:17.1
5,-9,3:17.1
5,-8,3:17.1
5,-7,3:17.1
5,-6,3:17.1
5,-5,3:17.1
5,-4,3:17.1
5,-3,3:17.1
5,-2,3:17.1
6,-27,3:17.1
6,-26,3:17.1
6,-25,3:17.1
6,-24,3:17.1
6,-23,3:17.1
6,-22,3:17.1
6,-21,3:17.1
6,-20,3:17.1
6,-19,3:17.1
6,-18,3:17.1
6,-17,3:17.1
6,-16,3:17.1
6,-15,3:17.1
6,-14,3:17.1
6,-13,3:17.1
6,-12,3:17.1
6,-11,3:17.1
6,-10,3:17.1
6,-9,3:17.1
6,-8,3:17.1
6,-7,3:17.1
6,-6,3:17.1
6,-5,3:17.1
6,-4,3:17.1
6,-3,3:17.1
6,-2,3:17.1
7,-27,3:17.1
7,-26,3:17.1
7,-25,3:17.1
7,-24,3:17.1
7,-23,3:17.1
7,-22,3:17.1
7,-21,3:17.1
7,-20,3:17.1
7,-19,3:17.1
7,-18,3:17.1
7,-17,3:17.1
7,-16,3:17.1
7,-15,3:17.1
7,-14,3:17.1
7,-13,3:17.1
7,-12,3:17.1
7,-11,3:17.1
7,-10,3:17.1
7,-9,3:17.1
7,-8,3:17.1
7,-7,3:17.1
7,-6,3:17.1
7,-5,3:17.1
7,-4,3:17.1
7,-3,3:17.1
7,-2,3:17.1
8,-27,3:17.1
8,-26,3:17.1
8,-25,3:17.1
8,-24,3:17.1
8,-23,3:17.1
8,-22,3:17.1
8,-21,3:17.1
8,-20,3:17.1
8,-19,3:17.1
8,-18,3:17.1
8,-17,3:17.1
8,-16,3:17.1
8,-15,3:17.1
8,-14,3:17.1
8,-13,3:17.1
8,-12,3:17.1
8,-11,3:17.1
8,-10,3:17.1
8,-9,3:17.1
8,-8,3:17.1
8,-7,3:17.1
8,-6,3:17.1
8,-5,3:17.1
8,-4,3:17.1
8,-3,3:17.1
8,-2,3:17.1
9,-29,3:17.1
9,-28,3:17.1
9,-27,3:17.1
9,-26,3:17.1
9,-25,3:17.1
9,-24,3:17.1
9,-23,3:17.1
9,-22,3:17.1
9,-21,3:17.1
9,-20,3:17.1
9,-19,3:17.1
9,-18,3:17.1
9,-17,3:17.1
9,-16,3:17.1
9,-15,3:17.1
9,-14,3:17.1
9,-13,3:17.1
9,-12,3:17.1
9,-11,3:17.1
9,-10,3:17.1
9,-9,3:17.1
9,-8,3:17.1
9,-7,3:17.1
9,-6,3:17.1
9,-5,3:17.1
9,-4,3:17.1
9,-3,3:17.1
9,-2,3:17.1
10,-30,3:17.1
10,-29,3:17.1
10,-28,3:17.1
10,-27,3:17.1
10,-26,3:17.1
10,-25,3:17.1
10,-24,3:17.1
10,-23,3:17.1
10,-22,3:17.1
10,-21,3:17.1
10,-20,3:17.1
10,-19,3:17.1
10,-18,3:17.1
10,-17,3:17.1
10,-16,3:17.1
10,-15,3:17.1
10,-14,3:17.1
10,-13,3:17.1
10,-12,3:17.1
10,-11,3:17.1
10,-10,3:17.1
10,-9,3:17.1
10,-8,3:17.1
10,-7,3:17.1
10,-6,3:17.1
10,-5,3:17.1
10,-4,3:17.1
10,-3,3:17.1
10,-2,3:17.1
10,-1,3:17.1
11,-31,3:17.1
11,-30,3:17.1
11,-29,3:17.1
11,-28,3:17.1
11,-27,3:17.1
11,-26,3:17.1
11,-25,3:17.1
11,-24,3:17.1
11,-23,3:17.1
11,-22,3:17.1
11,-21,3:17.1
11,-20,3:17.1
11,-19,3:17.1
11,-18,3:17.1
11,-17,3:17.1
11,-16,3:17.1
11,-15,3:17.1
11,-14,3:17.1
11,-13,3:17.1
11,-12,3:17.1
11,-11,3:17.1
11,-10,3:17.1
11,-9,3:17.1
11,-8,3:17.1
11,-7,3:17.1
11,-6,3:17.1
11,-5,3:17.1
11,-4,3:17.1
11,-3,3:17.1
11,-2,3:17.1
11,-1,3:17.1
11,0,3:17.1
12,-32,3:17.1
12,-31,3:17.1
12,-30,3:17.1
12,-29,3:17.1
12,-28,3:17.1
12,-27,3:17.1
12,-26,3:17.1
12,-25,3:17.1
12,-24,3:17.1
12,-23,3:17.1
12,-22,3:17.1
12,-21,3:17.1
12,-20,3:17.1
12,-19,3:17.1
12,-18,3:17.1
12,-17,3:17.1
12,-16,3:17.1
12,-15,3:17.1
12,-14,3:17.1
12,-13,3:17.1
12,-12,3:17.1
12,-11,3:17.1
12,-10,3:17.1
12,-9,3:17.1
12,-8,3:17.1
12,-7,3:17.1
12,-6,3:17.1
12,-5,3:17.1
12,-4,3:17.1
12,-3,3:17.1
12,-2,3:17.1
12,-1,3:17.1
12,0,3:17.1
12,1,3:17.1
13,-32,3:17.1
13,-31,3:17.1
13,-30,3:17.1
13,-29,3:17.1
13,-28,3:17.1
13,-27,3:17.1
13,-26,3:17.1
13,-25,3:17.1
13,-24,3:17.1
13,-23,3:17.1
13,-22,3:17.1
13,-21,3:17.1
13,-20,3:17.1
13,-19,3:17.1
13,-18,3:17.1
13,-17,3:17.1
13,-16,3:17.1
13,-15,3:17.1
13,-14,3:17.1
13,-13,3:17.1
13,-12,3:17.1
13,-11,3:17.1
13,-10,3:17.1
13,-9,3:17.1
13,-8,3:17.1
13,-7,3:17.1
13,-6,3:17.1
13,-5,3:17.1
13,-4,3:17.1
13,-3,3:17.1
13,-2,3:17.1
13,-1,3:17.1
13,0,3:17.1
13,1,3:17.1
13,2,3:17.1
14,-32,3:17.1
14,-31,3:17.1
14,-30,3:17.1
14,-29,3:17.1
14,-28,3:17.1
14,-27,3:17.1
14,-26,3:17.1
14,-25,3:17.1
14,-24,3:17.1
14,-23,3:17.1
14,-22,3:17.1
14,-21,3:17.1
14,-20,3:17.1
14,-19,3:17.1
14,-18,3:17.1
14,-17,3:17.1
14,-16,3:17.1
14,-15,3:17.1
14,-14,3:17.1
14,-13,3:17.1
14,-12,3:17.1
14,-11,3:17.1
14,-10,3:17.1
14,-9,3:17.1
14,-8,3:17.1
14,-7,3:17.1
14,-6,3:17.1
14,-5,3:17.1
14,-4,3:17.1
14,-3,3:17.1
14,-2,3:17.1
14,-1,3:17.1
14,0,3:17.1
14,1,3:17.1
14,2,3:17.1
15,-32,3:17.1
15,-31,3:17.1
15,-30,3:17.1
15,-29,3:17.1
15,-28,3:17.1
15,-27,3:17.1
15,-26,3:17.1
15,-25,3:17.1
15,-24,3:17.1
15,-23,3:17.1
15,-22,3:17.1
15,-21,3:17.1
15,-20,3:17.1
15,-19,3:17.1
15,-18,3:17.1
15,-17,3:17.1
15,-16,3:17.1
15,-15,3:17.1
15,-14,3:17.1
15,-13,3:17.1
15,-12,3:17.1
15,-11,3:17.1
15,-10,3:17.1
15,-9,3:17.1
15,-8,3:17.1
15,-7,3:17.1
15,-6,3:17.1
15,-5,3:17.1
15,-4,3:17.1
15,-3,3:17.1
15,-2,3:17.1
15,-1,3:17.1
15,0,3:17.1
15,1,3:17.1
15,2,3:17.1
15,3,3:17.1
16,-32,3:17.1
16,-31,3:17.1
16,-30,3:17.1
16,-29,3:17.1
16,-28,3:17.1
16,-27,3:17.1
16,-26,3:17.1
16,-25,3:17.1
16,-24,3:17.1
16,-23,3:17.1
16,-22,3:17.1
16,-21,3:17.1
16,-20,3:17.1
16,-19,3:17.1
16,-18,3:17.1
16,-17,3:17.1
16,-16,3:17.1
16,-15,3:17.1
16,-14,3:17.1
16,-13,3:17.1
16,-12,3:17.1
16,-11,3:17.1
16,-10,3:17.1
16,-9,3:17.1
16,-8,3:17.1
16,-7,3:17.1
16,-6,3:17.1
16,-5,3:17.1
16,-4,3:17.1
16,-3,3:17.1
16,-2,3:17.1
16,-1,3:17.1
16,0,3:17.1
16,1,3:17.1
16,2,3:17.1
16,3,3:17.1
17,-32,3:17.1
17,-31,3:17.1
17,-30,3:17.1
17,-29,3:17.1
17,-28,3:17.1
17,-27,3:17.1
17,-26,3:17.1
17,-25,3:17.1
17,-24,3:17.1
17,-23,3:17.1
17,-22,3:17.1
17,-21,3:17.1
17,-20,3:17.1
17,-19,3:17.1
17,-18,3:17.1
17,-17,3:17.1
17,-16,3:17.1
17,-15,3:17.1
17,-14,3:17.1
17,-13,3:17.1
17,-12,3:17.1
17,-11,3:17.1
17,-10,3:17.1
17,-9,3:17.1
17,-8,3:17.1
17,-7,3:17.1
17,-6,3:17.1
17,-5,3:17.1
17,-4,3:17.1
17,-3,3:17.1
17,-2,3:17.1
17,-1,3:17.1
17,0,3:17.1
17,1,3:17.1
17,2,3:17.1
17,3,3:17.1
18,-33,3:17.1
18,-32,3:17.1
18,-31,3:17.1
18,-30,3:17.1
18,-29,3:17.1
18,-28,3:17.1
18,-27,3:17.1
18,-26,3:17.1
18,-25,3:17.1
18,-24,3:17.1
18,-23,3:17.1
18,-22,3:17.1
18,-21,3:17.1
18,-20,3:17.1
18,-19,3:17.1
18,-18,3:17.1
18,-17,3:17.1
18,-16,3:17.1
18,-15,3:17.1
18,-14,3:17.1
18,-13,3:17.1
18,-12,3:17.1
18,-11,3:17.1
18,-10,3:17.1
18,-9,3:17.1
18,-8,3:17.1
18,-7,3:17.1
18,-6,3:17.1
18,-5,3:17.1
18,-4,3:17.1
18,-3,3:17.1
18,-2,3:17.1
18,-1,3:17.1
18,0,3:17.1
18,1,3:17.1
18,2,3:17.1
18,3,3:17.1
19,-35,3:17.1
19,-34,3:17.1
19,-33,3:17.1
19,-32,3:17.1
19,-31,3:17.1
19,-30,3:17.1
19,-29,3:17.1
19,-28,3:17.1
19,-27,3:17.1
19,-26,3:17.1
19,-25,3:17.1
19,-24,3:17.1
19,-23,3:17.1
19,-22,3:17.1
19,-21,3:17.1
19,-20,3:17.1
19,-19,3:17.1
19,-18,3:17.1
19,-17,3:17.1
19,-16,3:17.1
19,-15,3:17.1
19,-14,3:17.1
19,-13,3:17.1
19,-12,3:17.1
19,-11,3:17.1
19,-10,3:17.1
19,-9,3:17.1
19,-8,3:17.1
19,-7,3:17.1
19,-6,3:17.1
19,-5,3:17.1
19,-4,3:17.1
19,-3,3:17.1
19,-2,3:17.1
19,-1,3:17.1
19,0,3:17.1
19,1,3:17.1
19,2,3:17.1
19,3,3:17.1
20,-38,3:17.1
20,-37,3:17.1
20,-36,3:17.1
20,-35,3:17.1
20,-34,3:17.1
20,-33,3:17.1
20,-32,3:17.1
20,-31,3:17.1
20,-30,3:17.1
20,-29,3:17.1
20,-28,3:17.1
20,-27,3:17.1
20,-26,3:17.1
20,-25,3:17.1
20,-24,3:17.1
20,-23,3:17.1
20,-22,3:17.1
20,-21,3:17.1
20,-20,3:17.1
20,-19,3:17.1
20,-18,3:17.1
20,-17,3:17.1
20,-16,3:17.1
20,-15,3:17.1
20,-14,3:17.1
20,-13,3:17.1
20,-12,3:17.1
20,-11,3:17.1
20,-10,3:17.1
20,-9,3:17.1
20,-8,3:17.1
20,-7,3:17.1
20,-6,3:17.1
20,-5,3:17.1
20,-4,3:17.1
20,-3,3:17.1
20,-2,3:17.1
20,-1,3:17.1
20,0,3:17.1
20,1,3:17.1
20,2,3:17.1
20,3,3:17.1
21,-39,3:17.1
21,-38,3:17.1
21,-37,3:17.1
21,-36,3:17.1
21,-35,3:17.1
21,-34,3:17.1
21,-33,3:17.1
21,-32,3:17.1
21,-31,3:17.1
21,-30,3:17.1
21,-29,3:17.1
21,-28,3:17.1
21,-27,3:17.1
21,-26,3:17.1
21,-25,3:17.1
21,-24,3:17.1
21,-23,3:17.1
21,-22,3:17.1
21,-21,3:17.1
21,-20,3:17.1
21,-19,3:17.1
21,-18,3:17.1
21,-17,3:17.1
21,-16,3:17.1
21,-15,3:17.1
21,-14,3:17.1
21,-13,3:17.1
21,-12,3:17.1
21,-11,3:17.1
21,-10,3:17.1
21,-9,3:17.1
21,-8,3:17.1
21,-7,3:17.1
21,-6,3:17.1
21,-5,3:17.1
21,-4,3:17.1
21,-3,3:17.1
21,-2,3:17.1
21,-1,3:17.1
21,0,3:17.1
21,1,3:17.1
21,2,3:17.1
21,3,3:17.1
22,-40,3:17.1
22,-39,3:17.1
22,-38,3:17.1
22,-37,3:17.1
22,-36,3:17.1
22,-35,3:17.1
22,-34,3:17.1
22,-33,3:17.1
22,-32,3:17.1
22,-31,3:17.1
22,-30,3:17.1
22,-29,3:17.1
22,-28,3:17.1
22,-27,3:17.1
22,-26,3:17.1
22,-25,3:17.1
22,-24,3:17.1
22,-23,3:17.1
22,-22,3:17.1
22,-21,3:17.1
22,-20,3:17.1
22,-19,3:17.1
22,-18,3:17.1
22,-17,3:17.1
22,-16,3:17.1
22,-15,3:17.1
22,-14,3:17.1
22,-13,3:17.1
22,-12,3:17.1
22,-11,3:17.1
22,-10,3:17.1
22,-9,3:17.1
22,-8,3:17.1
22,-7,3:17.1
22,-6,3:17.1
22,-5,3:17.1
22,-4,3:17.1
22,-3,3:17.1
22,-2,3:17.1
22,-1,3:17.1
22,0,3:17.1
22,1,3:17.1
22,2,3:17.1
22,3,3:17.1
23,-41,3:17.1
23,-40,3:17.1
23,-39,3:17.1
23,-38,3:17.1
23,-37,3:17.1
23,-36,3:17.1
23,-35,3:17.1
23,-34,3:17.1
23,-33,3:17.1
23,-32,3:17.1
23,-31,3:17.1
23,-30,3:17.1
23,-29,3:17.1
23,-28,3:17.1
23,-27,3:17.1
23,-26,3:17.1
23,-25,3:17.1
23,-24,3:17.1
23,-23,3:17.1
23,-22,3:17.1
23,-21,3:17.1
23,-20,3:17.1
23,-19,3:17.1
23,-18,3:17.1
23,-17,3:17.1
23,-16,3:17.1
23,-15,3:17.1
23,-14,3:17.1
23,-13,3:17.1
23,-12,3:17.1
23,-11,3:17.1
23,-10,3:17.1
23,-9,3:17.1
23,-8,3:17.1
23,-7,3:17.1
23,-6,3:17.1
23,-5,3:17.1
23,-4,3:17.1
23,-3,3:17.1
23,-2,3:17.1
23,-1,3:17.1
23,0,3:17.1
23,1,3:17.1
23,2,3:17.1
23,3,3:17.1
23,4,3:17.1
24,-41,3:17.1
24,-40,3:17.1
24,-39,3:17.1
24,-38,3:17.1
24,-37,3:17.1
24,-36,3:17.1
24,-35,3:17.1
24,-34,3:17.1
24,-33,3:17.1
24,-32,3:17.1
24,-31,3:17.1
24,-30,3:17.1
24,-29,3:17.1
24,-28,3:17.1
24,-27,3:17.1
24,-26,3:17.1
24,-25,3:17.1
24,-24,3:17.1
24,-23,3:17.1
24,-22,3:17.1
24,-21,3:17.1
24,-20,3:17.1
24,-19,3:17.1
24,-18,3:17.1
24,-17,3:17.1
24,-16,3:17.1
24,-15,3:17.1
24,-14,3:17.1
24,-13,3:17.1
24,-12,3:17.1
24,-11,3:17.1
24,-10,3:17.1
24,-9,3:17.1
24,-8,3:17.1
24,-7,3:17.1
24,-6,3:17.1
24,-5,3:17.1
24,-4,3:17.1
24,-3,3:17.1
24,-2,3:17.1
24,-1,3:17.1
24,0,3:17.1
24,1,3:17.1
24,2,3:17.1
24,3,3:17.1
24,4,3:17.1
25,-42,3:17.1
25,-41,3:17.1
25,-40,3:17.1
25,-39,3:17.1
25,-38,3:17.1
25,-37,3:17.1
25,-36,3:17.1
25,-35,3:17.1
25,-34,3:17.1
25,-33,3:17.1
25,-32,3:17.1
25,-31,3:17.1
25,-30,3:17.1
25,-29,3:17.1
25,-28,3:17.1
25,-27,3:17.1
25,-26,3:17.1
25,-25,3:17.1
25,-24,3:17.1
25,-23,3:17.1
25,-22,3:17.1
25,-21,3:17.1
25,-20,3:17.1
25,-19,3:17.1
25,-18,3:17.1
25,-17,3:17.1
25,-16,3:17.1
25,-15,3:17.1
25,-14,3:17.1
25,-13,3:17.1
25,-12,3:17.1
25,-11,3:17.1
25,-10,3:17.1
25,-9,3:17.1
25,-8,3:17.1
25,-7,3:17.1
25,-6,3:17.1
25,-5,3:17.1
25,-4,3:17.1
25,-3,3:17.1
25,-2,3:17.1
25,-1,3:17.1
25,0,3:17.1
25,1,3:17.1
25,2,3:17.1
25,3,3:17.1
25,4,3:17.1
26,-42,3:17.1
26,-41,3:17.1
26,-40,3:17.1
26,-39,3:17.1
26,-38,3:17.1
26,-37,3:17.1
26,-36,3:17.1
26,-35,3:17.1
26,-34,3:17.1
26,-33,3:17.1
26,-32,3:17.1
26,-31,3:17.1
26,-30,3:17.1
26,-29,3:17.1
26,-28,3:17.1
26,-27,3:17.1
26,-26,3:17.1
26,-25,3:17.1
26,-24,3:17.1
26,-23,3:17.1
26,-22,3:17.1
26,-21,3:17.1
26,-20,3:17.1
26,-19,3:17.1
26,-18,3:17.1
26,-17,3:17.1
26,-16,3:17.1
26,-15,3:17.1
26,-14,3:17.1
26,-13,3:17.1
26,-12,3:17.1
26,-11,3:17.1
26,-10,3:17.1
26,-9,3:17.1
26,-8,3:17.1
26,-7,3:17.1
26,-6,3:17.1
26,-5,3:17.1
26,-4,3:17.1
26,-3,3:17.1
26,-2,3:17.1
26,-1,3:17.1
26,0,3:17.1
26,1,3:17.1
26,2,3:17.1
26,3,3:17.1
26,4,3:17.1
27,-42,3:17.1
27,-41,3:17.1
27,-40,3:17.1
27,-39,3:17.1
27,-38,3:17.1
27,-37,3:17.1
27,-36,3:17.1
27,-35,3:17.1
27,-34,3:17.1
27,-33,3:17.1
27,-32,3:17.1
27,-31,3:17.1
27,-30,3:17.1
27,-29,3:17.1
27,-28,3:17.1
27,-27,3:17.1
27,-26,3:17.1
27,-25,3:17.1
27,-24,3:17.1
27,-23,3:17.1
27,-22,3:17.1
27,-21,3:17.1
27,-20,3:17.1
27,-19,3:17.1
27,-18,3:17.1
27,-17,3:17.1
27,-16,3:17.1
27,-15,3:17.1
27,-14,3:17.1
27,-13,3:17.1
27,-12,3:17.1
27,-11,3:17.1
27,-10,3:17.1
27,-9,3:17.1
27,-8,3:17.1
27,-7,3:17.1
27,-6,3:17.1
27,-5,3:17.1
27,-4,3:17.1
27,-3,3:17.1
27,-2,3:17.1
27,-1,3:17.1
27,0,3:17.1
27,1,3:17.1
27,2,3:17.1
27,3,3:17.1
27,4,3:17.1
28,-42,3:17.1
28,-41,3:17.1
28,-40,3:17.1
28,-39,3:17.1
28,-38,3:17.1
28,-37,3:17.1
28,-36,3:17.1
28,-35,3:17.1
28,-34,3:17.1
28,-33,3:17.1
28,-32,3:17.1
28,-31,3:17.1
28,-30,3:17.1
28,-29,3:17.1
28,-28,3:17.1
28,-27,3:17.1
28,-26,3:17.1
28,-25,3:17.1
28,-24,3:17.1
28,-23,3:17.1
28,-22,3:17.1
28,-21,3:17.1
28,-20,3:17.1
28,-19,3:17.1
28,-18,3:17.1
28,-17,3:17.1
28,-16,3:17.1
28,-15,3:17.1
28,-14,3:17.1
28,-13,3:17.1
28,-12,3:17.1
28,-11,3:17.1
28,-10,3:17.1
28,-9,3:17.1
28,-8,3:17.1
28,-7,3:17.1
28,-6,3:17.1
28,-5,3:17.1
28,-4,3:17.1
28,-3,3:17.1
28,-2,3:17.1
28,-1,3:17.1
28,0,3:17.1
28,1,3:17.1
28,2,3:17.1
28,3,3:17.1
29,-42,3:17.1
29,-41,3:17.1
29,-40,3:17.1
29,-39,3:17.1
29,-38,3:17.1
29,-37,3:17.1
29,-36,3:17.1
29,-35,3:17.1
29,-34,3:17.1
29,-33,3:17.1
29,-32,3:17.1
29,-31,3:17.1
29,-30,3:17.1
29,-29,3:17.1
29,-28,3:17.1
29,-27,3:17.1
29,-26,3:17.1
29,-25,3:17.1
29,-24,3:17.1
29,-23,3:17.1
29,-22,3:17.1
29,-21,3:17.1
29,-20,3:17.1
29,-19,3:17.1
29,-18,3:17.1
29,-17,3:17.1
29,-16,3:17.1
29,-15,3:17.1
29,-14,3:17.1
29,-13,3:17.1
29,-12,3:17.1
29,-11,3:17.1
29,-10,3:17.1
29,-9,3:17.1
29,-8,3:17.1
29,-7,3:17.1
29,-6,3:17.1
29,-5,3:17.1
29,-4,3:17.1
29,-3,3:17.1
29,-2,3:17.1
29,-1,3:17.1
29,0,3:17.1
29,1,3:17.1
29,2,3:17.1
29,3,3:17.1
30,-41,3:17.1
30,-40,3:17.1
30,-39,3:17.1
30,-38,3:17.1
30,-37,3:17.1
30,-36,3:17.1
30,-35,3:17.1
30,-34,3:17.1
30,-33,3:17.1
30,-32,3:17.1
30,-31,3:17.1
30,-30,3:17.1
30,-29,3:17.1
30,-28,3:17.1
30,-27,3:17.1
30,-26,3:17.1
30,-25,3:17.1
30,-24,3:17.1
30,-23,3:17.1
30,-22,3:17.1
30,-21,3:17.1
30,-20,3:17.1
30,-19,3:17.1
30,-18,3:17.1
30,-17,3:17.1
30,-16,3:17.1
30,-15,3:17.1
30,-14,3:17.1
30,-13,3:17.1
30,-12,3:17.1
30,-11,3:17.1
30,-10,3:17.1
30,-9,3:17.1
30,-8,3:17.1
30,-7,3:17.1
30,-6,3:17.1
30,-5,3:17.1
30,-4,3:17.1
30,-3,3:17.1
30,-2,3:17.1
30,-1,3:17.1
30,0,3:17.1
30,1,3:17.1
30,2,3:17.1
30,3,3:17.1
31,-40,3:17.1
31,-39,3:17.1
31,-38,3:17.1
31,-37,3:17.1
31,-36,3:17.1
31,-35,3:17.1
31,-34,3:17.1
31,-33,3:17.1
31,-32,3:17.1
31,-31,3:17.1
31,-30,3:17.1
31,-29,3:17.1
31,-28,3:17.1
31,-27,3:17.1
31,-26,3:17.1
31,-25,3:17.1
31,-24,3:17.1
31,-23,3:17.1
31,-22,3:17.1
31,-21,3:17.1
31,-20,3:17.1
31,-19,3:17.1
31,-18,3:17.1
31,-17,3:17.1
31,-16,3:17.1
31,-15,3:17.1
31,-14,3:17.1
31,-13,3:17.1
31,-12,3:17.1
31,-11,3:17.1
31,-10,3:17.1
31,-9,3:17.1
31,-8,3:17.1
31,-7,3:17.1
31,-6,3:17.1
31,-5,3:17.1
31,-4,3:17.1
31,-3,3:17.1
31,-2,3:17.1
31,-1,3:17.1
31,0,3:17.1
31,1,3:17.1
31,2,3:17.1
31,3,3:17.1
32,-40,3:17.1
32,-39,3:17.1
32,-38,3:17.1
32,-37,3:17.1
32,-36,3:17.1
32,-35,3:17.1
32,-34,3:17.1
32,-33,3:17.1
32,-32,3:17.1
32,-31,3:17.1
32,-30,3:17.1
32,-29,3:17.1
32,-28,3:17.1
32,-27,3:17.1
32,-26,3:17.1
32,-25,3:17.1
32,-24,3:17.1
32,-23,3:17.1
32,-22,3:17.1
32,-21,3:17.1
32,-20,3:17.1
32,-19,3:17.1
32,-18,3:17.1
32,-17,3:17.1
32,-16,3:17.1
32,-15,3:17.1
32,-14,3:17.1
32,-13,3:17.1
32,-12,3:17.1
32,-11,3:17.1
32,-10,3:17.1
32,-9,3:17.1
32,-8,3:17.1
32,-7,3:17.1
32,-6,3:17.1
32,-5,3:17.1
32,-4,3:17.1
32,-3,3:17.1
32,-2,3:17.1
32,-1,3:17.1
32,0,3:17.1
32,1,3:17.1
32,2,3:17.1
33,-39,3:17.1
33,-38,3:17.1
33,-37,3:17.1
33,-36,3:17.1
33,-35,3:17.1
33,-34,3:17.1
33,-33,3:17.1
33,-32,3:17.1
33,-31,3:17.1
33,-30,3:17.1
33,-29,3:17.1
33,-28,3:17.1
33,-27,3:17.1
33,-26,3:17.1
33,-25,3:17.1
33,-24,3:17.1
33,-23,3:17.1
33,-22,3:17.1
33,-21,3:17.1
33,-20,3:17.1
33,-19,3:17.1
33,-18,3:17.1
33,-17,3:17.1
33,-16,3:17.1
33,-15,3:17.1
33,-14,3:17.1
33,-13,3:17.1
33,-12,3:17.1
33,-11,3:17.1
33,-10,3:17.1
33,-9,3:17.1
33,-8,3:17.1
33,-7,3:17.1
33,-6,3:17.1
33,-5,3:17.1
33,-4,3:17.1
33,-3,3:17.1
33,-2,3:17.1
33,-1,3:17.1
33,0,3:17.1
33,1,3:17.1
33,2,3:17.1
34,-39,3:17.1
34,-38,3:17.1
34,-37,3:17.1
34,-36,3:17.1
34,-35,3:17.1
34,-34,3:17.1
34,-33,3:17.1
34,-32,3:17.1
34,-31,3:17.1
34,-30,3:17.1
34,-29,3:17.1
34,-28,3:17.1
34,-27,3:17.1
34,-26,3:17.1
34,-25,3:17.1
34,-24,3:17.1
34,-23,3:17.1
34,-22,3:17.1
34,-21,3:17.1
34,-20,3:17.1
34,-19,3:17.1
34,-18,3:17.1
34,-17,3:17.1
34,-16,3:17.1
34,-15,3:17.1
34,-14,3:17.1
34,-13,3:17.1
34,-12,3:17.1
34,-11,3:17.1
34,-10,3:17.1
34,-9,3:17.1
34,-8,3:17.1
34,-7,3:17.1
34,-6,3:17.1
34,-5,3:17.1
34,-4,3:17.1
34,-3,3:17.1
34,-2,3:17.1
34,-1,3:17.1
34,0,3:17.1
34,1,3:17.1
34,2,3:17.1
35,-38,3:17.1
35,-37,3:17.1
35,-36,3:17.1
35,-35,3:17.1
35,-34,3:17.1
35,-33,3:17.1
35,-32,3:17.1
35,-31,3:17.1
35,-30,3:17.1
35,-29,3:17.1
35,-28,3:17.1
35,-27,3:17.1
35,-26,3:17.1
35,-25,3:17.1
35,-24,3:17.1
35,-23,3:17.1
35,-22,3:17.1
35,-21,3:17.1
35,-20,3:17.1
35,-19,3:17.1
35,-18,3:17.1
35,-17,3:17.1
35,-16,3:17.1
35,-15,3:17.1
35,-14,3:17.1
35,-13,3:17.1
35,-12,3:17.1
35,-11,3:17.1
35,-10,3:17.1
35,-9,3:17.1
35,-8,3:17.1
35,-7,3:17.1
35,-6,3:17.1
35,-5,3:17.1
35,-4,3:17.1
35,-3,3:17.1
35,-2,3:17.1
35,-1,3:17.1
35,0,3:17.1
35,1,3:17.1
36,-37,3:17.1
36,-36,3:17.1
36,-35,3:17.1
36,-34,3:17.1
36,-33,3:17.1
36,-32,3:17.1
36,-31,3:17.1
36,-30,3:17.1
36,-29,3:17.1
36,-28,3:17.1
36,-27,3:17.1
36,-26,3:17.1
36,-25,3:17.1
36,-24,3:17.1
36,-23,3:17.1
36,-22,3:17.1
36,-21,3:17.1
36,-20,3:17.1
36,-19,3:17.1
36,-18,3:17.1
36,-17,3:17.1
36,-16,3:17.1
36,-15,3:17.1
36,-14,3:17.1
36,-13,3:17.1
36,-12,3:17.1
36,-11,3:17.1
36,-10,3:17.1
36,-9,3:17.1
36,-8,3:17.1
36,-7,3:17.1
36,-6,3:17.1
36,-5,3:17.1
36,-4,3:17.1
36,-3,3:17.1
36,-2,3:17.1
36,-1,3:17.1
36,0,3:17.1
37,-37,3:17.1
37,-36,3:17.1
37,-35,3:17.1
37,-34,3:17.1
37,-33,3:17.1
37,-32,3:17.1
37,-31,3:17.1
37,-30,3:17.1
37,-29,3:17.1
37,-28,3:17.1
37,-27,3:17.1
37,-26,3:17.1
37,-25,3:17.1
37,-24,3:17.1
37,-23,3:17.1
37,-22,3:17.1
37,-21,3:17.1
37,-20,3:17.1
37,-19,3:17.1
37,-18,3:17.1
37,-17,3:17.1
37,-16,3:17.1
37,-15,3:17.1
37,-14,3:17.1
37,-13,3:17.1
37,-12,3:17.1
37,-11,3:17.1
37,-10,3:17.1
37,-9,3:17.1
37,-8,3:17.1
37,-7,3:17.1
37,-6,3:17.1
37,-5,3:17.1
37,-4,3:17.1
37,-3,3:17.1
37,-2,3:17.1
37,-1,3:17.1
37,0,3:17.1
38,-36,3:17.1
38,-35,3:17.1
38,-34,3:17.1
38,-33,3:17.1
38,-32,3:17.1
38,-31,3:17.1
38,-30,3:17.1
38,-29,3:17.1
38,-28,3:17.1
38,-27,3:17.1
38,-26,3:17.1
38,-25,3:17.1
38,-24,3:17.1
38,-23,3:17.1
38,-22,3:17.1
38,-21,3:17.1
38,-20,3:17.1
38,-19,3:17.1
38,-18,3:17.1
38,-17,3:17.1
38,-16,3:17.1
38,-15,3:17.1
38,-14,3:17.1
38,-13,3:17.1
38,-12,3:17.1
38,-11,3:17.1
38,-10,3:17.1
38,-9,3:17.1
38,-8,3:17.1
38,-7,3:17.1
38,-6,3:17.1
38,-5,3:17.1
38,-4,3:17.1
38,-3,3:17.1
38,-2,3:17.1
38,-1,3:17.1
39,-35,3:17.1
39,-34,3:17.1
39,-33,3:17.1
39,-32,3:17.1
39,-31,3:17.1
39,-30,3:17.1
39,-29,3:17.1
39,-28,3:17.1
39,-27,3:17.1
39,-26,3:17.1
39,-25,3:17.1
39,-23,3:17.1
39,-22,3:17.1
39,-21,3:17.1
39,-20,3:17.1
39,-19,3:17.1
39,-18,3:17.1
39,-17,3:17.1
39,-16,3:17.1
39,-15,3:17.1
39,-14,3:17.1
39,-13,3:17.1
39,-12,3:17.1
39,-11,3:17.1
39,-10,3:17.1
39,-9,3:17.1
39,-8,3:17.1
39,-7,3:17.1
39,-6,3:17.1
39,-5,3:17.1
39,-4,3:17.1
39,-3,3:17.1
39,-2,3:17.1
40,-33,3:17.1
40,-32,3:17.1
40,-31,3:17.1
40,-30,3:17.1
40,-29,3:17.1
40,-28,3:17.1
40,-27,3:17.1
40,-23,3:17.1
40,-22,3:17.1
40,-21,3:17.1
40,-20,3:17.1
40,-19,3:17.1
40,-18,3:17.1
40,-17,3:17.1
40,-16,3:17.1
40,-15,3:17.1
40,-14,3:17.1
40,-13,3:17.1
40,-12,3:17.1
40,-11,3:17.1
40,-10,3:17.1
40,-9,3:17.1
40,-8,3:17.1
40,-7,3:17.1
40,-6,3:17.1
40,-5,3:17.1
40,-4,3:17.1
40,-3,3:17.1
40,-2,3:17.1
40,-1,3:17.1
41,-30,3:17.1
41,-23,3:17.1
41,-22,3:17.1
41,-21,3:17.1
41,-20,3:17.1
41,-19,3:17.1
41,-18,3:17.1
41,-17,3:17.1
41,-16,3:17.1
41,-15,3:17.1
41,-14,3:17.1
41,-13,3:17.1
41,-12,3:17.1
41,-11,3:17.1
41,-10,3:17.1
41,-9,3:17.1
41,-8,3:17.1
41,-7,3:17.1
41,-6,3:17.1
41,-5,3:17.1
41,-4,3:17.1
41,-3,3:17.1
41,-2,3:17.1
41,-1,3:17.1
42,-23,3:17.1
42,-22,3:17.1
42,-21,3:17.1
42,-20,3:17.1
42,-19,3:17.1
42,-18,3:17.1
42,-17,3:17.1
42,-16,3:17.1
42,-15,3:17.1
42,-14,3:17.1
42,-13,3:17.1
42,-12,3:17.1
42,-11,3:17.1
42,-10,3:17.1
42,-9,3:17.1
42,-8,3:17.1
42,-7,3:17.1
42,-6,3:17.1
42,-5,3:17.1
42,-4,3:17.1
42,-3,3:17.1
42,-2,3:17.1
42,-1,3:17.1
43,-22,3:17.1
43,-21,3:17.1
43,-20,3:17.1
43,-19,3:17.1
43,-18,3:17.1
43,-17,3:17.1
43,-16,3:17.1
43,-15,3:17.1
43,-14,3:17.1
43,-13,3:17.1
43,-12,3:17.1
43,-11,3:17.1
43,-10,3:17.1
43,-9,3:17.1
43,-8,3:17.1
43,-7,3:17.1
43,-6,3:17.1
43,-5,3:17.1
43,-4,3:17.1
43,-3,3:17.1
43,-2,3:17.1
43,-1,3:17.1
44,-22,3:17.1
44,-21,3:17.1
44,-20,3:17.1
44,-19,3:17.1
44,-18,3:17.1
44,-17,3:17.1
44,-16,3:17.1
44,-15,3:17.1
44,-14,3:17.1
44,-13,3:17.1
44,-12,3:17.1
44,-11,3:17.1
44,-10,3:17.1
44,-9,3:17.1
44,-8,3:17.1
44,-7,3:17.1
44,-6,3:17.1
44,-5,3:17.1
44,-4,3:17.1
44,-3,3:17.1
44,-2,3:17.1
44,-1,3:17.1
45,-21,3:17.1
45,-20,3:17.1
45,-19,3:17.1
45,-18,3:17.1
45,-17,3:17.1
45,-16,3:17.1
45,-15,3:17.1
45,-14,3:17.1
45,-13,3:17.1
45,-12,3:17.1
45,-11,3:17.1
45,-10,3:17.1
45,-9,3:17.1
45,-8,3:17.1
45,-7,3:17.1
45,-6,3:17.1
45,-5,3:17.1
45,-4,3:17.1
45,-3,3:17.1
45,-2,3:17.1
45,-1,3:17.1
46,-21,3:17.1
46,-20,3:17.1
46,-19,3:17.1
46,-18,3:17.1
46,-17,3:17.1
46,-16,3:17.1
46,-15,3:17.1
46,-14,3:17.1
46,-13,3:17.1
46,-12,3:17.1
46,-11,3:17.1
46,-10,3:17.1
46,-9,3:17.1
46,-8,3:17.1
46,-7,3:17.1
46,-6,3:17.1
46,-5,3:17.1
46,-4,3:17.1
46,-3,3:17.1
46,-2,3:17.1
47,-20,3:17.1
47,-19,3:17.1
47,-18,3:17.1
47,-17,3:17.1
47,-16,3:17.1
47,-15,3:17.1
47,-14,3:17.1
47,-13,3:17.1
47,-12,3:17.1
47,-11,3:17.1
47,-10,3:17.1
47,-9,3:17.1
47,-8,3:17.1
47,-7,3:17.1
47,-6,3:17.1
47,-5,3:17.1
47,-4,3:17.1
47,-3,3:17.1
47,-2,3:17.1
48,-19,3:17.1
48,-18,3:17.1
48,-17,3:17.1
48,-16,3:17.1
48,-15,3:17.1
48,-14,3:17.1
48,-13,3:17.1
48,-12,3:17.1
48,-11,3:17.1
48,-10,3:17.1
48,-9,3:17.1
48,-8,3:17.1
48,-7,3:17.1
48,-6,3:17.1
48,-5,3:17.1
48,-4,3:17.1
48,-3,3:17.1
49,-17,3:17.1
49,-16,3:17.1
49,-15,3:17.1
49,-14,3:17.1
49,-13,3:17.1
49,-12,3:17.1
49,-11,3:17.1
49,-10,3:17.1
49,-9,3:17.1
49,-8,3:17.1
49,-7,3:17.1
49,-6,3:17.1
49,-5,3:17.1
49,-4,3:17.1
50,-11,3:17.1
50,-10,3:17.1
50,-9,3:17.1
50,-8,3:17.1
50,-7,3:17.1
50,-6,3:17.1
4,-21,4:17.1
4,-20,4:17.1
4,-19,4:17.1
4,-12,4:17.1
4,-11,4:17.1
4,-10,4:17.1
4,-9,4:17.1
4,-8,4:17.1
5,-23,4:17.1
5,-22,4:17.1
5,-21,4:17.1
5,-20,4:17.1
5,-19,4:17.1
5,-18,4:17.1
5,-17,4:17.1
5,-14,4:17.1
5,-13,4:17.1
5,-12,4:17.1
5,-11,4:17.1
5,-10,4:17.1
5,-9,4:17.1
5,-8,4:17.1
5,-7,4:17.1
5,-6,4:17.1
6,-24,4:17.1
6,-23,4:17.1
6,-22,4:17.1
6,-21,4:17.1
6,-20,4:17.1
6,-19,4:17.1
6,-18,4:17.1
6,-17,4:17.1
6,-16,4:17.1
6,-14,4:17.1
6,-13,4:17.1
6,-12,4:17.1
6,-11,4:17.1
6,-10,4:17.1
6,-9,4:17.1
6,-8,4:17.1
6,-7,4:17.1
6,-6,4:17.1
7,-24,4:17.1
7,-23,4:17.1
7,-22,4:17.1
7,-21,4:17.1
7,-20,4:17.1
7,-19,4:17.1
7,-18,4:17.1
7,-17,4:17.1
7,-16,4:17.1
7,-15,4:17.1
7,-14,4:17.1
7,-13,4:17.1
7,-12,4:17.1
7,-11,4:17.1
7,-10,4:17.1
7,-9,4:17.1
7,-8,4:17.1
7,-7,4:17.1
7,-6,4:17.1
7,-5,4:17.1
8,-25,4:17.1
8,-24,4:17.1
8,-23,4:17.1
8,-22,4:17.1
8,-21,4:17.1
8,-20,4:17.1
8,-19,4:17.1
8,-18,4:17.1
8,-17,4:17.1
8,-16,4:17.1
8,-15,4:17.1
8,-14,4:17.1
8,-13,4:17.1
8,-12,4:17.1
8,-11,4:17.1
8,-10,4:17.1
8,-9,4:17.1
8,-8,4:17.1
8,-7,4:17.1
8,-6,4:17.1
8,-5,4:17.1
9,-28,4:17.1
9,-27,4:17.1
9,-26,4:17.1
9,-25,4:17.1
9,-24,4:17.1
9,-23,4:17.1
9,-22,4:17.1
9,-21,4:17.1
9,-20,4:17.1
9,-19,4:17.1
9,-18,4:17.1
9,-17,4:17.1
9,-16,4:17.1
9,-15,4:17.1
9,-14,4:17.1
9,-13,4:17.1
9,-12,4:17.1
9,-11,4:17.1
9,-10,4:17.1
9,-9,4:17.1
9,-8,4:17.1
9,-7,4:17.1
9,-6,4:17.1
9,-5,4:17.1
10,-30,4:17.1
10,-29,4:17.1
10,-28,4:17.1
10,-27,4:17.1
10,-26,4:17.1
10,-25,4:17.1
10,-24,4:17.1
10,-23,4:17.1
10,-22,4:17.1
10,-21,4:17.1
10,-20,4:17.1
10,-19,4:17.1
10,-18,4:17.1
10,-17,4:17.1
10,-16,4:17.1
10,-15,4:17.1
10,-14,4:17.1
10,-13,4:17.1
10,-12,4:17.1
10,-11,4:17.1
10,-10,4:17.1
10,-9,4:17.1
10,-8,4:17.1
10,-7,4:17.1
10,-6,4:17.1
10,-5,4:17.1
11,-30,4:17.1
11,-29,4:17.1
11,-28,4:17.1
11,-27,4:17.1
11,-26,4:17.1
11,-25,4:17.1
11,-24,4:17.1
11,-23,4:17.1
11,-22,4:17.1
11,-21,4:17.1
11,-20,4:17.1
11,-19,4:17.1
11,-18,4:17.1
11,-17,4:17.1
11,-16,4:17.1
11,-15,4:17.1
11,-14,4:17.1
11,-13,4:17.1
11,-12,4:17.1
11,-11,4:17.1
11,-10,4:17.1
11,-9,4:17.1
11,-8,4:17.1
11,-7,4:17.1
11,-6,4:17.1
11,-5,4:17.1
12,-31,4:17.1
12,-30,4:17.1
12,-29,4:17.1
12,-28,4:17.1
12,-27,4:17.1
12,-26,4:17.1
12,-25,4:17.1
12,-24,4:17.1
12,-23,4:17.1
12,-22,4:17.1
12,-21,4:17.1
12,-20,4:17.1
12,-19,4:17.1
12,-18,4:17.1
12,-17,4:17.1
12,-16,4:17.1
12,-15,4:17.1
12,-14,4:17.1
12,-13,4:17.1
12,-12,4:17.1
12,-11,4:17.1
12,-10,4:17.1
12,-9,4:17.1
12,-8,4:17.1
12,-7,4:17.1
12,-6,4:17.1
13,-31,4:17.1
13,-30,4:17.1
13,-29,4:17.1
13,-28,4:17.1
13,-27,4:17.1
13,-26,4:17.1
13,-25,4:17.1
13,-24,4:17.1
13,-23,4:17.1
13,-22,4:17.1
13,-21,4:17.1
13,-20,4:17.1
13,-19,4:17.1
13,-18,4:17.1
13,-17,4:17.1
13,-16,4:17.1
13,-15,4:17.1
13,-14,4:17.1
13,-13,4:17.1
13,-12,4:17.1
13,-11,4:17.1
13,-10,4:17.1
13,-9,4:17.1
13,-8,4:17.1
13,-7,4:17.1
13,-6,4:17.1
13,-5,4:17.1
14,-31,4:17.1
14,-30,4:17.1
14,-29,4:17.1
14,-28,4:17.1
14,-27,4:17.1
14,-26,4:17.1
14,-25,4:17.1
14,-24,4:17.1
14,-23,4:17.1
14,-22,4:17.1
14,-21,4:17.1
14,-20,4:17.1
14,-19,4:17.1
14,-18,4:17.1
14,-17,4:17.1
14,-16,4:17.1
14,-15,4:17.1
14,-14,4:17.1
14,-13,4:17.1
14,-12,4:17.1
14,-11,4:17.1
14,-10,4:17.1
14,-9,4:17.1
14,-8,4:17.1
14,-7,4:17.1
14,-6,4:17.1
14,-5,4:17.1
14,-4,4:17.1
15,-31,4:17.1
15,-30,4:17.1
15,-29,4:17.1
15,-28,4:17.1
15,-27,4:17.1
15,-26,4:17.1
15,-25,4:17.1
15,-24,4:17.1
15,-23,4:17.1
15,-22,4:17.1
15,-21,4:17.1
15,-20,4:17.1
15,-19,4:17.1
15,-18,4:17.1
15,-17,4:17.1
15,-16,4:17.1
15,-15,4:17.1
15,-14,4:17.1
15,-13,4:17.1
15,-12,4:17.1
15,-11,4:17.1
15,-10,4:17.1
15,-9,4:17.1
15,-8,4:17.1
15,-7,4:17.1
15,-6,4:17.1
15,-5,4:17.1
15,-4,4:17.1
15,-3,4:17.1
16,-31,4:17.1
16,-30,4:17.1
16,-29,4:17.1
16,-28,4:17.1
16,-27,4:17.1
16,-26,4:17.1
16,-25,4:17.1
16,-24,4:17.1
16,-23,4:17.1
16,-22,4:17.1
16,-21,4:17.1
16,-20,4:17.1
16,-19,4:17.1
16,-18,4:17.1
16,-17,4:17.1
16,-16,4:17.1
16,-15,4:17.1
16,-14,4:17.1
16,-13,4:17.1
16,-12,4:17.1
16,-11,4:17.1
16,-10,4:17.1
16,-9,4:17.1
16,-8,4:17.1
16,-7,4:17.1
16,-6,4:17.1
16,-5,4:17.1
16,-4,4:17.1
16,-3,4:17.1
16,-2,4:17.1
16,-1,4:17.1
17,-32,4:17.1
17,-31,4:17.1
17,-30,4:17.1
17,-29,4:17.1
17,-28,4:17.1
17,-27,4:17.1
17,-26,4:17.1
17,-25,4:17.1
17,-24,4:17.1
17,-23,4:17.1
17,-22,4:17.1
17,-21,4:17.1
17,-20,4:17.1
17,-19,4:17.1
17,-18,4:17.1
17,-17,4:17.1
17,-16,4:17.1
17,-15,4:17.1
17,-14,4:17.1
17,-13,4:17.1
17,-12,4:17.1
17,-11,4:17.1
17,-10,4:17.1
17,-9,4:17.1
17,-8,4:17.1
17,-7,4:17.1
17,-6,4:17.1
17,-5,4:17.1
17,-4,4:17.1
17,-3,4:17.1
17,-2,4:17.1
17,-1,4:17.1
17,0,4:17.1
18,-35,4:17.1
18,-32,4:17.1
18,-31,4:17.1
18,-30,4:17.1
18,-29,4:17.1
18,-28,4:17.1
18,-27,4:17.1
18,-26,4:17.1
18,-25,4:17.1
18,-24,4:17.1
18,-23,4:17.1
18,-22,4:17.1
18,-21,4:17.1
18,-20,4:17.1
18,-19,4:17.1
18,-18,4:17.1
18,-17,4:17.1
18,-16,4:17.1
18,-15,4:17.1
18,-14,4:17.1
18,-13,4:17.1
18,-12,4:17.1
18,-11,4:17.1
18,-10,4:17.1
18,-9,4:17.1
18,-8,4:17.1
18,-7,4:17.1
18,-6,4:17.1
18,-5,4:17.1
18,-4,4:17.1
18,-3,4:17.1
18,-2,4:17.1
18,-1,4:17.1
18,0,4:17.1
18,1,4:17.1
19,-38,4:17.1
19,-37,4:17.1
19,-36,4:17.1
19,-35,4:17.1
19,-34,4:17.1
19,-33,4:17.1
19,-32,4:17.1
19,-31,4:17.1
19,-30,4:17.1
19,-29,4:17.1
19,-28,4:17.1
19,-27,4:17.1
19,-26,4:17.1
19,-25,4:17.1
19,-24,4:17.1
19,-23,4:17.1
19,-22,4:17.1
19,-21,4:17.1
19,-20,4:17.1
19,-19,4:17.1
19,-18,4:17.1
19,-17,4:17.1
19,-16,4:17.1
19,-15,4:17.1
19,-14,4:17.1
19,-13,4:17.1
19,-12,4:17.1
19,-11,4:17.1
19,-10,4:17.1
19,-9,4:17.1
19,-8,4:17.1
19,-7,4:17.1
19,-6,4:17.1
19,-5,4:17.1
19,-4,4:17.1
19,-3,4:17.1
19,-2,4:17.1
19,-1,4:17.1
19,0,4:17.1
19,1,4:17.1
19,2,4:17.1
20,-39,4:17.1
20,-38,4:17.1
20,-37,4:17.1
20,-36,4:17.1
20,-35,4:17.1
20,-34,4:17.1
20,-33,4:17.1
20,-32,4:17.1
20,-31,4:17.1
20,-30,4:17.1
20,-29,4:17.1
20,-28,4:17.1
20,-27,4:17.1
20,-26,4:17.1
20,-25,4:17.1
20,-24,4:17.1
20,-23,4:17.1
20,-22,4:17.1
20,-21,4:17.1
20,-20,4:17.1
20,-19,4:17.1
20,-18,4:17.1
20,-17,4:17.1
20,-16,4:17.1
20,-15,4:17.1
20,-14,4:17.1
20,-13,4:17.1
20,-12,4:17.1
20,-11,4:17.1
20,-10,4:17.1
20,-9,4:17.1
20,-8,4:17.1
20,-7,4:17.1
20,-6,4:17.1
20,-5,4:17.1
20,-4,4:17.1
20,-3,4:17.1
20,-2,4:17.1
20,-1,4:17.1
20,0,4:17.1
20,1,4:17.1
20,2,4:17.1
20,3,4:17.1
21,-40,4:17.1
21,-39,4:17.1
21,-38,4:17.1
21,-37,4:17.1
21,-36,4:17.1
21,-35,4:17.1
21,-34,4:17.1
21,-33,4:17.1
21,-32,4:17.1
21,-31,4:17.1
21,-30,4:17.1
21,-29,4:17.1
21,-28,4:17.1
21,-27,4:17.1
21,-26,4:17.1
21,-25,4:17.1
21,-24,4:17.1
21,-23,4:17.1
21,-22,4:17.1
21,-21,4:17.1
21,-20,4:17.1
21,-19,4:17.1
21,-18,4:17.1
21,-17,4:17.1
21,-16,4:17.1
21,-15,4:17.1
21,-14,4:17.1
21,-13,4:17.1
21,-12,4:17.1
21,-11,4:17.1
21,-10,4:17.1
21,-9,4:17.1
21,-8,4:17.1
21,-7,4:17.1
21,-6,4:17.1
21,-5,4:17.1
21,-4,4:17.1
21,-3,4:17.1
21,-2,4:17.1
21,-1,4:17.1
21,0,4:17.1
21,1,4:17.1
21,2,4:17.1
21,3,4:17.1
22,-41,4:17.1
22,-40,4:17.1
22,-39,4:17.1
22,-38,4:17.1
22,-37,4:17.1
22,-36,4:17.1
22,-35,4:17.1
22,-34,4:17.1
22,-33,4:17.1
22,-32,4:17.1
22,-31,4:17.1
22,-30,4:17.1
22,-29,4:17.1
22,-28,4:17.1
22,-27,4:17.1
22,-26,4:17.1
22,-25,4:17.1
22,-24,4:17.1
22,-23,4:17.1
22,-22,4:17.1
22,-21,4:17.1
22,-20,4:17.1
22,-19,4:17.1
22,-18,4:17.1
22,-17,4:17.1
22,-16,4:17.1
22,-15,4:17.1
22,-14,4:17.1
22,-13,4:17.1
22,-12,4:17.1
22,-11,4:17.1
22,-10,4:17.1
22,-9,4:17.1
22,-8,4:17.1
22,-7,4:17.1
22,-6,4:17.1
22,-5,4:17.1
22,-4,4:17.1
22,-3,4:17.1
22,-2,4:17.1
22,-1,4:17.1
22,0,4:17.1
22,1,4:17.1
22,2,4:17.1
22,3,4:17.1
22,4,4:17.1
23,-41,4:17.1
23,-40,4:17.1
23,-39,4:17.1
23,-38,4:17.1
23,-37,4:17.1
23,-36,4:17.1
23,-35,4:17.1
23,-34,4:17.1
23,-33,4:17.1
23,-32,4:17.1
23,-31,4:17.1
23,-30,4:17.1
23,-29,4:17.1
23,-28,4:17.1
23,-27,4:17.1
23,-26,4:17.1
23,-25,4:17.1
23,-24,4:17.1
23,-23,4:17.1
23,-22,4:17.1
23,-21,4:17.1
23,-20,4:17.1
23,-19,4:17.1
23,-18,4:17.1
23,-17,4:17.1
23,-16,4:17.1
23,-15,4:17.1
23,-14,4:17.1
23,-13,4:17.1
23,-12,4:17.1
23,-11,4:17.1
23,-10,4:17.1
23,-9,4:17.1
23,-8,4:17.1
23,-7,4:17.1
23,-6,4:17.1
23,-5,4:17.1
23,-4,4:17.1
23,-3,4:17.1
23,-2,4:17.1
23,-1,4:17.1
23,0,4:17.1
23,1,4:17.1
23,2,4:17.1
23,3,4:17.1
23,4,4:17.1
24,-41,4:17.1
24,-40,4:17.1
24,-39,4:17.1
24,-38,4:17.1
24,-37,4:17.1
24,-36,4:17.1
24,-35,4:17.1
24,-34,4:17.1
24,-33,4:17.1
24,-32,4:17.1
24,-31,4:17.1
24,-30,4:17.1
24,-29,4:17.1
24,-28,4:17.1
24,-27,4:17.1
24,-26,4:17.1
24,-25,4:17.1
24,-24,4:17.1
24,-23,4:17.1
24,-22,4:17.1
24,-21,4:17.1
24,-20,4:17.1
24,-19,4:17.1
24,-18,4:17.1
24,-17,4:17.1
24,-16,4:17.1
24,-15,4:17.1
24,-14,4:17.1
24,-13,4:17.1
24,-12,4:17.1
24,-11,4:17.1
24,-10,4:17.1
24,-9,4:17.1
24,-8,4:17.1
24,-7,4:17.1
24,-6,4:17.1
24,-5,4:17.1
24,-4,4:17.1
24,-3,4:17.1
24,-2,4:17.1
24,-1,4:17.1
24,0,4:17.1
24,1,4:17.1
24,2,4:17.1
24,3,4:17.1
24,4,4:17.1
25,-42,4:17.1
25,-41,4:17.1
25,-40,4:17.1
25,-39,4:17.1
25,-38,4:17.1
25,-37,4:17.1
25,-36,4:17.1
25,-35,4:17.1
25,-34,4:17.1
25,-33,4:17.1
25,-32,4:17.1
25,-31,4:17.1
25,-30,4:17.1
25,-29,4:17.1
25,-28,4:17.1
25,-27,4:17.1
25,-26,4:17.1
25,-25,4:17.1
25,-24,4:17.1
25,-23,4:17.1
25,-22,4:17.1
25,-21,4:17.1
25,-20,4:17.1
25,-19,4:17.1
25,-18,4:17.1
25,-17,4:17.1
25,-16,4:17.1
25,-15,4:17.1
25,-14,4:17.1
25,-13,4:17.1
25,-12,4:17.1
25,-11,4:17.1
25,-10,4:17.1
25,-9,4:17.1
25,-8,4:17.1
25,-7,4:17.1
25,-6,4:17.1
25,-5,4:17.1
25,-4,4:17.1
25,-3,4:17.1
25,-2,4:17.1
25,-1,4:17.1
25,0,4:17.1
25,1,4:17.1
25,2,4:17.1
25,3,4:17.1
25,4,4:17.1
26,-41,4:17.1
26,-40,4:17.1
26,-39,4:17.1
26,-38,4:17.1
26,-37,4:17.1
26,-36,4:17.1
26,-35,4:17.1
26,-34,4:17.1
26,-33,4:17.1
26,-32,4:17.1
26,-31,4:17.1
26,-30,4:17.1
26,-29,4:17.1
26,-28,4:17.1
26,-27,4:17.1
26,-26,4:17.1
26,-25,4:17.1
26,-24,4:17.1
26,-23,4:17.1
26,-22,4:17.1
26,-21,4:17.1
26,-20,4:17.1
26,-19,4:17.1
26,-18,4:17.1
26,-17,4:17.1
26,-16,4:17.1
26,-15,4:17.1
26,-14,4:17.1
26,-13,4:17.1
26,-12,4:17.1
26,-11,4:17.1
26,-10,4:17.1
26,-9,4:17.1
26,-8,4:17.1
26,-7,4:17.1
26,-6,4:17.1
26,-5,4:17.1
26,-4,4:17.1
26,-3,4:17.1
26,-2,4:17.1
26,-1,4:17.1
26,0,4:17.1
26,1,4:17.1
26,2,4:17.1
26,3,4:17.1
26,4,4:17.1
27,-41,4:17.1
27,-40,4:17.1
27,-39,4:17.1
27,-38,4:17.1
27,-37,4:17.1
27,-36,4:17.1
27,-35,4:17.1
27,-34,4:17.1
27,-33,4:17.1
27,-32,4:17.1
27,-31,4:17.1
27,-30,4:17.1
27,-29,4:17.1
27,-28,4:17.1
27,-27,4:17.1
27,-26,4:17.1
27,-25,4:17.1
27,-24,4:17.1
27,-23,4:17.1
27,-22,4:17.1
27,-21,4:17.1
27,-20,4:17.1
27,-19,4:17.1
27,-18,4:17.1
27,-17,4:17.1
27,-16,4:17.1
27,-15,4:17.1
27,-14,4:17.1
27,-13,4:17.1
27,-12,4:17.1
27,-11,4:17.1
27,-10,4:17.1
27,-9,4:17.1
27,-8,4:17.1
27,-7,4:17.1
27,-6,4:17.1
27,-5,4:17.1
27,-4,4:17.1
27,-3,4:17.1
27,-2,4:17.1
27,-1,4:17.1
27,0,4:17.1
27,1,4:17.1
27,2,4:17.1
27,3,4:17.1
27,4,4:17.1
28,-41,4:17.1
28,-40,4:17.1
28,-39,4:17.1
28,-38,4:17.1
28,-37,4:17.1
28,-36,4:17.1
28,-35,4:17.1
28,-34,4:17.1
28,-33,4:17.1
28,-32,4:17.1
28,-31,4:17.1
28,-30,4:17.1
28,-29,4:17.1
28,-28,4:17.1
28,-27,4:17.1
28,-26,4:17.1
28,-25,4:17.1
28,-24,4:17.1
28,-23,4:17.1
28,-22,4:17.1
28,-21,4:17.1
28,-20,4:17.1
28,-19,4:17.1
28,-18,4:17.1
28,-17,4:17.1
28,-16,4:17.1
28,-15,4:17.1
28,-14,4:17.1
28,-13,4:17.1
28,-12,4:17.1
28,-11,4:17.1
28,-10,4:17.1
28,-9,4:17.1
28,-8,4:17.1
28,-7,4:17.1
28,-6,4:17.1
28,-5,4:17.1
28,-4,4:17.1
28,-3,4:17.1
28,-2,4:17.1
28,-1,4:17.1
28,0,4:17.1
28,1,4:17.1
28,2,4:17.1
28,3,4:17.1
28,4,4:17.1
29,-41,4:17.1
29,-40,4:17.1
29,-39,4:17.1
29,-38,4:17.1
29,-37,4:17.1
29,-36,4:17.1
29,-35,4:17.1
29,-34,4:17.1
29,-33,4:17.1
29,-32,4:17.1
29,-31,4:17.1
29,-30,4:17.1
29,-29,4:17.1
29,-28,4:17.1
29,-27,4:17.1
29,-26,4:17.1
29,-25,4:17.1
29,-24,4:17.1
29,-23,4:17.1
29,-22,4:17.1
29,-21,4:17.1
29,-20,4:17.1
29,-19,4:17.1
29,-18,4:17.1
29,-17,4:17.1
29,-16,4:17.1
29,-15,4:17.1
29,-14,4:17.1
29,-13,4:17.1
29,-12,4:17.1
29,-11,4:17.1
29,-10,4:17.1
29,-9,4:17.1
29,-8,4:17.1
29,-7,4:17.1
29,-6,4:17.1
29,-5,4:17.1
29,-4,4:17.1
29,-3,4:17.1
29,-2,4:17.1
29,-1,4:17.1
29,0,4:17.1
29,1,4:17.1
29,2,4:17.1
29,3,4:17.1
30,-40,4:17.1
30,-39,4:17.1
30,-38,4:17.1
30,-37,4:17.1
30,-36,4:17.1
30,-35,4:17.1
30,-34,4:17.1
30,-33,4:17.1
30,-32,4:17.1
30,-31,4:17.1
30,-30,4:17.1
30,-29,4:17.1
30,-28,4:17.1
30,-27,4:17.1
30,-26,4:17.1
30,-25,4:17.1
30,-24,4:17.1
30,-23,4:17.1
30,-22,4:17.1
30,-21,4:17.1
30,-20,4:17.1
30,-19,4:17.1
30,-18,4:17.1
30,-17,4:17.1
30,-16,4:17.1
30,-15,4:17.1
30,-14,4:17.1
30,-13,4:17.1
30,-12,4:17.1
30,-11,4:17.1
30,-10,4:17.1
30,-9,4:17.1
30,-8,4:17.1
30,-7,4:17.1
30,-6,4:17.1
30,-5,4:17.1
30,-4,4:17.1
30,-3,4:17.1
30,-2,4:17.1
30,-1,4:17.1
30,0,4:17.1
30,1,4:17.1
30,2,4:17.1
30,3,4:17.1
31,-40,4:17.1
31,-39,4:17.1
