[META]
version=2.0
spawnOnBlockType=1,2,3,12,13
spawnSunlight=True
spawnDarkness=True
spawnWater=False
spawnLava=False
underFill=True
randomRotation=True
dig=True
tree=False
branch=False
needsFoundation=True
rarity=1000
collisionPercentage=100
spawnElevationMin=0
spawnElevationMax=250
spawnInBiome=TallForest
[DATA]
-35,5,0:17.0
-35,6,0:17.0
-35,7,0:17.0
-34,5,0:17.0
-34,6,0:17.0
-34,7,0:17.0
-33,5,0:17.0
-33,6,0:17.0
-33,7,0:17.0
-32,5,0:17.0
-32,6,0:17.0
-32,7,0:17.0
-31,6,0:17.0
-31,7,0:17.0
-31,8,0:17.0
-30,6,0:17.0
-30,7,0:17.0
-30,8,0:17.0
-29,6,0:17.0
-29,7,0:17.0
-29,8,0:17.0
-28,-11,0:17.0
-28,6,0:17.0
-28,7,0:17.0
-28,8,0:17.0
-28,15,0:17.0
-28,16,0:17.0
-28,17,0:17.0
-27,-12,0:17.0
-27,-11,0:17.0
-27,-10,0:17.0
-27,13,0:17.0
-27,14,0:17.0
-27,15,0:17.0
-27,16,0:17.0
-27,17,0:17.0
-26,-12,0:17.0
-26,-11,0:17.0
-26,-10,0:17.0
-26,12,0:17.0
-26,13,0:17.0
-26,14,0:17.0
-26,15,0:17.0
-26,16,0:17.0
-26,17,0:17.0
-25,-12,0:17.0
-25,-11,0:17.0
-25,-10,0:17.0
-25,11,0:17.0
-25,12,0:17.0
-25,13,0:17.0
-25,14,0:17.0
-25,15,0:17.0
-25,16,0:17.0
-24,-11,0:17.0
-24,12,0:17.0
-24,13,0:17.0
-24,14,0:17.0
-17,10,0:17.0
-17,11,0:17.0
-17,12,0:17.0
-16,10,0:17.0
-16,11,0:17.0
-16,12,0:17.0
-16,13,0:17.0
-15,10,0:17.0
-15,11,0:17.0
-15,12,0:17.0
-15,13,0:17.0
-15,28,0:17.0
-14,-17,0:17.0
-14,-16,0:17.0
-14,-15,0:17.0
-14,11,0:17.0
-14,12,0:17.0
-14,13,0:17.0
-14,27,0:17.0
-14,28,0:17.0
-14,29,0:17.0
-13,-18,0:17.0
-13,-17,0:17.0
-13,-16,0:17.0
-13,-15,0:17.0
-13,-14,0:17.0
-13,-13,0:17.0
-13,-12,0:17.0
-13,27,0:17.0
-13,28,0:17.0
-13,29,0:17.0
-12,-19,0:17.0
-12,-18,0:17.0
-12,-17,0:17.0
-12,-16,0:17.0
-12,-15,0:17.0
-12,-14,0:17.0
-12,-13,0:17.0
-12,-12,0:17.0
-12,-11,0:17.0
-12,-10,0:17.0
-12,-9,0:17.0
-12,-5,0:17.0
-12,-1,0:17.0
-12,0,0:17.0
-12,1,0:17.0
-12,2,0:17.0
-12,3,0:17.0
-12,27,0:17.0
-12,28,0:17.0
-12,29,0:17.0
-12,30,0:17.0
-11,-23,0:17.0
-11,-21,0:17.0
-11,-20,0:17.0
-11,-19,0:17.0
-11,-18,0:17.0
-11,-17,0:17.0
-11,-16,0:17.0
-11,-14,0:17.0
-11,-13,0:17.0
-11,-12,0:17.0
-11,-11,0:17.0
-11,-10,0:17.0
-11,-9,0:17.0
-11,-8,0:17.0
-11,-6,0:17.0
-11,-5,0:17.0
-11,-4,0:17.0
-11,-3,0:17.0
-11,-2,0:17.0
-11,-1,0:17.0
-11,0,0:17.0
-11,1,0:17.0
-11,2,0:17.0
-11,3,0:17.0
-11,4,0:17.0
-11,5,0:17.0
-11,6,0:17.0
-11,27,0:17.0
-11,28,0:17.0
-11,29,0:17.0
-11,30,0:17.0
-11,31,0:17.0
-10,-24,0:17.0
-10,-23,0:17.0
-10,-22,0:17.0
-10,-21,0:17.0
-10,-20,0:17.0
-10,-19,0:17.0
-10,-13,0:17.0
-10,-12,0:17.0
-10,-11,0:17.0
-10,-10,0:17.0
-10,-9,0:17.0
-10,-8,0:17.0
-10,-7,0:17.0
-10,-6,0:17.0
-10,-5,0:17.0
-10,-4,0:17.0
-10,-3,0:17.0
-10,-2,0:17.0
-10,-1,0:17.0
-10,0,0:17.0
-10,1,0:17.0
-10,2,0:17.0
-10,3,0:17.0
-10,4,0:17.0
-10,5,0:17.0
-10,6,0:17.0
-10,7,0:17.0
-10,26,0:17.0
-10,27,0:17.0
-10,28,0:17.0
-10,29,0:17.0
-10,30,0:17.0
-10,31,0:17.0
-9,-23,0:17.0
-9,-22,0:17.0
-9,-21,0:17.0
-9,-20,0:17.0
-9,-8,0:17.0
-9,-7,0:17.0
-9,-6,0:17.0
-9,-5,0:17.0
-9,-4,0:17.0
-9,-3,0:17.0
-9,-2,0:17.0
-9,-1,0:17.0
-9,0,0:17.0
-9,1,0:17.0
-9,2,0:17.0
-9,3,0:17.0
-9,4,0:17.0
-9,5,0:17.0
-9,6,0:17.0
-9,7,0:17.0
-9,8,0:17.0
-9,25,0:17.0
-9,26,0:17.0
-9,27,0:17.0
-9,29,0:17.0
-9,30,0:17.0
-9,31,0:17.0
-8,-22,0:17.0
-8,-7,0:17.0
-8,-6,0:17.0
-8,-5,0:17.0
-8,-4,0:17.0
-8,-3,0:17.0
-8,-2,0:17.0
-8,-1,0:17.0
-8,0,0:17.0
-8,1,0:17.0
-8,2,0:17.0
-8,3,0:17.0
-8,4,0:17.0
-8,5,0:17.0
-8,6,0:17.0
-8,7,0:17.0
-8,8,0:17.0
-8,9,0:17.0
-8,26,0:17.0
-7,-7,0:17.0
-7,-6,0:17.0
-7,-5,0:17.0
-7,-4,0:17.0
-7,-3,0:17.0
-7,2,0:17.0
-7,4,0:17.0
-7,5,0:17.0
-7,6,0:17.0
-7,7,0:17.0
-7,8,0:17.0
-7,9,0:17.0
-7,10,0:17.0
-6,-7,0:17.0
-6,-6,0:17.0
-6,-5,0:17.0
-6,-4,0:17.0
-6,5,0:17.0
-6,6,0:17.0
-6,7,0:17.0
-6,8,0:17.0
-6,9,0:17.0
-6,10,0:17.0
-6,11,0:17.0
-5,-7,0:17.0
-5,-6,0:17.0
-5,-5,0:17.0
-5,-4,0:17.0
-5,5,0:17.0
-5,6,0:17.0
-5,7,0:17.0
-5,8,0:17.0
-5,9,0:17.0
-5,10,0:17.0
-5,11,0:17.0
-5,12,0:17.0
-4,-8,0:17.0
-4,-7,0:17.0
-4,-6,0:17.0
-4,-5,0:17.0
-4,-4,0:17.0
-4,6,0:17.0
-4,7,0:17.0
-4,8,0:17.0
-4,9,0:17.0
-4,10,0:17.0
-4,11,0:17.0
-4,12,0:17.0
-4,13,0:17.0
-3,-8,0:17.0
-3,-7,0:17.0
-3,-6,0:17.0
-3,-5,0:17.0
-3,-4,0:17.0
-3,6,0:17.0
-3,7,0:17.0
-3,8,0:17.0
-3,9,0:17.0
-3,10,0:17.0
-3,12,0:17.0
-2,-8,0:17.0
-2,-7,0:17.0
-2,-6,0:17.0
-2,-5,0:17.0
-2,-4,0:17.0
-2,7,0:17.0
-2,8,0:17.0
-2,9,0:17.0
-2,10,0:17.0
-1,-8,0:17.0
-1,-7,0:17.0
-1,-6,0:17.0
-1,-5,0:17.0
-1,-4,0:17.0
-1,-3,0:17.0
-1,7,0:17.0
-1,8,0:17.0
-1,9,0:17.0
-1,10,0:17.0
0,-7,0:17.0
0,-6,0:17.0
0,-5,0:17.0
0,-4,0:17.0
0,-3,0:17.0
0,6,0:17.0
0,7,0:17.0
0,8,0:17.0
0,9,0:17.0
0,10,0:17.0
0,23,0:17.0
1,-7,0:17.0
1,-6,0:17.0
1,-5,0:17.0
1,-4,0:17.0
1,-3,0:17.0
1,-2,0:17.0
1,-1,0:17.0
1,5,0:17.0
1,6,0:17.0
1,7,0:17.0
1,8,0:17.0
1,9,0:17.0
1,22,0:17.0
1,23,0:17.0
1,24,0:17.0
2,-10,0:17.0
2,-9,0:17.0
2,-8,0:17.0
2,-7,0:17.0
2,-6,0:17.0
2,-5,0:17.0
2,-4,0:17.0
2,-3,0:17.0
2,-2,0:17.0
2,-1,0:17.0
2,4,0:17.0
2,5,0:17.0
2,6,0:17.0
2,7,0:17.0
2,8,0:17.0
2,9,0:17.0
2,22,0:17.0
2,23,0:17.0
2,24,0:17.0
3,-11,0:17.0
3,-10,0:17.0
3,-9,0:17.0
3,-8,0:17.0
3,-7,0:17.0
3,-6,0:17.0
3,-5,0:17.0
3,-4,0:17.0
3,-3,0:17.0
3,-2,0:17.0
3,-1,0:17.0
3,0,0:17.0
3,1,0:17.0
3,2,0:17.0
3,3,0:17.0
3,4,0:17.0
3,5,0:17.0
3,6,0:17.0
3,7,0:17.0
3,8,0:17.0
3,23,0:17.0
4,-12,0:17.0
4,-11,0:17.0
4,-10,0:17.0
4,-9,0:17.0
4,-8,0:17.0
4,-5,0:17.0
4,-4,0:17.0
4,-3,0:17.0
4,-2,0:17.0
4,-1,0:17.0
4,0,0:17.0
4,1,0:17.0
4,2,0:17.0
4,3,0:17.0
4,4,0:17.0
4,5,0:17.0
4,6,0:17.0
4,7,0:17.0
4,22,0:17.0
4,23,0:17.0
4,24,0:17.0
5,-12,0:17.0
5,-11,0:17.0
5,-10,0:17.0
5,-9,0:17.0
5,-6,0:17.0
5,-5,0:17.0
5,-4,0:17.0
5,-3,0:17.0
5,-2,0:17.0
5,-1,0:17.0
5,0,0:17.0
5,1,0:17.0
5,2,0:17.0
5,3,0:17.0
5,4,0:17.0
5,5,0:17.0
5,6,0:17.0
5,22,0:17.0
5,23,0:17.0
5,24,0:17.0
6,-12,0:17.0
6,-11,0:17.0
6,-10,0:17.0
6,-6,0:17.0
6,-5,0:17.0
6,-4,0:17.0
6,-3,0:17.0
6,-1,0:17.0
6,0,0:17.0
6,1,0:17.0
6,2,0:17.0
6,3,0:17.0
6,22,0:17.0
6,23,0:17.0
6,24,0:17.0
6,25,0:17.0
7,-6,0:17.0
7,-5,0:17.0
7,-4,0:17.0
7,22,0:17.0
7,23,0:17.0
7,24,0:17.0
7,25,0:17.0
7,26,0:17.0
8,-21,0:17.0
8,-20,0:17.0
8,-19,0:17.0
8,-5,0:17.0
8,23,0:17.0
8,24,0:17.0
8,25,0:17.0
8,26,0:17.0
8,27,0:17.0
9,-22,0:17.0
9,-21,0:17.0
9,-20,0:17.0
9,-19,0:17.0
9,-18,0:17.0
9,24,0:17.0
9,25,0:17.0
9,26,0:17.0
9,27,0:17.0
9,28,0:17.0
10,-23,0:17.0
10,-22,0:17.0
10,-21,0:17.0
10,-20,0:17.0
10,-19,0:17.0
10,25,0:17.0
10,26,0:17.0
10,27,0:17.0
10,28,0:17.0
11,-24,0:17.0
11,-23,0:17.0
11,-22,0:17.0
11,-21,0:17.0
11,-20,0:17.0
11,26,0:17.0
11,27,0:17.0
11,28,0:17.0
12,-23,0:17.0
12,-22,0:17.0
12,-21,0:17.0
15,13,0:17.0
16,-1,0:17.0
16,10,0:17.0
16,11,0:17.0
16,12,0:17.0
16,13,0:17.0
16,14,0:17.0
16,17,0:17.0
16,18,0:17.0
16,19,0:17.0
17,-4,0:17.0
17,-3,0:17.0
17,-2,0:17.0
17,-1,0:17.0
17,0,0:17.0
17,10,0:17.0
17,11,0:17.0
17,12,0:17.0
17,13,0:17.0
17,16,0:17.0
17,17,0:17.0
17,18,0:17.0
17,19,0:17.0
17,20,0:17.0
18,-5,0:17.0
18,-4,0:17.0
18,-3,0:17.0
18,-2,0:17.0
18,-1,0:17.0
18,0,0:17.0
18,10,0:17.0
18,11,0:17.0
18,12,0:17.0
18,13,0:17.0
18,14,0:17.0
18,17,0:17.0
18,18,0:17.0
18,19,0:17.0
19,-4,0:17.0
19,-3,0:17.0
19,-2,0:17.0
19,-1,0:17.0
19,0,0:17.0
19,1,0:17.0
19,11,0:17.0
19,12,0:17.0
19,13,0:17.0
20,-12,0:17.0
20,-3,0:17.0
20,-1,0:17.0
20,0,0:17.0
20,1,0:17.0
20,2,0:17.0
21,-14,0:17.0
21,-13,0:17.0
21,-12,0:17.0
21,-11,0:17.0
21,1,0:17.0
21,2,0:17.0
21,3,0:17.0
22,-15,0:17.0
22,-14,0:17.0
22,-13,0:17.0
22,-12,0:17.0
22,-11,0:17.0
22,2,0:17.0
23,-14,0:17.0
23,-13,0:17.0
23,-12,0:17.0
23,-11,0:17.0
-30,7,1:17.0
-29,6,1:17.0
-29,7,1:17.0
-29,8,1:17.0
-28,6,1:17.0
-28,7,1:17.0
-28,8,1:17.0
-28,16,1:17.0
-27,-11,1:17.0
-27,6,1:17.0
-27,7,1:17.0
-27,8,1:17.0
-27,14,1:17.0
-27,15,1:17.0
-27,16,1:17.0
-27,17,1:17.0
-26,-12,1:17.0
-26,-11,1:17.0
-26,-10,1:17.0
-26,7,1:17.0
-26,8,1:17.0
-26,9,1:17.0
-26,11,1:17.0
-26,12,1:17.0
-26,13,1:17.0
-26,14,1:17.0
-26,15,1:17.0
-26,16,1:17.0
-25,-12,1:17.0
-25,-11,1:17.0
-25,-10,1:17.0
-25,8,1:17.0
-25,11,1:17.0
-25,12,1:17.0
-25,13,1:17.0
-25,14,1:17.0
-25,15,1:17.0
-24,-12,1:17.0
-24,-11,1:17.0
-24,-10,1:17.0
-24,11,1:17.0
-24,12,1:17.0
-24,13,1:17.0
-23,-11,1:17.0
-23,12,1:17.0
-17,9,1:17.0
-17,10,1:17.0
-17,11,1:17.0
-16,8,1:17.0
-16,9,1:17.0
-16,10,1:17.0
-16,11,1:17.0
-16,12,1:17.0
-15,-6,1:17.0
-15,9,1:17.0
-15,10,1:17.0
-15,11,1:17.0
-15,12,1:17.0
-15,13,1:17.0
-14,-16,1:17.0
-14,-7,1:17.0
-14,-6,1:17.0
-14,-5,1:17.0
-14,12,1:17.0
-14,28,1:17.0
-13,-17,1:17.0
-13,-16,1:17.0
-13,-15,1:17.0
-13,-13,1:17.0
-13,-7,1:17.0
-13,-6,1:17.0
-13,-5,1:17.0
-13,27,1:17.0
-13,28,1:17.0
-13,29,1:17.0
-12,-18,1:17.0
-12,-17,1:17.0
-12,-16,1:17.0
-12,-14,1:17.0
-12,-13,1:17.0
-12,-12,1:17.0
-12,-11,1:17.0
-12,-10,1:17.0
-12,-9,1:17.0
-12,-8,1:17.0
-12,-6,1:17.0
-12,-5,1:17.0
-12,-4,1:17.0
-12,2,1:17.0
-12,7,1:17.0
-12,27,1:17.0
-12,28,1:17.0
-12,29,1:17.0
-11,-17,1:17.0
-11,-13,1:17.0
-11,-12,1:17.0
-11,-11,1:17.0
-11,-10,1:17.0
-11,-9,1:17.0
-11,-8,1:17.0
-11,-7,1:17.0
-11,-6,1:17.0
-11,-5,1:17.0
-11,-4,1:17.0
-11,-3,1:17.0
-11,1,1:17.0
-11,2,1:17.0
-11,3,1:17.0
-11,5,1:17.0
-11,6,1:17.0
-11,7,1:17.0
-11,8,1:17.0
-11,26,1:17.0
-11,27,1:17.0
-11,28,1:17.0
-11,29,1:17.0
-11,30,1:17.0
-10,-12,1:17.0
-10,-11,1:17.0
-10,-10,1:17.0
-10,-9,1:17.0
-10,-8,1:17.0
-10,-7,1:17.0
-10,-6,1:17.0
-10,-5,1:17.0
-10,-4,1:17.0
-10,-3,1:17.0
-10,-2,1:17.0
-10,0,1:17.0
-10,1,1:17.0
-10,2,1:17.0
-10,3,1:17.0
-10,4,1:17.0
-10,5,1:17.0
-10,6,1:17.0
-10,7,1:17.0
-10,9,1:17.0
-10,25,1:17.0
-10,26,1:17.0
-10,27,1:17.0
-10,28,1:17.0
-10,29,1:17.0
-10,30,1:17.0
-10,31,1:17.0
-9,-9,1:17.0
-9,-8,1:17.0
-9,-7,1:17.0
-9,-6,1:17.0
-9,-5,1:17.0
-9,-4,1:17.0
-9,-3,1:17.0
-9,-2,1:17.0
-9,-1,1:17.0
-9,0,1:17.0
-9,1,1:17.0
-9,2,1:17.0
-9,3,1:17.0
-9,4,1:17.0
-9,5,1:17.0
-9,8,1:17.0
-9,9,1:17.0
-9,10,1:17.0
-9,23,1:17.0
-9,24,1:17.0
-9,25,1:17.0
-9,26,1:17.0
-9,27,1:17.0
-9,28,1:17.0
-9,30,1:17.0
-8,-8,1:17.0
-8,-7,1:17.0
-8,-6,1:17.0
-8,-5,1:17.0
-8,-4,1:17.0
-8,-3,1:17.0
-8,-2,1:17.0
-8,0,1:17.0
-8,1,1:17.0
-8,2,1:17.0
-8,3,1:17.0
-8,4,1:17.0
-8,5,1:17.0
-8,8,1:17.0
-8,9,1:17.0
-8,11,1:17.0
-8,18,1:18.0
-8,22,1:17.0
-8,23,1:17.0
-8,24,1:17.0
-8,25,1:17.0
-8,26,1:17.0
-8,27,1:17.0
-7,-9,1:17.0
-7,-8,1:17.0
-7,-7,1:17.0
-7,-5,1:17.0
-7,-2,1:17.0
-7,-1,1:17.0
-7,1,1:17.0
-7,2,1:17.0
-7,3,1:17.0
-7,4,1:17.0
-7,5,1:17.0
-7,6,1:17.0
-7,7,1:17.0
-7,8,1:17.0
-7,9,1:17.0
-7,10,1:17.0
-7,11,1:17.0
-7,12,1:17.0
-7,20,1:17.0
-7,21,1:17.0
-7,22,1:17.0
-7,23,1:17.0
-7,24,1:17.0
-6,-9,1:17.0
-6,-8,1:17.0
-6,-7,1:17.0
-6,-5,1:17.0
-6,-3,1:17.0
-6,5,1:17.0
-6,6,1:17.0
-6,7,1:17.0
-6,8,1:17.0
-6,9,1:17.0
-6,10,1:17.0
-6,11,1:17.0
-6,12,1:17.0
-6,19,1:17.0
-6,20,1:17.0
-6,21,1:17.0
-6,22,1:17.0
-5,-8,1:17.0
-5,-6,1:17.0
-5,-5,1:17.0
-5,-4,1:17.0
-5,-3,1:17.0
-5,5,1:17.0
-5,6,1:17.0
-5,7,1:17.0
-5,8,1:17.0
-5,9,1:17.0
-5,10,1:17.0
-5,11,1:17.0
-5,12,1:17.0
-5,13,1:17.0
-5,19,1:17.0
-5,20,1:17.0
-5,21,1:17.0
-4,-7,1:17.0
-4,-5,1:17.0
-4,-4,1:17.0
-4,6,1:17.0
-4,7,1:17.0
-4,8,1:17.0
-4,9,1:17.0
-4,10,1:17.0
-4,11,1:17.0
-4,12,1:17.0
-4,13,1:17.0
-4,18,1:17.0
-4,19,1:17.0
-4,20,1:17.0
-3,-8,1:17.0
-3,-7,1:17.0
-3,-6,1:17.0
-3,-5,1:17.0
-3,-4,1:17.0
-3,6,1:17.0
-3,7,1:17.0
-3,8,1:17.0
-3,9,1:17.0
-3,10,1:17.0
-3,11,1:17.0
-3,12,1:17.0
-3,13,1:17.0
-3,19,1:17.0
-2,-7,1:17.0
-2,-5,1:17.0
-2,-4,1:17.0
-2,-3,1:17.0
-2,6,1:17.0
-2,7,1:17.0
-2,8,1:17.0
-2,9,1:17.0
-2,22,1:17.0
-1,-7,1:17.0
-1,-6,1:17.0
-1,-5,1:17.0
-1,-4,1:17.0
-1,-3,1:17.0
-1,-2,1:17.0
-1,5,1:17.0
-1,8,1:17.0
-1,9,1:17.0
-1,10,1:17.0
-1,21,1:17.0
-1,22,1:17.0
-1,23,1:17.0
0,-8,1:17.0
0,-7,1:17.0
0,-6,1:17.0
0,-5,1:17.0
0,-4,1:17.0
0,-3,1:17.0
0,-2,1:17.0
0,4,1:17.0
0,5,1:17.0
0,6,1:17.0
0,8,1:17.0
0,9,1:17.0
0,22,1:17.0
0,23,1:17.0
0,24,1:17.0
1,-7,1:17.0
1,-6,1:17.0
1,-5,1:17.0
1,-4,1:17.0
1,-3,1:17.0
1,-2,1:17.0
1,-1,1:17.0
1,3,1:17.0
1,4,1:17.0
1,5,1:17.0
1,7,1:17.0
1,8,1:17.0
1,9,1:17.0
1,22,1:17.0
1,23,1:17.0
1,24,1:17.0
2,-9,1:17.0
2,-8,1:17.0
2,-7,1:17.0
2,-6,1:17.0
2,-5,1:17.0
2,-4,1:17.0
2,-3,1:17.0
2,-2,1:17.0
2,-1,1:17.0
2,0,1:17.0
2,1,1:17.0
2,2,1:17.0
2,6,1:17.0
2,7,1:17.0
2,8,1:17.0
2,22,1:17.0
2,23,1:17.0
2,24,1:17.0
2,25,1:18.0
3,-10,1:17.0
3,-9,1:17.0
3,-8,1:17.0
3,-7,1:17.0
3,-6,1:17.0
3,-5,1:17.0
3,-4,1:17.0
3,-3,1:17.0
3,-2,1:17.0
3,-1,1:17.0
3,0,1:17.0
3,1,1:17.0
3,2,1:17.0
3,3,1:17.0
3,4,1:17.0
3,5,1:17.0
3,6,1:17.0
3,7,1:17.0
3,8,1:17.0
3,22,1:17.0
3,23,1:17.0
3,24,1:17.0
4,-11,1:17.0
4,-10,1:17.0
4,-9,1:17.0
4,-8,1:17.0
4,-7,1:17.0
4,-4,1:17.0
4,-3,1:17.0
4,-2,1:17.0
4,-1,1:17.0
4,0,1:17.0
4,1,1:17.0
4,2,1:17.0
4,3,1:17.0
4,4,1:17.0
4,5,1:17.0
4,6,1:17.0
4,7,1:17.0
4,8,1:17.0
4,22,1:17.0
4,23,1:17.0
4,24,1:17.0
5,-12,1:17.0
5,-11,1:17.0
5,-10,1:17.0
5,-8,1:17.0
5,-5,1:17.0
5,-4,1:17.0
5,-3,1:17.0
5,-2,1:17.0
5,-1,1:17.0
5,0,1:17.0
5,1,1:17.0
5,2,1:17.0
5,3,1:17.0
5,4,1:17.0
5,5,1:17.0
5,22,1:17.0
5,23,1:17.0
5,24,1:17.0
6,-11,1:17.0
6,-9,1:17.0
6,-8,1:17.0
6,-7,1:17.0
6,-6,1:17.0
6,-5,1:17.0
6,-4,1:17.0
6,-3,1:17.0
6,-2,1:17.0
6,22,1:17.0
6,23,1:17.0
6,24,1:17.0
7,-10,1:17.0
7,-9,1:17.0
7,-8,1:17.0
7,-6,1:17.0
7,-5,1:17.0
7,-4,1:17.0
7,23,1:17.0
7,24,1:17.0
7,25,1:17.0
8,-20,1:17.0
8,-19,1:17.0
8,-18,1:17.0
8,-17,1:17.0
8,-9,1:17.0
8,-7,1:17.0
8,-6,1:17.0
8,-5,1:17.0
8,-4,1:17.0
8,24,1:17.0
8,25,1:17.0
8,26,1:17.0
9,-21,1:17.0
9,-20,1:17.0
9,-19,1:17.0
9,-18,1:17.0
9,-17,1:17.0
9,-16,1:17.0
9,-6,1:17.0
9,25,1:17.0
9,26,1:17.0
9,27,1:17.0
10,-22,1:17.0
10,-21,1:17.0
10,-20,1:17.0
10,-19,1:17.0
10,-18,1:17.0
10,-17,1:17.0
10,26,1:17.0
10,27,1:17.0
10,28,1:17.0
11,-23,1:17.0
11,-22,1:17.0
11,-21,1:17.0
11,27,1:17.0
12,-22,1:17.0
14,14,1:17.0
15,12,1:17.0
15,13,1:17.0
15,14,1:17.0
15,15,1:17.0
16,11,1:17.0
16,12,1:17.0
16,13,1:17.0
16,14,1:17.0
16,15,1:17.0
16,16,1:17.0
16,17,1:17.0
16,18,1:17.0
17,-5,1:17.0
17,-4,1:17.0
17,-3,1:17.0
17,-1,1:17.0
17,10,1:17.0
17,11,1:17.0
17,12,1:17.0
17,13,1:17.0
17,14,1:17.0
17,15,1:17.0
17,16,1:17.0
17,17,1:17.0
17,18,1:17.0
17,19,1:17.0
18,-6,1:17.0
18,-5,1:17.0
18,-4,1:17.0
18,-3,1:17.0
18,-2,1:17.0
18,-1,1:17.0
18,0,1:17.0
18,11,1:17.0
18,12,1:17.0
18,13,1:17.0
18,14,1:17.0
18,15,1:17.0
18,16,1:17.0
18,17,1:17.0
18,18,1:17.0
19,-12,1:17.0
19,-9,1:18.0
19,-5,1:17.0
19,-4,1:17.0
19,-3,1:17.0
19,-1,1:17.0
19,12,1:17.0
19,13,1:17.0
19,14,1:17.0
19,15,1:18.0
20,-13,1:17.0
20,-12,1:17.0
20,-11,1:17.0
21,-13,1:17.0
21,-12,1:17.0
21,-11,1:17.0
22,-14,1:17.0
22,-13,1:17.0
22,-12,1:17.0
22,-11,1:17.0
23,-13,1:17.0
23,-12,1:17.0
-29,7,2:17.0
-28,6,2:17.0
-28,7,2:17.0
-28,8,2:17.0
-27,6,2:17.0
-27,7,2:17.0
-27,8,2:17.0
-27,9,2:17.0
-26,-11,2:17.0
-26,6,2:17.0
-26,7,2:17.0
-26,8,2:17.0
-26,9,2:17.0
-26,12,2:17.0
-25,-12,2:17.0
-25,-11,2:17.0
-25,-10,2:17.0
-25,7,2:17.0
-25,8,2:17.0
-25,9,2:17.0
-25,11,2:17.0
-25,12,2:17.0
-25,13,2:17.0
-24,-12,2:17.0
-24,-11,2:17.0
-24,-10,2:17.0
-24,7,2:17.0
-24,8,2:17.0
-24,9,2:17.0
-24,11,2:17.0
-24,12,2:17.0
-24,13,2:17.0
-23,-12,2:17.0
-23,-11,2:17.0
-23,-10,2:17.0
-23,8,2:17.0
-23,9,2:17.0
-23,10,2:17.0
-23,11,2:17.0
-23,12,2:17.0
-23,13,2:17.0
-22,-11,2:17.0
-22,7,2:18.0
-22,9,2:17.0
-22,10,2:17.0
-22,11,2:17.0
-22,12,2:17.0
-21,10,2:17.0
-21,11,2:17.0
-21,12,2:17.0
-20,10,2:17.0
-20,11,2:17.0
-20,12,2:17.0
-19,-8,2:18.0
-19,11,2:17.0
-18,9,2:17.0
-17,8,2:17.0
-17,9,2:17.0
-17,10,2:17.0
-17,11,2:18.0
-16,-6,2:17.0
-16,8,2:17.0
-16,9,2:17.0
-16,10,2:17.0
-16,11,2:17.0
-16,12,2:18.0
-15,-7,2:17.0
-15,-6,2:17.0
-15,-5,2:17.0
-15,8,2:17.0
-15,9,2:17.0
-15,10,2:17.0
-15,11,2:18.0
-15,12,2:18.0
-14,-7,2:17.0
-14,-6,2:17.0
-14,-5,2:17.0
-13,-7,2:17.0
-13,-6,2:17.0
-13,-5,2:17.0
-13,-4,2:17.0
-12,-11,2:17.0
-12,-10,2:17.0
-12,-9,2:17.0
-12,-8,2:17.0
-12,-7,2:17.0
-12,-6,2:17.0
-12,-5,2:17.0
-12,-4,2:17.0
-12,1,2:17.0
-12,2,2:17.0
-12,3,2:17.0
-12,5,2:17.0
-12,6,2:17.0
-12,7,2:17.0
-12,8,2:17.0
-12,28,2:17.0
-11,-12,2:17.0
-11,-11,2:17.0
-11,-10,2:17.0
-11,-9,2:17.0
-11,-8,2:17.0
-11,-7,2:17.0
-11,-6,2:17.0
-11,-5,2:17.0
-11,-4,2:17.0
-11,1,2:17.0
-11,2,2:17.0
-11,3,2:17.0
-11,4,2:17.0
-11,5,2:17.0
-11,6,2:17.0
-11,7,2:17.0
-11,8,2:17.0
-11,27,2:17.0
-11,28,2:17.0
-11,29,2:17.0
-10,-11,2:17.0
-10,-10,2:17.0
-10,-9,2:17.0
-10,-8,2:17.0
-10,-7,2:17.0
-10,-5,2:17.0
-10,-4,2:17.0
-10,-3,2:17.0
-10,-2,2:17.0
-10,-1,2:17.0
-10,1,2:17.0
-10,2,2:17.0
-10,3,2:17.0
-10,4,2:17.0
-10,5,2:18.0
-10,6,2:17.0
-10,7,2:17.0
-10,8,2:17.0
-10,9,2:17.0
-10,10,2:17.0
-10,24,2:17.0
-10,25,2:17.0
-10,26,2:17.0
-10,27,2:17.0
-10,28,2:17.0
-9,-8,2:17.0
-9,-7,2:17.0
-9,-6,2:17.0
-9,-4,2:17.0
-9,-3,2:17.0
-9,-2,2:17.0
-9,-1,2:17.0
-9,0,2:17.0
-9,1,2:17.0
-9,2,2:17.0
-9,3,2:17.0
-9,4,2:17.0
-9,5,2:17.0
-9,6,2:18.0
-9,7,2:18.0
-9,8,2:17.0
-9,9,2:17.0
-9,10,2:17.0
-9,22,2:17.0
-9,23,2:17.0
-9,24,2:17.0
-9,25,2:17.0
-9,26,2:17.0
-9,27,2:17.0
-8,-9,2:17.0
-8,-8,2:17.0
-8,-7,2:17.0
-8,-6,2:17.0
-8,-3,2:17.0
-8,-2,2:17.0
-8,-1,2:17.0
-8,0,2:17.0
-8,1,2:17.0
-8,2,2:17.0
-8,3,2:17.0
-8,4,2:17.0
-8,5,2:17.0
-8,8,2:17.0
-8,9,2:17.0
-8,10,2:17.0
-8,11,2:17.0
-8,12,2:17.0
-8,18,2:18.0
-8,21,2:17.0
-8,22,2:17.0
-8,23,2:17.0
-8,24,2:17.0
-8,25,2:17.0
-8,26,2:17.0
-7,-9,2:17.0
-7,-8,2:17.0
-7,-7,2:17.0
-7,-6,2:17.0
-7,-5,2:17.0
-7,-3,2:17.0
-7,-2,2:17.0
-7,-1,2:17.0
-7,2,2:17.0
-7,3,2:17.0
-7,4,2:17.0
-7,5,2:17.0
-7,6,2:17.0
-7,7,2:17.0
-7,8,2:17.0
-7,9,2:18.0
-7,10,2:17.0
-7,11,2:17.0
-7,12,2:17.0
-7,17,2:17.0
-7,19,2:17.0
-7,20,2:17.0
-7,21,2:17.0
-7,22,2:17.0
-7,23,2:17.0
-7,24,2:17.0
-7,25,2:17.0
-6,-9,2:17.0
-6,-8,2:17.0
-6,-7,2:17.0
-6,-6,2:17.0
-6,-3,2:17.0
-6,-2,2:17.0
-6,5,2:17.0
-6,6,2:17.0
-6,7,2:17.0
-6,8,2:17.0
-6,9,2:17.0
-6,10,2:17.0
-6,11,2:17.0
-6,12,2:17.0
-6,16,2:17.0
-6,17,2:17.0
-6,18,2:17.0
-6,19,2:17.0
-6,20,2:17.0
-6,21,2:17.0
-6,22,2:17.0
-6,23,2:17.0
-5,-9,2:17.0
-5,-8,2:17.0
-5,-7,2:17.0
-5,-6,2:17.0
-5,-5,2:17.0
-5,-4,2:17.0
-5,-3,2:17.0
-5,5,2:17.0
-5,6,2:17.0
-5,7,2:17.0
-5,8,2:17.0
-5,9,2:17.0
-5,10,2:17.0
-5,11,2:17.0
-5,12,2:17.0
-5,15,2:17.0
-5,16,2:17.0
-5,17,2:17.0
-5,18,2:17.0
-5,19,2:17.0
-5,20,2:17.0
-5,21,2:17.0
-5,22,2:17.0
-4,-7,2:17.0
-4,-6,2:17.0
-4,-5,2:17.0
-4,-4,2:17.0
-4,-3,2:17.0
-4,6,2:17.0
-4,7,2:17.0
-4,8,2:17.0
-4,9,2:17.0
-4,10,2:17.0
-4,11,2:17.0
-4,12,2:17.0
-4,13,2:17.0
-4,14,2:17.0
-4,15,2:17.0
-4,16,2:17.0
-4,17,2:17.0
-4,18,2:17.0
-4,19,2:17.0
-4,20,2:17.0
-4,21,2:17.0
-3,-8,2:17.0
-3,-7,2:17.0
-3,-6,2:17.0
-3,-5,2:17.0
-3,-4,2:17.0
-3,-3,2:17.0
-3,6,2:17.0
-3,7,2:17.0
-3,8,2:17.0
-3,9,2:17.0
-3,12,2:17.0
-3,15,2:17.0
-3,17,2:17.0
-3,18,2:17.0
-3,19,2:17.0
-3,20,2:17.0
-3,21,2:17.0
-2,-7,2:17.0
-2,-5,2:17.0
-2,-4,2:17.0
-2,-3,2:17.0
-2,-2,2:17.0
-2,6,2:17.0
-2,7,2:17.0
-2,8,2:17.0
-2,9,2:17.0
-2,20,2:17.0
-2,21,2:17.0
-2,22,2:17.0
-2,23,2:17.0
-1,-8,2:17.0
-1,-7,2:17.0
-1,-6,2:17.0
-1,-5,2:17.0
-1,-4,2:17.0
-1,-3,2:17.0
-1,-2,2:17.0
-1,4,2:17.0
-1,5,2:17.0
-1,6,2:17.0
-1,7,2:17.0
-1,8,2:17.0
-1,9,2:17.0
-1,20,2:17.0
-1,21,2:17.0
-1,22,2:17.0
-1,23,2:17.0
-1,24,2:17.0
0,-8,2:17.0
0,-7,2:17.0
0,-6,2:17.0
0,-5,2:17.0
0,-4,2:17.0
0,-3,2:17.0
0,-2,2:17.0
0,-1,2:17.0
0,4,2:17.0
0,5,2:17.0
0,6,2:17.0
0,7,2:17.0
0,21,2:17.0
0,22,2:17.0
0,23,2:17.0
0,24,2:17.0
1,-8,2:17.0
1,-7,2:17.0
1,-6,2:17.0
1,-5,2:17.0
1,-4,2:17.0
1,-3,2:17.0
1,-2,2:17.0
1,-1,2:17.0
1,1,2:17.0
1,3,2:17.0
1,4,2:17.0
1,5,2:17.0
1,6,2:17.0
1,7,2:17.0
1,8,2:17.0
1,22,2:17.0
1,23,2:17.0
1,24,2:17.0
2,-8,2:17.0
2,-7,2:17.0
2,-6,2:17.0
2,-5,2:17.0
2,-4,2:17.0
2,-3,2:17.0
2,-2,2:17.0
2,-1,2:17.0
2,0,2:17.0
2,1,2:17.0
2,2,2:17.0
2,3,2:17.0
2,6,2:17.0
2,7,2:17.0
2,8,2:17.0
2,21,2:18.0
2,22,2:17.0
2,23,2:17.0
2,24,2:17.0
2,25,2:18.0
3,-9,2:17.0
3,-8,2:17.0
3,-7,2:17.0
3,-6,2:17.0
3,-5,2:17.0
3,-2,2:17.0
3,1,2:17.0
3,2,2:17.0
3,3,2:17.0
3,4,2:17.0
3,5,2:17.0
3,6,2:17.0
3,7,2:17.0
3,8,2:17.0
3,22,2:17.0
3,23,2:17.0
3,24,2:17.0
4,-8,2:17.0
4,-7,2:17.0
4,-6,2:17.0
4,-5,2:17.0
4,-3,2:17.0
4,-2,2:17.0
4,-1,2:17.0
4,0,2:17.0
4,1,2:17.0
4,2,2:17.0
4,3,2:17.0
4,4,2:17.0
4,5,2:17.0
4,6,2:17.0
4,7,2:17.0
4,22,2:17.0
4,23,2:17.0
4,24,2:17.0
5,-9,2:17.0
5,-8,2:17.0
5,-7,2:17.0
5,-6,2:17.0
5,-5,2:17.0
5,-4,2:17.0
5,-3,2:17.0
5,-2,2:17.0
5,1,2:17.0
5,4,2:17.0
5,5,2:17.0
5,6,2:17.0
5,22,2:17.0
5,23,2:17.0
5,24,2:17.0
6,-10,2:17.0
6,-9,2:17.0
6,-8,2:17.0
6,-7,2:17.0
6,-6,2:17.0
6,-5,2:17.0
6,-4,2:17.0
6,-3,2:17.0
6,23,2:17.0
7,-17,2:17.0
7,-10,2:17.0
7,-9,2:17.0
7,-8,2:17.0
7,-7,2:17.0
7,-6,2:17.0
7,-5,2:17.0
7,-4,2:17.0
8,-19,2:17.0
8,-18,2:17.0
8,-17,2:17.0
8,-16,2:17.0
8,-10,2:17.0
8,-9,2:17.0
8,-8,2:17.0
8,-7,2:17.0
8,-6,2:17.0
8,-5,2:17.0
8,-4,2:17.0
9,-20,2:17.0
9,-19,2:17.0
9,-18,2:17.0
9,-17,2:17.0
9,-16,2:17.0
9,-7,2:17.0
9,-6,2:17.0
9,-5,2:17.0
10,-19,2:17.0
10,-18,2:17.0
10,-17,2:17.0
10,-16,2:17.0
10,-8,2:17.0
10,-7,2:17.0
10,-6,2:17.0
11,-7,2:17.0
12,-6,2:17.0
13,-7,2:17.0
13,-6,2:17.0
13,-5,2:17.0
13,14,2:17.0
14,-8,2:17.0
14,-7,2:17.0
14,-6,2:17.0
14,13,2:17.0
14,14,2:17.0
14,15,2:17.0
15,-9,2:17.0
15,-8,2:17.0
15,-7,2:17.0
15,13,2:17.0
15,14,2:17.0
15,15,2:17.0
16,-12,2:18.0
16,-10,2:17.0
16,-9,2:17.0
16,-8,2:17.0
16,-7,2:17.0
16,-6,2:17.0
16,12,2:17.0
16,13,2:17.0
16,14,2:17.0
16,15,2:17.0
16,16,2:17.0
16,17,2:17.0
17,-11,2:17.0
17,-10,2:17.0
17,-9,2:17.0
17,-7,2:17.0
17,-6,2:17.0
17,-5,2:17.0
17,-4,2:17.0
17,11,2:17.0
17,12,2:17.0
17,13,2:17.0
17,14,2:17.0
17,15,2:17.0
17,16,2:17.0
17,17,2:17.0
17,18,2:17.0
18,-12,2:17.0
18,-11,2:17.0
18,-10,2:17.0
18,-7,2:17.0
18,-6,2:17.0
18,-5,2:17.0
18,-4,2:17.0
18,-3,2:17.0
18,12,2:17.0
18,13,2:17.0
18,14,2:17.0
18,15,2:17.0
18,16,2:17.0
18,17,2:17.0
19,-13,2:17.0
19,-12,2:17.0
19,-11,2:17.0
19,-9,2:18.0
19,-6,2:17.0
19,-5,2:17.0
19,-4,2:17.0
19,13,2:17.0
19,14,2:18.0
19,15,2:18.0
20,-13,2:17.0
20,-12,2:17.0
20,-11,2:17.0
21,-13,2:17.0
21,-12,2:17.0
21,-11,2:17.0
22,-12,2:17.0
-28,7,3:17.0
-27,6,3:17.0
-27,7,3:17.0
-27,8,3:17.0
-26,7,3:17.0
-26,8,3:17.0
-26,9,3:17.0
-25,-11,3:17.0
-25,7,3:17.0
-25,8,3:17.0
-25,9,3:17.0
-25,12,3:17.0
-24,-12,3:17.0
-24,-11,3:17.0
-24,-10,3:17.0
-24,7,3:17.0
-24,8,3:17.0
-24,9,3:17.0
-24,10,3:17.0
-24,11,3:17.0
-24,12,3:17.0
-24,13,3:17.0
-23,-12,3:17.0
-23,-11,3:17.0
-23,-10,3:17.0
-23,7,3:17.0
-23,8,3:17.0
-23,9,3:17.0
-23,10,3:17.0
-23,11,3:17.0
-23,12,3:17.0
-23,13,3:17.0
-22,-12,3:17.0
-22,-11,3:17.0
-22,-10,3:17.0
-22,7,3:18.0
-22,8,3:17.0
-22,9,3:17.0
-22,10,3:17.0
-22,11,3:17.0
-22,12,3:17.0
-22,13,3:17.0
-21,-12,3:17.0
-21,-11,3:17.0
-21,-10,3:17.0
-21,9,3:17.0
-21,10,3:17.0
-21,11,3:17.0
-21,12,3:17.0
-20,-11,3:17.0
-20,8,3:17.0
-20,9,3:17.0
-20,10,3:17.0
-20,11,3:17.0
-20,12,3:17.0
-19,-8,3:18.0
-19,7,3:17.0
-19,8,3:17.0
-19,9,3:17.0
-19,10,3:17.0
-19,11,3:17.0
-19,12,3:17.0
-18,6,3:17.0
-18,7,3:17.0
-18,8,3:17.0
-18,9,3:17.0
-18,10,3:17.0
-18,11,3:18.0
-17,6,3:17.0
-17,7,3:17.0
-17,8,3:17.0
-17,9,3:17.0
-17,10,3:17.0
-17,11,3:18.0
-16,-7,3:17.0
-16,-6,3:17.0
-16,-5,3:17.0
-16,5,3:17.0
-16,6,3:17.0
-16,7,3:17.0
-16,8,3:17.0
-16,9,3:17.0
-16,10,3:17.0
-16,11,3:18.0
-15,-8,3:17.0
-15,-7,3:17.0
-15,-6,3:17.0
-15,-5,3:17.0
-15,5,3:17.0
-15,6,3:17.0
-15,7,3:17.0
-15,9,3:17.0
-14,-10,3:17.0
-14,-9,3:17.0
-14,-8,3:17.0
-14,-7,3:17.0
-14,-6,3:17.0
-14,-5,3:17.0
-14,6,3:17.0
-13,-11,3:17.0
-13,-10,3:17.0
-13,-9,3:17.0
-13,-8,3:17.0
-13,-7,3:17.0
-13,-6,3:17.0
-13,-5,3:17.0
-13,5,3:17.0
-12,-10,3:17.0
-12,-9,3:17.0
-12,-8,3:17.0
-12,-6,3:17.0
-12,-5,3:17.0
-12,-4,3:17.0
-12,2,3:17.0
-12,3,3:17.0
-12,4,3:17.0
-12,5,3:17.0
-12,6,3:17.0
-12,7,3:17.0
-11,-9,3:17.0
-11,-8,3:17.0
-11,-7,3:17.0
-11,-5,3:17.0
-11,1,3:17.0
-11,2,3:17.0
-11,3,3:17.0
-11,4,3:17.0
-11,5,3:17.0
-11,6,3:17.0
-11,7,3:17.0
-11,8,3:17.0
-10,-8,3:17.0
-10,-5,3:17.0
-10,-2,3:17.0
-10,0,3:17.0
-10,1,3:17.0
-10,2,3:17.0
-10,3,3:17.0
-10,4,3:17.0
-10,5,3:17.0
-10,6,3:17.0
-10,7,3:17.0
-10,8,3:18.0
-10,9,3:17.0
-10,25,3:17.0
-9,-6,3:17.0
-9,-5,3:17.0
-9,-4,3:17.0
-9,-3,3:17.0
-9,-2,3:17.0
-9,-1,3:17.0
-9,0,3:17.0
-9,1,3:17.0
-9,2,3:17.0
-9,3,3:17.0
-9,4,3:17.0
-9,5,3:17.0
-9,6,3:18.0
-9,7,3:18.0
-9,8,3:17.0
-9,9,3:17.0
-9,10,3:17.0
-9,23,3:17.0
-9,24,3:17.0
-9,25,3:17.0
-9,26,3:17.0
-8,-8,3:17.0
-8,-7,3:17.0
-8,-6,3:17.0
-8,-5,3:17.0
-8,-4,3:17.0
-8,-3,3:17.0
-8,-2,3:17.0
-8,-1,3:17.0
-8,0,3:17.0
-8,1,3:17.0
-8,2,3:17.0
-8,3,3:17.0
-8,4,3:17.0
-8,5,3:17.0
-8,6,3:17.0
-8,8,3:18.0
-8,9,3:17.0
-8,10,3:17.0
-8,11,3:17.0
-8,18,3:18.0
-8,22,3:17.0
-8,23,3:17.0
-8,24,3:17.0
-8,25,3:17.0
-7,-9,3:17.0
-7,-8,3:17.0
-7,-7,3:17.0
-7,-6,3:17.0
-7,-5,3:17.0
-7,-4,3:17.0
-7,-3,3:17.0
-7,-2,3:17.0
-7,-1,3:17.0
-7,1,3:17.0
-7,2,3:17.0
-7,3,3:17.0
-7,4,3:17.0
-7,5,3:17.0
-7,6,3:17.0
-7,8,3:18.0
-7,9,3:18.0
-7,10,3:17.0
-7,11,3:17.0
-7,12,3:17.0
-7,16,3:17.0
-7,17,3:17.0
-7,18,3:17.0
-7,20,3:17.0
-7,21,3:17.0
-7,22,3:17.0
-7,23,3:17.0
-7,24,3:17.0
-6,-9,3:17.0
-6,-8,3:17.0
-6,-7,3:17.0
-6,-6,3:17.0
-6,-5,3:17.0
-6,-3,3:17.0
-6,-2,3:17.0
-6,-1,3:17.0
-6,5,3:17.0
-6,6,3:17.0
-6,7,3:17.0
-6,8,3:17.0
-6,9,3:18.0
-6,10,3:18.0
-6,11,3:17.0
-6,12,3:17.0
-6,13,3:17.0
-6,15,3:17.0
-6,16,3:17.0
-6,17,3:17.0
-6,18,3:17.0
-6,19,3:17.0
-6,20,3:17.0
-6,21,3:17.0
-6,22,3:17.0
-5,-8,3:17.0
-5,-7,3:17.0
-5,-6,3:17.0
-5,-5,3:17.0
-5,-4,3:17.0
-5,-3,3:17.0
-5,5,3:17.0
-5,6,3:17.0
-5,7,3:17.0
-5,8,3:17.0
-5,9,3:17.0
-5,10,3:18.0
-5,11,3:18.0
-5,12,3:17.0
-5,13,3:17.0
-5,14,3:17.0
-5,15,3:17.0
-5,16,3:17.0
-5,17,3:17.0
-5,18,3:17.0
-5,19,3:17.0
-5,20,3:17.0
-5,21,3:17.0
-4,-8,3:17.0
-4,-7,3:17.0
-4,-6,3:17.0
-4,-5,3:17.0
-4,-4,3:17.0
-4,-3,3:17.0
-4,6,3:17.0
-4,7,3:17.0
-4,8,3:17.0
-4,13,3:17.0
-4,14,3:17.0
-4,15,3:17.0
-4,16,3:17.0
-4,17,3:17.0
-4,18,3:17.0
-4,19,3:17.0
-4,20,3:17.0
-4,21,3:17.0
-3,-8,3:17.0
-3,-7,3:17.0
-3,-6,3:17.0
-3,-5,3:17.0
-3,-4,3:17.0
-3,-3,3:17.0
-3,5,3:17.0
-3,6,3:17.0
-3,7,3:17.0
-3,8,3:17.0
-3,9,3:17.0
-3,14,3:17.0
-3,15,3:17.0
-3,16,3:17.0
-3,17,3:17.0
-3,18,3:17.0
-3,19,3:17.0
-3,20,3:17.0
-3,21,3:17.0
-3,22,3:17.0
-2,-8,3:17.0
-2,-7,3:17.0
-2,-6,3:17.0
-2,-5,3:17.0
-2,-4,3:17.0
-2,-3,3:17.0
-2,6,3:17.0
-2,7,3:17.0
-2,8,3:17.0
-2,9,3:17.0
-2,19,3:17.0
-2,20,3:17.0
-2,21,3:17.0
-2,22,3:17.0
-1,-7,3:17.0
-1,-6,3:17.0
-1,-5,3:17.0
-1,-4,3:17.0
-1,-3,3:17.0
-1,-2,3:17.0
-1,5,3:17.0
-1,6,3:17.0
-1,7,3:17.0
-1,8,3:17.0
-1,20,3:17.0
-1,21,3:17.0
-1,22,3:17.0
-1,23,3:17.0
0,-8,3:17.0
0,-7,3:17.0
0,-6,3:17.0
0,-5,3:17.0
0,-4,3:17.0
0,-3,3:17.0
0,-2,3:17.0
0,4,3:17.0
0,5,3:17.0
0,6,3:17.0
0,7,3:17.0
0,8,3:17.0
0,20,3:17.0
0,21,3:17.0
0,22,3:17.0
0,23,3:17.0
0,24,3:17.0
1,-7,3:17.0
1,-6,3:17.0
1,-5,3:17.0
1,-3,3:17.0
1,-2,3:17.0
1,-1,3:17.0
1,0,3:17.0
1,1,3:17.0
1,2,3:17.0
1,3,3:17.0
1,4,3:17.0
1,5,3:18.0
1,6,3:17.0
1,7,3:17.0
1,8,3:17.0
1,22,3:18.0
1,23,3:17.0
2,-7,3:17.0
2,-6,3:17.0
2,-5,3:17.0
2,-3,3:17.0
2,-2,3:17.0
2,-1,3:17.0
2,0,3:17.0
2,1,3:17.0
2,2,3:17.0
2,3,3:17.0
2,4,3:18.0
2,5,3:17.0
2,6,3:18.0
2,7,3:17.0
2,8,3:17.0
2,21,3:18.0
2,22,3:18.0
2,23,3:17.0
2,24,3:18.0
2,25,3:18.0
3,-8,3:17.0
3,-7,3:17.0
3,-6,3:17.0
3,-5,3:17.0
3,-4,3:17.0
3,-3,3:17.0
3,-2,3:17.0
3,-1,3:17.0
3,0,3:17.0
3,1,3:17.0
3,2,3:17.0
3,3,3:17.0
3,4,3:17.0
3,5,3:17.0
3,6,3:17.0
3,7,3:17.0
3,8,3:17.0
3,22,3:17.0
3,23,3:17.0
3,24,3:17.0
4,-9,3:17.0
4,-8,3:17.0
4,-7,3:17.0
4,-6,3:17.0
4,-5,3:17.0
4,-4,3:17.0
4,-3,3:17.0
4,-2,3:17.0
4,-1,3:17.0
4,2,3:17.0
4,3,3:17.0
4,4,3:17.0
4,5,3:17.0
4,6,3:17.0
4,7,3:17.0
4,8,3:17.0
4,23,3:17.0
5,-10,3:17.0
5,-9,3:17.0
5,-8,3:17.0
5,-7,3:17.0
5,-6,3:17.0
5,-5,3:17.0
5,-4,3:17.0
5,-2,3:17.0
5,5,3:17.0
5,7,3:17.0
6,-11,3:17.0
6,-10,3:17.0
6,-9,3:17.0
6,-8,3:17.0
6,-7,3:17.0
6,-6,3:17.0
6,-5,3:17.0
7,-18,3:17.0
7,-17,3:17.0
7,-16,3:17.0
7,-10,3:17.0
7,-9,3:17.0
7,-8,3:17.0
7,-7,3:17.0
7,-6,3:17.0
7,-5,3:17.0
7,-4,3:17.0
8,-18,3:17.0
8,-17,3:17.0
8,-16,3:17.0
8,-15,3:17.0
8,-9,3:17.0
8,-7,3:17.0
8,-6,3:17.0
8,-5,3:17.0
9,-19,3:17.0
9,-18,3:17.0
9,-17,3:17.0
9,-16,3:17.0
9,-8,3:17.0
9,-7,3:17.0
9,-6,3:17.0
9,-5,3:17.0
10,-18,3:17.0
10,-17,3:17.0
10,-8,3:17.0
10,-7,3:17.0
10,-6,3:17.0
10,-5,3:17.0
11,-8,3:17.0
11,-7,3:17.0
11,-6,3:17.0
11,-5,3:17.0
12,-7,3:17.0
12,-6,3:17.0
12,-5,3:17.0
12,14,3:17.0
13,-8,3:17.0
13,-7,3:17.0
13,-6,3:17.0
13,-5,3:17.0
13,13,3:17.0
13,14,3:17.0
13,15,3:17.0
14,-9,3:17.0
14,-8,3:17.0
14,-7,3:17.0
14,-6,3:17.0
14,-5,3:17.0
14,13,3:17.0
14,14,3:17.0
14,15,3:17.0
15,-10,3:17.0
15,-9,3:17.0
15,-8,3:17.0
15,-7,3:17.0
15,-6,3:17.0
15,13,3:17.0
15,14,3:17.0
15,15,3:17.0
16,-12,3:18.0
16,-11,3:17.0
16,-10,3:17.0
16,-9,3:17.0
16,-8,3:17.0
16,-7,3:17.0
16,-6,3:17.0
16,-5,3:17.0
16,13,3:17.0
16,14,3:17.0
16,15,3:17.0
16,16,3:17.0
17,-12,3:17.0
17,-11,3:17.0
17,-10,3:17.0
17,-9,3:17.0
17,-7,3:17.0
17,-6,3:17.0
17,-5,3:17.0
17,14,3:17.0
17,15,3:17.0
17,16,3:17.0
17,17,3:17.0
18,-13,3:17.0
18,-12,3:17.0
18,-11,3:17.0
18,-10,3:17.0
18,-9,3:17.0
18,-6,3:17.0
18,-5,3:17.0
18,-4,3:17.0
18,14,3:18.0
18,15,3:17.0
18,16,3:17.0
19,-13,3:17.0
19,-12,3:17.0
19,-11,3:17.0
19,-10,3:17.0
19,-9,3:18.0
19,-6,3:17.0
19,-5,3:17.0
20,-13,3:17.0
20,-12,3:17.0
20,-11,3:17.0
21,-12,3:17.0
-27,8,4:18.0
-26,7,4:18.0
-26,8,4:17.0
-26,9,4:18.0
-25,7,4:17.0
-25,8,4:17.0
-25,9,4:17.0
-24,-11,4:17.0
-24,7,4:17.0
-24,8,4:17.0
-24,9,4:17.0
-24,11,4:17.0
-24,12,4:17.0
-23,-12,4:17.0
-23,-11,4:17.0
-23,-10,4:17.0
-23,7,4:18.0
-23,8,4:17.0
-23,9,4:17.0
-23,10,4:17.0
-23,11,4:17.0
-23,12,4:17.0
-23,13,4:17.0
-22,-13,4:18.0
-22,-12,4:17.0
-22,-11,4:17.0
-22,-10,4:17.0
-22,7,4:18.0
-22,8,4:18.0
-22,9,4:17.0
-22,10,4:17.0
-22,11,4:17.0
-22,12,4:17.0
-21,-12,4:17.0
-21,-11,4:17.0
-21,-10,4:17.0
-21,8,4:17.0
-21,9,4:17.0
-21,10,4:17.0
-21,11,4:17.0
-21,12,4:17.0
-20,-12,4:17.0
-20,-11,4:17.0
-20,-10,4:17.0
-20,7,4:17.0
-20,8,4:17.0
-20,9,4:17.0
-20,10,4:17.0
-20,11,4:17.0
-20,12,4:17.0
-19,-11,4:17.0
-19,-10,4:17.0
-19,-9,4:17.0
-19,-8,4:18.0
-19,6,4:17.0
-19,7,4:17.0
-19,8,4:17.0
-19,9,4:17.0
-19,10,4:17.0
-19,11,4:17.0
-18,-10,4:17.0
-18,-9,4:17.0
-18,-8,4:17.0
-18,6,4:17.0
-18,7,4:17.0
-18,8,4:17.0
-18,9,4:17.0
-17,-9,4:17.0
-17,-8,4:17.0
-17,-7,4:17.0
-17,5,4:17.0
-17,6,4:17.0
-17,7,4:17.0
-17,8,4:17.0
-17,9,4:17.0
-17,10,4:17.0
-16,-10,4:17.0
-16,-9,4:17.0
-16,-8,4:17.0
-16,-7,4:17.0
-16,-6,4:17.0
-16,5,4:17.0
-16,6,4:17.0
-16,7,4:17.0
-16,8,4:17.0
-16,9,4:17.0
-15,-9,4:17.0
-15,-8,4:17.0
-15,-7,4:17.0
-15,-6,4:17.0
-15,-5,4:17.0
-15,5,4:17.0
-15,6,4:17.0
-15,7,4:17.0
-14,-11,4:17.0
-14,-10,4:17.0
-14,-9,4:17.0
-14,-8,4:17.0
-14,-7,4:17.0
-14,-6,4:17.0
-14,5,4:17.0
-14,6,4:17.0
-14,7,4:17.0
-13,-11,4:17.0
-13,-10,4:17.0
-13,-9,4:17.0
-13,-8,4:17.0
-13,-7,4:17.0
-13,4,4:17.0
-13,5,4:17.0
-13,6,4:17.0
-12,-11,4:17.0
-12,-10,4:17.0
-12,-9,4:17.0
-12,-8,4:17.0
-12,3,4:17.0
-12,4,4:17.0
-12,5,4:17.0
-12,6,4:17.0
-12,7,4:17.0
-12,8,4:17.0
-11,0,4:17.0
-11,1,4:17.0
-11,2,4:17.0
-11,3,4:17.0
-11,4,4:17.0
-11,5,4:17.0
-11,6,4:17.0
-11,7,4:17.0
-11,8,4:17.0
-10,-6,4:17.0
-10,-5,4:17.0
-10,-4,4:17.0
-10,-1,4:17.0
-10,0,4:17.0
-10,1,4:17.0
-10,2,4:17.0
-10,3,4:17.0
-10,4,4:17.0
-10,5,4:17.0
-10,6,4:17.0
-10,7,4:17.0
-10,8,4:17.0
-10,9,4:17.0
-10,10,4:17.0
-9,-6,4:17.0
-9,-5,4:17.0
-9,-4,4:17.0
-9,-3,4:17.0
-9,-2,4:17.0
-9,-1,4:17.0
-9,0,4:17.0
-9,1,4:17.0
-9,2,4:17.0
-9,3,4:17.0
-9,4,4:17.0
-9,5,4:17.0
-9,6,4:17.0
-9,7,4:17.0
-9,8,4:17.0
-9,9,4:17.0
-9,10,4:17.0
-9,11,4:17.0
-8,-7,4:17.0
-8,-6,4:17.0
-8,-5,4:17.0
-8,-4,4:17.0
-8,-3,4:17.0
-8,-2,4:17.0
-8,-1,4:17.0
-8,0,4:17.0
-8,1,4:17.0
-8,2,4:17.0
-8,3,4:17.0
-8,4,4:17.0
-8,5,4:17.0
-8,6,4:17.0
-8,8,4:17.0
-8,9,4:17.0
-8,10,4:17.0
-8,11,4:17.0
-8,18,4:18.0
-7,-8,4:18.0
-7,-7,4:17.0
-7,-6,4:17.0
-7,-5,4:17.0
-7,-4,4:17.0
-7,-3,4:17.0
-7,-2,4:17.0
-7,-1,4:17.0
-7,0,4:17.0
-7,2,4:17.0
-7,3,4:17.0
-7,4,4:17.0
-7,5,4:17.0
-7,6,4:17.0
-7,7,4:17.0
-7,9,4:17.0
-7,10,4:17.0
-7,11,4:17.0
-7,12,4:17.0
-7,13,4:17.0
-7,17,4:17.0
-7,18,4:18.0
-7,19,4:18.0
-6,-8,4:17.0
-6,-7,4:17.0
-6,-6,4:17.0
-6,-5,4:17.0
-6,-4,4:17.0
-6,-3,4:17.0
-6,-2,4:17.0
-6,5,4:17.0
-6,6,4:17.0
-6,7,4:17.0
-6,8,4:17.0
-6,10,4:17.0
-6,11,4:17.0
-6,12,4:17.0
-6,13,4:17.0
-6,14,4:17.0
-6,16,4:17.0
-6,17,4:17.0
-6,18,4:17.0
-6,19,4:17.0
-5,-7,4:17.0
-5,-6,4:17.0
-5,-5,4:17.0
-5,-4,4:17.0
-5,-3,4:17.0
-5,5,4:17.0
-5,6,4:17.0
-5,7,4:17.0
-5,8,4:17.0
-5,11,4:17.0
-5,12,4:17.0
-5,13,4:17.0
-5,14,4:17.0
-5,15,4:17.0
-5,16,4:17.0
-5,17,4:17.0
-5,18,4:17.0
-5,19,4:17.0
-5,20,4:17.0
-4,-7,4:17.0
-4,-6,4:17.0
-4,-5,4:17.0
-4,-4,4:17.0
-4,-3,4:17.0
-4,5,4:17.0
-4,6,4:17.0
-4,7,4:17.0
-4,8,4:17.0
-4,9,4:17.0
-4,12,4:17.0
-4,13,4:17.0
-4,14,4:17.0
-4,15,4:17.0
-4,16,4:17.0
-4,17,4:17.0
-4,18,4:17.0
-4,19,4:17.0
-4,20,4:17.0
-4,21,4:17.0
-3,-8,4:17.0
-3,-7,4:17.0
-3,-6,4:17.0
-3,-5,4:17.0
-3,-4,4:17.0
-3,5,4:17.0
-3,6,4:17.0
-3,7,4:17.0
-3,8,4:17.0
-3,9,4:17.0
-3,13,4:17.0
-3,14,4:17.0
-3,15,4:17.0
-3,17,4:17.0
-3,18,4:17.0
-3,19,4:17.0
-3,20,4:17.0
-3,21,4:17.0
-2,-7,4:17.0
-2,-6,4:17.0
-2,-5,4:17.0
-2,-4,4:17.0
-2,5,4:17.0
-2,6,4:17.0
-2,7,4:17.0
-2,8,4:17.0
-2,9,4:17.0
-2,20,4:17.0
-2,21,4:17.0
-2,22,4:17.0
-1,-7,4:17.0
-1,-6,4:17.0
-1,-5,4:17.0
-1,-4,4:17.0
-1,-3,4:17.0
-1,5,4:17.0
-1,6,4:17.0
-1,20,4:17.0
-1,21,4:17.0
-1,22,4:17.0
0,-6,4:17.0
0,-5,4:17.0
0,-4,4:17.0
0,-3,4:17.0
0,-2,4:17.0
0,3,4:17.0
0,4,4:17.0
0,5,4:17.0
0,6,4:17.0
0,7,4:17.0
0,21,4:17.0
1,-3,4:17.0
1,-2,4:17.0
1,-1,4:17.0
1,0,4:17.0
1,1,4:17.0
1,2,4:17.0
1,3,4:17.0
1,4,4:18.0
1,5,4:18.0
1,6,4:18.0
1,7,4:17.0
1,8,4:17.0
2,-6,4:17.0
2,-5,4:17.0
2,-4,4:17.0
2,-3,4:17.0
2,-2,4:17.0
2,-1,4:17.0
2,0,4:17.0
2,1,4:17.0
2,2,4:17.0
2,3,4:17.0
2,4,4:17.0
2,5,4:17.0
2,6,4:17.0
2,7,4:17.0
2,8,4:17.0
2,22,4:18.0
2,23,4:18.0
2,24,4:18.0
3,-7,4:17.0
3,-6,4:17.0
3,-5,4:17.0
3,-4,4:17.0
3,-3,4:17.0
3,-2,4:17.0
3,-1,4:17.0
3,0,4:17.0
3,1,4:17.0
3,2,4:17.0
3,3,4:17.0
3,4,4:17.0
3,5,4:17.0
3,6,4:17.0
3,7,4:17.0
3,8,4:17.0
3,23,4:18.0
4,-10,4:17.0
4,-9,4:17.0
4,-8,4:17.0
4,-7,4:17.0
4,-6,4:17.0
4,-5,4:17.0
4,-4,4:17.0
4,-3,4:17.0
4,-2,4:17.0
4,-1,4:17.0
4,0,4:17.0
4,3,4:17.0
4,4,4:17.0
4,5,4:17.0
4,6,4:17.0
4,7,4:17.0
4,8,4:17.0
4,9,4:17.0
5,-11,4:17.0
5,-10,4:17.0
5,-9,4:17.0
5,-8,4:17.0
5,-7,4:17.0
5,-6,4:17.0
5,-5,4:17.0
5,-4,4:17.0
5,-3,4:17.0
5,-2,4:17.0
5,-1,4:17.0
5,6,4:17.0
5,7,4:17.0
5,8,4:17.0
5,9,4:17.0
5,10,4:17.0
6,-15,4:17.0
6,-12,4:17.0
6,-11,4:17.0
6,-10,4:17.0
6,-9,4:17.0
6,-8,4:17.0
6,-7,4:17.0
6,-6,4:17.0
6,9,4:17.0
7,-17,4:17.0
7,-16,4:17.0
7,-15,4:17.0
7,-14,4:17.0
7,-13,4:17.0
7,-12,4:17.0
7,-11,4:17.0
7,-10,4:17.0
7,-9,4:17.0
7,-7,4:17.0
8,-18,4:17.0
8,-17,4:17.0
8,-16,4:17.0
8,-15,4:17.0
8,-12,4:17.0
8,-6,4:17.0
9,-17,4:17.0
9,-16,4:17.0
9,-15,4:17.0
9,-7,4:17.0
9,-6,4:17.0
9,-5,4:17.0
10,-8,4:17.0
10,-7,4:17.0
10,-6,4:17.0
10,-5,4:17.0
10,15,4:17.0
11,-7,4:17.0
11,-6,4:17.0
11,-5,4:17.0
11,14,4:17.0
11,15,4:17.0
11,16,4:17.0
12,-7,4:17.0
12,-6,4:17.0
12,-5,4:17.0
12,13,4:17.0
12,14,4:17.0
12,15,4:17.0
13,-7,4:17.0
13,-6,4:17.0
13,-5,4:17.0
13,13,4:17.0
13,14,4:17.0
13,15,4:17.0
14,-8,4:17.0
14,-7,4:17.0
14,-6,4:17.0
14,13,4:17.0
14,14,4:17.0
14,15,4:17.0
15,-9,4:17.0
15,-8,4:17.0
15,-7,4:17.0
15,14,4:17.0
16,-11,4:18.0
16,-10,4:17.0
16,-9,4:17.0
16,-6,4:17.0
17,-12,4:18.0
17,-11,4:18.0
17,-10,4:18.0
17,-9,4:18.0
18,-11,4:17.0
18,-10,4:17.0
18,-9,4:18.0
19,-12,4:17.0
19,-11,4:17.0
20,-12,4:17.0
-26,8,5:18.0
-25,8,5:18.0
-24,8,5:18.0
-23,-12,5:18.0
-23,-11,5:17.0
-23,8,5:18.0
-22,-13,5:18.0
-22,-12,5:17.0
-22,-11,5:17.0
-22,-10,5:17.0
-22,10,5:17.0
-21,-12,5:17.0
-21,-11,5:17.0
-21,-10,5:17.0
-21,9,5:17.0
-21,10,5:17.0
-21,11,5:17.0
-20,-12,5:17.0
-20,-11,5:17.0
-20,-10,5:17.0
-20,-9,5:17.0
-20,-8,5:18.0
-20,8,5:17.0
-20,9,5:17.0
-20,10,5:17.0
-19,-12,5:17.0
-19,-11,5:17.0
-19,-10,5:17.0
-19,-9,5:17.0
-19,-8,5:17.0
-19,-7,5:18.0
-19,7,5:17.0
-19,8,5:17.0
-19,9,5:17.0
-18,-11,5:17.0
-18,-10,5:17.0
-18,-9,5:17.0
-18,-8,5:17.0
-18,-7,5:17.0
-18,6,5:17.0
-18,7,5:17.0
-18,8,5:17.0
-17,-10,5:17.0
-17,-9,5:17.0
-17,-8,5:17.0
-17,-7,5:17.0
-17,-6,5:17.0
-17,6,5:17.0
-17,7,5:17.0
-17,8,5:17.0
-17,9,5:17.0
-16,-10,5:17.0
-16,-9,5:17.0
-16,-8,5:17.0
-16,-7,5:17.0
-16,-6,5:17.0
-16,5,5:17.0
-16,6,5:17.0
-16,7,5:17.0
-16,8,5:17.0
-15,-10,5:17.0
-15,-9,5:17.0
-15,-8,5:17.0
-15,-7,5:17.0
-15,-6,5:17.0
-15,5,5:17.0
-15,6,5:17.0
-15,7,5:17.0
-14,-10,5:17.0
-14,-9,5:17.0
-14,-8,5:17.0
-14,-7,5:17.0
-14,4,5:17.0
-14,5,5:17.0
-14,6,5:17.0
-14,7,5:17.0
-13,-11,5:17.0
-13,-10,5:17.0
-13,-9,5:17.0
-13,-8,5:17.0
-13,4,5:17.0
-13,5,5:17.0
-13,6,5:17.0
-13,7,5:17.0
-12,-10,5:17.0
-12,-9,5:17.0
-12,4,5:17.0
-12,5,5:17.0
-12,6,5:17.0
-12,7,5:17.0
-11,1,5:17.0
-11,5,5:17.0
-11,6,5:17.0
-11,7,5:17.0
-11,8,5:17.0
-10,-5,5:17.0
-10,-4,5:17.0
-10,-3,5:17.0
-10,0,5:17.0
-10,1,5:17.0
-10,2,5:17.0
-10,4,5:17.0
-10,5,5:17.0
-10,6,5:17.0
-10,7,5:17.0
-10,8,5:17.0
-10,9,5:17.0
-9,-6,5:17.0
-9,-5,5:17.0
-9,-4,5:17.0
-9,-3,5:17.0
-9,-2,5:17.0
-9,-1,5:17.0
-9,0,5:17.0
-9,1,5:17.0
-9,4,5:17.0
-9,5,5:17.0
-9,6,5:17.0
-9,7,5:17.0
-9,8,5:17.0
-9,9,5:17.0
-9,10,5:17.0
-8,-7,5:18.0
-8,-6,5:17.0
-8,-5,5:17.0
-8,-4,5:17.0
-8,-3,5:17.0
-8,-2,5:17.0
-8,-1,5:17.0
-8,0,5:17.0
-8,1,5:17.0
-8,2,5:17.0
-8,4,5:17.0
-8,5,5:17.0
-8,6,5:17.0
-8,9,5:17.0
-8,10,5:17.0
-8,11,5:17.0
-7,-8,5:18.0
-7,-7,5:17.0
-7,-6,5:17.0
-7,-5,5:17.0
-7,-4,5:17.0
-7,-3,5:17.0
-7,-2,5:17.0
-7,-1,5:17.0
-7,0,5:17.0
-7,1,5:17.0
-7,3,5:17.0
-7,4,5:17.0
-7,5,5:17.0
-7,6,5:17.0
-7,7,5:17.0
-7,8,5:17.0
-7,10,5:17.0
-7,11,5:17.0
-7,12,5:17.0
-6,-7,5:18.0
-6,-6,5:17.0
-6,-5,5:17.0
-6,-4,5:17.0
-6,-3,5:17.0
-6,4,5:17.0
-6,5,5:17.0
-6,6,5:17.0
-6,7,5:17.0
-6,8,5:17.0
-6,10,5:17.0
-6,11,5:17.0
-6,12,5:17.0
-6,13,5:17.0
-6,17,5:17.0
-5,-7,5:17.0
-5,-6,5:17.0
-5,-5,5:17.0
-5,-4,5:17.0
-5,-3,5:17.0
-5,5,5:17.0
-5,6,5:17.0
-5,7,5:17.0
-5,8,5:17.0
-5,10,5:17.0
-5,11,5:17.0
-5,12,5:17.0
-5,13,5:17.0
-5,14,5:17.0
-5,15,5:17.0
-5,16,5:17.0
-5,17,5:17.0
-5,18,5:17.0
-4,-7,5:17.0
-4,-6,5:17.0
-4,-5,5:17.0
-4,-4,5:17.0
-4,6,5:17.0
-4,7,5:17.0
-4,8,5:17.0
-4,11,5:17.0
-4,12,5:17.0
-4,13,5:17.0
-4,14,5:17.0
-4,15,5:17.0
-4,17,5:17.0
-3,-7,5:17.0
-3,-6,5:17.0
-3,-5,5:17.0
-3,-4,5:17.0
-3,5,5:17.0
-3,6,5:17.0
-3,7,5:17.0
-3,8,5:17.0
-3,9,5:17.0
-3,13,5:17.0
-3,14,5:17.0
-3,15,5:17.0
-2,-7,5:17.0
-2,-6,5:17.0
-2,-5,5:17.0
-2,-4,5:17.0
-2,6,5:17.0
-2,8,5:17.0
-1,-7,5:17.0
-1,-6,5:17.0
-1,-5,5:17.0
-1,-4,5:17.0
-1,-3,5:17.0
-1,4,5:17.0
-1,5,5:17.0
-1,6,5:17.0
0,-7,5:17.0
0,-6,5:17.0
0,-5,5:17.0
0,-3,5:17.0
0,-2,5:17.0
0,-1,5:17.0
0,4,5:17.0
0,5,5:17.0
0,6,5:17.0
0,7,5:17.0
1,-4,5:17.0
1,-3,5:17.0
1,-2,5:17.0
1,-1,5:17.0
1,0,5:17.0
1,3,5:17.0
1,4,5:17.0
1,5,5:18.0
1,6,5:17.0
2,-5,5:17.0
2,-4,5:17.0
2,-3,5:17.0
2,-2,5:17.0
2,-1,5:17.0
2,0,5:17.0
2,1,5:17.0
2,2,5:17.0
2,3,5:17.0
2,4,5:18.0
2,5,5:17.0
2,7,5:17.0
3,-6,5:17.0
3,-5,5:17.0
3,-4,5:17.0
3,-3,5:17.0
3,-2,5:17.0
3,-1,5:17.0
3,0,5:17.0
3,3,5:17.0
3,4,5:17.0
3,5,5:17.0
3,6,5:17.0
3,7,5:17.0
3,8,5:17.0
3,9,5:17.0
4,-9,5:17.0
4,-8,5:17.0
4,-7,5:17.0
4,-6,5:17.0
4,-5,5:17.0
4,-4,5:17.0
4,-3,5:17.0
4,-2,5:17.0
4,-1,5:17.0
4,5,5:17.0
4,6,5:17.0
4,7,5:17.0
4,8,5:17.0
4,9,5:17.0
4,10,5:17.0
5,-12,5:17.0
5,-11,5:17.0
5,-10,5:17.0
5,-9,5:17.0
5,-8,5:17.0
5,-7,5:17.0
5,-6,5:17.0
5,-4,5:17.0
5,-2,5:17.0
5,7,5:17.0
5,8,5:17.0
5,9,5:17.0
5,10,5:17.0
5,11,5:17.0
6,-16,5:17.0
6,-15,5:17.0
6,-14,5:17.0
6,-13,5:17.0
6,-12,5:17.0
6,-11,5:17.0
6,-10,5:17.0
6,-9,5:17.0
6,-8,5:17.0
6,-7,5:17.0
6,8,5:17.0
6,9,5:17.0
6,10,5:17.0
7,-17,5:17.0
7,-16,5:17.0
7,-15,5:17.0
7,-14,5:17.0
7,-13,5:17.0
7,-12,5:17.0
7,-11,5:17.0
7,-10,5:17.0
7,9,5:50.3
8,-17,5:17.0
8,-16,5:17.0
8,-15,5:17.0
8,-14,5:17.0
8,-13,5:17.0
8,-12,5:17.0
8,-11,5:17.0
8,15,5:18.0
9,-17,5:17.0
9,-16,5:17.0
9,-15,5:17.0
9,-6,5:17.0
10,-7,5:17.0
10,-6,5:17.0
10,-5,5:17.0
10,11,5:18.0
10,14,5:17.0
10,15,5:17.0
10,16,5:17.0
11,-7,5:17.0
11,-6,5:17.0
11,-5,5:17.0
11,13,5:17.0
11,14,5:17.0
11,15,5:17.0
11,16,5:17.0
12,-7,5:17.0
12,-6,5:17.0
12,-5,5:17.0
12,13,5:17.0
12,14,5:17.0
12,15,5:17.0
12,16,5:17.0
13,-6,5:17.0
13,13,5:17.0
13,14,5:17.0
13,15,5:17.0
14,14,5:17.0
-22,-12,6:18.0
-21,-12,6:18.0
-21,-11,6:17.0
-20,-12,6:17.0
-20,-11,6:17.0
-20,-10,6:17.0
-19,-11,6:17.0
-19,-10,6:17.0
-19,-9,6:17.0
-19,-8,6:18.0
-18,-10,6:17.0
-18,-9,6:17.0
-18,-8,6:17.0
-17,-9,6:17.0
-17,-8,6:17.0
-17,-7,6:17.0
-16,-10,6:17.0
-16,-9,6:17.0
-16,-8,6:17.0
-16,-7,6:17.0
-16,-6,6:17.0
-15,-9,6:17.0
-15,-7,6:17.0
-15,4,6:17.0
-15,5,6:17.0
-15,6,6:17.0
-14,4,6:17.0
-14,5,6:17.0
-14,6,6:17.0
-14,7,6:17.0
-13,4,6:17.0
-13,5,6:17.0
-13,6,6:17.0
-12,2,6:17.0
-12,5,6:17.0
-11,1,6:17.0
-11,2,6:17.0
-11,3,6:17.0
-11,7,6:17.0
-11,8,6:17.0
-11,9,6:17.0
-10,-4,6:17.0
-10,2,6:17.0
-10,3,6:17.0
-10,4,6:17.0
-10,5,6:17.0
-10,6,6:17.0
-10,7,6:17.0
-10,8,6:17.0
-10,9,6:17.0
-10,10,6:17.0
-9,-5,6:17.0
-9,-4,6:17.0
-9,-3,6:17.0
-9,0,6:17.0
-9,1,6:17.0
-9,2,6:17.0
-9,3,6:17.0
-9,4,6:17.0
-9,5,6:17.0
-9,6,6:17.0
-9,7,6:17.0
-9,8,6:17.0
-9,9,6:17.0
-9,10,6:17.0
-8,-6,6:18.0
-8,-5,6:17.0
-8,-4,6:17.0
-8,-3,6:17.0
-8,-1,6:17.0
-8,0,6:17.0
-8,1,6:17.0
-8,2,6:17.0
-8,5,6:17.0
-8,8,6:17.0
-8,9,6:17.0
-8,10,6:17.0
-7,-7,6:18.0
-7,-6,6:18.0
-7,-5,6:17.0
-7,-4,6:17.0
-7,-3,6:17.0
-7,-2,6:17.0
-7,-1,6:17.0
-7,0,6:17.0
-7,1,6:17.0
-7,3,6:17.0
-7,4,6:17.0
-7,5,6:17.0
-7,6,6:17.0
-7,7,6:17.0
-7,11,6:17.0
-6,-6,6:18.0
-6,-5,6:17.0
-6,-4,6:17.0
-6,-3,6:17.0
-6,-2,6:17.0
-6,4,6:17.0
-6,5,6:17.0
-6,6,6:17.0
-6,7,6:17.0
-6,8,6:17.0
-6,10,6:17.0
-6,11,6:17.0
-6,12,6:17.0
-5,-6,6:17.0
-5,-5,6:17.0
-5,-4,6:17.0
-5,-3,6:17.0
-5,4,6:17.0
-5,5,6:17.0
-5,6,6:17.0
-5,7,6:17.0
-5,10,6:17.0
-5,11,6:17.0
-5,12,6:17.0
-5,13,6:17.0
-5,14,6:17.0
-4,-7,6:17.0
-4,-6,6:17.0
-4,-5,6:17.0
-4,-4,6:17.0
-4,6,6:17.0
-4,7,6:17.0
-4,10,6:17.0
-4,11,6:17.0
-4,12,6:17.0
-4,13,6:17.0
-4,14,6:17.0
-4,15,6:17.0
-3,-6,6:17.0
-3,-5,6:17.0
-3,-4,6:17.0
-3,6,6:17.0
-3,7,6:17.0
-3,8,6:17.0
-3,12,6:17.0
-3,13,6:17.0
-3,14,6:17.0
-2,-6,6:17.0
-2,-5,6:17.0
-2,-4,6:17.0
-2,6,6:17.0
-2,7,6:17.0
-1,-7,6:17.0
-1,-6,6:17.0
-1,-5,6:17.0
-1,-4,6:17.0
-1,-3,6:17.0
-1,5,6:17.0
-1,6,6:17.0
-1,7,6:17.0
0,-6,6:17.0
0,-5,6:17.0
0,-4,6:17.0
0,-3,6:17.0
0,-2,6:17.0
0,-1,6:17.0
0,4,6:17.0
0,5,6:17.0
0,6,6:17.0
0,7,6:17.0
1,-5,6:17.0
1,-4,6:17.0
1,-3,6:17.0
1,-2,6:17.0
1,-1,6:17.0
1,0,6:17.0
1,3,6:17.0
1,4,6:17.0
1,5,6:17.0
1,6,6:17.0
1,7,6:17.0
2,-5,6:17.0
2,-4,6:17.0
2,-3,6:17.0
2,-2,6:17.0
2,-1,6:17.0
2,0,6:17.0
2,1,6:17.0
2,2,6:17.0
2,4,6:17.0
3,-5,6:17.0
3,-4,6:17.0
3,-3,6:17.0
3,-2,6:17.0
3,-1,6:17.0
3,8,6:17.0
4,-8,6:17.0
4,-4,6:17.0
4,-3,6:17.0
4,-2,6:17.0
4,7,6:17.0
4,8,6:17.0
4,9,6:17.0
4,10,6:17.0
4,11,6:17.0
5,-11,6:17.0
5,-10,6:17.0
5,-9,6:17.0
5,-8,6:17.0
5,-7,6:17.0
5,8,6:17.0
5,9,6:17.0
5,10,6:17.0
5,11,6:17.0
6,-15,6:17.0
6,-14,6:17.0
6,-13,6:17.0
6,-12,6:17.0
6,-11,6:17.0
6,-10,6:17.0
6,-9,6:17.0
6,-8,6:17.0
6,9,6:17.0
6,10,6:17.0
6,11,6:17.0
7,-16,6:17.0
7,-15,6:17.0
7,-14,6:17.0
7,-13,6:17.0
7,-12,6:17.0
7,-11,6:17.0
7,-10,6:17.0
7,-9,6:17.0
7,10,6:17.0
7,11,6:17.0
7,12,6:17.0
8,-17,6:17.0
8,-16,6:17.0
8,-15,6:17.0
8,-14,6:17.0
8,-13,6:17.0
8,-12,6:17.0
8,-11,6:17.0
8,-10,6:17.0
8,11,6:17.0
8,12,6:17.0
8,13,6:17.0
8,15,6:18.0
9,-16,6:17.0
9,12,6:17.0
9,13,6:17.0
9,14,6:17.0
10,11,6:18.0
10,13,6:17.0
10,14,6:17.0
10,15,6:17.0
11,13,6:17.0
11,14,6:17.0
11,15,6:17.0
11,16,6:17.0
12,13,6:17.0
12,14,6:17.0
12,15,6:17.0
13,14,6:17.0
-15,5,7:17.0
-14,4,7:17.0
-14,5,7:17.0
-14,6,7:17.0
-13,5,7:17.0
-12,1,7:17.0
-12,2,7:17.0
-12,3,7:17.0
-12,5,7:17.0
-11,1,7:17.0
-11,2,7:17.0
-11,3,7:17.0
-11,4,7:17.0
-11,5,7:17.0
-11,6,7:17.0
-11,8,7:17.0
-10,1,7:17.0
-10,2,7:17.0
-10,3,7:17.0
-10,4,7:17.0
-10,5,7:17.0
-10,7,7:17.0
-10,8,7:17.0
-10,9,7:17.0
-9,-4,7:17.0
-9,0,7:17.0
-9,1,7:17.0
-9,2,7:17.0
-9,3,7:17.0
-9,4,7:17.0
-9,8,7:17.0
-9,9,7:17.0
-9,10,7:17.0
-8,-5,7:17.0
-8,-4,7:17.0
-8,-3,7:17.0
-8,0,7:17.0
-8,1,7:17.0
-8,2,7:17.0
-8,3,7:17.0
-8,4,7:17.0
-8,5,7:17.0
-8,6,7:17.0
-8,9,7:17.0
-7,-5,7:18.0
-7,-4,7:17.0
-7,-3,7:17.0
-7,-2,7:17.0
-7,-1,7:17.0
-7,0,7:17.0
-7,1,7:17.0
-7,2,7:17.0
-7,3,7:17.0
-7,4,7:17.0
-7,5,7:17.0
-7,6,7:17.0
-7,7,7:17.0
-7,9,7:17.0
-6,-5,7:18.0
-6,-4,7:17.0
-6,-3,7:17.0
-6,-2,7:17.0
-6,4,7:17.0
-6,5,7:17.0
-6,6,7:17.0
-6,7,7:17.0
-6,8,7:17.0
-6,9,7:17.0
-6,10,7:17.0
-6,11,7:17.0
-5,-5,7:17.0
-5,-4,7:17.0
-5,-3,7:17.0
-5,-2,7:17.0
-5,5,7:17.0
-5,6,7:17.0
-5,7,7:17.0
-5,8,7:17.0
-5,9,7:17.0
-5,10,7:17.0
-5,11,7:17.0
-5,12,7:17.0
-5,13,7:17.0
-4,-6,7:17.0
-4,-5,7:17.0
-4,-4,7:17.0
-4,-3,7:17.0
-4,6,7:17.0
-4,7,7:17.0
-4,8,7:17.0
-4,11,7:17.0
-4,12,7:17.0
-4,13,7:17.0
-4,14,7:17.0
-3,-5,7:17.0
-3,-4,7:17.0
-3,-3,7:17.0
-3,6,7:17.0
-3,7,7:17.0
-3,8,7:17.0
-3,13,7:17.0
-2,-5,7:17.0
-2,-4,7:17.0
-2,6,7:17.0
-2,7,7:17.0
-2,8,7:17.0
-1,-6,7:17.0
-1,-5,7:17.0
-1,-4,7:17.0
-1,-3,7:17.0
-1,5,7:17.0
-1,6,7:17.0
0,-5,7:17.0
0,-3,7:17.0
0,-2,7:17.0
0,-1,7:17.0
0,0,7:17.0
0,4,7:17.0
0,5,7:17.0
0,6,7:17.0
0,7,7:17.0
1,-4,7:17.0
1,-2,7:17.0
1,-1,7:17.0
1,0,7:17.0
1,3,7:17.0
1,4,7:17.0
1,5,7:17.0
1,6,7:17.0
2,-5,7:17.0
2,-4,7:17.0
2,-3,7:17.0
2,-2,7:17.0
2,-1,7:17.0
2,0,7:17.0
2,1,7:17.0
2,2,7:17.0
2,3,7:17.0
2,4,7:17.0
2,5,7:17.0
3,-5,7:17.0
3,-4,7:17.0
3,-3,7:17.0
3,-2,7:17.0
3,-1,7:17.0
3,0,7:17.0
3,3,7:17.0
4,-5,7:17.0
4,-4,7:17.0
4,-3,7:17.0
4,10,7:17.0
5,-10,7:17.0
5,-6,7:18.0
5,9,7:17.0
5,10,7:17.0
5,11,7:17.0
6,-14,7:17.0
6,-13,7:17.0
6,-11,7:17.0
6,-10,7:17.0
6,-9,7:17.0
6,9,7:17.0
6,10,7:17.0
6,11,7:17.0
6,12,7:17.0
7,-15,7:17.0
7,-14,7:17.0
7,-13,7:17.0
7,-12,7:17.0
7,-11,7:17.0
7,-10,7:17.0
7,9,7:17.0
7,10,7:17.0
7,11,7:17.0
7,12,7:17.0
7,13,7:17.0
8,-14,7:17.0
8,-13,7:17.0
8,-11,7:17.0
8,10,7:17.0
8,11,7:17.0
8,12,7:17.0
8,13,7:17.0
8,14,7:17.0
8,15,7:18.0
9,11,7:17.0
9,12,7:17.0
9,13,7:17.0
9,14,7:17.0
9,15,7:17.0
10,11,7:18.0
10,12,7:17.0
10,13,7:17.0
10,14,7:17.0
10,15,7:17.0
11,13,7:17.0
11,14,7:17.0
11,15,7:17.0
12,14,7:17.0
-12,2,8:17.0
-12,4,8:17.0
-12,5,8:17.0
-12,6,8:17.0
-11,1,8:17.0
-11,2,8:17.0
-11,3,8:17.0
-11,4,8:17.0
-11,5,8:17.0
-11,6,8:17.0
-10,2,8:17.0
-10,3,8:17.0
-10,4,8:17.0
-10,5,8:17.0
-10,6,8:17.0
-9,1,8:17.0
-9,2,8:17.0
-9,3,8:17.0
-9,4,8:17.0
-9,5,8:17.0
-8,-2,8:17.0
-8,0,8:17.0
-8,1,8:17.0
-8,2,8:17.0
-8,4,8:17.0
-8,5,8:17.0
-8,6,8:17.0
-8,7,8:17.0
-7,-3,8:17.0
-7,-2,8:17.0
-7,-1,8:17.0
-7,1,8:17.0
-7,3,8:17.0
-7,4,8:17.0
-7,5,8:17.0
-7,6,8:17.0
-7,7,8:17.0
-7,8,8:17.0
-7,9,8:17.0
-7,10,8:17.0
-6,-4,8:17.0
-6,-3,8:17.0
-6,-2,8:17.0
-6,4,8:17.0
-6,5,8:17.0
-6,6,8:17.0
-6,7,8:17.0
-6,8,8:17.0
-6,9,8:17.0
-6,10,8:17.0
-6,11,8:17.0
-5,-4,8:17.0
-5,-3,8:17.0
-5,-2,8:17.0
-5,4,8:17.0
-5,5,8:17.0
-5,6,8:17.0
-5,7,8:17.0
-5,8,8:17.0
-5,9,8:17.0
-5,10,8:17.0
-4,-5,8:17.0
-4,-4,8:17.0
-4,-3,8:17.0
-4,-2,8:17.0
-4,6,8:17.0
-4,7,8:17.0
-4,8,8:17.0
-4,9,8:17.0
-3,-5,8:17.0
-3,-4,8:17.0
-3,-3,8:17.0
-3,6,8:17.0
-3,7,8:17.0
-3,8,8:17.0
-2,-5,8:17.0
-2,-4,8:17.0
-2,-3,8:17.0
-2,5,8:17.0
-2,6,8:17.0
-2,7,8:17.0
-1,-3,8:17.0
-1,5,8:17.0
-1,6,8:17.0
0,-3,8:17.0
0,-1,8:17.0
0,3,8:17.0
0,4,8:17.0
0,5,8:17.0
1,-3,8:17.0
1,-2,8:17.0
1,-1,8:17.0
1,0,8:17.0
1,1,8:17.0
1,2,8:17.0
1,3,8:17.0
1,4,8:17.0
1,5,8:17.0
2,-8,8:18.0
2,-4,8:17.0
2,-3,8:17.0
2,-2,8:17.0
2,-1,8:17.0
2,0,8:17.0
2,1,8:17.0
2,2,8:17.0
2,3,8:17.0
2,4,8:17.0
2,5,8:17.0
3,-8,8:18.0
3,-5,8:17.0
3,-4,8:17.0
3,-3,8:17.0
3,-2,8:17.0
3,-1,8:17.0
3,1,8:17.0
3,2,8:17.0
3,3,8:17.0
3,4,8:17.0
4,-4,8:17.0
5,-6,8:18.0
5,10,8:17.0
6,-6,8:18.0
6,9,8:17.0
6,10,8:17.0
6,11,8:17.0
7,10,8:17.0
7,11,8:17.0
7,12,8:17.0
8,11,8:17.0
8,12,8:17.0
8,13,8:17.0
8,14,8:18.0
8,15,8:18.0
9,11,8:18.0
9,12,8:17.0
9,13,8:17.0
9,14,8:17.0
10,11,8:18.0
10,12,8:18.0
10,13,8:17.0
10,14,8:17.0
10,15,8:17.0
11,14,8:17.0
-12,5,9:17.0
-11,2,9:17.0
-11,3,9:17.0
-11,4,9:17.0
-11,5,9:17.0
-11,6,9:17.0
-10,2,9:17.0
-10,3,9:17.0
-10,4,9:17.0
-10,5,9:17.0
-9,2,9:17.0
-9,3,9:17.0
-9,4,9:17.0
-8,-3,9:17.0
-8,-2,9:17.0
-8,-1,9:17.0
-8,0,9:17.0
-8,1,9:17.0
-8,2,9:17.0
-8,3,9:17.0
-8,4,9:17.0
-8,5,9:17.0
-8,6,9:17.0
-7,-3,9:17.0
-7,-2,9:17.0
-7,-1,9:17.0
-7,2,9:17.0
-7,3,9:17.0
-7,4,9:17.0
-7,5,9:17.0
-7,6,9:17.0
-7,7,9:17.0
-7,9,9:17.0
-7,10,9:17.0
-7,11,9:17.0
-6,-4,9:17.0
-6,-3,9:17.0
-6,-2,9:17.0
-6,-1,9:17.0
-6,3,9:17.0
-6,4,9:17.0
-6,5,9:17.0
-6,6,9:17.0
-6,7,9:17.0
-6,8,9:17.0
-6,9,9:17.0
-6,10,9:17.0
-6,11,9:17.0
-5,-4,9:17.0
-5,-3,9:17.0
-5,-2,9:17.0
-5,5,9:17.0
-5,6,9:17.0
-5,7,9:17.0
-5,8,9:17.0
-5,9,9:17.0
-5,10,9:17.0
-5,11,9:17.0
-4,-5,9:17.0
-4,-4,9:17.0
-4,-3,9:17.0
-4,6,9:17.0
-4,7,9:17.0
-4,8,9:17.0
-3,-5,9:17.0
-3,-4,9:17.0
-3,-3,9:17.0
-3,5,9:17.0
-3,6,9:17.0
-3,7,9:17.0
-3,8,9:17.0
-3,9,9:17.0
-2,-4,9:17.0
-2,5,9:17.0
-2,6,9:17.0
-2,7,9:17.0
-2,8,9:17.0
-1,-3,9:17.0
-1,5,9:17.0
-1,6,9:17.0
-1,7,9:17.0
0,-3,9:17.0
0,-2,9:17.0
0,4,9:17.0
0,5,9:17.0
1,-3,9:17.0
1,-2,9:17.0
1,-1,9:17.0
1,0,9:17.0
1,1,9:17.0
1,2,9:17.0
1,3,9:17.0
1,4,9:17.0
1,5,9:17.0
2,-8,9:18.0
2,-3,9:17.0
2,-2,9:17.0
2,-1,9:17.0
2,0,9:17.0
2,1,9:17.0
2,2,9:17.0
2,3,9:17.0
2,4,9:17.0
3,-9,9:18.0
3,-8,9:18.0
3,-2,9:17.0
3,0,9:17.0
3,1,9:17.0
3,2,9:17.0
3,3,9:17.0
4,-7,9:18.0
5,-7,9:18.0
5,-6,9:17.0
5,-5,9:18.0
6,-7,9:18.0
6,-6,9:17.0
7,-6,9:18.0
7,-5,9:18.0
8,12,9:18.0
8,13,9:18.0
8,14,9:18.0
9,12,9:18.0
9,13,9:18.0
-11,3,10:17.0
-10,2,10:17.0
-10,3,10:17.0
-10,4,10:17.0
-9,1,10:17.0
-9,2,10:17.0
-9,3,10:17.0
-9,4,10:17.0
-8,-2,10:17.0
-8,0,10:17.0
-8,1,10:17.0
-8,2,10:17.0
-8,3,10:17.0
-8,4,10:17.0
-8,7,10:18.0
-7,-4,10:17.0
-7,-3,10:17.0
-7,-2,10:17.0
-7,-1,10:17.0
-7,1,10:17.0
-7,2,10:17.0
-7,3,10:17.0
-7,4,10:17.0
-7,5,10:17.0
-7,6,10:17.0
-7,7,10:17.0
-7,10,10:17.0
-6,-4,10:17.0
-6,-3,10:17.0
-6,-2,10:17.0
-6,4,10:17.0
-6,5,10:17.0
-6,6,10:17.0
-6,7,10:17.0
-6,9,10:17.0
-6,10,10:17.0
-6,11,10:17.0
-5,-5,10:17.0
-5,-4,10:17.0
-5,-3,10:17.0
-5,-2,10:17.0
-5,5,10:17.0
-5,6,10:17.0
-5,7,10:17.0
-5,10,10:17.0
-4,-5,10:17.0
-4,-4,10:17.0
-4,-3,10:17.0
-4,5,10:17.0
-4,6,10:17.0
-4,7,10:17.0
-4,8,10:17.0
-4,9,10:17.0
-3,-5,10:17.0
-3,-4,10:17.0
-3,-3,10:17.0
-3,5,10:17.0
-3,6,10:17.0
-3,7,10:17.0
-3,8,10:17.0
-3,9,10:17.0
-2,-4,10:17.0
-2,-2,10:17.0
-2,5,10:17.0
-2,6,10:17.0
-2,7,10:17.0
-2,8,10:17.0
-2,9,10:17.0
-1,-3,10:17.0
-1,-2,10:17.0
-1,-1,10:17.0
-1,5,10:17.0
-1,6,10:17.0
0,-4,10:17.0
0,-3,10:17.0
0,-2,10:17.0
0,-1,10:17.0
0,5,10:17.0
1,-3,10:17.0
1,-2,10:17.0
1,-1,10:17.0
1,1,10:17.0
1,3,10:17.0
1,4,10:17.0
2,-8,10:18.0
2,-3,10:17.0
2,-2,10:17.0
2,-1,10:17.0
2,0,10:17.0
2,1,10:17.0
2,2,10:17.0
3,-9,10:18.0
3,-8,10:17.0
3,-1,10:17.0
3,1,10:17.0
4,-8,10:18.0
4,-7,10:17.0
5,-7,10:18.0
6,-7,10:18.0
-10,3,11:17.0
-9,0,11:17.0
-9,2,11:17.0
-9,3,11:17.0
-9,4,11:17.0
-8,-1,11:17.0
-8,0,11:17.0
-8,1,11:17.0
-8,2,11:17.0
-8,3,11:17.0
-8,4,11:17.0
-8,7,11:18.0
-7,-5,11:17.0
-7,-3,11:17.0
-7,-2,11:17.0
-7,-1,11:17.0
-7,0,11:17.0
-7,2,11:17.0
-7,3,11:17.0
-7,4,11:17.0
-7,5,11:17.0
-7,6,11:17.0
-7,7,11:18.0
-7,8,11:18.0
-6,-11,11:18.0
-6,-6,11:17.0
-6,-5,11:17.0
-6,-4,11:17.0
-6,-3,11:17.0
-6,-2,11:17.0
-6,4,11:17.0
-6,5,11:17.0
-6,6,11:17.0
-6,7,11:17.0
-5,-5,11:17.0
-5,-4,11:17.0
-5,-3,11:17.0
-5,4,11:17.0
-5,5,11:17.0
-5,6,11:17.0
-4,-5,11:17.0
-4,-4,11:17.0
-4,-3,11:17.0
-4,5,11:17.0
-4,6,11:17.0
-4,8,11:17.0
-3,-4,11:17.0
-3,5,11:17.0
-3,6,11:17.0
-3,7,11:17.0
-3,8,11:17.0
-3,9,11:17.0
-2,-4,11:17.0
-2,-3,11:17.0
-2,-2,11:17.0
-2,-1,11:17.0
-2,6,11:17.0
-2,8,11:17.0
-1,-5,11:17.0
-1,-4,11:17.0
-1,-3,11:17.0
-1,-2,11:17.0
-1,-1,11:17.0
-1,5,11:17.0
0,-4,11:17.0
0,-3,11:17.0
0,-2,11:17.0
0,-1,11:17.0
0,4,11:17.0
0,5,11:17.0
1,-4,11:17.0
1,-3,11:17.0
1,-2,11:17.0
1,-1,11:17.0
1,0,11:17.0
1,3,11:17.0
2,-2,11:17.0
2,-1,11:17.0
2,0,11:17.0
2,1,11:17.0
2,2,11:17.0
3,-9,11:18.0
3,-2,11:17.0
3,-1,11:17.0
3,0,11:17.0
4,-8,11:18.0
-10,2,12:17.0
-10,3,12:17.0
-10,4,12:17.0
-9,-1,12:17.0
-9,0,12:17.0
-9,1,12:17.0
-9,2,12:17.0
-9,3,12:17.0
-9,4,12:17.0
-8,-1,12:17.0
-8,0,12:17.0
-8,1,12:17.0
-8,2,12:17.0
-8,3,12:17.0
-8,4,12:17.0
-8,5,12:17.0
-8,7,12:18.0
-7,-6,12:17.0
-7,-5,12:17.0
-7,-4,12:17.0
-7,-2,12:17.0
-7,-1,12:17.0
-7,0,12:17.0
-7,1,12:17.0
-7,3,12:17.0
-7,4,12:17.0
-7,5,12:17.0
-7,6,12:17.0
-7,7,12:17.0
-7,8,12:18.0
-6,-11,12:18.0
-6,-6,12:17.0
-6,-5,12:17.0
-6,-4,12:17.0
-6,-3,12:17.0
-6,3,12:17.0
-6,4,12:17.0
-6,5,12:17.0
-6,6,12:17.0
-6,7,12:17.0
-5,-6,12:17.0
-5,-5,12:17.0
-5,-4,12:17.0
-5,-3,12:17.0
-5,-2,12:17.0
-5,4,12:17.0
-5,5,12:17.0
-5,6,12:17.0
-5,7,12:17.0
-4,-5,12:17.0
-4,-4,12:17.0
-4,-3,12:17.0
-4,5,12:17.0
-4,6,12:17.0
-3,-4,12:17.0
-3,6,12:17.0
-2,-5,12:17.0
-2,-4,12:17.0
-2,-3,12:17.0
-2,-2,12:17.0
-2,6,12:17.0
-1,-5,12:17.0
-1,-4,12:17.0
-1,-3,12:17.0
-1,-2,12:17.0
-1,-1,12:17.0
-1,5,12:17.0
0,-5,12:17.0
0,-4,12:17.0
0,-3,12:17.0
0,-2,12:17.0
0,4,12:17.0
1,-3,12:17.0
1,-2,12:17.0
1,-1,12:17.0
1,0,12:17.0
1,1,12:17.0
1,3,12:17.0
2,-2,12:17.0
2,-1,12:17.0
2,0,12:17.0
2,1,12:17.0
2,2,12:17.0
3,-1,12:17.0
3,0,12:17.0
3,1,12:17.0
-10,3,13:17.0
-9,0,13:17.0
-9,2,13:17.0
-9,3,13:17.0
-9,4,13:17.0
-8,-1,13:17.0
-8,0,13:17.0
-8,1,13:17.0
-8,2,13:17.0
-8,3,13:17.0
-8,4,13:17.0
-8,7,13:18.0
-7,-5,13:17.0
-7,-3,13:17.0
-7,-2,13:17.0
-7,-1,13:17.0
-7,0,13:17.0
-7,2,13:17.0
-7,3,13:17.0
-7,4,13:17.0
-7,5,13:17.0
-7,6,13:17.0
-7,7,13:18.0
-7,8,13:18.0
-6,-11,13:18.0
-6,-10,13:18.0
-6,-6,13:17.0
-6,-5,13:17.0
-6,-4,13:17.0
-6,-3,13:17.0
-6,-2,13:17.0
-6,3,13:17.0
-6,4,13:17.0
-6,5,13:17.0
-6,6,13:17.0
-6,7,13:17.0
-5,-5,13:17.0
-5,-4,13:17.0
-5,-3,13:17.0
-5,-2,13:17.0
-5,1,13:18.0
-5,4,13:17.0
-5,5,13:17.0
-5,6,13:17.0
-4,-4,13:17.0
-4,-3,13:17.0
-4,-2,13:17.0
-4,5,13:17.0
-4,6,13:17.0
-3,-4,13:17.0
-3,6,13:17.0
-2,-4,13:17.0
-2,-3,13:17.0
-2,6,13:17.0
-1,-5,13:17.0
-1,-4,13:17.0
-1,-3,13:17.0
-1,-2,13:17.0
-1,5,13:17.0
-1,6,13:18.0
0,-4,13:17.0
0,-3,13:17.0
0,4,13:17.0
0,5,13:17.0
1,-3,13:17.0
1,-2,13:17.0
1,-1,13:17.0
1,0,13:17.0
1,3,13:17.0
2,-2,13:17.0
2,-1,13:17.0
2,0,13:17.0
2,1,13:17.0
2,2,13:17.0
2,3,13:18.0
3,-2,13:17.0
3,-1,13:17.0
3,0,13:17.0
7,-16,13:17.0
7,-15,13:17.0
8,-17,13:17.0
8,-16,13:17.0
9,-18,13:18.0
9,-16,13:17.0
10,-18,13:18.0
10,-17,13:18.0
-12,-9,14:18.0
-10,2,14:17.0
-9,-9,14:18.0
-9,1,14:17.0
-9,2,14:17.0
-8,-10,14:18.0
-8,0,14:17.0
-8,1,14:17.0
-8,2,14:17.0
-7,-10,14:18.0
-7,-4,14:17.0
-7,-3,14:17.0
-7,-2,14:17.0
-7,-1,14:17.0
-7,2,14:17.0
-7,5,14:17.0
-7,6,14:18.0
-6,-11,14:18.0
-6,-10,14:17.0
-6,-9,14:18.0
-6,-4,14:17.0
-6,-3,14:17.0
-6,-2,14:17.0
-6,3,14:17.0
-6,4,14:17.0
-5,-4,14:17.0
-5,-3,14:17.0
-5,-2,14:17.0
-5,-1,14:18.0
-5,0,14:18.0
-5,1,14:18.0
-5,4,14:17.0
-4,-5,14:17.0
-4,-4,14:17.0
-4,-3,14:17.0
-4,5,14:17.0
-3,-5,14:17.0
-3,-4,14:17.0
-3,-3,14:17.0
-3,5,14:17.0
-3,6,14:17.0
-3,7,14:17.0
-2,-6,14:17.0
-2,-5,14:17.0
-2,-4,14:17.0
-2,6,14:17.0
-1,-5,14:17.0
-1,5,14:17.0
-1,6,14:18.0
0,-4,14:17.0
0,-2,14:17.0
0,-1,14:17.0
0,5,14:17.0
1,-5,14:17.0
1,-4,14:17.0
1,-3,14:17.0
1,-2,14:17.0
1,-1,14:17.0
1,3,14:17.0
1,4,14:17.0
2,-6,14:17.0
2,-5,14:17.0
2,-4,14:17.0
2,-3,14:17.0
2,-2,14:17.0
2,-1,14:17.0
2,0,14:17.0
2,1,14:17.0
2,2,14:17.0
2,3,14:18.0
3,-5,14:17.0
3,-1,14:17.0
5,-16,14:18.0
6,-18,14:18.0
6,-17,14:18.0
6,-16,14:18.0
6,-15,14:18.0
7,-19,14:18.0
7,-18,14:18.0
7,-17,14:18.0
7,-16,14:18.0
7,-15,14:17.0
8,-20,14:18.0
8,-19,14:18.0
8,-18,14:18.0
8,-17,14:18.0
8,-16,14:17.0
8,-15,14:17.0
9,-20,14:18.0
9,-19,14:18.0
9,-18,14:18.0
9,-17,14:18.0
9,-16,14:17.0
10,-19,14:18.0
10,-18,14:18.0
10,-17,14:18.0
10,-16,14:18.0
11,-18,14:18.0
11,-17,14:18.0
11,-16,14:18.0
11,-15,14:18.0
12,-16,14:18.0
13,-14,14:18.0
14,-14,14:18.0
14,-13,14:18.0
15,-14,14:18.0
15,-13,14:18.0
15,-12,14:18.0
16,-13,14:18.0
-20,19,15:18.0
-19,17,15:18.0
-19,18,15:18.0
-19,19,15:18.0
-19,20,15:18.0
-18,16,15:18.0
-18,17,15:18.0
-18,18,15:18.0
-18,19,15:18.0
-17,17,15:18.0
-14,-9,15:18.0
-12,-9,15:18.0
-10,1,15:17.0
-10,2,15:17.0
-10,3,15:17.0
-9,-10,15:18.0
-9,-9,15:18.0
-9,1,15:17.0
-9,2,15:17.0
-8,-11,15:18.0
-8,-10,15:17.0
-8,0,15:17.0
-8,1,15:17.0
-8,2,15:17.0
-7,-3,15:17.0
-7,-2,15:17.0
-7,-1,15:17.0
-7,2,15:17.0
-7,5,15:17.0
-6,-4,15:17.0
-6,-3,15:17.0
-6,-2,15:17.0
-6,3,15:17.0
-6,4,15:17.0
-5,-5,15:17.0
-5,-4,15:17.0
-5,-3,15:17.0
-5,-1,15:18.0
-5,0,15:17.0
-5,1,15:18.0
-5,4,15:17.0
-4,-5,15:17.0
-4,-4,15:17.0
-4,-3,15:17.0
-4,5,15:17.0
-4,7,15:17.0
-3,-6,15:17.0
-3,-5,15:17.0
-3,-4,15:17.0
-3,-3,15:17.0
-3,5,15:17.0
-3,6,15:17.0
-3,7,15:17.0
-2,-6,15:17.0
-2,-5,15:17.0
-2,-4,15:17.0
-2,-3,15:17.0
-2,5,15:17.0
-2,6,15:17.0
-2,7,15:17.0
-1,-6,15:17.0
-1,-5,15:17.0
-1,-4,15:17.0
-1,-3,15:17.0
-1,5,15:17.0
-1,6,15:18.0
0,-5,15:17.0
0,-4,15:17.0
0,-3,15:17.0
0,-2,15:17.0
0,5,15:17.0
0,6,15:18.0
1,-6,15:17.0
1,-5,15:17.0
1,-4,15:17.0
1,-3,15:17.0
1,-2,15:17.0
1,-1,15:17.0
1,3,15:17.0
1,4,15:17.0
2,-7,15:17.0
2,-6,15:17.0
2,-5,15:17.0
2,-4,15:17.0
2,-3,15:17.0
2,-2,15:17.0
2,0,15:17.0
2,1,15:17.0
2,2,15:17.0
2,3,15:18.0
3,-6,15:17.0
3,-5,15:17.0
3,-4,15:17.0
3,-3,15:17.0
3,-2,15:17.0
3,-1,15:17.0
4,-2,15:17.0
5,-16,15:18.0
5,-15,15:18.0
6,-17,15:18.0
6,-16,15:18.0
6,-15,15:18.0
7,-18,15:18.0
7,-17,15:18.0
7,-16,15:18.0
7,-15,15:18.0
8,-19,15:18.0
8,-18,15:18.0
8,-17,15:18.0
8,-16,15:18.0
8,-15,15:17.0
8,-14,15:17.0
9,-19,15:18.0
9,-18,15:18.0
9,-17,15:18.0
9,-16,15:18.0
10,-18,15:18.0
10,-17,15:18.0
10,-16,15:18.0
10,-15,15:18.0
11,-17,15:18.0
11,-16,15:18.0
11,-15,15:18.0
11,-14,15:18.0
12,-16,15:18.0
12,-15,15:18.0
12,-14,15:18.0
12,-11,15:17.0
12,-10,15:17.0
13,-15,15:18.0
13,-14,15:18.0
13,-13,15:18.0
13,-12,15:17.0
14,-15,15:18.0
14,-14,15:18.0
14,-13,15:18.0
14,-12,15:18.0
14,-11,15:17.0
14,-10,15:17.0
15,-15,15:18.0
15,-14,15:18.0
15,-13,15:18.0
15,-12,15:18.0
15,-11,15:17.0
15,-10,15:17.0
15,-8,15:18.0
16,-14,15:18.0
16,-13,15:18.0
16,-12,15:18.0
16,-11,15:17.0
16,-10,15:17.0
16,-9,15:18.0
16,-8,15:18.0
16,-7,15:18.0
17,-13,15:18.0
17,-10,15:18.0
17,-9,15:18.0
17,-8,15:18.0
17,-7,15:18.0
18,-11,15:18.0
18,-10,15:18.0
18,-9,15:18.0
18,-8,15:18.0
19,-12,15:18.0
19,-11,15:18.0
19,-10,15:18.0
19,-9,15:18.0
20,-11,15:18.0
-20,17,16:18.0
-20,18,16:18.0
-20,19,16:18.0
-20,20,16:18.0
-20,21,16:18.0
-19,16,16:18.0
-19,17,16:18.0
-19,18,16:18.0
-19,19,16:18.0
-19,20,16:18.0
-19,21,16:18.0
-19,22,16:18.0
-18,15,16:18.0
-18,16,16:18.0
-18,17,16:18.0
-18,18,16:18.0
-18,19,16:18.0
-18,20,16:18.0
-18,21,16:18.0
-18,22,16:18.0
-17,16,16:18.0
-17,17,16:18.0
-17,18,16:18.0
-17,19,16:17.0
-17,20,16:17.0
-16,16,16:17.0
-16,17,16:17.0
-16,18,16:17.0
-16,19,16:17.0
-16,21,16:18.0
-15,-6,16:17.0
-15,-4,16:17.0
-15,17,16:17.0
-15,18,16:17.0
-15,19,16:18.0
-15,20,16:18.0
-15,21,16:18.0
-15,22,16:18.0
-14,-9,16:18.0
-14,-8,16:17.0
-14,-2,16:17.0
-14,18,16:18.0
-14,19,16:18.0
-14,20,16:18.0
-14,21,16:18.0
-13,-9,16:18.0
-13,19,16:18.0
-12,-9,16:18.0
-10,-9,16:18.0
-10,2,16:17.0
-9,-10,16:18.0
-9,-9,16:17.0
-9,1,16:17.0
-9,2,16:17.0
-9,3,16:17.0
-8,-10,16:18.0
-8,0,16:17.0
-8,1,16:17.0
-8,2,16:17.0
-7,-2,16:17.0
-7,-1,16:17.0
-7,3,16:17.0
-7,4,16:17.0
-7,5,16:17.0
-7,20,16:18.0
-6,-5,16:17.0
-6,-4,16:17.0
-6,-3,16:17.0
-6,4,16:17.0
-6,5,16:17.0
-6,19,16:18.0
-6,20,16:18.0
-6,21,16:18.0
-5,-5,16:17.0
-5,-4,16:17.0
-5,-3,16:17.0
-5,0,16:18.0
-5,1,16:18.0
-5,4,16:17.0
-5,20,16:18.0
-4,-4,16:17.0
-4,-3,16:17.0
-4,5,16:17.0
-4,20,16:18.0
-3,-5,16:17.0
-3,-4,16:17.0
-3,-3,16:17.0
-3,5,16:17.0
-3,6,16:17.0
-3,7,16:17.0
-3,19,16:18.0
-3,20,16:18.0
-2,-6,16:17.0
-2,-5,16:17.0
-2,-4,16:17.0
-2,-1,16:18.0
-2,6,16:17.0
-2,20,16:18.0
-1,-5,16:17.0
-1,-3,16:17.0
-1,5,16:17.0
0,-4,16:17.0
0,-3,16:17.0
0,5,16:17.0
1,-7,16:17.0
1,-6,16:17.0
1,-5,16:17.0
1,-4,16:17.0
1,-3,16:17.0
1,-2,16:17.0
1,-1,16:17.0
1,3,16:17.0
1,4,16:17.0
2,-7,16:17.0
2,-6,16:17.0
2,-5,16:17.0
2,-4,16:17.0
2,-3,16:17.0
2,-2,16:17.0
2,-1,16:17.0
2,0,16:17.0
2,1,16:17.0
2,2,16:17.0
2,3,16:18.0
3,-7,16:17.0
3,-6,16:17.0
3,-5,16:17.0
3,-3,16:17.0
3,-2,16:17.0
3,-1,16:17.0
4,-6,16:17.0
4,-3,16:17.0
4,-2,16:17.0
4,-1,16:17.0
5,-16,16:18.0
6,-18,16:18.0
6,-17,16:18.0
6,-16,16:18.0
6,-15,16:18.0
6,-13,16:18.0
7,-19,16:18.0
7,-18,16:18.0
7,-17,16:18.0
7,-16,16:18.0
7,-15,16:17.0
7,-14,16:18.0
7,-13,16:18.0
7,-12,16:18.0
8,-20,16:18.0
8,-19,16:18.0
8,-18,16:18.0
8,-17,16:18.0
8,-16,16:17.0
8,-15,16:17.0
8,-14,16:17.0
8,-13,16:18.0
9,-20,16:18.0
9,-19,16:18.0
9,-18,16:18.0
9,-17,16:18.0
9,-16,16:17.0
9,-15,16:17.0
9,-14,16:17.0
9,-11,16:17.0
10,-19,16:18.0
10,-18,16:18.0
10,-17,16:18.0
10,-16,16:18.0
10,-15,16:18.0
10,-14,16:18.0
10,-12,16:17.0
10,-11,16:17.0
10,-10,16:17.0
11,-18,16:18.0
11,-17,16:18.0
11,-16,16:18.0
11,-15,16:18.0
11,-14,16:18.0
11,-11,16:17.0
12,-16,16:18.0
12,-15,16:18.0
12,-14,16:18.0
12,-13,16:18.0
12,-12,16:17.0
12,-11,16:17.0
12,-10,16:17.0
13,-15,16:18.0
13,-14,16:18.0
13,-13,16:18.0
13,-12,16:17.0
13,-11,16:17.0
13,-10,16:17.0
14,-15,16:18.0
14,-14,16:18.0
14,-13,16:18.0
14,-12,16:17.0
14,-11,16:17.0
14,-10,16:17.0
14,-8,16:18.0
15,-15,16:18.0
15,-14,16:18.0
15,-13,16:18.0
15,-12,16:18.0
15,-11,16:17.0
15,-10,16:17.0
15,-9,16:18.0
15,-8,16:18.0
15,-7,16:18.0
16,-15,16:18.0
16,-14,16:18.0
16,-13,16:18.0
16,-12,16:18.0
16,-11,16:17.0
16,-10,16:18.0
16,-9,16:18.0
16,-8,16:18.0
16,-7,16:18.0
17,-14,16:18.0
17,-13,16:18.0
17,-12,16:18.0
17,-11,16:18.0
17,-10,16:18.0
17,-9,16:18.0
17,-8,16:18.0
17,-7,16:18.0
18,-12,16:18.0
18,-11,16:18.0
18,-10,16:18.0
18,-9,16:18.0
18,-8,16:18.0
18,-7,16:18.0
19,-12,16:18.0
19,-11,16:18.0
19,-10,16:18.0
19,-9,16:18.0
19,-8,16:18.0
20,-12,16:18.0
20,-11,16:18.0
20,-10,16:18.0
-27,4,17:18.0
-27,5,17:18.0
-26,3,17:18.0
-26,4,17:18.0
-26,5,17:18.0
-26,6,17:18.0
-25,4,17:18.0
-20,18,17:18.0
-20,19,17:18.0
-20,20,17:18.0
-20,21,17:18.0
-19,15,17:18.0
-19,16,17:18.0
-19,17,17:18.0
-19,18,17:18.0
-19,19,17:18.0
-19,20,17:18.0
-19,21,17:18.0
-19,22,17:18.0
-18,14,17:18.0
-18,15,17:18.0
-18,16,17:18.0
-18,17,17:18.0
-18,18,17:18.0
-18,19,17:18.0
-18,20,17:18.0
-18,21,17:18.0
-18,22,17:18.0
-18,23,17:18.0
-17,15,17:18.0
-17,16,17:18.0
-17,17,17:18.0
-17,18,17:17.0
-17,19,17:18.0
-17,20,17:17.0
-17,22,17:18.0
-16,16,17:17.0
-16,17,17:17.0
-16,18,17:17.0
-16,19,17:17.0
-16,20,17:18.0
-16,21,17:18.0
-16,22,17:18.0
-16,23,17:18.0
-15,-7,17:17.0
-15,-6,17:17.0
-15,-5,17:17.0
-15,-4,17:17.0
-15,-3,17:17.0
-15,16,17:17.0
-15,17,17:17.0
-15,18,17:18.0
-15,19,17:18.0
-15,20,17:18.0
-15,21,17:18.0
-15,22,17:18.0
-14,-9,17:18.0
-14,-8,17:17.0
-14,-2,17:17.0
-14,17,17:17.0
-14,18,17:18.0
-14,19,17:18.0
-14,20,17:18.0
-14,21,17:18.0
-13,-10,17:18.0
-13,-9,17:17.0
-13,-1,17:17.0
-13,18,17:18.0
-13,19,17:18.0
-13,20,17:18.0
-12,-9,17:18.0
-12,19,17:18.0
-9,-9,17:18.0
-9,2,17:17.0
-8,0,17:17.0
-8,1,17:17.0
-8,2,17:17.0
-8,3,17:17.0
-8,4,17:17.0
-8,5,17:17.0
-7,-3,17:17.0
-7,-2,17:17.0
-7,-1,17:17.0
-7,2,17:17.0
-7,3,17:17.0
-7,4,17:17.0
-7,5,17:17.0
-7,19,17:18.0
-7,20,17:18.0
-7,21,17:18.0
-6,-4,17:17.0
-6,-3,17:17.0
-6,-2,17:17.0
-6,5,17:17.0
-6,19,17:18.0
-6,20,17:18.0
-6,21,17:18.0
-6,22,17:18.0
-5,-5,17:17.0
-5,-4,17:17.0
-5,-3,17:17.0
-5,4,17:17.0
-5,19,17:18.0
-5,20,17:18.0
-5,21,17:18.0
-4,-4,17:17.0
-4,5,17:17.0
-4,19,17:18.0
-4,20,17:18.0
-4,21,17:18.0
-3,-4,17:17.0
-3,6,17:17.0
-3,19,17:18.0
-3,20,17:18.0
-3,21,17:18.0
-2,-4,17:17.0
-2,-1,17:18.0
-2,6,17:17.0
-2,19,17:18.0
-2,20,17:18.0
-2,21,17:18.0
-1,-3,17:17.0
-1,5,17:17.0
-1,20,17:18.0
0,-3,17:17.0
0,-2,17:17.0
0,5,17:17.0
1,-6,17:17.0
1,-3,17:17.0
1,-2,17:17.0
1,-1,17:17.0
1,3,17:17.0
1,4,17:17.0
2,-6,17:17.0
2,-5,17:17.0
2,-3,17:17.0
2,-2,17:17.0
2,-1,17:17.0
2,0,17:17.0
2,1,17:17.0
2,2,17:17.0
2,3,17:18.0
2,4,17:18.0
3,-6,17:17.0
3,-5,17:17.0
3,-4,17:17.0
3,-3,17:17.0
3,-2,17:17.0
3,-1,17:17.0
3,2,17:18.0
3,3,17:18.0
4,-6,17:17.0
4,-5,17:17.0
4,-2,17:17.0
5,-8,17:17.0
5,-7,17:17.0
5,-6,17:17.0
6,-18,17:18.0
6,-17,17:18.0
6,-16,17:18.0
6,-14,17:18.0
6,-13,17:18.0
6,-12,17:18.0
6,-9,17:17.0
6,-8,17:17.0
6,-7,17:17.0
6,-6,17:17.0
7,-19,17:18.0
7,-18,17:18.0
7,-17,17:18.0
7,-16,17:18.0
7,-15,17:17.0
7,-14,17:18.0
7,-13,17:18.0
7,-12,17:18.0
7,-10,17:17.0
7,-9,17:17.0
7,-8,17:17.0
7,-7,17:17.0
8,-18,17:18.0
8,-17,17:18.0
8,-16,17:18.0
8,-15,17:17.0
8,-14,17:18.0
8,-13,17:18.0
8,-12,17:18.0
8,-11,17:17.0
8,-9,17:17.0
9,-17,17:18.0
9,-16,17:18.0
9,-15,17:18.0
9,-14,17:17.0
9,-13,17:18.0
9,-12,17:17.0
9,-11,17:17.0
9,-10,17:17.0
10,-18,17:18.0
10,-16,17:18.0
10,-15,17:18.0
10,-14,17:18.0
10,-12,17:17.0
10,-11,17:17.0
10,-10,17:17.0
11,-16,17:18.0
11,-15,17:18.0
11,-14,17:18.0
11,-13,17:18.0
11,-12,17:17.0
11,-11,17:17.0
12,-15,17:18.0
12,-14,17:18.0
12,-13,17:18.0
12,-12,17:18.0
12,-11,17:17.0
13,-15,17:18.0
13,-14,17:18.0
13,-13,17:18.0
13,-12,17:18.0
13,-11,17:17.0
13,-10,17:18.0
14,-14,17:18.0
14,-13,17:18.0
14,-12,17:18.0
14,-11,17:18.0
14,-10,17:18.0
14,-9,17:18.0
14,-8,17:18.0
14,-7,17:18.0
15,-15,17:18.0
15,-14,17:18.0
15,-13,17:18.0
15,-12,17:18.0
15,-11,17:18.0
15,-10,17:18.0
15,-9,17:18.0
15,-8,17:18.0
15,-7,17:18.0
16,-14,17:18.0
16,-13,17:18.0
16,-12,17:18.0
16,-11,17:18.0
16,-10,17:18.0
16,-9,17:18.0
16,-8,17:18.0
16,-7,17:18.0
17,-13,17:18.0
17,-11,17:18.0
17,-10,17:18.0
17,-9,17:18.0
17,-8,17:18.0
17,-7,17:18.0
18,-11,17:18.0
18,-10,17:18.0
18,-9,17:18.0
18,-8,17:18.0
19,-12,17:18.0
19,-11,17:18.0
19,-10,17:18.0
19,-9,17:18.0
20,-11,17:18.0
-29,3,18:18.0
-29,4,18:18.0
-28,2,18:18.0
-28,3,18:18.0
-28,4,18:18.0
-28,5,18:18.0
-27,1,18:18.0
-27,2,18:18.0
-27,3,18:18.0
-27,4,18:18.0
-27,5,18:18.0
-27,6,18:18.0
-26,1,18:18.0
-26,3,18:18.0
-26,4,18:18.0
-26,5,18:18.0
-26,6,18:18.0
-26,7,18:18.0
-25,0,18:18.0
-25,1,18:18.0
-25,2,18:18.0
-25,3,18:18.0
-25,4,18:18.0
-25,5,18:18.0
-24,1,18:18.0
-20,20,18:18.0
-19,15,18:18.0
-19,16,18:18.0
-19,18,18:18.0
-19,19,18:18.0
-19,20,18:18.0
-19,21,18:18.0
-18,14,18:18.0
-18,15,18:18.0
-18,16,18:18.0
-18,17,18:18.0
-18,18,18:18.0
-18,19,18:18.0
-18,20,18:18.0
-18,21,18:18.0
-18,22,18:18.0
-17,14,18:18.0
-17,15,18:18.0
-17,16,18:18.0
-17,17,18:17.0
-17,18,18:18.0
-17,19,18:18.0
-17,20,18:18.0
-17,21,18:18.0
-17,22,18:18.0
-17,23,18:18.0
-16,16,18:17.0
-16,17,18:17.0
-16,18,18:17.0
-16,19,18:17.0
-16,20,18:18.0
-16,21,18:18.0
-16,22,18:18.0
-16,23,18:18.0
-15,-7,18:17.0
-15,-6,18:17.0
-15,-5,18:17.0
-15,-4,18:17.0
-15,-3,18:17.0
-15,15,18:17.0
-15,16,18:17.0
-15,17,18:17.0
-15,18,18:17.0
-15,19,18:18.0
-15,20,18:18.0
-15,21,18:18.0
-15,22,18:18.0
-14,-9,18:18.0
-14,-8,18:17.0
-14,-7,18:17.0
-14,-3,18:17.0
-14,-2,18:17.0
-14,16,18:17.0
-14,17,18:17.0
-14,18,18:18.0
-14,19,18:18.0
-14,20,18:18.0
-14,21,18:18.0
-13,-10,18:18.0
-13,-9,18:18.0
-13,-8,18:17.0
-13,-2,18:17.0
-13,-1,18:17.0
-13,17,18:17.0
-13,18,18:18.0
-13,19,18:18.0
-13,20,18:18.0
-13,21,18:18.0
-12,-9,18:18.0
-12,18,18:18.0
-12,19,18:18.0
-12,20,18:18.0
-9,-3,18:17.0
-9,-2,18:17.0
-9,1,18:17.0
-9,2,18:17.0
-9,3,18:17.0
-9,19,18:18.0
-8,-2,18:17.0
-8,-1,18:17.0
-8,0,18:17.0
-8,1,18:17.0
-8,2,18:17.0
-8,3,18:17.0
-8,18,18:18.0
-8,19,18:18.0
-8,20,18:18.0
-8,21,18:18.0
-7,-4,18:17.0
-7,-3,18:17.0
-7,-2,18:17.0
-7,-1,18:17.0
-7,0,18:17.0
-7,1,18:17.0
-7,2,18:17.0
-7,3,18:17.0
-7,4,18:17.0
-7,17,18:18.0
-7,19,18:18.0
-7,20,18:18.0
-7,21,18:18.0
-7,22,18:18.0
-6,-4,18:17.0
-6,-3,18:17.0
-6,-2,18:17.0
-6,-1,18:17.0
-6,0,18:17.0
-6,5,18:17.0
-6,16,18:18.0
-6,17,18:18.0
-6,18,18:17.0
-6,19,18:17.0
-6,20,18:18.0
-6,21,18:18.0
-6,22,18:18.0
-5,-4,18:17.0
-5,-3,18:17.0
-5,-2,18:17.0
-5,5,18:17.0
-5,6,18:17.0
-5,7,18:17.0
-5,17,18:18.0
-5,18,18:18.0
-5,19,18:17.0
-5,20,18:18.0
-5,21,18:18.0
-5,22,18:18.0
-4,-5,18:17.0
-4,-4,18:17.0
-4,-3,18:17.0
-4,5,18:17.0
-4,6,18:17.0
-4,7,18:17.0
-4,8,18:17.0
-4,18,18:17.0
-4,19,18:18.0
-4,20,18:18.0
-4,21,18:18.0
-4,22,18:18.0
-3,-5,18:17.0
-3,-4,18:17.0
-3,-3,18:17.0
-3,5,18:17.0
-3,6,18:17.0
-3,7,18:17.0
-3,17,18:17.0
-3,18,18:17.0
-3,19,18:18.0
-3,20,18:18.0
-3,21,18:18.0
-3,22,18:18.0
-2,-5,18:17.0
-2,-4,18:17.0
-2,-3,18:17.0
-2,-1,18:18.0
-2,5,18:17.0
-2,6,18:17.0
-2,18,18:17.0
-2,19,18:18.0
-2,20,18:18.0
-2,21,18:18.0
-2,22,18:18.0
-1,-3,18:17.0
-1,5,18:17.0
-1,6,18:17.0
-1,19,18:18.0
-1,20,18:18.0
-1,21,18:18.0
0,-3,18:17.0
0,-2,18:17.0
0,-1,18:17.0
0,4,18:17.0
0,5,18:17.0
0,6,18:17.0
1,-3,18:17.0
1,-2,18:17.0
1,-1,18:17.0
1,0,18:17.0
1,2,18:17.0
1,3,18:17.0
1,4,18:17.0
2,-6,18:17.0
2,-5,18:17.0
2,-4,18:17.0
2,-3,18:17.0
2,-2,18:17.0
2,-1,18:17.0
2,0,18:17.0
2,1,18:17.0
2,2,18:17.0
2,3,18:17.0
2,4,18:17.0
3,-6,18:17.0
3,-5,18:17.0
3,-4,18:17.0
3,-3,18:17.0
3,-2,18:17.0
3,-1,18:17.0
3,2,18:17.0
3,3,18:17.0
4,-6,18:17.0
4,-5,18:17.0
4,-4,18:17.0
4,-3,18:17.0
4,-2,18:17.0
4,-1,18:17.0
5,-8,18:17.0
5,-7,18:17.0
5,-6,18:17.0
5,-5,18:17.0
6,-17,18:18.0
6,-13,18:18.0
6,-10,18:17.0
6,-9,18:17.0
6,-8,18:17.0
6,-7,18:17.0
6,-6,18:17.0
7,-18,18:18.0
7,-17,18:18.0
7,-16,18:18.0
7,-14,18:18.0
7,-13,18:18.0
7,-12,18:18.0
7,-11,18:17.0
7,-10,18:17.0
7,-9,18:17.0
7,-8,18:17.0
7,-7,18:17.0
7,-6,18:17.0
8,-17,18:18.0
8,-16,18:18.0
8,-15,18:18.0
8,-14,18:18.0
8,-13,18:18.0
8,-12,18:18.0
8,-11,18:17.0
8,-10,18:17.0
8,-9,18:17.0
8,-8,18:17.0
9,-17,18:18.0
9,-16,18:18.0
9,-15,18:18.0
9,-14,18:18.0
9,-13,18:18.0
9,-12,18:18.0
9,-11,18:17.0
10,-17,18:18.0
10,-16,18:18.0
10,-15,18:18.0
10,-14,18:18.0
10,-13,18:18.0
10,-12,18:17.0
10,-11,18:17.0
11,-16,18:18.0
11,-15,18:18.0
11,-14,18:18.0
11,-13,18:18.0
11,-12,18:18.0
11,-11,18:18.0
11,-9,18:18.0
12,-14,18:18.0
12,-13,18:18.0
12,-12,18:18.0
12,-11,18:18.0
12,-10,18:18.0
12,-9,18:18.0
12,-8,18:18.0
13,-14,18:18.0
13,-13,18:18.0
13,-12,18:18.0
13,-11,18:18.0
13,-10,18:18.0
13,-9,18:18.0
14,-13,18:18.0
14,-12,18:18.0
14,-11,18:18.0
14,-10,18:18.0
14,-9,18:18.0
14,-8,18:18.0
15,-13,18:18.0
15,-12,18:18.0
15,-11,18:18.0
15,-10,18:18.0
15,-9,18:18.0
15,-8,18:18.0
15,-7,18:18.0
16,-13,18:18.0
16,-12,18:18.0
16,-11,18:18.0
16,-10,18:18.0
16,-9,18:18.0
16,-8,18:18.0
17,-12,18:18.0
17,-11,18:18.0
17,-10,18:18.0
17,-9,18:18.0
18,-10,18:18.0
-30,3,19:18.0
-30,4,19:18.0
-29,2,19:18.0
-29,3,19:18.0
-29,4,19:18.0
-29,5,19:18.0
-28,1,19:18.0
-28,2,19:18.0
-28,3,19:18.0
-28,4,19:18.0
-28,5,19:18.0
-28,6,19:18.0
-27,0,19:18.0
-27,1,19:18.0
-27,2,19:18.0
-27,3,19:18.0
-27,4,19:18.0
-27,5,19:18.0
-27,6,19:18.0
-27,7,19:18.0
-26,0,19:18.0
-26,1,19:18.0
-26,2,19:18.0
-26,3,19:18.0
-26,4,19:18.0
-26,5,19:18.0
-26,6,19:18.0
-26,7,19:18.0
-26,8,19:18.0
-25,0,19:18.0
-25,1,19:18.0
-25,2,19:18.0
-25,3,19:17.0
-25,4,19:18.0
-25,5,19:17.0
-25,6,19:18.0
-25,7,19:18.0
-25,8,19:18.0
-25,9,19:18.0
-24,0,19:18.0
-24,1,19:18.0
-24,2,19:18.0
-24,4,19:17.0
-24,5,19:18.0
-24,6,19:18.0
-24,7,19:18.0
-24,8,19:18.0
-23,6,19:18.0
-19,15,19:18.0
-19,16,19:18.0
-19,17,19:18.0
-19,18,19:18.0
-19,19,19:18.0
-18,14,19:18.0
-18,15,19:18.0
-18,16,19:18.0
-18,17,19:18.0
-18,18,19:18.0
-18,19,19:18.0
-18,20,19:18.0
-18,21,19:18.0
-17,15,19:18.0
-17,16,19:18.0
-17,17,19:18.0
-17,18,19:18.0
-17,19,19:18.0
-17,20,19:18.0
-17,21,19:18.0
-17,22,19:18.0
-16,15,19:17.0
-16,16,19:17.0
-16,17,19:17.0
-16,19,19:18.0
-16,20,19:18.0
-16,21,19:18.0
-16,22,19:18.0
-15,-6,19:17.0
-15,-4,19:17.0
-15,14,19:17.0
-15,15,19:17.0
-15,16,19:17.0
-15,17,19:17.0
-15,18,19:17.0
-15,19,19:18.0
-15,20,19:18.0
-15,21,19:18.0
-15,22,19:18.0
-14,-9,19:18.0
-14,-8,19:17.0
-14,-7,19:17.0
-14,-3,19:17.0
-14,-2,19:17.0
-14,-1,19:18.0
-14,15,19:17.0
-14,16,19:17.0
-14,17,19:17.0
-14,18,19:18.0
-14,19,19:18.0
-14,20,19:18.0
-14,21,19:18.0
-13,-2,19:17.0
-13,-1,19:17.0
-13,18,19:18.0
-13,19,19:18.0
-13,20,19:18.0
-12,0,19:17.0
-12,19,19:18.0
-10,-4,19:17.0
-10,-3,19:17.0
-9,-1,19:17.0
-9,0,19:17.0
-9,2,19:17.0
-9,18,19:18.0
-9,19,19:18.0
-9,20,19:18.0
-8,-4,19:17.0
-8,-3,19:17.0
-8,-1,19:17.0
-8,0,19:17.0
-8,1,19:17.0
-8,2,19:17.0
-8,3,19:17.0
-8,4,19:17.0
-8,17,19:18.0
-8,18,19:18.0
-8,19,19:18.0
-8,20,19:18.0
-8,21,19:18.0
-7,-3,19:17.0
-7,-1,19:17.0
-7,0,19:17.0
-7,1,19:17.0
-7,2,19:17.0
-7,3,19:17.0
-7,4,19:17.0
-7,5,19:17.0
-7,16,19:18.0
-7,17,19:18.0
-7,18,19:18.0
-7,19,19:18.0
-7,20,19:18.0
-7,21,19:18.0
-7,22,19:18.0
-6,-4,19:17.0
-6,-3,19:17.0
-6,-1,19:17.0
-6,0,19:17.0
-6,1,19:17.0
-6,4,19:17.0
-6,5,19:17.0
-6,6,19:17.0
-6,15,19:18.0
-6,16,19:18.0
-6,17,19:18.0
-6,18,19:17.0
-6,19,19:17.0
-6,20,19:17.0
-6,21,19:18.0
-6,22,19:18.0
-6,23,19:18.0
-5,-5,19:17.0
-5,-4,19:17.0
-5,-3,19:17.0
-5,5,19:17.0
-5,6,19:17.0
-5,7,19:17.0
-5,8,19:17.0
-5,14,19:17.0
-5,15,19:17.0
-5,16,19:18.0
-5,17,19:18.0
-5,18,19:17.0
-5,19,19:17.0
-5,20,19:17.0
-5,22,19:18.0
-4,-6,19:17.0
-4,-5,19:17.0
-4,-4,19:17.0
-4,-3,19:17.0
-4,-2,19:17.0
-4,6,19:17.0
-4,7,19:17.0
-4,8,19:17.0
-4,9,19:17.0
-4,15,19:17.0
-4,16,19:17.0
-4,17,19:17.0
-4,18,19:18.0
-4,19,19:18.0
-4,20,19:18.0
-4,21,19:18.0
-4,22,19:18.0
-3,-6,19:17.0
-3,-5,19:17.0
-3,-4,19:17.0
-3,-3,19:17.0
-3,-2,19:17.0
-3,-1,19:18.0
-3,5,19:17.0
-3,6,19:17.0
-3,7,19:17.0
-3,8,19:17.0
-3,16,19:17.0
-3,17,19:17.0
-3,18,19:17.0
-3,19,19:18.0
-3,20,19:18.0
-3,21,19:18.0
-3,22,19:18.0
-2,-6,19:17.0
-2,-5,19:17.0
-2,-4,19:17.0
-2,-3,19:17.0
-2,-2,19:17.0
-2,-1,19:17.0
-2,0,19:18.0
-2,5,19:17.0
-2,6,19:17.0
-2,7,19:17.0
-2,8,19:17.0
-2,17,19:17.0
-2,18,19:17.0
-2,19,19:18.0
-2,20,19:18.0
-2,21,19:18.0
-2,22,19:18.0
-1,-5,19:17.0
-1,-4,19:17.0
-1,-3,19:17.0
-1,-2,19:17.0
-1,-1,19:17.0
-1,4,19:17.0
-1,5,19:17.0
-1,6,19:17.0
-1,7,19:17.0
-1,18,19:18.0
-1,19,19:18.0
-1,20,19:18.0
-1,21,19:18.0
0,-3,19:17.0
0,-2,19:17.0
0,-1,19:17.0
0,0,19:17.0
0,1,19:17.0
0,3,19:17.0
0,4,19:17.0
0,5,19:17.0
0,6,19:17.0
0,7,19:17.0
0,19,19:18.0
1,-3,19:17.0
1,-2,19:17.0
1,-1,19:17.0
1,0,19:17.0
1,1,19:17.0
1,2,19:17.0
1,3,19:17.0
1,4,19:17.0
1,5,19:17.0
1,6,19:17.0
2,-5,19:17.0
2,-4,19:17.0
2,-3,19:17.0
2,-1,19:17.0
2,0,19:17.0
2,1,19:17.0
2,2,19:17.0
2,3,19:17.0
2,4,19:17.0
2,5,19:17.0
3,-6,19:17.0
3,-5,19:17.0
3,-4,19:17.0
3,1,19:17.0
3,2,19:17.0
3,3,19:17.0
3,4,19:17.0
4,-6,19:17.0
4,-5,19:17.0
5,-7,19:17.0
6,-9,19:17.0
6,-8,19:17.0
6,-7,19:17.0
6,-6,19:17.0
7,-15,19:18.0
7,-14,19:18.0
7,-13,19:18.0
7,-10,19:17.0
7,-9,19:17.0
7,-8,19:17.0
7,-7,19:17.0
8,-16,19:18.0
8,-15,19:18.0
8,-14,19:18.0
8,-13,19:18.0
8,-12,19:18.0
8,-11,19:17.0
8,-9,19:17.0
9,-17,19:18.0
9,-16,19:18.0
9,-15,19:18.0
9,-14,19:18.0
9,-13,19:18.0
10,-16,19:18.0
10,-15,19:18.0
10,-14,19:18.0
10,-13,19:18.0
10,-12,19:18.0
10,-11,19:18.0
11,-14,19:18.0
11,-13,19:18.0
11,-12,19:18.0
11,-11,19:18.0
11,-10,19:18.0
11,-9,19:18.0
12,-13,19:18.0
12,-12,19:18.0
12,-11,19:18.0
12,-10,19:18.0
12,-9,19:18.0
13,-13,19:18.0
13,-12,19:18.0
13,-11,19:18.0
13,-10,19:18.0
13,-9,19:18.0
14,-13,19:18.0
14,-12,19:18.0
14,-11,19:18.0
14,-10,19:18.0
14,-9,19:18.0
15,-13,19:18.0
15,-12,19:18.0
15,-11,19:18.0
15,-10,19:18.0
15,-9,19:18.0
15,-8,19:18.0
16,-13,19:18.0
16,-12,19:18.0
16,-11,19:18.0
16,-9,19:18.0
17,-13,19:18.0
17,-12,19:18.0
17,-11,19:18.0
19,5,19:18.0
19,6,19:18.0
20,4,19:18.0
20,5,19:18.0
20,6,19:18.0
20,7,19:18.0
20,8,19:18.0
21,4,19:18.0
21,5,19:18.0
21,6,19:18.0
21,7,19:18.0
21,8,19:18.0
21,9,19:18.0
22,7,19:18.0
22,8,19:18.0
25,6,19:18.0
26,5,19:18.0
26,6,19:18.0
26,7,19:18.0
27,6,19:18.0
-30,2,20:18.0
-30,3,20:18.0
-30,4,20:18.0
-29,2,20:18.0
-29,3,20:18.0
-29,4,20:18.0
-29,5,20:18.0
-29,6,20:18.0
-28,1,20:18.0
-28,2,20:18.0
-28,3,20:18.0
-28,4,20:18.0
-28,5,20:18.0
-28,6,20:18.0
-28,7,20:18.0
-27,0,20:18.0
-27,1,20:18.0
-27,2,20:18.0
-27,3,20:17.0
-27,4,20:17.0
-27,5,20:18.0
-27,6,20:18.0
-27,7,20:18.0
-27,8,20:18.0
-26,0,20:18.0
-26,1,20:18.0
-26,2,20:18.0
-26,3,20:17.0
-26,4,20:17.0
-26,5,20:17.0
-26,6,20:18.0
-26,7,20:18.0
-26,8,20:18.0
-26,9,20:18.0
-25,0,20:18.0
-25,1,20:18.0
-25,2,20:18.0
-25,3,20:17.0
-25,4,20:17.0
-25,5,20:18.0
-25,6,20:18.0
-25,7,20:18.0
-25,8,20:18.0
-24,1,20:18.0
-24,3,20:17.0
-24,4,20:17.0
-24,5,20:18.0
-24,6,20:18.0
-24,7,20:18.0
-24,8,20:18.0
-23,3,20:17.0
-23,4,20:17.0
-23,5,20:18.0
-23,6,20:18.0
-23,7,20:18.0
-23,8,20:18.0
-22,3,20:17.0
-22,4,20:17.0
-22,5,20:17.0
-22,7,20:18.0
-21,4,20:17.0
-19,16,20:18.0
-19,17,20:18.0
-18,5,20:18.0
-18,15,20:18.0
-18,16,20:18.0
-18,17,20:18.0
-18,18,20:18.0
-18,19,20:18.0
-17,11,20:18.0
-17,16,20:18.0
-17,17,20:18.0
-17,18,20:18.0
-17,19,20:18.0
-17,20,20:18.0
-17,21,20:18.0
-16,14,20:17.0
-16,15,20:17.0
-16,16,20:17.0
-16,17,20:18.0
-16,18,20:18.0
-16,19,20:18.0
-16,20,20:18.0
-16,21,20:18.0
-15,13,20:17.0
-15,14,20:17.0
-15,15,20:17.0
-15,16,20:17.0
-15,17,20:17.0
-15,18,20:18.0
-15,19,20:18.0
-15,20,20:18.0
-15,21,20:18.0
-14,-7,20:17.0
-14,-3,20:17.0
-14,-1,20:18.0
-14,12,20:17.0
-14,13,20:17.0
-14,14,20:17.0
-14,15,20:17.0
-14,16,20:17.0
-14,18,20:18.0
-14,19,20:18.0
-14,20,20:18.0
-13,-2,20:17.0
-13,-1,20:17.0
-13,0,20:17.0
-13,13,20:17.0
-13,18,20:18.0
-13,19,20:18.0
-12,0,20:17.0
-10,-5,20:17.0
-10,-4,20:17.0
-10,-3,20:17.0
-10,-2,20:17.0
-10,5,20:17.0
-9,-1,20:17.0
-9,0,20:17.0
-9,2,20:17.0
-9,4,20:17.0
-9,5,20:17.0
-9,6,20:17.0
-9,18,20:18.0
-9,19,20:18.0
-9,20,20:18.0
-9,21,20:18.0
-8,-5,20:17.0
-8,-4,20:17.0
-8,-3,20:17.0
-8,-1,20:17.0
-8,0,20:17.0
-8,1,20:17.0
-8,3,20:17.0
-8,4,20:17.0
-8,5,20:17.0
-8,16,20:18.0
-8,17,20:18.0
-8,18,20:18.0
-8,19,20:18.0
-8,20,20:18.0
-8,21,20:18.0
-7,-3,20:17.0
-7,-1,20:17.0
-7,0,20:17.0
-7,1,20:17.0
-7,3,20:17.0
-7,4,20:17.0
-7,5,20:17.0
-7,6,20:17.0
-7,15,20:18.0
-7,16,20:18.0
-7,17,20:18.0
-7,18,20:18.0
-7,19,20:18.0
-7,20,20:18.0
-7,21,20:18.0
-7,22,20:18.0
-6,-3,20:17.0
-6,-1,20:17.0
-6,0,20:17.0
-6,1,20:17.0
-6,4,20:17.0
-6,5,20:17.0
-6,6,20:17.0
-6,13,20:17.0
-6,14,20:17.0
-6,15,20:18.0
-6,16,20:18.0
-6,17,20:18.0
-6,18,20:18.0
-6,19,20:17.0
-6,20,20:17.0
-6,21,20:18.0
-6,22,20:18.0
-5,-6,20:17.0
-5,-5,20:17.0
-5,-4,20:17.0
-5,-3,20:17.0
-5,6,20:17.0
-5,7,20:17.0
-5,8,20:17.0
-5,9,20:17.0
-5,12,20:17.0
-5,13,20:17.0
-5,14,20:17.0
-5,15,20:18.0
-5,16,20:18.0
-5,17,20:18.0
-5,18,20:18.0
-5,19,20:17.0
-5,20,20:18.0
-5,21,20:18.0
-4,-6,20:17.0
-4,-5,20:17.0
-4,-4,20:17.0
-4,-3,20:17.0
-4,-2,20:17.0
-4,6,20:17.0
-4,7,20:17.0
-4,8,20:17.0
-4,9,20:17.0
-4,13,20:17.0
-4,14,20:17.0
-4,15,20:17.0
-4,16,20:18.0
-4,17,20:18.0
-4,18,20:18.0
-4,19,20:18.0
-4,20,20:18.0
-4,21,20:18.0
-3,-6,20:17.0
-3,-5,20:17.0
-3,-4,20:17.0
-3,-3,20:17.0
-3,-2,20:17.0
-3,4,20:17.0
-3,5,20:17.0
-3,6,20:17.0
-3,7,20:17.0
-3,8,20:17.0
-3,9,20:17.0
-3,15,20:17.0
-3,16,20:18.0
-3,17,20:18.0
-3,18,20:18.0
-3,19,20:18.0
-3,20,20:18.0
-3,21,20:18.0
-2,-6,20:17.0
-2,-5,20:17.0
-2,-4,20:17.0
-2,-3,20:17.0
-2,-2,20:17.0
-2,-1,20:18.0
-2,3,20:17.0
-2,4,20:17.0
-2,5,20:17.0
-2,6,20:17.0
-2,7,20:17.0
-2,8,20:17.0
-2,16,20:17.0
-2,17,20:18.0
-2,18,20:18.0
-2,19,20:18.0
-2,20,20:18.0
-2,21,20:18.0
-1,-5,20:17.0
-1,-4,20:17.0
-1,-3,20:17.0
-1,-2,20:17.0
-1,-1,20:17.0
-1,0,20:17.0
-1,2,20:17.0
-1,3,20:17.0
-1,4,20:17.0
-1,5,20:17.0
-1,6,20:17.0
-1,7,20:17.0
-1,8,20:17.0
-1,18,20:18.0
-1,19,20:18.0
-1,20,20:18.0
0,-3,20:17.0
0,-2,20:17.0
0,-1,20:17.0
0,1,20:17.0
0,2,20:17.0
0,3,20:17.0
0,4,20:17.0
0,5,20:17.0
0,6,20:17.0
0,7,20:17.0
0,18,20:18.0
0,19,20:18.0
1,-4,20:17.0
1,-2,20:17.0
1,-1,20:17.0
1,0,20:17.0
1,2,20:17.0
1,3,20:17.0
1,4,20:17.0
1,5,20:17.0
1,6,20:17.0
2,0,20:17.0
2,1,20:17.0
2,2,20:17.0
2,3,20:17.0
2,4,20:17.0
2,5,20:17.0
2,6,20:17.0
3,-4,20:17.0
3,2,20:17.0
3,3,20:17.0
3,5,20:17.0
3,9,20:18.0
4,4,20:17.0
4,5,20:17.0
4,6,20:17.0
5,5,20:17.0
7,-14,20:18.0
8,-15,20:18.0
8,-14,20:18.0
8,-13,20:18.0
9,-16,20:18.0
9,-15,20:18.0
9,-14,20:18.0
10,-14,20:18.0
10,-13,20:18.0
10,-12,20:18.0
10,-11,20:18.0
10,-10,20:18.0
11,-13,20:18.0
11,-12,20:18.0
11,-11,20:18.0
11,-10,20:18.0
12,-12,20:18.0
12,-11,20:18.0
12,-10,20:18.0
13,-12,20:18.0
13,-11,20:18.0
13,-10,20:18.0
14,-12,20:18.0
14,-11,20:18.0
14,-10,20:18.0
15,-12,20:18.0
15,-11,20:18.0
16,-13,20:18.0
16,-12,20:18.0
16,-11,20:18.0
17,-12,20:18.0
19,4,20:18.0
19,5,20:18.0
19,6,20:18.0
19,7,20:18.0
20,3,20:18.0
20,4,20:18.0
20,5,20:18.0
20,6,20:18.0
20,7,20:18.0
20,8,20:18.0
20,9,20:18.0
21,3,20:18.0
21,4,20:18.0
21,5,20:18.0
21,6,20:18.0
21,7,20:18.0
21,8,20:18.0
21,9,20:18.0
21,10,20:18.0
22,3,20:18.0
22,4,20:18.0
22,5,20:18.0
22,6,20:18.0
22,7,20:18.0
22,8,20:18.0
22,9,20:18.0
23,4,20:18.0
23,6,20:17.0
23,9,20:18.0
23,10,20:18.0
24,3,20:18.0
24,4,20:18.0
24,5,20:18.0
24,6,20:18.0
25,4,20:18.0
25,5,20:18.0
25,6,20:18.0
25,7,20:18.0
26,5,20:18.0
26,6,20:18.0
26,7,20:18.0
27,5,20:18.0
27,6,20:18.0
27,7,20:18.0
-30,3,21:18.0
-30,4,21:18.0
-30,5,21:18.0
-29,2,21:18.0
-29,3,21:18.0
-29,4,21:18.0
-29,5,21:18.0
-29,6,21:18.0
-28,1,21:18.0
-28,2,21:18.0
-28,3,21:18.0
-28,4,21:18.0
-28,5,21:18.0
-28,6,21:18.0
-28,7,21:18.0
-27,0,21:18.0
-27,1,21:18.0
-27,2,21:18.0
-27,4,21:17.0
-27,6,21:18.0
-27,7,21:18.0
-26,0,21:18.0
-26,1,21:18.0
-26,2,21:18.0
-26,3,21:17.0
-26,4,21:17.0
-26,5,21:18.0
-26,6,21:18.0
-26,7,21:18.0
-26,8,21:18.0
-25,0,21:18.0
-25,1,21:18.0
-25,2,21:18.0
-25,3,21:17.0
-25,4,21:17.0
-25,5,21:18.0
-25,6,21:18.0
-25,7,21:18.0
-25,8,21:18.0
-24,0,21:18.0
-24,1,21:18.0
-24,2,21:18.0
-24,3,21:17.0
-24,4,21:17.0
-24,5,21:18.0
-24,6,21:18.0
-24,7,21:18.0
-24,8,21:18.0
-24,9,21:18.0
-23,1,21:18.0
-23,3,21:17.0
-23,4,21:17.0
-23,5,21:18.0
-23,6,21:18.0
-23,7,21:18.0
-23,8,21:18.0
-23,9,21:18.0
-22,3,21:17.0
-22,4,21:17.0
-22,5,21:17.0
-22,6,21:18.0
-22,7,21:18.0
-22,8,21:18.0
-21,3,21:17.0
-21,4,21:17.0
-21,5,21:17.0
-21,6,21:17.0
-21,7,21:17.0
-20,6,21:17.0
-18,5,21:18.0
-18,16,21:18.0
-18,17,21:18.0
-17,11,21:18.0
-17,17,21:18.0
-17,18,21:18.0
-17,19,21:18.0
-17,20,21:18.0
-16,13,21:17.0
-16,14,21:17.0
-16,15,21:17.0
-16,17,21:18.0
-16,18,21:18.0
-16,19,21:18.0
-16,20,21:18.0
-15,12,21:17.0
-15,13,21:17.0
-15,14,21:17.0
-15,15,21:17.0
-15,16,21:17.0
-15,17,21:18.0
-15,18,21:18.0
-15,19,21:18.0
-15,20,21:18.0
-14,-7,21:17.0
-14,-6,21:17.0
-14,-5,21:17.0
-14,-4,21:17.0
-14,-3,21:17.0
-14,-1,21:18.0
-14,11,21:17.0
-14,12,21:17.0
-14,13,21:17.0
-14,14,21:17.0
-14,15,21:17.0
-14,18,21:18.0
-14,19,21:18.0
-13,-7,21:17.0
-13,-3,21:17.0
-13,-2,21:17.0
-13,-1,21:18.0
-13,12,21:17.0
-13,13,21:17.0
-13,14,21:17.0
-12,0,21:17.0
-12,6,21:17.0
-11,5,21:17.0
-11,6,21:17.0
-11,7,21:17.0
-10,-4,21:17.0
-10,-3,21:17.0
-10,-2,21:17.0
-10,-1,21:17.0
-10,4,21:17.0
-10,5,21:17.0
-10,6,21:17.0
-9,-5,21:17.0
-9,-4,21:17.0
-9,-3,21:17.0
-9,-2,21:17.0
-9,-1,21:17.0
-9,0,21:17.0
-9,2,21:17.0
-9,3,21:17.0
-9,4,21:17.0
-9,5,21:17.0
-9,6,21:17.0
-9,20,21:18.0
-8,-4,21:17.0
-8,-3,21:17.0
-8,-2,21:17.0
-8,-1,21:17.0
-8,0,21:17.0
-8,1,21:17.0
-8,3,21:17.0
-8,4,21:17.0
-8,5,21:17.0
-8,6,21:17.0
-8,18,21:18.0
-8,19,21:18.0
-8,20,21:18.0
-8,21,21:18.0
-7,-3,21:17.0
-7,-2,21:17.0
-7,-1,21:17.0
-7,0,21:17.0
-7,3,21:17.0
-7,4,21:17.0
-7,5,21:17.0
-7,16,21:18.0
-7,17,21:18.0
-7,18,21:18.0
-7,20,21:18.0
-6,-9,21:18.0
-6,-6,21:17.0
-6,-5,21:17.0
-6,-4,21:17.0
-6,-3,21:17.0
-6,-2,21:17.0
-6,-1,21:17.0
-6,0,21:17.0
-6,1,21:17.0
-6,3,21:17.0
-6,4,21:17.0
-6,5,21:17.0
-6,6,21:17.0
-6,9,21:17.0
-6,10,21:17.0
-6,11,21:17.0
-6,12,21:17.0
-6,13,21:17.0
-6,14,21:17.0
-6,15,21:18.0
-6,16,21:18.0
-6,17,21:18.0
-6,18,21:18.0
-6,19,21:18.0
-6,20,21:18.0
-5,-7,21:17.0
-5,-6,21:17.0
-5,-5,21:17.0
-5,-4,21:17.0
-5,-3,21:17.0
-5,-2,21:17.0
-5,-1,21:17.0
-5,0,21:17.0
-5,4,21:17.0
-5,5,21:17.0
-5,6,21:17.0
-5,7,21:17.0
-5,8,21:17.0
-5,9,21:17.0
-5,10,21:17.0
-5,11,21:17.0
-5,12,21:17.0
-5,13,21:17.0
-5,14,21:17.0
-5,15,21:17.0
-5,16,21:18.0
-5,17,21:18.0
-5,18,21:18.0
-5,19,21:18.0
-5,21,21:18.0
-4,-7,21:17.0
-4,-6,21:17.0
-4,-5,21:17.0
-4,-4,21:17.0
-4,-3,21:17.0
-4,-2,21:17.0
-4,-1,21:17.0
-4,0,21:17.0
-4,5,21:17.0
-4,6,21:17.0
-4,7,21:17.0
-4,8,21:17.0
-4,9,21:17.0
-4,10,21:17.0
-4,11,21:17.0
-4,12,21:17.0
-4,13,21:17.0
-4,14,21:17.0
-4,15,21:17.0
-4,16,21:18.0
-4,17,21:18.0
-4,18,21:18.0
-4,19,21:18.0
-4,20,21:18.0
-3,-7,21:17.0
-3,-6,21:17.0
-3,-5,21:17.0
-3,-4,21:17.0
-3,-3,21:17.0
-3,-2,21:17.0
-3,-1,21:17.0
-3,0,21:17.0
-3,4,21:17.0
-3,5,21:17.0
-3,6,21:17.0
-3,7,21:17.0
-3,8,21:17.0
-3,16,21:18.0
-3,17,21:18.0
-3,18,21:18.0
-3,19,21:18.0
-3,20,21:18.0
-2,-6,21:17.0
-2,-5,21:17.0
-2,-4,21:17.0
-2,-3,21:17.0
-2,-2,21:17.0
-2,-1,21:17.0
-2,0,21:17.0
-2,1,21:17.0
-2,2,21:17.0
-2,3,21:17.0
-2,4,21:17.0
-2,5,21:17.0
-2,6,21:17.0
-2,7,21:17.0
-2,8,21:17.0
-2,16,21:18.0
-2,17,21:18.0
-2,18,21:18.0
-2,19,21:18.0
-2,20,21:18.0
-1,-5,21:17.0
-1,-4,21:17.0
-1,-3,21:17.0
-1,-2,21:17.0
-1,-1,21:17.0
-1,0,21:17.0
-1,1,21:17.0
-1,2,21:17.0
-1,3,21:17.0
-1,4,21:17.0
-1,5,21:17.0
-1,6,21:17.0
-1,7,21:17.0
-1,8,21:17.0
-1,17,21:18.0
-1,18,21:18.0
-1,19,21:18.0
0,-4,21:17.0
0,-3,21:17.0
0,-2,21:17.0
0,-1,21:17.0
0,0,21:17.0
0,1,21:17.0
0,2,21:17.0
0,3,21:17.0
0,4,21:17.0
0,5,21:17.0
0,6,21:17.0
0,7,21:17.0
1,-1,21:17.0
1,0,21:17.0
1,1,21:17.0
1,2,21:17.0
1,3,21:17.0
1,4,21:17.0
1,5,21:17.0
1,6,21:17.0
2,-1,21:17.0
2,0,21:17.0
2,5,21:17.0
2,6,21:17.0
2,7,21:17.0
3,4,21:17.0
3,5,21:17.0
3,6,21:17.0
3,7,21:17.0
3,8,21:17.0
3,9,21:18.0
4,3,21:17.0
4,4,21:17.0
4,5,21:17.0
4,6,21:17.0
4,7,21:17.0
5,4,21:17.0
5,5,21:17.0
5,6,21:17.0
10,-12,21:18.0
10,-11,21:18.0
11,-12,21:18.0
11,-11,21:18.0
11,17,21:17.0
12,-11,21:18.0
12,16,21:17.0
12,17,21:17.0
12,18,21:17.0
12,20,21:18.0
13,-11,21:18.0
13,17,21:17.0
13,19,21:18.0
13,20,21:18.0
14,18,21:18.0
14,19,21:18.0
15,17,21:18.0
15,18,21:18.0
16,17,21:18.0
19,3,21:18.0
19,4,21:18.0
19,5,21:18.0
19,6,21:18.0
20,2,21:18.0
20,3,21:18.0
20,4,21:18.0
20,5,21:18.0
20,6,21:18.0
20,7,21:18.0
20,8,21:18.0
20,9,21:18.0
21,2,21:18.0
21,3,21:18.0
21,4,21:18.0
21,5,21:18.0
21,6,21:18.0
21,7,21:18.0
21,8,21:18.0
21,9,21:18.0
21,10,21:18.0
22,3,21:18.0
22,4,21:18.0
22,5,21:18.0
22,6,21:17.0
22,7,21:18.0
22,8,21:18.0
22,9,21:18.0
22,10,21:18.0
23,3,21:18.0
23,4,21:18.0
23,5,21:18.0
23,6,21:17.0
23,7,21:17.0
23,8,21:18.0
23,9,21:18.0
23,10,21:18.0
23,11,21:18.0
24,3,21:18.0
24,4,21:18.0
24,5,21:18.0
24,6,21:18.0
24,7,21:18.0
24,9,21:18.0
24,10,21:18.0
25,4,21:18.0
25,5,21:18.0
25,6,21:18.0
25,7,21:18.0
26,5,21:18.0
26,6,21:18.0
26,7,21:18.0
27,6,21:18.0
-30,4,22:18.0
-29,3,22:18.0
-29,4,22:18.0
-29,5,22:18.0
-28,4,22:18.0
-27,1,22:18.0
-27,2,22:18.0
-27,3,22:18.0
-27,4,22:18.0
-27,5,22:18.0
-27,6,22:18.0
-27,7,22:18.0
-26,0,22:18.0
-26,1,22:18.0
-26,2,22:18.0
-26,3,22:18.0
-26,4,22:18.0
-26,5,22:18.0
-26,6,22:18.0
-26,7,22:18.0
-25,0,22:18.0
-25,1,22:18.0
-25,2,22:18.0
-25,4,22:18.0
-25,5,22:18.0
-25,6,22:18.0
-25,7,22:18.0
-25,8,22:18.0
-24,0,22:18.0
-24,1,22:18.0
-24,2,22:18.0
-24,3,22:17.0
-24,4,22:17.0
-24,5,22:18.0
-24,6,22:18.0
-24,7,22:18.0
-24,8,22:18.0
-24,9,22:18.0
-23,0,22:18.0
-23,1,22:18.0
-23,2,22:18.0
-23,3,22:17.0
-23,4,22:18.0
-23,5,22:18.0
-23,6,22:18.0
-23,7,22:18.0
-23,8,22:18.0
-22,3,22:17.0
-22,4,22:17.0
-22,5,22:18.0
-22,6,22:18.0
-22,7,22:18.0
-22,8,22:17.0
-21,4,22:17.0
-21,5,22:17.0
-21,6,22:17.0
-21,7,22:17.0
-21,8,22:17.0
-20,5,22:17.0
-20,6,22:17.0
-20,7,22:17.0
-19,5,22:18.0
-19,6,22:17.0
-19,7,22:17.0
-19,8,22:17.0
-18,5,22:18.0
-18,7,22:17.0
-18,10,22:18.0
-17,9,22:17.0
-17,10,22:18.0
-17,11,22:18.0
-16,8,22:17.0
-16,9,22:17.0
-16,10,22:17.0
-16,14,22:17.0
-16,17,22:18.0
-16,18,22:18.0
-16,19,22:18.0
-15,-5,22:17.0
-15,8,22:17.0
-15,9,22:17.0
-15,10,22:17.0
-15,11,22:17.0
-15,12,22:17.0
-15,13,22:17.0
-15,14,22:17.0
-15,15,22:17.0
-15,18,22:18.0
-15,19,22:18.0
-14,-6,22:17.0
-14,-5,22:17.0
-14,-4,22:17.0
-14,9,22:17.0
-14,10,22:17.0
-14,11,22:17.0
-14,12,22:17.0
-14,13,22:17.0
-14,14,22:17.0
-13,-6,22:17.0
-13,-5,22:17.0
-13,-4,22:17.0
-13,8,22:17.0
-13,9,22:17.0
-13,10,22:17.0
-13,11,22:17.0
-13,12,22:17.0
-13,13,22:17.0
-12,-9,22:18.0
-12,0,22:17.0
-12,5,22:17.0
-12,6,22:17.0
-12,7,22:17.0
-12,9,22:17.0
-11,4,22:17.0
-11,5,22:17.0
-11,6,22:17.0
-11,7,22:17.0
-11,8,22:17.0
-10,-2,22:17.0
-10,4,22:17.0
-10,5,22:17.0
-10,6,22:17.0
-10,7,22:17.0
-9,-3,22:17.0
-9,-2,22:17.0
-9,-1,22:17.0
-9,0,22:17.0
-9,1,22:17.0
-9,2,22:17.0
-9,4,22:17.0
-9,5,22:17.0
-9,6,22:17.0
-8,-2,22:17.0
-8,-1,22:17.0
-8,0,22:17.0
-8,1,22:17.0
-8,2,22:17.0
-8,3,22:17.0
-8,4,22:17.0
-8,5,22:17.0
-7,-3,22:17.0
-7,-2,22:17.0
-7,-1,22:17.0
-7,0,22:17.0
-7,1,22:17.0
-7,2,22:17.0
-7,4,22:17.0
-7,5,22:17.0
-7,6,22:17.0
-6,-9,22:18.0
-6,-8,22:17.0
-6,-6,22:17.0
-6,-5,22:17.0
-6,-4,22:17.0
-6,-3,22:17.0
-6,-2,22:17.0
-6,-1,22:17.0
-6,0,22:17.0
-6,1,22:17.0
-6,2,22:17.0
-6,3,22:17.0
-6,4,22:17.0
-6,5,22:17.0
-6,6,22:17.0
-6,7,22:17.0
-6,8,22:17.0
-6,9,22:17.0
-6,10,22:17.0
-6,11,22:17.0
-6,12,22:17.0
-6,13,22:17.0
-6,14,22:17.0
-6,18,22:18.0
-5,-9,22:17.0
-5,-8,22:17.0
-5,-7,22:17.0
-5,-6,22:17.0
-5,-5,22:17.0
-5,-4,22:17.0
-5,-3,22:17.0
-5,-2,22:17.0
-5,-1,22:17.0
-5,0,22:17.0
-5,1,22:17.0
-5,5,22:17.0
-5,6,22:17.0
-5,7,22:17.0
-5,8,22:17.0
-5,9,22:17.0
-5,10,22:17.0
-5,11,22:17.0
-5,12,22:17.0
-5,13,22:17.0
-5,14,22:17.0
-5,15,22:17.0
-5,17,22:18.0
-5,18,22:18.0
-4,-8,22:17.0
-4,-7,22:17.0
-4,-6,22:17.0
-4,-5,22:17.0
-4,-4,22:17.0
-4,-3,22:17.0
-4,-2,22:17.0
-4,-1,22:17.0
-4,0,22:17.0
-4,5,22:17.0
-4,6,22:17.0
-4,7,22:17.0
-4,8,22:17.0
-4,9,22:17.0
-4,10,22:17.0
-4,11,22:17.0
-4,12,22:17.0
-4,13,22:17.0
-4,14,22:17.0
-4,16,22:18.0
-4,17,22:18.0
-4,18,22:18.0
-4,19,22:18.0
-3,-7,22:17.0
-3,-6,22:17.0
-3,-5,22:17.0
-3,-4,22:17.0
-3,-3,22:17.0
-3,-2,22:17.0
-3,-1,22:17.0
-3,0,22:17.0
-3,4,22:17.0
-3,5,22:17.0
-3,6,22:17.0
-3,7,22:17.0
-3,8,22:17.0
-3,16,22:18.0
-3,17,22:18.0
-3,18,22:18.0
-2,-6,22:17.0
-2,-5,22:17.0
-2,-4,22:17.0
-2,-3,22:17.0
-2,-2,22:17.0
-2,-1,22:17.0
-2,0,22:17.0
-2,2,22:17.0
-2,3,22:17.0
-2,4,22:17.0
-2,5,22:17.0
-2,6,22:17.0
-2,7,22:17.0
-2,8,22:17.0
-2,17,22:18.0
-2,18,22:18.0
-2,19,22:18.0
-1,-5,22:17.0
-1,-4,22:17.0
-1,-3,22:17.0
-1,-2,22:17.0
-1,-1,22:17.0
-1,0,22:17.0
-1,2,22:17.0
-1,3,22:17.0
-1,4,22:17.0
-1,5,22:17.0
-1,6,22:17.0
-1,7,22:17.0
-1,8,22:17.0
-1,18,22:18.0
0,-6,22:18.0
0,-5,22:17.0
0,-4,22:17.0
0,-3,22:17.0
0,-2,22:17.0
0,-1,22:17.0
0,0,22:17.0
0,1,22:17.0
0,2,22:17.0
0,3,22:17.0
0,4,22:17.0
0,5,22:17.0
0,6,22:17.0
0,7,22:17.0
1,-4,22:17.0
1,-2,22:17.0
1,-1,22:17.0
1,0,22:17.0
1,1,22:17.0
1,2,22:17.0
1,5,22:17.0
1,6,22:17.0
1,7,22:17.0
2,-1,22:17.0
2,0,22:17.0
2,1,22:17.0
2,4,22:17.0
2,5,22:17.0
2,6,22:17.0
2,7,22:17.0
2,8,22:17.0
3,-2,22:17.0
3,3,22:17.0
3,4,22:17.0
3,5,22:17.0
3,6,22:17.0
3,7,22:17.0
3,8,22:17.0
3,9,22:18.0
4,3,22:17.0
4,4,22:17.0
4,5,22:17.0
4,6,22:17.0
4,7,22:17.0
4,8,22:17.0
5,3,22:17.0
5,4,22:17.0
5,5,22:17.0
5,6,22:17.0
5,7,22:17.0
5,8,22:17.0
6,3,22:17.0
6,4,22:17.0
6,5,22:17.0
6,6,22:17.0
6,7,22:17.0
7,4,22:17.0
7,6,22:17.0
8,17,22:18.0
9,16,22:18.0
9,17,22:18.0
9,18,22:18.0
10,17,22:18.0
10,18,22:18.0
10,19,22:18.0
11,15,22:17.0
11,16,22:17.0
11,17,22:17.0
11,18,22:18.0
11,19,22:18.0
11,20,22:18.0
12,14,22:17.0
12,15,22:17.0
12,16,22:17.0
12,17,22:17.0
12,18,22:17.0
12,19,22:18.0
12,20,22:18.0
12,21,22:18.0
13,15,22:17.0
13,16,22:17.0
13,17,22:17.0
13,18,22:18.0
13,19,22:18.0
13,20,22:18.0
13,21,22:18.0
14,17,22:18.0
14,18,22:18.0
14,19,22:18.0
14,20,22:18.0
15,16,22:18.0
15,17,22:18.0
15,18,22:18.0
15,19,22:18.0
16,15,22:18.0
16,16,22:18.0
16,17,22:18.0
16,18,22:18.0
17,17,22:18.0
19,2,22:18.0
19,3,22:18.0
20,1,22:18.0
20,2,22:18.0
20,3,22:18.0
20,4,22:18.0
20,5,22:17.0
20,6,22:17.0
20,7,22:17.0
20,12,22:18.0
21,1,22:18.0
21,2,22:18.0
21,3,22:18.0
21,4,22:18.0
21,5,22:17.0
21,6,22:17.0
21,7,22:17.0
21,8,22:17.0
21,11,22:18.0
21,12,22:18.0
22,2,22:18.0
22,3,22:18.0
22,4,22:18.0
22,5,22:18.0
22,6,22:17.0
22,7,22:17.0
22,8,22:18.0
22,9,22:18.0
22,10,22:18.0
23,2,22:18.0
23,3,22:18.0
23,4,22:18.0
23,5,22:18.0
23,6,22:17.0
23,7,22:17.0
23,8,22:18.0
23,9,22:18.0
23,10,22:18.0
23,11,22:18.0
24,3,22:18.0
24,4,22:18.0
24,5,22:18.0
24,6,22:18.0
24,7,22:17.0
24,8,22:18.0
24,9,22:18.0
24,10,22:18.0
25,4,22:18.0
25,5,22:18.0
25,6,22:18.0
25,7,22:18.0
26,6,22:18.0
-28,3,23:18.0
-28,4,23:18.0
-28,5,23:18.0
-27,3,23:18.0
-27,4,23:18.0
-27,5,23:18.0
-27,6,23:18.0
-26,1,23:18.0
-26,2,23:18.0
-26,3,23:18.0
-26,4,23:18.0
-26,5,23:18.0
-26,6,23:18.0
-25,1,23:18.0
-25,3,23:18.0
-25,4,23:18.0
-25,5,23:18.0
-25,6,23:18.0
-24,0,23:18.0
-24,1,23:18.0
-24,2,23:18.0
-24,3,23:18.0
-24,4,23:18.0
-24,5,23:18.0
-24,6,23:18.0
-23,1,23:18.0
-23,2,23:18.0
-23,3,23:18.0
-23,4,23:18.0
-23,5,23:18.0
-23,6,23:18.0
-23,7,23:18.0
-22,3,23:18.0
-22,4,23:18.0
-22,5,23:18.0
-22,6,23:18.0
-22,7,23:17.0
-22,8,23:17.0
-21,5,23:17.0
-21,6,23:17.0
-21,7,23:17.0
-20,5,23:17.0
-20,6,23:17.0
-20,7,23:17.0
-20,8,23:17.0
-19,4,23:18.0
-19,5,23:17.0
-19,6,23:17.0
-19,7,23:17.0
-19,8,23:17.0
-18,5,23:18.0
-18,6,23:17.0
-18,7,23:17.0
-18,8,23:17.0
-18,10,23:18.0
-17,7,23:17.0
-17,8,23:17.0
-17,9,23:17.0
-17,10,23:17.0
-17,11,23:18.0
-16,7,23:17.0
-16,8,23:17.0
-16,9,23:17.0
-16,10,23:17.0
-15,-5,23:17.0
-15,8,23:17.0
-15,9,23:17.0
-15,10,23:17.0
-15,11,23:17.0
-15,12,23:17.0
-14,-6,23:17.0
-14,-5,23:17.0
-14,-4,23:17.0
-14,8,23:17.0
-14,9,23:17.0
-14,10,23:17.0
-14,11,23:17.0
-14,12,23:17.0
-14,13,23:17.0
-13,-6,23:17.0
-13,-5,23:17.0
-13,-4,23:17.0
-13,-1,23:17.0
-13,7,23:17.0
-13,8,23:17.0
-13,9,23:17.0
-13,10,23:17.0
-13,11,23:17.0
-13,12,23:17.0
-12,-9,23:18.0
-12,0,23:17.0
-12,6,23:17.0
-12,7,23:17.0
-12,8,23:17.0
-12,9,23:17.0
-12,10,23:17.0
-11,-9,23:18.0
-11,5,23:17.0
-11,6,23:17.0
-11,7,23:17.0
-11,8,23:17.0
-10,-1,23:17.0
-10,1,23:17.0
-10,4,23:17.0
-10,5,23:17.0
-10,6,23:17.0
-10,7,23:17.0
-10,8,23:17.0
-9,-2,23:17.0
-9,-1,23:17.0
-9,0,23:17.0
-9,1,23:17.0
-9,2,23:17.0
-9,3,23:17.0
-9,5,23:17.0
-8,-3,23:17.0
-8,-2,23:17.0
-8,-1,23:17.0
-8,0,23:17.0
-8,1,23:17.0
-8,2,23:17.0
-8,3,23:17.0
-8,4,23:17.0
-8,5,23:17.0
-8,6,23:17.0
-7,-3,23:17.0
-7,-2,23:17.0
-7,-1,23:17.0
-7,0,23:17.0
-7,1,23:17.0
-7,2,23:17.0
-7,3,23:17.0
-7,4,23:17.0
-7,5,23:17.0
-7,6,23:17.0
-7,7,23:17.0
-6,-9,23:18.0
-6,-6,23:17.0
-6,-5,23:17.0
-6,-4,23:17.0
-6,-3,23:17.0
-6,-2,23:17.0
-6,-1,23:17.0
-6,0,23:17.0
-6,1,23:17.0
-6,2,23:17.0
-6,3,23:17.0
-6,4,23:17.0
-6,5,23:17.0
-6,6,23:17.0
-6,7,23:17.0
-6,8,23:17.0
-6,9,23:17.0
-6,10,23:17.0
-6,11,23:17.0
-6,12,23:17.0
-5,-9,23:17.0
-5,-8,23:18.0
-5,-7,23:17.0
-5,-6,23:17.0
-5,-5,23:17.0
-5,-4,23:17.0
-5,-3,23:17.0
-5,-2,23:17.0
-5,-1,23:17.0
-5,0,23:17.0
-5,1,23:17.0
-5,3,23:17.0
-5,4,23:17.0
-5,5,23:17.0
-5,6,23:17.0
-5,7,23:17.0
-5,8,23:17.0
-5,9,23:17.0
-5,10,23:17.0
-5,11,23:17.0
-5,12,23:17.0
-5,13,23:17.0
-4,-9,23:17.0
-4,-8,23:17.0
-4,-7,23:17.0
-4,-6,23:17.0
-4,-5,23:17.0
-4,-4,23:17.0
-4,-3,23:17.0
-4,-2,23:17.0
-4,-1,23:17.0
-4,0,23:17.0
-4,1,23:17.0
-4,4,23:17.0
-4,5,23:17.0
-4,6,23:17.0
-4,7,23:17.0
-4,8,23:17.0
-4,9,23:17.0
-4,10,23:17.0
-4,11,23:17.0
-4,12,23:17.0
-3,-9,23:17.0
-3,-8,23:17.0
-3,-7,23:17.0
-3,-6,23:17.0
-3,-5,23:17.0
-3,-4,23:17.0
-3,-3,23:17.0
-3,-2,23:17.0
-3,-1,23:17.0
-3,0,23:17.0
-3,4,23:17.0
-3,5,23:17.0
-3,6,23:17.0
-3,7,23:17.0
-3,8,23:17.0
-2,-7,23:17.0
-2,-6,23:17.0
-2,-5,23:17.0
-2,-4,23:17.0
-2,-3,23:17.0
-2,-2,23:17.0
-2,-1,23:17.0
-2,2,23:17.0
-2,4,23:17.0
-2,5,23:17.0
-2,6,23:17.0
-2,7,23:17.0
-2,8,23:17.0
-1,-5,23:17.0
-1,-4,23:17.0
-1,-3,23:17.0
-1,-2,23:17.0
-1,-1,23:17.0
-1,1,23:17.0
-1,2,23:17.0
-1,3,23:17.0
-1,4,23:17.0
-1,5,23:17.0
-1,6,23:17.0
-1,7,23:17.0
-1,8,23:17.0
0,-6,23:18.0
0,-5,23:17.0
0,-4,23:17.0
0,-3,23:17.0
0,-2,23:17.0
0,-1,23:17.0
0,0,23:17.0
0,1,23:17.0
0,2,23:17.0
0,3,23:17.0
0,4,23:17.0
0,5,23:17.0
0,6,23:17.0
0,7,23:17.0
1,-4,23:17.0
1,-3,23:17.0
1,-2,23:17.0
1,-1,23:17.0
1,0,23:17.0
1,1,23:17.0
1,2,23:17.0
1,4,23:17.0
1,5,23:17.0
1,6,23:17.0
2,0,23:17.0
2,1,23:17.0
2,2,23:17.0
2,4,23:17.0
2,5,23:17.0
2,6,23:17.0
2,7,23:17.0
3,4,23:17.0
3,5,23:17.0
3,6,23:17.0
3,7,23:17.0
3,8,23:17.0
3,9,23:18.0
4,3,23:17.0
4,4,23:17.0
4,5,23:17.0
4,6,23:17.0
4,7,23:17.0
4,8,23:17.0
5,3,23:17.0
5,4,23:17.0
5,5,23:17.0
5,6,23:17.0
5,7,23:17.0
5,8,23:17.0
6,3,23:17.0
6,4,23:17.0
6,5,23:17.0
6,6,23:17.0
6,7,23:17.0
6,8,23:17.0
7,3,23:17.0
7,4,23:17.0
7,5,23:17.0
7,6,23:17.0
7,7,23:17.0
8,4,23:17.0
8,5,23:17.0
8,6,23:17.0
8,16,23:18.0
8,17,23:18.0
9,5,23:17.0
9,15,23:18.0
9,16,23:18.0
9,17,23:18.0
9,18,23:18.0
10,16,23:18.0
10,17,23:18.0
10,18,23:18.0
10,19,23:18.0
11,14,23:17.0
11,15,23:18.0
11,16,23:18.0
11,17,23:18.0
11,18,23:18.0
11,19,23:18.0
11,20,23:18.0
12,13,23:17.0
12,14,23:17.0
12,15,23:17.0
12,16,23:18.0
12,17,23:17.0
12,18,23:18.0
12,19,23:18.0
12,20,23:18.0
12,21,23:18.0
13,14,23:17.0
13,15,23:17.0
13,16,23:17.0
13,17,23:18.0
13,18,23:18.0
13,19,23:18.0
13,20,23:18.0
14,14,23:18.0
14,15,23:18.0
14,16,23:18.0
14,17,23:18.0
14,18,23:18.0
14,19,23:18.0
15,13,23:18.0
15,14,23:18.0
15,15,23:18.0
15,16,23:18.0
15,17,23:18.0
15,18,23:18.0
16,10,23:17.0
16,13,23:18.0
16,14,23:18.0
16,15,23:18.0
16,16,23:18.0
16,17,23:18.0
17,9,23:17.0
17,10,23:17.0
17,11,23:17.0
17,12,23:18.0
17,13,23:18.0
17,14,23:18.0
17,15,23:18.0
17,16,23:18.0
18,8,23:17.0
18,9,23:17.0
18,10,23:17.0
18,13,23:18.0
18,14,23:18.0
19,5,23:18.0
19,7,23:17.0
19,8,23:17.0
19,9,23:17.0
19,10,23:17.0
19,11,23:17.0
19,13,23:18.0
20,2,23:18.0
20,3,23:18.0
20,4,23:18.0
20,5,23:18.0
20,6,23:18.0
20,7,23:17.0
20,8,23:17.0
20,9,23:17.0
20,10,23:17.0
20,11,23:18.0
20,12,23:18.0
20,13,23:18.0
20,14,23:18.0
21,2,23:18.0
21,3,23:18.0
21,4,23:18.0
21,5,23:18.0
21,6,23:17.0
21,7,23:17.0
21,8,23:18.0
21,9,23:17.0
21,10,23:18.0
21,11,23:18.0
21,12,23:18.0
22,1,23:18.0
22,2,23:18.0
22,3,23:18.0
22,4,23:18.0
22,5,23:17.0
22,6,23:17.0
22,7,23:18.0
22,8,23:18.0
22,9,23:18.0
22,11,23:18.0
22,12,23:18.0
23,2,23:18.0
23,3,23:18.0
23,4,23:18.0
23,5,23:18.0
23,6,23:18.0
23,7,23:18.0
23,8,23:18.0
23,9,23:18.0
23,10,23:18.0
24,3,23:18.0
24,4,23:18.0
24,5,23:18.0
24,6,23:18.0
24,7,23:18.0
24,8,23:18.0
24,9,23:18.0
25,4,23:18.0
25,5,23:18.0
25,6,23:18.0
25,7,23:18.0
26,5,23:18.0
26,6,23:18.0
26,7,23:18.0
-28,4,24:18.0
-27,3,24:18.0
-27,4,24:18.0
-27,5,24:18.0
-26,3,24:18.0
-26,4,24:18.0
-26,5,24:18.0
-25,4,24:18.0
-25,5,24:18.0
-24,2,24:18.0
-24,3,24:18.0
-24,4,24:18.0
-24,5,24:18.0
-23,2,24:18.0
-23,3,24:18.0
-23,4,24:18.0
-23,5,24:18.0
-23,6,24:18.0
-22,2,24:18.0
-22,3,24:18.0
-22,4,24:18.0
-22,5,24:18.0
-21,6,24:17.0
-20,5,24:17.0
-20,6,24:17.0
-20,7,24:17.0
-19,5,24:18.0
-19,6,24:17.0
-19,7,24:17.0
-18,5,24:18.0
-18,6,24:17.0
-17,6,24:17.0
-17,7,24:17.0
-17,9,24:17.0
-17,10,24:18.0
-17,11,24:18.0
-16,7,24:17.0
-16,8,24:17.0
-16,9,24:17.0
-16,10,24:17.0
-15,7,24:17.0
-15,8,24:17.0
-15,9,24:17.0
-15,10,24:17.0
-15,11,24:17.0
-14,-7,24:17.0
-14,-6,24:17.0
-14,-5,24:17.0
-14,-4,24:17.0
-14,-3,24:17.0
-14,7,24:17.0
-14,8,24:17.0
-14,9,24:17.0
-14,10,24:17.0
-14,11,24:17.0
-14,12,24:17.0
-13,-9,24:18.0
-13,-8,24:17.0
-13,-7,24:17.0
-13,-6,24:17.0
-13,-5,24:17.0
-13,-4,24:17.0
-13,-3,24:17.0
-13,-2,24:17.0
-13,6,24:17.0
-13,7,24:17.0
-13,8,24:17.0
-13,9,24:17.0
-13,10,24:17.0
-13,11,24:17.0
-12,-10,24:18.0
-12,-9,24:17.0
-12,-8,24:17.0
-12,-2,24:17.0
-12,-1,24:17.0
-12,6,24:17.0
-12,7,24:17.0
-12,8,24:17.0
-12,9,24:17.0
-11,-9,24:18.0
-11,6,24:17.0
-11,7,24:17.0
-11,8,24:17.0
-10,-2,24:17.0
-10,-1,24:17.0
-10,0,24:17.0
-10,1,24:17.0
-10,2,24:17.0
-10,7,24:17.0
-9,-2,24:17.0
-9,-1,24:17.0
-9,0,24:17.0
-9,1,24:17.0
-9,2,24:17.0
-9,5,24:17.0
-9,7,24:17.0
-8,-2,24:17.0
-8,-1,24:17.0
-8,0,24:17.0
-8,1,24:17.0
-8,2,24:17.0
-8,3,24:17.0
-8,4,24:17.0
-8,5,24:17.0
-8,6,24:17.0
-8,7,24:17.0
-8,8,24:17.0
-7,-3,24:17.0
-7,-2,24:17.0
-7,-1,24:17.0
-7,0,24:17.0
-7,1,24:17.0
-7,2,24:17.0
-7,3,24:17.0
-7,4,24:17.0
-7,5,24:17.0
-7,6,24:17.0
-7,7,24:17.0
-6,-10,24:17.0
-6,-6,24:17.0
-6,-5,24:17.0
-6,-4,24:17.0
-6,-3,24:17.0
-6,-2,24:17.0
-6,-1,24:17.0
-6,0,24:17.0
-6,1,24:17.0
-6,2,24:17.0
-6,3,24:17.0
-6,4,24:17.0
-6,5,24:17.0
-6,6,24:17.0
-6,7,24:17.0
-6,8,24:17.0
-5,-11,24:17.0
-5,-10,24:17.0
-5,-9,24:18.0
-5,-8,24:18.0
-5,-6,24:17.0
-5,-5,24:17.0
-5,-4,24:17.0
-5,-3,24:17.0
-5,-2,24:17.0
-5,-1,24:17.0
-5,0,24:17.0
-5,1,24:17.0
-5,3,24:17.0
-5,4,24:17.0
-5,5,24:17.0
-5,6,24:17.0
-5,7,24:17.0
-5,8,24:17.0
-5,9,24:17.0
-4,-10,24:17.0
-4,-9,24:17.0
-4,-8,24:17.0
-4,-7,24:17.0
-4,-6,24:17.0
-4,-5,24:17.0
-4,-4,24:17.0
-4,-3,24:17.0
-4,-2,24:17.0
-4,-1,24:17.0
-4,0,24:17.0
-4,1,24:17.0
-4,2,24:17.0
-4,4,24:17.0
-4,5,24:17.0
-4,6,24:18.0
-4,7,24:17.0
-4,8,24:17.0
-3,-10,24:17.0
-3,-9,24:17.0
-3,-8,24:17.0
-3,-7,24:17.0
-3,-6,24:17.0
-3,-5,24:17.0
-3,-4,24:17.0
-3,-3,24:17.0
-3,-2,24:17.0
-3,-1,24:17.0
-3,0,24:17.0
-3,1,24:17.0
-3,4,24:17.0
-3,5,24:17.0
-3,6,24:17.0
-3,7,24:17.0
-2,-9,24:17.0
-2,-8,24:17.0
-2,-7,24:17.0
-2,-6,24:17.0
-2,-5,24:17.0
-2,-4,24:17.0
-2,-3,24:17.0
-2,-2,24:17.0
-2,-1,24:17.0
-2,0,24:17.0
-2,1,24:17.0
-2,4,24:17.0
-2,5,24:17.0
-2,6,24:17.0
-2,7,24:17.0
-1,-6,24:18.0
-1,-5,24:17.0
-1,-4,24:17.0
-1,-3,24:17.0
-1,-2,24:17.0
-1,-1,24:17.0
-1,0,24:17.0
-1,1,24:17.0
-1,2,24:17.0
-1,3,24:17.0
-1,4,24:17.0
-1,5,24:17.0
-1,6,24:17.0
-1,7,24:17.0
0,-6,24:18.0
0,-5,24:17.0
0,-4,24:17.0
0,-3,24:17.0
0,-2,24:17.0
0,-1,24:17.0
0,0,24:17.0
0,1,24:17.0
0,2,24:17.0
0,3,24:17.0
0,4,24:17.0
0,5,24:17.0
0,6,24:17.0
1,-4,24:17.0
1,-3,24:17.0
1,-2,24:17.0
1,0,24:17.0
1,1,24:17.0
1,2,24:17.0
1,3,24:17.0
1,4,24:17.0
1,5,24:17.0
1,6,24:17.0
2,1,24:17.0
2,3,24:17.0
2,4,24:17.0
2,5,24:17.0
2,6,24:17.0
2,7,24:18.0
3,4,24:17.0
3,5,24:17.0
3,6,24:17.0
3,7,24:17.0
3,8,24:18.0
3,9,24:18.0
4,4,24:17.0
4,5,24:17.0
4,6,24:17.0
4,7,24:17.0
4,8,24:18.0
5,4,24:17.0
5,5,24:17.0
5,6,24:17.0
5,7,24:17.0
5,8,24:17.0
6,3,24:17.0
6,4,24:17.0
6,5,24:17.0
6,6,24:17.0
6,7,24:17.0
6,8,24:17.0
7,4,24:17.0
7,5,24:17.0
7,6,24:17.0
7,7,24:17.0
7,8,24:17.0
8,4,24:17.0
8,5,24:17.0
8,6,24:17.0
8,7,24:17.0
8,15,24:18.0
9,4,24:17.0
9,5,24:17.0
9,6,24:17.0
9,14,24:18.0
9,15,24:18.0
9,16,24:18.0
9,17,24:18.0
10,12,24:17.0
10,15,24:18.0
10,16,24:18.0
10,17,24:18.0
10,18,24:18.0
11,3,24:18.0
11,11,24:17.0
11,12,24:17.0
11,13,24:17.0
11,14,24:17.0
11,15,24:18.0
11,16,24:18.0
11,17,24:18.0
11,18,24:18.0
11,19,24:18.0
12,12,24:17.0
12,13,24:17.0
12,14,24:17.0
12,15,24:18.0
12,16,24:18.0
12,17,24:18.0
12,18,24:18.0
12,19,24:18.0
12,20,24:18.0
13,12,24:17.0
13,13,24:17.0
13,14,24:17.0
13,15,24:17.0
13,16,24:17.0
13,17,24:18.0
13,18,24:18.0
13,19,24:18.0
13,20,24:18.0
14,13,24:18.0
14,14,24:18.0
14,15,24:18.0
14,16,24:18.0
14,17,24:18.0
14,18,24:18.0
14,19,24:18.0
15,9,24:17.0
15,12,24:18.0
15,13,24:18.0
15,14,24:18.0
15,15,24:18.0
15,16,24:18.0
15,17,24:18.0
15,18,24:18.0
16,8,24:17.0
16,9,24:17.0
16,10,24:17.0
16,11,24:17.0
16,12,24:18.0
16,13,24:18.0
16,14,24:18.0
16,15,24:18.0
16,16,24:18.0
16,17,24:18.0
17,8,24:17.0
