[META]
version=2.0
spawnOnBlockType=13
spawnSunlight=True
spawnDarkness=False
spawnWater=False
spawnLava=False
underFill=False
randomRotation=True
dig=False
tree=False
branch=False
needsFoundation=False
rarity=2
collisionPercentage=0
spawnElevationMin=0
spawnElevationMax=90
spawnInBiome=DesertGravel
[DATA]
-3,-3,0:1
-3,-2,0:1
-4,-2,0:1
-4,-1,0:1
-5,0,0:1
-5,1,0:1
-5,2,0:1
-4,2,0:1
-4,3,0:1
-3,3,0:1
-3,4,0:1
-2,4,0:1
-1,4,0:1
0,4,0:1
0,3,0:1
1,3,0:1
1,2,0:1
1,1,0:1
1,0,0:1
1,-1,0:1
0,-1,0:1
-1,-1,0:1
-2,-1,0:1
-2,-2,0:1
-1,-2,0:1
-1,0,0:1
-1,1,0:1
-1,2,0:1
0,2,0:1
0,1,0:1
-1,3,0:1
-2,3,0:1
-2,2,0:1
-3,2,0:1
-3,1,0:1
-4,1,0:1
-4,0,0:1
-3,0,0:1
-2,0,0:1
-3,-1,0:1
-2,-3,0:1
-1,-3,0:1
0,-3,0:1
0,-2,0:1
1,-2,0:1
2,0,0:1
2,1,0:1
2,2,0:1
2,3,0:1
1,4,0:1
-4,4,0:1
-5,3,0:1
-6,1,0:1
-6,0,0:1
-6,-1,0:1
-5,-1,0:1
-5,-2,0:1
-2,1,0:35.5
0,0,0:1
-2,1,-1:1
-3,0,-1:1
-3,1,-1:1
-3,2,-1:1
-2,2,-1:1
-1,2,-1:1
-1,1,-1:1
-1,0,-1:1
-2,0,-1:1
-2,-1,-1:1
-3,-1,-1:1
-4,-1,-1:1
-4,0,-1:1
-4,1,-1:1
-4,2,-1:1
-4,3,-1:1
-3,3,-1:1
-2,3,-1:1
-1,3,-1:1
0,3,-1:1
0,2,-1:1
0,1,-1:1
0,0,-1:1
0,-1,-1:1
-1,-1,-1:1
-3,-2,-1:1
-4,-2,-1:1
-5,-2,-1:1
-5,-1,-1:1
-6,-1,-1:1
-6,0,-1:1
-6,1,-1:1
-6,2,-1:1
-6,3,-1:1
-5,3,-1:1
-5,4,-1:1
-5,2,-1:1
-5,1,-1:1
-5,0,-1:1
-7,0,-1:1
-7,1,-1:1
-7,2,-1:1
-7,-1,-1:1
-6,-2,-1:1
-5,-3,-1:1
-4,-3,-1:1
-4,-4,-1:1
-3,-4,-1:1
-2,-4,-1:1
-2,-5,-1:1
-1,-5,-1:1
-1,-4,-1:1
0,-4,-1:1
1,-4,-1:1
1,-3,-1:1
2,-3,-1:1
2,-2,-1:1
2,-1,-1:1
3,-1,-1:1
3,0,-1:1
3,1,-1:1
3,2,-1:1
3,3,-1:1
3,4,-1:1
2,4,-1:1
2,5,-1:1
1,5,-1:1
0,5,-1:1
-1,5,-1:1
-2,5,-1:1
-2,6,-1:1
-3,6,-1:1
-4,6,-1:1
-4,5,-1:1
-5,5,-1:1
-6,4,-1:1
-7,3,-1:1
-4,4,-1:1
-3,4,-1:1
-3,5,-1:1
-2,4,-1:1
-1,4,-1:1
0,4,-1:1
1,4,-1:1
2,3,-1:1
2,2,-1:1
1,2,-1:1
1,3,-1:1
2,1,-1:1
1,1,-1:1
1,0,-1:1
2,0,-1:1
1,-1,-1:1
1,-2,-1:1
0,-2,-1:1
0,-3,-1:1
-1,-3,-1:1
-2,-3,-1:1
-3,-3,-1:1
-2,-2,-1:1
-1,-2,-1:1
-2,0,-2:1
-2,1,-2:1
-1,1,-2:1
-1,0,-2:1
-3,-1,-2:1
-2,-1,-2:1
-1,-1,-2:1
0,-1,-2:1
0,0,-2:1
0,1,-2:1
0,2,-2:1
-1,2,-2:1
-2,2,-2:1
-2,3,-2:1
-3,3,-2:1
-3,2,-2:1
-3,1,-2:1
-3,0,-2:1
-4,0,-2:1
-4,1,-2:1
-4,2,-2:1
-4,3,-2:1
-2,4,-2:1
-1,4,-2:1
0,4,-2:1
0,3,-2:1
1,2,-2:1
1,1,-2:1
1,0,-2:1
1,-1,-2:1
1,-2,-2:1
0,-2,-2:1
0,-3,-2:1
-1,-3,-2:1
-2,-3,-2:1
-3,-3,-2:1
-3,-2,-2:1
-4,-2,-2:1
-5,-2,-2:1
-5,-1,-2:1
-5,0,-2:1
-5,1,-2:1
-5,2,-2:1
-5,3,-2:1
-3,4,-2:1
-4,4,-2:1
-5,4,-2:1
-4,-1,-2:1
-1,3,-2:1
1,3,-2:1
2,1,-2:1
2,0,-2:1
2,-1,-2:1
2,-2,-2:1
-1,-2,-2:1
-2,-2,-2:1
-5,-3,-2:1
-4,-3,-2:1
0,-4,-2:1
1,-4,-2:1
2,-4,-2:1
2,-3,-2:1
1,-3,-2:1
-1,-4,-2:1
-2,-4,-2:1
-3,-4,-2:1
-5,-4,-2:1
-4,-4,-2:1
-6,-2,-2:1
-6,-1,-2:1
-6,0,-2:1
-6,1,-2:1
-6,2,-2:1
-3,-5,-2:1
-2,-5,-2:1
-1,-5,-2:1
0,-5,-2:1
-2,0,-3:1
-2,1,-3:1
-1,1,-3:1
-1,0,-3:1
-3,-3,-3:1
-4,-3,-3:1
-4,-2,-3:1
-4,-1,-3:1
-4,0,-3:1
-4,1,-3:1
-4,2,-3:1
-4,3,-3:1
-3,3,-3:1
-2,3,-3:1
-2,4,-3:1
-1,4,-3:1
0,4,-3:1
1,4,-3:1
1,3,-3:1
2,3,-3:1
2,2,-3:1
2,1,-3:1
2,0,-3:1
2,-1,-3:1
2,-2,-3:1
1,-2,-3:1
1,-3,-3:1
0,-3,-3:1
-1,-3,-3:1
-2,-3,-3:1
-3,-2,-3:1
-2,-2,-3:1
-1,-2,-3:1
-1,-1,-3:1
-2,-1,-3:1
-3,-1,-3:1
-3,0,-3:1
-3,1,-3:1
-3,2,-3:1
-2,2,-3:1
-1,2,-3:1
-1,3,-3:1
0,3,-3:1
0,2,-3:1
1,2,-3:1
1,1,-3:1
0,1,-3:1
1,0,-3:1
1,-1,-3:1
0,-1,-3:1
0,-2,-3:1
1,-4,-3:1
0,-4,-3:1
0,-5,-3:1
-1,-5,-3:1
-2,-5,-3:1
-3,-5,-3:1
-3,-4,-3:1
-4,-4,-3:1
-5,-4,-3:1
-5,-3,-3:1
-6,-3,-3:1
-6,-2,-3:1
-6,-4,-3:1
-6,-5,-3:1
-5,-5,-3:1
-4,-5,-3:1
-7,-3,-3:1
-7,-2,-3:1
-7,-1,-3:1
-7,0,-3:1
-7,1,-3:1
-7,2,-3:1
-7,3,-3:1
-7,4,-3:1
-6,5,-3:1
-5,5,-3:1
-4,5,-3:1
-4,6,-3:1
-3,6,-3:1
-2,6,-3:1
-1,6,-3:1
0,6,-3:1
1,6,-3:1
2,6,-3:1
2,5,-3:1
3,5,-3:1
3,4,-3:1
3,3,-3:1
3,2,-3:1
3,1,-3:1
4,1,-3:1
4,0,-3:1
4,-1,-3:1
3,-1,-3:1
3,-2,-3:1
2,-3,-3:1
-1,-4,-3:1
-2,-4,-3:1
2,-4,-3:1
3,-3,-3:1
3,0,-3:1
2,4,-3:1
1,5,-3:1
0,5,-3:1
-1,5,-3:1
-2,5,-3:1
-3,5,-3:1
-4,4,-3:1
-5,4,-3:1
-5,3,-3:1
-6,4,-3:1
-6,3,-3:1
-6,2,-3:1
-6,1,-3:1
-5,1,-3:1
-5,0,-3:1
-6,0,-3:1
-6,-1,-3:1
-5,-1,-3:1
-5,-2,-3:1
-5,2,-3:1
-8,0,-3:1
-8,1,-3:1
-8,2,-3:1
-3,4,-3:1
-3,7,-3:1
-2,7,-3:1
-1,7,-3:1
0,7,-3:1
-3,-6,-3:1
-2,-6,-3:1
0,0,-3:1
-6,-4,-4:1
-6,-3,-4:1
-6,-2,-4:1
-6,-1,-4:1
-6,0,-4:1
-6,1,-4:1
-6,2,-4:1
-6,3,-4:1
-6,4,-4:1
-6,5,-4:1
-5,5,-4:1
-4,5,-4:1
-3,5,-4:1
-2,5,-4:1
-1,5,-4:1
0,5,-4:1
1,5,-4:1
2,5,-4:1
3,5,-4:1
3,4,-4:1
3,3,-4:1
3,2,-4:1
3,1,-4:1
3,0,-4:1
3,-1,-4:1
3,-2,-4:1
3,-3,-4:1
3,-4,-4:1
2,-4,-4:1
1,-4,-4:1
0,-4,-4:1
-1,-4,-4:1
-2,-4,-4:1
-3,-4,-4:1
-4,-4,-4:1
-5,-4,-4:1
-5,-3,-4:1
-5,-2,-4:1
-5,-1,-4:1
-5,0,-4:1
-5,1,-4:1
-5,2,-4:1
-5,3,-4:1
-5,4,-4:1
-4,4,-4:1
-3,4,-4:1
-2,4,-4:1
-1,4,-4:1
0,4,-4:1
1,4,-4:1
2,4,-4:1
2,3,-4:1
2,2,-4:1
2,1,-4:1
2,0,-4:1
2,-1,-4:1
2,-2,-4:1
2,-3,-4:1
1,-3,-4:1
0,-3,-4:1
-1,-3,-4:1
-2,-3,-4:1
-3,-3,-4:1
-4,-3,-4:1
-4,-2,-4:1
-4,-1,-4:1
-4,0,-4:1
-4,1,-4:1
-4,2,-4:1
-4,3,-4:1
-3,3,-4:1
-2,3,-4:1
-1,3,-4:1
0,3,-4:1
1,3,-4:1
1,2,-4:1
1,1,-4:1
1,0,-4:1
1,-1,-4:1
1,-2,-4:1
0,-2,-4:1
-1,-2,-4:1
-2,-2,-4:1
-3,-1,-4:1
-3,0,-4:1
-3,1,-4:1
-3,2,-4:1
-2,2,-4:1
-1,2,-4:1
0,2,-4:1
0,1,-4:1
0,0,-4:1
-1,1,-4:1
-2,1,-4:1
-2,0,-4:1
-1,0,-4:1
-1,-1,-4:1
0,-1,-4:1
-2,-1,-4:1
-3,-2,-4:1
-7,-2,-4:1
-7,-1,-4:1
-7,0,-4:1
-7,1,-4:1
-7,2,-4:1
-7,3,-4:1
-4,6,-4:1
-3,6,-4:1
-2,6,-4:1
-1,6,-4:1
0,6,-4:1
1,6,-4:1
2,6,-4:1
-4,-5,-4:1
-3,-5,-4:1
-2,-5,-4:1
-1,-5,-4:1
0,-5,-4:1
1,-5,-4:1
4,-2,-4:1
4,-1,-4:1
4,0,-4:1
4,1,-4:1
4,2,-4:1
4,3,-4:1
-6,-4,-5:1
-6,-3,-5:1
-6,-2,-5:1
-6,-1,-5:1
-6,0,-5:1
-6,1,-5:1
-6,2,-5:1
-6,3,-5:1
-6,4,-5:1
-6,5,-5:1
-5,5,-5:1
-4,5,-5:1
-3,5,-5:1
-2,5,-5:1
-1,5,-5:1
0,5,-5:1
1,5,-5:1
2,5,-5:1
3,5,-5:1
3,4,-5:1
3,3,-5:1
3,2,-5:1
3,1,-5:1
3,0,-5:1
3,-1,-5:1
3,-2,-5:1
3,-3,-5:1
3,-4,-5:1
2,-4,-5:1
1,-4,-5:1
0,-4,-5:1
-1,-4,-5:1
-2,-4,-5:1
-3,-4,-5:1
-4,-4,-5:1
-5,-4,-5:1
-5,-3,-5:1
-5,-2,-5:1
-5,-1,-5:1
-5,0,-5:1
-5,1,-5:1
-5,2,-5:1
-5,3,-5:1
-5,4,-5:1
-4,4,-5:1
-3,4,-5:1
-2,4,-5:1
-1,4,-5:1
0,4,-5:1
1,4,-5:1
2,4,-5:1
2,3,-5:1
2,2,-5:1
2,1,-5:1
2,0,-5:1
2,-1,-5:1
2,-2,-5:1
2,-3,-5:1
1,-3,-5:1
0,-3,-5:1
-1,-3,-5:1
-2,-3,-5:1
-3,-3,-5:1
-4,-3,-5:1
-4,-2,-5:1
-4,-1,-5:1
-4,0,-5:1
-4,1,-5:1
-4,2,-5:1
-4,3,-5:1
-3,3,-5:1
-2,3,-5:1
-1,3,-5:1
0,3,-5:1
1,3,-5:1
1,2,-5:1
1,1,-5:1
1,0,-5:1
1,-1,-5:1
1,-2,-5:1
0,-2,-5:1
-1,-2,-5:1
-2,-2,-5:1
-3,-2,-5:1
-3,-1,-5:1
-3,0,-5:89
-3,1,-5:89
-3,2,-5:1
-2,2,-5:89
-1,2,-5:89
0,2,-5:1
0,1,-5:89
0,0,-5:89
0,-1,-5:1
-1,-1,-5:89
-2,-1,-5:89
-7,-4,-5:1
-7,-3,-5:1
-8,-2,-5:1
-8,-1,-5:1
-8,0,-5:1
-8,1,-5:1
-8,2,-5:1
-8,3,-5:1
-8,4,-5:1
-7,1,-5:1
-7,0,-5:1
-7,-1,-5:1
-7,-2,-5:1
-7,2,-5:1
-7,3,-5:1
-7,4,-5:1
-7,5,-5:1
-8,5,-5:1
-7,6,-5:1
-6,6,-5:1
-5,6,-5:1
-4,6,-5:1
-3,6,-5:1
-2,6,-5:1
-2,7,-5:1
-3,7,-5:1
-4,7,-5:1
-1,7,-5:1
0,7,-5:1
-1,6,-5:1
0,6,-5:1
1,6,-5:1
2,6,-5:1
3,6,-5:1
4,6,-5:1
5,6,-5:1
5,5,-5:1
4,5,-5:1
4,4,-5:1
4,3,-5:1
4,2,-5:1
5,2,-5:1
5,1,-5:1
5,0,-5:1
5,-1,-5:1
4,-1,-5:1
4,-2,-5:1
4,0,-5:1
4,1,-5:1
5,3,-5:1
6,2,-5:1
6,1,-5:1
6,0,-5:1
6,-1,-5:1
5,-2,-5:1
4,-3,-5:1
4,-4,-5:1
4,-5,-5:1
4,-6,-5:1
3,-6,-5:1
2,-6,-5:1
1,-6,-5:1
1,-7,-5:1
0,-7,-5:1
-1,-7,-5:1
-2,-7,-5:1
-3,-7,-5:1
-4,-7,-5:1
-4,-6,-5:1
-5,-6,-5:1
-6,-6,-5:1
-6,-5,-5:1
-7,-5,-5:1
-5,-5,-5:1
-4,-5,-5:1
-3,-5,-5:1
-2,-5,-5:1
-1,-5,-5:1
0,-5,-5:1
1,-5,-5:1
2,-5,-5:1
3,-5,-5:1
0,-6,-5:1
-1,-6,-5:1
-2,-6,-5:1
-3,-6,-5:1
5,4,-5:1
1,7,-5:1
-5,7,-5:1
-2,0,-5:0
-2,1,-5:0
-1,1,-5:0
-1,0,-5:0
-6,-4,-6:1
-6,-3,-6:1
-6,-2,-6:1
-6,-1,-6:1
-6,0,-6:1
-6,1,-6:1
-6,2,-6:1
-6,3,-6:1
-6,4,-6:1
-6,5,-6:1
-5,5,-6:1
-4,5,-6:1
-3,5,-6:1
-2,5,-6:1
-1,5,-6:1
0,5,-6:1
1,5,-6:1
2,5,-6:1
3,5,-6:1
3,4,-6:1
3,3,-6:1
3,2,-6:1
3,1,-6:1
3,0,-6:1
3,-1,-6:1
3,-2,-6:1
3,-3,-6:1
3,-4,-6:1
2,-4,-6:1
1,-4,-6:1
0,-4,-6:1
-1,-4,-6:1
-2,-4,-6:1
-3,-4,-6:1
-4,-4,-6:1
-5,-4,-6:1
-7,-5,-6:35.0
-7,-4,-6:35.0
-7,-3,-6:35.0
-7,-2,-6:35.0
-7,-1,-6:35.0
-7,0,-6:35.0
-7,1,-6:35.0
-7,2,-6:35.0
-7,3,-6:35.0
-7,4,-6:35.0
-7,5,-6:35.0
-7,6,-6:35.0
-6,6,-6:35.0
-5,6,-6:35.0
-4,6,-6:35.0
-3,6,-6:35.0
-2,6,-6:35.0
-1,6,-6:35.0
0,6,-6:35.0
1,6,-6:35.0
2,6,-6:35.0
3,6,-6:35.0
4,6,-6:35.0
4,5,-6:35.0
4,4,-6:35.0
4,3,-6:35.0
4,2,-6:35.0
5,2,-6:35.0
5,1,-6:35.0
5,0,-6:35.0
5,-1,-6:35.0
5,-2,-6:35.0
5,-3,-6:35.0
5,-4,-6:35.0
5,-5,-6:35.0
4,-5,-6:35.0
4,-6,-6:35.0
3,-6,-6:35.0
2,-6,-6:35.0
1,-6,-6:35.0
0,-6,-6:35.0
-1,-6,-6:35.0
-2,-6,-6:35.0
-3,-6,-6:35.0
-4,-6,-6:35.0
-5,-6,-6:35.0
-5,-5,-6:35.0
-6,-5,-6:35.0
-4,-5,-6:35.0
-3,-5,-6:35.0
-2,-5,-6:35.0
-1,-5,-6:35.0
0,-5,-6:35.0
1,-5,-6:35.0
2,-5,-6:35.0
3,-5,-6:35.0
4,-4,-6:35.0
4,-3,-6:35.0
4,-2,-6:35.0
4,-1,-6:35.0
4,0,-6:35.0
4,1,-6:35.0
-8,-2,-6:35.0
-8,-1,-6:35.0
-8,0,-6:35.0
-8,1,-6:35.0
-8,2,-6:35.0
-8,3,-6:35.0
-8,4,-6:35.0
-4,7,-6:35.0
-3,7,-6:35.0
-2,7,-6:35.0
-1,7,-6:35.0
0,7,-6:35.0
1,7,-6:35.0
2,7,-6:35.0
3,7,-6:35.0
-5,-3,-6:0
-5,-2,-6:0
-5,-1,-6:0
-5,0,-6:0
-5,1,-6:0
-5,2,-6:0
-5,3,-6:0
-5,4,-6:0
-4,4,-6:0
-3,4,-6:0
-2,4,-6:0
-1,4,-6:0
0,4,-6:0
1,4,-6:0
2,4,-6:0
2,3,-6:0
2,2,-6:0
2,1,-6:0
2,0,-6:0
2,-1,-6:0
2,-2,-6:0
2,-3,-6:0
1,-3,-6:0
0,-3,-6:0
-1,-3,-6:0
-2,-3,-6:0
-3,-3,-6:0
-4,-3,-6:0
-4,-2,-6:0
-4,-1,-6:0
-4,0,-6:0
-4,1,-6:0
-4,2,-6:0
-4,3,-6:0
-3,3,-6:0
-2,3,-6:0
-1,3,-6:0
0,3,-6:0
1,3,-6:0
1,2,-6:0
1,1,-6:0
1,0,-6:0
1,-1,-6:0
1,-2,-6:0
0,-2,-6:0
-1,-2,-6:0
-2,-2,-6:0
-3,-2,-6:0
-3,-1,-6:0
-3,0,-6:0
-3,1,-6:0
-3,2,-6:0
-2,2,-6:0
-1,2,-6:0
0,2,-6:0
0,1,-6:0
0,0,-6:0
0,-1,-6:0
-1,-1,-6:0
-2,-1,-6:0
-2,0,-6:0
-2,1,-6:0
-1,1,-6:0
-1,0,-6:0
-6,-4,-7:1
-6,-3,-7:1
-6,-2,-7:1
-6,-1,-7:1
-6,0,-7:1
-6,1,-7:1
-6,2,-7:1
-6,3,-7:1
-6,4,-7:1
-6,5,-7:1
-5,5,-7:1
-4,5,-7:1
-3,5,-7:1
-2,5,-7:1
-1,5,-7:1
0,5,-7:1
1,5,-7:1
2,5,-7:1
3,5,-7:1
3,4,-7:1
3,3,-7:1
3,2,-7:1
3,1,-7:1
3,0,-7:1
3,-1,-7:1
3,-2,-7:1
3,-3,-7:1
3,-4,-7:1
2,-4,-7:1
1,-4,-7:1
0,-4,-7:1
-1,-4,-7:1
-2,-4,-7:1
-3,-4,-7:1
-4,-4,-7:1
-5,-4,-7:1
-7,-5,-7:35.0
-7,-4,-7:35.0
-7,-3,-7:35.0
-7,-2,-7:35.0
-7,-1,-7:35.0
-7,0,-7:35.0
-7,1,-7:35.0
-7,2,-7:35.0
-7,3,-7:35.0
-7,4,-7:35.0
-7,5,-7:35.0
-7,6,-7:35.0
-7,7,-7:35.0
-8,4,-7:35.0
-8,3,-7:35.0
-8,2,-7:35.0
-8,1,-7:35.0
-8,0,-7:35.0
-8,-1,-7:35.0
-8,-2,-7:35.0
-6,-5,-7:35.0
-5,-5,-7:35.0
-4,-5,-7:35.0
-3,-5,-7:35.0
-2,-5,-7:35.0
-1,-5,-7:35.0
0,-5,-7:35.0
1,-5,-7:35.0
2,-5,-7:35.0
3,-5,-7:35.0
4,-5,-7:35.0
1,-6,-7:35.0
0,-6,-7:35.0
-1,-6,-7:35.0
-2,-6,-7:35.0
-3,-6,-7:35.0
-4,-6,-7:35.0
-5,-6,-7:35.0
4,-4,-7:35.0
4,-3,-7:35.0
4,-2,-7:35.0
4,-1,-7:35.0
4,0,-7:35.0
4,1,-7:35.0
4,2,-7:35.0
4,3,-7:35.0
4,4,-7:35.0
4,5,-7:35.0
4,6,-7:35.0
4,7,-7:35.0
5,3,-7:35.0
5,2,-7:35.0
5,1,-7:35.0
5,0,-7:35.0
5,-1,-7:35.0
5,-2,-7:35.0
5,-3,-7:35.0
3,6,-7:35.0
2,6,-7:35.0
1,6,-7:35.0
0,6,-7:35.0
-1,6,-7:35.0
-2,6,-7:35.0
-3,6,-7:35.0
-4,6,-7:35.0
-5,6,-7:35.0
-6,6,-7:35.0
-6,7,-7:35.0
-5,7,-7:35.0
-4,7,-7:35.0
-3,7,-7:35.0
-2,7,-7:35.0
-1,7,-7:35.0
0,7,-7:35.0
1,7,-7:35.0
2,7,-7:35.0
3,7,-7:35.0
3,8,-7:35.0
2,8,-7:35.0
1,8,-7:35.0
0,8,-7:35.0
-1,8,-7:35.0
-2,8,-7:35.0
-3,8,-7:35.0
-4,8,-7:35.0
-5,8,-7:35.0
-6,8,-7:35.0
-8,5,-7:35.0
6,-1,-7:35.0
6,0,-7:35.0
6,1,-7:35.0
-9,0,-7:35.0
-9,1,-7:35.0
-9,2,-7:35.0
-9,3,-7:35.0
-3,-7,-7:35.0
-2,-7,-7:35.0
-5,-3,-7:0
-5,-2,-7:0
-5,-1,-7:0
-5,0,-7:0
-5,1,-7:0
-5,2,-7:0
-5,3,-7:0
-5,4,-7:0
-4,4,-7:0
-3,4,-7:0
-2,4,-7:0
-1,4,-7:0
0,4,-7:0
1,4,-7:0
2,4,-7:0
2,3,-7:0
2,2,-7:0
2,1,-7:0
2,0,-7:0
2,-1,-7:0
2,-2,-7:0
2,-3,-7:0
1,-3,-7:0
0,-3,-7:0
-1,-3,-7:0
-2,-3,-7:0
-3,-3,-7:0
-4,-3,-7:0
-4,-2,-7:0
-4,-1,-7:0
-4,0,-7:0
-4,1,-7:0
-4,2,-7:0
-4,3,-7:0
-3,3,-7:0
-2,3,-7:0
-1,3,-7:0
0,3,-7:0
1,3,-7:0
1,2,-7:0
1,1,-7:0
1,0,-7:0
1,-1,-7:0
1,-2,-7:0
0,-2,-7:0
-1,-2,-7:0
-2,-2,-7:0
-3,-2,-7:0
-3,-1,-7:0
-3,0,-7:0
-3,1,-7:0
-3,2,-7:0
-2,2,-7:0
-1,2,-7:0
0,2,-7:0
0,1,-7:0
0,0,-7:0
0,-1,-7:0
-1,-1,-7:0
-2,-1,-7:0
-2,0,-7:0
-2,1,-7:0
-1,1,-7:0
-1,0,-7:0
-6,-4,-8:1
-6,-3,-8:1
-6,-2,-8:1
-6,-1,-8:1
-6,0,-8:1
-6,1,-8:1
-6,2,-8:1
-6,3,-8:1
-6,4,-8:1
-6,5,-8:1
-5,5,-8:1
-4,5,-8:1
-3,5,-8:1
-2,5,-8:1
-1,5,-8:1
0,5,-8:1
1,5,-8:1
2,5,-8:1
3,5,-8:1
3,4,-8:1
3,3,-8:1
3,2,-8:1
3,1,-8:1
3,0,-8:1
3,-1,-8:1
3,-2,-8:1
3,-3,-8:1
3,-4,-8:1
2,-4,-8:1
1,-4,-8:1
0,-4,-8:1
-1,-4,-8:1
-2,-4,-8:1
-3,-4,-8:1
-4,-4,-8:1
-5,-4,-8:1
-7,-5,-8:35.0
-7,-4,-8:35.0
-7,-3,-8:35.0
-7,-2,-8:35.0
-7,-1,-8:35.0
-7,0,-8:35.0
-7,1,-8:35.0
-7,2,-8:35.0
-7,3,-8:35.0
-7,4,-8:35.0
-7,5,-8:35.0
-7,6,-8:35.0
-8,3,-8:35.0
-8,2,-8:35.0
-8,1,-8:35.0
-8,0,-8:35.0
-8,-1,-8:35.0
-8,-2,-8:35.0
-8,-3,-8:35.0
-8,4,-8:35.0
-6,6,-8:35.0
-5,6,-8:35.0
-4,6,-8:35.0
-3,6,-8:35.0
-2,6,-8:35.0
-1,6,-8:35.0
0,6,-8:35.0
1,6,-8:35.0
2,6,-8:35.0
3,6,-8:35.0
4,6,-8:35.0
5,6,-8:35.0
2,7,-8:35.0
1,7,-8:35.0
0,7,-8:35.0
-1,7,-8:35.0
-2,7,-8:35.0
-3,7,-8:35.0
-4,7,-8:35.0
-5,7,-8:35.0
4,5,-8:35.0
4,4,-8:35.0
4,3,-8:35.0
5,3,-8:35.0
5,2,-8:35.0
5,1,-8:35.0
5,0,-8:35.0
4,0,-8:35.0
4,-1,-8:35.0
4,-2,-8:35.0
4,-3,-8:35.0
4,-4,-8:35.0
4,-5,-8:35.0
4,1,-8:35.0
4,2,-8:35.0
5,4,-8:35.0
5,5,-8:35.0
3,7,-8:35.0
4,7,-8:35.0
-6,-5,-8:35.0
-5,-5,-8:35.0
-4,-5,-8:35.0
-3,-5,-8:35.0
-2,-5,-8:35.0
-1,-5,-8:35.0
0,-5,-8:35.0
1,-5,-8:35.0
2,-5,-8:35.0
3,-5,-8:35.0
2,-6,-8:35.0
1,-6,-8:35.0
0,-6,-8:35.0
-1,-6,-8:35.0
-2,-6,-8:35.0
-3,-6,-8:35.0
-4,-6,-8:35.0
-5,-6,-8:35.0
-5,-3,-8:0
-4,-3,-8:0
-3,-3,-8:0
-2,-3,-8:0
-1,-3,-8:0
0,-3,-8:0
2,-3,-8:0
1,-2,-8:0
0,-2,-8:0
-1,-2,-8:0
-2,-2,-8:0
-3,-2,-8:0
-4,-2,-8:0
-5,-1,-8:0
-5,0,-8:0
-5,1,-8:0
-5,2,-8:0
-5,3,-8:0
-4,4,-8:0
-3,4,-8:0
-4,3,-8:0
-4,2,-8:0
-4,1,-8:0
-4,0,-8:0
-4,-1,-8:0
-3,-1,-8:0
-3,0,-8:0
-3,1,-8:0
-3,2,-8:0
-3,3,-8:0
-2,-1,-8:0
-2,0,-8:0
-2,1,-8:0
-2,2,-8:0
-2,3,-8:0
-1,4,-8:0
-1,3,-8:0
-1,2,-8:0
-1,1,-8:0
-1,0,-8:0
-1,-1,-8:0
0,-1,-8:0
0,0,-8:0
0,1,-8:0
0,2,-8:0
0,3,-8:0
1,4,-8:0
1,3,-8:0
1,2,-8:0
1,1,-8:0
1,0,-8:0
1,-1,-8:0
2,-1,-8:0
2,0,-8:0
2,1,-8:0
2,3,-8:0
-2,4,-8:0
-5,4,-8:0
-5,-2,-8:0
1,-3,-8:0
2,-2,-8:0
2,2,-8:0
2,4,-8:0
0,4,-8:0
-6,-4,-9:7
-6,-3,-9:7
-6,-2,-9:7
-6,-1,-9:7
-6,0,-9:7
-6,1,-9:7
-6,2,-9:7
-6,3,-9:7
-6,4,-9:7
-6,5,-9:7
-5,5,-9:7
-4,5,-9:7
-3,5,-9:7
-2,5,-9:7
-1,5,-9:7
0,5,-9:7
1,5,-9:7
2,5,-9:7
3,5,-9:7
3,4,-9:7
3,3,-9:7
3,2,-9:7
3,1,-9:7
3,0,-9:7
3,-1,-9:7
3,-2,-9:7
3,-3,-9:7
3,-4,-9:7
2,-4,-9:7
1,-4,-9:7
0,-4,-9:7
-1,-4,-9:7
-2,-4,-9:7
-3,-4,-9:7
-4,-4,-9:7
-5,-4,-9:7
-7,-6,-9:35.0
-7,-5,-9:35.0
-7,-4,-9:35.0
-7,-3,-9:35.0
-7,-2,-9:35.0
-7,-1,-9:35.0
-7,0,-9:35.0
-7,1,-9:35.0
-7,2,-9:35.0
-7,3,-9:35.0
-7,4,-9:35.0
-7,5,-9:35.0
-7,6,-9:35.0
-7,7,-9:35.0
-8,7,-9:35.0
-8,6,-9:35.0
-8,5,-9:35.0
-8,4,-9:35.0
-8,3,-9:35.0
-8,2,-9:35.0
-8,1,-9:35.0
-8,0,-9:35.0
-8,-1,-9:35.0
-8,-2,-9:35.0
-8,-3,-9:35.0
-6,-5,-9:35.0
-6,-6,-9:35.0
-5,-6,-9:35.0
-4,-6,-9:35.0
-3,-6,-9:35.0
-2,-6,-9:35.0
-1,-6,-9:35.0
0,-6,-9:35.0
1,-6,-9:35.0
2,-6,-9:35.0
3,-6,-9:35.0
4,-6,-9:35.0
4,-5,-9:35.0
5,-5,-9:35.0
5,-4,-9:35.0
5,-3,-9:35.0
5,-2,-9:35.0
6,-2,-9:35.0
6,-1,-9:35.0
6,0,-9:35.0
6,1,-9:35.0
6,2,-9:35.0
6,3,-9:35.0
6,4,-9:35.0
6,5,-9:35.0
5,5,-9:35.0
5,6,-9:35.0
4,6,-9:35.0
4,7,-9:35.0
3,7,-9:35.0
2,7,-9:35.0
1,7,-9:35.0
0,7,-9:35.0
-1,7,-9:35.0
-2,7,-9:35.0
-3,7,-9:35.0
-4,7,-9:35.0
-5,7,-9:35.0
-6,7,-9:35.0
-6,6,-9:35.0
-5,6,-9:35.0
-4,6,-9:35.0
-3,6,-9:35.0
-2,6,-9:35.0
-1,6,-9:35.0
0,6,-9:35.0
1,6,-9:35.0
2,6,-9:35.0
3,6,-9:35.0
4,5,-9:35.0
4,4,-9:35.0
4,3,-9:35.0
4,2,-9:35.0
4,1,-9:35.0
4,0,-9:35.0
4,-1,-9:35.0
4,-2,-9:35.0
4,-3,-9:35.0
4,-4,-9:35.0
5,-1,-9:35.0
5,4,-9:35.0
5,3,-9:35.0
5,2,-9:35.0
5,1,-9:35.0
5,0,-9:35.0
3,-5,-9:35.0
2,-5,-9:35.0
1,-5,-9:35.0
0,-5,-9:35.0
-1,-5,-9:35.0
-2,-5,-9:35.0
-3,-5,-9:35.0
-4,-5,-9:35.0
-5,-5,-9:35.0
-4,8,-9:35.0
-3,8,-9:35.0
-2,8,-9:35.0
-1,8,-9:35.0
0,8,-9:35.0
1,8,-9:35.0
-9,-1,-9:35.0
-9,0,-9:35.0
-9,1,-9:35.0
-9,2,-9:35.0
-9,3,-9:35.0
-9,4,-9:35.0
-8,-5,-9:35.0
-8,-4,-9:35.0
-3,-7,-9:35.0
-2,-7,-9:35.0
-1,-7,-9:35.0
2,-3,-9:25
2,0,-9:84
2,3,-9:61.2
-1,4,-9:23.2
-4,4,-9:58
-3,4,-9:58
-5,1,-9:54
-5,0,-9:54
-4,-3,-9:92
-3,-3,-9:92
-2,-3,-9:92
-1,-3,-9:92
0,-3,-9:92
-5,-3,-9:92
-5,2,-9:117
-5,3,-9:117
-5,-1,-9:47
2,-1,-9:47
2,1,-9:47
1,4,-9:91.0
-5,-2,-9:89
-4,-2,-9:0
-4,-1,-9:0
-4,0,-9:0
-4,1,-9:0
-4,2,-9:0
-5,4,-9:89
-4,3,-9:0
-3,3,-9:0
-3,2,-9:0
-3,1,-9:0
-3,0,-9:0
-3,-1,-9:0
-3,-2,-9:0
-2,-2,-9:0
-1,-2,-9:0
0,-2,-9:0
1,-2,-9:0
2,-2,-9:89
1,-3,-9:89
-2,-1,-9:0
-1,-1,-9:0
-1,0,-9:0
-1,1,-9:0
-2,2,-9:0
-2,3,-9:0
-2,4,-9:89
-1,2,-9:0
-1,3,-9:0
0,-1,-9:0
0,0,-9:0
0,1,-9:0
0,2,-9:0
0,3,-9:0
0,4,-9:89
1,-1,-9:0
1,0,-9:0
1,1,-9:0
1,2,-9:0
1,3,-9:0
2,2,-9:89
2,4,-9:89
-2,0,-9:0
-2,1,-9:0
-6,-4,-10:7
-6,-3,-10:7
-6,-2,-10:7
-6,-1,-10:7
-6,0,-10:7
-6,1,-10:7
-6,2,-10:7
-6,3,-10:7
-6,4,-10:7
-6,5,-10:7
-5,5,-10:7
-4,5,-10:7
-3,5,-10:7
-2,5,-10:7
-1,5,-10:7
0,5,-10:7
1,5,-10:7
2,5,-10:7
3,5,-10:7
3,4,-10:7
3,3,-10:7
3,2,-10:7
3,1,-10:7
3,0,-10:7
3,-1,-10:7
3,-2,-10:7
3,-3,-10:7
3,-4,-10:7
2,-4,-10:7
1,-4,-10:7
0,-4,-10:7
-1,-4,-10:7
-2,-4,-10:7
-3,-4,-10:7
-4,-4,-10:7
-5,-4,-10:7
-5,-3,-10:7
-5,-2,-10:7
-5,-1,-10:7
-5,0,-10:7
-5,1,-10:7
-5,2,-10:7
-5,3,-10:7
-5,4,-10:7
-4,4,-10:7
-3,4,-10:7
-2,4,-10:7
-1,4,-10:7
0,4,-10:7
1,4,-10:7
2,4,-10:7
2,3,-10:7
2,2,-10:7
2,1,-10:7
2,0,-10:7
2,-1,-10:7
2,-2,-10:7
2,-3,-10:7
1,-3,-10:7
0,-3,-10:7
-1,-3,-10:7
-2,-3,-10:7
-3,-3,-10:7
-4,-3,-10:7
-4,-2,-10:7
-4,-1,-10:7
-4,0,-10:7
-4,1,-10:7
-4,2,-10:7
-4,3,-10:7
-3,3,-10:7
-2,3,-10:7
-1,3,-10:7
0,3,-10:7
1,3,-10:7
1,2,-10:7
1,1,-10:7
1,0,-10:7
1,-1,-10:7
1,-2,-10:7
0,-2,-10:7
-1,-2,-10:7
-2,-2,-10:7
-2,-1,-10:7
-3,-1,-10:7
-3,0,-10:7
-3,1,-10:7
-3,2,-10:7
-2,2,-10:7
-1,2,-10:7
0,2,-10:7
0,1,-10:7
0,0,-10:7
0,-1,-10:7
-1,-1,-10:7
-1,0,-10:7
-1,1,-10:7
-2,1,-10:7
-2,0,-10:7
-3,-2,-10:7
-7,-5,-10:35.0
-7,-4,-10:35.0
-7,-3,-10:35.0
-7,-2,-10:35.0
-7,-1,-10:35.0
-7,0,-10:35.0
-7,1,-10:35.0
-7,2,-10:35.0
-7,3,-10:35.0
-7,4,-10:35.0
-7,5,-10:35.0
-7,6,-10:35.0
-6,6,-10:35.0
-5,6,-10:35.0
-4,6,-10:35.0
-3,6,-10:35.0
-2,6,-10:35.0
-1,6,-10:35.0
0,6,-10:35.0
1,6,-10:35.0
2,6,-10:35.0
3,6,-10:35.0
4,6,-10:35.0
4,5,-10:35.0
4,4,-10:35.0
4,3,-10:35.0
4,2,-10:35.0
4,1,-10:35.0
4,0,-10:35.0
4,-1,-10:35.0
4,-2,-10:35.0
4,-3,-10:35.0
4,-4,-10:35.0
4,-5,-10:35.0
3,-5,-10:35.0
2,-5,-10:35.0
1,-5,-10:35.0
0,-5,-10:35.0
-1,-5,-10:35.0
-2,-5,-10:35.0
-3,-5,-10:35.0
-4,-5,-10:35.0
-5,-5,-10:35.0
-6,-5,-10:35.0
-6,-6,-10:35.0
-5,-6,-10:35.0
-4,-6,-10:35.0
-3,-7,-10:35.0
-2,-7,-10:35.0
-1,-7,-10:35.0
0,-7,-10:35.0
0,-6,-10:35.0
1,-7,-10:35.0
1,-6,-10:35.0
2,-6,-10:35.0
-1,-6,-10:35.0
-2,-6,-10:35.0
-3,-6,-10:35.0
-8,-3,-10:35.0
-8,-2,-10:35.0
-8,-1,-10:35.0
-8,0,-10:35.0
-8,1,-10:35.0
-8,2,-10:35.0
-8,3,-10:35.0
-8,4,-10:35.0
-9,3,-10:35.0
-9,2,-10:35.0
-9,1,-10:35.0
-9,0,-10:35.0
-6,7,-10:35.0
-5,7,-10:35.0
-4,7,-10:35.0
-3,7,-10:35.0
-2,7,-10:35.0
-1,7,-10:35.0
0,7,-10:35.0
1,7,-10:35.0
0,8,-10:35.0
-1,8,-10:35.0
-2,8,-10:35.0
2,7,-10:35.0
5,5,-10:35.0
5,4,-10:35.0
5,3,-10:35.0
5,2,-10:35.0
5,1,-10:35.0
5,0,-10:35.0
5,-1,-10:35.0
5,-2,-10:35.0
5,-3,-10:35.0
6,1,-10:35.0
6,2,-10:35.0
6,3,-10:35.0
-8,-6,-11:1
-8,-5,-11:1
-8,-4,-11:1
-9,-4,-11:1
-9,-3,-11:1
-9,-2,-11:1
-9,-1,-11:1
-9,0,-11:1
-9,1,-11:1
-9,2,-11:1
-9,3,-11:1
-8,3,-11:1
-8,4,-11:1
-8,5,-11:1
-7,5,-11:1
-7,6,-11:1
-7,7,-11:1
-6,7,-11:1
-5,7,-11:1
-4,8,-11:1
-3,8,-11:1
-2,8,-11:1
-1,8,-11:1
0,8,-11:1
1,8,-11:1
2,8,-11:1
3,8,-11:1
4,8,-11:1
5,7,-11:1
6,7,-11:1
6,6,-11:1
7,6,-11:1
7,5,-11:1
7,4,-11:1
8,4,-11:1
8,3,-11:1
8,2,-11:1
8,1,-11:1
8,0,-11:1
8,-1,-11:1
8,-2,-11:1
8,-3,-11:1
8,-4,-11:1
8,-5,-11:1
8,-6,-11:1
7,-6,-11:1
7,-7,-11:1
6,-7,-11:1
5,-8,-11:1
4,-8,-11:1
3,-8,-11:1
2,-8,-11:1
2,-7,-11:1
1,-7,-11:1
0,-7,-11:1
-1,-7,-11:1
-2,-7,-11:1
-3,-7,-11:1
-4,-7,-11:1
-5,-7,-11:1
-6,-7,-11:1
-6,-8,-11:1
-7,-8,-11:1
-7,-7,-11:1
-7,-6,-11:1
-7,-5,-11:1
-7,-4,-11:1
-7,-3,-11:1
-7,-2,-11:1
-7,-1,-11:1
-7,0,-11:1
-7,1,-11:1
-7,2,-11:1
-7,3,-11:1
-7,4,-11:1
-8,2,-11:1
-8,1,-11:1
-8,0,-11:1
-8,-1,-11:1
-8,-2,-11:1
-8,-3,-11:1
-6,-5,-11:1
-5,-5,-11:1
-5,-6,-11:1
-4,-6,-11:1
-5,-8,-11:1
-4,-8,-11:1
-3,-8,-11:1
-2,-8,-11:1
-1,-8,-11:1
0,-8,-11:1
1,-8,-11:1
1,-9,-11:1
0,-9,-11:1
-6,-6,-11:1
-3,-6,-11:1
-3,-5,-11:1
-3,-4,-11:1
-4,-4,-11:1
-4,-3,-11:1
-4,-2,-11:1
-5,-2,-11:1
-5,-1,-11:1
-5,0,-11:1
-5,1,-11:1
-5,2,-11:1
-5,3,-11:1
-5,4,-11:1
-5,5,-11:1
-5,6,-11:1
-6,6,-11:1
-6,5,-11:1
-6,4,-11:1
-6,3,-11:1
-6,2,-11:1
-6,1,-11:1
-6,0,-11:1
-6,-1,-11:1
-6,-2,-11:1
-6,-3,-11:1
-6,-4,-11:1
-5,-4,-11:1
-5,-3,-11:1
-4,-5,-11:1
-4,-1,-11:1
-4,0,-11:1
-4,1,-11:1
-4,2,-11:1
-3,2,-11:1
-3,3,-11:1
-3,4,-11:1
-3,5,-11:1
-3,6,-11:1
-4,6,-11:1
-4,7,-11:1
-4,5,-11:1
-4,4,-11:1
-4,3,-11:1
-3,7,-11:1
-2,7,-11:1
-1,7,-11:1
0,7,-11:1
1,7,-11:1
2,7,-11:1
3,7,-11:1
4,7,-11:1
-2,6,-11:1
-2,5,-11:1
-2,4,-11:1
-2,3,-11:1
-2,2,-11:1
-2,1,-11:1
-2,0,-11:1
-2,-1,-11:1
-2,-2,-11:1
-2,-3,-11:1
-2,-4,-11:1
-2,-5,-11:1
-2,-6,-11:1
-3,-3,-11:1
-3,-2,-11:1
-3,-1,-11:1
-3,0,-11:1
-3,1,-11:1
-1,-5,-11:1
-1,-6,-11:1
-1,-4,-11:1
-1,-3,-11:1
-1,-2,-11:1
-1,-1,-11:1
-1,0,-11:1
-1,1,-11:1
-1,2,-11:1
-1,3,-11:1
-1,4,-11:1
-1,5,-11:1
-1,6,-11:1
0,6,-11:1
0,5,-11:1
0,4,-11:1
0,3,-11:1
0,2,-11:1
0,1,-11:1
0,0,-11:1
0,-1,-11:1
0,-2,-11:1
0,-3,-11:1
0,-4,-11:1
0,-5,-11:1
1,-5,-11:1
1,-6,-11:1
1,-4,-11:1
1,-3,-11:1
1,-2,-11:1
1,-1,-11:1
1,0,-11:1
1,1,-11:1
1,2,-11:1
1,3,-11:1
1,4,-11:1
1,5,-11:1
1,6,-11:1
2,6,-11:1
2,5,-11:1
2,4,-11:1
2,3,-11:1
2,2,-11:1
2,1,-11:1
3,1,-11:1
3,0,-11:1
3,-1,-11:1
3,-2,-11:1
3,-3,-11:1
3,-4,-11:1
3,-5,-11:1
3,-6,-11:1
3,-7,-11:1
2,-6,-11:1
2,-5,-11:1
2,-4,-11:1
2,-3,-11:1
2,-2,-11:1
2,-1,-11:1
2,0,-11:1
0,-6,-11:1
4,-6,-11:1
4,-7,-11:1
4,-5,-11:1
4,-4,-11:1
4,-3,-11:1
4,-2,-11:1
4,-1,-11:1
4,0,-11:1
4,1,-11:1
4,2,-11:1
4,3,-11:1
4,4,-11:1
4,5,-11:1
4,6,-11:1
3,6,-11:1
3,5,-11:1
3,4,-11:1
3,3,-11:1
3,2,-11:1
5,0,-11:1
5,-1,-11:1
5,-2,-11:1
5,-3,-11:1
5,-4,-11:1
5,-5,-11:1
5,-6,-11:1
5,-7,-11:1
6,0,-11:1
6,1,-11:1
6,2,-11:1
6,3,-11:1
5,3,-11:1
5,4,-11:1
5,5,-11:1
5,6,-11:1
5,2,-11:1
5,1,-11:1
6,4,-11:1
6,5,-11:1
7,2,-11:1
7,3,-11:1
7,1,-11:1
7,0,-11:1
7,-1,-11:1
7,-2,-11:1
7,-3,-11:1
7,-4,-11:1
7,-5,-11:1
6,-5,-11:1
6,-6,-11:1
6,-4,-11:1
6,-3,-11:1
6,-2,-11:1
6,-1,-11:1
-4,-9,-11:1
-3,-9,-11:1
-2,-9,-11:1
-1,-9,-11:1
