[META]
version=2.0
spawnOnBlockType=13
spawnSunlight=True
spawnDarkness=False
spawnWater=False
spawnLava=False
underFill=True
randomRotation=True
dig=True
tree=False
branch=False
needsFoundation=True
rarity=2
collisionPercentage=0
spawnElevationMin=0
spawnElevationMax=72
spawnInBiome=DesertGravel
[DATA]
-12,-14,0:1
-12,-13,0:1
-12,-12,0:1
-12,-11,0:1
-12,-10,0:1
-12,-9,0:1
-12,-8,0:1
-12,-7,0:1
-12,-6,0:1
-12,-5,0:1
-12,-4,0:1
-12,-3,0:1
-12,-2,0:1
-12,-1,0:1
-12,0,0:1
-11,0,0:1
-10,0,0:1
-9,0,0:1
-8,0,0:1
-7,0,0:1
-6,0,0:1
-6,-1,0:1
-6,-2,0:1
-6,-3,0:1
-6,-6,0:1
-6,-7,0:1
-6,-8,0:1
-6,-9,0:1
-5,-9,0:1
-4,-9,0:1
-3,-9,0:1
-2,-9,0:1
-2,-10,0:1
-2,-11,0:1
-2,-12,0:1
-2,-13,0:1
-2,-14,0:1
-2,-15,0:1
-3,-15,0:1
-4,-15,0:1
-5,-15,0:1
-6,-15,0:1
-7,-15,0:1
-8,-15,0:1
-9,-15,0:1
-10,-15,0:1
-11,-15,0:1
-12,-15,0:1
-1,7,0:1
2,7,0:1
3,7,0:1
4,7,0:1
5,7,0:1
5,8,0:1
5,9,0:1
5,10,0:1
5,11,0:1
5,12,0:1
5,13,0:1
5,14,0:1
5,15,0:1
4,15,0:1
3,15,0:1
2,15,0:1
1,15,0:1
0,15,0:1
-1,15,0:1
-2,15,0:1
-3,15,0:1
-3,14,0:1
-3,13,0:1
-3,12,0:1
-3,11,0:1
-3,10,0:1
-3,9,0:1
-3,8,0:1
-3,7,0:1
-2,7,0:1
4,-11,0:1
4,-10,0:1
4,-9,0:1
4,-8,0:1
4,-7,0:1
4,-4,0:1
4,-3,0:1
4,-2,0:1
4,-1,0:1
4,0,0:1
4,1,0:1
5,1,0:1
6,1,0:1
7,1,0:1
8,1,0:1
9,1,0:1
10,1,0:1
10,0,0:1
10,-1,0:1
10,-2,0:1
10,-3,0:1
10,-4,0:1
10,-5,0:1
10,-6,0:1
10,-7,0:1
10,-8,0:1
10,-9,0:1
10,-10,0:1
10,-11,0:1
5,-11,0:1
6,-11,0:1
7,-11,0:1
8,-11,0:1
9,-11,0:1
-3,-10,0:52
5,-10,0:52
4,8,0:52
-12,-15,-1:1
-12,-14,-1:1
-12,-13,-1:1
-12,-12,-1:1
-12,-11,-1:1
-12,-10,-1:1
-12,-9,-1:1
-12,-8,-1:1
-12,-7,-1:1
-12,-6,-1:1
-12,-5,-1:1
-12,-4,-1:1
-12,-3,-1:1
-12,-2,-1:1
-11,-2,-1:1
-10,-2,-1:1
-9,-2,-1:1
-8,-2,-1:1
-7,-2,-1:1
-7,-3,-1:1
-7,-4,-1:1
-7,-5,-1:1
-7,-6,-1:1
-7,-7,-1:1
-7,-8,-1:1
-7,-9,-1:1
-7,-10,-1:1
-6,-10,-1:1
-5,-10,-1:1
-4,-10,-1:1
-3,-10,-1:1
-3,-11,-1:1
-3,-12,-1:1
-3,-13,-1:1
-3,-14,-1:1
-3,-15,-1:1
-4,-15,-1:1
-5,-15,-1:1
-6,-15,-1:1
-7,-15,-1:1
-8,-15,-1:1
-10,-15,-1:1
-11,-15,-1:1
-12,0,-1:1
-11,0,-1:1
-10,0,-1:1
-9,0,-1:1
-8,0,-1:1
-7,0,-1:1
-7,-1,-1:1
-8,-1,-1:1
-9,-1,-1:1
-10,-1,-1:1
-11,-1,-1:1
-12,-1,-1:1
-4,-14,-1:1
-4,-13,-1:1
-4,-12,-1:1
-4,-11,-1:1
-5,-11,-1:1
-6,-11,-1:1
-7,-11,-1:1
-8,-11,-1:1
-9,-11,-1:1
-9,-10,-1:1
-10,-10,-1:1
-11,-10,-1:1
-11,-9,-1:1
-11,-8,-1:1
-11,-7,-1:1
-11,-6,-1:1
-11,-5,-1:1
-11,-4,-1:1
-11,-3,-1:1
-10,-3,-1:1
-9,-3,-1:1
-8,-3,-1:1
-8,-4,-1:1
-8,-5,-1:1
-8,-6,-1:1
-8,-7,-1:1
-8,-8,-1:1
-8,-9,-1:1
-8,-10,-1:1
-9,-9,-1:1
-9,-8,-1:1
-9,-7,-1:1
-9,-6,-1:1
-9,-5,-1:1
-9,-4,-1:1
-10,-4,-1:1
-10,-5,-1:1
-10,-6,-1:1
-10,-7,-1:1
-10,-8,-1:1
-10,-9,-1:1
-10,-11,-1:1
-10,-12,-1:1
-10,-13,-1:1
-10,-14,-1:1
-9,-15,-1:1
-9,-14,-1:1
-9,-13,-1:1
-9,-12,-1:1
-8,-12,-1:1
-7,-12,-1:1
-7,-13,-1:1
-6,-13,-1:1
-6,-14,-1:1
-5,-14,-1:1
-5,-13,-1:1
-5,-12,-1:1
-6,-12,-1:1
-7,-14,-1:1
-8,-14,-1:1
-8,-13,-1:1
-11,-14,-1:1
-11,-13,-1:1
-11,-12,-1:1
-11,-11,-1:1
-3,7,-1:1
-3,8,-1:1
-3,9,-1:1
-3,10,-1:1
-3,11,-1:1
-3,12,-1:1
-3,13,-1:1
-3,14,-1:1
-3,15,-1:1
-2,15,-1:1
-1,15,-1:1
0,15,-1:1
1,15,-1:1
2,15,-1:1
3,15,-1:1
4,15,-1:1
5,15,-1:1
5,14,-1:1
5,13,-1:1
5,12,-1:1
4,12,-1:1
4,11,-1:1
4,10,-1:1
5,10,-1:1
5,9,-1:1
5,8,-1:1
5,7,-1:1
4,7,-1:1
3,7,-1:1
2,7,-1:1
1,7,-1:1
0,7,-1:1
-1,7,-1:1
-2,7,-1:1
-2,8,-1:1
-2,9,-1:1
-2,10,-1:1
-2,11,-1:1
-2,12,-1:1
-2,13,-1:1
-2,14,-1:1
-1,14,-1:1
0,14,-1:1
1,14,-1:1
2,14,-1:1
3,14,-1:1
4,14,-1:1
4,13,-1:1
5,11,-1:1
4,9,-1:1
4,8,-1:1
3,11,-1:1
3,12,-1:1
3,13,-1:1
3,10,-1:1
3,9,-1:1
3,8,-1:1
2,9,-1:1
2,10,-1:1
2,11,-1:1
2,12,-1:1
2,13,-1:1
2,8,-1:1
1,8,-1:1
0,8,-1:1
-1,8,-1:1
-1,9,-1:1
-1,10,-1:1
-1,11,-1:1
-1,12,-1:1
-1,13,-1:1
0,13,-1:1
1,13,-1:1
1,12,-1:1
1,11,-1:1
1,10,-1:1
1,9,-1:1
0,9,-1:1
0,10,-1:1
0,11,-1:1
0,12,-1:1
4,-11,-1:1
4,-10,-1:1
4,-9,-1:1
4,-8,-1:1
4,-7,-1:1
4,-6,-1:1
4,-5,-1:1
4,-4,-1:1
4,-3,-1:1
4,-2,-1:1
4,-1,-1:1
4,0,-1:1
4,1,-1:1
5,1,-1:1
6,1,-1:1
7,1,-1:1
8,1,-1:1
9,1,-1:1
10,1,-1:1
10,0,-1:1
10,-1,-1:1
10,-2,-1:1
10,-3,-1:1
10,-4,-1:1
10,-5,-1:1
10,-6,-1:1
10,-7,-1:1
10,-8,-1:1
10,-9,-1:1
10,-10,-1:1
10,-11,-1:1
9,-11,-1:1
8,-11,-1:1
7,-11,-1:1
6,-11,-1:1
5,-11,-1:1
5,-10,-1:1
5,-9,-1:1
5,-8,-1:1
5,-7,-1:1
5,-6,-1:1
5,-5,-1:1
5,-4,-1:1
5,-3,-1:1
5,-2,-1:1
5,-1,-1:1
5,0,-1:1
6,0,-1:1
6,-1,-1:1
6,-2,-1:1
6,-3,-1:1
6,-4,-1:1
6,-5,-1:1
6,-6,-1:1
6,-7,-1:1
6,-8,-1:1
6,-9,-1:1
6,-10,-1:1
7,-10,-1:1
7,-9,-1:1
7,-8,-1:1
7,-7,-1:1
7,-6,-1:1
7,-5,-1:1
7,-4,-1:1
7,-3,-1:1
7,-2,-1:1
7,-1,-1:1
7,0,-1:1
8,0,-1:1
8,-1,-1:1
8,-2,-1:1
8,-3,-1:1
8,-4,-1:1
8,-5,-1:1
8,-6,-1:1
8,-7,-1:1
8,-8,-1:1
8,-9,-1:1
8,-10,-1:1
9,-10,-1:1
9,-9,-1:1
9,-8,-1:1
9,-7,-1:1
9,-6,-1:1
9,-5,-1:1
9,-4,-1:1
9,-3,-1:1
9,-2,-1:1
9,-1,-1:1
9,0,-1:1
-6,-6,1:1
-6,-7,1:1
-6,-8,1:1
-6,-9,1:1
-5,-9,1:1
-4,-9,1:1
-3,-9,1:1
-2,-9,1:1
-2,-10,1:1
-2,-11,1:102
-2,-12,1:102
-2,-13,1:102
-2,-14,1:1
-2,-15,1:1
-12,-15,1:1
-11,-15,1:1
-10,-15,1:1
-5,-15,1:1
-4,-15,1:1
-3,-15,1:1
-12,-14,1:1
-12,-13,1:1
-12,-12,1:1
-12,-11,1:102
-12,-10,1:102
-12,-9,1:102
-12,-8,1:102
-12,-7,1:102
-12,-6,1:1
-12,-5,1:1
-12,-4,1:1
-12,-3,1:1
-10,0,1:1
-9,0,1:102
-8,0,1:102
-7,0,1:1
-6,0,1:1
-6,-1,1:1
-6,-2,1:1
-6,-3,1:1
-1,7,1:1
-2,7,1:1
-3,7,1:1
-3,8,1:102
-3,9,1:102
-3,10,1:102
-3,11,1:102
-3,12,1:1
0,15,1:1
1,15,1:102
2,15,1:102
3,15,1:102
4,15,1:1
5,15,1:1
5,14,1:1
5,13,1:102
5,12,1:102
5,10,1:102
5,9,1:102
5,8,1:1
5,7,1:1
4,7,1:1
3,7,1:1
2,7,1:1
5,11,1:102
4,-4,1:1
4,-3,1:1
4,-2,1:1
7,1,1:1
8,1,1:1
9,1,1:1
10,1,1:1
10,-8,1:1
10,-7,1:1
10,-6,1:102
10,-5,1:102
10,-4,1:102
10,-3,1:102
10,-2,1:102
10,-1,1:1
10,0,1:1
8,-11,1:1
7,-11,1:1
6,-11,1:1
5,-11,1:1
4,-11,1:1
4,-10,1:102
4,-9,1:102
4,-8,1:1
4,-7,1:1
-9,-15,1:102
-8,-15,1:102
-7,-15,1:102
-6,-15,1:102
-10,0,2:1
-7,0,2:1
-6,0,2:1
-6,-1,2:1
-6,-2,2:1
-6,-3,2:1
-6,-6,2:1
-6,-7,2:1
-6,-8,2:1
-6,-9,2:1
-5,-9,2:1
-4,-9,2:1
-3,-9,2:1
-2,-9,2:1
-2,-10,2:1
-2,-11,2:1
-2,-12,2:1
-5,-15,2:1
-6,-15,2:102
-7,-15,2:102
-8,-15,2:102
-9,-15,2:102
-10,-15,2:1
-12,-12,2:1
-12,-11,2:1
-12,-10,2:102
-12,-9,2:102
-12,-8,2:102
-12,-7,2:102
-12,-6,2:102
-12,-5,2:1
-12,-4,2:1
-1,7,2:1
-2,7,2:1
-3,7,2:1
-3,8,2:1
-3,11,2:1
1,15,2:1
2,15,2:102
3,15,2:102
4,15,2:102
5,15,2:1
5,14,2:1
5,13,2:1
5,10,2:1
5,9,2:1
5,8,2:1
5,7,2:1
4,7,2:102
3,7,2:102
2,7,2:1
4,-4,2:1
4,-3,2:1
4,-2,2:1
7,1,2:1
8,1,2:1
9,1,2:1
10,1,2:1
10,-7,2:1
10,-6,2:1
10,-5,2:102
10,-4,2:102
10,-3,2:102
10,-2,2:102
10,-1,2:1
10,0,2:1
7,-11,2:1
6,-11,2:1
5,-11,2:1
4,-11,2:1
4,-10,2:1
4,-9,2:1
4,-8,2:1
4,-7,2:1
-4,-15,3:1
-5,-15,3:1
-6,-15,3:1
-7,-15,3:1
-8,-15,3:1
-9,-15,3:1
-10,-15,3:1
-11,-15,3:1
-12,-13,3:1
-12,-12,3:1
-12,-11,3:1
-12,-10,3:1
-12,-9,3:1
-12,-8,3:1
-12,-7,3:1
-12,-6,3:1
-12,-5,3:1
-12,-4,3:1
-12,-3,3:1
-11,0,3:1
-10,0,3:1
-7,0,3:1
-6,0,3:1
-6,-1,3:1
-6,-2,3:1
-6,-3,3:1
-6,-6,3:1
-6,-7,3:1
-6,-8,3:1
-6,-9,3:1
-5,-9,3:1
-4,-9,3:1
-3,-9,3:1
-2,-9,3:1
-2,-10,3:1
-2,-11,3:1
-2,-12,3:1
-2,-13,3:1
-1,7,3:1
-2,7,3:1
-3,8,3:1
-3,7,3:1
-3,11,3:1
-3,12,3:1
-1,15,3:1
0,15,3:1
1,15,3:1
2,15,3:1
3,15,3:1
4,15,3:1
5,15,3:1
2,7,3:1
3,7,3:1
4,7,3:1
5,7,3:1
5,8,3:1
5,9,3:1
5,10,3:1
5,13,3:1
5,14,3:1
4,-4,3:1
4,-3,3:1
4,-2,3:1
4,-1,3:1
6,1,3:1
7,1,3:1
8,1,3:1
9,1,3:1
10,1,3:1
10,-7,3:1
10,-6,3:1
10,-5,3:1
10,-4,3:1
10,-3,3:1
10,-2,3:1
10,-1,3:1
10,0,3:1
8,-11,3:1
7,-11,3:1
6,-11,3:1
5,-11,3:1
4,-11,3:1
4,-10,3:1
4,-9,3:1
4,-8,3:1
4,-7,3:1
4,-11,4:1
4,-10,4:1
4,-9,4:1
4,-8,4:1
4,-7,4:1
4,-6,4:1
4,-5,4:1
4,-4,4:1
4,-3,4:1
4,-2,4:1
4,-1,4:1
4,0,4:1
4,1,4:1
5,1,4:1
9,1,4:1
10,1,4:1
10,0,4:1
10,-1,4:1
10,-2,4:1
10,-3,4:1
7,-11,4:1
8,-11,4:1
9,-11,4:1
10,-11,4:1
10,-8,4:1
10,-7,4:1
10,-6,4:1
10,-5,4:1
10,-4,4:1
2,7,4:1
3,7,4:1
4,7,4:1
5,7,4:1
5,8,4:1
5,9,4:1
5,10,4:1
5,11,4:1
5,12,4:1
5,13,4:1
5,14,4:1
3,15,4:1
2,15,4:1
1,15,4:1
-1,15,4:1
-2,15,4:1
0,15,4:1
-3,13,4:1
-3,12,4:1
-3,11,4:1
-3,10,4:1
-3,9,4:1
-3,8,4:1
-3,7,4:1
-2,7,4:1
-1,7,4:1
0,7,4:1
1,7,4:1
-6,-9,4:1
-6,-8,4:1
-6,-7,4:1
-6,-6,4:1
-6,-5,4:1
-6,-4,4:1
-6,-3,4:1
-6,-2,4:1
-6,-1,4:1
-9,0,4:1
-10,0,4:1
-11,0,4:1
-12,0,4:1
-12,-3,4:1
-12,-4,4:1
-12,-5,4:1
-12,-6,4:1
-12,-7,4:1
-12,-8,4:1
-12,-9,4:1
-12,-10,4:1
-12,-11,4:1
-12,-12,4:1
-10,-15,4:1
-9,-15,4:1
-8,-15,4:1
-7,-15,4:1
-6,-15,4:1
-5,-15,4:1
-2,-12,4:1
-2,-11,4:1
-2,-10,4:1
-2,-9,4:1
-3,-9,4:1
-4,-9,4:1
-5,-9,4:1
-10,-15,5:1
-11,-15,5:1
-12,-15,5:1
-12,-14,5:1
-12,-13,5:1
-12,-12,5:1
-12,-11,5:1
-12,-10,5:1
-12,-9,5:1
-12,-4,5:1
-12,-3,5:1
-12,-2,5:1
-12,-1,5:1
-12,0,5:1
-11,0,5:1
-6,-3,5:1
-6,-4,5:1
-6,-5,5:1
-6,-6,5:1
-6,-7,5:1
-4,-9,5:1
-3,-9,5:1
-2,-9,5:1
-2,-11,5:1
-2,-10,5:1
-5,-15,5:1
-6,-15,5:1
4,-9,5:1
4,-8,5:1
4,-7,5:1
4,-6,5:1
4,-5,5:1
4,-4,5:1
4,-3,5:1
10,-6,5:1
10,-5,5:1
10,-4,5:1
10,-3,5:1
10,-2,5:1
5,1,5:1
7,1,5:1
8,1,5:1
9,1,5:1
4,-11,5:1
5,-11,5:1
6,-11,5:1
7,-11,5:1
8,-11,5:1
9,-11,5:1
10,-9,5:1
10,-8,5:1
-3,10,5:1
-3,11,5:1
-3,12,5:1
-3,13,5:1
-3,14,5:1
-3,15,5:1
-2,15,5:1
-1,15,5:1
2,15,5:1
5,12,5:1
5,11,5:1
5,10,5:1
5,9,5:1
2,7,5:1
1,7,5:1
0,7,5:1
-1,7,5:1
-1,8,5:1
-1,9,5:1
-1,10,5:1
-1,11,5:1
-1,12,5:1
-1,13,5:1
-1,14,5:1
5,-8,5:1
6,-8,5:1
7,-8,5:1
8,-8,5:1
9,-8,5:1
5,-3,5:1
6,-3,5:1
7,-3,5:1
8,-3,5:1
9,-3,5:1
-11,-4,5:1
-10,-4,5:1
-9,-4,5:1
-8,-4,5:1
-7,-4,5:1
-11,-12,5:1
-10,-12,5:1
-9,-12,5:1
-8,-12,5:1
-7,-12,5:1
-6,-12,5:1
-5,-14,5:1
-5,-13,5:1
-5,-12,5:1
-4,-12,5:1
-4,-11,5:1
-4,-10,5:1
-9,-11,5:1
-9,-10,5:1
-12,-14,6:1
-12,-13,6:1
-12,-12,6:1
-9,-12,6:1
-8,-12,6:1
-7,-12,6:1
-4,-10,6:1
-4,-9,6:1
-3,-9,6:1
-6,-6,6:1
-6,-5,6:1
-6,-4,6:1
-9,-4,6:1
-10,-4,6:1
-11,-4,6:1
-12,-1,6:1
-12,0,6:1
-11,0,6:1
-6,-15,6:1
-5,-15,6:1
-5,-14,6:1
-10,-15,6:1
-12,-9,6:1
1,7,6:1
0,7,6:1
-1,7,6:1
-1,8,6:1
-1,9,6:1
-3,13,6:1
-3,14,6:1
-3,15,6:1
-2,15,6:1
5,10,6:1
5,11,6:1
5,12,6:1
2,15,6:1
4,-4,6:1
4,-3,6:1
5,-3,6:1
6,-3,6:1
7,-3,6:1
8,-8,6:1
9,-8,6:1
10,-8,6:1
10,-9,6:1
10,-3,6:1
10,-4,6:1
10,-2,6:1
8,1,6:1
7,1,6:1
4,-11,6:1
9,-11,6:1
4,-9,6:1
4,-8,6:1
4,-7,6:1
