
#######################################################################
# +-----------------------------------------------------------------+ #
# |                            BO3 object                           | #
# +-----------------------------------------------------------------+ #
#######################################################################

# This is the config file of a custom object.
# If you add this object correctly to your BiomeConfigs, it will spawn in the world.

# This is the creator of this BO3 object
Author:Androkai,mysource ... but just for conveting to bo3

# A short description of this BO3 object
Description:Converted version of the BO2 Netherturm

# The BO3 version, don't change this! It can be used by external applications to do a version check.
Version:3

# The settings mode, WriteAll, WriteWithoutComments or WriteDisable. See WorldConfig.
SettingsMode:WriteDisable

#######################################################################
# +-----------------------------------------------------------------+ #
# |                          Main settings                          | #
# +-----------------------------------------------------------------+ #
#######################################################################

# This needs to be set to true to spawn the object in the Tree and Sapling resources.
Tree:false

# The frequency of the BO3 from 1 to 200. Tries this many times to spawn this BO3 when using the CustomObject(...) resource.
# Ignored by Tree(..), Sapling(..) and CustomStructure(..)
Frequency:1

# The rarity of the BO3 from 0 to 100. Each spawn attempt has rarity% chance to succeed when using the CustomObject(...) resource.
# Ignored by Tree(..), Sapling(..) and CustomStructure(..)
Rarity:20.0

# If you set this to true, the BO3 will be placed with a random rotation.
RotateRandomly:true

# The spawn height of the BO3 - randomY, highestBlock or highestSolidBlock.
SpawnHeight:randomY

# The height limits for the BO3.
MinHeight:0
MaxHeight:128

# Objects can have other objects attacthed to it: branches. Branches can also
# have branches attached to it, which can also have branches, etc. This is the
# maximum branch depth for this objects.
MaxBranchDepth:5

# When spawned with the UseWorld keyword, this BO3 should NOT spawn in the following biomes.
# If you write the BO3 name directly in the BiomeConfigs, this will be ignored.
ExcludedBiomes:All

#######################################################################
# +-----------------------------------------------------------------+ #
# |                      Source block settings                      | #
# +-----------------------------------------------------------------+ #
#######################################################################

# The block the BO3 should spawn in
SourceBlock:10,74,87

# The maximum percentage of the BO3 that can be outside the SourceBlock.
# The BO3 won't be placed on a location with more blocks outside the SourceBlock than this percentage.
MaxPercentageOutsideSourceBlock:99

# What to do when a block is about to be placed outside the SourceBlock? (dontPlace, placeAnyway)
OutsideSourceBlock:placeAnyway

#######################################################################
# +-----------------------------------------------------------------+ #
# |                              Blocks                             | #
# +-----------------------------------------------------------------+ #
#######################################################################

# All the blocks used in the BO3 are listed here. Possible blocks:
# Block(x,y,z,id[.data][,nbtfile.nbt)
# RandomBlock(x,y,z,id[:data][,nbtfile.nbt],chance[,id[:data][,nbtfile.nbt],chance[,...]])
# So RandomBlock(0,0,0,CHEST,chest.nbt,50,CHEST,anotherchest.nbt,100) will spawn a chest at
# the BO3 origin, and give it a 50% chance to have the contents of chest.nbt, or, if that
# fails, a 100% percent chance to have the contents of anotherchest.nbt.
Block(0,-121,-5,NETHER_BRICK)
Block(0,-120,-5,NETHER_BRICK)
Block(-5,-9,2,NETHER_BRICK)
Block(-5,-8,2,NETHER_BRICK)
Block(-5,-7,2,NETHER_BRICK)
Block(0,-125,-5,NETHER_BRICK)
Block(0,-124,-5,NETHER_BRICK)
Block(0,-123,-5,NETHER_BRICK)
Block(0,-122,-5,NETHER_BRICK)
Block(-5,-2,2,NETHER_BRICK)
Block(-5,-1,2,NETHER_BRICK)
Block(-5,-6,2,NETHER_BRICK)
Block(-5,-5,2,NETHER_BRICK)
Block(-1,39,-7,NETHER_BRICK)
Block(-5,-4,2,NETHER_BRICK)
Block(-5,-3,2,NETHER_BRICK)
Block(0,-128,-5,NETHER_BRICK)
Block(0,-129,-5,NETHER_BRICK)
Block(0,-126,-5,NETHER_BRICK)
Block(-1,40,-7,STEP:6)
Block(0,-127,-5,NETHER_BRICK)
Block(0,-110,-5,NETHER_BRICK)
Block(0,-112,-5,NETHER_BRICK)
Block(0,-111,-5,NETHER_BRICK)
Block(0,-180,-4,NETHER_BRICK)
Block(0,-114,-5,NETHER_BRICK)
Block(0,-181,-4,NETHER_BRICK)
Block(0,-113,-5,NETHER_BRICK)
Block(0,-182,-4,NETHER_BRICK)
Block(0,-183,-4,NETHER_BRICK)
Block(0,-184,-4,NETHER_BRICK)
Block(0,-185,-4,NETHER_BRICK)
Block(-1,37,-7,NETHER_BRICK)
Block(-1,38,-7,NETHER_BRICK)
Block(-1,35,-7,NETHER_BRICK)
Block(-1,36,-7,NETHER_BRICK)
Block(-2,-6,4,NETHER_BRICK)
Block(-1,33,-7,NETHER_BRICK)
Block(-2,-7,4,NETHER_BRICK)
Block(-1,34,-7,NETHER_BRICK)
Block(-2,-8,4,NETHER_BRICK)
Block(-1,31,-7,STEP:14)
Block(-2,-9,4,NETHER_BRICK)
Block(-1,32,-7,NETHER_BRICK)
Block(0,-115,-5,NETHER_BRICK)
Block(-2,-2,4,NETHER_BRICK)
Block(0,-116,-5,NETHER_BRICK)
Block(-2,-3,4,NETHER_BRICK)
Block(0,-117,-5,NETHER_BRICK)
Block(-2,-4,4,NETHER_BRICK)
Block(0,-118,-5,NETHER_BRICK)
Block(-2,-5,4,NETHER_BRICK)
Block(0,-119,-5,NETHER_BRICK)
Block(-2,-1,4,NETHER_BRICK)
Block(0,-103,-5,NETHER_BRICK)
Block(0,-102,-5,NETHER_BRICK)
Block(0,-101,-5,NETHER_BRICK)
Block(0,-100,-5,NETHER_BRICK)
Block(0,-178,1,NETHER_BRICK)
Block(0,-179,1,NETHER_BRICK)
Block(0,-176,1,NETHER_BRICK)
Block(0,-177,1,NETHER_BRICK)
Block(0,-174,1,NETHER_BRICK)
Block(0,-175,1,NETHER_BRICK)
Block(0,-172,1,NETHER_BRICK)
Block(0,-173,1,NETHER_BRICK)
Block(0,-108,-5,NETHER_BRICK)
Block(0,-170,1,NETHER_BRICK)
Block(0,-109,-5,NETHER_BRICK)
Block(0,-171,1,NETHER_BRICK)
Block(0,-106,-5,NETHER_BRICK)
Block(0,-107,-5,NETHER_BRICK)
Block(0,-104,-5,NETHER_BRICK)
Block(0,-105,-5,NETHER_BRICK)
Block(-5,38,3,NETHER_FENCE)
Block(-5,39,3,NETHER_FENCE)
Block(-5,40,3,STEP:6)
Block(0,-185,1,NETHER_BRICK)
Block(0,-181,1,NETHER_BRICK)
Block(0,-182,1,NETHER_BRICK)
Block(0,-183,1,NETHER_BRICK)
Block(0,-184,1,NETHER_BRICK)
Block(0,-180,1,NETHER_BRICK)
Block(3,-19,0,NETHER_BRICK)
Block(-2,-100,-1,NETHER_BRICK)
Block(-2,-101,-1,NETHER_BRICK)
Block(-2,-102,-1,NETHER_BRICK)
Block(-2,-103,-1,NETHER_BRICK)
Block(-2,-104,-1,NETHER_BRICK)
Block(-2,-105,-1,NETHER_BRICK)
Block(-2,-106,-1,NETHER_BRICK)
Block(-2,-107,-1,NETHER_BRICK)
Block(-2,-108,-1,NETHER_BRICK)
Block(-2,-109,-1,NETHER_BRICK)
Block(3,-20,0,NETHER_BRICK)
Block(3,-21,0,NETHER_BRICK)
Block(3,-24,0,NETHER_BRICK)
Block(3,-25,0,NETHER_BRICK)
Block(3,-22,0,NETHER_BRICK)
Block(3,-23,0,NETHER_BRICK)
Block(3,-28,0,NETHER_BRICK)
Block(3,-29,0,NETHER_BRICK)
Block(3,-26,0,NETHER_BRICK)
Block(3,-27,0,NETHER_BRICK)
Block(3,-10,0,NETHER_BRICK)
Block(3,-11,0,NETHER_BRICK)
Block(3,-12,0,NETHER_BRICK)
Block(3,-13,0,NETHER_BRICK)
Block(3,-14,0,NETHER_BRICK)
Block(3,-15,0,NETHER_BRICK)
Block(3,-16,0,NETHER_BRICK)
Block(3,-17,0,NETHER_BRICK)
Block(3,-18,0,NETHER_BRICK)
Block(-2,-121,-1,NETHER_BRICK)
Block(-2,-122,-1,NETHER_BRICK)
Block(-2,-123,-1,NETHER_BRICK)
Block(-2,-124,-1,NETHER_BRICK)
Block(-2,-120,-1,NETHER_BRICK)
Block(-2,-129,-1,NETHER_BRICK)
Block(-2,-125,-1,NETHER_BRICK)
Block(-2,-126,-1,NETHER_BRICK)
Block(-2,-127,-1,NETHER_BRICK)
Block(-2,-128,-1,NETHER_BRICK)
Block(-2,-112,-1,NETHER_BRICK)
Block(-2,-113,-1,NETHER_BRICK)
Block(-2,-110,-1,NETHER_BRICK)
Block(-2,-111,-1,NETHER_BRICK)
Block(-2,-118,-1,NETHER_BRICK)
Block(-2,-119,-1,NETHER_BRICK)
Block(-2,-116,-1,NETHER_BRICK)
Block(-2,-117,-1,NETHER_BRICK)
Block(-2,-114,-1,NETHER_BRICK)
Block(-2,-115,-1,NETHER_BRICK)
Block(-5,44,0,NETHER_BRICK_STAIRS)
Block(0,-115,-4,NETHER_BRICK)
Block(2,9,0,NETHER_BRICK)
Block(3,-67,0,NETHER_BRICK)
Block(0,-114,-4,NETHER_BRICK)
Block(2,8,0,GLOWSTONE)
Block(3,-66,0,NETHER_BRICK)
Block(0,-110,1,NETHER_BRICK)
Block(0,-117,-4,NETHER_BRICK)
Block(3,-69,0,NETHER_BRICK)
Block(0,-111,1,NETHER_BRICK)
Block(0,-116,-4,NETHER_BRICK)
Block(3,-68,0,NETHER_BRICK)
Block(0,-112,1,NETHER_BRICK)
Block(0,-119,-4,NETHER_BRICK)
Block(0,-113,1,NETHER_BRICK)
Block(0,-118,-4,NETHER_BRICK)
Block(0,-114,1,NETHER_BRICK)
Block(0,-115,1,NETHER_BRICK)
Block(3,-61,0,NETHER_BRICK)
Block(3,-60,0,NETHER_BRICK)
Block(3,-63,0,NETHER_BRICK)
Block(-5,39,0,NETHER_BRICK)
Block(3,-62,0,NETHER_BRICK)
Block(-5,38,0,NETHER_BRICK)
Block(3,-65,0,NETHER_BRICK)
Block(3,-64,0,NETHER_BRICK)
Block(3,-129,2,NETHER_BRICK)
Block(4,-136,0,NETHER_BRICK)
Block(4,-135,0,NETHER_BRICK)
Block(-2,-149,-1,NETHER_BRICK)
Block(3,-127,2,NETHER_BRICK)
Block(4,-134,0,NETHER_BRICK)
Block(-2,-148,-1,NETHER_BRICK)
Block(3,-128,2,NETHER_BRICK)
Block(4,-133,0,NETHER_BRICK)
Block(-2,-147,-1,NETHER_BRICK)
Block(3,-125,2,NETHER_BRICK)
Block(3,-126,2,NETHER_BRICK)
Block(4,-139,0,NETHER_BRICK)
Block(3,-123,2,NETHER_BRICK)
Block(4,-138,0,NETHER_BRICK)
Block(-5,40,0,NETHERRACK)
Block(3,-124,2,NETHER_BRICK)
Block(4,-137,0,NETHER_BRICK)
Block(-5,41,0,FIRE:15)
Block(0,-106,1,NETHER_BRICK)
Block(3,-121,2,NETHER_BRICK)
Block(-2,-142,-1,NETHER_BRICK)
Block(-3,3,-3,NETHER_BRICK)
Block(0,-105,1,NETHER_BRICK)
Block(3,-122,2,NETHER_BRICK)
Block(-2,-141,-1,NETHER_BRICK)
Block(-3,2,-3,NETHER_BRICK)
Block(0,-108,1,NETHER_BRICK)
Block(-2,-140,-1,NETHER_BRICK)
Block(-3,1,-3,NETHER_BRICK)
Block(0,-107,1,NETHER_BRICK)
Block(3,-120,2,NETHER_BRICK)
Block(-3,0,-3,NETHER_BRICK)
Block(0,-110,-4,NETHER_BRICK)
Block(4,-132,0,NETHER_BRICK)
Block(-2,-146,-1,NETHER_BRICK)
Block(-3,7,-3,NETHER_BRICK_STAIRS:3)
Block(0,-109,1,NETHER_BRICK)
Block(0,-111,-4,NETHER_BRICK)
Block(4,-131,0,NETHER_BRICK)
Block(-2,-145,-1,NETHER_BRICK)
Block(-3,6,-3,NETHER_BRICK)
Block(0,-112,-4,NETHER_BRICK)
Block(4,-130,0,NETHER_BRICK)
Block(-2,-144,-1,NETHER_BRICK)
Block(-3,5,-3,NETHER_BRICK)
Block(0,-113,-4,NETHER_BRICK)
Block(-2,-143,-1,NETHER_BRICK)
Block(-3,4,-3,NETHER_BRICK)
Block(0,-106,-4,NETHER_BRICK)
Block(0,-121,1,NETHER_BRICK)
Block(3,-58,0,NETHER_BRICK)
Block(0,-105,-4,NETHER_BRICK)
Block(0,-122,1,NETHER_BRICK)
Block(3,-57,0,NETHER_BRICK)
Block(0,-104,-4,NETHER_BRICK)
Block(3,-56,0,NETHER_BRICK)
Block(0,-103,-4,NETHER_BRICK)
Block(0,-120,1,NETHER_BRICK)
Block(3,-55,0,NETHER_BRICK)
Block(0,-125,1,NETHER_BRICK)
Block(0,-109,-4,NETHER_BRICK)
Block(0,-126,1,NETHER_BRICK)
Block(0,-108,-4,NETHER_BRICK)
Block(0,-123,1,NETHER_BRICK)
Block(0,-107,-4,NETHER_BRICK)
Block(0,-124,1,NETHER_BRICK)
Block(3,-59,0,NETHER_BRICK)
Block(4,-119,0,NETHER_BRICK)
Block(3,-50,0,NETHER_BRICK)
Block(-5,24,0,STEP:6)
Block(3,-54,0,NETHER_BRICK)
Block(3,-109,2,NETHER_BRICK)
Block(3,-53,0,NETHER_BRICK)
Block(3,-52,0,NETHER_BRICK)
Block(3,-51,0,NETHER_BRICK)
Block(3,-116,2,NETHER_BRICK)
Block(4,-123,0,NETHER_BRICK)
Block(-2,-137,-1,NETHER_BRICK)
Block(3,-117,2,NETHER_BRICK)
Block(4,-122,0,NETHER_BRICK)
Block(-2,-136,-1,NETHER_BRICK)
Block(3,-118,2,NETHER_BRICK)
Block(4,-125,0,NETHER_BRICK)
Block(-2,-139,-1,NETHER_BRICK)
Block(3,-119,2,NETHER_BRICK)
Block(4,-124,0,NETHER_BRICK)
Block(-2,-138,-1,NETHER_BRICK)
Block(3,-112,2,NETHER_BRICK)
Block(4,-127,0,NETHER_BRICK)
Block(3,-113,2,NETHER_BRICK)
Block(4,-126,0,NETHER_BRICK)
Block(3,-114,2,NETHER_BRICK)
Block(4,-129,0,NETHER_BRICK)
Block(-5,31,0,STEP:14)
Block(3,-115,2,NETHER_BRICK)
Block(4,-128,0,NETHER_BRICK)
Block(-5,32,0,NETHER_BRICK)
Block(0,-119,1,NETHER_BRICK)
Block(0,-118,1,NETHER_BRICK)
Block(3,-110,2,NETHER_BRICK)
Block(0,-117,1,NETHER_BRICK)
Block(-2,-131,-1,NETHER_BRICK)
Block(3,-111,2,NETHER_BRICK)
Block(0,-116,1,NETHER_BRICK)
Block(-2,-130,-1,NETHER_BRICK)
Block(0,-101,-4,NETHER_BRICK)
Block(-2,-133,-1,NETHER_BRICK)
Block(0,-102,-4,NETHER_BRICK)
Block(-2,-132,-1,NETHER_BRICK)
Block(4,-121,0,NETHER_BRICK)
Block(-2,-135,-1,NETHER_BRICK)
Block(4,-120,0,NETHER_BRICK)
Block(-2,-134,-1,NETHER_BRICK)
Block(0,-100,-4,NETHER_BRICK)
Block(-2,-170,-1,NETHER_BRICK)
Block(3,-49,0,NETHER_BRICK)
Block(-2,-171,-1,NETHER_BRICK)
Block(3,-48,0,NETHER_BRICK)
Block(0,-137,-4,NETHER_BRICK)
Block(3,-45,0,NETHER_BRICK)
Block(0,-136,-4,NETHER_BRICK)
Block(3,-44,0,NETHER_BRICK)
Block(0,-139,-4,NETHER_BRICK)
Block(-5,40,2,STEP:6)
Block(3,-47,0,NETHER_BRICK)
Block(0,-138,-4,NETHER_BRICK)
Block(3,-46,0,NETHER_BRICK)
Block(3,-41,0,NETHER_BRICK)
Block(3,-40,0,NETHER_BRICK)
Block(3,-43,0,NETHER_BRICK)
Block(3,-42,0,NETHER_BRICK)
Block(4,-108,0,NETHER_BRICK)
Block(4,-109,0,NETHER_BRICK)
Block(4,-118,0,NETHER_BRICK)
Block(3,-147,2,NETHER_BRICK)
Block(4,-117,0,NETHER_BRICK)
Block(3,-148,2,NETHER_BRICK)
Block(4,-116,0,NETHER_BRICK)
Block(3,-145,2,NETHER_BRICK)
Block(4,-115,0,NETHER_BRICK)
Block(3,-146,2,NETHER_BRICK)
Block(4,-114,0,NETHER_BRICK)
Block(0,-185,-5,NETHER_BRICK)
Block(4,-113,0,NETHER_BRICK)
Block(0,-184,-5,NETHER_BRICK)
Block(4,-112,0,NETHER_BRICK)
Block(3,-149,2,NETHER_BRICK)
Block(4,-111,0,NETHER_BRICK)
Block(-2,-169,-1,NETHER_BRICK)
Block(4,-110,0,NETHER_BRICK)
Block(0,-132,-4,NETHER_BRICK)
Block(-2,-168,-1,NETHER_BRICK)
Block(0,-181,-5,NETHER_BRICK)
Block(0,-133,-4,NETHER_BRICK)
Block(3,-140,2,NETHER_BRICK)
Block(-2,-167,-1,NETHER_BRICK)
Block(0,-180,-5,NETHER_BRICK)
Block(-5,39,2,NETHER_FENCE)
Block(0,-134,-4,NETHER_BRICK)
Block(-2,-166,-1,NETHER_BRICK)
Block(0,-183,-5,NETHER_BRICK)
Block(0,-135,-4,NETHER_BRICK)
Block(-2,-165,-1,NETHER_BRICK)
Block(0,-182,-5,NETHER_BRICK)
Block(3,-143,2,NETHER_BRICK)
Block(-2,-164,-1,NETHER_BRICK)
Block(3,-144,2,NETHER_BRICK)
Block(-2,-163,-1,NETHER_BRICK)
Block(0,-130,-4,NETHER_BRICK)
Block(3,-141,2,NETHER_BRICK)
Block(-2,-162,-1,NETHER_BRICK)
Block(-5,38,2,GLOWSTONE)
Block(0,-131,-4,NETHER_BRICK)
Block(3,-142,2,NETHER_BRICK)
Block(-2,-161,-1,NETHER_BRICK)
Block(0,-103,1,NETHER_BRICK)
Block(0,-104,1,NETHER_BRICK)
Block(3,-39,0,NETHER_BRICK)
Block(0,-101,1,NETHER_BRICK)
Block(-5,31,2,STEP:14)
Block(3,-38,0,NETHER_BRICK)
Block(0,-102,1,NETHER_BRICK)
Block(0,-129,-4,NETHER_BRICK)
Block(-2,-160,-1,NETHER_BRICK)
Block(-5,32,2,NETHER_BRICK)
Block(3,-37,0,NETHER_BRICK)
Block(0,-128,-4,NETHER_BRICK)
Block(3,-36,0,NETHER_BRICK)
Block(0,-127,-4,NETHER_BRICK)
Block(0,-100,1,NETHER_BRICK)
Block(-5,30,2,NETHER_BRICK_STAIRS:1)
Block(3,-35,0,NETHER_BRICK)
Block(0,-126,-4,NETHER_BRICK)
Block(3,-34,0,NETHER_BRICK)
Block(0,-125,-4,NETHER_BRICK)
Block(3,-33,0,NETHER_BRICK)
Block(3,-32,0,NETHER_BRICK)
Block(3,-31,0,NETHER_BRICK)
Block(3,-30,0,NETHER_BRICK)
Block(4,-105,0,NETHER_BRICK)
Block(3,-134,2,NETHER_BRICK)
Block(4,-104,0,NETHER_BRICK)
Block(3,-135,2,NETHER_BRICK)
Block(0,-179,-5,NETHER_BRICK)
Block(4,-107,0,NETHER_BRICK)
Block(3,-136,2,NETHER_BRICK)
Block(0,-178,-5,NETHER_BRICK)
Block(4,-106,0,NETHER_BRICK)
Block(3,-137,2,NETHER_BRICK)
Block(0,-177,-5,NETHER_BRICK)
Block(4,-101,0,NETHER_BRICK)
Block(3,-138,2,NETHER_BRICK)
Block(-2,-159,-1,NETHER_BRICK)
Block(0,-176,-5,NETHER_BRICK)
Block(3,-139,2,NETHER_BRICK)
Block(-2,-158,-1,NETHER_BRICK)
Block(0,-175,-5,NETHER_BRICK)
Block(4,-100,0,NETHER_BRICK)
Block(4,-103,0,NETHER_BRICK)
Block(0,-174,-5,NETHER_BRICK)
Block(4,-102,0,NETHER_BRICK)
Block(0,-173,-5,NETHER_BRICK)
Block(0,-123,-4,NETHER_BRICK)
Block(-2,-155,-1,NETHER_BRICK)
Block(0,-172,-5,NETHER_BRICK)
Block(2,2,0,NETHER_BRICK)
Block(0,-124,-4,NETHER_BRICK)
Block(-2,-154,-1,NETHER_BRICK)
Block(0,-171,-5,NETHER_BRICK)
Block(2,3,0,NETHER_BRICK)
Block(0,-121,-4,NETHER_BRICK)
Block(-2,-157,-1,NETHER_BRICK)
Block(0,-170,-5,NETHER_BRICK)
Block(-5,29,2,NETHER_FENCE)
Block(0,-122,-4,NETHER_BRICK)
Block(-2,-156,-1,NETHER_BRICK)
Block(-5,28,2,NETHER_FENCE)
Block(3,-130,2,NETHER_BRICK)
Block(-2,-151,-1,NETHER_BRICK)
Block(0,-120,-4,NETHER_BRICK)
Block(3,-131,2,NETHER_BRICK)
Block(-2,-150,-1,NETHER_BRICK)
Block(3,-132,2,NETHER_BRICK)
Block(-2,-153,-1,NETHER_BRICK)
Block(2,0,0,NETHER_BRICK)
Block(-5,25,2,NETHER_BRICK_STAIRS:1)
Block(3,-133,2,NETHER_BRICK)
Block(-2,-152,-1,NETHER_BRICK)
Block(-5,24,2,NETHER_BRICK)
Block(2,1,0,NETHER_BRICK)
Block(0,-151,1,NETHER_BRICK)
Block(0,-150,1,NETHER_BRICK)
Block(0,-153,1,NETHER_BRICK)
Block(0,-158,-4,NETHER_BRICK)
Block(0,-152,1,NETHER_BRICK)
Block(0,-159,-4,NETHER_BRICK)
Block(0,-155,1,NETHER_BRICK)
Block(0,-154,1,NETHER_BRICK)
Block(0,-157,1,NETHER_BRICK)
Block(0,-156,1,NETHER_BRICK)
Block(0,-159,1,NETHER_BRICK)
Block(-5,23,2,NETHER_BRICK_STAIRS:4)
Block(0,-158,1,NETHER_BRICK)
Block(0,-149,1,NETHER_BRICK)
Block(0,-151,-4,NETHER_BRICK)
Block(4,-171,0,NETHER_BRICK)
Block(-2,-185,-1,NETHER_BRICK)
Block(0,-150,-4,NETHER_BRICK)
Block(4,-172,0,NETHER_BRICK)
Block(0,-153,-4,NETHER_BRICK)
Block(-2,-183,-1,NETHER_BRICK)
Block(0,-152,-4,NETHER_BRICK)
Block(4,-170,0,NETHER_BRICK)
Block(-2,-184,-1,NETHER_BRICK)
Block(0,-155,-4,NETHER_BRICK)
Block(4,-175,0,NETHER_BRICK)
Block(0,-154,-4,NETHER_BRICK)
Block(4,-176,0,NETHER_BRICK)
Block(0,-157,-4,NETHER_BRICK)
Block(0,-160,-5,NETHER_BRICK)
Block(4,-173,0,NETHER_BRICK)
Block(0,-156,-4,NETHER_BRICK)
Block(0,-161,-5,NETHER_BRICK)
Block(4,-174,0,NETHER_BRICK)
Block(0,-162,-5,NETHER_BRICK)
Block(4,-179,0,NETHER_BRICK)
Block(0,-163,-5,NETHER_BRICK)
Block(0,-164,-5,NETHER_BRICK)
Block(4,-177,0,NETHER_BRICK)
Block(0,-165,-5,NETHER_BRICK)
Block(4,-178,0,NETHER_BRICK)
Block(0,-166,-5,NETHER_BRICK)
Block(0,-167,-5,NETHER_BRICK)
Block(0,-168,-5,NETHER_BRICK)
Block(0,-169,-5,NETHER_BRICK)
Block(3,-93,0,NETHER_BRICK)
Block(3,-94,0,NETHER_BRICK)
Block(3,-91,0,NETHER_BRICK)
Block(0,-159,-5,NETHER_BRICK)
Block(3,-92,0,NETHER_BRICK)
Block(0,-162,1,NETHER_BRICK)
Block(3,-97,0,NETHER_BRICK)
Block(0,-161,1,NETHER_BRICK)
Block(3,-98,0,NETHER_BRICK)
Block(0,-160,1,NETHER_BRICK)
Block(3,-95,0,NETHER_BRICK)
Block(3,-96,0,NETHER_BRICK)
Block(0,-149,-4,NETHER_BRICK)
Block(0,-166,1,NETHER_BRICK)
Block(0,-165,1,NETHER_BRICK)
Block(0,-147,-4,NETHER_BRICK)
Block(0,-164,1,NETHER_BRICK)
Block(3,-99,0,NETHER_BRICK)
Block(0,-148,-4,NETHER_BRICK)
Block(0,-163,1,NETHER_BRICK)
Block(-2,-180,-1,NETHER_BRICK)
Block(0,-169,1,NETHER_BRICK)
Block(0,-168,1,NETHER_BRICK)
Block(-2,-182,-1,NETHER_BRICK)
Block(0,-167,1,NETHER_BRICK)
Block(-2,-181,-1,NETHER_BRICK)
Block(0,-142,-4,NETHER_BRICK)
Block(-2,-172,-1,NETHER_BRICK)
Block(0,-141,-4,NETHER_BRICK)
Block(-2,-173,-1,NETHER_BRICK)
Block(4,-9,2,NETHER_BRICK)
Block(0,-140,-4,NETHER_BRICK)
Block(4,-160,0,NETHER_BRICK)
Block(-2,-174,-1,NETHER_BRICK)
Block(4,-8,2,NETHER_BRICK)
Block(4,-161,0,NETHER_BRICK)
Block(-2,-175,-1,NETHER_BRICK)
Block(4,-7,2,NETHER_BRICK)
Block(0,-146,-4,NETHER_BRICK)
Block(4,-162,0,NETHER_BRICK)
Block(-2,-176,-1,NETHER_BRICK)
Block(4,-6,2,NETHER_BRICK)
Block(0,-145,-4,NETHER_BRICK)
Block(0,-150,-5,NETHER_BRICK)
Block(4,-163,0,NETHER_BRICK)
Block(-2,-177,-1,NETHER_BRICK)
Block(4,-5,2,NETHER_BRICK)
Block(0,-144,-4,NETHER_BRICK)
Block(4,-164,0,NETHER_BRICK)
Block(-2,-178,-1,NETHER_BRICK)
Block(4,-4,2,NETHER_BRICK)
Block(0,-143,-4,NETHER_BRICK)
Block(4,-165,0,NETHER_BRICK)
Block(-2,-179,-1,NETHER_BRICK)
Block(4,-3,2,NETHER_BRICK)
Block(0,-153,-5,NETHER_BRICK)
Block(4,-166,0,NETHER_BRICK)
Block(4,-2,2,NETHER_BRICK)
Block(0,-154,-5,NETHER_BRICK)
Block(4,-167,0,NETHER_BRICK)
Block(4,-1,2,NETHER_BRICK)
Block(0,-151,-5,NETHER_BRICK)
Block(4,-168,0,NETHER_BRICK)
Block(0,-152,-5,NETHER_BRICK)
Block(4,-169,0,NETHER_BRICK)
Block(0,-157,-5,NETHER_BRICK)
Block(3,-90,0,NETHER_BRICK)
Block(0,-158,-5,NETHER_BRICK)
Block(0,-155,-5,NETHER_BRICK)
Block(0,-156,-5,NETHER_BRICK)
Block(-5,-3,0,NETHER_BRICK)
Block(3,-84,0,NETHER_BRICK)
Block(-5,-4,0,NETHER_BRICK)
Block(3,-85,0,NETHER_BRICK)
Block(3,-86,0,NETHER_BRICK)
Block(-5,-1,0,NETHER_BRICK)
Block(-5,-2,0,NETHER_BRICK)
Block(3,-87,0,NETHER_BRICK)
Block(0,-149,-5,NETHER_BRICK)
Block(3,-80,0,NETHER_BRICK)
Block(0,-148,-5,NETHER_BRICK)
Block(3,-81,0,NETHER_BRICK)
Block(3,-82,0,NETHER_BRICK)
Block(3,-83,0,NETHER_BRICK)
Block(0,-135,1,NETHER_BRICK)
Block(0,-134,1,NETHER_BRICK)
Block(0,-137,1,NETHER_BRICK)
Block(-5,-9,0,NETHER_BRICK)
Block(0,-136,1,NETHER_BRICK)
Block(0,-131,1,NETHER_BRICK)
Block(-5,-7,0,NETHER_BRICK)
Block(3,-88,0,NETHER_BRICK)
Block(0,-130,1,NETHER_BRICK)
Block(-5,-8,0,NETHER_BRICK)
Block(3,-89,0,NETHER_BRICK)
Block(0,-133,1,NETHER_BRICK)
Block(-5,-5,0,NETHER_BRICK)
Block(0,-132,1,NETHER_BRICK)
Block(-5,-6,0,NETHER_BRICK)
Block(4,-153,0,NETHER_BRICK)
Block(0,-177,-4,NETHER_BRICK)
Block(4,-154,0,NETHER_BRICK)
Block(0,-176,-4,NETHER_BRICK)
Block(4,-151,0,NETHER_BRICK)
Block(0,-179,-4,NETHER_BRICK)
Block(4,-152,0,NETHER_BRICK)
Block(0,-178,-4,NETHER_BRICK)
Block(0,-127,1,NETHER_BRICK)
Block(0,-173,-4,NETHER_BRICK)
Block(3,-100,2,NETHER_BRICK)
Block(0,-128,1,NETHER_BRICK)
Block(4,-150,0,NETHER_BRICK)
Block(0,-172,-4,NETHER_BRICK)
Block(0,-129,1,NETHER_BRICK)
Block(0,-175,-4,NETHER_BRICK)
Block(0,-174,-4,NETHER_BRICK)
Block(3,-104,2,NETHER_BRICK)
Block(0,-144,-5,NETHER_BRICK)
Block(3,-103,2,NETHER_BRICK)
Block(0,-145,-5,NETHER_BRICK)
Block(3,-102,2,NETHER_BRICK)
Block(0,-146,-5,NETHER_BRICK)
Block(4,-159,0,NETHER_BRICK)
Block(0,-171,-4,NETHER_BRICK)
Block(3,-101,2,NETHER_BRICK)
Block(0,-147,-5,NETHER_BRICK)
Block(0,-170,-4,NETHER_BRICK)
Block(3,-108,2,NETHER_BRICK)
Block(0,-140,-5,NETHER_BRICK)
Block(4,-157,0,NETHER_BRICK)
Block(3,-107,2,NETHER_BRICK)
Block(0,-141,-5,NETHER_BRICK)
Block(4,-158,0,NETHER_BRICK)
Block(3,-106,2,NETHER_BRICK)
Block(0,-142,-5,NETHER_BRICK)
Block(4,-155,0,NETHER_BRICK)
Block(3,-105,2,NETHER_BRICK)
Block(0,-143,-5,NETHER_BRICK)
Block(4,-156,0,NETHER_BRICK)
Block(0,-140,1,NETHER_BRICK)
Block(3,-75,0,NETHER_BRICK)
Block(3,-76,0,NETHER_BRICK)
Block(3,-73,0,NETHER_BRICK)
Block(3,-74,0,NETHER_BRICK)
Block(3,-71,0,NETHER_BRICK)
Block(0,-139,-5,NETHER_BRICK)
Block(3,-72,0,NETHER_BRICK)
Block(0,-138,-5,NETHER_BRICK)
Block(0,-137,-5,NETHER_BRICK)
Block(3,-70,0,NETHER_BRICK)
Block(0,-148,1,NETHER_BRICK)
Block(0,-147,1,NETHER_BRICK)
Block(0,-146,1,NETHER_BRICK)
Block(0,-145,1,NETHER_BRICK)
Block(0,-144,1,NETHER_BRICK)
Block(3,-79,0,NETHER_BRICK)
Block(0,-143,1,NETHER_BRICK)
Block(0,-142,1,NETHER_BRICK)
Block(0,-169,-4,NETHER_BRICK)
Block(3,-77,0,NETHER_BRICK)
Block(0,-141,1,NETHER_BRICK)
Block(3,-78,0,NETHER_BRICK)
Block(4,-140,0,NETHER_BRICK)
Block(0,-168,-4,NETHER_BRICK)
Block(4,-141,0,NETHER_BRICK)
Block(0,-167,-4,NETHER_BRICK)
Block(4,-142,0,NETHER_BRICK)
Block(0,-166,-4,NETHER_BRICK)
Block(4,-143,0,NETHER_BRICK)
Block(0,-165,-4,NETHER_BRICK)
Block(0,-164,-4,NETHER_BRICK)
Block(0,-163,-4,NETHER_BRICK)
Block(0,-138,1,NETHER_BRICK)
Block(0,-162,-4,NETHER_BRICK)
Block(0,-139,1,NETHER_BRICK)
Block(0,-161,-4,NETHER_BRICK)
Block(0,-135,-5,NETHER_BRICK)
Block(4,-148,0,NETHER_BRICK)
Block(0,-160,-4,NETHER_BRICK)
Block(0,-136,-5,NETHER_BRICK)
Block(4,-149,0,NETHER_BRICK)
Block(0,-133,-5,NETHER_BRICK)
Block(0,-134,-5,NETHER_BRICK)
Block(0,-131,-5,NETHER_BRICK)
Block(4,-144,0,NETHER_BRICK)
Block(0,-132,-5,NETHER_BRICK)
Block(4,-145,0,NETHER_BRICK)
Block(4,-146,0,NETHER_BRICK)
Block(0,-130,-5,NETHER_BRICK)
Block(4,-147,0,NETHER_BRICK)
Block(-1,-1,-2,NETHER_BRICK)
Block(-1,-4,-2,NETHER_BRICK)
Block(-1,-5,-2,NETHER_BRICK)
Block(-1,-2,-2,NETHER_BRICK)
Block(-1,-3,-2,NETHER_BRICK)
Block(-1,-8,-2,NETHER_BRICK)
Block(-1,-9,-2,NETHER_BRICK)
Block(-1,-6,-2,NETHER_BRICK)
Block(-1,-7,-2,NETHER_BRICK)
Block(5,23,3,STEP:14)
Block(5,24,3,STEP:6)
Block(-1,11,-2,NETHER_BRICK)
Block(-1,10,-2,NETHER_BRICK)
Block(-1,15,-2,NETHER_BRICK)
Block(-1,14,-2,NETHER_BRICK)
Block(-1,13,-2,NETHER_BRICK)
Block(-1,12,-2,NETHER_BRICK)
Block(-1,19,-2,NETHER_BRICK)
Block(-1,18,-2,NETHER_BRICK)
Block(5,39,3,NETHER_FENCE)
Block(-1,17,-2,NETHER_BRICK)
Block(5,38,3,NETHER_FENCE)
Block(-1,16,-2,NETHER_BRICK)
Block(-1,21,-2,NETHER_BRICK)
Block(5,31,3,STEP:14)
Block(-1,22,-2,NETHER_BRICK)
Block(5,32,3,SOUL_SAND)
Block(-1,20,-2,NETHER_BRICK)
Block(-1,24,-2,NETHER_BRICK)
Block(-1,23,-2,NETHER_BRICK)
Block(-1,26,-2,NETHER_BRICK)
Block(-1,25,-2,NETHER_BRICK)
Block(-1,28,-2,NETHER_BRICK)
Block(-1,27,-2,NETHER_BRICK)
Block(-1,29,-2,NETHER_BRICK)
Block(-2,3,3,NETHER_BRICK)
Block(-2,2,3,NETHER_BRICK)
Block(-2,1,3,NETHER_BRICK)
Block(-2,0,3,NETHER_BRICK)
Block(5,40,3,STEP:6)
Block(-2,7,3,NETHER_BRICK)
Block(-1,30,-2,NETHER_BRICK)
Block(-2,6,3,NETHER_BRICK)
Block(-1,31,-2,NETHER_BRICK)
Block(-2,5,3,NETHER_BRICK)
Block(-1,32,-2,NETHER_BRICK)
Block(-2,4,3,NETHER_BRICK)
Block(-1,33,-2,NETHER_BRICK)
Block(-2,9,3,NETHER_BRICK)
Block(-2,8,3,NETHER_BRICK)
Block(-1,39,-2,NETHER_BRICK)
Block(-1,38,-2,NETHER_BRICK)
Block(-1,37,-2,NETHER_BRICK)
Block(-1,36,-2,NETHER_BRICK)
Block(-1,35,-2,NETHER_BRICK)
Block(-1,34,-2,NETHER_BRICK)
Block(4,40,3,STEP:6)
Block(-1,40,-2,NETHER_BRICK)
Block(-1,49,-2,NETHER_BRICK)
Block(-1,46,-2,NETHER_BRICK)
Block(-1,48,-2,NETHER_BRICK)
Block(-1,47,-2,NETHER_BRICK)
Block(-1,52,-2,NETHER_BRICK)
Block(-1,53,-2,NETHER_BRICK)
Block(-1,54,-2,NETHER_BRICK)
Block(-1,55,-2,NETHER_BRICK_STAIRS:2)
Block(-1,50,-2,NETHER_BRICK)
Block(-1,51,-2,NETHER_BRICK)
Block(4,24,3,NETHER_BRICK_STAIRS:4)
Block(4,25,3,NETHER_BRICK_STAIRS:1)
Block(4,31,3,NETHER_BRICK_STAIRS:7)
Block(4,32,3,SOUL_SAND)
Block(4,39,3,NETHER_BRICK)
Block(4,38,3,NETHER_BRICK)
Block(-3,-110,3,NETHER_BRICK)
Block(-3,-111,3,NETHER_BRICK)
Block(-3,-114,3,NETHER_BRICK)
Block(-3,-115,3,NETHER_BRICK)
Block(-3,-112,3,NETHER_BRICK)
Block(-3,-113,3,NETHER_BRICK)
Block(-3,-118,3,NETHER_BRICK)
Block(-3,-119,3,NETHER_BRICK)
Block(-3,-116,3,NETHER_BRICK)
Block(-2,38,4,NETHER_FENCE)
Block(-3,-117,3,NETHER_BRICK)
Block(-2,39,4,NETHER_FENCE)
Block(-2,40,4,STEP:6)
Block(-3,-100,3,NETHER_BRICK)
Block(-3,-101,3,NETHER_BRICK)
Block(-3,-102,3,NETHER_BRICK)
Block(-3,-103,3,NETHER_BRICK)
Block(-3,-104,3,NETHER_BRICK)
Block(-3,-105,3,NETHER_BRICK)
Block(-3,-106,3,NETHER_BRICK)
Block(-3,-107,3,NETHER_BRICK)
Block(-3,-108,3,NETHER_BRICK)
Block(-3,-109,3,NETHER_BRICK)
Block(-2,45,4,NETHER_FENCE)
Block(-2,46,4,NETHER_BRICK_STAIRS)
Block(-3,-139,3,NETHER_BRICK)
Block(-3,-138,3,NETHER_BRICK)
Block(-3,-137,3,NETHER_BRICK)
Block(-3,-136,3,NETHER_BRICK)
Block(3,31,-5,STEP:14)
Block(-3,-135,3,NETHER_BRICK)
Block(3,32,-5,SOUL_SAND)
Block(-3,-134,3,NETHER_BRICK)
Block(-3,-133,3,NETHER_BRICK)
Block(-3,-132,3,NETHER_BRICK)
Block(-3,-131,3,NETHER_BRICK)
Block(-3,-130,3,NETHER_BRICK)
Block(3,39,-5,NETHER_FENCE)
Block(-3,-140,3,NETHER_BRICK)
Block(3,38,-5,NETHER_FENCE)
Block(-2,22,4,NETHER_BRICK_STAIRS:7)
Block(-2,24,4,NETHER_BRICK_STAIRS:6)
Block(-2,23,4,NETHER_BRICK_STAIRS:2)
Block(-2,25,4,NETHER_BRICK_STAIRS:3)
Block(-3,-128,3,NETHER_BRICK)
Block(-3,-127,3,NETHER_BRICK)
Block(-3,-129,3,NETHER_BRICK)
Block(-3,-124,3,NETHER_BRICK)
Block(-3,-123,3,NETHER_BRICK)
Block(-3,-126,3,NETHER_BRICK)
Block(-3,-125,3,NETHER_BRICK)
Block(-3,-120,3,NETHER_BRICK)
Block(-3,-122,3,NETHER_BRICK)
Block(3,23,-5,STEP:14)
Block(-3,-121,3,NETHER_BRICK)
Block(3,24,-5,STEP:6)
Block(-2,31,4,NETHER_BRICK_STAIRS:7)
Block(-2,32,4,SOUL_SAND)
Block(-3,-155,3,NETHER_BRICK)
Block(-3,-154,3,NETHER_BRICK)
Block(-3,-153,3,NETHER_BRICK)
Block(-3,-152,3,NETHER_BRICK)
Block(-3,-159,3,NETHER_BRICK)
Block(-3,-158,3,NETHER_BRICK)
Block(-3,-157,3,NETHER_BRICK)
Block(-3,-156,3,NETHER_BRICK)
Block(-3,-161,3,NETHER_BRICK)
Block(-3,-162,3,NETHER_BRICK)
Block(-3,-160,3,NETHER_BRICK)
Block(-3,-149,3,NETHER_BRICK)
Block(3,40,-5,STEP:6)
Block(-3,-142,3,NETHER_BRICK)
Block(-3,-141,3,NETHER_BRICK)
Block(-3,-144,3,NETHER_BRICK)
Block(-3,-143,3,NETHER_BRICK)
Block(-3,-146,3,NETHER_BRICK)
Block(-3,-145,3,NETHER_BRICK)
Block(-3,-148,3,NETHER_BRICK)
Block(-3,-147,3,NETHER_BRICK)
Block(4,-8,3,NETHER_BRICK)
Block(4,-9,3,NETHER_BRICK)
Block(4,-6,3,NETHER_BRICK)
Block(4,-7,3,NETHER_BRICK)
Block(-3,-150,3,NETHER_BRICK)
Block(4,-4,3,NETHER_BRICK)
Block(-3,-151,3,NETHER_BRICK)
Block(4,-5,3,NETHER_BRICK)
Block(4,-2,3,NETHER_BRICK)
Block(4,-3,3,NETHER_BRICK)
Block(4,-1,3,NETHER_BRICK)
Block(-5,24,1,STEP:6)
Block(6,-170,-1,NETHER_BRICK)
Block(6,-172,-1,NETHER_BRICK)
Block(6,-171,-1,NETHER_BRICK)
Block(6,-174,-1,NETHER_BRICK)
Block(6,-173,-1,NETHER_BRICK)
Block(6,-176,-1,NETHER_BRICK)
Block(6,-175,-1,NETHER_BRICK)
Block(6,-178,-1,NETHER_BRICK)
Block(6,-177,-1,NETHER_BRICK)
Block(-5,31,1,STEP:14)
Block(6,-179,-1,NETHER_BRICK)
Block(-5,32,1,SOUL_SAND)
Block(6,-180,-1,NETHER_BRICK)
Block(6,-181,-1,NETHER_BRICK)
Block(6,-185,-1,NETHER_BRICK)
Block(6,-184,-1,NETHER_BRICK)
Block(6,-183,-1,NETHER_BRICK)
Block(6,-182,-1,NETHER_BRICK)
Block(-6,39,5,STEP:6)
Block(-5,38,1,NETHER_FENCE)
Block(-5,39,1,NETHER_FENCE)
Block(-6,-185,0,NETHER_BRICK)
Block(-5,40,1,STEP:6)
Block(-5,44,1,NETHER_BRICK_STAIRS)
Block(-6,38,5,NETHER_BRICK)
Block(-5,43,1,NETHER_BRICK)
Block(-5,42,1,NETHER_BRICK_STAIRS:5)
Block(2,0,1,NETHER_BRICK)
Block(2,3,1,NETHER_BRICK)
Block(2,2,1,NETHER_BRICK)
Block(2,1,1,NETHER_BRICK)
Block(8,38,-1,NETHER_BRICK)
Block(8,37,-1,NETHER_FENCE)
Block(8,39,-1,NETHER_BRICK_STAIRS:1)
Block(8,36,-1,NETHER_FENCE)
Block(8,35,-1,NETHER_BRICK_STAIRS:5)
Block(8,32,-1,NETHER_BRICK)
Block(-1,-88,0,NETHER_BRICK)
Block(-2,-120,-5,NETHER_BRICK)
Block(-1,-87,0,NETHER_BRICK)
Block(-6,-140,0,NETHER_BRICK)
Block(-1,-89,0,NETHER_BRICK)
Block(1,-5,0,NETHER_BRICK)
Block(-1,-80,0,NETHER_BRICK)
Block(1,-4,0,NETHER_BRICK)
Block(1,-3,0,NETHER_BRICK)
Block(-1,-82,0,NETHER_BRICK)
Block(1,-2,0,NETHER_BRICK)
Block(-1,-81,0,NETHER_BRICK)
Block(2,9,1,NETHER_BRICK)
Block(-1,-84,0,NETHER_BRICK)
Block(1,-1,0,NETHER_BRICK)
Block(2,8,1,NETHER_BRICK)
Block(-1,-83,0,NETHER_BRICK)
Block(-1,-86,0,NETHER_BRICK)
Block(-1,-85,0,NETHER_BRICK)
Block(-6,-138,0,NETHER_BRICK)
Block(-6,-139,0,NETHER_BRICK)
Block(-2,-119,-5,NETHER_BRICK)
Block(-2,-118,-5,NETHER_BRICK)
Block(-2,-117,-5,NETHER_BRICK)
Block(-6,-134,0,NETHER_BRICK)
Block(-2,-116,-5,NETHER_BRICK)
Block(-6,-135,0,NETHER_BRICK)
Block(-2,-115,-5,NETHER_BRICK)
Block(-6,-136,0,NETHER_BRICK)
Block(-2,-114,-5,NETHER_BRICK)
Block(-6,-137,0,NETHER_BRICK)
Block(-2,-113,-5,NETHER_BRICK)
Block(-6,-130,0,NETHER_BRICK)
Block(-2,-112,-5,NETHER_BRICK)
Block(-6,-131,0,NETHER_BRICK)
Block(-2,-111,-5,NETHER_BRICK)
Block(-6,-132,0,NETHER_BRICK)
Block(-2,-110,-5,NETHER_BRICK)
Block(-6,-133,0,NETHER_BRICK)
Block(-1,-79,0,NETHER_BRICK)
Block(1,1,6,NETHER_BRICK)
Block(-1,-78,0,NETHER_BRICK)
Block(1,2,6,NETHER_BRICK)
Block(-2,-130,-5,NETHER_BRICK)
Block(1,3,6,NETHER_BRICK)
Block(-1,-77,0,NETHER_BRICK)
Block(-2,-131,-5,NETHER_BRICK)
Block(1,4,6,NETHER_BRICK)
Block(-1,-76,0,NETHER_BRICK)
Block(1,5,6,NETHER_BRICK_STAIRS:2)
Block(6,-101,-1,NETHER_BRICK)
Block(6,-100,-1,NETHER_BRICK)
Block(6,-103,-1,NETHER_BRICK)
Block(-1,-71,0,NETHER_BRICK)
Block(6,-102,-1,NETHER_BRICK)
Block(-1,-70,0,NETHER_BRICK)
Block(6,-105,-1,NETHER_BRICK)
Block(6,-104,-1,NETHER_BRICK)
Block(6,-107,-1,NETHER_BRICK)
Block(-1,-75,0,NETHER_BRICK)
Block(6,-106,-1,NETHER_BRICK)
Block(-1,-74,0,NETHER_BRICK)
Block(6,-109,-1,NETHER_BRICK)
Block(-1,-73,0,NETHER_BRICK)
Block(6,-108,-1,NETHER_BRICK)
Block(-1,-72,0,NETHER_BRICK)
Block(-6,-129,0,NETHER_BRICK)
Block(-2,-129,-5,NETHER_BRICK)
Block(-6,-127,0,NETHER_BRICK)
Block(-6,-128,0,NETHER_BRICK)
Block(-6,-125,0,NETHER_BRICK)
Block(-2,-126,-5,NETHER_BRICK)
Block(-2,-125,-5,NETHER_BRICK)
Block(-6,-126,0,NETHER_BRICK)
Block(-6,-123,0,NETHER_BRICK)
Block(-2,-128,-5,NETHER_BRICK)
Block(-6,-124,0,NETHER_BRICK)
Block(-2,-127,-5,NETHER_BRICK)
Block(-6,-121,0,NETHER_BRICK)
Block(-2,-122,-5,NETHER_BRICK)
Block(-2,-121,-5,NETHER_BRICK)
Block(-6,-122,0,NETHER_BRICK)
Block(-2,-124,-5,NETHER_BRICK)
Block(-6,-120,0,NETHER_BRICK)
Block(-2,-123,-5,NETHER_BRICK)
Block(6,-112,-1,NETHER_BRICK)
Block(-2,2,5,NETHER_BRICK)
Block(6,-111,-1,NETHER_BRICK)
Block(-2,3,5,NETHER_BRICK)
Block(-1,-69,0,NETHER_BRICK)
Block(6,-110,-1,NETHER_BRICK)
Block(-2,4,5,NETHER_BRICK)
Block(-2,5,5,NETHER_BRICK)
Block(-1,-66,0,NETHER_BRICK)
Block(-1,-65,0,NETHER_BRICK)
Block(-2,0,5,NETHER_BRICK)
Block(-1,-68,0,NETHER_BRICK)
Block(-2,1,5,NETHER_BRICK)
Block(-1,-67,0,NETHER_BRICK)
Block(-1,-62,0,NETHER_BRICK)
Block(6,-119,-1,NETHER_BRICK)
Block(-1,-61,0,NETHER_BRICK)
Block(6,-118,-1,NETHER_BRICK)
Block(-1,-64,0,NETHER_BRICK)
Block(6,-117,-1,NETHER_BRICK)
Block(-1,-63,0,NETHER_BRICK)
Block(6,-116,-1,NETHER_BRICK)
Block(-2,6,5,NETHER_BRICK)
Block(6,-115,-1,NETHER_BRICK)
Block(-2,7,5,NETHER_BRICK_STAIRS:1)
Block(6,-114,-1,NETHER_BRICK)
Block(-1,-60,0,NETHER_BRICK)
Block(6,-113,-1,NETHER_BRICK)
Block(-6,-116,0,NETHER_BRICK)
Block(-6,-117,0,NETHER_BRICK)
Block(-6,-118,0,NETHER_BRICK)
Block(-6,-119,0,NETHER_BRICK)
Block(1,0,6,NETHER_BRICK)
Block(-6,-110,0,NETHER_BRICK)
Block(-6,-111,0,NETHER_BRICK)
Block(-6,-112,0,NETHER_BRICK)
Block(-6,-113,0,NETHER_BRICK)
Block(-6,-114,0,NETHER_BRICK)
Block(-6,-115,0,NETHER_BRICK)
Block(6,-121,-1,NETHER_BRICK)
Block(6,-120,-1,NETHER_BRICK)
Block(6,-123,-1,NETHER_BRICK)
Block(-1,-59,0,NETHER_BRICK)
Block(6,-122,-1,NETHER_BRICK)
Block(-1,-58,0,NETHER_BRICK)
Block(-1,-57,0,NETHER_BRICK)
Block(-1,-56,0,NETHER_BRICK)
Block(-1,-55,0,NETHER_BRICK)
Block(-1,-54,0,NETHER_BRICK)
Block(6,-129,-1,NETHER_BRICK)
Block(-1,-53,0,NETHER_BRICK)
Block(6,-128,-1,NETHER_BRICK)
Block(-1,-52,0,NETHER_BRICK)
Block(-1,-51,0,NETHER_BRICK)
Block(-1,-50,0,NETHER_BRICK)
Block(6,-125,-1,NETHER_BRICK)
Block(6,-124,-1,NETHER_BRICK)
Block(6,-127,-1,NETHER_BRICK)
Block(6,-126,-1,NETHER_BRICK)
Block(-6,-107,0,NETHER_BRICK)
Block(-2,-108,-5,NETHER_BRICK)
Block(1,-6,0,NETHER_BRICK)
Block(-5,2,2,NETHER_BRICK)
Block(-2,-107,-5,NETHER_BRICK)
Block(-6,-108,0,NETHER_BRICK)
Block(1,-7,0,NETHER_BRICK)
Block(-5,3,2,NETHER_BRICK)
Block(-6,-105,0,NETHER_BRICK)
Block(1,-8,0,NETHER_BRICK)
Block(-5,4,2,NETHER_BRICK)
Block(-6,-106,0,NETHER_BRICK)
Block(-2,-109,-5,NETHER_BRICK)
Block(1,-9,0,NETHER_BRICK)
Block(-5,5,2,NETHER_BRICK)
Block(-6,-109,0,NETHER_BRICK)
Block(-5,0,2,NETHER_BRICK)
Block(-5,1,2,NETHER_BRICK)
Block(-2,-100,-5,NETHER_BRICK)
Block(-6,-100,0,NETHER_BRICK)
Block(-2,-102,-5,NETHER_BRICK)
Block(-2,-101,-5,NETHER_BRICK)
Block(-6,-103,0,NETHER_BRICK)
Block(-2,-104,-5,NETHER_BRICK)
Block(-5,6,2,NETHER_BRICK)
Block(-2,-103,-5,NETHER_BRICK)
Block(-6,-104,0,NETHER_BRICK)
Block(-5,7,2,NETHER_BRICK_STAIRS:2)
Block(-6,-101,0,NETHER_BRICK)
Block(-2,-106,-5,NETHER_BRICK)
Block(-6,-102,0,NETHER_BRICK)
Block(-2,-105,-5,NETHER_BRICK)
Block(6,-137,-1,NETHER_BRICK)
Block(1,18,0,NETHER_BRICK)
Block(6,-138,-1,NETHER_BRICK)
Block(1,19,0,NETHER_BRICK)
Block(6,-135,-1,NETHER_BRICK)
Block(1,16,0,NETHER_BRICK)
Block(6,-136,-1,NETHER_BRICK)
Block(1,17,0,NETHER_BRICK)
Block(1,14,0,NETHER_BRICK)
Block(1,15,0,NETHER_BRICK)
Block(6,-139,-1,NETHER_BRICK)
Block(1,12,0,NETHER_BRICK)
Block(1,13,0,NETHER_BRICK)
Block(-2,-164,-5,NETHER_BRICK)
Block(-6,-181,0,NETHER_BRICK)
Block(1,10,0,NETHER_BRICK)
Block(6,-130,-1,NETHER_BRICK)
Block(-2,-163,-5,NETHER_BRICK)
Block(-6,-182,0,NETHER_BRICK)
Block(1,11,0,NETHER_BRICK)
Block(-2,-162,-5,NETHER_BRICK)
Block(-6,-183,0,NETHER_BRICK)
Block(-2,-161,-5,NETHER_BRICK)
Block(-6,-184,0,NETHER_BRICK)
Block(6,-133,-1,NETHER_BRICK)
Block(-2,-160,-5,NETHER_BRICK)
Block(6,-134,-1,NETHER_BRICK)
Block(6,-131,-1,NETHER_BRICK)
Block(6,-132,-1,NETHER_BRICK)
Block(-6,-180,0,NETHER_BRICK)
Block(-6,-179,0,NETHER_BRICK)
Block(-6,-178,0,NETHER_BRICK)
Block(-2,-158,-5,NETHER_BRICK)
Block(-2,-159,-5,NETHER_BRICK)
Block(-2,-156,-5,NETHER_BRICK)
Block(-6,-175,0,NETHER_BRICK)
Block(-2,-157,-5,NETHER_BRICK)
Block(-6,-174,0,NETHER_BRICK)
Block(-2,-154,-5,NETHER_BRICK)
Block(-6,-177,0,NETHER_BRICK)
Block(-2,-155,-5,NETHER_BRICK)
Block(-6,-176,0,NETHER_BRICK)
Block(6,-146,-1,NETHER_BRICK)
Block(6,-147,-1,NETHER_BRICK)
Block(6,-148,-1,NETHER_BRICK)
Block(6,-149,-1,NETHER_BRICK)
Block(-6,-172,0,NETHER_BRICK)
Block(-2,-173,-5,NETHER_BRICK)
Block(-2,-172,-5,NETHER_BRICK)
Block(-6,-173,0,NETHER_BRICK)
Block(6,-140,-1,NETHER_BRICK)
Block(-6,-170,0,NETHER_BRICK)
Block(-2,-175,-5,NETHER_BRICK)
Block(6,-141,-1,NETHER_BRICK)
Block(-6,-171,0,NETHER_BRICK)
Block(-2,-174,-5,NETHER_BRICK)
Block(6,-142,-1,NETHER_BRICK)
Block(6,-143,-1,NETHER_BRICK)
Block(6,-144,-1,NETHER_BRICK)
Block(-2,-171,-5,NETHER_BRICK)
Block(6,-145,-1,NETHER_BRICK)
Block(-2,-170,-5,NETHER_BRICK)
Block(-2,-169,-5,NETHER_BRICK)
Block(-6,-169,0,NETHER_BRICK)
Block(-6,-168,0,NETHER_BRICK)
Block(-6,-167,0,NETHER_BRICK)
Block(-2,-165,-5,NETHER_BRICK)
Block(-6,-166,0,NETHER_BRICK)
Block(-5,-7,1,NETHER_BRICK)
Block(-6,-165,0,NETHER_BRICK)
Block(-2,-166,-5,NETHER_BRICK)
Block(-5,-6,1,NETHER_BRICK)
Block(-6,-164,0,NETHER_BRICK)
Block(-2,-167,-5,NETHER_BRICK)
Block(-5,-9,1,NETHER_BRICK)
Block(-6,-163,0,NETHER_BRICK)
Block(-2,-168,-5,NETHER_BRICK)
Block(-5,-8,1,NETHER_BRICK)
Block(-5,-3,1,NETHER_BRICK)
Block(-5,-2,1,NETHER_BRICK)
Block(-5,-5,1,NETHER_BRICK)
Block(-5,-4,1,NETHER_BRICK)
Block(-5,-1,1,NETHER_BRICK)
Block(1,37,0,NETHER_FENCE)
Block(6,-159,-1,NETHER_BRICK)
Block(6,-157,-1,NETHER_BRICK)
Block(6,-158,-1,NETHER_BRICK)
Block(6,-155,-1,NETHER_BRICK)
Block(6,-156,-1,NETHER_BRICK)
Block(6,-153,-1,NETHER_BRICK)
Block(6,-154,-1,NETHER_BRICK)
Block(-2,-142,-5,NETHER_BRICK)
Block(6,-151,-1,NETHER_BRICK)
Block(1,32,0,NETHER_BRICK)
Block(-2,-141,-5,NETHER_BRICK)
Block(6,-152,-1,NETHER_BRICK)
Block(-6,-160,0,NETHER_BRICK)
Block(-2,-140,-5,NETHER_BRICK)
Block(-6,-161,0,NETHER_BRICK)
Block(1,30,0,NETHER_BRICK)
Block(6,-150,-1,NETHER_BRICK)
Block(-6,-162,0,NETHER_BRICK)
Block(1,31,0,NETHER_BRICK)
Block(-2,-134,-5,NETHER_BRICK)
Block(-6,-153,0,NETHER_BRICK)
Block(-2,-135,-5,NETHER_BRICK)
Block(-6,-152,0,NETHER_BRICK)
Block(-2,-132,-5,NETHER_BRICK)
Block(-6,-155,0,NETHER_BRICK)
Block(-2,-133,-5,NETHER_BRICK)
Block(-6,-154,0,NETHER_BRICK)
Block(-2,-138,-5,NETHER_BRICK)
Block(-6,-157,0,NETHER_BRICK)
Block(-2,-139,-5,NETHER_BRICK)
Block(-6,-156,0,NETHER_BRICK)
Block(-2,-136,-5,NETHER_BRICK)
Block(-6,-159,0,NETHER_BRICK)
Block(-2,-137,-5,NETHER_BRICK)
Block(-6,-158,0,NETHER_BRICK)
Block(-1,-96,0,NETHER_BRICK)
Block(1,23,0,NETHER_BRICK)
Block(-1,-97,0,NETHER_BRICK)
Block(1,24,0,NETHER_BRICK)
Block(-1,-94,0,NETHER_BRICK)
Block(1,25,0,NETHER_BRICK)
Block(-1,-95,0,NETHER_BRICK)
Block(1,26,0,NETHER_BRICK)
Block(6,-168,-1,NETHER_BRICK)
Block(-1,-92,0,NETHER_BRICK)
Block(1,27,0,NETHER_BRICK)
Block(6,-169,-1,NETHER_BRICK)
Block(-1,-93,0,NETHER_BRICK)
Block(1,28,0,NETHER_BRICK)
Block(-1,-90,0,NETHER_BRICK)
Block(1,29,0,NETHER_BRICK)
Block(-1,-91,0,NETHER_BRICK)
Block(6,-164,-1,NETHER_BRICK)
Block(6,-165,-1,NETHER_BRICK)
Block(6,-166,-1,NETHER_BRICK)
Block(6,-167,-1,NETHER_BRICK)
Block(-6,-150,0,NETHER_BRICK)
Block(-2,-151,-5,NETHER_BRICK)
Block(6,-160,-1,NETHER_BRICK)
Block(-2,-150,-5,NETHER_BRICK)
Block(-6,-151,0,NETHER_BRICK)
Block(6,-161,-1,NETHER_BRICK)
Block(1,20,0,NETHER_BRICK)
Block(-2,-153,-5,NETHER_BRICK)
Block(6,-162,-1,NETHER_BRICK)
Block(-1,-98,0,NETHER_BRICK)
Block(1,21,0,NETHER_BRICK)
Block(-2,-152,-5,NETHER_BRICK)
Block(6,-163,-1,NETHER_BRICK)
Block(-1,-99,0,NETHER_BRICK)
Block(1,22,0,NETHER_BRICK)
Block(-2,-143,-5,NETHER_BRICK)
Block(-6,-144,0,NETHER_BRICK)
Block(-6,-143,0,NETHER_BRICK)
Block(-2,-144,-5,NETHER_BRICK)
Block(-6,-142,0,NETHER_BRICK)
Block(-2,-145,-5,NETHER_BRICK)
Block(-6,-141,0,NETHER_BRICK)
Block(-2,-146,-5,NETHER_BRICK)
Block(-2,-147,-5,NETHER_BRICK)
Block(-6,-148,0,NETHER_BRICK)
Block(-6,-147,0,NETHER_BRICK)
Block(-2,-148,-5,NETHER_BRICK)
Block(-6,-146,0,NETHER_BRICK)
Block(-2,-149,-5,NETHER_BRICK)
Block(-6,-145,0,NETHER_BRICK)
Block(-6,-149,0,NETHER_BRICK)
Block(-4,-112,-1,NETHER_BRICK)
Block(-4,-113,-1,NETHER_BRICK)
Block(-4,-114,-1,NETHER_BRICK)
Block(-4,-115,-1,NETHER_BRICK)
Block(-4,-116,-1,NETHER_BRICK)
Block(4,-70,-2,NETHER_BRICK)
Block(-4,-117,-1,NETHER_BRICK)
Block(-4,-118,-1,NETHER_BRICK)
Block(-4,-119,-1,NETHER_BRICK)
Block(4,-74,-2,NETHER_BRICK)
Block(4,-73,-2,NETHER_BRICK)
Block(4,-72,-2,NETHER_BRICK)
Block(4,-71,-2,NETHER_BRICK)
Block(4,-78,-2,NETHER_BRICK)
Block(4,-77,-2,NETHER_BRICK)
Block(-4,-110,-1,NETHER_BRICK)
Block(4,-76,-2,NETHER_BRICK)
Block(-4,-111,-1,NETHER_BRICK)
Block(4,-75,-2,NETHER_BRICK)
Block(1,40,0,NETHER_BRICK)
Block(4,-68,-2,NETHER_BRICK)
Block(4,-69,-2,NETHER_BRICK)
Block(1,48,0,NETHER_BRICK)
Block(1,47,0,NETHER_BRICK)
Block(1,46,0,NETHER_BRICK)
Block(1,49,0,NETHER_BRICK)
Block(-4,-125,-1,NETHER_BRICK)
Block(-4,-126,-1,NETHER_BRICK)
Block(-4,-123,-1,NETHER_BRICK)
Block(-4,-124,-1,NETHER_BRICK)
Block(-4,-129,-1,NETHER_BRICK)
Block(-4,-127,-1,NETHER_BRICK)
Block(-4,-128,-1,NETHER_BRICK)
Block(4,-61,-2,NETHER_BRICK)
Block(4,-60,-2,NETHER_BRICK)
Block(4,-63,-2,NETHER_BRICK)
Block(4,-62,-2,NETHER_BRICK)
Block(-4,-121,-1,NETHER_BRICK)
Block(4,-65,-2,NETHER_BRICK)
Block(-4,-122,-1,NETHER_BRICK)
Block(4,-64,-2,NETHER_BRICK)
Block(4,-67,-2,NETHER_BRICK)
Block(-4,-120,-1,NETHER_BRICK)
Block(4,-66,-2,NETHER_BRICK)
Block(4,-57,-2,NETHER_BRICK)
Block(4,-58,-2,NETHER_BRICK)
Block(4,-59,-2,NETHER_BRICK)
Block(1,52,0,NETHER_BRICK)
Block(1,55,0,NETHER_BRICK)
Block(1,54,0,NETHER_BRICK_STAIRS:5)
Block(1,56,0,NETHER_BRICK_STAIRS:1)
Block(4,-92,-2,NETHER_BRICK)
Block(4,-91,-2,NETHER_BRICK)
Block(4,-90,-2,NETHER_BRICK)
Block(4,-99,-2,NETHER_BRICK)
Block(4,-98,-2,NETHER_BRICK)
Block(-4,40,-2,STEP:6)
Block(4,-97,-2,NETHER_BRICK)
Block(4,-96,-2,NETHER_BRICK)
Block(0,-179,-1,NETHER_BRICK)
Block(4,-95,-2,NETHER_BRICK)
Block(0,-178,-1,NETHER_BRICK)
Block(4,-94,-2,NETHER_BRICK)
Block(0,-177,-1,NETHER_BRICK)
Block(4,-93,-2,NETHER_BRICK)
Block(0,-175,-1,NETHER_BRICK)
Block(0,-176,-1,NETHER_BRICK)
Block(0,-173,-1,NETHER_BRICK)
Block(-4,38,-2,NETHER_FENCE)
Block(0,-174,-1,NETHER_BRICK)
Block(0,-171,-1,NETHER_BRICK)
Block(-4,32,-2,SOUL_SAND)
Block(0,-172,-1,NETHER_BRICK)
Block(-4,31,-2,NETHER_BRICK_STAIRS:4)
Block(0,-170,-1,NETHER_BRICK)
Block(-4,39,-2,NETHER_FENCE)
Block(-4,-107,-1,NETHER_BRICK)
Block(-4,-108,-1,NETHER_BRICK)
Block(-4,-105,-1,NETHER_BRICK)
Block(4,-81,-2,NETHER_BRICK)
Block(-4,-106,-1,NETHER_BRICK)
Block(4,-80,-2,NETHER_BRICK)
Block(-4,-103,-1,NETHER_BRICK)
Block(-4,-104,-1,NETHER_BRICK)
Block(-4,-101,-1,NETHER_BRICK)
Block(-4,-102,-1,NETHER_BRICK)
Block(4,-87,-2,NETHER_BRICK)
Block(4,-86,-2,NETHER_BRICK)
Block(-4,-100,-1,NETHER_BRICK)
Block(4,-89,-2,NETHER_BRICK)
Block(4,-88,-2,NETHER_BRICK)
Block(4,-83,-2,NETHER_BRICK)
Block(4,-82,-2,NETHER_BRICK)
Block(4,-85,-2,NETHER_BRICK)
Block(4,-84,-2,NETHER_BRICK)
Block(0,-184,-1,NETHER_BRICK)
Block(0,-185,-1,NETHER_BRICK)
Block(-4,46,-2,NETHER_BRICK_STAIRS:2)
Block(0,-180,-1,NETHER_BRICK)
Block(4,-79,-2,NETHER_BRICK)
Block(-4,45,-2,NETHER_FENCE)
Block(0,-181,-1,NETHER_BRICK)
Block(0,-182,-1,NETHER_BRICK)
Block(0,-183,-1,NETHER_BRICK)
Block(-4,-109,-1,NETHER_BRICK)
Block(4,-30,-2,NETHER_BRICK)
Block(4,-33,-2,NETHER_BRICK)
Block(4,-34,-2,NETHER_BRICK)
Block(3,-179,2,NETHER_BRICK)
Block(4,-31,-2,NETHER_BRICK)
Block(3,-178,2,NETHER_BRICK)
Block(4,-32,-2,NETHER_BRICK)
Block(-1,-163,-2,NETHER_BRICK)
Block(3,-177,2,NETHER_BRICK)
Block(-1,-164,-2,NETHER_BRICK)
Block(3,-176,2,NETHER_BRICK)
Block(-1,-165,-2,NETHER_BRICK)
Block(3,-175,2,NETHER_BRICK)
Block(-1,-166,-2,NETHER_BRICK)
Block(3,-174,2,NETHER_BRICK)
Block(-1,-167,-2,NETHER_BRICK)
Block(3,-173,2,NETHER_BRICK)
Block(-1,-168,-2,NETHER_BRICK)
Block(3,-172,2,NETHER_BRICK)
Block(-1,-169,-2,NETHER_BRICK)
Block(3,-171,2,NETHER_BRICK)
Block(3,-170,2,NETHER_BRICK)
Block(-1,-30,0,NETHER_BRICK)
Block(-1,-31,0,NETHER_BRICK)
Block(-1,-171,-2,NETHER_BRICK)
Block(-7,39,-2,NETHER_BRICK)
Block(-1,-170,-2,NETHER_BRICK)
Block(-7,38,-2,NETHER_BRICK)
Block(-1,-173,-2,NETHER_BRICK)
Block(-7,37,-2,NETHER_BRICK_STAIRS:6)
Block(-1,-172,-2,NETHER_BRICK)
Block(-7,35,-2,NETHER_BRICK_STAIRS:6)
Block(-1,-36,0,NETHER_BRICK)
Block(4,-27,-2,NETHER_BRICK)
Block(-1,-37,0,NETHER_BRICK)
Block(4,-26,-2,NETHER_BRICK)
Block(-1,-38,0,NETHER_BRICK)
Block(4,-25,-2,NETHER_BRICK)
Block(-7,32,-2,NETHER_BRICK)
Block(-1,-39,0,NETHER_BRICK)
Block(4,-24,-2,NETHER_BRICK)
Block(-7,31,-2,STEP:14)
Block(-1,-32,0,NETHER_BRICK)
Block(-7,30,-2,NETHER_BRICK_STAIRS)
Block(-1,-33,0,NETHER_BRICK)
Block(-1,-34,0,NETHER_BRICK)
Block(4,-29,-2,NETHER_BRICK)
Block(-1,-35,0,NETHER_BRICK)
Block(4,-28,-2,NETHER_BRICK)
Block(-3,9,-2,NETHER_BRICK)
Block(4,-20,-2,NETHER_BRICK)
Block(4,-21,-2,NETHER_BRICK)
Block(4,-22,-2,NETHER_BRICK)
Block(4,-23,-2,NETHER_BRICK)
Block(-1,-176,-2,NETHER_BRICK)
Block(-3,1,-2,NETHER_BRICK)
Block(-1,-177,-2,NETHER_BRICK)
Block(3,-185,2,NETHER_BRICK)
Block(-3,2,-2,NETHER_BRICK)
Block(-1,-174,-2,NETHER_BRICK)
Block(-3,3,-2,NETHER_BRICK)
Block(-1,-175,-2,NETHER_BRICK)
Block(-3,4,-2,NETHER_BRICK)
Block(3,-182,2,NETHER_BRICK)
Block(-3,5,-2,NETHER_BRICK)
Block(3,-181,2,NETHER_BRICK)
Block(-3,6,-2,NETHER_BRICK)
Block(-1,-178,-2,NETHER_BRICK)
Block(3,-184,2,NETHER_BRICK)
Block(-3,7,-2,NETHER_BRICK)
Block(-1,-179,-2,NETHER_BRICK)
Block(3,-183,2,NETHER_BRICK)
Block(-3,8,-2,NETHER_BRICK)
Block(-1,-180,-2,NETHER_BRICK)
Block(-1,-41,0,NETHER_BRICK)
Block(-1,-42,0,NETHER_BRICK)
Block(3,-180,2,NETHER_BRICK)
Block(-1,-40,0,NETHER_BRICK)
Block(-1,-184,-2,NETHER_BRICK)
Block(-1,-183,-2,NETHER_BRICK)
Block(-1,-182,-2,NETHER_BRICK)
Block(-3,0,-2,NETHER_BRICK)
Block(-1,-181,-2,NETHER_BRICK)
Block(-2,7,4,NETHER_BRICK_STAIRS:2)
Block(4,-14,-2,NETHER_BRICK)
Block(-4,22,-2,NETHER_BRICK_STAIRS:4)
Block(-2,6,4,NETHER_BRICK)
Block(-1,-49,0,NETHER_BRICK)
Block(4,-13,-2,NETHER_BRICK)
Block(-4,23,-2,NETHER_BRICK_STAIRS:1)
Block(-2,5,4,NETHER_BRICK)
Block(4,-16,-2,NETHER_BRICK)
Block(-2,4,4,NETHER_BRICK)
Block(-1,-47,0,NETHER_BRICK)
Block(4,-15,-2,NETHER_BRICK)
Block(-2,3,4,NETHER_BRICK)
Block(-1,-48,0,NETHER_BRICK)
Block(4,-18,-2,NETHER_BRICK)
Block(-2,2,4,NETHER_BRICK)
Block(-7,40,-2,STEP:6)
Block(-1,-45,0,NETHER_BRICK)
Block(4,-17,-2,NETHER_BRICK)
Block(-2,1,4,NETHER_BRICK)
Block(-1,-46,0,NETHER_BRICK)
Block(-4,24,-2,NETHER_BRICK_STAIRS:5)
Block(-2,0,4,NETHER_BRICK)
Block(-1,-43,0,NETHER_BRICK)
Block(4,-19,-2,NETHER_BRICK)
Block(-4,25,-2,NETHER_BRICK_STAIRS)
Block(-1,-44,0,NETHER_BRICK)
Block(3,-159,2,NETHER_BRICK)
Block(-1,-19,0,NETHER_BRICK)
Block(4,-55,-2,NETHER_BRICK)
Block(3,-158,2,NETHER_BRICK)
Block(-1,-18,0,NETHER_BRICK)
Block(4,-56,-2,NETHER_BRICK)
Block(3,-157,2,NETHER_BRICK)
Block(4,-53,-2,NETHER_BRICK)
Block(3,-156,2,NETHER_BRICK)
Block(4,-54,-2,NETHER_BRICK)
Block(4,-51,-2,NETHER_BRICK)
Block(4,-52,-2,NETHER_BRICK)
Block(4,-50,-2,NETHER_BRICK)
Block(3,-151,2,NETHER_BRICK)
Block(3,-150,2,NETHER_BRICK)
Block(3,-155,2,NETHER_BRICK)
Block(-1,-185,-2,NETHER_BRICK)
Block(3,-154,2,NETHER_BRICK)
Block(3,-153,2,NETHER_BRICK)
Block(3,-152,2,NETHER_BRICK)
Block(-1,-10,0,NETHER_BRICK)
Block(-1,-11,0,NETHER_BRICK)
Block(-1,-12,0,NETHER_BRICK)
Block(-1,-13,0,NETHER_BRICK)
Block(-1,-14,0,NETHER_BRICK)
Block(4,-49,-2,NETHER_BRICK)
Block(-1,-15,0,NETHER_BRICK)
Block(4,-48,-2,NETHER_BRICK)
Block(-1,-16,0,NETHER_BRICK)
Block(4,-47,-2,NETHER_BRICK)
Block(-1,-17,0,NETHER_BRICK)
Block(4,-46,-2,NETHER_BRICK)
Block(3,-168,2,NETHER_BRICK)
Block(4,-42,-2,NETHER_BRICK)
Block(3,-167,2,NETHER_BRICK)
Block(4,-43,-2,NETHER_BRICK)
Block(4,-44,-2,NETHER_BRICK)
Block(3,-169,2,NETHER_BRICK)
Block(4,-45,-2,NETHER_BRICK)
Block(-1,-29,0,NETHER_BRICK)
Block(4,-40,-2,NETHER_BRICK)
Block(4,-41,-2,NETHER_BRICK)
Block(3,-160,2,NETHER_BRICK)
Block(3,-162,2,NETHER_BRICK)
Block(3,-161,2,NETHER_BRICK)
Block(3,-164,2,NETHER_BRICK)
Block(3,-163,2,NETHER_BRICK)
Block(3,-166,2,NETHER_BRICK)
Block(3,-165,2,NETHER_BRICK)
Block(-7,28,-2,NETHER_FENCE)
Block(-1,-20,0,NETHER_BRICK)
Block(-7,29,-2,NETHER_FENCE)
Block(-1,-23,0,NETHER_BRICK)
Block(4,-39,-2,NETHER_BRICK)
Block(-1,-24,0,NETHER_BRICK)
Block(-1,-21,0,NETHER_BRICK)
Block(-1,-22,0,NETHER_BRICK)
Block(4,-36,-2,NETHER_BRICK)
Block(-1,-27,0,NETHER_BRICK)
Block(4,-35,-2,NETHER_BRICK)
Block(-1,-28,0,NETHER_BRICK)
Block(4,-38,-2,NETHER_BRICK)
Block(-1,-25,0,NETHER_BRICK)
Block(4,-37,-2,NETHER_BRICK)
Block(-1,-26,0,NETHER_BRICK)
Block(-4,-2,-2,NETHER_BRICK)
Block(-4,-1,-2,NETHER_BRICK)
Block(0,-110,-1,NETHER_BRICK)
Block(-4,-6,-2,NETHER_BRICK)
Block(-4,-5,-2,NETHER_BRICK)
Block(-4,-4,-2,NETHER_BRICK)
Block(-4,-3,-2,NETHER_BRICK)
Block(-4,39,6,NETHER_BRICK)
Block(-4,-9,-2,NETHER_BRICK)
Block(-4,38,6,NETHER_BRICK)
Block(-4,-8,-2,NETHER_BRICK)
Block(-4,-7,-2,NETHER_BRICK)
Block(-1,-122,-2,NETHER_BRICK)
Block(0,-119,-1,NETHER_BRICK)
Block(-1,-121,-2,NETHER_BRICK)
Block(-1,-120,-2,NETHER_BRICK)
Block(-1,-126,-2,NETHER_BRICK)
Block(-1,-125,-2,NETHER_BRICK)
Block(-1,-124,-2,NETHER_BRICK)
Block(-1,-123,-2,NETHER_BRICK)
Block(0,-112,-1,NETHER_BRICK)
Block(0,-111,-1,NETHER_BRICK)
Block(-1,-129,-2,NETHER_BRICK)
Block(0,-114,-1,NETHER_BRICK)
Block(-1,-128,-2,NETHER_BRICK)
Block(0,-113,-1,NETHER_BRICK)
Block(-1,-127,-2,NETHER_BRICK)
Block(0,-116,-1,NETHER_BRICK)
Block(0,-115,-1,NETHER_BRICK)
Block(0,-118,-1,NETHER_BRICK)
Block(0,-117,-1,NETHER_BRICK)
Block(0,-120,-1,NETHER_BRICK)
Block(0,-121,-1,NETHER_BRICK)
Block(-1,-140,-2,NETHER_BRICK)
Block(-1,-131,-2,NETHER_BRICK)
Block(-1,-130,-2,NETHER_BRICK)
Block(-1,-133,-2,NETHER_BRICK)
Block(-1,-132,-2,NETHER_BRICK)
Block(-1,-135,-2,NETHER_BRICK)
Block(-1,-134,-2,NETHER_BRICK)
Block(-1,-137,-2,NETHER_BRICK)
Block(-1,-136,-2,NETHER_BRICK)
Block(0,-125,-1,NETHER_BRICK)
Block(-1,-139,-2,NETHER_BRICK)
Block(0,-124,-1,NETHER_BRICK)
Block(-1,-138,-2,NETHER_BRICK)
Block(0,-123,-1,NETHER_BRICK)
Block(0,-122,-1,NETHER_BRICK)
Block(0,-129,-1,NETHER_BRICK)
Block(0,-128,-1,NETHER_BRICK)
Block(0,-127,-1,NETHER_BRICK)
Block(0,-126,-1,NETHER_BRICK)
Block(-4,-180,-1,NETHER_BRICK)
Block(-1,-150,-2,NETHER_BRICK)
Block(-1,-151,-2,NETHER_BRICK)
Block(-1,-148,-2,NETHER_BRICK)
Block(-1,-147,-2,NETHER_BRICK)
Block(-1,-146,-2,NETHER_BRICK)
Block(-1,-145,-2,NETHER_BRICK)
Block(-1,-144,-2,NETHER_BRICK)
Block(-1,-143,-2,NETHER_BRICK)
Block(-1,-142,-2,NETHER_BRICK)
Block(-4,-178,-1,NETHER_BRICK)
Block(-1,-141,-2,NETHER_BRICK)
Block(-4,-179,-1,NETHER_BRICK)
Block(-4,-176,-1,NETHER_BRICK)
Block(4,-10,-2,NETHER_BRICK)
Block(-4,-177,-1,NETHER_BRICK)
Block(-4,-174,-1,NETHER_BRICK)
Block(4,-12,-2,NETHER_BRICK)
Block(-4,-175,-1,NETHER_BRICK)
Block(4,-11,-2,NETHER_BRICK)
Block(-4,-172,-1,NETHER_BRICK)
Block(-4,-173,-1,NETHER_BRICK)
Block(-4,-170,-1,NETHER_BRICK)
Block(-1,-149,-2,NETHER_BRICK)
Block(-4,-171,-1,NETHER_BRICK)
Block(-1,-160,-2,NETHER_BRICK)
Block(-1,-161,-2,NETHER_BRICK)
Block(-1,-162,-2,NETHER_BRICK)
Block(-1,-157,-2,NETHER_BRICK)
Block(-1,-156,-2,NETHER_BRICK)
Block(-1,-159,-2,NETHER_BRICK)
Block(-1,-158,-2,NETHER_BRICK)
Block(-1,-153,-2,NETHER_BRICK)
Block(-1,-152,-2,NETHER_BRICK)
Block(0,-109,-1,NETHER_BRICK)
Block(-1,-155,-2,NETHER_BRICK)
Block(0,-108,-1,NETHER_BRICK)
Block(-1,-154,-2,NETHER_BRICK)
Block(0,-107,-1,NETHER_BRICK)
Block(-4,-185,-1,NETHER_BRICK)
Block(0,-106,-1,NETHER_BRICK)
Block(0,-105,-1,NETHER_BRICK)
Block(0,-104,-1,NETHER_BRICK)
Block(0,-103,-1,NETHER_BRICK)
Block(-4,-181,-1,NETHER_BRICK)
Block(0,-102,-1,NETHER_BRICK)
Block(-4,-182,-1,NETHER_BRICK)
Block(0,-101,-1,NETHER_BRICK)
Block(-4,-183,-1,NETHER_BRICK)
Block(-4,-184,-1,NETHER_BRICK)
Block(0,-100,-1,NETHER_BRICK)
Block(0,-150,-1,NETHER_BRICK)
Block(0,-152,-1,NETHER_BRICK)
Block(0,-151,-1,NETHER_BRICK)
Block(0,-154,-1,NETHER_BRICK)
Block(0,-153,-1,NETHER_BRICK)
Block(-4,-151,-1,NETHER_BRICK)
Block(0,-155,-1,NETHER_BRICK)
Block(-4,-150,-1,NETHER_BRICK)
Block(0,-156,-1,NETHER_BRICK)
Block(0,-157,-1,NETHER_BRICK)
Block(0,-158,-1,NETHER_BRICK)
Block(-4,-155,-1,NETHER_BRICK)
Block(0,-159,-1,NETHER_BRICK)
Block(-4,-154,-1,NETHER_BRICK)
Block(-4,-153,-1,NETHER_BRICK)
Block(-4,-152,-1,NETHER_BRICK)
Block(-4,-159,-1,NETHER_BRICK)
Block(-4,-158,-1,NETHER_BRICK)
Block(-4,-157,-1,NETHER_BRICK)
Block(-4,-156,-1,NETHER_BRICK)
Block(0,-161,-1,NETHER_BRICK)
Block(0,-160,-1,NETHER_BRICK)
Block(0,-165,-1,NETHER_BRICK)
Block(0,-164,-1,NETHER_BRICK)
Block(0,-163,-1,NETHER_BRICK)
Block(0,-162,-1,NETHER_BRICK)
Block(-4,-160,-1,NETHER_BRICK)
Block(0,-168,-1,NETHER_BRICK)
Block(0,-169,-1,NETHER_BRICK)
Block(-4,-162,-1,NETHER_BRICK)
Block(0,-166,-1,NETHER_BRICK)
Block(-4,-161,-1,NETHER_BRICK)
Block(0,-167,-1,NETHER_BRICK)
Block(-4,-164,-1,NETHER_BRICK)
Block(-4,-163,-1,NETHER_BRICK)
Block(-4,-166,-1,NETHER_BRICK)
Block(-4,-165,-1,NETHER_BRICK)
Block(-4,-168,-1,NETHER_BRICK)
Block(-4,-167,-1,NETHER_BRICK)
Block(-4,-169,-1,NETHER_BRICK)
Block(0,-130,-1,NETHER_BRICK)
Block(0,-132,-1,NETHER_BRICK)
Block(0,-131,-1,NETHER_BRICK)
Block(-4,-133,-1,NETHER_BRICK)
Block(0,-137,-1,NETHER_BRICK)
Block(-4,-132,-1,NETHER_BRICK)
Block(0,-138,-1,NETHER_BRICK)
Block(-1,-109,-2,NETHER_BRICK)
Block(-4,-131,-1,NETHER_BRICK)
Block(0,-139,-1,NETHER_BRICK)
Block(-4,-130,-1,NETHER_BRICK)
Block(-1,-107,-2,NETHER_BRICK)
Block(0,-133,-1,NETHER_BRICK)
Block(-1,-108,-2,NETHER_BRICK)
Block(0,-134,-1,NETHER_BRICK)
Block(-1,-105,-2,NETHER_BRICK)
Block(0,-135,-1,NETHER_BRICK)
Block(-1,-106,-2,NETHER_BRICK)
Block(0,-136,-1,NETHER_BRICK)
Block(-1,-103,-2,NETHER_BRICK)
Block(-1,-104,-2,NETHER_BRICK)
Block(-1,-101,-2,NETHER_BRICK)
Block(-4,-139,-1,NETHER_BRICK)
Block(-1,-102,-2,NETHER_BRICK)
Block(-4,-138,-1,NETHER_BRICK)
Block(-4,-137,-1,NETHER_BRICK)
Block(-4,-136,-1,NETHER_BRICK)
Block(-1,-100,-2,NETHER_BRICK)
Block(-4,-135,-1,NETHER_BRICK)
Block(-4,-134,-1,NETHER_BRICK)
Block(0,-143,-1,NETHER_BRICK)
Block(0,-142,-1,NETHER_BRICK)
Block(0,-141,-1,NETHER_BRICK)
Block(0,-140,-1,NETHER_BRICK)
Block(-4,-142,-1,NETHER_BRICK)
Block(-4,-141,-1,NETHER_BRICK)
Block(-4,-144,-1,NETHER_BRICK)
Block(0,-148,-1,NETHER_BRICK)
Block(-4,-143,-1,NETHER_BRICK)
Block(0,-149,-1,NETHER_BRICK)
Block(-1,-116,-2,NETHER_BRICK)
Block(0,-146,-1,NETHER_BRICK)
Block(-1,-117,-2,NETHER_BRICK)
Block(0,-147,-1,NETHER_BRICK)
Block(-1,-118,-2,NETHER_BRICK)
Block(-4,-140,-1,NETHER_BRICK)
Block(0,-144,-1,NETHER_BRICK)
Block(-1,-119,-2,NETHER_BRICK)
Block(0,-145,-1,NETHER_BRICK)
Block(-1,-112,-2,NETHER_BRICK)
Block(-1,-113,-2,NETHER_BRICK)
Block(-4,-149,-1,NETHER_BRICK)
Block(-4,32,6,NETHER_BRICK)
Block(-1,-114,-2,NETHER_BRICK)
Block(-1,-115,-2,NETHER_BRICK)
Block(-4,-146,-1,NETHER_BRICK)
Block(-4,37,6,NETHER_FENCE)
Block(-4,-145,-1,NETHER_BRICK)
Block(-4,36,6,NETHER_BRICK_STAIRS:7)
Block(-1,-110,-2,NETHER_BRICK)
Block(-4,-148,-1,NETHER_BRICK)
Block(-1,-111,-2,NETHER_BRICK)
Block(-4,-147,-1,NETHER_BRICK)
Block(2,-84,-3,NETHER_BRICK)
Block(0,29,2,NETHER_BRICK)
Block(1,-53,-5,NETHER_BRICK)
Block(2,-83,-3,NETHER_BRICK)
Block(0,28,2,NETHER_BRICK)
Block(1,-54,-5,NETHER_BRICK)
Block(2,-86,-3,NETHER_BRICK)
Block(1,-51,-5,NETHER_BRICK)
Block(2,-85,-3,NETHER_BRICK)
Block(1,-52,-5,NETHER_BRICK)
Block(2,-80,-3,NETHER_BRICK)
Block(0,25,2,NETHER_BRICK)
Block(1,-57,-5,NETHER_BRICK)
Block(0,24,2,NETHER_BRICK)
Block(1,-58,-5,NETHER_BRICK)
Block(2,-82,-3,NETHER_BRICK)
Block(0,27,2,NETHER_BRICK)
Block(1,-55,-5,NETHER_BRICK)
Block(2,-81,-3,NETHER_BRICK)
Block(0,26,2,NETHER_BRICK)
Block(1,-56,-5,NETHER_BRICK)
Block(0,21,2,NETHER_BRICK)
Block(2,4,2,NETHER_BRICK)
Block(0,20,2,NETHER_BRICK)
Block(2,5,2,NETHER_BRICK)
Block(0,23,2,NETHER_BRICK)
Block(2,6,2,NETHER_BRICK)
Block(1,-59,-5,NETHER_BRICK)
Block(0,22,2,NETHER_BRICK)
Block(2,7,2,NETHER_BRICK)
Block(2,8,2,NETHER_BRICK)
Block(2,9,2,NETHER_BRICK)
Block(2,-76,-3,NETHER_BRICK)
Block(1,-61,-5,NETHER_BRICK)
Block(2,-77,-3,NETHER_BRICK)
Block(1,-60,-5,NETHER_BRICK)
Block(2,-78,-3,NETHER_BRICK)
Block(2,-79,-3,NETHER_BRICK)
Block(2,-97,-3,NETHER_BRICK)
Block(1,-40,-5,NETHER_BRICK)
Block(2,-96,-3,NETHER_BRICK)
Block(0,19,2,NETHER_BRICK)
Block(1,-41,-5,NETHER_BRICK)
Block(2,-95,-3,NETHER_BRICK)
Block(0,18,2,NETHER_BRICK)
Block(1,-42,-5,NETHER_BRICK)
Block(2,-94,-3,NETHER_BRICK)
Block(0,17,2,NETHER_BRICK)
Block(1,-43,-5,NETHER_BRICK)
Block(2,-93,-3,NETHER_BRICK)
Block(0,16,2,NETHER_BRICK)
Block(1,-44,-5,NETHER_BRICK)
Block(2,-92,-3,NETHER_BRICK)
Block(0,15,2,NETHER_BRICK)
Block(1,-45,-5,NETHER_BRICK)
Block(2,-91,-3,NETHER_BRICK)
Block(0,14,2,NETHER_BRICK)
Block(4,40,1,STEP:6)
Block(1,-46,-5,NETHER_BRICK)
Block(2,-90,-3,NETHER_BRICK)
Block(0,13,2,NETHER_BRICK)
Block(1,-47,-5,NETHER_BRICK)
Block(0,12,2,NETHER_BRICK)
Block(1,-48,-5,NETHER_BRICK)
Block(0,11,2,NETHER_BRICK)
Block(1,-49,-5,NETHER_BRICK)
Block(0,10,2,NETHER_BRICK)
Block(4,44,1,NETHER_BRICK_STAIRS:4)
Block(2,-89,-3,NETHER_BRICK)
Block(4,45,1,NETHER_BRICK)
Block(4,46,1,NETHER_BRICK_STAIRS:1)
Block(2,-87,-3,NETHER_BRICK)
Block(1,-50,-5,NETHER_BRICK)
Block(2,-88,-3,NETHER_BRICK)
Block(1,-35,-5,NETHER_BRICK)
Block(1,-36,-5,NETHER_BRICK)
Block(1,-33,-5,NETHER_BRICK)
Block(1,-34,-5,NETHER_BRICK)
Block(1,-31,-5,NETHER_BRICK)
Block(1,-32,-5,NETHER_BRICK)
Block(1,-30,-5,NETHER_BRICK)
Block(1,-39,-5,NETHER_BRICK)
Block(1,-37,-5,NETHER_BRICK)
Block(1,-38,-5,NETHER_BRICK)
Block(2,-98,-3,NETHER_BRICK)
Block(2,-99,-3,NETHER_BRICK)
Block(4,32,1,SOUL_SAND)
Block(4,31,1,NETHER_BRICK_STAIRS:5)
Block(1,-22,-5,NETHER_BRICK)
Block(1,-23,-5,NETHER_BRICK)
Block(1,-24,-5,NETHER_BRICK)
Block(1,-25,-5,NETHER_BRICK)
Block(1,-20,-5,NETHER_BRICK)
Block(1,-21,-5,NETHER_BRICK)
Block(1,-26,-5,NETHER_BRICK)
Block(1,-27,-5,NETHER_BRICK)
Block(1,-28,-5,NETHER_BRICK)
Block(1,-29,-5,NETHER_BRICK)
Block(2,3,2,NETHER_BRICK)
Block(2,2,2,NETHER_BRICK)
Block(2,1,2,NETHER_BRICK)
Block(2,0,2,NETHER_BRICK)
Block(4,23,1,STEP:6)
Block(4,24,1,NETHER_BRICK_STAIRS:4)
Block(4,25,1,NETHER_BRICK_STAIRS:1)
Block(4,7,-2,NETHER_BRICK_STAIRS)
Block(1,-98,-5,NETHER_BRICK)
Block(4,2,-2,NETHER_BRICK)
Block(1,-97,-5,NETHER_BRICK)
Block(4,1,-2,NETHER_BRICK)
Block(2,-40,-3,NETHER_BRICK)
Block(1,-96,-5,NETHER_BRICK)
Block(4,0,-2,NETHER_BRICK)
Block(2,-41,-3,NETHER_BRICK)
Block(1,-95,-5,NETHER_BRICK)
Block(2,-42,-3,NETHER_BRICK)
Block(4,6,-2,NETHER_BRICK)
Block(4,5,-2,NETHER_BRICK)
Block(4,4,-2,NETHER_BRICK)
Block(1,-99,-5,NETHER_BRICK)
Block(4,3,-2,NETHER_BRICK)
Block(2,-37,-3,NETHER_BRICK)
Block(2,-36,-3,NETHER_BRICK)
Block(2,-39,-3,NETHER_BRICK)
Block(2,-38,-3,NETHER_BRICK)
Block(0,-8,2,NETHER_BRICK)
Block(2,-33,-3,NETHER_BRICK)
Block(0,-7,2,NETHER_BRICK)
Block(2,-32,-3,NETHER_BRICK)
Block(2,-35,-3,NETHER_BRICK)
Block(0,-9,2,NETHER_BRICK)
Block(2,-34,-3,NETHER_BRICK)
Block(0,-5,2,NETHER_BRICK)
Block(1,-85,-5,NETHER_BRICK)
Block(2,-52,-3,NETHER_BRICK)
Block(0,-6,2,NETHER_BRICK)
Block(1,-84,-5,NETHER_BRICK)
Block(2,-53,-3,NETHER_BRICK)
Block(0,-3,2,NETHER_BRICK)
Block(1,-87,-5,NETHER_BRICK)
Block(2,-50,-3,NETHER_BRICK)
Block(0,-4,2,NETHER_BRICK)
Block(1,-86,-5,NETHER_BRICK)
Block(2,-51,-3,NETHER_BRICK)
Block(1,-89,-5,NETHER_BRICK)
Block(0,-1,2,NETHER_BRICK)
Block(0,-2,2,NETHER_BRICK)
Block(1,-88,-5,NETHER_BRICK)
Block(2,-49,-3,NETHER_BRICK)
Block(2,-48,-3,NETHER_BRICK)
Block(1,-90,-5,NETHER_BRICK)
Block(2,-47,-3,NETHER_BRICK)
Block(1,-91,-5,NETHER_BRICK)
Block(2,-46,-3,NETHER_BRICK)
Block(1,-92,-5,NETHER_BRICK)
Block(2,-45,-3,NETHER_BRICK)
Block(1,-93,-5,NETHER_BRICK)
Block(2,-44,-3,NETHER_BRICK)
Block(1,-94,-5,NETHER_BRICK)
Block(2,-43,-3,NETHER_BRICK)
Block(1,-79,-5,NETHER_BRICK)
Block(1,-78,-5,NETHER_BRICK)
Block(1,-77,-5,NETHER_BRICK)
Block(2,-60,-3,NETHER_BRICK)
Block(1,-76,-5,NETHER_BRICK)
Block(2,-61,-3,NETHER_BRICK)
Block(1,-75,-5,NETHER_BRICK)
Block(2,-62,-3,NETHER_BRICK)
Block(1,-74,-5,NETHER_BRICK)
Block(2,-63,-3,NETHER_BRICK)
Block(1,-73,-5,NETHER_BRICK)
Block(2,-64,-3,NETHER_BRICK)
Block(1,-82,-5,NETHER_BRICK)
Block(2,-55,-3,NETHER_BRICK)
Block(1,-83,-5,NETHER_BRICK)
Block(2,-54,-3,NETHER_BRICK)
Block(1,-80,-5,NETHER_BRICK)
Block(2,-57,-3,NETHER_BRICK)
Block(1,-81,-5,NETHER_BRICK)
Block(2,-56,-3,NETHER_BRICK)
Block(2,-59,-3,NETHER_BRICK)
Block(2,-58,-3,NETHER_BRICK)
Block(2,-70,-3,NETHER_BRICK)
Block(1,-67,-5,NETHER_BRICK)
Block(2,-71,-3,NETHER_BRICK)
Block(1,-66,-5,NETHER_BRICK)
Block(1,-69,-5,NETHER_BRICK)
Block(1,-68,-5,NETHER_BRICK)
Block(2,-74,-3,NETHER_BRICK)
Block(1,-63,-5,NETHER_BRICK)
Block(2,-75,-3,NETHER_BRICK)
Block(1,-62,-5,NETHER_BRICK)
Block(2,-72,-3,NETHER_BRICK)
Block(1,-65,-5,NETHER_BRICK)
Block(2,-73,-3,NETHER_BRICK)
Block(1,-64,-5,NETHER_BRICK)
Block(2,-68,-3,NETHER_BRICK)
Block(1,-70,-5,NETHER_BRICK)
Block(2,-67,-3,NETHER_BRICK)
Block(1,-71,-5,NETHER_BRICK)
Block(2,-66,-3,NETHER_BRICK)
Block(1,-72,-5,NETHER_BRICK)
Block(2,-65,-3,NETHER_BRICK)
Block(2,-69,-3,NETHER_BRICK)
Block(1,-49,5,NETHER_BRICK)
Block(1,-50,5,NETHER_BRICK)
Block(1,-51,5,NETHER_BRICK)
Block(1,-56,5,NETHER_BRICK)
Block(1,-57,5,NETHER_BRICK)
Block(1,-58,5,NETHER_BRICK)
Block(1,-59,5,NETHER_BRICK)
Block(1,-52,5,NETHER_BRICK)
Block(1,-53,5,NETHER_BRICK)
Block(1,-54,5,NETHER_BRICK)
Block(1,-55,5,NETHER_BRICK)
Block(1,-61,5,NETHER_BRICK)
Block(1,-62,5,NETHER_BRICK)
Block(1,-60,5,NETHER_BRICK)
Block(5,39,-6,STEP:6)
Block(1,-69,5,NETHER_BRICK)
Block(1,-67,5,NETHER_BRICK)
Block(5,38,-6,NETHER_BRICK)
Block(1,-68,5,NETHER_BRICK)
Block(1,-65,5,NETHER_BRICK)
Block(1,-66,5,NETHER_BRICK)
Block(1,-63,5,NETHER_BRICK)
Block(1,-64,5,NETHER_BRICK)
Block(1,-28,5,NETHER_BRICK)
Block(1,-27,5,NETHER_BRICK)
Block(2,-18,-3,NETHER_BRICK)
Block(2,-19,-3,NETHER_BRICK)
Block(1,-29,5,NETHER_BRICK)
Block(2,-12,-3,NETHER_BRICK)
Block(2,-13,-3,NETHER_BRICK)
Block(2,-10,-3,NETHER_BRICK)
Block(2,-11,-3,NETHER_BRICK)
Block(2,-16,-3,NETHER_BRICK)
Block(2,-17,-3,NETHER_BRICK)
Block(2,-14,-3,NETHER_BRICK)
Block(2,-15,-3,NETHER_BRICK)
Block(0,3,-1,NETHER_BRICK)
Block(0,2,-1,NETHER_BRICK)
Block(0,1,-1,NETHER_BRICK)
Block(0,0,-1,NETHER_BRICK)
Block(2,-20,-3,NETHER_BRICK)
Block(1,-30,5,NETHER_BRICK)
Block(1,-31,5,NETHER_BRICK)
Block(0,9,-1,NETHER_BRICK)
Block(1,-32,5,NETHER_BRICK)
Block(0,8,-1,NETHER_BRICK)
Block(1,-33,5,NETHER_BRICK)
Block(0,7,-1,NETHER_BRICK)
Block(1,-34,5,NETHER_BRICK)
Block(0,6,-1,NETHER_BRICK)
Block(1,-35,5,NETHER_BRICK)
Block(0,5,-1,NETHER_BRICK)
Block(1,-36,5,NETHER_BRICK)
Block(0,4,-1,NETHER_BRICK)
Block(1,-37,5,NETHER_BRICK)
Block(2,-29,-3,NETHER_BRICK)
Block(1,-39,5,NETHER_BRICK)
Block(1,-38,5,NETHER_BRICK)
Block(-1,-9,-4,NETHER_BRICK)
Block(-1,-8,-4,NETHER_BRICK)
Block(-1,-7,-4,NETHER_BRICK)
Block(2,-21,-3,NETHER_BRICK)
Block(-1,-6,-4,NETHER_BRICK)
Block(2,-22,-3,NETHER_BRICK)
Block(-1,-5,-4,NETHER_BRICK)
Block(2,-23,-3,NETHER_BRICK)
Block(-1,-4,-4,NETHER_BRICK)
Block(2,-24,-3,NETHER_BRICK)
Block(-1,-3,-4,NETHER_BRICK)
Block(2,-25,-3,NETHER_BRICK)
Block(-1,-2,-4,NETHER_BRICK)
Block(2,-26,-3,NETHER_BRICK)
Block(-1,-1,-4,NETHER_BRICK)
Block(2,-27,-3,NETHER_BRICK)
Block(2,-28,-3,NETHER_BRICK)
Block(1,-40,5,NETHER_BRICK)
Block(2,-31,-3,NETHER_BRICK)
Block(2,-30,-3,NETHER_BRICK)
Block(1,-43,5,NETHER_BRICK)
Block(1,-44,5,NETHER_BRICK)
Block(1,-41,5,NETHER_BRICK)
Block(1,-42,5,NETHER_BRICK)
Block(1,-47,5,NETHER_BRICK)
Block(1,-48,5,NETHER_BRICK)
Block(1,-45,5,NETHER_BRICK)
Block(1,-46,5,NETHER_BRICK)
Block(-4,-11,3,NETHER_BRICK)
Block(-4,-10,3,NETHER_BRICK)
Block(1,-16,-5,NETHER_BRICK)
Block(-4,-18,3,NETHER_BRICK)
Block(1,-15,-5,NETHER_BRICK)
Block(-4,-19,3,NETHER_BRICK)
Block(-4,-16,3,NETHER_BRICK)
Block(1,-18,-5,NETHER_BRICK)
Block(-4,-17,3,NETHER_BRICK)
Block(1,-17,-5,NETHER_BRICK)
Block(-4,-14,3,NETHER_BRICK)
Block(1,-97,5,NETHER_BRICK)
Block(-4,-15,3,NETHER_BRICK)
Block(1,-19,-5,NETHER_BRICK)
Block(1,-96,5,NETHER_BRICK)
Block(-4,-12,3,NETHER_BRICK)
Block(1,-99,5,NETHER_BRICK)
Block(-4,-13,3,NETHER_BRICK)
Block(1,-98,5,NETHER_BRICK)
Block(1,-93,5,NETHER_BRICK)
Block(1,-92,5,NETHER_BRICK)
Block(1,-10,-5,NETHER_BRICK)
Block(1,-95,5,NETHER_BRICK)
Block(1,-94,5,NETHER_BRICK)
Block(1,-12,-5,NETHER_BRICK)
Block(1,-11,-5,NETHER_BRICK)
Block(1,-14,-5,NETHER_BRICK)
Block(1,-91,5,NETHER_BRICK)
Block(1,-13,-5,NETHER_BRICK)
Block(1,-90,5,NETHER_BRICK)
Block(-4,-20,3,NETHER_BRICK)
Block(-4,-22,3,NETHER_BRICK)
Block(-4,-21,3,NETHER_BRICK)
Block(-4,-27,3,NETHER_BRICK)
Block(-4,-28,3,NETHER_BRICK)
Block(-4,-29,3,NETHER_BRICK)
Block(-4,-23,3,NETHER_BRICK)
Block(-4,-24,3,NETHER_BRICK)
Block(-4,-25,3,NETHER_BRICK)
Block(-4,-26,3,NETHER_BRICK)
Block(1,-75,5,NETHER_BRICK)
Block(1,-74,5,NETHER_BRICK)
Block(1,-77,5,NETHER_BRICK)
Block(1,-76,5,NETHER_BRICK)
Block(1,-79,5,NETHER_BRICK)
Block(1,-78,5,NETHER_BRICK)
Block(1,-71,5,NETHER_BRICK)
Block(1,-70,5,NETHER_BRICK)
Block(1,-73,5,NETHER_BRICK)
Block(1,-72,5,NETHER_BRICK)
Block(1,-88,5,NETHER_BRICK)
Block(1,-87,5,NETHER_BRICK)
Block(1,-86,5,NETHER_BRICK)
Block(1,-85,5,NETHER_BRICK)
Block(1,-89,5,NETHER_BRICK)
Block(1,-80,5,NETHER_BRICK)
Block(1,-84,5,NETHER_BRICK)
Block(1,-83,5,NETHER_BRICK)
Block(1,-82,5,NETHER_BRICK)
Block(1,-81,5,NETHER_BRICK)
Block(0,-132,5,NETHER_BRICK)
Block(0,-133,5,NETHER_BRICK)
Block(-1,44,-4,NETHER_BRICK_STAIRS:7)
Block(0,-110,4,NETHER_BRICK)
Block(0,-130,5,NETHER_BRICK)
Block(-1,45,-4,NETHER_BRICK)
Block(0,-131,5,NETHER_BRICK)
Block(-1,46,-4,NETHER_BRICK_STAIRS:2)
Block(-1,40,-4,STEP:6)
Block(0,-116,4,NETHER_BRICK)
Block(-2,-20,-5,NETHER_BRICK)
Block(0,-115,4,NETHER_BRICK)
Block(-4,-69,3,NETHER_BRICK)
Block(-2,-21,-5,NETHER_BRICK)
Block(0,-118,4,NETHER_BRICK)
Block(0,-138,5,NETHER_BRICK)
Block(-4,-68,3,NETHER_BRICK)
Block(0,-117,4,NETHER_BRICK)
Block(0,-139,5,NETHER_BRICK)
Block(-4,-67,3,NETHER_BRICK)
Block(0,-112,4,NETHER_BRICK)
Block(0,-136,5,NETHER_BRICK)
Block(0,-111,4,NETHER_BRICK)
Block(0,-137,5,NETHER_BRICK)
Block(-4,25,2,NETHER_BRICK_STAIRS)
Block(0,-114,4,NETHER_BRICK)
Block(0,-134,5,NETHER_BRICK)
Block(-4,24,2,NETHER_BRICK_STAIRS:5)
Block(0,-113,4,NETHER_BRICK)
Block(0,-135,5,NETHER_BRICK)
Block(-4,23,2,NETHER_BRICK_STAIRS:1)
Block(3,-147,3,NETHER_BRICK)
Block(-4,32,2,SOUL_SAND)
Block(-4,-61,3,NETHER_BRICK)
Block(-2,-29,-5,NETHER_BRICK)
Block(3,-146,3,NETHER_BRICK)
Block(-4,-62,3,NETHER_BRICK)
Block(-2,-28,-5,NETHER_BRICK)
Block(3,-149,3,NETHER_BRICK)
Block(-2,-27,-5,NETHER_BRICK)
Block(3,-148,3,NETHER_BRICK)
Block(-4,31,2,NETHER_BRICK_STAIRS:4)
Block(-4,-60,3,NETHER_BRICK)
Block(-2,-26,-5,NETHER_BRICK)
Block(0,-108,4,NETHER_BRICK)
Block(-4,-65,3,NETHER_BRICK)
Block(-2,-25,-5,NETHER_BRICK)
Block(0,-109,4,NETHER_BRICK)
Block(-4,-66,3,NETHER_BRICK)
Block(-2,-24,-5,NETHER_BRICK)
Block(-4,-63,3,NETHER_BRICK)
Block(-2,-23,-5,NETHER_BRICK)
Block(-4,-64,3,NETHER_BRICK)
Block(-2,-22,-5,NETHER_BRICK)
Block(3,-141,3,NETHER_BRICK)
Block(3,-140,3,NETHER_BRICK)
Block(3,-143,3,NETHER_BRICK)
Block(3,-142,3,NETHER_BRICK)
Block(3,-145,3,NETHER_BRICK)
Block(3,-144,3,NETHER_BRICK)
Block(0,-141,5,NETHER_BRICK)
Block(0,-142,5,NETHER_BRICK)
Block(0,-143,5,NETHER_BRICK)
Block(0,-144,5,NETHER_BRICK)
Block(0,-140,5,NETHER_BRICK)
Block(0,-107,4,NETHER_BRICK)
Block(0,-149,5,NETHER_BRICK)
Block(-4,-57,3,NETHER_BRICK)
Block(0,-106,4,NETHER_BRICK)
Block(-4,-56,3,NETHER_BRICK)
Block(-2,-30,-5,NETHER_BRICK)
Block(0,-105,4,NETHER_BRICK)
Block(-4,-59,3,NETHER_BRICK)
Block(-2,-31,-5,NETHER_BRICK)
Block(0,-104,4,NETHER_BRICK)
Block(-4,-58,3,NETHER_BRICK)
Block(-2,-32,-5,NETHER_BRICK)
Block(0,-103,4,NETHER_BRICK)
Block(0,-145,5,NETHER_BRICK)
Block(0,-102,4,NETHER_BRICK)
Block(0,-146,5,NETHER_BRICK)
Block(0,-101,4,NETHER_BRICK)
Block(0,-147,5,NETHER_BRICK)
Block(0,-148,5,NETHER_BRICK)
Block(0,-100,4,NETHER_BRICK)
Block(2,-102,-1,NETHER_BRICK)
Block(-1,-7,-5,NETHER_BRICK)
Block(-2,-38,-5,NETHER_BRICK)
Block(2,-103,-1,NETHER_BRICK)
Block(3,-159,3,NETHER_BRICK)
Block(-1,-8,-5,NETHER_BRICK)
Block(-2,-37,-5,NETHER_BRICK)
Block(2,-104,-1,NETHER_BRICK)
Block(3,-158,3,NETHER_BRICK)
Block(-1,-5,-5,NETHER_BRICK)
Block(-4,-50,3,NETHER_BRICK)
Block(2,-105,-1,NETHER_BRICK)
Block(3,-157,3,NETHER_BRICK)
Block(-1,-6,-5,NETHER_BRICK)
Block(-4,22,2,NETHER_BRICK_STAIRS:4)
Block(-4,-51,3,NETHER_BRICK)
Block(-2,-39,-5,NETHER_BRICK)
Block(-1,-3,-5,NETHER_BRICK)
Block(-4,-52,3,NETHER_BRICK)
Block(-2,-34,-5,NETHER_BRICK)
Block(-1,-4,-5,NETHER_BRICK)
Block(-4,-53,3,NETHER_BRICK)
Block(-2,-33,-5,NETHER_BRICK)
Block(2,-100,-1,NETHER_BRICK)
Block(-1,-1,-5,NETHER_BRICK)
Block(-4,-54,3,NETHER_BRICK)
Block(-2,-36,-5,NETHER_BRICK)
Block(2,-101,-1,NETHER_BRICK)
Block(-1,-2,-5,NETHER_BRICK)
Block(-4,-55,3,NETHER_BRICK)
Block(-2,-35,-5,NETHER_BRICK)
Block(3,-152,3,NETHER_BRICK)
Block(3,-151,3,NETHER_BRICK)
Block(3,-150,3,NETHER_BRICK)
Block(2,-106,-1,NETHER_BRICK)
Block(3,-156,3,NETHER_BRICK)
Block(2,-107,-1,NETHER_BRICK)
Block(3,-155,3,NETHER_BRICK)
Block(2,-108,-1,NETHER_BRICK)
Block(3,-154,3,NETHER_BRICK)
Block(-1,-9,-5,NETHER_BRICK)
Block(2,-109,-1,NETHER_BRICK)
Block(3,-153,3,NETHER_BRICK)
Block(0,-150,5,NETHER_BRICK)
Block(0,-151,5,NETHER_BRICK)
Block(0,-130,4,NETHER_BRICK)
Block(0,-154,5,NETHER_BRICK)
Block(1,-184,5,NETHER_BRICK)
Block(0,-155,5,NETHER_BRICK)
Block(1,-185,5,NETHER_BRICK)
Block(0,-132,4,NETHER_BRICK)
Block(0,-152,5,NETHER_BRICK)
Block(1,-182,5,NETHER_BRICK)
Block(0,-131,4,NETHER_BRICK)
Block(0,-153,5,NETHER_BRICK)
Block(1,-183,5,NETHER_BRICK)
Block(0,-134,4,NETHER_BRICK)
Block(0,-158,5,NETHER_BRICK)
Block(-3,25,4,NETHER_BRICK_STAIRS)
Block(0,-133,4,NETHER_BRICK)
Block(0,-159,5,NETHER_BRICK)
Block(-3,24,4,NETHER_BRICK_STAIRS:6)
Block(0,-136,4,NETHER_BRICK)
Block(0,-156,5,NETHER_BRICK)
Block(0,-135,4,NETHER_BRICK)
Block(0,-157,5,NETHER_BRICK)
Block(-4,-49,3,NETHER_BRICK)
Block(0,-138,4,NETHER_BRICK)
Block(-4,-48,3,NETHER_BRICK)
Block(-2,-42,-5,NETHER_BRICK)
Block(0,-137,4,NETHER_BRICK)
Block(-4,-47,3,NETHER_BRICK)
Block(-2,-43,-5,NETHER_BRICK)
Block(-4,-46,3,NETHER_BRICK)
Block(-2,-40,-5,NETHER_BRICK)
Block(0,-139,4,NETHER_BRICK)
Block(-4,-45,3,NETHER_BRICK)
Block(-2,-41,-5,NETHER_BRICK)
Block(2,-111,-1,NETHER_BRICK)
Block(-2,-47,-5,NETHER_BRICK)
Block(-4,-43,3,NETHER_BRICK)
Block(2,-112,-1,NETHER_BRICK)
Block(-2,-46,-5,NETHER_BRICK)
Block(-4,-44,3,NETHER_BRICK)
Block(-2,-45,-5,NETHER_BRICK)
Block(-4,-41,3,NETHER_BRICK)
Block(2,-110,-1,NETHER_BRICK)
Block(-2,-44,-5,NETHER_BRICK)
Block(-4,-42,3,NETHER_BRICK)
Block(2,-115,-1,NETHER_BRICK)
Block(3,-169,3,NETHER_BRICK)
Block(-3,31,4,NETHER_BRICK_STAIRS:4)
Block(2,-116,-1,NETHER_BRICK)
Block(3,-168,3,NETHER_BRICK)
Block(-3,32,4,SOUL_SAND)
Block(-4,-40,3,NETHER_BRICK)
Block(2,-113,-1,NETHER_BRICK)
Block(-2,-49,-5,NETHER_BRICK)
Block(2,-114,-1,NETHER_BRICK)
Block(-2,-48,-5,NETHER_BRICK)
Block(2,-119,-1,NETHER_BRICK)
Block(3,-165,3,NETHER_BRICK)
Block(1,-181,5,NETHER_BRICK)
Block(3,-164,3,NETHER_BRICK)
Block(1,-180,5,NETHER_BRICK)
Block(2,-117,-1,NETHER_BRICK)
Block(3,-167,3,NETHER_BRICK)
Block(2,-118,-1,NETHER_BRICK)
Block(3,-166,3,NETHER_BRICK)
Block(3,-161,3,NETHER_BRICK)
Block(3,-160,3,NETHER_BRICK)
Block(3,-163,3,NETHER_BRICK)
Block(3,-162,3,NETHER_BRICK)
Block(-2,-3,1,NETHER_BRICK)
Block(0,-160,5,NETHER_BRICK)
Block(3,-170,3,NETHER_BRICK)
Block(-2,-4,1,NETHER_BRICK)
Block(0,-161,5,NETHER_BRICK)
Block(-2,-5,1,NETHER_BRICK)
Block(0,-162,5,NETHER_BRICK)
Block(-2,-6,1,NETHER_BRICK)
Block(0,-121,4,NETHER_BRICK)
Block(0,-163,5,NETHER_BRICK)
Block(-2,-7,1,NETHER_BRICK)
Block(0,-120,4,NETHER_BRICK)
Block(0,-164,5,NETHER_BRICK)
Block(-2,-8,1,NETHER_BRICK)
Block(0,-165,5,NETHER_BRICK)
Block(-2,-9,1,NETHER_BRICK)
Block(0,-166,5,NETHER_BRICK)
Block(0,-125,4,NETHER_BRICK)
Block(0,-167,5,NETHER_BRICK)
Block(-3,38,4,NETHER_BRICK)
Block(-4,-39,3,NETHER_BRICK)
Block(0,-124,4,NETHER_BRICK)
Block(0,-168,5,NETHER_BRICK)
Block(-4,-38,3,NETHER_BRICK)
Block(0,-123,4,NETHER_BRICK)
Block(0,-169,5,NETHER_BRICK)
Block(0,-122,4,NETHER_BRICK)
Block(-2,-50,-5,NETHER_BRICK)
Block(0,-129,4,NETHER_BRICK)
Block(-2,-51,-5,NETHER_BRICK)
Block(-4,-35,3,NETHER_BRICK)
Block(0,-128,4,NETHER_BRICK)
Block(-2,-52,-5,NETHER_BRICK)
Block(-4,-34,3,NETHER_BRICK)
Block(0,-127,4,NETHER_BRICK)
Block(-2,-1,1,NETHER_BRICK)
Block(-2,-53,-5,NETHER_BRICK)
Block(-4,-37,3,NETHER_BRICK)
Block(0,-126,4,NETHER_BRICK)
Block(-2,-2,1,NETHER_BRICK)
Block(-3,39,4,NETHER_BRICK)
Block(-2,-54,-5,NETHER_BRICK)
Block(-4,-36,3,NETHER_BRICK)
Block(2,-120,-1,NETHER_BRICK)
Block(-3,40,4,STEP:6)
Block(-2,-56,-5,NETHER_BRICK)
Block(-4,-30,3,NETHER_BRICK)
Block(2,-121,-1,NETHER_BRICK)
Block(-2,-55,-5,NETHER_BRICK)
Block(-4,-31,3,NETHER_BRICK)
Block(0,-119,4,NETHER_BRICK)
Block(2,-122,-1,NETHER_BRICK)
Block(-2,-58,-5,NETHER_BRICK)
Block(-4,-32,3,NETHER_BRICK)
Block(2,-123,-1,NETHER_BRICK)
Block(-2,-57,-5,NETHER_BRICK)
Block(-4,-33,3,NETHER_BRICK)
Block(2,-124,-1,NETHER_BRICK)
Block(2,-125,-1,NETHER_BRICK)
Block(-2,-59,-5,NETHER_BRICK)
Block(2,-126,-1,NETHER_BRICK)
Block(2,-127,-1,NETHER_BRICK)
Block(3,-179,3,NETHER_BRICK)
Block(2,-128,-1,NETHER_BRICK)
Block(3,-178,3,NETHER_BRICK)
Block(2,-129,-1,NETHER_BRICK)
Block(3,-177,3,NETHER_BRICK)
Block(3,-176,3,NETHER_BRICK)
Block(3,-175,3,NETHER_BRICK)
Block(3,-174,3,NETHER_BRICK)
Block(3,-173,3,NETHER_BRICK)
Block(3,-172,3,NETHER_BRICK)
Block(3,-171,3,NETHER_BRICK)
Block(0,-159,4,NETHER_BRICK)
Block(-2,-65,-5,NETHER_BRICK)
Block(2,-130,-1,NETHER_BRICK)
Block(-2,-64,-5,NETHER_BRICK)
Block(1,-169,5,NETHER_BRICK)
Block(-2,-63,-5,NETHER_BRICK)
Block(1,-168,5,NETHER_BRICK)
Block(-2,-62,-5,NETHER_BRICK)
Block(0,-155,4,NETHER_BRICK)
Block(7,32,1,NETHER_BRICK)
Block(-2,-61,-5,NETHER_BRICK)
Block(0,-156,4,NETHER_BRICK)
Block(7,31,1,STEP:14)
Block(-2,-60,-5,NETHER_BRICK)
Block(0,-157,4,NETHER_BRICK)
Block(0,-179,5,NETHER_BRICK)
Block(0,-158,4,NETHER_BRICK)
Block(0,-178,5,NETHER_BRICK)
Block(0,-151,4,NETHER_BRICK)
Block(1,-163,5,NETHER_BRICK)
Block(0,-177,5,NETHER_BRICK)
Block(0,-152,4,NETHER_BRICK)
Block(1,-162,5,NETHER_BRICK)
Block(0,-176,5,NETHER_BRICK)
Block(0,-153,4,NETHER_BRICK)
Block(1,-161,5,NETHER_BRICK)
Block(0,-175,5,NETHER_BRICK)
Block(0,-154,4,NETHER_BRICK)
Block(1,-160,5,NETHER_BRICK)
Block(0,-174,5,NETHER_BRICK)
Block(1,-167,5,NETHER_BRICK)
Block(0,-173,5,NETHER_BRICK)
Block(1,-166,5,NETHER_BRICK)
Block(0,-172,5,NETHER_BRICK)
Block(1,-165,5,NETHER_BRICK)
Block(0,-171,5,NETHER_BRICK)
Block(0,-150,4,NETHER_BRICK)
Block(1,-164,5,NETHER_BRICK)
Block(0,-170,5,NETHER_BRICK)
Block(2,-130,2,NETHER_BRICK)
Block(2,-132,2,NETHER_BRICK)
Block(3,-100,3,NETHER_BRICK)
Block(3,-101,3,NETHER_BRICK)
Block(2,-131,2,NETHER_BRICK)
Block(2,-139,-1,NETHER_BRICK)
Block(3,-102,3,NETHER_BRICK)
Block(2,-134,2,NETHER_BRICK)
Block(2,-138,-1,NETHER_BRICK)
Block(7,35,1,NETHER_BRICK)
Block(3,-103,3,NETHER_BRICK)
Block(2,-133,2,NETHER_BRICK)
Block(2,-137,-1,NETHER_BRICK)
Block(7,36,1,NETHER_BRICK)
Block(3,-104,3,NETHER_BRICK)
Block(2,-136,2,NETHER_BRICK)
Block(2,-136,-1,NETHER_BRICK)
Block(7,33,1,NETHER_BRICK)
Block(3,-105,3,NETHER_BRICK)
Block(2,-135,2,NETHER_BRICK)
Block(2,-135,-1,NETHER_BRICK)
Block(7,34,1,NETHER_BRICK)
Block(3,-106,3,NETHER_BRICK)
Block(2,-134,-1,NETHER_BRICK)
Block(2,-138,2,NETHER_BRICK)
Block(7,39,1,NETHER_BRICK)
Block(-2,-68,-5,NETHER_BRICK)
Block(3,-107,3,NETHER_BRICK)
Block(2,-133,-1,NETHER_BRICK)
Block(2,-137,2,NETHER_BRICK)
Block(-2,-69,-5,NETHER_BRICK)
Block(3,-108,3,NETHER_BRICK)
Block(2,-132,-1,NETHER_BRICK)
Block(7,37,1,NETHER_BRICK)
Block(-2,-66,-5,NETHER_BRICK)
Block(3,-109,3,NETHER_BRICK)
Block(2,-131,-1,NETHER_BRICK)
Block(2,-139,2,NETHER_BRICK)
Block(7,38,1,NETHER_BRICK)
Block(-2,-67,-5,NETHER_BRICK)
Block(-4,-2,2,NETHER_BRICK)
Block(-1,24,-5,STEP:6)
Block(-2,-74,-5,NETHER_BRICK)
Block(1,-179,5,NETHER_BRICK)
Block(-4,-3,2,NETHER_BRICK)
Block(-2,-73,-5,NETHER_BRICK)
Block(2,-119,2,NETHER_BRICK)
Block(2,-140,-1,NETHER_BRICK)
Block(0,-148,4,NETHER_BRICK)
Block(-4,-4,2,NETHER_BRICK)
Block(-2,-76,-5,NETHER_BRICK)
Block(2,-141,-1,NETHER_BRICK)
Block(0,-149,4,NETHER_BRICK)
Block(-4,-5,2,NETHER_BRICK)
Block(-2,-75,-5,NETHER_BRICK)
Block(0,-146,4,NETHER_BRICK)
Block(-2,-70,-5,NETHER_BRICK)
Block(0,-147,4,NETHER_BRICK)
Block(7,40,1,STEP:6)
Block(0,-144,4,NETHER_BRICK)
Block(-2,-72,-5,NETHER_BRICK)
Block(0,-145,4,NETHER_BRICK)
Block(-4,-1,2,NETHER_BRICK)
Block(-2,-71,-5,NETHER_BRICK)
Block(0,-142,4,NETHER_BRICK)
Block(1,-172,5,NETHER_BRICK)
Block(-2,-183,-5,NETHER_BRICK)
Block(0,-143,4,NETHER_BRICK)
Block(1,-171,5,NETHER_BRICK)
Block(-2,-184,-5,NETHER_BRICK)
Block(0,-185,5,NETHER_BRICK)
Block(-1,12,-4,NETHER_BRICK_STAIRS:3)
Block(0,-140,4,NETHER_BRICK)
Block(1,-174,5,NETHER_BRICK)
Block(-2,-185,-5,NETHER_BRICK)
Block(-1,11,-4,NETHER_BRICK)
Block(0,-141,4,NETHER_BRICK)
Block(1,-173,5,NETHER_BRICK)
Block(-1,10,-4,NETHER_BRICK)
Block(1,-176,5,NETHER_BRICK)
Block(0,-182,5,NETHER_BRICK)
Block(-4,-6,2,NETHER_BRICK)
Block(1,-175,5,NETHER_BRICK)
Block(-2,-180,-5,NETHER_BRICK)
Block(0,-181,5,NETHER_BRICK)
Block(-4,-7,2,NETHER_BRICK)
Block(1,-178,5,NETHER_BRICK)
Block(-2,-181,-5,NETHER_BRICK)
Block(0,-184,5,NETHER_BRICK)
Block(-4,-8,2,NETHER_BRICK)
Block(1,-177,5,NETHER_BRICK)
Block(-2,-182,-5,NETHER_BRICK)
Block(0,-183,5,NETHER_BRICK)
Block(-4,-9,2,NETHER_BRICK)
Block(0,-180,5,NETHER_BRICK)
Block(3,-111,3,NETHER_BRICK)
Block(2,-121,2,NETHER_BRICK)
Block(-2,-177,-5,NETHER_BRICK)
Block(3,-112,3,NETHER_BRICK)
Block(2,-120,2,NETHER_BRICK)
Block(-2,-176,-5,NETHER_BRICK)
Block(-2,-179,-5,NETHER_BRICK)
Block(-4,-91,3,NETHER_BRICK)
Block(3,-110,3,NETHER_BRICK)
Block(1,-170,5,NETHER_BRICK)
Block(-2,-178,-5,NETHER_BRICK)
Block(-4,-90,3,NETHER_BRICK)
Block(3,-115,3,NETHER_BRICK)
Block(2,-125,2,NETHER_BRICK)
Block(2,-147,-1,NETHER_BRICK)
Block(-4,-93,3,NETHER_BRICK)
Block(3,-116,3,NETHER_BRICK)
Block(2,-124,2,NETHER_BRICK)
Block(2,-146,-1,NETHER_BRICK)
Block(-4,-92,3,NETHER_BRICK)
Block(3,-113,3,NETHER_BRICK)
Block(2,-123,2,NETHER_BRICK)
Block(2,-149,-1,NETHER_BRICK)
Block(-4,-95,3,NETHER_BRICK)
Block(3,-114,3,NETHER_BRICK)
Block(2,-122,2,NETHER_BRICK)
Block(2,-148,-1,NETHER_BRICK)
Block(-4,-94,3,NETHER_BRICK)
Block(3,-119,3,NETHER_BRICK)
Block(2,-129,2,NETHER_BRICK)
Block(2,-143,-1,NETHER_BRICK)
Block(-2,-77,-5,NETHER_BRICK)
Block(-4,-97,3,NETHER_BRICK)
Block(5,39,6,STEP:6)
Block(2,-128,2,NETHER_BRICK)
Block(2,-142,-1,NETHER_BRICK)
Block(-2,-78,-5,NETHER_BRICK)
Block(-4,-96,3,NETHER_BRICK)
Block(5,38,6,NETHER_BRICK)
Block(3,-117,3,NETHER_BRICK)
Block(2,-127,2,NETHER_BRICK)
Block(2,-145,-1,NETHER_BRICK)
Block(-2,-79,-5,NETHER_BRICK)
Block(-4,-99,3,NETHER_BRICK)
Block(3,-118,3,NETHER_BRICK)
Block(2,-126,2,NETHER_BRICK)
Block(2,-144,-1,NETHER_BRICK)
Block(-4,-98,3,NETHER_BRICK)
Block(0,-177,4,NETHER_BRICK)
Block(-2,-83,-5,NETHER_BRICK)
Block(0,-178,4,NETHER_BRICK)
Block(-2,-82,-5,NETHER_BRICK)
Block(0,-179,4,NETHER_BRICK)
Block(-2,-81,-5,NETHER_BRICK)
Block(-1,31,-5,STEP:14)
Block(-2,-80,-5,NETHER_BRICK)
Block(-1,32,-5,SOUL_SAND)
Block(2,-108,2,NETHER_BRICK)
Block(1,-149,5,NETHER_BRICK)
Block(2,-151,-1,NETHER_BRICK)
Block(-2,-87,-5,NETHER_BRICK)
Block(2,-109,2,NETHER_BRICK)
Block(1,-148,5,NETHER_BRICK)
Block(2,-152,-1,NETHER_BRICK)
Block(-2,-86,-5,NETHER_BRICK)
Block(1,-147,5,NETHER_BRICK)
Block(-2,-85,-5,NETHER_BRICK)
Block(-4,-89,3,NETHER_BRICK)
Block(1,-146,5,NETHER_BRICK)
Block(2,-150,-1,NETHER_BRICK)
Block(-2,-84,-5,NETHER_BRICK)
Block(1,-145,5,NETHER_BRICK)
Block(1,-144,5,NETHER_BRICK)
Block(0,-170,4,NETHER_BRICK)
Block(1,-143,5,NETHER_BRICK)
Block(0,-171,4,NETHER_BRICK)
Block(1,-142,5,NETHER_BRICK)
Block(0,-172,4,NETHER_BRICK)
Block(1,-141,5,NETHER_BRICK)
Block(0,-173,4,NETHER_BRICK)
Block(5,32,5,NETHER_BRICK)
Block(1,-140,5,NETHER_BRICK)
Block(0,-174,4,NETHER_BRICK)
Block(0,-175,4,NETHER_BRICK)
Block(-1,24,-4,NETHER_BRICK_STAIRS:7)
Block(0,-176,4,NETHER_BRICK)
Block(-1,23,-4,STEP:6)
Block(3,-120,3,NETHER_BRICK)
Block(-4,-80,3,NETHER_BRICK)
Block(3,-121,3,NETHER_BRICK)
Block(2,-110,2,NETHER_BRICK)
Block(3,-122,3,NETHER_BRICK)
Block(3,-123,3,NETHER_BRICK)
Block(5,38,5,NETHER_BRICK)
Block(5,39,5,NETHER_BRICK)
Block(2,-116,2,NETHER_BRICK)
Block(3,-128,3,NETHER_BRICK)
Block(2,-156,-1,NETHER_BRICK)
Block(-4,-88,3,NETHER_BRICK)
Block(2,-115,2,NETHER_BRICK)
Block(3,-129,3,NETHER_BRICK)
Block(2,-155,-1,NETHER_BRICK)
Block(-4,-87,3,NETHER_BRICK)
Block(2,-118,2,NETHER_BRICK)
Block(2,-154,-1,NETHER_BRICK)
Block(-4,-86,3,NETHER_BRICK)
Block(-2,-88,-5,NETHER_BRICK)
Block(2,-117,2,NETHER_BRICK)
Block(2,-153,-1,NETHER_BRICK)
Block(-4,-85,3,NETHER_BRICK)
Block(-2,-89,-5,NETHER_BRICK)
Block(2,-112,2,NETHER_BRICK)
Block(3,-124,3,NETHER_BRICK)
Block(-4,-84,3,NETHER_BRICK)
Block(2,-111,2,NETHER_BRICK)
Block(3,-125,3,NETHER_BRICK)
Block(2,-159,-1,NETHER_BRICK)
Block(-4,-83,3,NETHER_BRICK)
Block(2,-114,2,NETHER_BRICK)
Block(3,-126,3,NETHER_BRICK)
Block(2,-158,-1,NETHER_BRICK)
Block(-4,-82,3,NETHER_BRICK)
Block(2,-113,2,NETHER_BRICK)
Block(3,-127,3,NETHER_BRICK)
Block(2,-157,-1,NETHER_BRICK)
Block(-4,-81,3,NETHER_BRICK)
Block(0,-168,4,NETHER_BRICK)
Block(-2,-92,-5,NETHER_BRICK)
Block(-1,42,-5,NETHER_BRICK_STAIRS:7)
Block(0,-169,4,NETHER_BRICK)
Block(-2,-91,-5,NETHER_BRICK)
Block(-1,43,-5,NETHER_BRICK)
Block(0,-166,4,NETHER_BRICK)
Block(-2,-94,-5,NETHER_BRICK)
Block(-1,40,-5,STEP:6)
Block(0,-167,4,NETHER_BRICK)
Block(-2,-93,-5,NETHER_BRICK)
Block(1,-158,5,NETHER_BRICK)
Block(2,-160,-1,NETHER_BRICK)
Block(-4,-78,3,NETHER_BRICK)
Block(-2,-96,-5,NETHER_BRICK)
Block(1,-157,5,NETHER_BRICK)
Block(2,-161,-1,NETHER_BRICK)
Block(-4,-79,3,NETHER_BRICK)
Block(-2,-95,-5,NETHER_BRICK)
Block(2,-162,-1,NETHER_BRICK)
Block(-2,-98,-5,NETHER_BRICK)
Block(-1,44,-5,NETHER_BRICK_STAIRS:2)
Block(1,-159,5,NETHER_BRICK)
Block(2,-163,-1,NETHER_BRICK)
Block(-2,-97,-5,NETHER_BRICK)
Block(1,-154,5,NETHER_BRICK)
Block(0,-160,4,NETHER_BRICK)
Block(-1,31,-4,NETHER_BRICK_STAIRS:6)
Block(1,-153,5,NETHER_BRICK)
Block(0,-161,4,NETHER_BRICK)
Block(1,-156,5,NETHER_BRICK)
Block(1,-155,5,NETHER_BRICK)
Block(1,-150,5,NETHER_BRICK)
Block(0,-164,4,NETHER_BRICK)
Block(0,-165,4,NETHER_BRICK)
Block(1,-152,5,NETHER_BRICK)
Block(0,-162,4,NETHER_BRICK)
Block(-2,-90,-5,NETHER_BRICK)
Block(1,-151,5,NETHER_BRICK)
Block(0,-163,4,NETHER_BRICK)
Block(-1,32,-4,SOUL_SAND)
Block(3,-133,3,NETHER_BRICK)
Block(3,-134,3,NETHER_BRICK)
Block(3,-131,3,NETHER_BRICK)
Block(-1,25,-4,NETHER_BRICK_STAIRS:2)
Block(3,-132,3,NETHER_BRICK)
Block(3,-130,3,NETHER_BRICK)
Block(2,-107,2,NETHER_BRICK)
Block(2,-165,-1,NETHER_BRICK)
Block(-2,-99,-5,NETHER_BRICK)
Block(-4,-75,3,NETHER_BRICK)
Block(2,-106,2,NETHER_BRICK)
Block(2,-164,-1,NETHER_BRICK)
Block(-1,39,-5,NETHER_FENCE)
Block(-4,-74,3,NETHER_BRICK)
Block(2,-105,2,NETHER_BRICK)
Block(3,-139,3,NETHER_BRICK)
Block(2,-167,-1,NETHER_BRICK)
Block(-1,38,-5,NETHER_FENCE)
Block(-4,-77,3,NETHER_BRICK)
Block(2,-104,2,NETHER_BRICK)
Block(2,-166,-1,NETHER_BRICK)
Block(-4,-76,3,NETHER_BRICK)
Block(2,-103,2,NETHER_BRICK)
Block(3,-137,3,NETHER_BRICK)
Block(2,-169,-1,NETHER_BRICK)
Block(-4,-71,3,NETHER_BRICK)
Block(2,-102,2,NETHER_BRICK)
Block(3,-138,3,NETHER_BRICK)
Block(2,-168,-1,NETHER_BRICK)
Block(-4,-70,3,NETHER_BRICK)
Block(2,-101,2,NETHER_BRICK)
Block(3,-135,3,NETHER_BRICK)
Block(-4,-73,3,NETHER_BRICK)
Block(3,-136,3,NETHER_BRICK)
Block(2,-100,2,NETHER_BRICK)
Block(-4,-72,3,NETHER_BRICK)
Block(2,-179,2,NETHER_BRICK)
Block(2,-179,-1,NETHER_BRICK)
Block(2,-177,2,NETHER_BRICK)
Block(2,-178,2,NETHER_BRICK)
Block(2,-175,-1,NETHER_BRICK)
Block(2,-176,-1,NETHER_BRICK)
Block(2,-177,-1,NETHER_BRICK)
Block(2,-178,-1,NETHER_BRICK)
Block(2,-171,2,NETHER_BRICK)
Block(2,-18,5,NETHER_BRICK)
Block(2,-172,2,NETHER_BRICK)
Block(2,-17,5,NETHER_BRICK)
Block(2,-16,5,NETHER_BRICK)
Block(2,-170,2,NETHER_BRICK)
Block(2,-15,5,NETHER_BRICK)
Block(2,-175,2,NETHER_BRICK)
Block(2,-176,2,NETHER_BRICK)
Block(2,-173,2,NETHER_BRICK)
Block(2,-174,2,NETHER_BRICK)
Block(2,-19,5,NETHER_BRICK)
Block(2,-20,5,NETHER_BRICK)
Block(2,-21,5,NETHER_BRICK)
Block(2,-24,5,NETHER_BRICK)
Block(2,-25,5,NETHER_BRICK)
Block(2,-22,5,NETHER_BRICK)
Block(2,-23,5,NETHER_BRICK)
Block(2,-172,-1,NETHER_BRICK)
Block(2,-171,-1,NETHER_BRICK)
Block(2,-174,-1,NETHER_BRICK)
Block(2,-173,-1,NETHER_BRICK)
Block(2,-170,-1,NETHER_BRICK)
Block(2,-166,2,NETHER_BRICK)
Block(2,-167,2,NETHER_BRICK)
Block(2,-168,2,NETHER_BRICK)
Block(2,-169,2,NETHER_BRICK)
Block(2,-160,2,NETHER_BRICK)
Block(2,-161,2,NETHER_BRICK)
Block(2,-162,2,NETHER_BRICK)
Block(2,-163,2,NETHER_BRICK)
Block(2,-164,2,NETHER_BRICK)
Block(2,-165,2,NETHER_BRICK)
Block(0,-185,4,NETHER_BRICK)
Block(0,-184,4,NETHER_BRICK)
Block(2,-10,5,NETHER_BRICK)
Block(0,-181,4,NETHER_BRICK)
Block(-3,-8,4,NETHER_BRICK)
Block(2,-11,5,NETHER_BRICK)
Block(0,-180,4,NETHER_BRICK)
Block(-3,-7,4,NETHER_BRICK)
Block(2,-12,5,NETHER_BRICK)
Block(0,-183,4,NETHER_BRICK)
Block(2,-13,5,NETHER_BRICK)
Block(0,-182,4,NETHER_BRICK)
Block(-3,-9,4,NETHER_BRICK)
Block(2,-14,5,NETHER_BRICK)
Block(2,-185,-1,NETHER_BRICK)
Block(-3,-4,4,NETHER_BRICK)
Block(2,-184,-1,NETHER_BRICK)
Block(-3,-3,4,NETHER_BRICK)
Block(2,-183,-1,NETHER_BRICK)
Block(-3,-6,4,NETHER_BRICK)
Block(2,-182,-1,NETHER_BRICK)
Block(-3,-5,4,NETHER_BRICK)
Block(2,-181,-1,NETHER_BRICK)
Block(2,-180,-1,NETHER_BRICK)
Block(-3,-2,4,NETHER_BRICK)
Block(-3,-1,4,NETHER_BRICK)
Block(2,-159,2,NETHER_BRICK)
Block(2,-157,2,NETHER_BRICK)
Block(-2,50,1,NETHER_BRICK)
Block(2,-158,2,NETHER_BRICK)
Block(2,-155,2,NETHER_BRICK)
Block(-2,52,1,NETHER_BRICK)
Block(2,-156,2,NETHER_BRICK)
Block(-2,51,1,NETHER_BRICK)
Block(2,-153,2,NETHER_BRICK)
Block(2,-154,2,NETHER_BRICK)
Block(2,-151,2,NETHER_BRICK)
Block(2,-152,2,NETHER_BRICK)
Block(2,-150,2,NETHER_BRICK)
Block(2,-39,5,NETHER_BRICK)
Block(2,-38,5,NETHER_BRICK)
Block(2,-37,5,NETHER_BRICK)
Block(2,-46,5,NETHER_BRICK)
Block(2,-47,5,NETHER_BRICK)
Block(2,-44,5,NETHER_BRICK)
Block(2,-45,5,NETHER_BRICK)
Block(2,-42,5,NETHER_BRICK)
Block(2,-43,5,NETHER_BRICK)
Block(2,-40,5,NETHER_BRICK)
Block(2,-41,5,NETHER_BRICK)
Block(-2,46,1,NETHER_BRICK)
Block(-2,47,1,NETHER_BRICK)
Block(-2,48,1,NETHER_BRICK)
Block(-2,49,1,NETHER_BRICK)
Block(2,-148,2,NETHER_BRICK)
Block(2,-149,2,NETHER_BRICK)
Block(2,-144,2,NETHER_BRICK)
Block(2,-145,2,NETHER_BRICK)
Block(2,-146,2,NETHER_BRICK)
Block(2,-147,2,NETHER_BRICK)
Block(2,-140,2,NETHER_BRICK)
Block(2,-141,2,NETHER_BRICK)
Block(2,-142,2,NETHER_BRICK)
Block(2,-143,2,NETHER_BRICK)
Block(2,-27,5,NETHER_BRICK)
Block(2,-26,5,NETHER_BRICK)
Block(2,-29,5,NETHER_BRICK)
Block(2,-28,5,NETHER_BRICK)
Block(2,-33,5,NETHER_BRICK)
Block(2,-34,5,NETHER_BRICK)
Block(2,-35,5,NETHER_BRICK)
Block(2,-36,5,NETHER_BRICK)
Block(2,-30,5,NETHER_BRICK)
Block(2,-31,5,NETHER_BRICK)
Block(2,-32,5,NETHER_BRICK)
Block(-2,55,1,NETHER_BRICK_STAIRS)
Block(-2,53,1,NETHER_BRICK)
Block(-2,54,1,NETHER_BRICK)
Block(3,-184,3,NETHER_BRICK)
Block(3,-185,3,NETHER_BRICK)
Block(3,-182,3,NETHER_BRICK)
Block(2,-59,5,NETHER_BRICK)
Block(3,-183,3,NETHER_BRICK)
Block(-2,30,1,NETHER_BRICK)
Block(-2,25,1,NETHER_BRICK)
Block(0,50,2,NETHER_FENCE)
Block(-2,24,1,NETHER_BRICK)
Block(0,51,2,NETHER_FENCE)
Block(-2,27,1,NETHER_BRICK)
Block(0,52,2,NETHER_BRICK)
Block(-2,26,1,NETHER_BRICK)
Block(-2,21,1,NETHER_BRICK)
Block(2,-61,5,NETHER_BRICK)
Block(0,54,2,STEP:14)
Block(-2,20,1,NETHER_BRICK)
Block(2,-60,5,NETHER_BRICK)
Block(0,55,2,NETHER_BRICK_STAIRS:3)
Block(-2,23,1,NETHER_BRICK)
Block(-2,22,1,NETHER_BRICK)
Block(2,-65,5,NETHER_BRICK)
Block(2,-64,5,NETHER_BRICK)
Block(2,-63,5,NETHER_BRICK)
Block(2,-62,5,NETHER_BRICK)
Block(3,-181,3,NETHER_BRICK)
Block(-2,29,1,NETHER_BRICK)
Block(2,-69,5,NETHER_BRICK)
Block(3,-180,3,NETHER_BRICK)
Block(-2,28,1,NETHER_BRICK)
Block(2,-68,5,NETHER_BRICK)
Block(2,-67,5,NETHER_BRICK)
Block(2,-66,5,NETHER_BRICK)
Block(2,-48,5,NETHER_BRICK)
Block(2,-49,5,NETHER_BRICK)
Block(-2,40,1,NETHER_BRICK)
Block(0,-108,5,NETHER_BRICK)
Block(-2,38,1,NETHER_BRICK)
Block(0,-107,5,NETHER_BRICK)
Block(-2,37,1,NETHER_BRICK)
Block(0,-106,5,NETHER_BRICK)
Block(-2,36,1,NETHER_BRICK)
Block(0,-105,5,NETHER_BRICK)
Block(-2,35,1,NETHER_BRICK)
Block(0,-104,5,NETHER_BRICK)
Block(-2,34,1,NETHER_BRICK)
Block(0,-103,5,NETHER_BRICK)
Block(-2,33,1,NETHER_BRICK)
Block(0,-102,5,NETHER_BRICK)
Block(-2,32,1,NETHER_BRICK)
Block(2,-50,5,NETHER_BRICK)
Block(0,-101,5,NETHER_BRICK)
Block(-2,31,1,NETHER_BRICK)
Block(0,-100,5,NETHER_BRICK)
Block(2,-52,5,NETHER_BRICK)
Block(2,-51,5,NETHER_BRICK)
Block(2,-54,5,NETHER_BRICK)
Block(2,-53,5,NETHER_BRICK)
Block(2,-56,5,NETHER_BRICK)
Block(2,-55,5,NETHER_BRICK)
Block(2,-58,5,NETHER_BRICK)
Block(-2,39,1,NETHER_BRICK)
Block(2,-57,5,NETHER_BRICK)
Block(0,-109,5,NETHER_BRICK)
Block(0,-113,5,NETHER_BRICK)
Block(2,-83,5,NETHER_BRICK)
Block(-4,45,2,NETHER_FENCE)
Block(0,31,2,NETHER_BRICK)
Block(0,-112,5,NETHER_BRICK)
Block(2,-82,5,NETHER_BRICK)
Block(-4,46,2,NETHER_BRICK_STAIRS:3)
Block(0,32,2,NETHER_BRICK)
Block(0,-115,5,NETHER_BRICK)
Block(2,-81,5,NETHER_BRICK)
Block(0,-114,5,NETHER_BRICK)
Block(2,-80,5,NETHER_BRICK)
Block(0,-117,5,NETHER_BRICK)
Block(0,-116,5,NETHER_BRICK)
Block(0,-119,5,NETHER_BRICK)
Block(0,-118,5,NETHER_BRICK)
Block(0,30,2,NETHER_BRICK)
Block(0,39,2,NETHER_BRICK)
Block(2,-89,5,NETHER_BRICK)
Block(2,-88,5,NETHER_BRICK)
Block(2,-87,5,NETHER_BRICK)
Block(0,35,2,NETHER_BRICK)
Block(2,-86,5,NETHER_BRICK)
Block(0,36,2,NETHER_BRICK)
Block(0,-111,5,NETHER_BRICK)
Block(2,-85,5,NETHER_BRICK)
Block(0,37,2,NETHER_BRICK)
Block(0,-110,5,NETHER_BRICK)
Block(2,-84,5,NETHER_BRICK)
Block(0,38,2,NETHER_BRICK)
Block(2,-185,2,NETHER_BRICK)
Block(2,-184,2,NETHER_BRICK)
Block(-2,-19,-5,NETHER_BRICK)
Block(2,-181,2,NETHER_BRICK)
Block(2,-180,2,NETHER_BRICK)
Block(2,-183,2,NETHER_BRICK)
Block(2,-182,2,NETHER_BRICK)
Block(-2,-13,-5,NETHER_BRICK)
Block(-4,40,2,STEP:6)
Block(-2,-14,-5,NETHER_BRICK)
Block(-2,-11,-5,NETHER_BRICK)
Block(-2,-12,-5,NETHER_BRICK)
Block(-2,-17,-5,NETHER_BRICK)
Block(-2,-18,-5,NETHER_BRICK)
Block(-2,-15,-5,NETHER_BRICK)
Block(-2,-16,-5,NETHER_BRICK)
Block(0,-126,5,NETHER_BRICK)
Block(-2,12,1,NETHER_BRICK)
Block(2,-70,5,NETHER_BRICK)
Block(0,-125,5,NETHER_BRICK)
Block(-2,11,1,NETHER_BRICK)
Block(0,-124,5,NETHER_BRICK)
Block(-2,10,1,NETHER_BRICK)
Block(2,-72,5,NETHER_BRICK)
Block(0,-123,5,NETHER_BRICK)
Block(2,-71,5,NETHER_BRICK)
Block(-2,-10,-5,NETHER_BRICK)
Block(0,40,2,NETHER_BRICK)
Block(-2,16,1,NETHER_BRICK)
Block(0,-129,5,NETHER_BRICK)
Block(-2,15,1,NETHER_BRICK)
Block(0,-128,5,NETHER_BRICK)
Block(-2,14,1,NETHER_BRICK)
Block(-4,38,2,NETHER_FENCE)
Block(0,-127,5,NETHER_BRICK)
Block(-2,13,1,NETHER_BRICK)
Block(-4,39,2,NETHER_FENCE)
Block(2,-78,5,NETHER_BRICK)
Block(-2,19,1,NETHER_BRICK)
Block(2,-77,5,NETHER_BRICK)
Block(-2,18,1,NETHER_BRICK)
Block(2,-79,5,NETHER_BRICK)
Block(-2,17,1,NETHER_BRICK)
Block(0,-122,5,NETHER_BRICK)
Block(0,48,2,NETHER_BRICK)
Block(2,-74,5,NETHER_BRICK)
Block(0,-121,5,NETHER_BRICK)
Block(0,49,2,NETHER_BRICK)
Block(2,-73,5,NETHER_BRICK)
Block(0,-120,5,NETHER_BRICK)
Block(0,46,2,NETHER_BRICK)
Block(2,-76,5,NETHER_BRICK)
Block(0,47,2,NETHER_BRICK)
Block(2,-75,5,NETHER_BRICK)
Block(2,7,3,NETHER_BRICK)
Block(2,8,3,NETHER_BRICK)
Block(2,9,3,NETHER_BRICK)
Block(2,3,3,NETHER_BRICK)
Block(2,4,3,NETHER_BRICK)
Block(2,5,3,NETHER_BRICK)
Block(2,6,3,NETHER_BRICK)
Block(2,-133,-2,NETHER_BRICK)
Block(2,-132,-2,NETHER_BRICK)
Block(2,-135,-2,NETHER_BRICK)
Block(2,-134,-2,NETHER_BRICK)
Block(2,-137,-2,NETHER_BRICK)
Block(2,-136,-2,NETHER_BRICK)
Block(2,-139,-2,NETHER_BRICK)
Block(2,-138,-2,NETHER_BRICK)
Block(2,-130,-2,NETHER_BRICK)
Block(2,-131,-2,NETHER_BRICK)
Block(2,-129,-2,NETHER_BRICK)
Block(2,-124,-2,NETHER_BRICK)
Block(2,-123,-2,NETHER_BRICK)
Block(2,-122,-2,NETHER_BRICK)
Block(2,-121,-2,NETHER_BRICK)
Block(2,-128,-2,NETHER_BRICK)
Block(2,-127,-2,NETHER_BRICK)
Block(2,-126,-2,NETHER_BRICK)
Block(2,-125,-2,NETHER_BRICK)
Block(2,-120,-2,NETHER_BRICK)
Block(3,-177,-1,NETHER_BRICK)
Block(2,-93,5,NETHER_BRICK)
Block(3,-176,-1,NETHER_BRICK)
Block(2,-94,5,NETHER_BRICK)
Block(3,-175,-1,NETHER_BRICK)
Block(2,-91,5,NETHER_BRICK)
Block(3,-174,-1,NETHER_BRICK)
Block(2,-92,5,NETHER_BRICK)
Block(2,-90,5,NETHER_BRICK)
Block(3,-179,-1,NETHER_BRICK)
Block(3,-178,-1,NETHER_BRICK)
Block(2,-159,-2,NETHER_BRICK)
Block(2,-158,-2,NETHER_BRICK)
Block(2,-99,5,NETHER_BRICK)
Block(2,-155,-2,NETHER_BRICK)
Block(2,-97,5,NETHER_BRICK)
Block(2,-154,-2,NETHER_BRICK)
Block(2,-98,5,NETHER_BRICK)
Block(2,-157,-2,NETHER_BRICK)
Block(2,-95,5,NETHER_BRICK)
Block(2,-156,-2,NETHER_BRICK)
Block(2,-96,5,NETHER_BRICK)
Block(2,-150,-2,NETHER_BRICK)
Block(2,-151,-2,NETHER_BRICK)
Block(2,-152,-2,NETHER_BRICK)
Block(2,-153,-2,NETHER_BRICK)
Block(3,-172,-1,NETHER_BRICK)
Block(3,-173,-1,NETHER_BRICK)
Block(3,-170,-1,NETHER_BRICK)
Block(3,-171,-1,NETHER_BRICK)
Block(3,-185,-1,NETHER_BRICK)
Block(2,-149,-2,NETHER_BRICK)
Block(2,-148,-2,NETHER_BRICK)
Block(2,-147,-2,NETHER_BRICK)
Block(2,-146,-2,NETHER_BRICK)
Block(2,-145,-2,NETHER_BRICK)
Block(2,-144,-2,NETHER_BRICK)
Block(2,-143,-2,NETHER_BRICK)
Block(2,-141,-2,NETHER_BRICK)
Block(2,-142,-2,NETHER_BRICK)
Block(2,-140,-2,NETHER_BRICK)
Block(3,-180,-1,NETHER_BRICK)
Block(3,-181,-1,NETHER_BRICK)
Block(3,-182,-1,NETHER_BRICK)
Block(3,-183,-1,NETHER_BRICK)
Block(3,-184,-1,NETHER_BRICK)
Block(2,-176,-2,NETHER_BRICK)
Block(4,5,-3,NETHER_BRICK)
Block(2,-177,-2,NETHER_BRICK)
Block(4,4,-3,NETHER_BRICK)
Block(2,-178,-2,NETHER_BRICK)
Block(4,3,-3,NETHER_BRICK)
Block(2,-179,-2,NETHER_BRICK)
Block(4,2,-3,NETHER_BRICK)
Block(4,1,-3,NETHER_BRICK)
Block(4,0,-3,NETHER_BRICK)
Block(-3,-185,3,NETHER_BRICK)
Block(4,7,-3,NETHER_BRICK_STAIRS:3)
Block(4,6,-3,NETHER_BRICK)
Block(2,-171,-2,NETHER_BRICK)
Block(2,-170,-2,NETHER_BRICK)
Block(2,-173,-2,NETHER_BRICK)
Block(2,-172,-2,NETHER_BRICK)
Block(2,-175,-2,NETHER_BRICK)
Block(2,-174,-2,NETHER_BRICK)
Block(2,-167,-2,NETHER_BRICK)
Block(2,-168,-2,NETHER_BRICK)
Block(2,-165,-2,NETHER_BRICK)
Block(2,-166,-2,NETHER_BRICK)
Block(2,-169,-2,NETHER_BRICK)
Block(-1,40,7,STEP:6)
Block(-1,36,7,NETHER_BRICK)
Block(-1,37,7,NETHER_BRICK)
Block(-1,38,7,NETHER_BRICK)
Block(-1,39,7,NETHER_BRICK)
Block(2,-160,-2,NETHER_BRICK)
Block(2,-164,-2,NETHER_BRICK)
Block(2,-163,-2,NETHER_BRICK)
Block(2,-162,-2,NETHER_BRICK)
Block(2,-161,-2,NETHER_BRICK)
Block(-3,-165,3,NETHER_BRICK)
Block(-3,-166,3,NETHER_BRICK)
Block(-3,-163,3,NETHER_BRICK)
Block(-3,-164,3,NETHER_BRICK)
Block(-3,-169,3,NETHER_BRICK)
Block(-3,-167,3,NETHER_BRICK)
Block(-3,-168,3,NETHER_BRICK)
Block(-3,-173,3,NETHER_BRICK)
Block(-3,-172,3,NETHER_BRICK)
Block(-3,-171,3,NETHER_BRICK)
Block(-3,-170,3,NETHER_BRICK)
Block(-3,-174,3,NETHER_BRICK)
Block(-3,-175,3,NETHER_BRICK)
Block(-3,-176,3,NETHER_BRICK)
Block(-3,-177,3,NETHER_BRICK)
Block(-3,-178,3,NETHER_BRICK)
Block(-3,-179,3,NETHER_BRICK)
Block(-3,-180,3,NETHER_BRICK)
Block(-3,-182,3,NETHER_BRICK)
Block(2,1,3,NETHER_BRICK)
Block(-3,-181,3,NETHER_BRICK)
Block(2,2,3,NETHER_BRICK)
Block(-3,-184,3,NETHER_BRICK)
Block(-3,-183,3,NETHER_BRICK)
Block(2,0,3,NETHER_BRICK)
Block(2,-185,-2,NETHER_BRICK)
Block(2,-184,-2,NETHER_BRICK)
Block(2,-183,-2,NETHER_BRICK)
Block(2,-182,-2,NETHER_BRICK)
Block(2,-181,-2,NETHER_BRICK)
Block(2,-180,-2,NETHER_BRICK)
Block(1,-115,5,NETHER_BRICK)
Block(1,-116,5,NETHER_BRICK)
Block(1,-113,5,NETHER_BRICK)
Block(1,-114,5,NETHER_BRICK)
Block(1,-119,5,NETHER_BRICK)
Block(-1,-127,-1,NETHER_BRICK)
Block(-1,-126,-1,NETHER_BRICK)
Block(1,-117,5,NETHER_BRICK)
Block(-1,-129,-1,NETHER_BRICK)
Block(1,-118,5,NETHER_BRICK)
Block(-1,-128,-1,NETHER_BRICK)
Block(-1,-123,-1,NETHER_BRICK)
Block(-5,32,5,NETHER_BRICK)
Block(-1,-122,-1,NETHER_BRICK)
Block(-1,-125,-1,NETHER_BRICK)
Block(-1,-124,-1,NETHER_BRICK)
Block(1,-111,5,NETHER_BRICK)
Block(1,-112,5,NETHER_BRICK)
Block(-1,-121,-1,NETHER_BRICK)
Block(1,-110,5,NETHER_BRICK)
Block(-1,-120,-1,NETHER_BRICK)
Block(1,18,-1,NETHER_BRICK)
Block(1,19,-1,NETHER_BRICK)
Block(1,14,-1,NETHER_BRICK)
Block(1,15,-1,NETHER_BRICK)
Block(1,16,-1,NETHER_BRICK)
Block(1,17,-1,NETHER_BRICK)
Block(1,-102,5,NETHER_BRICK)
Block(1,-103,5,NETHER_BRICK)
Block(1,-104,5,NETHER_BRICK)
Block(1,-105,5,NETHER_BRICK)
Block(-1,-119,-1,NETHER_BRICK)
Block(1,-106,5,NETHER_BRICK)
Block(-1,-118,-1,NETHER_BRICK)
Block(1,-107,5,NETHER_BRICK)
Block(-1,-117,-1,NETHER_BRICK)
Block(1,-108,5,NETHER_BRICK)
Block(-1,-116,-1,NETHER_BRICK)
Block(1,-109,5,NETHER_BRICK)
Block(-1,-115,-1,NETHER_BRICK)
Block(-1,-114,-1,NETHER_BRICK)
Block(1,11,-1,NETHER_BRICK)
Block(-1,-113,-1,NETHER_BRICK)
Block(1,10,-1,NETHER_BRICK)
Block(-1,-112,-1,NETHER_BRICK)
Block(1,13,-1,NETHER_BRICK)
Block(-1,-111,-1,NETHER_BRICK)
Block(1,12,-1,NETHER_BRICK)
Block(-1,-110,-1,NETHER_BRICK)
Block(1,-100,5,NETHER_BRICK)
Block(1,-101,5,NETHER_BRICK)
Block(-1,-105,-1,NETHER_BRICK)
Block(-1,32,7,NETHER_BRICK)
Block(-1,-104,-1,NETHER_BRICK)
Block(-1,33,7,NETHER_BRICK)
Block(-1,-107,-1,NETHER_BRICK)
Block(1,-139,5,NETHER_BRICK)
Block(-1,34,7,NETHER_BRICK)
Block(-1,-106,-1,NETHER_BRICK)
Block(-1,35,7,NETHER_BRICK)
Block(-1,-109,-1,NETHER_BRICK)
Block(1,-137,5,NETHER_BRICK)
Block(-1,-108,-1,NETHER_BRICK)
Block(1,-138,5,NETHER_BRICK)
Block(1,-135,5,NETHER_BRICK)
Block(1,-136,5,NETHER_BRICK)
Block(-1,31,7,STEP:14)
Block(1,-133,5,NETHER_BRICK)
Block(2,10,-3,NETHER_BRICK)
Block(1,-134,5,NETHER_BRICK)
Block(1,-131,5,NETHER_BRICK)
Block(1,-132,5,NETHER_BRICK)
Block(-1,-101,-1,NETHER_BRICK)
Block(1,-130,5,NETHER_BRICK)
Block(-1,-100,-1,NETHER_BRICK)
Block(-1,-103,-1,NETHER_BRICK)
Block(-1,-102,-1,NETHER_BRICK)
Block(2,11,-3,NETHER_BRICK_STAIRS)
Block(-5,39,5,NETHER_BRICK)
Block(-5,38,5,NETHER_BRICK)
Block(1,-128,5,NETHER_BRICK)
Block(1,-129,5,NETHER_BRICK)
Block(1,-124,5,NETHER_BRICK)
Block(1,-125,5,NETHER_BRICK)
Block(1,-126,5,NETHER_BRICK)
Block(1,-127,5,NETHER_BRICK)
Block(1,-120,5,NETHER_BRICK)
Block(1,-121,5,NETHER_BRICK)
Block(1,-122,5,NETHER_BRICK)
Block(1,-123,5,NETHER_BRICK)
Block(-3,6,-4,NETHER_BRICK)
Block(-3,5,-4,NETHER_BRICK)
Block(-3,4,-4,NETHER_BRICK)
Block(-3,3,-4,NETHER_BRICK)
Block(1,-7,1,NETHER_BRICK)
Block(-3,2,-4,NETHER_BRICK)
Block(1,-8,1,NETHER_BRICK)
Block(-3,1,-4,NETHER_BRICK)
Block(1,-9,1,NETHER_BRICK)
Block(-3,0,-4,NETHER_BRICK)
Block(-3,7,-4,NETHER_BRICK_STAIRS:1)
Block(0,-1,3,NETHER_BRICK)
Block(0,-3,3,NETHER_BRICK)
Block(0,-2,3,NETHER_BRICK)
Block(0,-5,3,NETHER_BRICK)
Block(0,-4,3,NETHER_BRICK)
Block(0,-7,3,NETHER_BRICK)
Block(0,-6,3,NETHER_BRICK)
Block(1,-9,-1,NETHER_BRICK)
Block(1,-8,-1,NETHER_BRICK)
Block(1,-5,-1,NETHER_BRICK)
Block(1,-4,-1,NETHER_BRICK)
Block(1,-7,-1,NETHER_BRICK)
Block(1,-6,-1,NETHER_BRICK)
Block(1,-1,-1,NETHER_BRICK)
Block(1,-3,-1,NETHER_BRICK)
Block(1,-2,-1,NETHER_BRICK)
Block(1,-6,1,NETHER_BRICK)
Block(1,-5,1,NETHER_BRICK)
Block(1,-4,1,NETHER_BRICK)
Block(1,-3,1,NETHER_BRICK)
Block(1,-2,1,NETHER_BRICK)
Block(1,-1,1,NETHER_BRICK)
Block(2,-9,-3,NETHER_BRICK)
Block(2,-4,-3,NETHER_BRICK)
Block(2,-3,-3,NETHER_BRICK)
Block(2,-2,-3,NETHER_BRICK)
Block(2,-1,-3,NETHER_BRICK)
Block(2,-8,-3,NETHER_BRICK)
Block(2,-7,-3,NETHER_BRICK)
Block(2,-6,-3,NETHER_BRICK)
Block(2,-5,-3,NETHER_BRICK)
Block(2,-116,-2,NETHER_BRICK)
Block(2,-117,-2,NETHER_BRICK)
Block(2,-114,-2,NETHER_BRICK)
Block(2,-115,-2,NETHER_BRICK)
Block(2,-112,-2,NETHER_BRICK)
Block(2,-113,-2,NETHER_BRICK)
Block(2,-110,-2,NETHER_BRICK)
Block(2,-111,-2,NETHER_BRICK)
Block(2,-118,-2,NETHER_BRICK)
Block(2,-119,-2,NETHER_BRICK)
Block(0,-8,3,NETHER_BRICK)
Block(0,-9,3,NETHER_BRICK)
Block(2,-103,-2,NETHER_BRICK)
Block(2,-104,-2,NETHER_BRICK)
Block(2,-105,-2,NETHER_BRICK)
Block(2,-106,-2,NETHER_BRICK)
Block(2,-100,-2,NETHER_BRICK)
Block(2,-101,-2,NETHER_BRICK)
Block(2,-102,-2,NETHER_BRICK)
Block(2,-107,-2,NETHER_BRICK)
Block(2,-108,-2,NETHER_BRICK)
Block(2,-109,-2,NETHER_BRICK)
Block(1,13,1,NETHER_BRICK)
Block(1,14,1,NETHER_BRICK)
Block(1,15,1,NETHER_BRICK)
Block(1,16,1,NETHER_BRICK)
Block(1,17,1,NETHER_BRICK)
Block(1,18,1,NETHER_BRICK)
Block(1,19,1,NETHER_BRICK)
Block(-1,-26,-1,NETHER_BRICK)
Block(-1,-25,-1,NETHER_BRICK)
Block(-1,-28,-1,NETHER_BRICK)
Block(-1,-27,-1,NETHER_BRICK)
Block(1,10,1,NETHER_BRICK)
Block(-1,-29,-1,NETHER_BRICK)
Block(1,11,1,NETHER_BRICK)
Block(1,12,1,NETHER_BRICK)
Block(-1,-20,-1,NETHER_BRICK)
Block(-1,-21,-1,NETHER_BRICK)
Block(-1,-22,-1,NETHER_BRICK)
Block(-1,-23,-1,NETHER_BRICK)
Block(-1,-24,-1,NETHER_BRICK)
Block(0,12,3,NETHER_BRICK)
Block(1,26,1,NETHER_BRICK)
Block(0,13,3,NETHER_BRICK)
Block(1,27,1,NETHER_BRICK)
Block(1,24,1,NETHER_BRICK)
Block(0,10,3,NETHER_BRICK)
Block(0,11,3,NETHER_BRICK)
Block(1,25,1,NETHER_BRICK)
Block(1,28,1,NETHER_BRICK)
Block(1,29,1,NETHER_BRICK)
Block(-1,-17,-1,NETHER_BRICK)
Block(-1,-16,-1,NETHER_BRICK)
Block(-1,-15,-1,NETHER_BRICK)
Block(-1,-14,-1,NETHER_BRICK)
Block(1,22,1,NETHER_BRICK)
Block(0,16,3,NETHER_BRICK)
Block(1,23,1,NETHER_BRICK)
Block(0,17,3,NETHER_BRICK_STAIRS:2)
Block(-1,-19,-1,NETHER_BRICK)
Block(1,20,1,NETHER_BRICK)
Block(0,14,3,NETHER_BRICK)
Block(-1,-18,-1,NETHER_BRICK)
Block(1,21,1,NETHER_BRICK)
Block(0,15,3,NETHER_BRICK)
Block(-1,-12,-1,NETHER_BRICK)
Block(-1,-13,-1,NETHER_BRICK)
Block(-1,-10,-1,NETHER_BRICK)
Block(-1,-11,-1,NETHER_BRICK)
Block(0,22,3,STEP:6)
Block(-1,-178,-1,NETHER_BRICK)
Block(0,25,3,NETHER_BRICK_STAIRS:6)
Block(1,31,1,NETHER_BRICK)
Block(-1,-177,-1,NETHER_BRICK)
Block(0,26,3,NETHER_BRICK)
Block(1,32,1,NETHER_BRICK)
Block(-1,-179,-1,NETHER_BRICK)
Block(-1,-174,-1,NETHER_BRICK)
Block(0,29,3,NETHER_BRICK_STAIRS:7)
Block(-1,-48,-1,NETHER_BRICK)
Block(-1,-173,-1,NETHER_BRICK)
Block(-1,-47,-1,NETHER_BRICK)
Block(-1,-176,-1,NETHER_BRICK)
Block(-1,-175,-1,NETHER_BRICK)
Block(1,30,1,NETHER_BRICK)
Block(-1,-49,-1,NETHER_BRICK)
Block(-1,-180,-1,NETHER_BRICK)
Block(-1,-43,-1,NETHER_BRICK)
Block(-1,-181,-1,NETHER_BRICK)
Block(-1,-44,-1,NETHER_BRICK)
Block(-1,-182,-1,NETHER_BRICK)
Block(-1,-45,-1,NETHER_BRICK)
Block(-1,-183,-1,NETHER_BRICK)
Block(-1,-46,-1,NETHER_BRICK)
Block(-1,-40,-1,NETHER_BRICK)
Block(-1,-41,-1,NETHER_BRICK)
Block(-1,-42,-1,NETHER_BRICK)
Block(0,30,3,NETHER_BRICK)
Block(0,31,3,NETHER_BRICK)
Block(1,48,1,NETHER_BRICK)
Block(1,49,1,NETHER_BRICK)
Block(1,46,1,NETHER_BRICK)
Block(0,32,3,NETHER_BRICK)
Block(1,47,1,NETHER_BRICK)
Block(1,44,1,GLOWSTONE)
Block(0,38,3,NETHER_BRICK)
Block(1,45,1,NETHER_BRICK)
Block(0,39,3,NETHER_BRICK)
