
#######################################################################
# +-----------------------------------------------------------------+ #
# |                            BO3 object                           | #
# +-----------------------------------------------------------------+ #
#######################################################################

# This is the config file of a custom object.
# If you add this object correctly to your BiomeConfigs, it will spawn in the world.

# This is the creator of this BO3 object
Author:LanToaster

# A short description of this BO3 object
Description:No description given

# The BO3 version, don't change this! It can be used by external applications to do a version check.
Version:3

# The settings mode, WriteAll, WriteWithoutComments or WriteDisable. See WorldConfig.
SettingsMode:WriteDisable

#######################################################################
# +-----------------------------------------------------------------+ #
# |                          Main settings                          | #
# +-----------------------------------------------------------------+ #
#######################################################################

# This needs to be set to true to spawn the object in the Tree and Sapling resources.
Tree:true

# The frequency of the BO3 from 1 to 200. Tries this many times to spawn this BO3 when using the CustomObject(...) resource.
# Ignored by Tree(..), Sapling(..) and CustomStructure(..)
Frequency:1

# The rarity of the BO3 from 0 to 100. Each spawn attempt has rarity% chance to succeed when using the CustomObject(...) resource.
# Ignored by Tree(..), Sapling(..) and CustomStructure(..)
Rarity:100.0

# If you set this to true, the BO3 will be placed with a random rotation.
RotateRandomly:false

# The spawn height of the BO3 - randomY, highestBlock or highestSolidBlock.
SpawnHeight:highestBlock

# The height limits for the BO3.
MinHeight:0
MaxHeight:256

# Objects can have other objects attacthed to it: branches. Branches can also
# have branches attached to it, which can also have branches, etc. This is the
# maximum branch depth for this objects.
MaxBranchDepth:10

# When spawned with the UseWorld keyword, this BO3 should NOT spawn in the following biomes.
# If you write the BO3 name directly in the BiomeConfigs, this will be ignored.
ExcludedBiomes:All

#######################################################################
# +-----------------------------------------------------------------+ #
# |                      Source block settings                      | #
# +-----------------------------------------------------------------+ #
#######################################################################

# The block the BO3 should spawn in
SourceBlock:74

# The maximum percentage of the BO3 that can be outside the SourceBlock.
# The BO3 won't be placed on a location with more blocks outside the SourceBlock than this percentage.
MaxPercentageOutsideSourceBlock:65

# What to do when a block is about to be placed outside the SourceBlock? (dontPlace, placeAnyway)
OutsideSourceBlock:placeAnyway

#######################################################################
# +-----------------------------------------------------------------+ #
# |                              Blocks                             | #
# +-----------------------------------------------------------------+ #
#######################################################################

# All the blocks used in the BO3 are listed here. Possible blocks:
# Block(x,y,z,id[.data][,nbtfile.nbt)
# RandomBlock(x,y,z,id[:data][,nbtfile.nbt],chance[,id[:data][,nbtfile.nbt],chance[,...]])
# So RandomBlock(0,0,0,CHEST,chest.nbt,50,CHEST,anotherchest.nbt,100) will spawn a chest at
# the BO3 origin, and give it a 50% chance to have the contents of chest.nbt, or, if that
# fails, a 100% percent chance to have the contents of anotherchest.nbt.
Block(-6,1,-1,NETHER_BRICK)
Block(-6,1,0,NETHER_BRICK)
Block(-6,1,1,NETHER_BRICK)
Block(-6,2,-1,NETHER_BRICK)
Block(-6,2,0,NETHER_BRICK)
Block(-6,2,1,NETHER_BRICK)
Block(-6,3,-1,NETHER_BRICK)
Block(-6,3,0,NETHER_BRICK)
Block(-6,3,1,NETHER_BRICK)
Block(-6,4,-1,NETHER_BRICK)
Block(-6,4,0,NETHER_BRICK)
Block(-6,4,1,NETHER_BRICK)
Block(-6,5,-1,NETHER_BRICK)
Block(-6,5,0,NETHER_BRICK)
Block(-6,5,1,NETHER_BRICK)
Block(-6,6,-1,NETHER_BRICK)
Block(-6,6,0,NETHER_BRICK)
Block(-6,6,1,NETHER_BRICK)
Block(-6,7,-1,NETHER_BRICK)
Block(-6,7,0,NETHER_BRICK)
Block(-6,7,1,NETHER_BRICK)
Block(-6,8,-1,NETHER_BRICK)
Block(-6,8,0,NETHER_BRICK)
Block(-6,8,1,NETHER_BRICK)
Block(-6,9,-1,NETHER_BRICK)
Block(-6,9,0,NETHER_BRICK)
Block(-6,9,1,NETHER_BRICK)
Block(-6,10,-1,NETHER_BRICK_STAIRS)
Block(-6,10,0,NETHER_BRICK_STAIRS)
Block(-6,10,1,NETHER_BRICK_STAIRS)
Block(-6,15,6,SANDSTONE)
Block(-5,0,-1,NETHER_BRICK)
Block(-5,0,0,NETHER_BRICK)
Block(-5,0,1,NETHER_BRICK)
Block(-5,1,-3,NETHER_BRICK)
Block(-5,1,-2,OBSIDIAN)
Block(-5,1,-1,STATIONARY_LAVA)
Block(-5,1,0,STATIONARY_LAVA)
Block(-5,1,1,STATIONARY_LAVA)
Block(-5,1,2,OBSIDIAN)
Block(-5,1,3,NETHER_BRICK)
Block(-5,2,-3,NETHER_BRICK)
Block(-5,2,-2,OBSIDIAN)
Block(-5,2,-1,STATIONARY_LAVA)
Block(-5,2,0,STATIONARY_LAVA)
Block(-5,2,1,STATIONARY_LAVA)
Block(-5,2,2,OBSIDIAN)
Block(-5,2,3,NETHER_BRICK)
Block(-5,3,-3,NETHER_BRICK)
Block(-5,3,-2,OBSIDIAN)
Block(-5,3,-1,STATIONARY_LAVA)
Block(-5,3,0,STATIONARY_LAVA)
Block(-5,3,1,STATIONARY_LAVA)
Block(-5,3,2,OBSIDIAN)
Block(-5,3,3,NETHER_BRICK)
Block(-5,4,-3,NETHER_BRICK)
Block(-5,4,-2,OBSIDIAN)
Block(-5,4,-1,STATIONARY_LAVA)
Block(-5,4,0,STATIONARY_LAVA)
Block(-5,4,1,STATIONARY_LAVA)
Block(-5,4,2,OBSIDIAN)
Block(-5,4,3,NETHER_BRICK)
Block(-5,5,-3,NETHER_BRICK)
Block(-5,5,-2,OBSIDIAN)
Block(-5,5,-1,STATIONARY_LAVA)
Block(-5,5,0,STATIONARY_LAVA)
Block(-5,5,1,STATIONARY_LAVA)
Block(-5,5,2,OBSIDIAN)
Block(-5,5,3,NETHER_BRICK)
Block(-5,6,-3,NETHER_BRICK)
Block(-5,6,-2,OBSIDIAN)
Block(-5,6,-1,AIR)
Block(-5,6,0,AIR)
Block(-5,6,1,AIR)
Block(-5,6,2,OBSIDIAN)
Block(-5,6,3,NETHER_BRICK)
Block(-5,7,-3,NETHER_BRICK)
Block(-5,7,-2,OBSIDIAN)
Block(-5,7,-1,AIR)
Block(-5,7,0,AIR)
Block(-5,7,1,AIR)
Block(-5,7,2,OBSIDIAN)
Block(-5,7,3,NETHER_BRICK)
Block(-5,8,-3,NETHER_BRICK)
Block(-5,8,-2,OBSIDIAN)
Block(-5,8,-1,AIR)
Block(-5,8,0,AIR)
Block(-5,8,1,AIR)
Block(-5,8,2,OBSIDIAN)
Block(-5,8,3,NETHER_BRICK)
Block(-5,9,-3,NETHER_BRICK)
Block(-5,9,-2,OBSIDIAN)
Block(-5,9,-1,AIR)
Block(-5,9,0,AIR)
Block(-5,9,1,AIR)
Block(-5,9,2,OBSIDIAN)
Block(-5,9,3,NETHER_BRICK)
Block(-5,10,-3,OBSIDIAN)
Block(-5,10,-2,OBSIDIAN)
Block(-5,10,-1,NETHER_BRICK)
Block(-5,10,0,NETHER_BRICK)
Block(-5,10,1,NETHER_BRICK)
Block(-5,10,2,OBSIDIAN)
Block(-5,10,3,OBSIDIAN)
Block(-5,11,-1,NETHER_BRICK)
Block(-5,11,0,NETHER_BRICK)
Block(-5,11,1,NETHER_BRICK)
Block(-5,12,-1,NETHER_BRICK)
Block(-5,12,0,NETHER_BRICK)
Block(-5,12,1,NETHER_BRICK)
Block(-5,13,-1,NETHER_BRICK)
Block(-5,13,0,NETHER_BRICK)
Block(-5,13,1,NETHER_BRICK)
Block(-5,14,-1,NETHER_BRICK_STAIRS)
Block(-5,14,0,NETHER_BRICK)
Block(-5,14,1,NETHER_BRICK_STAIRS)
Block(-4,0,-3,NETHER_BRICK)
Block(-4,0,-2,NETHER_BRICK)
Block(-4,0,-1,NETHER_BRICK)
Block(-4,0,0,NETHER_BRICK)
Block(-4,0,1,NETHER_BRICK)
Block(-4,0,2,NETHER_BRICK)
Block(-4,0,3,NETHER_BRICK)
Block(-4,1,-4,OBSIDIAN)
Block(-4,1,-3,STATIONARY_LAVA)
Block(-4,1,-2,STATIONARY_LAVA)
Block(-4,1,-1,STATIONARY_LAVA)
Block(-4,1,0,STATIONARY_LAVA)
Block(-4,1,1,STATIONARY_LAVA)
Block(-4,1,2,STATIONARY_LAVA)
Block(-4,1,3,STATIONARY_LAVA)
Block(-4,1,4,OBSIDIAN)
Block(-4,2,-4,OBSIDIAN)
Block(-4,2,-3,STATIONARY_LAVA)
Block(-4,2,-2,STATIONARY_LAVA)
Block(-4,2,-1,STATIONARY_LAVA)
Block(-4,2,0,STATIONARY_LAVA)
Block(-4,2,1,STATIONARY_LAVA)
Block(-4,2,2,STATIONARY_LAVA)
Block(-4,2,3,STATIONARY_LAVA)
Block(-4,2,4,OBSIDIAN)
Block(-4,3,-4,OBSIDIAN)
Block(-4,3,-3,STATIONARY_LAVA)
Block(-4,3,-2,STATIONARY_LAVA)
Block(-4,3,-1,STATIONARY_LAVA)
Block(-4,3,0,STATIONARY_LAVA)
Block(-4,3,1,STATIONARY_LAVA)
Block(-4,3,2,STATIONARY_LAVA)
Block(-4,3,3,STATIONARY_LAVA)
Block(-4,3,4,OBSIDIAN)
Block(-4,4,-4,OBSIDIAN)
Block(-4,4,-3,STATIONARY_LAVA)
Block(-4,4,-2,STATIONARY_LAVA)
Block(-4,4,-1,STATIONARY_LAVA)
Block(-4,4,0,STATIONARY_LAVA)
Block(-4,4,1,STATIONARY_LAVA)
Block(-4,4,2,STATIONARY_LAVA)
Block(-4,4,3,STATIONARY_LAVA)
Block(-4,4,4,OBSIDIAN)
Block(-4,5,-4,OBSIDIAN)
Block(-4,5,-3,STATIONARY_LAVA)
Block(-4,5,-2,STATIONARY_LAVA)
Block(-4,5,-1,STATIONARY_LAVA)
Block(-4,5,0,STATIONARY_LAVA)
Block(-4,5,1,STATIONARY_LAVA)
Block(-4,5,2,STATIONARY_LAVA)
Block(-4,5,3,STATIONARY_LAVA)
Block(-4,5,4,OBSIDIAN)
Block(-4,6,-4,OBSIDIAN)
Block(-4,6,-3,NETHER_FENCE)
Block(-4,6,-2,NETHER_FENCE)
Block(-4,6,-1,NETHER_FENCE)
Block(-4,6,0,NETHER_FENCE)
Block(-4,6,1,NETHER_FENCE)
Block(-4,6,2,NETHER_FENCE)
Block(-4,6,3,NETHER_FENCE)
Block(-4,6,4,OBSIDIAN)
Block(-4,7,-4,OBSIDIAN)
Block(-4,7,-3,AIR)
Block(-4,7,-2,AIR)
Block(-4,7,-1,AIR)
Block(-4,7,0,AIR)
Block(-4,7,1,AIR)
Block(-4,7,2,AIR)
Block(-4,7,3,AIR)
Block(-4,7,4,OBSIDIAN)
Block(-4,8,-4,OBSIDIAN)
Block(-4,8,-3,AIR)
Block(-4,8,-2,AIR)
Block(-4,8,-1,AIR)
Block(-4,8,0,AIR)
Block(-4,8,1,AIR)
Block(-4,8,2,AIR)
Block(-4,8,3,AIR)
Block(-4,8,4,OBSIDIAN)
Block(-4,9,-4,OBSIDIAN)
Block(-4,9,-3,AIR)
Block(-4,9,-2,AIR)
Block(-4,9,-1,AIR)
Block(-4,9,0,AIR)
Block(-4,9,1,AIR)
Block(-4,9,2,AIR)
Block(-4,9,3,AIR)
Block(-4,9,4,OBSIDIAN)
Block(-4,10,-4,OBSIDIAN)
Block(-4,10,-3,NETHER_FENCE)
Block(-4,10,-2,NETHER_FENCE)
Block(-4,10,-1,NETHER_FENCE)
Block(-4,10,0,NETHER_BRICK_STAIRS:5)
Block(-4,10,1,NETHER_FENCE)
Block(-4,10,2,NETHER_FENCE)
Block(-4,10,3,NETHER_FENCE)
Block(-4,10,4,OBSIDIAN)
Block(-4,11,-4,NETHER_FENCE)
Block(-4,11,-3,OBSIDIAN)
Block(-4,11,-2,OBSIDIAN)
Block(-4,11,-1,NETHER_BRICK_STAIRS:5)
Block(-4,11,0,NETHER_BRICK)
Block(-4,11,1,NETHER_BRICK_STAIRS:5)
Block(-4,11,2,OBSIDIAN)
Block(-4,11,3,OBSIDIAN)
Block(-4,11,4,NETHER_FENCE)
Block(-4,12,-4,NETHER_FENCE)
Block(-4,12,-3,OBSIDIAN)
Block(-4,12,-2,NETHER_BRICK)
Block(-4,12,-1,NETHER_FENCE)
Block(-4,12,0,NETHER_FENCE)
Block(-4,12,1,NETHER_FENCE)
Block(-4,12,2,NETHER_BRICK)
Block(-4,12,3,OBSIDIAN)
Block(-4,12,4,NETHER_FENCE)
Block(-4,13,-3,OBSIDIAN)
Block(-4,13,-2,NETHER_BRICK)
Block(-4,13,-1,NETHER_FENCE)
Block(-4,13,0,NETHER_FENCE)
Block(-4,13,1,NETHER_FENCE)
Block(-4,13,2,NETHER_BRICK)
Block(-4,13,3,OBSIDIAN)
Block(-4,14,-3,OBSIDIAN)
Block(-4,14,-2,NETHER_BRICK)
Block(-4,14,-1,NETHER_BRICK)
Block(-4,14,0,NETHER_BRICK)
Block(-4,14,1,NETHER_BRICK)
Block(-4,14,2,NETHER_BRICK)
Block(-4,14,3,OBSIDIAN)
Block(-4,15,-3,OBSIDIAN)
Block(-4,15,-2,OBSIDIAN)
Block(-4,15,-1,NETHER_BRICK)
Block(-4,15,0,NETHER_BRICK)
Block(-4,15,1,NETHER_BRICK)
Block(-4,15,2,OBSIDIAN)
Block(-4,15,3,OBSIDIAN)
Block(-3,0,-4,NETHER_BRICK)
Block(-3,0,-3,NETHER_BRICK)
Block(-3,0,-2,NETHER_BRICK)
Block(-3,0,-1,NETHER_BRICK)
Block(-3,0,0,NETHER_BRICK)
Block(-3,0,1,NETHER_BRICK)
Block(-3,0,2,NETHER_BRICK)
Block(-3,0,3,NETHER_BRICK)
Block(-3,0,4,NETHER_BRICK)
Block(-3,1,-5,NETHER_BRICK)
Block(-3,1,-4,STATIONARY_LAVA)
Block(-3,1,-3,STATIONARY_LAVA)
Block(-3,1,-2,STATIONARY_LAVA)
Block(-3,1,-1,STATIONARY_LAVA)
Block(-3,1,0,STATIONARY_LAVA)
Block(-3,1,1,STATIONARY_LAVA)
Block(-3,1,2,STATIONARY_LAVA)
Block(-3,1,3,STATIONARY_LAVA)
Block(-3,1,4,STATIONARY_LAVA)
Block(-3,1,5,NETHER_BRICK)
Block(-3,2,-5,NETHER_BRICK)
Block(-3,2,-4,STATIONARY_LAVA)
Block(-3,2,-3,STATIONARY_LAVA)
Block(-3,2,-2,STATIONARY_LAVA)
Block(-3,2,-1,STATIONARY_LAVA)
Block(-3,2,0,STATIONARY_LAVA)
Block(-3,2,1,STATIONARY_LAVA)
Block(-3,2,2,STATIONARY_LAVA)
Block(-3,2,3,STATIONARY_LAVA)
Block(-3,2,4,STATIONARY_LAVA)
Block(-3,2,5,NETHER_BRICK)
Block(-3,3,-5,NETHER_BRICK)
Block(-3,3,-4,STATIONARY_LAVA)
Block(-3,3,-3,STATIONARY_LAVA)
Block(-3,3,-2,STATIONARY_LAVA)
Block(-3,3,-1,STATIONARY_LAVA)
Block(-3,3,0,STATIONARY_LAVA)
Block(-3,3,1,STATIONARY_LAVA)
Block(-3,3,2,STATIONARY_LAVA)
Block(-3,3,3,STATIONARY_LAVA)
Block(-3,3,4,STATIONARY_LAVA)
Block(-3,3,5,NETHER_BRICK)
Block(-3,4,-5,NETHER_BRICK)
Block(-3,4,-4,STATIONARY_LAVA)
Block(-3,4,-3,STATIONARY_LAVA)
Block(-3,4,-2,STATIONARY_LAVA)
Block(-3,4,-1,STATIONARY_LAVA)
Block(-3,4,0,STATIONARY_LAVA)
Block(-3,4,1,STATIONARY_LAVA)
Block(-3,4,2,STATIONARY_LAVA)
Block(-3,4,3,STATIONARY_LAVA)
Block(-3,4,4,STATIONARY_LAVA)
Block(-3,4,5,NETHER_BRICK)
Block(-3,5,-5,NETHER_BRICK)
Block(-3,5,-4,STATIONARY_LAVA)
Block(-3,5,-3,STATIONARY_LAVA)
Block(-3,5,-2,STATIONARY_LAVA)
Block(-3,5,-1,STATIONARY_LAVA)
Block(-3,5,0,STATIONARY_LAVA)
Block(-3,5,1,STATIONARY_LAVA)
Block(-3,5,2,STATIONARY_LAVA)
Block(-3,5,3,STATIONARY_LAVA)
Block(-3,5,4,STATIONARY_LAVA)
Block(-3,5,5,NETHER_BRICK)
Block(-3,6,-5,NETHER_BRICK)
Block(-3,6,-4,NETHER_FENCE)
Block(-3,6,-3,STEP:6)
Block(-3,6,-2,STEP:6)
Block(-3,6,-1,STEP:6)
Block(-3,6,0,STEP:6)
Block(-3,6,1,STEP:6)
Block(-3,6,2,AIR)
Block(-3,6,3,AIR)
Block(-3,6,4,NETHER_FENCE)
Block(-3,6,5,NETHER_BRICK)
Block(-3,7,-5,NETHER_BRICK)
Block(-3,7,-4,AIR)
Block(-3,7,-3,AIR)
Block(-3,7,-2,AIR)
Block(-3,7,-1,AIR)
Block(-3,7,0,AIR)
Block(-3,7,1,AIR)
Block(-3,7,2,AIR)
Block(-3,7,3,AIR)
Block(-3,7,4,AIR)
Block(-3,7,5,NETHER_BRICK)
Block(-3,8,-5,NETHER_BRICK)
Block(-3,8,-4,AIR)
Block(-3,8,-3,AIR)
Block(-3,8,-2,AIR)
Block(-3,8,-1,AIR)
Block(-3,8,0,AIR)
Block(-3,8,1,STEP:14)
Block(-3,8,2,STEP:6)
Block(-3,8,3,STEP:6)
Block(-3,8,4,AIR)
Block(-3,8,5,NETHER_BRICK)
Block(-3,9,-5,NETHER_BRICK)
Block(-3,9,-4,AIR)
Block(-3,9,-3,AIR)
Block(-3,9,-2,AIR)
Block(-3,9,-1,STEP:14)
Block(-3,9,0,STEP:6)
Block(-3,9,1,AIR)
Block(-3,9,2,AIR)
Block(-3,9,3,AIR)
Block(-3,9,4,AIR)
Block(-3,9,5,NETHER_BRICK)
Block(-3,10,-5,OBSIDIAN)
Block(-3,10,-4,NETHER_FENCE)
Block(-3,10,-3,STEP:6)
Block(-3,10,-2,STEP:6)
Block(-3,10,-1,AIR)
Block(-3,10,0,AIR)
Block(-3,10,1,AIR)
Block(-3,10,2,AIR)
Block(-3,10,3,AIR)
Block(-3,10,4,NETHER_FENCE)
Block(-3,10,5,OBSIDIAN)
Block(-3,11,-4,OBSIDIAN)
Block(-3,11,-3,AIR)
Block(-3,11,-2,AIR)
Block(-3,11,-1,AIR)
Block(-3,11,0,AIR)
Block(-3,11,1,AIR)
Block(-3,11,2,AIR)
Block(-3,11,3,AIR)
Block(-3,11,4,OBSIDIAN)
Block(-3,12,-4,OBSIDIAN)
Block(-3,12,-3,AIR)
Block(-3,12,-2,AIR)
Block(-3,12,-1,AIR)
Block(-3,12,0,AIR)
Block(-3,12,1,AIR)
Block(-3,12,2,AIR)
Block(-3,12,3,AIR)
Block(-3,12,4,OBSIDIAN)
Block(-3,13,-4,OBSIDIAN)
Block(-3,13,-3,AIR)
Block(-3,13,-2,AIR)
Block(-3,13,-1,AIR)
Block(-3,13,0,AIR)
Block(-3,13,1,AIR)
Block(-3,13,2,AIR)
Block(-3,13,3,AIR)
Block(-3,13,4,OBSIDIAN)
Block(-3,14,-4,OBSIDIAN)
Block(-3,14,-3,AIR)
Block(-3,14,-2,NETHER_BRICK_STAIRS:5)
Block(-3,14,-1,AIR)
Block(-3,14,0,AIR)
Block(-3,14,1,AIR)
Block(-3,14,2,NETHER_BRICK_STAIRS:5)
Block(-3,14,3,AIR)
Block(-3,14,4,OBSIDIAN)
Block(-3,15,-4,OBSIDIAN)
Block(-3,15,-3,AIR)
Block(-3,15,-2,REDSTONE_TORCH_ON:5)
Block(-3,15,-1,AIR)
Block(-3,15,0,AIR)
Block(-3,15,1,AIR)
Block(-3,15,2,REDSTONE_TORCH_ON:5)
Block(-3,15,3,AIR)
Block(-3,15,4,OBSIDIAN)
Block(-2,0,-4,NETHER_BRICK)
Block(-2,0,-3,NETHER_BRICK)
Block(-2,0,-2,NETHER_BRICK)
Block(-2,0,-1,NETHER_BRICK)
Block(-2,0,0,NETHER_BRICK)
Block(-2,0,1,NETHER_BRICK)
Block(-2,0,2,NETHER_BRICK)
Block(-2,0,3,NETHER_BRICK)
Block(-2,0,4,NETHER_BRICK)
Block(-2,1,-5,OBSIDIAN)
Block(-2,1,-4,STATIONARY_LAVA)
Block(-2,1,-3,STATIONARY_LAVA)
Block(-2,1,-2,STATIONARY_LAVA)
Block(-2,1,-1,STATIONARY_LAVA)
Block(-2,1,0,STATIONARY_LAVA)
Block(-2,1,1,STATIONARY_LAVA)
Block(-2,1,2,STATIONARY_LAVA)
Block(-2,1,3,STATIONARY_LAVA)
Block(-2,1,4,STATIONARY_LAVA)
Block(-2,1,5,OBSIDIAN)
Block(-2,2,-5,OBSIDIAN)
Block(-2,2,-4,STATIONARY_LAVA)
Block(-2,2,-3,STATIONARY_LAVA)
Block(-2,2,-2,STATIONARY_LAVA)
Block(-2,2,-1,STATIONARY_LAVA)
Block(-2,2,0,STATIONARY_LAVA)
Block(-2,2,1,STATIONARY_LAVA)
Block(-2,2,2,STATIONARY_LAVA)
Block(-2,2,3,STATIONARY_LAVA)
Block(-2,2,4,STATIONARY_LAVA)
Block(-2,2,5,OBSIDIAN)
Block(-2,3,-5,OBSIDIAN)
Block(-2,3,-4,STATIONARY_LAVA)
Block(-2,3,-3,STATIONARY_LAVA)
Block(-2,3,-2,STATIONARY_LAVA)
Block(-2,3,-1,STATIONARY_LAVA)
Block(-2,3,0,STATIONARY_LAVA)
Block(-2,3,1,STATIONARY_LAVA)
Block(-2,3,2,STATIONARY_LAVA)
Block(-2,3,3,STATIONARY_LAVA)
Block(-2,3,4,STATIONARY_LAVA)
Block(-2,3,5,OBSIDIAN)
Block(-2,4,-5,OBSIDIAN)
Block(-2,4,-4,STATIONARY_LAVA)
Block(-2,4,-3,STATIONARY_LAVA)
Block(-2,4,-2,STATIONARY_LAVA)
Block(-2,4,-1,STATIONARY_LAVA)
Block(-2,4,0,STATIONARY_LAVA)
Block(-2,4,1,STATIONARY_LAVA)
Block(-2,4,2,STATIONARY_LAVA)
Block(-2,4,3,STATIONARY_LAVA)
Block(-2,4,4,STATIONARY_LAVA)
Block(-2,4,5,OBSIDIAN)
Block(-2,5,-5,OBSIDIAN)
Block(-2,5,-4,STATIONARY_LAVA)
Block(-2,5,-3,STATIONARY_LAVA)
Block(-2,5,-2,STATIONARY_LAVA)
Block(-2,5,-1,STATIONARY_LAVA)
Block(-2,5,0,STATIONARY_LAVA)
Block(-2,5,1,STATIONARY_LAVA)
Block(-2,5,2,STATIONARY_LAVA)
Block(-2,5,3,STATIONARY_LAVA)
Block(-2,5,4,STATIONARY_LAVA)
Block(-2,5,5,OBSIDIAN)
Block(-2,6,-5,OBSIDIAN)
Block(-2,6,-4,NETHER_FENCE)
Block(-2,6,-3,STEP:6)
Block(-2,6,-2,STEP:6)
Block(-2,6,-1,STEP:6)
Block(-2,6,0,STEP:6)
Block(-2,6,1,STEP:6)
Block(-2,6,2,AIR)
Block(-2,6,3,AIR)
Block(-2,6,4,NETHER_FENCE)
Block(-2,6,5,OBSIDIAN)
Block(-2,7,-5,OBSIDIAN)
Block(-2,7,-4,AIR)
Block(-2,7,-3,AIR)
Block(-2,7,-2,AIR)
Block(-2,7,-1,AIR)
Block(-2,7,0,AIR)
Block(-2,7,1,AIR)
Block(-2,7,2,AIR)
Block(-2,7,3,AIR)
Block(-2,7,4,AIR)
Block(-2,7,5,OBSIDIAN)
Block(-2,8,-5,OBSIDIAN)
Block(-2,8,-4,AIR)
Block(-2,8,-3,AIR)
Block(-2,8,-2,AIR)
Block(-2,8,-1,AIR)
Block(-2,8,0,AIR)
Block(-2,8,1,STEP:14)
Block(-2,8,2,STEP:6)
Block(-2,8,3,STEP:6)
Block(-2,8,4,AIR)
Block(-2,8,5,OBSIDIAN)
Block(-2,9,-5,OBSIDIAN)
Block(-2,9,-4,AIR)
Block(-2,9,-3,AIR)
Block(-2,9,-2,AIR)
Block(-2,9,-1,STEP:14)
Block(-2,9,0,STEP:6)
Block(-2,9,1,AIR)
Block(-2,9,2,AIR)
Block(-2,9,3,AIR)
Block(-2,9,4,AIR)
Block(-2,9,5,OBSIDIAN)
Block(-2,10,-5,OBSIDIAN)
Block(-2,10,-4,NETHER_FENCE)
Block(-2,10,-3,STEP:6)
Block(-2,10,-2,STEP:6)
Block(-2,10,-1,AIR)
Block(-2,10,0,AIR)
Block(-2,10,1,AIR)
Block(-2,10,2,AIR)
Block(-2,10,3,AIR)
Block(-2,10,4,NETHER_FENCE)
Block(-2,10,5,OBSIDIAN)
Block(-2,11,-4,OBSIDIAN)
Block(-2,11,-3,AIR)
Block(-2,11,-2,AIR)
Block(-2,11,-1,AIR)
Block(-2,11,0,AIR)
Block(-2,11,1,AIR)
Block(-2,11,2,AIR)
Block(-2,11,3,AIR)
Block(-2,11,4,OBSIDIAN)
Block(-2,12,-4,NETHER_BRICK)
Block(-2,12,-3,AIR)
Block(-2,12,-2,AIR)
Block(-2,12,-1,AIR)
Block(-2,12,0,AIR)
Block(-2,12,1,AIR)
Block(-2,12,2,AIR)
Block(-2,12,3,AIR)
Block(-2,12,4,NETHER_BRICK)
Block(-2,13,-4,NETHER_BRICK)
Block(-2,13,-3,AIR)
Block(-2,13,-2,AIR)
Block(-2,13,-1,AIR)
Block(-2,13,0,AIR)
Block(-2,13,1,AIR)
Block(-2,13,2,AIR)
Block(-2,13,3,AIR)
Block(-2,13,4,NETHER_BRICK)
Block(-2,14,-4,NETHER_BRICK)
Block(-2,14,-3,AIR)
Block(-2,14,-2,AIR)
Block(-2,14,-1,AIR)
Block(-2,14,0,AIR)
Block(-2,14,1,AIR)
Block(-2,14,2,AIR)
Block(-2,14,3,AIR)
Block(-2,14,4,NETHER_BRICK)
Block(-2,15,-4,OBSIDIAN)
Block(-2,15,-3,AIR)
Block(-2,15,-2,AIR)
Block(-2,15,-1,AIR)
Block(-2,15,0,AIR)
Block(-2,15,1,AIR)
Block(-2,15,2,AIR)
Block(-2,15,3,AIR)
Block(-2,15,4,OBSIDIAN)
Block(-1,0,-5,NETHER_BRICK)
Block(-1,0,-4,NETHER_BRICK)
Block(-1,0,-3,NETHER_BRICK)
Block(-1,0,-2,NETHER_BRICK)
Block(-1,0,-1,NETHER_BRICK)
Block(-1,0,0,NETHER_BRICK)
Block(-1,0,1,NETHER_BRICK)
Block(-1,0,2,NETHER_BRICK)
Block(-1,0,3,NETHER_BRICK)
Block(-1,0,4,NETHER_BRICK)
Block(-1,0,5,NETHER_BRICK)
Block(-1,1,-6,NETHER_BRICK)
Block(-1,1,-5,STATIONARY_LAVA)
Block(-1,1,-4,STATIONARY_LAVA)
Block(-1,1,-3,STATIONARY_LAVA)
Block(-1,1,-2,STATIONARY_LAVA)
Block(-1,1,-1,STATIONARY_LAVA)
Block(-1,1,0,STATIONARY_LAVA)
Block(-1,1,1,STATIONARY_LAVA)
Block(-1,1,2,STATIONARY_LAVA)
Block(-1,1,3,STATIONARY_LAVA)
Block(-1,1,4,STATIONARY_LAVA)
Block(-1,1,5,STATIONARY_LAVA)
Block(-1,1,6,NETHER_BRICK)
Block(-1,2,-6,NETHER_BRICK)
Block(-1,2,-5,STATIONARY_LAVA)
Block(-1,2,-4,STATIONARY_LAVA)
Block(-1,2,-3,STATIONARY_LAVA)
Block(-1,2,-2,STATIONARY_LAVA)
Block(-1,2,-1,STATIONARY_LAVA)
Block(-1,2,0,STATIONARY_LAVA)
Block(-1,2,1,STATIONARY_LAVA)
Block(-1,2,2,STATIONARY_LAVA)
Block(-1,2,3,STATIONARY_LAVA)
Block(-1,2,4,STATIONARY_LAVA)
Block(-1,2,5,STATIONARY_LAVA)
Block(-1,2,6,NETHER_BRICK)
Block(-1,3,-6,NETHER_BRICK)
Block(-1,3,-5,STATIONARY_LAVA)
Block(-1,3,-4,STATIONARY_LAVA)
Block(-1,3,-3,STATIONARY_LAVA)
Block(-1,3,-2,STATIONARY_LAVA)
Block(-1,3,-1,STATIONARY_LAVA)
Block(-1,3,0,STATIONARY_LAVA)
Block(-1,3,1,STATIONARY_LAVA)
Block(-1,3,2,STATIONARY_LAVA)
Block(-1,3,3,STATIONARY_LAVA)
Block(-1,3,4,STATIONARY_LAVA)
Block(-1,3,5,STATIONARY_LAVA)
Block(-1,3,6,NETHER_BRICK)
Block(-1,4,-6,NETHER_BRICK)
Block(-1,4,-5,STATIONARY_LAVA)
Block(-1,4,-4,STATIONARY_LAVA)
Block(-1,4,-3,STATIONARY_LAVA)
Block(-1,4,-2,STATIONARY_LAVA)
Block(-1,4,-1,STATIONARY_LAVA)
Block(-1,4,0,STATIONARY_LAVA)
Block(-1,4,1,STATIONARY_LAVA)
Block(-1,4,2,STATIONARY_LAVA)
Block(-1,4,3,STATIONARY_LAVA)
Block(-1,4,4,STATIONARY_LAVA)
Block(-1,4,5,STATIONARY_LAVA)
Block(-1,4,6,NETHER_BRICK)
Block(-1,5,-6,NETHER_BRICK)
Block(-1,5,-5,STATIONARY_LAVA)
Block(-1,5,-4,STATIONARY_LAVA)
Block(-1,5,-3,STATIONARY_LAVA)
Block(-1,5,-2,STATIONARY_LAVA)
Block(-1,5,-1,STATIONARY_LAVA)
Block(-1,5,0,STATIONARY_LAVA)
Block(-1,5,1,STATIONARY_LAVA)
Block(-1,5,2,STATIONARY_LAVA)
Block(-1,5,3,STATIONARY_LAVA)
Block(-1,5,4,STATIONARY_LAVA)
Block(-1,5,5,STATIONARY_LAVA)
Block(-1,5,6,NETHER_BRICK)
Block(-1,6,-6,NETHER_BRICK)
Block(-1,6,-5,AIR)
Block(-1,6,-4,NETHER_FENCE)
Block(-1,6,-3,STEP:6)
Block(-1,6,-2,STEP:6)
Block(-1,6,-1,STEP:14)
Block(-1,6,0,STEP:14)
Block(-1,6,1,STEP:14)
Block(-1,6,2,AIR)
Block(-1,6,3,AIR)
Block(-1,6,4,NETHER_FENCE)
Block(-1,6,5,AIR)
Block(-1,6,6,NETHER_BRICK)
Block(-1,7,-6,NETHER_BRICK)
Block(-1,7,-5,AIR)
Block(-1,7,-4,AIR)
Block(-1,7,-3,AIR)
Block(-1,7,-2,AIR)
Block(-1,7,-1,NETHER_BRICK_STAIRS:6)
Block(-1,7,0,NETHER_BRICK_STAIRS:4)
Block(-1,7,1,NETHER_BRICK_STAIRS:4)
Block(-1,7,2,STEP:14)
Block(-1,7,3,STEP:14)
Block(-1,7,4,AIR)
Block(-1,7,5,AIR)
Block(-1,7,6,NETHER_BRICK)
Block(-1,8,-6,NETHER_BRICK)
Block(-1,8,-5,AIR)
Block(-1,8,-4,AIR)
Block(-1,8,-3,AIR)
Block(-1,8,-2,AIR)
Block(-1,8,-1,NETHER_FENCE)
Block(-1,8,0,AIR)
Block(-1,8,1,NETHER_FENCE)
Block(-1,8,2,AIR)
Block(-1,8,3,AIR)
Block(-1,8,4,AIR)
Block(-1,8,5,AIR)
Block(-1,8,6,NETHER_BRICK)
Block(-1,9,-6,NETHER_BRICK)
Block(-1,9,-5,AIR)
Block(-1,9,-4,AIR)
Block(-1,9,-3,AIR)
Block(-1,9,-2,AIR)
Block(-1,9,-1,AIR)
Block(-1,9,0,AIR)
Block(-1,9,1,AIR)
Block(-1,9,2,AIR)
Block(-1,9,3,AIR)
Block(-1,9,4,AIR)
Block(-1,9,5,AIR)
Block(-1,9,6,NETHER_BRICK)
Block(-1,10,-6,NETHER_BRICK_STAIRS:2)
Block(-1,10,-5,NETHER_BRICK)
Block(-1,10,-4,NETHER_FENCE)
Block(-1,10,-3,STEP:14)
Block(-1,10,-2,STEP:14)
Block(-1,10,-1,AIR)
Block(-1,10,0,AIR)
Block(-1,10,1,AIR)
Block(-1,10,2,AIR)
Block(-1,10,3,AIR)
Block(-1,10,4,NETHER_FENCE)
Block(-1,10,5,NETHER_BRICK)
Block(-1,10,6,NETHER_BRICK_STAIRS:3)
Block(-1,11,-5,NETHER_BRICK)
Block(-1,11,-4,NETHER_BRICK_STAIRS:7)
Block(-1,11,-3,AIR)
Block(-1,11,-2,AIR)
Block(-1,11,-1,NETHER_FENCE)
Block(-1,11,0,NETHER_FENCE)
Block(-1,11,1,NETHER_FENCE)
Block(-1,11,2,AIR)
Block(-1,11,3,AIR)
Block(-1,11,4,NETHER_BRICK_STAIRS:6)
Block(-1,11,5,NETHER_BRICK)
Block(-1,12,-5,NETHER_BRICK)
Block(-1,12,-4,NETHER_FENCE)
Block(-1,12,-3,AIR)
Block(-1,12,-2,AIR)
Block(-1,12,-1,AIR)
Block(-1,12,0,AIR)
Block(-1,12,1,AIR)
Block(-1,12,2,AIR)
Block(-1,12,3,AIR)
Block(-1,12,4,NETHER_FENCE)
Block(-1,12,5,NETHER_BRICK)
Block(-1,13,-5,NETHER_BRICK)
Block(-1,13,-4,NETHER_FENCE)
Block(-1,13,-3,AIR)
Block(-1,13,-2,AIR)
Block(-1,13,-1,AIR)
Block(-1,13,0,AIR)
Block(-1,13,1,AIR)
Block(-1,13,2,AIR)
Block(-1,13,3,AIR)
Block(-1,13,4,NETHER_FENCE)
Block(-1,13,5,NETHER_BRICK)
Block(-1,14,-5,NETHER_BRICK_STAIRS:2)
Block(-1,14,-4,NETHER_BRICK)
Block(-1,14,-3,NETHER_BRICK_STAIRS:7)
Block(-1,14,-2,AIR)
Block(-1,14,-1,AIR)
Block(-1,14,0,AIR)
Block(-1,14,1,AIR)
Block(-1,14,2,AIR)
Block(-1,14,3,NETHER_BRICK_STAIRS:6)
Block(-1,14,4,NETHER_BRICK)
Block(-1,14,5,NETHER_BRICK_STAIRS:3)
Block(-1,15,-4,NETHER_BRICK)
Block(-1,15,-3,REDSTONE_TORCH_ON:5)
Block(-1,15,-2,AIR)
Block(-1,15,-1,AIR)
Block(-1,15,0,AIR)
Block(-1,15,1,AIR)
Block(-1,15,2,STEP:14)
Block(-1,15,3,STEP:14)
Block(-1,15,4,NETHER_BRICK)
Block(0,0,-5,NETHER_BRICK)
Block(0,0,-4,NETHER_BRICK)
Block(0,0,-3,NETHER_BRICK)
Block(0,0,-2,NETHER_BRICK)
Block(0,0,-1,NETHER_BRICK)
Block(0,0,0,NETHER_BRICK)
Block(0,0,1,NETHER_BRICK)
Block(0,0,2,NETHER_BRICK)
Block(0,0,3,NETHER_BRICK)
Block(0,0,4,NETHER_BRICK)
Block(0,0,5,NETHER_BRICK)
Block(0,1,-6,NETHER_BRICK)
Block(0,1,-5,STATIONARY_LAVA)
Block(0,1,-4,STATIONARY_LAVA)
Block(0,1,-3,STATIONARY_LAVA)
Block(0,1,-2,STATIONARY_LAVA)
Block(0,1,-1,STATIONARY_LAVA)
Block(0,1,0,STATIONARY_LAVA)
Block(0,1,1,STATIONARY_LAVA)
Block(0,1,2,STATIONARY_LAVA)
Block(0,1,3,STATIONARY_LAVA)
Block(0,1,4,STATIONARY_LAVA)
Block(0,1,5,STATIONARY_LAVA)
Block(0,1,6,NETHER_BRICK)
Block(0,2,-6,NETHER_BRICK)
Block(0,2,-5,STATIONARY_LAVA)
Block(0,2,-4,STATIONARY_LAVA)
Block(0,2,-3,STATIONARY_LAVA)
Block(0,2,-2,STATIONARY_LAVA)
Block(0,2,-1,STATIONARY_LAVA)
Block(0,2,0,STATIONARY_LAVA)
Block(0,2,1,STATIONARY_LAVA)
Block(0,2,2,STATIONARY_LAVA)
Block(0,2,3,STATIONARY_LAVA)
Block(0,2,4,STATIONARY_LAVA)
Block(0,2,5,STATIONARY_LAVA)
Block(0,2,6,NETHER_BRICK)
Block(0,3,-6,NETHER_BRICK)
Block(0,3,-5,STATIONARY_LAVA)
Block(0,3,-4,STATIONARY_LAVA)
Block(0,3,-3,STATIONARY_LAVA)
Block(0,3,-2,STATIONARY_LAVA)
Block(0,3,-1,STATIONARY_LAVA)
Block(0,3,0,STATIONARY_LAVA)
Block(0,3,1,STATIONARY_LAVA)
Block(0,3,2,STATIONARY_LAVA)
Block(0,3,3,STATIONARY_LAVA)
Block(0,3,4,STATIONARY_LAVA)
Block(0,3,5,STATIONARY_LAVA)
Block(0,3,6,NETHER_BRICK)
Block(0,4,-6,NETHER_BRICK)
Block(0,4,-5,STATIONARY_LAVA)
Block(0,4,-4,STATIONARY_LAVA)
Block(0,4,-3,STATIONARY_LAVA)
Block(0,4,-2,STATIONARY_LAVA)
Block(0,4,-1,STATIONARY_LAVA)
Block(0,4,0,STATIONARY_LAVA)
Block(0,4,1,STATIONARY_LAVA)
Block(0,4,2,STATIONARY_LAVA)
Block(0,4,3,STATIONARY_LAVA)
Block(0,4,4,STATIONARY_LAVA)
Block(0,4,5,STATIONARY_LAVA)
Block(0,4,6,NETHER_BRICK)
Block(0,5,-6,NETHER_BRICK)
Block(0,5,-5,STATIONARY_LAVA)
Block(0,5,-4,STATIONARY_LAVA)
Block(0,5,-3,STATIONARY_LAVA)
Block(0,5,-2,STATIONARY_LAVA)
Block(0,5,-1,STATIONARY_LAVA)
Block(0,5,0,STATIONARY_LAVA)
Block(0,5,1,STATIONARY_LAVA)
Block(0,5,2,STATIONARY_LAVA)
Block(0,5,3,STATIONARY_LAVA)
Block(0,5,4,STATIONARY_LAVA)
Block(0,5,5,STATIONARY_LAVA)
Block(0,5,6,NETHER_BRICK)
Block(0,6,-6,NETHER_BRICK)
Block(0,6,-5,AIR)
Block(0,6,-4,NETHER_FENCE)
Block(0,6,-3,STEP:6)
Block(0,6,-2,STEP:6)
Block(0,6,-1,STEP:14)
Block(0,6,0,STATIONARY_LAVA:8)
Block(0,6,1,STEP:14)
Block(0,6,2,AIR)
Block(0,6,3,AIR)
Block(0,6,4,NETHER_FENCE)
Block(0,6,5,AIR)
Block(0,6,6,NETHER_BRICK)
Block(0,7,-6,NETHER_BRICK)
Block(0,7,-5,AIR)
Block(0,7,-4,AIR)
Block(0,7,-3,AIR)
Block(0,7,-2,AIR)
Block(0,7,-1,NETHER_BRICK_STAIRS:6)
Block(0,7,0,STATIONARY_LAVA:8)
Block(0,7,1,NETHER_BRICK_STAIRS:7)
Block(0,7,2,STEP:6)
Block(0,7,3,STEP:6)
Block(0,7,4,AIR)
Block(0,7,5,AIR)
Block(0,7,6,NETHER_BRICK)
Block(0,8,-6,NETHER_BRICK)
Block(0,8,-5,AIR)
Block(0,8,-4,AIR)
Block(0,8,-3,AIR)
Block(0,8,-2,AIR)
Block(0,8,-1,AIR)
Block(0,8,0,STATIONARY_LAVA:8)
Block(0,8,1,AIR)
Block(0,8,2,AIR)
Block(0,8,3,AIR)
Block(0,8,4,AIR)
Block(0,8,5,AIR)
Block(0,8,6,NETHER_BRICK)
Block(0,9,-6,NETHER_BRICK)
Block(0,9,-5,AIR)
Block(0,9,-4,AIR)
Block(0,9,-3,AIR)
Block(0,9,-2,AIR)
Block(0,9,-1,AIR)
Block(0,9,0,STATIONARY_LAVA:8)
Block(0,9,1,AIR)
Block(0,9,2,AIR)
Block(0,9,3,AIR)
Block(0,9,4,AIR)
Block(0,9,5,AIR)
Block(0,9,6,NETHER_BRICK)
Block(0,10,-6,NETHER_BRICK_STAIRS:2)
Block(0,10,-5,NETHER_BRICK)
Block(0,10,-4,NETHER_BRICK_STAIRS:7)
Block(0,10,-3,AIR)
Block(0,10,-2,AIR)
Block(0,10,-1,AIR)
Block(0,10,0,STATIONARY_LAVA:8)
Block(0,10,1,AIR)
Block(0,10,2,AIR)
Block(0,10,3,AIR)
Block(0,10,4,NETHER_BRICK_STAIRS:6)
Block(0,10,5,NETHER_BRICK)
Block(0,10,6,NETHER_BRICK_STAIRS:3)
Block(0,11,-5,NETHER_BRICK)
Block(0,11,-4,NETHER_BRICK)
Block(0,11,-3,STEP:6)
Block(0,11,-2,STEP:6)
Block(0,11,-1,NETHER_FENCE)
Block(0,11,0,STATIONARY_LAVA:8)
Block(0,11,1,NETHER_FENCE)
Block(0,11,2,AIR)
Block(0,11,3,AIR)
Block(0,11,4,NETHER_BRICK)
Block(0,11,5,NETHER_BRICK)
Block(0,12,-5,NETHER_BRICK)
Block(0,12,-4,NETHER_FENCE)
Block(0,12,-3,AIR)
Block(0,12,-2,AIR)
Block(0,12,-1,AIR)
Block(0,12,0,STATIONARY_LAVA:8)
Block(0,12,1,AIR)
Block(0,12,2,AIR)
Block(0,12,3,AIR)
Block(0,12,4,NETHER_FENCE)
Block(0,12,5,NETHER_BRICK)
Block(0,13,-5,NETHER_BRICK)
Block(0,13,-4,NETHER_FENCE)
Block(0,13,-3,AIR)
Block(0,13,-2,AIR)
Block(0,13,-1,AIR)
Block(0,13,0,STATIONARY_LAVA:8)
Block(0,13,1,AIR)
Block(0,13,2,AIR)
Block(0,13,3,AIR)
Block(0,13,4,NETHER_FENCE)
Block(0,13,5,NETHER_BRICK)
Block(0,14,-5,NETHER_BRICK)
Block(0,14,-4,NETHER_BRICK)
Block(0,14,-3,AIR)
Block(0,14,-2,AIR)
Block(0,14,-1,AIR)
Block(0,14,0,STATIONARY_LAVA:8)
Block(0,14,1,AIR)
Block(0,14,2,AIR)
Block(0,14,3,AIR)
Block(0,14,4,NETHER_BRICK)
Block(0,14,5,NETHER_BRICK)
Block(0,15,-5,NETHER_BRICK_STAIRS:2)
Block(0,15,-4,NETHER_BRICK)
Block(0,15,-3,AIR)
Block(0,15,-2,AIR)
Block(0,15,-1,AIR)
Block(0,15,0,STATIONARY_LAVA:8)
Block(0,15,1,AIR)
Block(0,15,2,STEP:6)
Block(0,15,3,STEP:6)
Block(0,15,4,NETHER_BRICK)
Block(0,15,5,NETHER_BRICK_STAIRS:3)
Block(1,0,-5,NETHER_BRICK)
Block(1,0,-4,NETHER_BRICK)
Block(1,0,-3,NETHER_BRICK)
Block(1,0,-2,NETHER_BRICK)
Block(1,0,-1,NETHER_BRICK)
Block(1,0,0,NETHER_BRICK)
Block(1,0,1,NETHER_BRICK)
Block(1,0,2,NETHER_BRICK)
Block(1,0,3,NETHER_BRICK)
Block(1,0,4,NETHER_BRICK)
Block(1,0,5,NETHER_BRICK)
Block(1,1,-6,NETHER_BRICK)
Block(1,1,-5,STATIONARY_LAVA)
Block(1,1,-4,STATIONARY_LAVA)
Block(1,1,-3,STATIONARY_LAVA)
Block(1,1,-2,STATIONARY_LAVA)
Block(1,1,-1,STATIONARY_LAVA)
Block(1,1,0,STATIONARY_LAVA)
Block(1,1,1,STATIONARY_LAVA)
Block(1,1,2,STATIONARY_LAVA)
Block(1,1,3,STATIONARY_LAVA)
Block(1,1,4,STATIONARY_LAVA)
Block(1,1,5,STATIONARY_LAVA)
Block(1,1,6,NETHER_BRICK)
Block(1,2,-6,NETHER_BRICK)
Block(1,2,-5,STATIONARY_LAVA)
Block(1,2,-4,STATIONARY_LAVA)
Block(1,2,-3,STATIONARY_LAVA)
Block(1,2,-2,STATIONARY_LAVA)
Block(1,2,-1,STATIONARY_LAVA)
Block(1,2,0,STATIONARY_LAVA)
Block(1,2,1,STATIONARY_LAVA)
Block(1,2,2,STATIONARY_LAVA)
Block(1,2,3,STATIONARY_LAVA)
Block(1,2,4,STATIONARY_LAVA)
Block(1,2,5,STATIONARY_LAVA)
Block(1,2,6,NETHER_BRICK)
Block(1,3,-6,NETHER_BRICK)
Block(1,3,-5,STATIONARY_LAVA)
Block(1,3,-4,STATIONARY_LAVA)
Block(1,3,-3,STATIONARY_LAVA)
Block(1,3,-2,STATIONARY_LAVA)
Block(1,3,-1,STATIONARY_LAVA)
Block(1,3,0,STATIONARY_LAVA)
Block(1,3,1,STATIONARY_LAVA)
Block(1,3,2,STATIONARY_LAVA)
Block(1,3,3,STATIONARY_LAVA)
Block(1,3,4,STATIONARY_LAVA)
Block(1,3,5,STATIONARY_LAVA)
Block(1,3,6,NETHER_BRICK)
Block(1,4,-6,NETHER_BRICK)
Block(1,4,-5,STATIONARY_LAVA)
Block(1,4,-4,STATIONARY_LAVA)
Block(1,4,-3,STATIONARY_LAVA)
Block(1,4,-2,STATIONARY_LAVA)
Block(1,4,-1,STATIONARY_LAVA)
Block(1,4,0,STATIONARY_LAVA)
Block(1,4,1,STATIONARY_LAVA)
Block(1,4,2,STATIONARY_LAVA)
Block(1,4,3,STATIONARY_LAVA)
Block(1,4,4,STATIONARY_LAVA)
Block(1,4,5,STATIONARY_LAVA)
Block(1,4,6,NETHER_BRICK)
Block(1,5,-6,NETHER_BRICK)
Block(1,5,-5,STATIONARY_LAVA)
Block(1,5,-4,STATIONARY_LAVA)
Block(1,5,-3,STATIONARY_LAVA)
Block(1,5,-2,STATIONARY_LAVA)
Block(1,5,-1,STATIONARY_LAVA)
Block(1,5,0,STATIONARY_LAVA)
Block(1,5,1,STATIONARY_LAVA)
Block(1,5,2,STATIONARY_LAVA)
Block(1,5,3,STATIONARY_LAVA)
Block(1,5,4,STATIONARY_LAVA)
Block(1,5,5,STATIONARY_LAVA)
Block(1,5,6,NETHER_BRICK)
Block(1,6,-6,NETHER_BRICK)
Block(1,6,-5,AIR)
Block(1,6,-4,NETHER_FENCE)
Block(1,6,-3,STEP:6)
Block(1,6,-2,STEP:6)
Block(1,6,-1,STEP:14)
Block(1,6,0,STEP:14)
Block(1,6,1,STEP:14)
Block(1,6,2,STEP:14)
Block(1,6,3,STEP:14)
Block(1,6,4,NETHER_FENCE)
Block(1,6,5,AIR)
Block(1,6,6,NETHER_BRICK)
Block(1,7,-6,NETHER_BRICK)
Block(1,7,-5,AIR)
Block(1,7,-4,AIR)
Block(1,7,-3,AIR)
Block(1,7,-2,AIR)
Block(1,7,-1,NETHER_BRICK_STAIRS:5)
Block(1,7,0,NETHER_BRICK_STAIRS:5)
Block(1,7,1,NETHER_BRICK_STAIRS:7)
Block(1,7,2,AIR)
Block(1,7,3,AIR)
Block(1,7,4,AIR)
Block(1,7,5,AIR)
Block(1,7,6,NETHER_BRICK)
Block(1,8,-6,NETHER_BRICK)
Block(1,8,-5,AIR)
Block(1,8,-4,AIR)
Block(1,8,-3,AIR)
Block(1,8,-2,AIR)
Block(1,8,-1,NETHER_FENCE)
Block(1,8,0,AIR)
Block(1,8,1,NETHER_FENCE)
Block(1,8,2,AIR)
Block(1,8,3,AIR)
Block(1,8,4,AIR)
Block(1,8,5,AIR)
Block(1,8,6,NETHER_BRICK)
Block(1,9,-6,NETHER_BRICK)
Block(1,9,-5,AIR)
Block(1,9,-4,AIR)
Block(1,9,-3,AIR)
Block(1,9,-2,AIR)
Block(1,9,-1,AIR)
Block(1,9,0,AIR)
Block(1,9,1,AIR)
Block(1,9,2,AIR)
Block(1,9,3,AIR)
Block(1,9,4,AIR)
Block(1,9,5,AIR)
Block(1,9,6,NETHER_BRICK)
Block(1,10,-6,NETHER_BRICK_STAIRS:2)
Block(1,10,-5,NETHER_BRICK)
Block(1,10,-4,NETHER_FENCE)
Block(1,10,-3,AIR)
Block(1,10,-2,AIR)
Block(1,10,-1,AIR)
Block(1,10,0,AIR)
Block(1,10,1,AIR)
Block(1,10,2,AIR)
Block(1,10,3,AIR)
Block(1,10,4,NETHER_FENCE)
Block(1,10,5,NETHER_BRICK)
Block(1,10,6,NETHER_BRICK_STAIRS:3)
Block(1,11,-5,NETHER_BRICK)
Block(1,11,-4,NETHER_BRICK_STAIRS:7)
Block(1,11,-3,STEP:14)
Block(1,11,-2,STEP:14)
Block(1,11,-1,NETHER_FENCE)
Block(1,11,0,NETHER_FENCE)
Block(1,11,1,NETHER_FENCE)
Block(1,11,2,AIR)
Block(1,11,3,AIR)
Block(1,11,4,NETHER_BRICK_STAIRS:6)
Block(1,11,5,NETHER_BRICK)
Block(1,12,-5,NETHER_BRICK)
Block(1,12,-4,NETHER_FENCE)
Block(1,12,-3,AIR)
Block(1,12,-2,AIR)
Block(1,12,-1,AIR)
Block(1,12,0,AIR)
Block(1,12,1,AIR)
Block(1,12,2,AIR)
Block(1,12,3,AIR)
Block(1,12,4,NETHER_FENCE)
Block(1,12,5,NETHER_BRICK)
Block(1,13,-5,NETHER_BRICK)
Block(1,13,-4,NETHER_FENCE)
Block(1,13,-3,AIR)
Block(1,13,-2,AIR)
Block(1,13,-1,AIR)
Block(1,13,0,AIR)
Block(1,13,1,AIR)
Block(1,13,2,AIR)
Block(1,13,3,AIR)
Block(1,13,4,NETHER_FENCE)
Block(1,13,5,NETHER_BRICK)
Block(1,14,-5,NETHER_BRICK_STAIRS:2)
Block(1,14,-4,NETHER_BRICK)
Block(1,14,-3,NETHER_BRICK_STAIRS:7)
Block(1,14,-2,AIR)
Block(1,14,-1,AIR)
Block(1,14,0,AIR)
Block(1,14,1,AIR)
Block(1,14,2,STEP:14)
Block(1,14,3,NETHER_BRICK_STAIRS:6)
Block(1,14,4,NETHER_BRICK)
Block(1,14,5,NETHER_BRICK_STAIRS:3)
Block(1,15,-4,NETHER_BRICK)
Block(1,15,-3,REDSTONE_TORCH_ON:5)
Block(1,15,-2,AIR)
Block(1,15,-1,AIR)
Block(1,15,0,AIR)
Block(1,15,1,AIR)
Block(1,15,2,AIR)
Block(1,15,3,AIR)
Block(1,15,4,NETHER_BRICK)
Block(2,0,-4,NETHER_BRICK)
Block(2,0,-3,NETHER_BRICK)
Block(2,0,-2,NETHER_BRICK)
Block(2,0,-1,NETHER_BRICK)
Block(2,0,0,NETHER_BRICK)
Block(2,0,1,NETHER_BRICK)
Block(2,0,2,NETHER_BRICK)
Block(2,0,3,NETHER_BRICK)
Block(2,0,4,NETHER_BRICK)
Block(2,1,-5,OBSIDIAN)
Block(2,1,-4,STATIONARY_LAVA)
Block(2,1,-3,STATIONARY_LAVA)
Block(2,1,-2,STATIONARY_LAVA)
Block(2,1,-1,STATIONARY_LAVA)
Block(2,1,0,STATIONARY_LAVA)
Block(2,1,1,STATIONARY_LAVA)
Block(2,1,2,STATIONARY_LAVA)
Block(2,1,3,STATIONARY_LAVA)
Block(2,1,4,STATIONARY_LAVA)
Block(2,1,5,OBSIDIAN)
Block(2,2,-5,OBSIDIAN)
Block(2,2,-4,STATIONARY_LAVA)
Block(2,2,-3,STATIONARY_LAVA)
Block(2,2,-2,STATIONARY_LAVA)
Block(2,2,-1,STATIONARY_LAVA)
Block(2,2,0,STATIONARY_LAVA)
Block(2,2,1,STATIONARY_LAVA)
Block(2,2,2,STATIONARY_LAVA)
Block(2,2,3,STATIONARY_LAVA)
Block(2,2,4,STATIONARY_LAVA)
Block(2,2,5,OBSIDIAN)
Block(2,3,-5,OBSIDIAN)
Block(2,3,-4,STATIONARY_LAVA)
Block(2,3,-3,STATIONARY_LAVA)
Block(2,3,-2,STATIONARY_LAVA)
Block(2,3,-1,STATIONARY_LAVA)
Block(2,3,0,STATIONARY_LAVA)
Block(2,3,1,STATIONARY_LAVA)
Block(2,3,2,STATIONARY_LAVA)
Block(2,3,3,STATIONARY_LAVA)
Block(2,3,4,STATIONARY_LAVA)
Block(2,3,5,OBSIDIAN)
Block(2,4,-5,OBSIDIAN)
Block(2,4,-4,STATIONARY_LAVA)
Block(2,4,-3,STATIONARY_LAVA)
Block(2,4,-2,STATIONARY_LAVA)
Block(2,4,-1,STATIONARY_LAVA)
Block(2,4,0,STATIONARY_LAVA)
Block(2,4,1,STATIONARY_LAVA)
Block(2,4,2,STATIONARY_LAVA)
Block(2,4,3,STATIONARY_LAVA)
Block(2,4,4,STATIONARY_LAVA)
Block(2,4,5,OBSIDIAN)
Block(2,5,-5,OBSIDIAN)
Block(2,5,-4,STATIONARY_LAVA)
Block(2,5,-3,STATIONARY_LAVA)
Block(2,5,-2,STATIONARY_LAVA)
Block(2,5,-1,STATIONARY_LAVA)
Block(2,5,0,STATIONARY_LAVA)
Block(2,5,1,STATIONARY_LAVA)
Block(2,5,2,STATIONARY_LAVA)
Block(2,5,3,STATIONARY_LAVA)
Block(2,5,4,STATIONARY_LAVA)
Block(2,5,5,OBSIDIAN)
Block(2,6,-5,OBSIDIAN)
Block(2,6,-4,NETHER_FENCE)
Block(2,6,-3,STEP:6)
Block(2,6,-2,STEP:6)
Block(2,6,-1,STEP:6)
Block(2,6,0,STEP:6)
Block(2,6,1,STEP:6)
Block(2,6,2,STEP:6)
Block(2,6,3,STEP:6)
Block(2,6,4,NETHER_FENCE)
Block(2,6,5,OBSIDIAN)
Block(2,7,-5,OBSIDIAN)
Block(2,7,-4,AIR)
Block(2,7,-3,AIR)
Block(2,7,-2,AIR)
Block(2,7,-1,AIR)
Block(2,7,0,AIR)
Block(2,7,1,AIR)
Block(2,7,2,AIR)
Block(2,7,3,AIR)
Block(2,7,4,AIR)
Block(2,7,5,OBSIDIAN)
Block(2,8,-5,OBSIDIAN)
Block(2,8,-4,AIR)
Block(2,8,-3,AIR)
Block(2,8,-2,AIR)
Block(2,8,-1,AIR)
Block(2,8,0,AIR)
Block(2,8,1,AIR)
Block(2,8,2,AIR)
Block(2,8,3,AIR)
Block(2,8,4,AIR)
Block(2,8,5,OBSIDIAN)
Block(2,9,-5,OBSIDIAN)
Block(2,9,-4,AIR)
Block(2,9,-3,AIR)
Block(2,9,-2,AIR)
Block(2,9,-1,AIR)
Block(2,9,0,AIR)
Block(2,9,1,AIR)
Block(2,9,2,AIR)
Block(2,9,3,AIR)
Block(2,9,4,AIR)
Block(2,9,5,OBSIDIAN)
Block(2,10,-5,OBSIDIAN)
Block(2,10,-4,NETHER_FENCE)
Block(2,10,-3,AIR)
Block(2,10,-2,AIR)
Block(2,10,-1,AIR)
Block(2,10,0,AIR)
Block(2,10,1,AIR)
Block(2,10,2,AIR)
Block(2,10,3,AIR)
Block(2,10,4,NETHER_FENCE)
Block(2,10,5,OBSIDIAN)
Block(2,11,-4,OBSIDIAN)
Block(2,11,-3,AIR)
Block(2,11,-2,AIR)
Block(2,11,-1,AIR)
Block(2,11,0,AIR)
Block(2,11,1,AIR)
Block(2,11,2,AIR)
Block(2,11,3,AIR)
Block(2,11,4,OBSIDIAN)
Block(2,12,-4,NETHER_BRICK)
Block(2,12,-3,STEP:6)
Block(2,12,-2,STEP:6)
Block(2,12,-1,STEP:14)
Block(2,12,0,AIR)
Block(2,12,1,AIR)
Block(2,12,2,AIR)
Block(2,12,3,AIR)
Block(2,12,4,NETHER_BRICK)
Block(2,13,-4,NETHER_BRICK)
Block(2,13,-3,AIR)
Block(2,13,-2,AIR)
Block(2,13,-1,AIR)
Block(2,13,0,STEP:6)
Block(2,13,1,STEP:14)
Block(2,13,2,AIR)
Block(2,13,3,AIR)
Block(2,13,4,NETHER_BRICK)
Block(2,14,-4,NETHER_BRICK)
Block(2,14,-3,AIR)
Block(2,14,-2,AIR)
Block(2,14,-1,AIR)
Block(2,14,0,AIR)
Block(2,14,1,AIR)
Block(2,14,2,STEP:6)
Block(2,14,3,STEP:6)
Block(2,14,4,NETHER_BRICK)
Block(2,15,-4,OBSIDIAN)
Block(2,15,-3,AIR)
Block(2,15,-2,AIR)
Block(2,15,-1,AIR)
Block(2,15,0,AIR)
Block(2,15,1,AIR)
Block(2,15,2,AIR)
Block(2,15,3,AIR)
Block(2,15,4,OBSIDIAN)
Block(3,0,-4,NETHER_BRICK)
Block(3,0,-3,NETHER_BRICK)
Block(3,0,-2,NETHER_BRICK)
Block(3,0,-1,NETHER_BRICK)
Block(3,0,0,NETHER_BRICK)
Block(3,0,1,NETHER_BRICK)
Block(3,0,2,NETHER_BRICK)
Block(3,0,3,NETHER_BRICK)
Block(3,0,4,NETHER_BRICK)
Block(3,1,-5,NETHER_BRICK)
Block(3,1,-4,STATIONARY_LAVA)
Block(3,1,-3,STATIONARY_LAVA)
Block(3,1,-2,STATIONARY_LAVA)
Block(3,1,-1,STATIONARY_LAVA)
Block(3,1,0,STATIONARY_LAVA)
Block(3,1,1,STATIONARY_LAVA)
Block(3,1,2,STATIONARY_LAVA)
Block(3,1,3,STATIONARY_LAVA)
Block(3,1,4,STATIONARY_LAVA)
Block(3,1,5,NETHER_BRICK)
Block(3,2,-5,NETHER_BRICK)
Block(3,2,-4,STATIONARY_LAVA)
Block(3,2,-3,STATIONARY_LAVA)
Block(3,2,-2,STATIONARY_LAVA)
Block(3,2,-1,STATIONARY_LAVA)
Block(3,2,0,STATIONARY_LAVA)
Block(3,2,1,STATIONARY_LAVA)
Block(3,2,2,STATIONARY_LAVA)
Block(3,2,3,STATIONARY_LAVA)
Block(3,2,4,STATIONARY_LAVA)
Block(3,2,5,NETHER_BRICK)
Block(3,3,-5,NETHER_BRICK)
Block(3,3,-4,STATIONARY_LAVA)
Block(3,3,-3,STATIONARY_LAVA)
Block(3,3,-2,STATIONARY_LAVA)
Block(3,3,-1,STATIONARY_LAVA)
Block(3,3,0,STATIONARY_LAVA)
Block(3,3,1,STATIONARY_LAVA)
Block(3,3,2,STATIONARY_LAVA)
Block(3,3,3,STATIONARY_LAVA)
Block(3,3,4,STATIONARY_LAVA)
Block(3,3,5,NETHER_BRICK)
Block(3,4,-5,NETHER_BRICK)
Block(3,4,-4,STATIONARY_LAVA)
Block(3,4,-3,STATIONARY_LAVA)
Block(3,4,-2,STATIONARY_LAVA)
Block(3,4,-1,STATIONARY_LAVA)
Block(3,4,0,STATIONARY_LAVA)
Block(3,4,1,STATIONARY_LAVA)
Block(3,4,2,STATIONARY_LAVA)
Block(3,4,3,STATIONARY_LAVA)
Block(3,4,4,STATIONARY_LAVA)
Block(3,4,5,NETHER_BRICK)
Block(3,5,-5,NETHER_BRICK)
Block(3,5,-4,STATIONARY_LAVA)
Block(3,5,-3,STATIONARY_LAVA)
Block(3,5,-2,STATIONARY_LAVA)
Block(3,5,-1,STATIONARY_LAVA)
Block(3,5,0,STATIONARY_LAVA)
Block(3,5,1,STATIONARY_LAVA)
Block(3,5,2,STATIONARY_LAVA)
Block(3,5,3,STATIONARY_LAVA)
Block(3,5,4,STATIONARY_LAVA)
Block(3,5,5,NETHER_BRICK)
Block(3,6,-5,NETHER_BRICK)
Block(3,6,-4,NETHER_FENCE)
Block(3,6,-3,STEP:6)
Block(3,6,-2,STEP:6)
Block(3,6,-1,STEP:6)
Block(3,6,0,STEP:6)
Block(3,6,1,STEP:6)
Block(3,6,2,STEP:6)
Block(3,6,3,STEP:6)
Block(3,6,4,NETHER_FENCE)
Block(3,6,5,NETHER_BRICK)
Block(3,7,-5,NETHER_BRICK)
Block(3,7,-4,AIR)
Block(3,7,-3,AIR)
Block(3,7,-2,AIR)
Block(3,7,-1,AIR)
Block(3,7,0,AIR)
Block(3,7,1,AIR)
Block(3,7,2,AIR)
Block(3,7,3,AIR)
Block(3,7,4,AIR)
Block(3,7,5,NETHER_BRICK)
Block(3,8,-5,NETHER_BRICK)
Block(3,8,-4,AIR)
Block(3,8,-3,AIR)
Block(3,8,-2,AIR)
Block(3,8,-1,AIR)
Block(3,8,0,AIR)
Block(3,8,1,AIR)
Block(3,8,2,AIR)
Block(3,8,3,AIR)
Block(3,8,4,AIR)
Block(3,8,5,NETHER_BRICK)
Block(3,9,-5,NETHER_BRICK)
Block(3,9,-4,AIR)
Block(3,9,-3,AIR)
Block(3,9,-2,AIR)
Block(3,9,-1,AIR)
Block(3,9,0,AIR)
Block(3,9,1,AIR)
Block(3,9,2,AIR)
Block(3,9,3,AIR)
Block(3,9,4,AIR)
Block(3,9,5,NETHER_BRICK)
Block(3,10,-5,OBSIDIAN)
Block(3,10,-4,NETHER_FENCE)
Block(3,10,-3,AIR)
Block(3,10,-2,AIR)
Block(3,10,-1,AIR)
Block(3,10,0,AIR)
Block(3,10,1,AIR)
Block(3,10,2,AIR)
Block(3,10,3,AIR)
Block(3,10,4,NETHER_FENCE)
Block(3,10,5,OBSIDIAN)
Block(3,11,-4,OBSIDIAN)
Block(3,11,-3,AIR)
Block(3,11,-2,AIR)
Block(3,11,-1,AIR)
Block(3,11,0,AIR)
Block(3,11,1,AIR)
Block(3,11,2,AIR)
Block(3,11,3,AIR)
Block(3,11,4,OBSIDIAN)
Block(3,12,-4,OBSIDIAN)
Block(3,12,-3,STEP:6)
Block(3,12,-2,STEP:6)
Block(3,12,-1,STEP:14)
Block(3,12,0,AIR)
Block(3,12,1,AIR)
Block(3,12,2,AIR)
Block(3,12,3,AIR)
Block(3,12,4,OBSIDIAN)
Block(3,13,-4,OBSIDIAN)
Block(3,13,-3,AIR)
Block(3,13,-2,AIR)
Block(3,13,-1,AIR)
Block(3,13,0,STEP:6)
Block(3,13,1,STEP:14)
Block(3,13,2,AIR)
Block(3,13,3,AIR)
Block(3,13,4,OBSIDIAN)
Block(3,14,-4,OBSIDIAN)
Block(3,14,-3,AIR)
Block(3,14,-2,AIR)
Block(3,14,-1,AIR)
Block(3,14,0,AIR)
Block(3,14,1,AIR)
Block(3,14,2,STEP:6)
Block(3,14,3,STEP:6)
Block(3,14,4,OBSIDIAN)
Block(3,15,-4,OBSIDIAN)
Block(3,15,-3,AIR)
Block(3,15,-2,AIR)
Block(3,15,-1,AIR)
Block(3,15,0,AIR)
Block(3,15,1,AIR)
Block(3,15,2,AIR)
Block(3,15,3,AIR)
Block(3,15,4,OBSIDIAN)
Block(4,0,-3,NETHER_BRICK)
Block(4,0,-2,NETHER_BRICK)
Block(4,0,-1,NETHER_BRICK)
Block(4,0,0,NETHER_BRICK)
Block(4,0,1,NETHER_BRICK)
Block(4,0,2,NETHER_BRICK)
Block(4,0,3,NETHER_BRICK)
Block(4,1,-4,OBSIDIAN)
Block(4,1,-3,STATIONARY_LAVA)
Block(4,1,-2,STATIONARY_LAVA)
Block(4,1,-1,STATIONARY_LAVA)
Block(4,1,0,STATIONARY_LAVA)
Block(4,1,1,STATIONARY_LAVA)
Block(4,1,2,STATIONARY_LAVA)
Block(4,1,3,STATIONARY_LAVA)
Block(4,1,4,OBSIDIAN)
Block(4,2,-4,OBSIDIAN)
Block(4,2,-3,STATIONARY_LAVA)
Block(4,2,-2,STATIONARY_LAVA)
Block(4,2,-1,STATIONARY_LAVA)
Block(4,2,0,STATIONARY_LAVA)
Block(4,2,1,STATIONARY_LAVA)
Block(4,2,2,STATIONARY_LAVA)
Block(4,2,3,STATIONARY_LAVA)
Block(4,2,4,OBSIDIAN)
Block(4,3,-4,OBSIDIAN)
Block(4,3,-3,STATIONARY_LAVA)
Block(4,3,-2,STATIONARY_LAVA)
Block(4,3,-1,STATIONARY_LAVA)
Block(4,3,0,STATIONARY_LAVA)
Block(4,3,1,STATIONARY_LAVA)
Block(4,3,2,STATIONARY_LAVA)
Block(4,3,3,STATIONARY_LAVA)
Block(4,3,4,OBSIDIAN)
Block(4,4,-4,OBSIDIAN)
Block(4,4,-3,STATIONARY_LAVA)
Block(4,4,-2,STATIONARY_LAVA)
Block(4,4,-1,STATIONARY_LAVA)
Block(4,4,0,STATIONARY_LAVA)
Block(4,4,1,STATIONARY_LAVA)
Block(4,4,2,STATIONARY_LAVA)
Block(4,4,3,STATIONARY_LAVA)
Block(4,4,4,OBSIDIAN)
Block(4,5,-4,OBSIDIAN)
Block(4,5,-3,STATIONARY_LAVA)
Block(4,5,-2,STATIONARY_LAVA)
Block(4,5,-1,STATIONARY_LAVA)
Block(4,5,0,STATIONARY_LAVA)
Block(4,5,1,STATIONARY_LAVA)
Block(4,5,2,STATIONARY_LAVA)
Block(4,5,3,STATIONARY_LAVA)
Block(4,5,4,OBSIDIAN)
Block(4,6,-4,OBSIDIAN)
Block(4,6,-3,NETHER_FENCE)
Block(4,6,-2,NETHER_FENCE)
Block(4,6,-1,NETHER_FENCE)
Block(4,6,0,NETHER_FENCE)
Block(4,6,1,NETHER_FENCE)
Block(4,6,2,NETHER_FENCE)
Block(4,6,3,NETHER_FENCE)
Block(4,6,4,OBSIDIAN)
Block(4,7,-4,OBSIDIAN)
Block(4,7,-3,AIR)
Block(4,7,-2,AIR)
Block(4,7,-1,AIR)
Block(4,7,0,AIR)
Block(4,7,1,AIR)
Block(4,7,2,AIR)
Block(4,7,3,AIR)
Block(4,7,4,OBSIDIAN)
Block(4,8,-4,OBSIDIAN)
Block(4,8,-3,AIR)
Block(4,8,-2,AIR)
Block(4,8,-1,AIR)
Block(4,8,0,AIR)
Block(4,8,1,AIR)
Block(4,8,2,AIR)
Block(4,8,3,AIR)
Block(4,8,4,OBSIDIAN)
Block(4,9,-4,OBSIDIAN)
Block(4,9,-3,AIR)
Block(4,9,-2,AIR)
Block(4,9,-1,AIR)
Block(4,9,0,AIR)
Block(4,9,1,AIR)
Block(4,9,2,AIR)
Block(4,9,3,AIR)
Block(4,9,4,OBSIDIAN)
Block(4,10,-4,OBSIDIAN)
Block(4,10,-3,NETHER_FENCE)
Block(4,10,-2,NETHER_FENCE)
Block(4,10,-1,NETHER_FENCE)
Block(4,10,0,NETHER_BRICK_STAIRS:4)
Block(4,10,1,NETHER_FENCE)
Block(4,10,2,NETHER_FENCE)
Block(4,10,3,NETHER_FENCE)
Block(4,10,4,OBSIDIAN)
Block(4,11,-4,NETHER_FENCE)
Block(4,11,-3,OBSIDIAN)
Block(4,11,-2,OBSIDIAN)
Block(4,11,-1,NETHER_BRICK_STAIRS:4)
Block(4,11,0,NETHER_BRICK)
Block(4,11,1,NETHER_BRICK_STAIRS:4)
Block(4,11,2,OBSIDIAN)
Block(4,11,3,OBSIDIAN)
Block(4,11,4,NETHER_FENCE)
Block(4,12,-4,NETHER_FENCE)
Block(4,12,-3,OBSIDIAN)
Block(4,12,-2,NETHER_BRICK)
Block(4,12,-1,NETHER_FENCE)
Block(4,12,0,NETHER_FENCE)
Block(4,12,1,NETHER_FENCE)
Block(4,12,2,NETHER_BRICK)
Block(4,12,3,OBSIDIAN)
Block(4,12,4,NETHER_FENCE)
Block(4,13,-3,OBSIDIAN)
Block(4,13,-2,NETHER_BRICK)
Block(4,13,-1,NETHER_FENCE)
Block(4,13,0,NETHER_FENCE)
Block(4,13,1,NETHER_FENCE)
Block(4,13,2,NETHER_BRICK)
Block(4,13,3,OBSIDIAN)
Block(4,14,-3,OBSIDIAN)
Block(4,14,-2,NETHER_BRICK)
Block(4,14,-1,NETHER_BRICK)
Block(4,14,0,NETHER_BRICK)
Block(4,14,1,NETHER_BRICK)
Block(4,14,2,NETHER_BRICK)
Block(4,14,3,OBSIDIAN)
Block(4,15,-3,OBSIDIAN)
Block(4,15,-2,OBSIDIAN)
Block(4,15,-1,NETHER_BRICK)
Block(4,15,0,NETHER_BRICK)
Block(4,15,1,NETHER_BRICK)
Block(4,15,2,OBSIDIAN)
Block(4,15,3,OBSIDIAN)
Block(5,0,-1,NETHER_BRICK)
Block(5,0,0,NETHER_BRICK)
Block(5,0,1,NETHER_BRICK)
Block(5,1,-3,NETHER_BRICK)
Block(5,1,-2,OBSIDIAN)
Block(5,1,-1,STATIONARY_LAVA)
Block(5,1,0,STATIONARY_LAVA)
Block(5,1,1,STATIONARY_LAVA)
Block(5,1,2,OBSIDIAN)
Block(5,1,3,NETHER_BRICK)
Block(5,2,-3,NETHER_BRICK)
Block(5,2,-2,OBSIDIAN)
Block(5,2,-1,STATIONARY_LAVA)
Block(5,2,0,STATIONARY_LAVA)
Block(5,2,1,STATIONARY_LAVA)
Block(5,2,2,OBSIDIAN)
Block(5,2,3,NETHER_BRICK)
Block(5,3,-3,NETHER_BRICK)
Block(5,3,-2,OBSIDIAN)
Block(5,3,-1,STATIONARY_LAVA)
Block(5,3,0,STATIONARY_LAVA)
Block(5,3,1,STATIONARY_LAVA)
Block(5,3,2,OBSIDIAN)
Block(5,3,3,NETHER_BRICK)
Block(5,4,-3,NETHER_BRICK)
Block(5,4,-2,OBSIDIAN)
Block(5,4,-1,STATIONARY_LAVA)
Block(5,4,0,STATIONARY_LAVA)
Block(5,4,1,STATIONARY_LAVA)
Block(5,4,2,OBSIDIAN)
Block(5,4,3,NETHER_BRICK)
Block(5,5,-3,NETHER_BRICK)
Block(5,5,-2,OBSIDIAN)
Block(5,5,-1,STATIONARY_LAVA)
Block(5,5,0,STATIONARY_LAVA)
Block(5,5,1,STATIONARY_LAVA)
Block(5,5,2,OBSIDIAN)
Block(5,5,3,NETHER_BRICK)
Block(5,6,-3,NETHER_BRICK)
Block(5,6,-2,OBSIDIAN)
Block(5,6,-1,AIR)
Block(5,6,0,AIR)
Block(5,6,1,AIR)
Block(5,6,2,OBSIDIAN)
Block(5,6,3,NETHER_BRICK)
Block(5,7,-3,NETHER_BRICK)
Block(5,7,-2,OBSIDIAN)
Block(5,7,-1,AIR)
Block(5,7,0,AIR)
Block(5,7,1,AIR)
Block(5,7,2,OBSIDIAN)
Block(5,7,3,NETHER_BRICK)
Block(5,8,-3,NETHER_BRICK)
Block(5,8,-2,OBSIDIAN)
Block(5,8,-1,AIR)
Block(5,8,0,AIR)
Block(5,8,1,AIR)
Block(5,8,2,OBSIDIAN)
Block(5,8,3,NETHER_BRICK)
Block(5,9,-3,NETHER_BRICK)
Block(5,9,-2,OBSIDIAN)
Block(5,9,-1,AIR)
Block(5,9,0,AIR)
Block(5,9,1,AIR)
Block(5,9,2,OBSIDIAN)
Block(5,9,3,NETHER_BRICK)
Block(5,10,-3,OBSIDIAN)
Block(5,10,-2,OBSIDIAN)
Block(5,10,-1,NETHER_BRICK)
Block(5,10,0,NETHER_BRICK)
Block(5,10,1,NETHER_BRICK)
Block(5,10,2,OBSIDIAN)
Block(5,10,3,OBSIDIAN)
Block(5,11,-1,NETHER_BRICK)
Block(5,11,0,NETHER_BRICK)
Block(5,11,1,NETHER_BRICK)
Block(5,12,-1,NETHER_BRICK)
Block(5,12,0,NETHER_BRICK)
Block(5,12,1,NETHER_BRICK)
Block(5,13,-1,NETHER_BRICK)
Block(5,13,0,NETHER_BRICK)
Block(5,13,1,NETHER_BRICK)
Block(5,14,-1,NETHER_BRICK_STAIRS:1)
Block(5,14,0,NETHER_BRICK)
Block(5,14,1,NETHER_BRICK_STAIRS:1)
Block(5,15,0,NETHER_BRICK_STAIRS:1)
Block(6,0,-6,SANDSTONE)
Block(6,1,-1,NETHER_BRICK)
Block(6,1,0,NETHER_BRICK)
Block(6,1,1,NETHER_BRICK)
Block(6,2,-1,NETHER_BRICK)
Block(6,2,0,NETHER_BRICK)
Block(6,2,1,NETHER_BRICK)
Block(6,3,-1,NETHER_BRICK)
Block(6,3,0,NETHER_BRICK)
Block(6,3,1,NETHER_BRICK)
Block(6,4,-1,NETHER_BRICK)
Block(6,4,0,NETHER_BRICK)
Block(6,4,1,NETHER_BRICK)
Block(6,5,-1,NETHER_BRICK)
Block(6,5,0,NETHER_BRICK)
Block(6,5,1,NETHER_BRICK)
Block(6,6,-1,NETHER_BRICK)
Block(6,6,0,NETHER_BRICK)
Block(6,6,1,NETHER_BRICK)
Block(6,7,-1,NETHER_BRICK)
Block(6,7,0,NETHER_BRICK)
Block(6,7,1,NETHER_BRICK)
Block(6,8,-1,NETHER_BRICK)
Block(6,8,0,NETHER_BRICK)
Block(6,8,1,NETHER_BRICK)
Block(6,9,-1,NETHER_BRICK)
Block(6,9,0,NETHER_BRICK)
Block(6,9,1,NETHER_BRICK)
Block(6,10,-1,NETHER_BRICK_STAIRS:1)
Block(6,10,0,NETHER_BRICK_STAIRS:1)
Block(6,10,1,NETHER_BRICK_STAIRS:1)

#######################################################################
# +-----------------------------------------------------------------+ #
# |                            BO3 checks                           | #
# +-----------------------------------------------------------------+ #
#######################################################################

# Require a condition at a certain location in order for the BO3 to be spawned.
# BlockCheck(x,y,z,id[.data][,id[.data][,...]])

#######################################################################
# +-----------------------------------------------------------------+ #
# |                             Branches                            | #
# +-----------------------------------------------------------------+ #
#######################################################################

# Branches are objects that will spawn when this object spawns when it is used in
# the CustomStructure resource. Branches can also have branches, making complex
# structures possible.
# Branch(x,y,z,branchName,rotation,chance[,anotherBranchName,rotation,chance[,...]])
# branchName - name of the object to spawn.
# rotation - NORTH, SOUTH, EAST or WEST.
