
#######################################################################
# +-----------------------------------------------------------------+ #
# |                            BO3 object                           | #
# +-----------------------------------------------------------------+ #
#######################################################################

# This is the config file of a custom object.
# If you add this object correctly to your BiomeConfigs, it will spawn in the world.

# This is the creator of this BO3 object
Author:LanToaster

# A short description of this BO3 object
Description:No description given

# The BO3 version, don't change this! It can be used by external applications to do a version check.
Version:3

# The settings mode, WriteAll, WriteWithoutComments or WriteDisable. See WorldConfig.
SettingsMode:WriteDisable

#######################################################################
# +-----------------------------------------------------------------+ #
# |                          Main settings                          | #
# +-----------------------------------------------------------------+ #
#######################################################################

# This needs to be set to true to spawn the object in the Tree and Sapling resources.
Tree:true

# The frequency of the BO3 from 1 to 200. Tries this many times to spawn this BO3 when using the CustomObject(...) resource.
# Ignored by Tree(..), Sapling(..) and CustomStructure(..)
Frequency:1

# The rarity of the BO3 from 0 to 100. Each spawn attempt has rarity% chance to succeed when using the CustomObject(...) resource.
# Ignored by Tree(..), Sapling(..) and CustomStructure(..)
Rarity:100.0

# If you set this to true, the BO3 will be placed with a random rotation.
RotateRandomly:false

# The spawn height of the BO3 - randomY, highestBlock or highestSolidBlock.
SpawnHeight:highestBlock

# The height limits for the BO3.
MinHeight:0
MaxHeight:256

# Objects can have other objects attacthed to it: branches. Branches can also
# have branches attached to it, which can also have branches, etc. This is the
# maximum branch depth for this objects.
MaxBranchDepth:10

# When spawned with the UseWorld keyword, this BO3 should NOT spawn in the following biomes.
# If you write the BO3 name directly in the BiomeConfigs, this will be ignored.
ExcludedBiomes:All

#######################################################################
# +-----------------------------------------------------------------+ #
# |                      Source block settings                      | #
# +-----------------------------------------------------------------+ #
#######################################################################

# The block the BO3 should spawn in
SourceBlock:0

# The maximum percentage of the BO3 that can be outside the SourceBlock.
# The BO3 won't be placed on a location with more blocks outside the SourceBlock than this percentage.
MaxPercentageOutsideSourceBlock:100

# What to do when a block is about to be placed outside the SourceBlock? (dontPlace, placeAnyway)
OutsideSourceBlock:placeAnyway

#######################################################################
# +-----------------------------------------------------------------+ #
# |                              Blocks                             | #
# +-----------------------------------------------------------------+ #
#######################################################################

# All the blocks used in the BO3 are listed here. Possible blocks:
# Block(x,y,z,id[.data][,nbtfile.nbt)
# RandomBlock(x,y,z,id[:data][,nbtfile.nbt],chance[,id[:data][,nbtfile.nbt],chance[,...]])
# So RandomBlock(0,0,0,CHEST,chest.nbt,50,CHEST,anotherchest.nbt,100) will spawn a chest at
# the BO3 origin, and give it a 50% chance to have the contents of chest.nbt, or, if that
# fails, a 100% percent chance to have the contents of anotherchest.nbt.
Block(-7,3,-1,NETHER_FENCE)
Block(-7,3,0,NETHERRACK)
Block(-7,3,1,NETHER_FENCE)
Block(-7,4,-2,NETHER_BRICK_STAIRS:6)
Block(-7,4,-1,STEP:6)
Block(-7,4,0,STEP:6)
Block(-7,4,1,STEP:6)
Block(-7,4,2,NETHER_BRICK_STAIRS:7)
Block(-7,5,-2,NETHER_FENCE)
Block(-7,5,-1,AIR)
Block(-7,5,0,AIR)
Block(-7,5,1,AIR)
Block(-7,5,2,NETHER_FENCE)
Block(-7,6,-1,AIR)
Block(-7,6,0,AIR)
Block(-7,6,1,AIR)
Block(-7,7,0,AIR)
Block(-6,3,-1,NETHER_FENCE)
Block(-6,3,1,NETHER_FENCE)
Block(-6,4,-2,NETHER_BRICK_STAIRS:6)
Block(-6,4,-1,STEP:6)
Block(-6,4,0,STEP:6)
Block(-6,4,1,STEP:6)
Block(-6,4,2,NETHER_BRICK_STAIRS:7)
Block(-6,5,-2,NETHER_FENCE)
Block(-6,5,-1,AIR)
Block(-6,5,0,AIR)
Block(-6,5,1,AIR)
Block(-6,5,2,NETHER_FENCE)
Block(-6,6,-1,AIR)
Block(-6,6,0,AIR)
Block(-6,6,1,AIR)
Block(-6,7,0,AIR)
Block(-5,3,-1,NETHER_FENCE)
Block(-5,3,1,NETHER_FENCE)
Block(-5,4,-2,NETHER_BRICK_STAIRS:6)
Block(-5,4,-1,STEP:6)
Block(-5,4,0,STEP:6)
Block(-5,4,1,STEP:6)
Block(-5,4,2,NETHER_BRICK_STAIRS:7)
Block(-5,5,-2,NETHER_FENCE)
Block(-5,5,-1,AIR)
Block(-5,5,0,AIR)
Block(-5,5,1,AIR)
Block(-5,5,2,NETHER_FENCE)
Block(-5,6,-1,AIR)
Block(-5,6,0,AIR)
Block(-5,6,1,AIR)
Block(-5,7,0,AIR)
Block(-4,2,-1,NETHER_BRICK_STAIRS:4)
Block(-4,2,1,NETHER_BRICK_STAIRS:4)
Block(-4,3,-2,NETHER_FENCE)
Block(-4,3,-1,OBSIDIAN)
Block(-4,3,1,OBSIDIAN)
Block(-4,3,2,NETHER_FENCE)
Block(-4,4,-3,NETHER_FENCE)
Block(-4,4,-2,NETHER_BRICK_STAIRS:6)
Block(-4,4,-1,STEP:6)
Block(-4,4,0,STEP:6)
Block(-4,4,1,STEP:6)
Block(-4,4,2,NETHER_BRICK_STAIRS:7)
Block(-4,4,3,NETHER_FENCE)
Block(-4,5,-3,NETHER_FENCE)
Block(-4,5,-2,NETHER_BRICK)
Block(-4,5,-1,AIR)
Block(-4,5,0,AIR)
Block(-4,5,1,AIR)
Block(-4,5,2,NETHER_BRICK)
Block(-4,5,3,NETHER_FENCE)
Block(-4,6,-3,REDSTONE_TORCH_ON:5)
Block(-4,6,-2,STEP:6)
Block(-4,6,-1,AIR)
Block(-4,6,0,AIR)
Block(-4,6,1,AIR)
Block(-4,6,2,STEP:6)
Block(-4,6,3,REDSTONE_TORCH_ON:5)
Block(-4,7,0,AIR)
Block(-3,0,-1,OBSIDIAN)
Block(-3,0,0,OBSIDIAN)
Block(-3,0,1,OBSIDIAN)
Block(-3,1,-1,NETHER_BRICK)
Block(-3,1,0,OBSIDIAN)
Block(-3,1,1,NETHER_BRICK)
Block(-3,2,-1,NETHER_BRICK)
Block(-3,2,0,OBSIDIAN)
Block(-3,2,1,NETHER_BRICK)
Block(-3,3,-1,OBSIDIAN)
Block(-3,3,0,GLOWSTONE)
Block(-3,3,1,OBSIDIAN)
Block(-3,4,-4,NETHER_FENCE)
Block(-3,4,-2,NETHER_BRICK_STAIRS:6)
Block(-3,4,-1,STEP:6)
Block(-3,4,0,STEP:6)
Block(-3,4,1,STEP:6)
Block(-3,4,2,NETHER_BRICK_STAIRS:7)
Block(-3,4,4,NETHER_FENCE)
Block(-3,5,-4,NETHER_FENCE)
Block(-3,5,-2,NETHER_FENCE)
Block(-3,5,-1,AIR)
Block(-3,5,0,AIR)
Block(-3,5,1,AIR)
Block(-3,5,2,NETHER_FENCE)
Block(-3,5,4,NETHER_FENCE)
Block(-3,6,-4,REDSTONE_TORCH_ON:5)
Block(-3,6,-2,NETHER_BRICK)
Block(-3,6,-1,AIR)
Block(-3,6,0,AIR)
Block(-3,6,1,AIR)
Block(-3,6,2,NETHER_BRICK_STAIRS:3)
Block(-3,6,4,REDSTONE_TORCH_ON:5)
Block(-3,7,0,AIR)
Block(-3,9,-1,NETHER_BRICK_STAIRS:4)
Block(-3,9,1,NETHER_BRICK_STAIRS:4)
Block(-3,10,-1,OBSIDIAN)
Block(-3,10,0,OBSIDIAN)
Block(-3,10,1,OBSIDIAN)
Block(-2,0,-2,OBSIDIAN)
Block(-2,0,-1,STEP:6)
Block(-2,0,0,STEP:6)
Block(-2,0,1,STEP:6)
Block(-2,0,2,OBSIDIAN)
Block(-2,1,-2,NETHER_BRICK)
Block(-2,1,2,NETHER_BRICK)
Block(-2,2,-2,NETHER_BRICK)
Block(-2,2,2,NETHER_BRICK)
Block(-2,3,-4,NETHER_FENCE)
Block(-2,3,-2,OBSIDIAN)
Block(-2,3,2,OBSIDIAN)
Block(-2,3,4,NETHER_FENCE)
Block(-2,4,-7,NETHER_BRICK_STAIRS:4)
Block(-2,4,-6,NETHER_BRICK_STAIRS:4)
Block(-2,4,-5,NETHER_BRICK_STAIRS:4)
Block(-2,4,-4,NETHER_BRICK_STAIRS:4)
Block(-2,4,-3,NETHER_BRICK_STAIRS:4)
Block(-2,4,-2,NETHER_BRICK)
Block(-2,4,-1,NETHER_BRICK)
Block(-2,4,0,NETHER_BRICK)
Block(-2,4,1,NETHER_BRICK)
Block(-2,4,2,NETHER_BRICK)
Block(-2,4,3,NETHER_BRICK_STAIRS:4)
Block(-2,4,4,NETHER_BRICK_STAIRS:4)
Block(-2,4,5,NETHER_BRICK_STAIRS:4)
Block(-2,4,6,NETHER_BRICK_STAIRS:4)
Block(-2,4,7,NETHER_BRICK_STAIRS:4)
Block(-2,5,-7,NETHER_FENCE)
Block(-2,5,-6,NETHER_FENCE)
Block(-2,5,-5,NETHER_FENCE)
Block(-2,5,-4,NETHER_BRICK)
Block(-2,5,-3,NETHER_FENCE)
Block(-2,5,-2,NETHER_BRICK)
Block(-2,5,-1,AIR)
Block(-2,5,0,AIR)
Block(-2,5,1,AIR)
Block(-2,5,2,NETHER_BRICK)
Block(-2,5,3,NETHER_FENCE)
Block(-2,5,4,NETHER_BRICK)
Block(-2,5,5,NETHER_FENCE)
Block(-2,5,6,NETHER_FENCE)
Block(-2,5,7,NETHER_FENCE)
Block(-2,6,-4,STEP:6)
Block(-2,6,-3,NETHER_BRICK_STAIRS)
Block(-2,6,-2,NETHER_BRICK)
Block(-2,6,-1,AIR)
Block(-2,6,0,AIR)
Block(-2,6,1,AIR)
Block(-2,6,2,NETHER_BRICK)
Block(-2,6,3,NETHER_BRICK_STAIRS)
Block(-2,6,4,STEP:6)
Block(-2,7,-2,OBSIDIAN)
Block(-2,7,-1,NETHER_BRICK_STAIRS:7)
Block(-2,7,0,AIR)
Block(-2,7,1,NETHER_BRICK_STAIRS:6)
Block(-2,7,2,OBSIDIAN)
Block(-2,8,-2,NETHER_FENCE)
Block(-2,8,-1,NETHER_BRICK)
Block(-2,8,0,NETHER_BRICK)
Block(-2,8,1,NETHER_BRICK)
Block(-2,8,2,NETHER_FENCE)
Block(-2,9,-2,NETHER_FENCE)
Block(-2,9,-1,NETHER_BRICK)
Block(-2,9,0,NETHER_FENCE)
Block(-2,9,1,NETHER_BRICK)
Block(-2,9,2,NETHER_FENCE)
Block(-2,10,-2,OBSIDIAN)
Block(-2,10,-1,NETHER_BRICK)
Block(-2,10,0,NETHER_FENCE)
Block(-2,10,1,NETHER_BRICK)
Block(-2,10,2,OBSIDIAN)
Block(-1,0,-3,OBSIDIAN)
Block(-1,0,-2,STEP:6)
Block(-1,0,-1,STEP:6)
Block(-1,0,0,LADDER:4)
Block(-1,0,1,STEP:6)
Block(-1,0,2,STEP:6)
Block(-1,0,3,OBSIDIAN)
Block(-1,1,-3,NETHER_BRICK)
Block(-1,1,0,LADDER:4)
Block(-1,1,3,NETHER_BRICK)
Block(-1,2,-4,NETHER_BRICK_STAIRS:6)
Block(-1,2,-3,NETHER_BRICK)
Block(-1,2,0,LADDER:4)
Block(-1,2,3,NETHER_BRICK)
Block(-1,2,4,NETHER_BRICK_STAIRS:7)
Block(-1,3,-7,NETHER_FENCE)
Block(-1,3,-6,NETHER_FENCE)
Block(-1,3,-5,NETHER_FENCE)
Block(-1,3,-4,OBSIDIAN)
Block(-1,3,-3,OBSIDIAN)
Block(-1,3,0,LADDER:4)
Block(-1,3,3,OBSIDIAN)
Block(-1,3,4,OBSIDIAN)
Block(-1,3,5,NETHER_FENCE)
Block(-1,3,6,NETHER_FENCE)
Block(-1,3,7,NETHER_FENCE)
Block(-1,4,-7,STEP:6)
Block(-1,4,-6,STEP:6)
Block(-1,4,-5,STEP:6)
Block(-1,4,-4,STEP:6)
Block(-1,4,-3,STEP:6)
Block(-1,4,-2,NETHER_BRICK)
Block(-1,4,-1,NETHER_BRICK)
Block(-1,4,0,LADDER:4)
Block(-1,4,1,NETHER_BRICK)
Block(-1,4,2,NETHER_BRICK)
Block(-1,4,3,STEP:6)
Block(-1,4,4,STEP:6)
Block(-1,4,5,STEP:6)
Block(-1,4,6,STEP:6)
Block(-1,4,7,STEP:6)
Block(-1,5,-7,AIR)
Block(-1,5,-6,AIR)
Block(-1,5,-5,AIR)
Block(-1,5,-4,AIR)
Block(-1,5,-3,AIR)
Block(-1,5,-2,AIR)
Block(-1,5,-1,AIR)
Block(-1,5,0,LADDER:4)
Block(-1,5,1,AIR)
Block(-1,5,2,AIR)
Block(-1,5,3,AIR)
Block(-1,5,4,AIR)
Block(-1,5,5,AIR)
Block(-1,5,6,AIR)
Block(-1,5,7,AIR)
Block(-1,6,-7,AIR)
Block(-1,6,-6,AIR)
Block(-1,6,-5,AIR)
Block(-1,6,-4,AIR)
Block(-1,6,-3,AIR)
Block(-1,6,-2,AIR)
Block(-1,6,-1,AIR)
Block(-1,6,0,LADDER:4)
Block(-1,6,1,AIR)
Block(-1,6,2,AIR)
Block(-1,6,3,AIR)
Block(-1,6,4,AIR)
Block(-1,6,5,AIR)
Block(-1,6,6,AIR)
Block(-1,6,7,AIR)
Block(-1,7,-2,NETHER_BRICK_STAIRS:5)
Block(-1,7,-1,AIR)
Block(-1,7,0,LADDER:4)
Block(-1,7,1,AIR)
Block(-1,7,2,NETHER_BRICK_STAIRS:5)
Block(-1,8,-2,NETHER_BRICK)
Block(-1,8,-1,AIR)
Block(-1,8,0,LADDER:4)
Block(-1,8,1,AIR)
Block(-1,8,2,NETHER_BRICK)
Block(-1,9,-3,NETHER_BRICK_STAIRS:6)
Block(-1,9,-2,NETHER_BRICK)
Block(-1,9,-1,AIR)
Block(-1,9,0,LADDER:4)
Block(-1,9,1,AIR)
Block(-1,9,2,NETHER_BRICK)
Block(-1,9,3,NETHER_BRICK_STAIRS:7)
Block(-1,10,-3,OBSIDIAN)
Block(-1,10,-2,NETHER_BRICK)
Block(-1,10,-1,AIR)
Block(-1,10,0,LADDER:4)
Block(-1,10,1,AIR)
Block(-1,10,2,NETHER_BRICK)
Block(-1,10,3,OBSIDIAN)
Block(0,0,-3,OBSIDIAN)
Block(0,0,-2,STEP:6)
Block(0,0,-1,LADDER:2)
Block(0,0,0,NETHER_BRICK)
Block(0,0,1,LADDER:3)
Block(0,0,2,STEP:6)
Block(0,0,3,OBSIDIAN)
Block(0,1,-3,OBSIDIAN)
Block(0,1,-1,LADDER:2)
Block(0,1,0,NETHER_BRICK)
Block(0,1,1,LADDER:3)
Block(0,1,3,OBSIDIAN)
Block(0,2,-3,OBSIDIAN)
Block(0,2,-1,LADDER:2)
Block(0,2,0,NETHER_BRICK)
Block(0,2,1,LADDER:3)
Block(0,2,3,OBSIDIAN)
Block(0,3,-7,NETHERRACK)
Block(0,3,-3,GLOWSTONE)
Block(0,3,-1,LADDER:2)
Block(0,3,0,NETHER_BRICK)
Block(0,3,1,LADDER:3)
Block(0,3,3,GLOWSTONE)
Block(0,3,7,NETHERRACK)
Block(0,4,-7,STEP:6)
Block(0,4,-6,STEP:6)
Block(0,4,-5,STEP:6)
Block(0,4,-4,STEP:6)
Block(0,4,-3,STEP:6)
Block(0,4,-2,NETHER_BRICK)
Block(0,4,-1,LADDER:2)
Block(0,4,0,NETHER_BRICK)
Block(0,4,1,LADDER:3)
Block(0,4,2,NETHER_BRICK)
Block(0,4,3,STEP:6)
Block(0,4,4,STEP:6)
Block(0,4,5,STEP:6)
Block(0,4,6,STEP:6)
Block(0,4,7,STEP:6)
Block(0,5,-7,AIR)
Block(0,5,-6,AIR)
Block(0,5,-5,AIR)
Block(0,5,-4,AIR)
Block(0,5,-3,AIR)
Block(0,5,-2,AIR)
Block(0,5,-1,LADDER:2)
Block(0,5,0,NETHER_BRICK)
Block(0,5,1,LADDER:3)
Block(0,5,2,AIR)
Block(0,5,3,AIR)
Block(0,5,4,AIR)
Block(0,5,5,AIR)
Block(0,5,6,AIR)
Block(0,5,7,AIR)
Block(0,6,-7,AIR)
Block(0,6,-6,AIR)
Block(0,6,-5,AIR)
Block(0,6,-4,AIR)
Block(0,6,-3,AIR)
Block(0,6,-2,AIR)
Block(0,6,-1,LADDER:2)
Block(0,6,0,NETHER_BRICK)
Block(0,6,1,LADDER:3)
Block(0,6,2,AIR)
Block(0,6,3,AIR)
Block(0,6,4,AIR)
Block(0,6,5,AIR)
Block(0,6,6,AIR)
Block(0,6,7,AIR)
Block(0,7,-7,AIR)
Block(0,7,-6,AIR)
Block(0,7,-5,AIR)
Block(0,7,-4,AIR)
Block(0,7,-3,AIR)
Block(0,7,-2,AIR)
Block(0,7,-1,LADDER:2)
Block(0,7,0,NETHER_BRICK)
Block(0,7,1,LADDER:3)
Block(0,7,2,AIR)
Block(0,7,3,AIR)
Block(0,7,4,AIR)
Block(0,7,5,AIR)
Block(0,7,6,AIR)
Block(0,7,7,AIR)
Block(0,8,-2,NETHER_BRICK)
Block(0,8,-1,LADDER:2)
Block(0,8,0,NETHER_BRICK)
Block(0,8,1,LADDER:3)
Block(0,8,2,NETHER_BRICK)
Block(0,9,-2,NETHER_FENCE)
Block(0,9,-1,LADDER:2)
Block(0,9,0,NETHER_BRICK)
Block(0,9,1,LADDER:3)
Block(0,9,2,NETHER_FENCE)
Block(0,10,-3,OBSIDIAN)
Block(0,10,-2,NETHER_FENCE)
Block(0,10,-1,LADDER:2)
Block(0,10,0,NETHER_BRICK)
Block(0,10,1,LADDER:3)
Block(0,10,2,NETHER_FENCE)
Block(0,10,3,OBSIDIAN)
Block(1,0,-3,OBSIDIAN)
Block(1,0,-2,STEP:6)
Block(1,0,-1,STEP:6)
Block(1,0,0,LADDER:5)
Block(1,0,1,STEP:6)
Block(1,0,2,STEP:6)
Block(1,0,3,OBSIDIAN)
Block(1,1,-3,NETHER_BRICK)
Block(1,1,0,LADDER:5)
Block(1,1,3,NETHER_BRICK)
Block(1,2,-4,NETHER_BRICK_STAIRS:6)
Block(1,2,-3,NETHER_BRICK)
Block(1,2,0,LADDER:5)
Block(1,2,3,NETHER_BRICK)
Block(1,2,4,NETHER_BRICK_STAIRS:7)
Block(1,3,-7,NETHER_FENCE)
Block(1,3,-6,NETHER_FENCE)
Block(1,3,-5,NETHER_FENCE)
Block(1,3,-4,OBSIDIAN)
Block(1,3,-3,OBSIDIAN)
Block(1,3,0,LADDER:5)
Block(1,3,3,OBSIDIAN)
Block(1,3,4,OBSIDIAN)
Block(1,3,5,NETHER_FENCE)
Block(1,3,6,NETHER_FENCE)
Block(1,3,7,NETHER_FENCE)
Block(1,4,-7,STEP:6)
Block(1,4,-6,STEP:6)
Block(1,4,-5,STEP:6)
Block(1,4,-4,STEP:6)
Block(1,4,-3,STEP:6)
Block(1,4,-2,NETHER_BRICK)
Block(1,4,-1,NETHER_BRICK)
Block(1,4,0,LADDER:5)
Block(1,4,1,NETHER_BRICK)
Block(1,4,2,NETHER_BRICK)
Block(1,4,3,STEP:6)
Block(1,4,4,STEP:6)
Block(1,4,5,STEP:6)
Block(1,4,6,STEP:6)
Block(1,4,7,STEP:6)
Block(1,5,-7,AIR)
Block(1,5,-6,AIR)
Block(1,5,-5,AIR)
Block(1,5,-4,AIR)
Block(1,5,-3,AIR)
Block(1,5,-2,AIR)
Block(1,5,-1,AIR)
Block(1,5,0,LADDER:5)
Block(1,5,1,AIR)
Block(1,5,2,AIR)
Block(1,5,3,AIR)
Block(1,5,4,AIR)
Block(1,5,5,AIR)
Block(1,5,6,AIR)
Block(1,5,7,AIR)
Block(1,6,-7,AIR)
Block(1,6,-6,AIR)
Block(1,6,-5,AIR)
Block(1,6,-4,AIR)
Block(1,6,-3,AIR)
Block(1,6,-2,AIR)
Block(1,6,-1,AIR)
Block(1,6,0,LADDER:5)
Block(1,6,1,AIR)
Block(1,6,2,AIR)
Block(1,6,3,AIR)
Block(1,6,4,AIR)
Block(1,6,5,AIR)
Block(1,6,6,AIR)
Block(1,6,7,AIR)
Block(1,7,-2,NETHER_BRICK_STAIRS:4)
Block(1,7,-1,AIR)
Block(1,7,0,LADDER:5)
Block(1,7,1,AIR)
Block(1,7,2,NETHER_BRICK_STAIRS:4)
Block(1,8,-2,NETHER_BRICK)
Block(1,8,-1,AIR)
Block(1,8,0,LADDER:5)
Block(1,8,1,AIR)
Block(1,8,2,NETHER_BRICK)
Block(1,9,-3,NETHER_BRICK_STAIRS:6)
Block(1,9,-2,NETHER_BRICK)
Block(1,9,-1,AIR)
Block(1,9,0,LADDER:5)
Block(1,9,1,AIR)
Block(1,9,2,NETHER_BRICK)
Block(1,9,3,NETHER_BRICK_STAIRS:7)
Block(1,10,-3,OBSIDIAN)
Block(1,10,-2,NETHER_BRICK)
Block(1,10,-1,AIR)
Block(1,10,0,LADDER:5)
Block(1,10,1,AIR)
Block(1,10,2,NETHER_BRICK)
Block(1,10,3,OBSIDIAN)
Block(2,0,-2,OBSIDIAN)
Block(2,0,-1,STEP:6)
Block(2,0,0,STEP:6)
Block(2,0,1,STEP:6)
Block(2,0,2,OBSIDIAN)
Block(2,1,-2,NETHER_BRICK)
Block(2,1,2,NETHER_BRICK)
Block(2,2,-2,NETHER_BRICK)
Block(2,2,2,NETHER_BRICK)
Block(2,3,-4,NETHER_FENCE)
Block(2,3,-2,OBSIDIAN)
Block(2,3,2,OBSIDIAN)
Block(2,3,4,NETHER_FENCE)
Block(2,4,-7,NETHER_BRICK_STAIRS:5)
Block(2,4,-6,NETHER_BRICK_STAIRS:5)
Block(2,4,-5,NETHER_BRICK_STAIRS:5)
Block(2,4,-4,NETHER_BRICK_STAIRS:5)
Block(2,4,-3,NETHER_BRICK_STAIRS:5)
Block(2,4,-2,NETHER_BRICK_STAIRS:5)
Block(2,4,-1,NETHER_BRICK)
Block(2,4,0,NETHER_BRICK)
Block(2,4,1,NETHER_BRICK)
Block(2,4,2,NETHER_BRICK)
Block(2,4,3,NETHER_BRICK_STAIRS:5)
Block(2,4,4,NETHER_BRICK_STAIRS:5)
Block(2,4,5,NETHER_BRICK_STAIRS:5)
Block(2,4,6,NETHER_BRICK_STAIRS:5)
Block(2,4,7,NETHER_BRICK_STAIRS:5)
Block(2,5,-7,NETHER_FENCE)
Block(2,5,-6,NETHER_FENCE)
Block(2,5,-5,NETHER_FENCE)
Block(2,5,-4,NETHER_BRICK)
Block(2,5,-3,NETHER_FENCE)
Block(2,5,-2,NETHER_BRICK)
Block(2,5,-1,AIR)
Block(2,5,0,AIR)
Block(2,5,1,AIR)
Block(2,5,2,NETHER_BRICK)
Block(2,5,3,NETHER_FENCE)
Block(2,5,4,NETHER_BRICK)
Block(2,5,5,NETHER_FENCE)
Block(2,5,6,NETHER_FENCE)
Block(2,5,7,NETHER_FENCE)
Block(2,6,-4,STEP:6)
Block(2,6,-3,NETHER_BRICK_STAIRS:1)
Block(2,6,-2,NETHER_BRICK)
Block(2,6,-1,AIR)
Block(2,6,0,AIR)
Block(2,6,1,AIR)
Block(2,6,2,NETHER_BRICK)
Block(2,6,3,NETHER_BRICK_STAIRS:1)
Block(2,6,4,STEP:6)
Block(2,7,-2,OBSIDIAN)
Block(2,7,-1,NETHER_BRICK_STAIRS:7)
Block(2,7,0,AIR)
Block(2,7,1,NETHER_BRICK_STAIRS:6)
Block(2,7,2,OBSIDIAN)
Block(2,8,-2,NETHER_FENCE)
Block(2,8,-1,NETHER_BRICK)
Block(2,8,0,NETHER_BRICK)
Block(2,8,1,NETHER_BRICK)
Block(2,8,2,NETHER_FENCE)
Block(2,9,-2,NETHER_FENCE)
Block(2,9,-1,NETHER_BRICK)
Block(2,9,0,NETHER_FENCE)
Block(2,9,1,NETHER_BRICK)
Block(2,9,2,NETHER_FENCE)
Block(2,10,-2,OBSIDIAN)
Block(2,10,-1,NETHER_BRICK)
Block(2,10,0,NETHER_FENCE)
Block(2,10,1,NETHER_BRICK)
Block(2,10,2,OBSIDIAN)
Block(3,0,-1,OBSIDIAN)
Block(3,0,0,OBSIDIAN)
Block(3,0,1,OBSIDIAN)
Block(3,1,-1,NETHER_BRICK)
Block(3,1,0,OBSIDIAN)
Block(3,1,1,NETHER_BRICK)
Block(3,2,-1,NETHER_BRICK)
Block(3,2,0,OBSIDIAN)
Block(3,2,1,NETHER_BRICK)
Block(3,3,-1,OBSIDIAN)
Block(3,3,0,GLOWSTONE)
Block(3,3,1,OBSIDIAN)
Block(3,4,-4,NETHER_FENCE)
Block(3,4,-2,NETHER_BRICK_STAIRS:6)
Block(3,4,-1,STEP:6)
Block(3,4,0,STEP:6)
Block(3,4,1,STEP:6)
Block(3,4,2,NETHER_BRICK_STAIRS:7)
Block(3,4,4,NETHER_FENCE)
Block(3,5,-4,NETHER_FENCE)
Block(3,5,-2,NETHER_FENCE)
Block(3,5,-1,AIR)
Block(3,5,0,AIR)
Block(3,5,1,AIR)
Block(3,5,2,NETHER_FENCE)
Block(3,5,4,NETHER_FENCE)
Block(3,6,-4,REDSTONE_TORCH_ON:5)
Block(3,6,-2,NETHER_BRICK_STAIRS:2)
Block(3,6,-1,AIR)
Block(3,6,0,AIR)
Block(3,6,1,AIR)
Block(3,6,2,NETHER_BRICK_STAIRS:3)
Block(3,6,4,REDSTONE_TORCH_ON:5)
Block(3,7,0,AIR)
Block(3,9,-1,NETHER_BRICK_STAIRS:5)
Block(3,9,1,NETHER_BRICK_STAIRS:5)
Block(3,10,-1,OBSIDIAN)
Block(3,10,0,OBSIDIAN)
Block(3,10,1,OBSIDIAN)
Block(4,2,-1,NETHER_BRICK_STAIRS:5)
Block(4,2,1,NETHER_BRICK_STAIRS:5)
Block(4,3,-2,NETHER_FENCE)
Block(4,3,-1,OBSIDIAN)
Block(4,3,1,OBSIDIAN)
Block(4,3,2,NETHER_FENCE)
Block(4,4,-3,NETHER_FENCE)
Block(4,4,-2,NETHER_BRICK_STAIRS:6)
Block(4,4,-1,STEP:6)
Block(4,4,0,STEP:6)
Block(4,4,1,STEP:6)
Block(4,4,2,NETHER_BRICK_STAIRS:7)
Block(4,4,3,NETHER_FENCE)
Block(4,5,-3,NETHER_FENCE)
Block(4,5,-2,NETHER_BRICK)
Block(4,5,-1,AIR)
Block(4,5,0,AIR)
Block(4,5,1,AIR)
Block(4,5,2,NETHER_BRICK)
Block(4,5,3,NETHER_FENCE)
Block(4,6,-3,REDSTONE_TORCH_ON:5)
Block(4,6,-2,STEP:6)
Block(4,6,-1,AIR)
Block(4,6,0,AIR)
Block(4,6,1,AIR)
Block(4,6,2,STEP:6)
Block(4,6,3,REDSTONE_TORCH_ON:5)
Block(4,7,0,AIR)
Block(5,3,-1,NETHER_FENCE)
Block(5,3,1,NETHER_FENCE)
Block(5,4,-2,NETHER_BRICK_STAIRS:6)
Block(5,4,-1,STEP:6)
Block(5,4,0,STEP:6)
Block(5,4,1,STEP:6)
Block(5,4,2,NETHER_BRICK_STAIRS:7)
Block(5,5,-2,NETHER_FENCE)
Block(5,5,-1,AIR)
Block(5,5,0,AIR)
Block(5,5,1,AIR)
Block(5,5,2,NETHER_FENCE)
Block(5,6,-1,AIR)
Block(5,6,0,AIR)
Block(5,6,1,AIR)
Block(5,7,0,AIR)
Block(6,3,-1,NETHER_FENCE)
Block(6,3,1,NETHER_FENCE)
Block(6,4,-2,NETHER_BRICK_STAIRS:6)
Block(6,4,-1,STEP:6)
Block(6,4,0,STEP:6)
Block(6,4,1,STEP:6)
Block(6,4,2,NETHER_BRICK_STAIRS:7)
Block(6,5,-2,NETHER_FENCE)
Block(6,5,-1,AIR)
Block(6,5,0,AIR)
Block(6,5,1,AIR)
Block(6,5,2,NETHER_FENCE)
Block(6,6,-1,AIR)
Block(6,6,0,AIR)
Block(6,6,1,AIR)
Block(6,7,0,AIR)
Block(7,3,-1,NETHER_FENCE)
Block(7,3,0,NETHERRACK)
Block(7,3,1,NETHER_FENCE)
Block(7,4,-2,NETHER_BRICK_STAIRS:6)
Block(7,4,-1,STEP:6)
Block(7,4,0,STEP:6)
Block(7,4,1,STEP:6)
Block(7,4,2,NETHER_BRICK_STAIRS:7)
Block(7,5,-2,NETHER_FENCE)
Block(7,5,-1,AIR)
Block(7,5,0,AIR)
Block(7,5,1,AIR)
Block(7,5,2,NETHER_FENCE)
Block(7,6,-1,AIR)
Block(7,6,0,AIR)
Block(7,6,1,AIR)
Block(7,7,0,AIR)

#######################################################################
# +-----------------------------------------------------------------+ #
# |                            BO3 checks                           | #
# +-----------------------------------------------------------------+ #
#######################################################################

# Require a condition at a certain location in order for the BO3 to be spawned.
# BlockCheck(x,y,z,id[.data][,id[.data][,...]])

#######################################################################
# +-----------------------------------------------------------------+ #
# |                             Branches                            | #
# +-----------------------------------------------------------------+ #
#######################################################################

# Branches are objects that will spawn when this object spawns when it is used in
# the CustomStructure resource. Branches can also have branches, making complex
# structures possible.
# Branch(x,y,z,branchName,rotation,chance[,anotherBranchName,rotation,chance[,...]])
# branchName - name of the object to spawn.
# rotation - NORTH, SOUTH, EAST or WEST.
Branch(0,11,0,Nether-Tower-SpirePart,NORTH,100)
Branch(0,-15,0,Nether-Tower-Base1-A,NORTH,33,Nether-Tower-Base1-B,NORTH,50,Nether-Tower-Base1-C,NORTH,100)
Branch(0,0,15,Nether-Tower-Bridge,NORTH,40,Nether-Tower-Bridge-Broken,NORTH,100)
Branch(15,0,0,Nether-Tower-Bridge,WEST,40,Nether-Tower-Bridge-Broken,WEST,100)
Branch(-15,0,0,Nether-Tower-Bridge,EAST,40,Nether-Tower-Bridge-Broken,EAST,100)
