
#######################################################################
# +-----------------------------------------------------------------+ #
# |                            BO3 object                           | #
# +-----------------------------------------------------------------+ #
#######################################################################

# This is the config file of a custom object.
# If you add this object correctly to your BiomeConfigs, it will spawn in the world.

# This is the creator of this BO3 object
Author:LanToaster

# A short description of this BO3 object
Description:No description given

# The BO3 version, don't change this! It can be used by external applications to do a version check.
Version:3

# The settings mode, WriteAll, WriteWithoutComments or WriteDisable. See WorldConfig.
SettingsMode:WriteDisable

#######################################################################
# +-----------------------------------------------------------------+ #
# |                          Main settings                          | #
# +-----------------------------------------------------------------+ #
#######################################################################

# This needs to be set to true to spawn the object in the Tree and Sapling resources.
Tree:true

# The frequency of the BO3 from 1 to 200. Tries this many times to spawn this BO3 when using the CustomObject(...) resource.
# Ignored by Tree(..), Sapling(..) and CustomStructure(..)
Frequency:1

# The rarity of the BO3 from 0 to 100. Each spawn attempt has rarity% chance to succeed when using the CustomObject(...) resource.
# Ignored by Tree(..), Sapling(..) and CustomStructure(..)
Rarity:100.0

# If you set this to true, the BO3 will be placed with a random rotation.
RotateRandomly:false

# The spawn height of the BO3 - randomY, highestBlock or highestSolidBlock.
SpawnHeight:highestBlock

# The height limits for the BO3.
MinHeight:0
MaxHeight:256

# Objects can have other objects attacthed to it: branches. Branches can also
# have branches attached to it, which can also have branches, etc. This is the
# maximum branch depth for this objects.
MaxBranchDepth:10

# When spawned with the UseWorld keyword, this BO3 should NOT spawn in the following biomes.
# If you write the BO3 name directly in the BiomeConfigs, this will be ignored.
ExcludedBiomes:All

#######################################################################
# +-----------------------------------------------------------------+ #
# |                      Source block settings                      | #
# +-----------------------------------------------------------------+ #
#######################################################################

# The block the BO3 should spawn in
SourceBlock:0

# The maximum percentage of the BO3 that can be outside the SourceBlock.
# The BO3 won't be placed on a location with more blocks outside the SourceBlock than this percentage.
MaxPercentageOutsideSourceBlock:100

# What to do when a block is about to be placed outside the SourceBlock? (dontPlace, placeAnyway)
OutsideSourceBlock:placeAnyway

#######################################################################
# +-----------------------------------------------------------------+ #
# |                              Blocks                             | #
# +-----------------------------------------------------------------+ #
#######################################################################

# All the blocks used in the BO3 are listed here. Possible blocks:
# Block(x,y,z,id[.data][,nbtfile.nbt)
# RandomBlock(x,y,z,id[:data][,nbtfile.nbt],chance[,id[:data][,nbtfile.nbt],chance[,...]])
# So RandomBlock(0,0,0,CHEST,chest.nbt,50,CHEST,anotherchest.nbt,100) will spawn a chest at
# the BO3 origin, and give it a 50% chance to have the contents of chest.nbt, or, if that
# fails, a 100% percent chance to have the contents of anotherchest.nbt.
Block(-3,2,-4,NETHER_FENCE)
Block(-3,2,0,NETHER_FENCE)
Block(-3,2,4,NETHER_FENCE)
Block(-3,3,-4,NETHER_FENCE)
Block(-3,3,0,NETHER_FENCE)
Block(-3,3,4,NETHER_FENCE)
Block(-3,4,-4,REDSTONE_TORCH_ON:5)
Block(-3,4,0,NETHER_FENCE)
Block(-3,4,4,REDSTONE_TORCH_ON:5)
Block(-3,5,0,REDSTONE_TORCH_ON:5)
Block(-2,1,-4,NETHER_FENCE)
Block(-2,1,0,NETHER_FENCE)
Block(-2,1,4,NETHER_FENCE)
Block(-2,2,-7,NETHER_BRICK_STAIRS:4)
Block(-2,2,-6,NETHER_BRICK_STAIRS:4)
Block(-2,2,-5,NETHER_BRICK_STAIRS:4)
Block(-2,2,-4,NETHER_BRICK_STAIRS:4)
Block(-2,2,-3,NETHER_BRICK_STAIRS:4)
Block(-2,2,-2,NETHER_BRICK_STAIRS:4)
Block(-2,2,-1,NETHER_BRICK_STAIRS:4)
Block(-2,2,0,NETHER_BRICK)
Block(-2,2,1,NETHER_BRICK_STAIRS:4)
Block(-2,2,2,NETHER_BRICK_STAIRS:4)
Block(-2,2,3,NETHER_BRICK_STAIRS:4)
Block(-2,2,4,NETHER_BRICK_STAIRS:4)
Block(-2,2,5,NETHER_BRICK_STAIRS:4)
Block(-2,2,6,NETHER_BRICK_STAIRS:4)
Block(-2,2,7,NETHER_BRICK_STAIRS:4)
Block(-2,3,-7,NETHER_FENCE)
Block(-2,3,-6,NETHER_FENCE)
Block(-2,3,-5,NETHER_FENCE)
Block(-2,3,-4,NETHER_BRICK)
Block(-2,3,-3,NETHER_FENCE)
Block(-2,3,-2,NETHER_FENCE)
Block(-2,3,-1,NETHER_FENCE)
Block(-2,3,0,NETHER_BRICK)
Block(-2,3,1,NETHER_FENCE)
Block(-2,3,2,NETHER_FENCE)
Block(-2,3,3,NETHER_FENCE)
Block(-2,3,4,NETHER_BRICK)
Block(-2,3,5,NETHER_FENCE)
Block(-2,3,6,NETHER_FENCE)
Block(-2,3,7,NETHER_FENCE)
Block(-2,4,-4,STEP:6)
Block(-2,4,0,STEP:6)
Block(-2,4,4,STEP:6)
Block(-1,0,-4,NETHER_FENCE)
Block(-1,0,0,NETHER_FENCE)
Block(-1,0,4,NETHER_FENCE)
Block(-1,1,-7,NETHER_FENCE)
Block(-1,1,-6,NETHER_FENCE)
Block(-1,1,-5,NETHER_FENCE)
Block(-1,1,-4,OBSIDIAN)
Block(-1,1,-3,NETHER_FENCE)
Block(-1,1,-2,NETHER_FENCE)
Block(-1,1,-1,NETHER_FENCE)
Block(-1,1,0,OBSIDIAN)
Block(-1,1,1,NETHER_FENCE)
Block(-1,1,2,NETHER_FENCE)
Block(-1,1,3,NETHER_FENCE)
Block(-1,1,4,OBSIDIAN)
Block(-1,1,5,NETHER_FENCE)
Block(-1,1,6,NETHER_FENCE)
Block(-1,1,7,NETHER_FENCE)
Block(-1,2,-7,STEP:6)
Block(-1,2,-6,STEP:6)
Block(-1,2,-5,STEP:6)
Block(-1,2,-4,STEP:6)
Block(-1,2,-3,STEP:6)
Block(-1,2,-2,STEP:6)
Block(-1,2,-1,STEP:6)
Block(-1,2,0,STEP:6)
Block(-1,2,1,STEP:6)
Block(-1,2,2,STEP:6)
Block(-1,2,3,STEP:6)
Block(-1,2,4,STEP:6)
Block(-1,2,5,STEP:6)
Block(-1,2,6,STEP:6)
Block(-1,2,7,STEP:6)
Block(-1,3,-7,AIR)
Block(-1,3,-6,AIR)
Block(-1,3,-5,AIR)
Block(-1,3,-4,AIR)
Block(-1,3,-3,AIR)
Block(-1,3,-2,AIR)
Block(-1,3,-1,AIR)
Block(-1,3,0,AIR)
Block(-1,3,1,AIR)
Block(-1,3,2,AIR)
Block(-1,3,3,AIR)
Block(-1,3,4,AIR)
Block(-1,3,5,AIR)
Block(-1,3,6,AIR)
Block(-1,3,7,AIR)
Block(-1,4,-7,AIR)
Block(-1,4,-6,AIR)
Block(-1,4,-5,AIR)
Block(-1,4,-4,AIR)
Block(-1,4,-3,AIR)
Block(-1,4,-2,AIR)
Block(-1,4,-1,AIR)
Block(-1,4,0,AIR)
Block(-1,4,1,AIR)
Block(-1,4,2,AIR)
Block(-1,4,3,AIR)
Block(-1,4,4,AIR)
Block(-1,4,5,AIR)
Block(-1,4,6,AIR)
Block(-1,4,7,AIR)
Block(0,1,0,NETHER_FENCE)
Block(0,2,-7,STEP:6)
Block(0,2,-6,STEP:6)
Block(0,2,-5,STEP:6)
Block(0,2,-4,STEP:6)
Block(0,2,-3,STEP:6)
Block(0,2,-2,STEP:6)
Block(0,2,-1,STEP:6)
Block(0,2,0,STEP:6)
Block(0,2,1,STEP:6)
Block(0,2,2,STEP:6)
Block(0,2,3,STEP:6)
Block(0,2,4,STEP:6)
Block(0,2,5,STEP:6)
Block(0,2,6,STEP:6)
Block(0,2,7,STEP:6)
Block(0,3,-7,AIR)
Block(0,3,-6,AIR)
Block(0,3,-5,AIR)
Block(0,3,-4,AIR)
Block(0,3,-3,AIR)
Block(0,3,-2,AIR)
Block(0,3,-1,AIR)
Block(0,3,0,AIR)
Block(0,3,1,AIR)
Block(0,3,2,AIR)
Block(0,3,3,AIR)
Block(0,3,4,AIR)
Block(0,3,5,AIR)
Block(0,3,6,AIR)
Block(0,3,7,AIR)
Block(0,4,-7,AIR)
Block(0,4,-6,AIR)
Block(0,4,-5,AIR)
Block(0,4,-4,AIR)
Block(0,4,-3,AIR)
Block(0,4,-2,AIR)
Block(0,4,-1,AIR)
Block(0,4,0,AIR)
Block(0,4,1,AIR)
Block(0,4,2,AIR)
Block(0,4,3,AIR)
Block(0,4,4,AIR)
Block(0,4,5,AIR)
Block(0,4,6,AIR)
Block(0,4,7,AIR)
Block(0,5,-7,AIR)
Block(0,5,-6,AIR)
Block(0,5,-5,AIR)
Block(0,5,-4,AIR)
Block(0,5,-3,AIR)
Block(0,5,-2,AIR)
Block(0,5,-1,AIR)
Block(0,5,0,AIR)
Block(0,5,1,AIR)
Block(0,5,2,AIR)
Block(0,5,3,AIR)
Block(0,5,4,AIR)
Block(0,5,5,AIR)
Block(0,5,6,AIR)
Block(0,5,7,AIR)
Block(1,0,-4,NETHER_FENCE)
Block(1,0,0,NETHER_FENCE)
Block(1,0,4,NETHER_FENCE)
Block(1,1,-7,NETHER_FENCE)
Block(1,1,-6,NETHER_FENCE)
Block(1,1,-5,NETHER_FENCE)
Block(1,1,-4,OBSIDIAN)
Block(1,1,-3,NETHER_FENCE)
Block(1,1,-2,NETHER_FENCE)
Block(1,1,-1,NETHER_FENCE)
Block(1,1,0,OBSIDIAN)
Block(1,1,1,NETHER_FENCE)
Block(1,1,2,NETHER_FENCE)
Block(1,1,3,NETHER_FENCE)
Block(1,1,4,OBSIDIAN)
Block(1,1,5,NETHER_FENCE)
Block(1,1,6,NETHER_FENCE)
Block(1,1,7,NETHER_FENCE)
Block(1,2,-7,STEP:6)
Block(1,2,-6,STEP:6)
Block(1,2,-5,STEP:6)
Block(1,2,-4,STEP:6)
Block(1,2,-3,STEP:6)
Block(1,2,-2,STEP:6)
Block(1,2,-1,STEP:6)
Block(1,2,0,STEP:6)
Block(1,2,1,STEP:6)
Block(1,2,2,STEP:6)
Block(1,2,3,STEP:6)
Block(1,2,4,STEP:6)
Block(1,2,5,STEP:6)
Block(1,2,6,STEP:6)
Block(1,2,7,STEP:6)
Block(1,3,-7,AIR)
Block(1,3,-6,AIR)
Block(1,3,-5,AIR)
Block(1,3,-4,AIR)
Block(1,3,-3,AIR)
Block(1,3,-2,AIR)
Block(1,3,-1,AIR)
Block(1,3,0,AIR)
Block(1,3,1,AIR)
Block(1,3,2,AIR)
Block(1,3,3,AIR)
Block(1,3,4,AIR)
Block(1,3,5,AIR)
Block(1,3,6,AIR)
Block(1,3,7,AIR)
Block(1,4,-7,AIR)
Block(1,4,-6,AIR)
Block(1,4,-5,AIR)
Block(1,4,-4,AIR)
Block(1,4,-3,AIR)
Block(1,4,-2,AIR)
Block(1,4,-1,AIR)
Block(1,4,0,AIR)
Block(1,4,1,AIR)
Block(1,4,2,AIR)
Block(1,4,3,AIR)
Block(1,4,4,AIR)
Block(1,4,5,AIR)
Block(1,4,6,AIR)
Block(1,4,7,AIR)
Block(2,1,-4,NETHER_FENCE)
Block(2,1,0,NETHER_FENCE)
Block(2,1,4,NETHER_FENCE)
Block(2,2,-7,NETHER_BRICK_STAIRS:5)
Block(2,2,-6,NETHER_BRICK_STAIRS:5)
Block(2,2,-5,NETHER_BRICK_STAIRS:5)
Block(2,2,-4,NETHER_BRICK_STAIRS:5)
Block(2,2,-3,NETHER_BRICK_STAIRS:5)
Block(2,2,-2,NETHER_BRICK_STAIRS:5)
Block(2,2,-1,NETHER_BRICK_STAIRS:5)
Block(2,2,0,NETHER_BRICK)
Block(2,2,1,NETHER_BRICK_STAIRS:5)
Block(2,2,2,NETHER_BRICK_STAIRS:5)
Block(2,2,3,NETHER_BRICK_STAIRS:5)
Block(2,2,4,NETHER_BRICK_STAIRS:5)
Block(2,2,5,NETHER_BRICK_STAIRS:5)
Block(2,2,6,NETHER_BRICK_STAIRS:5)
Block(2,2,7,NETHER_BRICK_STAIRS:5)
Block(2,3,-7,NETHER_FENCE)
Block(2,3,-6,NETHER_FENCE)
Block(2,3,-5,NETHER_FENCE)
Block(2,3,-4,NETHER_BRICK)
Block(2,3,-3,NETHER_FENCE)
Block(2,3,-2,NETHER_FENCE)
Block(2,3,-1,NETHER_FENCE)
Block(2,3,0,NETHER_BRICK)
Block(2,3,1,NETHER_FENCE)
Block(2,3,2,NETHER_FENCE)
Block(2,3,3,NETHER_FENCE)
Block(2,3,4,NETHER_BRICK)
Block(2,3,5,NETHER_FENCE)
Block(2,3,6,NETHER_FENCE)
Block(2,3,7,NETHER_FENCE)
Block(2,4,-4,STEP:6)
Block(2,4,0,STEP:6)
Block(2,4,4,STEP:6)
Block(3,2,-4,NETHER_FENCE)
Block(3,2,0,NETHER_FENCE)
Block(3,2,4,NETHER_FENCE)
Block(3,3,-4,NETHER_FENCE)
Block(3,3,0,NETHER_FENCE)
Block(3,3,4,NETHER_FENCE)
Block(3,4,-4,REDSTONE_TORCH_ON:5)
Block(3,4,0,NETHER_FENCE)
Block(3,4,4,REDSTONE_TORCH_ON:5)
Block(3,5,0,REDSTONE_TORCH_ON:5)

#######################################################################
# +-----------------------------------------------------------------+ #
# |                            BO3 checks                           | #
# +-----------------------------------------------------------------+ #
#######################################################################

# Require a condition at a certain location in order for the BO3 to be spawned.
# BlockCheck(x,y,z,id[.data][,id[.data][,...]])

#######################################################################
# +-----------------------------------------------------------------+ #
# |                             Branches                            | #
# +-----------------------------------------------------------------+ #
#######################################################################

# Branches are objects that will spawn when this object spawns when it is used in
# the CustomStructure resource. Branches can also have branches, making complex
# structures possible.
# Branch(x,y,z,branchName,rotation,chance[,anotherBranchName,rotation,chance[,...]])
# branchName - name of the object to spawn.
# rotation - NORTH, SOUTH, EAST or WEST.
Branch(0,0,-15,Nether-Tower-Bridge,NORTH,65,Nether-Tower-Spire,NORTH,40,Nether-Tower-Bridge-Cross,NORTH,50,Nether-Tower-Bridge-Cross2,NORTH,100)