
#######################################################################
# +-----------------------------------------------------------------+ #
# |                            BO3 object                           | #
# +-----------------------------------------------------------------+ #
#######################################################################

# This is the config file of a custom object.
# If you add this object correctly to your BiomeConfigs, it will spawn in the world.

# This is the creator of this BO3 object
Author:LanToaster

# A short description of this BO3 object
Description:No description given

# The BO3 version, don't change this! It can be used by external applications to do a version check.
Version:3

# The settings mode, WriteAll, WriteWithoutComments or WriteDisable. See WorldConfig.
SettingsMode:WriteDisable

#######################################################################
# +-----------------------------------------------------------------+ #
# |                          Main settings                          | #
# +-----------------------------------------------------------------+ #
#######################################################################

# This needs to be set to true to spawn the object in the Tree and Sapling resources.
Tree:true

# The frequency of the BO3 from 1 to 200. Tries this many times to spawn this BO3 when using the CustomObject(...) resource.
# Ignored by Tree(..), Sapling(..) and CustomStructure(..)
Frequency:1

# The rarity of the BO3 from 0 to 100. Each spawn attempt has rarity% chance to succeed when using the CustomObject(...) resource.
# Ignored by Tree(..), Sapling(..) and CustomStructure(..)
Rarity:100.0

# If you set this to true, the BO3 will be placed with a random rotation.
RotateRandomly:false

# The spawn height of the BO3 - randomY, highestBlock or highestSolidBlock.
SpawnHeight:highestBlock

# The height limits for the BO3.
MinHeight:0
MaxHeight:256

# Objects can have other objects attacthed to it: branches. Branches can also
# have branches attached to it, which can also have branches, etc. This is the
# maximum branch depth for this objects.
MaxBranchDepth:10

# When spawned with the UseWorld keyword, this BO3 should NOT spawn in the following biomes.
# If you write the BO3 name directly in the BiomeConfigs, this will be ignored.
ExcludedBiomes:All

#######################################################################
# +-----------------------------------------------------------------+ #
# |                      Source block settings                      | #
# +-----------------------------------------------------------------+ #
#######################################################################

# The block the BO3 should spawn in
SourceBlock:74

# The maximum percentage of the BO3 that can be outside the SourceBlock.
# The BO3 won't be placed on a location with more blocks outside the SourceBlock than this percentage.
MaxPercentageOutsideSourceBlock:65

# What to do when a block is about to be placed outside the SourceBlock? (dontPlace, placeAnyway)
OutsideSourceBlock:placeAnyway

#######################################################################
# +-----------------------------------------------------------------+ #
# |                              Blocks                             | #
# +-----------------------------------------------------------------+ #
#######################################################################

# All the blocks used in the BO3 are listed here. Possible blocks:
# Block(x,y,z,id[.data][,nbtfile.nbt)
# RandomBlock(x,y,z,id[:data][,nbtfile.nbt],chance[,id[:data][,nbtfile.nbt],chance[,...]])
# So RandomBlock(0,0,0,CHEST,chest.nbt,50,CHEST,anotherchest.nbt,100) will spawn a chest at
# the BO3 origin, and give it a 50% chance to have the contents of chest.nbt, or, if that
# fails, a 100% percent chance to have the contents of anotherchest.nbt.
Block(-5,0,-2,OBSIDIAN)
Block(-5,0,-1,NETHER_BRICK_STAIRS:4)
Block(-5,0,0,NETHER_BRICK_STAIRS:4)
Block(-5,0,1,NETHER_BRICK_STAIRS:4)
Block(-5,0,2,OBSIDIAN)
Block(-5,1,-4,NETHER_FENCE)
Block(-5,1,-3,NETHER_FENCE)
Block(-5,1,-2,NETHER_BRICK)
Block(-5,1,-1,NETHER_BRICK)
Block(-5,1,0,NETHER_BRICK)
Block(-5,1,1,NETHER_BRICK)
Block(-5,1,2,NETHER_BRICK)
Block(-5,1,3,NETHER_FENCE)
Block(-5,1,4,NETHER_FENCE)
Block(-5,2,-3,NETHER_FENCE)
Block(-5,2,-2,NETHER_BRICK)
Block(-5,2,-1,NETHER_BRICK_STAIRS:3)
Block(-5,2,0,NETHER_BRICK_STAIRS)
Block(-5,2,1,NETHER_BRICK_STAIRS:2)
Block(-5,2,2,NETHER_BRICK)
Block(-5,2,3,NETHER_FENCE)
Block(-5,3,-4,NETHER_FENCE)
Block(-5,3,-3,NETHER_FENCE)
Block(-5,3,-2,NETHER_BRICK)
Block(-5,3,-1,NETHER_BRICK_STAIRS:7)
Block(-5,3,0,NETHER_BRICK_STAIRS:4)
Block(-5,3,1,NETHER_BRICK_STAIRS:6)
Block(-5,3,2,NETHER_BRICK)
Block(-5,3,3,NETHER_FENCE)
Block(-5,3,4,NETHER_FENCE)
Block(-5,4,-2,NETHER_BRICK_STAIRS:2)
Block(-5,4,-1,NETHER_BRICK_STAIRS)
Block(-5,4,0,NETHER_BRICK_STAIRS)
Block(-5,4,1,NETHER_BRICK_STAIRS)
Block(-5,4,2,NETHER_BRICK_STAIRS:3)
Block(-4,0,-4,OBSIDIAN)
Block(-4,0,-3,OBSIDIAN)
Block(-4,0,-2,NETHER_BRICK)
Block(-4,0,-1,NETHER_BRICK)
Block(-4,0,0,NETHER_BRICK)
Block(-4,0,1,NETHER_BRICK)
Block(-4,0,2,NETHER_BRICK)
Block(-4,0,3,OBSIDIAN)
Block(-4,0,4,OBSIDIAN)
Block(-4,1,-5,NETHER_FENCE)
Block(-4,1,-4,NETHER_BRICK)
Block(-4,1,-3,NETHER_BRICK)
Block(-4,1,-2,NETHER_BRICK)
Block(-4,1,-1,NETHER_BRICK)
Block(-4,1,0,NETHERRACK)
Block(-4,1,1,NETHER_BRICK_STAIRS:7)
Block(-4,1,2,AIR)
Block(-4,1,3,NETHER_BRICK)
Block(-4,1,4,NETHER_BRICK)
Block(-4,1,5,NETHER_FENCE)
Block(-4,2,-4,NETHER_BRICK)
Block(-4,2,-3,NETHER_BRICK)
Block(-4,2,-2,AIR)
Block(-4,2,0,FIRE:15)
Block(-4,2,3,NETHER_BRICK)
Block(-4,2,4,NETHER_BRICK)
Block(-4,3,-5,NETHER_FENCE)
Block(-4,3,-4,NETHER_BRICK)
Block(-4,3,-3,NETHER_BRICK)
Block(-4,3,3,NETHER_BRICK)
Block(-4,3,4,NETHER_BRICK)
Block(-4,3,5,NETHER_FENCE)
Block(-4,4,-3,NETHER_BRICK_STAIRS)
Block(-4,4,-2,NETHER_BRICK)
Block(-4,4,-1,NETHER_BRICK)
Block(-4,4,0,NETHER_BRICK)
Block(-4,4,1,NETHER_BRICK)
Block(-4,4,2,NETHER_BRICK)
Block(-4,4,3,NETHER_BRICK_STAIRS)
Block(-4,5,-1,OBSIDIAN)
Block(-4,5,0,OBSIDIAN)
Block(-4,5,1,OBSIDIAN)
Block(-4,6,-1,NETHER_BRICK)
Block(-4,6,0,NETHER_BRICK)
Block(-4,6,1,NETHER_BRICK)
Block(-4,7,-1,NETHER_BRICK)
Block(-4,7,0,NETHER_BRICK_STAIRS)
Block(-4,7,1,NETHER_BRICK)
Block(-4,8,-1,NETHER_BRICK)
Block(-4,8,0,NETHER_BRICK_STAIRS:4)
Block(-4,8,1,NETHER_BRICK)
Block(-4,9,-1,NETHER_BRICK)
Block(-4,9,0,NETHER_BRICK)
Block(-4,9,1,NETHER_BRICK)
Block(-4,10,-1,NETHER_BRICK_STAIRS:2)
Block(-4,10,0,NETHER_BRICK_STAIRS)
Block(-4,10,1,NETHER_BRICK_STAIRS:3)
Block(-3,0,-4,OBSIDIAN)
Block(-3,0,-3,NETHER_BRICK)
Block(-3,0,-2,NETHER_BRICK)
Block(-3,0,-1,NETHER_BRICK)
Block(-3,0,0,NETHER_BRICK)
Block(-3,0,1,NETHER_BRICK)
Block(-3,0,2,NETHER_BRICK)
Block(-3,0,3,NETHER_BRICK)
Block(-3,0,4,OBSIDIAN)
Block(-3,1,-5,NETHER_FENCE)
Block(-3,1,-4,NETHER_BRICK)
Block(-3,1,-3,SOUL_SAND)
Block(-3,1,-2,NETHER_BRICK_STAIRS:7)
Block(-3,1,-1,NETHER_BRICK_STAIRS:5)
Block(-3,1,0,NETHER_BRICK_STAIRS:5)
Block(-3,1,1,NETHER_BRICK_STAIRS:5)
Block(-3,1,2,AIR)
Block(-3,1,3,AIR)
Block(-3,1,4,NETHER_BRICK)
Block(-3,1,5,NETHER_FENCE)
Block(-3,2,-5,NETHER_FENCE)
Block(-3,2,-4,NETHER_BRICK)
Block(-3,2,-3,NETHER_WARTS)
Block(-3,2,3,AIR)
Block(-3,2,4,NETHER_BRICK)
Block(-3,2,5,NETHER_FENCE)
Block(-3,3,-5,NETHER_FENCE)
Block(-3,3,-4,NETHER_BRICK)
Block(-3,3,-3,AIR)
Block(-3,3,3,FIRE:15)
Block(-3,3,4,NETHER_BRICK)
Block(-3,3,5,NETHER_FENCE)
Block(-3,4,-4,NETHER_BRICK_STAIRS:2)
Block(-3,4,-3,NETHER_BRICK)
Block(-3,4,-2,NETHER_BRICK)
Block(-3,4,-1,NETHER_BRICK)
Block(-3,4,0,NETHER_BRICK)
Block(-3,4,1,NETHER_BRICK)
Block(-3,4,2,NETHER_BRICK)
Block(-3,4,3,NETHER_BRICK)
Block(-3,4,4,NETHER_BRICK_STAIRS:3)
Block(-3,5,-3,NETHER_FENCE)
Block(-3,5,-2,OBSIDIAN)
Block(-3,5,-1,NETHER_BRICK)
Block(-3,5,0,NETHER_BRICK)
Block(-3,5,1,NETHER_BRICK)
Block(-3,5,2,OBSIDIAN)
Block(-3,5,3,NETHER_FENCE)
Block(-3,6,-3,NETHER_FENCE)
Block(-3,6,-2,OBSIDIAN)
Block(-3,6,-1,AIR)
Block(-3,6,0,CHEST:5)
Block(-3,6,1,AIR)
Block(-3,6,2,OBSIDIAN)
Block(-3,6,3,NETHER_FENCE)
Block(-3,7,-3,REDSTONE_TORCH_ON:5)
Block(-3,7,-2,OBSIDIAN)
Block(-3,7,-1,AIR)
Block(-3,7,0,AIR)
Block(-3,7,1,AIR)
Block(-3,7,2,OBSIDIAN)
Block(-3,7,3,REDSTONE_TORCH_ON:5)
Block(-3,8,-2,OBSIDIAN)
Block(-3,8,-1,AIR)
Block(-3,8,0,AIR)
Block(-3,8,1,AIR)
Block(-3,8,2,OBSIDIAN)
Block(-3,9,-2,OBSIDIAN)
Block(-3,9,-1,AIR)
Block(-3,9,0,AIR)
Block(-3,9,1,AIR)
Block(-3,9,2,OBSIDIAN)
Block(-3,10,-2,STEP:6)
Block(-3,10,-1,NETHER_BRICK_STAIRS:7)
Block(-3,10,0,AIR)
Block(-3,10,1,NETHER_BRICK_STAIRS:6)
Block(-3,10,2,STEP:6)
Block(-3,11,-2,NETHER_FENCE)
Block(-3,11,-1,NETHER_BRICK)
Block(-3,11,0,NETHER_BRICK)
Block(-3,11,1,NETHER_BRICK)
Block(-3,11,2,NETHER_FENCE)
Block(-3,12,-2,NETHER_FENCE)
Block(-3,12,-1,NETHER_BRICK)
Block(-3,12,0,NETHER_FENCE)
Block(-3,12,1,NETHER_BRICK)
Block(-3,12,2,NETHER_FENCE)
Block(-3,13,-2,NETHER_BRICK_STAIRS:6)
Block(-3,13,-1,NETHER_BRICK)
Block(-3,13,0,NETHER_FENCE)
Block(-3,13,1,NETHER_BRICK)
Block(-3,13,2,NETHER_BRICK_STAIRS:7)
Block(-3,14,-2,OBSIDIAN)
Block(-3,14,-1,NETHER_BRICK)
Block(-3,14,0,NETHER_BRICK)
Block(-3,14,1,NETHER_BRICK)
Block(-3,14,2,OBSIDIAN)
Block(-2,0,-5,OBSIDIAN)
Block(-2,0,-4,NETHER_BRICK)
Block(-2,0,-3,NETHER_BRICK)
Block(-2,0,-2,NETHER_BRICK)
Block(-2,0,-1,NETHER_BRICK)
Block(-2,0,0,NETHER_BRICK)
Block(-2,0,1,NETHER_BRICK)
Block(-2,0,2,NETHER_BRICK)
Block(-2,0,3,NETHER_BRICK)
Block(-2,0,4,NETHER_BRICK)
Block(-2,0,5,OBSIDIAN)
Block(-2,1,-5,NETHER_BRICK)
Block(-2,1,-4,SOUL_SAND)
Block(-2,1,-3,SOUL_SAND)
Block(-2,1,-2,NETHER_BRICK_STAIRS:7)
Block(-2,1,3,AIR)
Block(-2,1,4,NETHER_FENCE)
Block(-2,1,5,NETHER_BRICK)
Block(-2,2,-5,NETHER_BRICK)
Block(-2,2,-4,NETHER_WARTS)
Block(-2,2,-3,NETHER_WARTS)
Block(-2,2,4,NETHER_FENCE)
Block(-2,2,5,NETHER_BRICK)
Block(-2,3,-5,NETHER_BRICK)
Block(-2,3,-4,AIR)
Block(-2,3,2,FIRE:15)
Block(-2,3,3,AIR)
Block(-2,3,4,NETHER_FENCE)
Block(-2,3,5,NETHER_BRICK)
Block(-2,4,-5,NETHER_BRICK_STAIRS)
Block(-2,4,-4,NETHER_BRICK)
Block(-2,4,-3,NETHER_BRICK)
Block(-2,4,-1,AIR)
Block(-2,4,0,AIR)
Block(-2,4,2,AIR)
Block(-2,4,3,NETHER_BRICK)
Block(-2,4,4,NETHER_BRICK)
Block(-2,4,5,NETHER_BRICK_STAIRS)
Block(-2,5,-3,OBSIDIAN)
Block(-2,5,-2,STEP:6)
Block(-2,5,-1,STEP:6)
Block(-2,5,0,STEP:6)
Block(-2,5,1,NETHER_BRICK)
Block(-2,5,2,NETHER_BRICK)
Block(-2,5,3,OBSIDIAN)
Block(-2,6,-3,OBSIDIAN)
Block(-2,6,-2,AIR)
Block(-2,6,-1,AIR)
Block(-2,6,0,AIR)
Block(-2,6,1,AIR)
Block(-2,6,2,NETHER_BRICK)
Block(-2,6,3,OBSIDIAN)
Block(-2,7,-3,OBSIDIAN)
Block(-2,7,-2,AIR)
Block(-2,7,-1,AIR)
Block(-2,7,0,AIR)
Block(-2,7,1,AIR)
Block(-2,7,2,NETHER_FENCE)
Block(-2,7,3,OBSIDIAN)
Block(-2,8,-3,OBSIDIAN)
Block(-2,8,-2,AIR)
Block(-2,8,-1,AIR)
Block(-2,8,0,AIR)
Block(-2,8,1,AIR)
Block(-2,8,2,NETHER_FENCE)
Block(-2,8,3,OBSIDIAN)
Block(-2,9,-3,OBSIDIAN)
Block(-2,9,-2,AIR)
Block(-2,9,-1,AIR)
Block(-2,9,0,NETHER_BRICK_STAIRS:4)
Block(-2,9,1,NETHER_BRICK_STAIRS:4)
Block(-2,9,2,NETHER_BRICK)
Block(-2,9,3,OBSIDIAN)
Block(-2,10,-3,STEP:6)
Block(-2,10,-2,OBSIDIAN)
Block(-2,10,-1,NETHER_BRICK)
Block(-2,10,0,NETHER_BRICK_STAIRS:3)
Block(-2,10,1,AIR)
Block(-2,10,2,OBSIDIAN)
Block(-2,10,3,STEP:6)
Block(-2,11,-3,NETHER_FENCE)
Block(-2,11,-2,OBSIDIAN)
Block(-2,11,-1,AIR)
Block(-2,11,0,AIR)
Block(-2,11,1,AIR)
Block(-2,11,2,OBSIDIAN)
Block(-2,11,3,NETHER_FENCE)
Block(-2,12,-3,NETHER_FENCE)
Block(-2,12,-2,OBSIDIAN)
Block(-2,12,-1,AIR)
Block(-2,12,0,AIR)
Block(-2,12,1,AIR)
Block(-2,12,2,OBSIDIAN)
Block(-2,12,3,NETHER_FENCE)
Block(-2,13,-3,NETHER_BRICK_STAIRS:4)
Block(-2,13,-2,OBSIDIAN)
Block(-2,13,-1,AIR)
Block(-2,13,0,AIR)
Block(-2,13,1,AIR)
Block(-2,13,2,OBSIDIAN)
Block(-2,13,3,NETHER_BRICK_STAIRS:4)
Block(-2,14,-3,OBSIDIAN)
Block(-2,14,-2,NETHER_BRICK)
Block(-2,14,-1,AIR)
Block(-2,14,0,AIR)
Block(-2,14,1,AIR)
Block(-2,14,2,NETHER_BRICK)
Block(-2,14,3,OBSIDIAN)
Block(-1,0,-5,NETHER_BRICK_STAIRS:6)
Block(-1,0,-4,NETHER_BRICK)
Block(-1,0,-3,NETHER_BRICK)
Block(-1,0,-2,NETHER_BRICK)
Block(-1,0,-1,NETHER_BRICK)
Block(-1,0,0,NETHER_BRICK)
Block(-1,0,1,NETHER_BRICK)
Block(-1,0,2,NETHER_BRICK)
Block(-1,0,3,NETHER_BRICK)
Block(-1,0,4,NETHER_BRICK)
Block(-1,0,5,NETHER_BRICK_STAIRS:7)
Block(-1,1,-5,NETHER_BRICK)
Block(-1,1,-4,SOUL_SAND)
Block(-1,1,-3,SOUL_SAND)
Block(-1,1,-2,NETHER_BRICK_STAIRS:7)
Block(-1,1,3,AIR)
Block(-1,1,4,AIR)
Block(-1,1,5,NETHER_BRICK)
Block(-1,2,-5,NETHER_BRICK_STAIRS:1)
Block(-1,2,-4,NETHER_WARTS)
Block(-1,2,-3,NETHER_WARTS:1)
Block(-1,2,4,AIR)
Block(-1,2,5,NETHER_BRICK_STAIRS:1)
Block(-1,3,-5,NETHER_BRICK_STAIRS:5)
Block(-1,3,-4,AIR)
Block(-1,3,3,AIR)
Block(-1,3,4,NETHER_FENCE)
Block(-1,3,5,NETHER_BRICK_STAIRS:5)
Block(-1,4,-5,NETHER_BRICK_STAIRS:2)
Block(-1,4,-4,NETHER_BRICK)
Block(-1,4,-3,NETHER_BRICK)
Block(-1,4,0,FIRE:15)
Block(-1,4,2,FIRE:15)
Block(-1,4,3,NETHER_BRICK)
Block(-1,4,4,NETHER_BRICK)
Block(-1,4,5,NETHER_BRICK_STAIRS:3)
Block(-1,5,-4,OBSIDIAN)
Block(-1,5,-3,NETHER_BRICK)
Block(-1,5,-2,STEP:6)
Block(-1,5,-1,STEP:6)
Block(-1,5,0,STEP:6)
Block(-1,5,1,NETHER_BRICK_STAIRS:2)
Block(-1,5,2,NETHER_BRICK)
Block(-1,5,3,NETHER_BRICK)
Block(-1,5,4,OBSIDIAN)
Block(-1,6,-4,NETHER_BRICK)
Block(-1,6,-3,AIR)
Block(-1,6,-2,AIR)
Block(-1,6,-1,AIR)
Block(-1,6,0,AIR)
Block(-1,6,1,AIR)
Block(-1,6,2,NETHER_BRICK_STAIRS:2)
Block(-1,6,3,NETHER_BRICK)
Block(-1,6,4,NETHER_BRICK)
Block(-1,7,-4,NETHER_BRICK)
Block(-1,7,-3,AIR)
Block(-1,7,-2,AIR)
Block(-1,7,-1,AIR)
Block(-1,7,0,AIR)
Block(-1,7,1,AIR)
Block(-1,7,2,AIR)
Block(-1,7,3,STEP:6)
Block(-1,7,4,NETHER_BRICK)
Block(-1,8,-4,NETHER_BRICK)
Block(-1,8,-3,AIR)
Block(-1,8,-2,AIR)
Block(-1,8,-1,AIR)
Block(-1,8,0,AIR)
Block(-1,8,1,AIR)
Block(-1,8,2,AIR)
Block(-1,8,3,AIR)
Block(-1,8,4,NETHER_BRICK)
Block(-1,9,-4,NETHER_BRICK)
Block(-1,9,-3,AIR)
Block(-1,9,-2,AIR)
Block(-1,9,-1,AIR)
Block(-1,9,0,NETHER_BRICK_STAIRS:6)
Block(-1,9,1,NETHER_BRICK_STAIRS:1)
Block(-1,9,2,AIR)
Block(-1,9,3,AIR)
Block(-1,9,4,NETHER_BRICK)
Block(-1,10,-4,NETHER_BRICK_STAIRS)
Block(-1,10,-3,NETHER_BRICK_STAIRS:5)
Block(-1,10,-2,STEP:14)
Block(-1,10,-1,NETHER_BRICK)
Block(-1,10,0,NETHER_BRICK)
Block(-1,10,1,AIR)
Block(-1,10,2,AIR)
Block(-1,10,3,NETHER_BRICK_STAIRS:5)
Block(-1,10,4,NETHER_BRICK_STAIRS)
Block(-1,11,-3,NETHER_BRICK)
Block(-1,11,-2,AIR)
Block(-1,11,-1,AIR)
Block(-1,11,0,LADDER:4)
Block(-1,11,1,AIR)
Block(-1,11,2,AIR)
Block(-1,11,3,NETHER_BRICK)
Block(-1,12,-3,NETHER_BRICK)
Block(-1,12,-2,AIR)
Block(-1,12,-1,AIR)
Block(-1,12,0,LADDER:4)
Block(-1,12,1,AIR)
Block(-1,12,2,AIR)
Block(-1,12,3,NETHER_BRICK)
Block(-1,13,-3,NETHER_BRICK)
Block(-1,13,-2,AIR)
Block(-1,13,-1,AIR)
Block(-1,13,0,LADDER:4)
Block(-1,13,1,AIR)
Block(-1,13,2,AIR)
Block(-1,13,3,NETHER_BRICK)
Block(-1,14,-3,NETHER_BRICK)
Block(-1,14,-2,AIR)
Block(-1,14,-1,AIR)
Block(-1,14,0,LADDER:4)
Block(-1,14,1,AIR)
Block(-1,14,2,AIR)
Block(-1,14,3,NETHER_BRICK)
Block(0,0,-5,NETHER_BRICK_STAIRS:6)
Block(0,0,-4,NETHER_BRICK)
Block(0,0,-3,NETHER_BRICK)
Block(0,0,-2,NETHER_BRICK)
Block(0,0,-1,STEP:6)
Block(0,0,0,LADDER:2)
Block(0,0,1,NETHER_BRICK)
Block(0,0,2,NETHER_BRICK)
Block(0,0,3,NETHER_BRICK)
Block(0,0,4,NETHER_BRICK)
Block(0,0,5,NETHER_BRICK_STAIRS:7)
Block(0,1,-5,NETHER_BRICK)
Block(0,1,-4,SOUL_SAND)
Block(0,1,-3,SOUL_SAND)
Block(0,1,-2,NETHER_BRICK_STAIRS:7)
Block(0,1,0,LADDER:2)
Block(0,1,1,NETHER_BRICK)
Block(0,1,2,NETHER_BRICK_STAIRS:3)
Block(0,1,3,AIR)
Block(0,1,4,AIR)
Block(0,1,5,NETHER_BRICK)
Block(0,2,-5,NETHER_FENCE)
Block(0,2,-4,NETHER_WARTS:2)
Block(0,2,-3,NETHER_WARTS:1)
Block(0,2,0,STEP:14)
Block(0,2,1,NETHER_BRICK_STAIRS:3)
Block(0,2,2,AIR)
Block(0,2,3,AIR)
Block(0,2,4,AIR)
Block(0,2,5,NETHER_BRICK_STAIRS:3)
Block(0,3,-5,NETHER_FENCE)
Block(0,3,-4,AIR)
Block(0,3,-3,AIR)
Block(0,3,-2,AIR)
Block(0,3,-1,NETHER_BRICK_STAIRS:6)
Block(0,3,0,NETHER_BRICK_STAIRS:3)
Block(0,3,2,AIR)
Block(0,3,3,AIR)
Block(0,3,4,NETHER_FENCE)
Block(0,3,5,NETHER_BRICK_STAIRS:7)
Block(0,4,-5,NETHER_BRICK_STAIRS:2)
Block(0,4,-4,NETHER_BRICK)
Block(0,4,-3,NETHER_BRICK)
Block(0,4,-2,NETHER_BRICK)
Block(0,4,-1,NETHER_BRICK_STAIRS:3)
Block(0,4,0,AIR)
Block(0,4,1,AIR)
Block(0,4,2,AIR)
Block(0,4,3,NETHER_BRICK)
Block(0,4,4,NETHER_BRICK)
Block(0,4,5,NETHER_BRICK_STAIRS:3)
Block(0,5,-4,OBSIDIAN)
Block(0,5,-3,NETHER_BRICK)
Block(0,5,-2,AIR)
Block(0,5,-1,AIR)
Block(0,5,0,AIR)
Block(0,5,1,AIR)
Block(0,5,2,NETHER_BRICK)
Block(0,5,3,NETHER_BRICK)
Block(0,5,4,OBSIDIAN)
Block(0,6,-4,NETHER_BRICK)
Block(0,6,-3,NETHER_BRICK_STAIRS:7)
Block(0,6,-2,AIR)
Block(0,6,-1,AIR)
Block(0,6,0,AIR)
Block(0,6,1,AIR)
Block(0,6,2,NETHER_BRICK_STAIRS:2)
Block(0,6,3,NETHER_BRICK)
Block(0,6,4,NETHER_BRICK)
Block(0,7,-4,NETHER_BRICK_STAIRS:2)
Block(0,7,-3,REDSTONE_TORCH_ON:5)
Block(0,7,-2,AIR)
Block(0,7,-1,AIR)
Block(0,7,0,AIR)
Block(0,7,1,AIR)
Block(0,7,2,NETHER_BRICK_STAIRS:6)
Block(0,7,3,NETHER_BRICK)
Block(0,7,4,NETHER_BRICK)
Block(0,8,-4,NETHER_BRICK_STAIRS:6)
Block(0,8,-3,AIR)
Block(0,8,-2,AIR)
Block(0,8,-1,AIR)
Block(0,8,0,AIR)
Block(0,8,1,NETHER_BRICK_STAIRS:6)
Block(0,8,2,NETHER_BRICK_STAIRS:3)
Block(0,8,3,AIR)
Block(0,8,4,NETHER_BRICK)
Block(0,9,-4,NETHER_BRICK)
Block(0,9,-3,AIR)
Block(0,9,-2,AIR)
Block(0,9,-1,AIR)
Block(0,9,0,NETHER_BRICK)
Block(0,9,1,LADDER:3)
Block(0,9,2,AIR)
Block(0,9,3,AIR)
Block(0,9,4,NETHER_BRICK)
Block(0,10,-4,NETHER_BRICK_STAIRS:2)
Block(0,10,-3,STEP:14)
Block(0,10,-2,STEP:14)
Block(0,10,-1,NETHER_BRICK)
Block(0,10,0,NETHER_BRICK)
Block(0,10,1,LADDER:3)
Block(0,10,2,AIR)
Block(0,10,3,AIR)
Block(0,10,4,NETHER_BRICK_STAIRS:3)
Block(0,11,-3,NETHER_BRICK)
Block(0,11,-2,AIR)
Block(0,11,-1,LADDER:2)
Block(0,11,0,NETHER_BRICK)
Block(0,11,1,LADDER:3)
Block(0,11,2,AIR)
Block(0,11,3,NETHER_BRICK)
Block(0,12,-3,NETHER_FENCE)
Block(0,12,-2,AIR)
Block(0,12,-1,LADDER:2)
Block(0,12,0,NETHER_BRICK)
Block(0,12,1,LADDER:3)
Block(0,12,2,AIR)
Block(0,12,3,NETHER_FENCE)
Block(0,13,-3,NETHER_FENCE)
Block(0,13,-2,AIR)
Block(0,13,-1,LADDER:2)
Block(0,13,0,NETHER_BRICK)
Block(0,13,1,LADDER:3)
Block(0,13,2,AIR)
Block(0,13,3,NETHER_FENCE)
Block(0,14,-3,NETHER_BRICK)
Block(0,14,-2,AIR)
Block(0,14,-1,LADDER:2)
Block(0,14,0,NETHER_BRICK)
Block(0,14,1,LADDER:3)
Block(0,14,2,AIR)
Block(0,14,3,NETHER_BRICK)
Block(1,0,-5,NETHER_BRICK_STAIRS:6)
Block(1,0,-4,NETHER_BRICK)
Block(1,0,-3,NETHER_BRICK)
Block(1,0,-2,NETHER_BRICK)
Block(1,0,-1,NETHER_BRICK)
Block(1,0,0,NETHER_BRICK)
Block(1,0,1,NETHER_BRICK)
Block(1,0,2,NETHER_BRICK)
Block(1,0,3,NETHER_BRICK)
Block(1,0,4,NETHER_BRICK)
Block(1,0,5,NETHER_BRICK_STAIRS:7)
Block(1,1,-5,NETHER_BRICK)
Block(1,1,-4,SOUL_SAND)
Block(1,1,-3,SOUL_SAND)
Block(1,1,-2,NETHER_BRICK_STAIRS:7)
Block(1,1,-1,AIR)
Block(1,1,0,AIR)
Block(1,1,1,AIR)
Block(1,1,2,AIR)
Block(1,1,3,AIR)
Block(1,1,4,AIR)
Block(1,1,5,NETHER_BRICK)
Block(1,2,-5,NETHER_BRICK_STAIRS)
Block(1,2,-4,NETHER_WARTS:2)
Block(1,2,-3,NETHER_WARTS:1)
Block(1,2,-2,AIR)
Block(1,2,0,AIR)
Block(1,2,1,AIR)
Block(1,2,2,AIR)
Block(1,2,3,AIR)
Block(1,2,4,AIR)
Block(1,2,5,NETHER_BRICK_STAIRS)
Block(1,3,-5,NETHER_BRICK_STAIRS:4)
Block(1,3,-4,AIR)
Block(1,3,-3,AIR)
Block(1,3,-2,AIR)
Block(1,3,-1,AIR)
Block(1,3,0,AIR)
Block(1,3,1,AIR)
Block(1,3,2,AIR)
Block(1,3,3,AIR)
Block(1,3,4,NETHER_FENCE)
Block(1,3,5,NETHER_BRICK_STAIRS:4)
Block(1,4,-5,NETHER_BRICK_STAIRS:2)
Block(1,4,-4,NETHER_BRICK)
Block(1,4,-3,NETHER_BRICK)
Block(1,4,-2,AIR)
Block(1,4,-1,AIR)
Block(1,4,0,AIR)
Block(1,4,1,AIR)
Block(1,4,2,AIR)
Block(1,4,3,NETHER_BRICK)
Block(1,4,4,NETHER_BRICK)
Block(1,4,5,NETHER_BRICK_STAIRS:3)
Block(1,5,-4,OBSIDIAN)
Block(1,5,-3,NETHER_BRICK)
Block(1,5,-2,STEP:6)
Block(1,5,-1,STEP:6)
Block(1,5,0,STEP:6)
Block(1,5,1,NETHER_BRICK_STAIRS:2)
Block(1,5,2,NETHER_BRICK)
Block(1,5,3,NETHER_BRICK)
Block(1,5,4,OBSIDIAN)
Block(1,6,-4,NETHER_BRICK)
Block(1,6,-3,AIR)
Block(1,6,-2,AIR)
Block(1,6,-1,AIR)
Block(1,6,0,AIR)
Block(1,6,1,AIR)
Block(1,6,2,NETHER_BRICK_STAIRS:2)
Block(1,6,3,NETHER_BRICK)
Block(1,6,4,NETHER_BRICK)
Block(1,7,-4,NETHER_BRICK)
Block(1,7,-3,AIR)
Block(1,7,-2,AIR)
Block(1,7,-1,AIR)
Block(1,7,0,AIR)
Block(1,7,1,AIR)
Block(1,7,2,AIR)
Block(1,7,3,STEP:6)
Block(1,7,4,NETHER_BRICK)
Block(1,8,-4,NETHER_BRICK)
Block(1,8,-3,AIR)
Block(1,8,-2,AIR)
Block(1,8,-1,AIR)
Block(1,8,0,AIR)
Block(1,8,1,AIR)
Block(1,8,2,AIR)
Block(1,8,3,AIR)
Block(1,8,4,NETHER_BRICK)
Block(1,9,-4,NETHER_BRICK)
Block(1,9,-3,AIR)
Block(1,9,-2,AIR)
Block(1,9,-1,AIR)
Block(1,9,0,NETHER_BRICK_STAIRS:6)
Block(1,9,1,NETHER_BRICK_STAIRS)
Block(1,9,2,AIR)
Block(1,9,3,AIR)
Block(1,9,4,NETHER_BRICK)
Block(1,10,-4,NETHER_BRICK_STAIRS:1)
Block(1,10,-3,NETHER_BRICK_STAIRS:4)
Block(1,10,-2,STEP:14)
Block(1,10,-1,NETHER_BRICK)
Block(1,10,0,NETHER_BRICK)
Block(1,10,1,AIR)
Block(1,10,2,AIR)
Block(1,10,3,NETHER_BRICK_STAIRS:4)
Block(1,10,4,NETHER_BRICK_STAIRS:1)
Block(1,11,-3,NETHER_BRICK)
Block(1,11,-2,AIR)
Block(1,11,-1,AIR)
Block(1,11,0,LADDER:5)
Block(1,11,1,AIR)
Block(1,11,2,AIR)
Block(1,11,3,NETHER_BRICK)
Block(1,12,-3,NETHER_BRICK)
Block(1,12,-2,AIR)
Block(1,12,-1,AIR)
Block(1,12,0,LADDER:5)
Block(1,12,1,AIR)
Block(1,12,2,AIR)
Block(1,12,3,NETHER_BRICK)
Block(1,13,-3,NETHER_BRICK)
Block(1,13,-2,AIR)
Block(1,13,-1,AIR)
Block(1,13,0,LADDER:5)
Block(1,13,1,AIR)
Block(1,13,2,AIR)
Block(1,13,3,NETHER_BRICK)
Block(1,14,-3,NETHER_BRICK)
Block(1,14,-2,AIR)
Block(1,14,-1,AIR)
Block(1,14,0,LADDER:5)
Block(1,14,1,AIR)
Block(1,14,2,AIR)
Block(1,14,3,NETHER_BRICK)
Block(2,0,-5,OBSIDIAN)
Block(2,0,-4,NETHER_BRICK)
Block(2,0,-3,NETHER_BRICK)
Block(2,0,-2,NETHER_BRICK)
Block(2,0,-1,NETHER_BRICK)
Block(2,0,0,NETHER_BRICK)
Block(2,0,1,NETHER_BRICK)
Block(2,0,2,NETHER_BRICK)
Block(2,0,3,NETHER_BRICK)
Block(2,0,4,NETHER_BRICK)
Block(2,0,5,OBSIDIAN)
Block(2,1,-5,NETHER_BRICK)
Block(2,1,-4,SOUL_SAND)
Block(2,1,-3,SOUL_SAND)
Block(2,1,-2,NETHER_BRICK_STAIRS:7)
Block(2,1,-1,AIR)
Block(2,1,0,AIR)
Block(2,1,1,AIR)
Block(2,1,2,AIR)
Block(2,1,3,AIR)
Block(2,1,4,NETHER_FENCE)
Block(2,1,5,NETHER_BRICK)
Block(2,2,-5,NETHER_BRICK)
Block(2,2,-4,NETHER_WARTS:3)
Block(2,2,-3,NETHER_WARTS:2)
Block(2,2,-2,AIR)
Block(2,2,-1,AIR)
Block(2,2,0,AIR)
Block(2,2,1,AIR)
Block(2,2,3,AIR)
Block(2,2,4,NETHER_FENCE)
Block(2,2,5,NETHER_BRICK)
Block(2,3,-5,NETHER_BRICK)
Block(2,3,-4,AIR)
Block(2,3,-3,AIR)
Block(2,3,-2,AIR)
Block(2,3,-1,AIR)
Block(2,3,0,AIR)
Block(2,3,1,AIR)
Block(2,3,2,AIR)
Block(2,3,3,AIR)
Block(2,3,4,NETHER_FENCE)
Block(2,3,5,NETHER_BRICK)
Block(2,4,-5,NETHER_BRICK_STAIRS:1)
Block(2,4,-4,NETHER_BRICK)
Block(2,4,-3,NETHER_BRICK)
Block(2,4,-2,AIR)
Block(2,4,-1,AIR)
Block(2,4,0,AIR)
Block(2,4,1,AIR)
Block(2,4,2,AIR)
Block(2,4,3,NETHER_BRICK)
Block(2,4,4,NETHER_BRICK)
Block(2,4,5,NETHER_BRICK_STAIRS:1)
Block(2,5,-3,OBSIDIAN)
Block(2,5,-2,STEP:6)
Block(2,5,-1,STEP:6)
Block(2,5,0,STEP:6)
Block(2,5,1,NETHER_BRICK)
Block(2,5,2,NETHER_BRICK)
Block(2,5,3,OBSIDIAN)
Block(2,6,-3,OBSIDIAN)
Block(2,6,-2,AIR)
Block(2,6,-1,AIR)
Block(2,6,0,AIR)
Block(2,6,1,AIR)
Block(2,6,2,NETHER_BRICK)
Block(2,6,3,OBSIDIAN)
Block(2,7,-3,OBSIDIAN)
Block(2,7,-2,AIR)
Block(2,7,-1,AIR)
Block(2,7,0,AIR)
Block(2,7,1,AIR)
Block(2,7,2,NETHER_FENCE)
Block(2,7,3,OBSIDIAN)
Block(2,8,-3,OBSIDIAN)
Block(2,8,-2,AIR)
Block(2,8,-1,AIR)
Block(2,8,0,AIR)
Block(2,8,1,AIR)
Block(2,8,2,NETHER_FENCE)
Block(2,8,3,OBSIDIAN)
Block(2,9,-3,OBSIDIAN)
Block(2,9,-2,AIR)
Block(2,9,-1,AIR)
Block(2,9,0,NETHER_BRICK_STAIRS:5)
Block(2,9,1,NETHER_BRICK_STAIRS:5)
Block(2,9,2,NETHER_BRICK)
Block(2,9,3,OBSIDIAN)
Block(2,10,-3,STEP:6)
Block(2,10,-2,OBSIDIAN)
Block(2,10,-1,NETHER_BRICK)
Block(2,10,0,NETHER_BRICK_STAIRS:3)
Block(2,10,1,AIR)
Block(2,10,2,OBSIDIAN)
Block(2,10,3,STEP:6)
Block(2,11,-3,NETHER_FENCE)
Block(2,11,-2,OBSIDIAN)
Block(2,11,-1,AIR)
Block(2,11,0,AIR)
Block(2,11,1,AIR)
Block(2,11,2,OBSIDIAN)
Block(2,11,3,NETHER_FENCE)
Block(2,12,-3,NETHER_FENCE)
Block(2,12,-2,OBSIDIAN)
Block(2,12,-1,AIR)
Block(2,12,0,AIR)
Block(2,12,1,AIR)
Block(2,12,2,OBSIDIAN)
Block(2,12,3,NETHER_FENCE)
Block(2,13,-3,NETHER_BRICK_STAIRS:5)
Block(2,13,-2,OBSIDIAN)
Block(2,13,-1,AIR)
Block(2,13,0,AIR)
Block(2,13,1,AIR)
Block(2,13,2,OBSIDIAN)
Block(2,13,3,NETHER_BRICK_STAIRS:5)
Block(2,14,-3,OBSIDIAN)
Block(2,14,-2,NETHER_BRICK)
Block(2,14,-1,AIR)
Block(2,14,0,AIR)
Block(2,14,1,AIR)
Block(2,14,2,NETHER_BRICK)
Block(2,14,3,OBSIDIAN)
Block(3,0,-4,OBSIDIAN)
Block(3,0,-3,NETHER_BRICK)
Block(3,0,-2,NETHER_BRICK)
Block(3,0,-1,NETHER_BRICK)
Block(3,0,0,NETHER_BRICK)
Block(3,0,1,NETHER_BRICK)
Block(3,0,2,NETHER_BRICK)
Block(3,0,3,NETHER_BRICK)
Block(3,0,4,OBSIDIAN)
Block(3,1,-5,NETHER_FENCE)
Block(3,1,-4,NETHER_BRICK)
Block(3,1,-3,SOUL_SAND)
Block(3,1,-2,NETHER_BRICK_STAIRS:7)
Block(3,1,-1,NETHER_BRICK_STAIRS:4)
Block(3,1,0,NETHER_BRICK_STAIRS:4)
Block(3,1,1,NETHER_BRICK_STAIRS:4)
Block(3,1,3,AIR)
Block(3,1,4,NETHER_BRICK)
Block(3,1,5,NETHER_FENCE)
Block(3,2,-5,NETHER_FENCE)
Block(3,2,-4,NETHER_BRICK)
Block(3,2,-3,NETHER_WARTS:1)
Block(3,2,-2,AIR)
Block(3,2,-1,AIR)
Block(3,2,4,NETHER_BRICK)
Block(3,2,5,NETHER_FENCE)
Block(3,3,-5,NETHER_FENCE)
Block(3,3,-4,NETHER_BRICK)
Block(3,3,-3,AIR)
Block(3,3,-2,AIR)
Block(3,3,-1,AIR)
Block(3,3,0,AIR)
Block(3,3,3,AIR)
Block(3,3,4,NETHER_BRICK)
Block(3,3,5,NETHER_FENCE)
Block(3,4,-4,NETHER_BRICK_STAIRS:2)
Block(3,4,-3,NETHER_BRICK)
Block(3,4,-2,NETHER_BRICK)
Block(3,4,-1,NETHER_BRICK)
Block(3,4,0,NETHER_BRICK)
Block(3,4,1,NETHER_BRICK)
Block(3,4,2,NETHER_BRICK)
Block(3,4,3,NETHER_BRICK)
Block(3,4,4,NETHER_BRICK_STAIRS:3)
Block(3,5,-3,NETHER_FENCE)
Block(3,5,-2,OBSIDIAN)
Block(3,5,-1,NETHER_BRICK)
Block(3,5,0,NETHER_BRICK)
Block(3,5,1,NETHER_BRICK)
Block(3,5,2,OBSIDIAN)
Block(3,5,3,NETHER_FENCE)
Block(3,6,-3,NETHER_FENCE)
Block(3,6,-2,OBSIDIAN)
Block(3,6,-1,AIR)
Block(3,6,0,CHEST:4)
Block(3,6,1,AIR)
Block(3,6,2,OBSIDIAN)
Block(3,6,3,NETHER_FENCE)
Block(3,7,-3,REDSTONE_TORCH_ON:5)
Block(3,7,-2,OBSIDIAN)
Block(3,7,-1,AIR)
Block(3,7,0,AIR)
Block(3,7,1,AIR)
Block(3,7,2,OBSIDIAN)
Block(3,7,3,REDSTONE_TORCH_ON:5)
Block(3,8,-2,OBSIDIAN)
Block(3,8,-1,AIR)
Block(3,8,0,AIR)
Block(3,8,1,AIR)
Block(3,8,2,OBSIDIAN)
Block(3,9,-2,OBSIDIAN)
Block(3,9,-1,AIR)
Block(3,9,0,AIR)
Block(3,9,1,AIR)
Block(3,9,2,OBSIDIAN)
Block(3,10,-2,STEP:6)
Block(3,10,-1,NETHER_BRICK_STAIRS:7)
Block(3,10,0,AIR)
Block(3,10,1,NETHER_BRICK_STAIRS:6)
Block(3,10,2,STEP:6)
Block(3,11,-2,NETHER_FENCE)
Block(3,11,-1,NETHER_BRICK)
Block(3,11,0,NETHER_BRICK)
Block(3,11,1,NETHER_BRICK)
Block(3,11,2,NETHER_FENCE)
Block(3,12,-2,NETHER_FENCE)
Block(3,12,-1,NETHER_BRICK)
Block(3,12,0,NETHER_FENCE)
Block(3,12,1,NETHER_BRICK)
Block(3,12,2,NETHER_FENCE)
Block(3,13,-2,NETHER_BRICK_STAIRS:6)
Block(3,13,-1,NETHER_BRICK)
Block(3,13,0,NETHER_FENCE)
Block(3,13,1,NETHER_BRICK)
Block(3,13,2,NETHER_BRICK_STAIRS:7)
Block(3,14,-2,OBSIDIAN)
Block(3,14,-1,NETHER_BRICK)
Block(3,14,0,NETHER_BRICK)
Block(3,14,1,NETHER_BRICK)
Block(3,14,2,OBSIDIAN)
Block(4,0,-4,OBSIDIAN)
Block(4,0,-3,OBSIDIAN)
Block(4,0,-2,NETHER_BRICK)
Block(4,0,-1,NETHER_BRICK)
Block(4,0,0,NETHER_BRICK)
Block(4,0,1,NETHER_BRICK)
Block(4,0,2,NETHER_BRICK)
Block(4,0,3,OBSIDIAN)
Block(4,0,4,OBSIDIAN)
Block(4,1,-5,NETHER_FENCE)
Block(4,1,-4,NETHER_BRICK)
Block(4,1,-3,NETHER_BRICK)
Block(4,1,-2,NETHER_BRICK)
Block(4,1,-1,NETHER_BRICK_STAIRS:6)
Block(4,1,0,NETHERRACK)
Block(4,1,1,NETHER_BRICK_STAIRS:7)
Block(4,1,3,NETHER_BRICK)
Block(4,1,4,NETHER_BRICK)
Block(4,1,5,NETHER_FENCE)
Block(4,2,-4,NETHER_BRICK)
Block(4,2,-3,NETHER_BRICK)
Block(4,2,-2,AIR)
Block(4,2,0,FIRE:15)
Block(4,2,3,NETHER_BRICK)
Block(4,2,4,NETHER_BRICK)
Block(4,3,-5,NETHER_FENCE)
Block(4,3,-4,NETHER_BRICK)
Block(4,3,-3,NETHER_BRICK)
Block(4,3,-2,AIR)
Block(4,3,3,NETHER_BRICK)
Block(4,3,4,NETHER_BRICK)
Block(4,3,5,NETHER_FENCE)
Block(4,4,-3,NETHER_BRICK_STAIRS:1)
Block(4,4,-2,NETHER_BRICK)
Block(4,4,-1,NETHER_BRICK)
Block(4,4,0,NETHER_BRICK)
Block(4,4,1,NETHER_BRICK)
Block(4,4,2,NETHER_BRICK)
Block(4,4,3,NETHER_BRICK_STAIRS:1)
Block(4,5,-1,OBSIDIAN)
Block(4,5,0,OBSIDIAN)
Block(4,5,1,OBSIDIAN)
Block(4,6,-1,NETHER_BRICK)
Block(4,6,0,NETHER_BRICK)
Block(4,6,1,NETHER_BRICK)
Block(4,7,-1,NETHER_BRICK)
Block(4,7,0,NETHER_BRICK_STAIRS:1)
Block(4,7,1,NETHER_BRICK)
Block(4,8,-1,NETHER_BRICK)
Block(4,8,0,NETHER_BRICK_STAIRS:5)
Block(4,8,1,NETHER_BRICK)
Block(4,9,-1,NETHER_BRICK)
Block(4,9,0,NETHER_BRICK)
Block(4,9,1,NETHER_BRICK)
Block(4,10,-1,NETHER_BRICK_STAIRS:2)
Block(4,10,0,NETHER_BRICK_STAIRS:1)
Block(4,10,1,NETHER_BRICK_STAIRS:3)
Block(5,0,-2,OBSIDIAN)
Block(5,0,-1,NETHER_BRICK_STAIRS:5)
Block(5,0,0,NETHER_BRICK_STAIRS:5)
Block(5,0,1,NETHER_BRICK_STAIRS:5)
Block(5,0,2,OBSIDIAN)
Block(5,1,-4,NETHER_FENCE)
Block(5,1,-3,NETHER_FENCE)
Block(5,1,-2,NETHER_BRICK)
Block(5,1,-1,NETHER_BRICK)
Block(5,1,0,NETHER_BRICK)
Block(5,1,1,NETHER_BRICK)
Block(5,1,2,NETHER_BRICK)
Block(5,1,3,NETHER_FENCE)
Block(5,1,4,NETHER_FENCE)
Block(5,2,-3,NETHER_FENCE)
Block(5,2,-2,NETHER_BRICK)
Block(5,2,-1,NETHER_BRICK_STAIRS:3)
Block(5,2,0,NETHER_BRICK_STAIRS:1)
Block(5,2,1,NETHER_BRICK_STAIRS:2)
Block(5,2,2,NETHER_BRICK)
Block(5,2,3,NETHER_FENCE)
Block(5,3,-4,NETHER_FENCE)
Block(5,3,-3,NETHER_FENCE)
Block(5,3,-2,NETHER_BRICK)
Block(5,3,-1,NETHER_BRICK_STAIRS:7)
Block(5,3,0,NETHER_BRICK_STAIRS:5)
Block(5,3,1,NETHER_BRICK_STAIRS:6)
Block(5,3,2,NETHER_BRICK)
Block(5,3,3,NETHER_FENCE)
Block(5,3,4,NETHER_FENCE)
Block(5,4,-2,NETHER_BRICK_STAIRS:2)
Block(5,4,-1,NETHER_BRICK_STAIRS:1)
Block(5,4,0,NETHER_BRICK_STAIRS:1)
Block(5,4,1,NETHER_BRICK_STAIRS:1)
Block(5,4,2,NETHER_BRICK_STAIRS:3)

#######################################################################
# +-----------------------------------------------------------------+ #
# |                            BO3 checks                           | #
# +-----------------------------------------------------------------+ #
#######################################################################

# Require a condition at a certain location in order for the BO3 to be spawned.
# BlockCheck(x,y,z,id[.data][,id[.data][,...]])

#######################################################################
# +-----------------------------------------------------------------+ #
# |                             Branches                            | #
# +-----------------------------------------------------------------+ #
#######################################################################

# Branches are objects that will spawn when this object spawns when it is used in
# the CustomStructure resource. Branches can also have branches, making complex
# structures possible.
# Branch(x,y,z,branchName,rotation,chance[,anotherBranchName,rotation,chance[,...]])
# branchName - name of the object to spawn.
# rotation - NORTH, SOUTH, EAST or WEST.
Branch(0,-7,0,Nether-Tower-Base2-A,NORTH,33,Nether-Tower-Base2-B,NORTH,50,Nether-Tower-Base2-C,NORTH,100)