[META]
version=2.0
spawnOnBlockType=2,3
spawnSunlight=True
spawnDarkness=True
spawnWater=False
spawnLava=False
underFill=False
randomRotation=True
dig=True
tree=True
branch=False
needsFoundation=True
rarity=30
collisionPercentage=2
spawnElevationMin=0
spawnElevationMax=220
spawnInBiome=WoWForest
[DATA]
0,-2,0:17
-1,-1,0:17
0,-1,0:17.0
1,-1,0:17.0
0,0,0:17.0
1,0,0:17.0
2,0,0:17
0,1,0:17
0,-1,1:17.0
1,-1,1:17.0
0,0,1:17.0
1,0,1:17.0
0,-1,2:17.0
0,0,2:17.0
1,0,2:17.0
0,-1,3:17.0
0,0,3:17.0
1,0,3:17.0
0,-1,4:17.0
0,0,4:17.0
1,0,4:17.0
0,-1,5:17.0
0,0,5:17.0
1,-4,6:18
-1,-3,6:18
0,-3,6:18
2,-2,6:18
3,-2,6:18
0,-1,6:17.0
0,0,6:17.0
1,0,6:18
0,1,6:18
1,1,6:18
2,1,6:18
0,2,6:18
1,2,6:18
2,2,6:18
2,-5,7:18
1,-4,7:18
2,-4,7:18
3,-4,7:18
-1,-3,7:18
0,-3,7:18
1,-3,7:18
2,-3,7:18
-2,-2,7:18
-1,-2,7:18
0,-2,7:17
1,-2,7:18
2,-2,7:18
-2,-1,7:18
-1,-1,7:18
0,-1,7:17
1,-1,7:18
2,-1,7:18
-2,0,7:18
0,0,7:17.0
1,1,7:18
1,2,7:18
2,-4,8:18
0,-3,8:18
1,-3,8:18
2,-3,8:18
-2,-2,8:18
-1,-2,8:18
0,-2,8:18
1,-2,8:18
2,-2,8:18
-2,-1,8:18
-1,-1,8:18
0,-1,8:18
1,-1,8:18
2,-1,8:18
-1,0,8:18
0,0,8:17.0
1,0,8:18
2,0,8:18
-1,1,8:18
0,1,8:18
1,1,8:18
-1,2,8:18
0,2,8:18
1,2,8:18
0,3,8:18
1,-3,9:18
2,-3,9:18
-1,-2,9:18
0,-2,9:18
1,-2,9:18
-2,-1,9:18
-1,-1,9:18
0,-1,9:18
1,-1,9:18
-2,0,9:18
-1,0,9:18
0,0,9:17.0
1,0,9:18
0,1,9:18
1,1,9:18
-1,2,9:18
0,2,9:18
1,2,9:18
0,3,9:18
1,-2,10:18
-2,-1,10:18
1,-1,10:18
-2,0,10:18
-1,0,10:18
0,0,10:17.0
1,0,10:18
2,0,10:18
-2,1,10:18
-1,1,10:18
0,1,10:17
1,1,10:18
2,1,10:18
-2,2,10:18
-1,2,10:18
0,2,10:18
1,2,10:18
-2,3,10:18
0,3,10:18
0,4,10:18
1,-3,11:18
0,-2,11:18
1,-2,11:18
2,-2,11:18
-2,-1,11:18
-1,-1,11:18
0,-1,11:18
1,-1,11:18
2,-1,11:18
-2,0,11:18
-1,0,11:18
0,0,11:17.0
1,0,11:18
2,0,11:18
-2,1,11:18
-1,1,11:18
0,1,11:18
1,1,11:18
2,1,11:18
-1,2,11:18
0,2,11:17.0
1,2,11:18
-2,3,11:18
-1,3,11:18
0,3,11:18
-2,4,11:18
-1,4,11:18
2,-3,12:18
1,-2,12:18
2,-2,12:18
-1,-1,12:18
0,-1,12:18
1,-1,12:18
-2,0,12:18
-1,0,12:18
0,0,12:17.0
1,0,12:18
-1,1,12:18
0,1,12:18
1,1,12:18
-1,2,12:18
0,2,12:18
1,2,12:18
-1,3,12:18
-1,4,12:18
1,-2,13:18
0,-1,13:18
1,-1,13:18
0,0,13:17.0
1,0,13:18
0,1,13:18
0,2,13:18
-1,3,13:18
0,-1,14:18
1,-1,14:18
0,0,14:18
1,0,14:18
2,0,14:18
-1,1,14:18
0,1,14:18
0,2,14:18
0,0,15:18
1,0,15:18
-1,1,15:18
0,1,15:18
0,0,16:18
1,0,16:18
