[META]
version=2.0
spawnOnBlockType=1,2,12
spawnSunlight=True
spawnDarkness=True
spawnWater=False
spawnLava=False
underFill=False
randomRotation=True
dig=True
tree=True
branch=False
needsFoundation=True
rarity=15
collisionPercentage=2
spawnElevationMin=0
spawnElevationMax=175
spawnInBiome=Plains
spawnAboveGround=True
spawnUnderGround=False
collisionBlockType=All
groupId=
diggingBranch=false
branchLimit=6
groupFrequencyMin=1
groupFrequencyMax=5
groupSeperationMin=0
groupSeperationMax=5
[DATA]
5,0,0:17.3
5,1,0:17.3
4,1,0:17.3
3,1,0:17.3
2,1,0:17.3
3,2,0:17.3
4,2,0:17.3
5,2,0:17.3
6,2,0:17.3
6,1,0:17.3
7,1,0:17.3
4,3,0:17.3
5,3,0:17.3
6,3,0:17.3
5,4,0:17.3
4,4,0:17.3
4,0,0:17.3
3,0,0:17.3
1,1,0:17.3
5,-1,0:17.3
8,1,0:17.3
5,5,0:17.3
3,4,0:17.3
4,3,-1:17.3
4,4,-1:17.3
3,4,-1:17.3
5,4,-1:17.3
5,5,-1:17.3
6,4,-1:17.3
6,3,-1:17.3
6,2,-1:17.3
7,2,-1:17.3
8,1,-1:17.3
7,1,-1:17.3
6,1,-1:17.3
5,1,-1:17.3
5,0,-1:17.3
4,0,-1:17.3
4,1,-1:17.3
3,1,-1:17.3
2,1,-1:17.3
2,2,-1:17.3
3,2,-1:17.3
4,2,-1:17.3
5,3,-1:17.3
5,2,-1:17.3
1,1,-1:17.3
5,-1,-1:17.3
3,0,-1:17.3
0,1,-1:17.3
0,0,-1:17.3
2,4,-1:17.3
2,5,-1:17.3
1,5,-1:17.3
5,6,-1:17.3
6,6,-1:17.3
6,7,-1:17.3
9,1,-1:17.3
9,0,-1:17.3
5,-2,-1:17.3
6,-2,-1:17.3
4,-2,-1:17.3
4,-3,-1:17.3
8,3,-1:17.3
-1,0,-1:17.3
3,1,1:17.3
4,1,1:17.3
5,1,1:17.3
5,2,1:17.3
6,2,1:17.3
5,3,1:17.3
4,3,1:17.3
4,2,1:17.3
3,2,1:17.3
5,0,1:17.3
4,0,1:17.3
3,0,1:17.3
2,1,1:17.3
3,1,2:17.3
3,2,2:17.3
4,2,2:17.3
5,2,2:17.3
5,1,2:17.3
4,1,2:17.3
4,0,2:17.3
3,0,2:17.3
2,0,2:17.3
2,1,2:17.3
2,0,3:17.3
3,0,3:17.3
4,0,3:17.3
4,1,3:17.3
3,1,3:17.3
2,1,3:17.3
4,2,3:17.3
1,0,3:17.3
1,-1,3:17.3
2,-1,3:17.3
3,2,3:18.3
5,2,3:18.3
5,1,3:18.3
0,-1,3:18.3
3,-1,3:18.3
1,0,4:17.3
2,-1,4:17.3
3,-1,4:17.3
3,0,4:17.3
2,1,4:17.3
2,0,4:17.3
4,-2,4:17.3
4,-1,4:17.3
3,-2,4:17.3
1,-1,4:17.3
4,0,4:17.3
5,-1,4:17.3
0,-1,4:17.3
3,1,4:18.3
4,1,4:18.3
4,2,4:18.3
3,-3,4:18.3
1,-2,4:18.3
-1,-1,4:18.3
0,0,5:17.3
0,-1,5:17.3
1,-2,5:17.3
2,-2,5:17.3
2,-1,5:17.3
1,0,5:17.3
1,-1,5:17.3
3,-3,5:17.3
3,-2,5:17.3
4,-2,5:17.3
4,-3,5:17.3
4,-1,5:17.3
5,-1,5:17.3
5,0,5:17.3
4,0,5:17.3
5,1,5:17.3
5,2,5:17.3
6,2,5:17.3
6,1,5:17.3
3,-1,5:18.3
3,0,5:18.3
2,0,5:18.3
2,1,5:18.3
-1,-1,5:18.3
6,-1,5:18.3
3,-4,5:18.3
7,2,5:18.3
0,-2,6:17.3
0,-1,6:17.3
1,-1,6:17.3
2,-1,6:17.3
2,0,6:17.3
1,-2,6:17.3
1,0,6:17.3
4,-4,6:17.3
4,-3,6:17.3
5,-3,6:17.3
5,-4,6:17.3
4,0,6:17.3
5,0,6:17.3
5,1,6:17.3
4,1,6:17.3
-1,-2,6:18.3
2,-2,6:18.3
3,-3,6:18.3
3,-2,6:18.3
4,-2,6:18.3
4,-1,6:18.3
5,-1,6:18.3
5,2,6:18.3
6,2,6:18.3
6,1,6:18.3
4,-5,6:18.3
1,1,6:18.3
0,0,6:18.3
6,-4,6:18.3
0,-3,6:18.3
1,-1,7:17.3
0,-1,7:17.3
-1,-2,7:17.3
-1,-3,7:17.3
0,-3,7:17.3
1,-2,7:17.3
0,-2,7:17.3
5,-5,7:17.3
5,-4,7:17.3
6,-4,7:17.3
6,-5,7:17.3
4,1,7:17.3
4,2,7:17.3
5,2,7:17.3
5,1,7:17.3
4,-4,7:18.3
5,-3,7:18.3
4,0,7:18.3
1,0,7:18.3
2,-1,7:18.3
-2,-3,7:18.3
-2,-4,7:18.3
-1,-4,7:18.3
2,0,7:18.3
4,-3,7:18.3
5,0,7:18.3
7,-5,7:18.3
7,-6,7:18.3
6,-6,7:18.3
8,-6,7:18.3
4,3,7:18.3
4,4,7:18.3
5,3,7:18.3
3,3,7:18.3
1,-3,7:18.3
0,0,7:18.3
-2,-2,8:17.3
-2,-3,8:17.3
-2,-4,8:17.3
-1,-4,8:17.3
-1,-3,8:17.3
0,-3,8:17.3
0,-2,8:17.3
-1,-2,8:17.3
0,-4,8:17.3
6,-5,8:17.3
6,-4,8:17.3
6,-3,8:17.3
7,-3,8:17.3
7,-4,8:17.3
5,-4,8:17.3
3,2,8:17.3
4,2,8:17.3
4,3,8:17.3
3,3,8:17.3
4,1,8:17.3
5,2,8:18.3
1,-2,8:18.3
0,-1,8:18.3
5,-5,8:18.3
-3,-3,8:18.3
-3,-4,8:18.3
-4,-4,8:18.3
-2,-5,8:18.3
-2,-6,8:18.3
-1,-6,8:18.3
1,-1,8:18.3
5,1,8:18.3
8,-4,8:18.3
8,-3,8:18.3
9,-3,8:18.3
7,-2,8:18.3
2,2,8:18.3
1,2,8:18.3
3,4,8:18.3
2,4,8:18.3
1,-4,8:18.3
-2,-1,8:18.3
-2,-3,9:17.3
-3,-3,9:17.3
-3,-4,9:17.3
-3,-5,9:17.3
-2,-5,9:17.3
-2,-4,9:17.3
-1,-3,9:17.3
7,-4,9:17.3
7,-3,9:17.3
8,-3,9:17.3
8,-4,9:17.3
6,-4,9:17.3
0,-3,9:17.3
3,2,9:17.3
2,2,9:17.3
2,3,9:17.3
3,3,9:17.3
4,3,9:17.3
-2,-2,9:18.3
-1,-2,9:18.3
-1,-4,9:18.3
6,-3,9:18.3
4,1,9:18.3
4,2,9:18.3
-4,-4,9:18.3
-4,-5,9:18.3
0,-4,9:18.3
0,-2,9:18.3
5,-4,9:18.3
6,-5,9:18.3
9,-3,9:18.3
8,-2,9:18.3
9,-2,9:18.3
1,3,9:18.3
1,2,9:18.3
1,4,9:18.3
0,4,9:18.3
3,4,9:18.3
-2,-6,9:18.3
8,-5,9:18.3
-4,-4,10:17.3
-4,-5,10:17.3
-4,-6,10:17.3
-3,-6,10:17.3
-3,-5,10:17.3
-3,-4,10:17.3
-2,-4,10:17.3
8,-3,10:17.3
8,-2,10:17.3
9,-2,10:17.3
9,-3,10:17.3
8,-4,10:17.3
-2,-3,10:17.3
1,3,10:17.3
2,3,10:17.3
2,4,10:17.3
1,4,10:17.3
2,2,10:17.3
-2,-5,10:18.3
7,-4,10:18.3
7,-3,10:18.3
3,2,10:18.3
3,3,10:18.3
4,3,10:18.3
-3,-3,10:18.3
0,-3,10:18.3
-1,-3,10:18.3
6,-4,10:18.3
0,4,10:18.3
-5,-5,10:18.3
-6,-5,10:18.3
-5,-6,10:18.3
-3,-7,10:18.3
10,-3,10:18.3
9,-1,10:18.3
9,0,10:18.3
8,-1,10:18.3
2,5,10:18.3
1,2,10:18.3
-5,-5,11:17.3
-5,-6,11:17.3
-4,-6,11:17.3
-4,-5,11:17.3
-3,-5,11:17.3
9,-2,11:17.3
9,-1,11:17.3
10,-1,11:17.3
10,-2,11:17.3
-3,-4,11:17.3
9,-3,11:17.3
0,3,11:17.3
1,3,11:17.3
1,4,11:17.3
0,4,11:17.3
2,4,11:17.3
-3,-6,11:18.3
-4,-4,11:18.3
8,-4,11:18.3
8,-2,11:18.3
2,2,11:18.3
2,3,11:18.3
-6,-6,11:18.3
-4,-7,11:18.3
-1,3,11:18.3
1,5,11:18.3
11,-2,11:18.3
10,0,11:18.3
8,-3,11:18.3
-2,-4,11:18.3
-2,-3,11:18.3
10,-3,11:17.3
11,-3,11:17.3
10,-4,11:17.3
11,-4,11:17.3
12,-5,11:18.3
12,-4,11:18.3
-6,-6,12:17.3
-6,-7,12:17.3
-5,-7,12:17.3
-5,-6,12:17.3
-4,-6,12:17.3
10,-1,12:17.3
10,0,12:17.3
11,0,12:17.3
11,-1,12:17.3
-5,-5,12:17.3
-4,-5,12:17.3
9,-1,12:17.3
10,-2,12:17.3
-1,4,12:17.3
0,4,12:17.3
0,5,12:17.3
-1,5,12:17.3
1,4,12:17.3
-3,-5,12:18.3
-3,-4,12:18.3
9,-3,12:18.3
9,-2,12:18.3
0,3,12:18.3
1,3,12:18.3
3,3,12:18.3
2,4,12:18.3
-7,-6,12:18.3
-7,-7,12:18.3
-5,-8,12:18.3
-2,5,12:18.3
-1,6,12:18.3
10,1,12:18.3
12,-1,12:18.3
12,0,12:18.3
11,-4,12:17.3
11,-5,12:17.3
12,-5,12:17.3
10,-4,12:18.3
10,-3,12:18.3
12,-3,12:18.3
11,-3,12:18.3
12,-6,12:18.3
13,-5,12:18.3
-6,-6,13:17.3
-7,-6,13:17.3
-7,-5,13:17.3
-6,-5,13:17.3
9,0,13:17.3
9,1,13:17.3
10,1,13:17.3
10,0,13:17.3
11,-1,13:17.3
11,0,13:17.3
-5,-6,13:17.3
-2,4,13:17.3
-1,4,13:17.3
-1,5,13:17.3
-2,5,13:17.3
-6,-7,13:18.3
-5,-7,13:18.3
-5,-5,13:18.3
-4,-6,13:18.3
10,-2,13:18.3
10,-1,13:18.3
0,4,13:18.3
0,5,13:18.3
1,4,13:18.3
-4,-5,13:18.3
9,-1,13:18.3
-3,-4,13:18.3
3,3,13:18.3
1,3,13:18.3
9,-3,13:18.3
-3,5,13:18.3
-2,6,13:18.3
-8,-5,13:18.3
-7,-4,13:18.3
11,1,13:18.3
10,2,13:18.3
12,-1,13:18.3
12,-5,13:17.3
13,-5,13:17.3
13,-6,13:17.3
13,-7,13:17.3
14,-6,13:17.3
12,-7,13:18.3
13,-8,13:18.3
15,-6,13:18.3
14,-5,13:18.3
11,-5,13:18.3
11,-4,13:18.3
-2,3,13:18.3
8,1,13:18.3
-8,-5,14:17.3
-7,-5,14:17.3
-7,-4,14:17.3
-8,-4,14:17.3
9,1,14:17.3
9,2,14:17.3
10,2,14:17.3
10,1,14:17.3
-3,5,14:17.3
-2,5,14:17.3
-2,6,14:17.3
-3,6,14:17.3
-2,4,14:17.3
-7,-6,14:18.3
-6,-6,14:18.3
-5,-6,14:18.3
-6,-5,14:18.3
11,-1,14:18.3
11,0,14:18.3
10,0,14:18.3
9,0,14:18.3
-1,4,14:18.3
-1,5,14:18.3
-4,-5,14:18.3
10,-2,14:18.3
1,4,14:18.3
13,-7,14:17.3
12,-8,14:17.3
13,-8,14:17.3
12,-9,14:17.3
14,-6,14:17.3
15,-6,14:17.3
15,-5,14:17.3
16,-5,14:17.3
12,-5,14:17.3
11,-5,14:17.3
11,-6,14:17.3
10,-6,14:17.3
15,-4,14:17.3
11,-9,14:18.3
12,-10,14:18.3
13,-9,14:18.3
13,-6,14:18.3
13,-5,14:18.3
10,-5,14:18.3
9,-6,14:18.3
10,-7,14:18.3
14,-4,14:18.3
15,-3,14:18.3
16,-4,14:18.3
17,-5,14:18.3
16,-6,14:18.3
15,-7,14:18.3
12,-4,14:18.3
-9,-4,14:18.3
-8,-3,14:18.3
-4,5,14:18.3
-3,7,14:18.3
-2,3,14:18.3
8,2,14:18.3
10,3,14:18.3
-9,-4,15:17.3
-8,-4,15:17.3
-8,-3,15:17.3
-7,-3,15:17.3
7,2,15:17.3
8,2,15:17.3
8,3,15:17.3
9,3,15:17.3
9,2,15:17.3
9,1,15:17.3
10,1,15:17.3
10,2,15:17.3
-9,-3,15:17.3
-4,5,15:17.3
-3,5,15:17.3
-3,6,15:17.3
-4,6,15:17.3
-8,-5,15:18.3
-7,-5,15:18.3
-7,-4,15:18.3
-2,4,15:18.3
-2,5,15:18.3
-2,6,15:18.3
10,0,15:18.3
-6,-6,15:18.3
-5,-6,15:18.3
11,-1,15:18.3
11,0,15:18.3
-1,5,15:18.3
12,-9,15:18.3
12,-8,15:18.3
10,-6,15:18.3
11,-6,15:18.3
15,-6,15:18.3
15,-5,15:18.3
16,-5,15:18.3
15,-4,15:18.3
13,-8,15:18.3
13,-7,15:18.3
14,-6,15:18.3
11,-5,15:18.3
12,-5,15:18.3
9,4,15:18.3
10,3,15:18.3
6,2,15:18.3
7,1,15:18.3
-5,6,15:18.3
-4,7,15:18.3
-8,-2,15:18.3
-10,-3,15:18.3
-9,-3,16:17.3
-10,-3,16:17.3
-10,-2,16:17.3
-9,-2,16:17.3
-8,-3,16:17.3
6,1,16:17.3
6,2,16:17.3
7,2,16:17.3
7,1,16:17.3
-4,6,16:17.3
-3,6,16:17.3
-3,7,16:17.3
-4,7,16:17.3
-11,-2,16:18.3
-11,-1,16:18.3
-10,-1,16:18.3
-5,7,16:18.3
-5,8,16:18.3
-4,8,16:18.3
-6,8,16:18.3
-5,9,16:18.3
-12,-1,16:18.3
8,2,16:18.3
8,3,16:18.3
9,1,16:18.3
10,2,16:18.3
9,3,16:18.3
-9,-4,16:18.3
-8,-4,16:18.3
-7,-3,16:18.3
-4,5,16:18.3
-3,5,16:18.3
10,1,16:18.3
9,2,16:18.3
-2,6,16:18.3
-7,-5,16:18.3
12,-9,16:18.3
11,-6,16:18.3
15,-5,16:18.3
5,1,16:18.3
5,0,16:18.3
6,0,16:18.3
-10,-3,17:17.3
-11,-4,17:17.3
-11,-3,17:17.3
-8,-3,17:17.3
-7,-2,17:17.3
-7,-3,17:17.3
-9,-2,17:17.3
-9,-1,17:17.3
-10,-2,17:17.3
-9,0,17:17.3
-10,0,17:17.3
-12,-4,17:18.3
-11,-5,17:18.3
-10,-4,17:18.3
-9,-3,17:18.3
-7,-1,17:18.3
-6,-2,17:18.3
-7,-4,17:18.3
-11,-2,17:18.3
-11,0,17:18.3
-10,1,17:18.3
-8,0,17:18.3
5,0,17:17.3
5,1,17:17.3
6,1,17:17.3
6,0,17:17.3
-4,7,17:17.3
-5,7,17:17.3
-3,6,17:17.3
-2,6,17:17.3
-1,6,17:17.3
-1,5,17:17.3
-1,4,17:17.3
0,4,17:17.3
0,6,17:17.3
0,7,17:17.3
0,8,17:17.3
1,8,17:17.3
-5,8,17:17.3
-5,9,17:17.3
-6,9,17:17.3
-6,7,17:17.3
-6,6,17:17.3
-7,6,17:17.3
-7,5,17:18.3
-8,6,17:18.3
-7,7,17:18.3
-7,9,17:18.3
-6,8,17:18.3
-6,10,17:18.3
-4,10,17:18.3
-4,9,17:18.3
-4,6,17:18.3
-1,7,17:18.3
0,9,17:18.3
2,8,17:18.3
1,7,17:18.3
0,5,17:18.3
1,4,17:18.3
0,3,17:18.3
-2,3,17:18.3
-2,4,17:18.3
-3,5,17:18.3
-3,7,17:18.3
-12,-1,17:18.3
9,1,17:18.3
8,3,17:18.3
6,2,17:18.3
7,2,17:18.3
7,1,17:18.3
-11,-1,18:17.3
-10,1,18:17.3
-10,0,18:17.3
-11,1,18:17.3
-9,-1,18:17.3
-8,-1,18:17.3
-8,0,18:17.3
-7,0,18:17.3
-6,1,18:17.3
-6,0,18:17.3
-5,0,18:17.3
-10,2,18:17.3
-7,-3,18:17.3
-7,-4,18:17.3
-6,-4,18:17.3
-7,-5,18:17.3
-5,-4,18:17.3
-5,-3,18:17.3
-11,-4,18:17.3
-12,-4,18:17.3
-12,-5,18:17.3
-13,-4,18:17.3
-13,-3,18:17.3
-4,-4,18:17.3
-12,-3,18:18.3
-14,-3,18:18.3
-13,-5,18:18.3
-12,-6,18:18.3
-7,-6,18:18.3
-8,-5,18:18.3
-5,-5,18:18.3
-3,-4,18:18.3
-4,-3,18:18.3
-5,-2,18:18.3
-4,0,18:18.3
-5,1,18:18.3
-6,2,18:18.3
-7,1,18:18.3
-9,1,18:18.3
-9,2,18:18.3
-10,3,18:18.3
-11,2,18:18.3
-12,1,18:18.3
-12,-1,18:18.3
-13,-2,18:18.3
-14,-4,18:18.3
-9,-2,18:18.3
-8,-3,18:18.3
5,0,18:17.3
5,-1,18:17.3
5,-2,18:17.3
4,-2,18:17.3
5,-3,18:17.3
6,-3,18:17.3
6,1,18:17.3
6,2,18:17.3
6,3,18:17.3
5,3,18:17.3
4,3,18:17.3
5,4,18:17.3
7,2,18:17.3
8,2,18:17.3
3,-2,18:17.3
3,-3,18:17.3
3,-1,18:17.3
2,-1,18:17.3
2,0,18:18.3
1,-1,18:18.3
2,-2,18:18.3
4,0,18:18.3
4,-3,18:18.3
3,-4,18:18.3
6,-4,18:18.3
7,-3,18:18.3
6,-2,18:18.3
6,0,18:18.3
8,1,18:18.3
9,2,18:18.3
8,3,18:18.3
6,4,18:18.3
5,5,18:18.3
4,4,18:18.3
3,3,18:18.3
4,2,18:18.3
-7,6,18:18.3
-6,6,18:18.3
-5,8,18:18.3
-6,9,18:18.3
-5,9,18:18.3
-4,7,18:18.3
-3,6,18:18.3
-2,6,18:18.3
-1,4,18:18.3
-1,5,18:18.3
0,4,18:18.3
0,7,18:18.3
0,8,18:18.3
1,8,18:18.3
-7,-7,18:18.3
-5,-6,18:18.3
-4,-6,18:18.3
-2,-4,18:18.3
-3,-3,18:18.3
-12,-7,18:18.3
-15,-4,18:18.3
-10,4,18:18.3
-6,3,18:18.3
-13,1,18:18.3
-4,-7,18:18.3
-7,-8,18:18.3
-8,-7,18:18.3
-6,5,18:18.3
-6,10,18:18.3
-6,11,18:18.3
-4,6,18:18.3
-4,5,18:18.3
-4,4,18:18.3
-2,3,18:18.3
-2,2,18:18.3
0,3,18:18.3
1,3,18:18.3
0,9,18:18.3
-1,9,18:18.3
1,7,18:18.3
1,6,18:18.3
2,6,18:18.3
-4,9,18:18.3
3,-5,18:18.3
2,-5,18:18.3
6,-5,18:18.3
7,-5,18:18.3
6,-6,18:18.3
8,-3,18:18.3
8,-2,18:18.3
0,-1,18:18.3
0,-2,18:18.3
5,6,18:18.3
6,6,18:18.3
6,7,18:18.3
8,4,18:18.3
10,2,18:18.3
10,1,18:18.3
8,0,18:18.3
9,-3,18:18.3
9,-4,18:18.3
5,1,18:18.3
-11,-3,18:18.3
-10,-3,18:18.3
-10,-2,18:18.3
-7,-2,18:18.3
-1,6,18:18.3
0,6,18:18.3
-5,7,18:18.3
-6,7,18:18.3
-9,0,18:18.3
-12,-5,19:18.3
-12,-6,19:18.3
-11,-4,19:18.3
-10,-4,19:18.3
-13,-3,19:18.3
-13,-2,19:18.3
-11,-2,19:18.3
-11,-1,19:18.3
-11,1,19:18.3
-12,1,19:18.3
-10,2,19:18.3
-10,3,19:18.3
-9,-1,19:18.3
-9,-2,19:18.3
-8,-1,19:18.3
-7,-1,19:18.3
-6,1,19:18.3
-6,2,19:18.3
-5,0,19:18.3
-4,0,19:18.3
-5,-1,19:18.3
-8,0,19:18.3
-8,1,19:18.3
-8,-5,19:18.3
-7,-5,19:18.3
-7,-6,19:18.3
-6,-5,19:18.3
-7,-4,19:18.3
-8,-3,19:18.3
-7,-3,19:18.3
-6,-4,19:18.3
-5,-4,19:18.3
-4,-4,19:18.3
-4,-5,19:18.3
-3,-4,19:18.3
-5,-3,19:18.3
-4,-3,19:18.3
-5,-2,19:18.3
-6,0,19:18.3
-10,1,19:18.3
-12,-4,19:18.3
-13,-4,19:18.3
-14,-4,19:18.3
2,-1,19:18.3
3,-1,19:18.3
3,-2,19:18.3
3,-3,19:18.3
5,-3,19:18.3
6,-3,19:18.3
5,-2,19:18.3
5,0,19:18.3
7,2,19:18.3
8,2,19:18.3
4,3,19:18.3
5,3,19:18.3
5,4,19:18.3
-2,6,19:18.3
-1,4,19:18.3
0,8,19:18.3
-5,8,19:18.3
-6,6,19:18.3
6,-5,19:18.3
8,-3,19:18.3
10,2,19:18.3
6,6,19:18.3
-2,2,19:18.3
-4,5,19:18.3
-6,10,19:18.3
1,6,19:18.3
1,3,19:18.3
3,-5,19:18.3
0,-1,19:18.3
8,0,19:18.3
8,4,19:18.3
-10,0,19:18.3
-7,0,19:18.3
4,-2,19:18.3
5,-1,19:18.3
6,1,19:18.3
6,2,19:18.3
6,3,19:18.3
5,-3,20:18.3
3,-2,20:18.3
7,2,20:18.3
5,3,20:18.3
-13,-4,20:18.3
-12,-4,20:18.3
-11,-2,20:18.3
-8,-1,20:18.3
-10,1,20:18.3
-5,0,20:18.3
-4,-4,20:18.3
-7,-5,20:18.3
-1,4,20:18.3
-5,8,20:18.3
1,6,20:18.3
8,-3,20:18.3
0,-1,20:18.3
