[META]
version=2.0
spawnOnBlockType=2,3
spawnSunlight=True
spawnDarkness=True
spawnWater=False
spawnLava=False
underFill=False
randomRotation=True
dig=True
tree=True
branch=False
needsFoundation=True
rarity=30
collisionPercentage=2
spawnElevationMin=0
spawnElevationMax=220
spawnInBiome=WoWForest
[DATA]
0,-2,0:17
1,-2,0:17
-3,-1,0:17
-2,-1,0:17
-1,-1,0:17.0
0,-1,0:17.0
1,-1,0:17.0
2,-1,0:17
-4,0,0:17
-3,0,0:17.0
-1,0,0:17.0
0,0,0:17.0
1,0,0:17.0
2,0,0:17
-3,1,0:17.0
-2,1,0:17
-1,1,0:17.0
0,1,0:17.0
1,1,0:17.0
-3,2,0:17
-1,2,0:17
1,2,0:17
1,-2,-1:17.0
-1,-1,-1:17.0
2,-1,-1:17.0
-3,0,-1:17.0
-3,1,-1:17.0
-1,1,-1:17.0
1,1,-1:17.0
-1,-1,1:17.0
0,-1,1:17.0
1,-1,1:17.0
-3,0,1:17.0
-2,0,1:17.0
-1,0,1:17.0
1,0,1:17.0
-4,1,1:18
-3,1,1:17.0
-2,1,1:17.0
-1,1,1:17.0
0,1,1:17.0
1,1,1:17.0
-2,2,1:18
-1,-1,2:17.0
0,-1,2:17.0
1,-1,2:17.0
-3,0,2:17.0
-2,0,2:17.0
-1,0,2:17.0
1,0,2:17.0
-4,1,2:18
-3,1,2:17.0
-1,1,2:17.0
0,1,2:17.0
1,1,2:17.0
-3,2,2:18
0,-1,3:17.0
1,-1,3:17.0
-3,0,3:17.0
-2,0,3:17.0
-1,0,3:17.0
1,0,3:17.0
-4,1,3:18
-3,1,3:18
-2,1,3:18
-1,1,3:17.0
0,1,3:17.0
1,1,3:17.0
-4,2,3:18
-3,2,3:18
-2,2,3:18
-3,-1,4:18
-2,-1,4:18
-1,-1,4:18
0,-1,4:17.0
1,-1,4:17.0
-3,0,4:17.0
-2,0,4:17.0
-1,0,4:17.0
1,0,4:17.0
-5,1,4:18
-4,1,4:18
-3,1,4:18
-2,1,4:18
-1,1,4:18
0,1,4:17.0
1,1,4:17.0
-4,2,4:18
-3,2,4:18
-3,3,4:18
-4,-1,5:18
-3,-1,5:18
-2,-1,5:18
0,-1,5:17.0
1,-1,5:17.0
-4,0,5:18
-3,0,5:18
-2,0,5:18
-1,0,5:17.0
0,0,5:17.0
1,0,5:17.0
-4,1,5:18
-3,1,5:18
-2,1,5:18
-1,1,5:18
0,1,5:17.0
1,1,5:17.0
-3,2,5:18
-2,2,5:18
-3,-1,6:18
-2,-1,6:18
0,-1,6:17.0
1,-1,6:17.0
-3,0,6:18
-2,0,6:18
0,0,6:17.0
1,0,6:17.0
-3,1,6:18
-2,1,6:18
0,1,6:17.0
1,1,6:17.0
-3,2,6:18
0,-1,7:17.0
1,-1,7:17.0
-3,0,7:18
-2,0,7:18
0,0,7:17.0
1,0,7:17.0
-3,1,7:18
-2,1,7:18
1,1,7:17.0
0,-1,8:17.0
1,-1,8:17.0
-3,0,8:18
-2,0,8:18
0,0,8:17.0
1,0,8:17.0
1,1,8:17.0
0,-1,9:17.0
1,-1,9:17.0
0,0,9:17.0
1,0,9:17.0
-3,-5,10:18
-5,-2,10:18
-1,-2,10:18
1,-2,10:18
-2,-1,10:18
-1,-1,10:18
0,-1,10:17.0
1,-1,10:18
-1,0,10:18
0,0,10:17.0
1,0,10:17.0
2,0,10:18
-2,1,10:18
0,1,10:18
2,1,10:18
3,1,10:18
6,1,10:18
7,1,10:18
-1,2,10:18
1,2,10:18
6,2,10:18
4,3,10:18
3,5,10:18
3,6,10:18
-2,-6,11:18
-3,-5,11:18
-2,-5,11:18
-3,-4,11:18
-2,-4,11:17
-1,-4,11:18
-4,-3,11:18
-3,-3,11:18
-2,-3,11:17.0
-1,-3,11:18
0,-3,11:18
-5,-2,11:18
-4,-2,11:18
-3,-2,11:18
-1,-2,11:18
1,-2,11:18
-6,-1,11:18
-3,-1,11:18
-2,-1,11:18
-1,-1,11:18
0,-1,11:18
1,-1,11:18
2,-1,11:18
3,-1,11:18
-3,0,11:18
-2,0,11:18
-1,0,11:18
0,0,11:17.0
1,0,11:17.0
2,0,11:18
4,0,11:18
5,0,11:18
-2,1,11:18
-1,1,11:18
0,1,11:18
1,1,11:18
2,1,11:18
4,1,11:18
5,1,11:17
6,1,11:18
7,1,11:18
-1,2,11:18
1,2,11:18
4,2,11:18
5,2,11:18
6,2,11:18
3,3,11:18
4,3,11:18
3,4,11:18
3,5,11:18
3,6,11:18
3,-5,12:18
-3,-4,12:18
-2,-4,12:18
3,-4,12:18
-3,-3,12:18
-2,-3,12:18
-1,-3,12:18
0,-3,12:18
1,-3,12:18
2,-3,12:18
3,-3,12:17
4,-3,12:17
5,-3,12:18
6,-3,12:18
7,-3,12:18
-5,-2,12:18
-4,-2,12:18
-3,-2,12:18
-2,-2,12:18
-1,-2,12:17
1,-2,12:18
2,-2,12:17.0
3,-2,12:18
-6,-1,12:18
-5,-1,12:18
-4,-1,12:17
-3,-1,12:18
-2,-1,12:18
-1,-1,12:18
0,-1,12:18
1,-1,12:18
2,-1,12:18
3,-1,12:18
-4,0,12:18
-3,0,12:18
-2,0,12:18
-1,0,12:18
0,0,12:17.0
1,0,12:17.0
2,0,12:18
3,0,12:18
4,0,12:18
-3,1,12:18
-2,1,12:18
-1,1,12:18
0,1,12:18
1,1,12:18
2,1,12:18
3,1,12:17
4,1,12:17
5,1,12:18
6,1,12:18
7,1,12:18
-3,2,12:18
0,2,12:18
1,2,12:18
2,2,12:17
3,2,12:18
4,2,12:18
5,2,12:18
-6,3,12:18
-5,3,12:18
-4,3,12:18
-3,3,12:17
-2,3,12:17.0
-1,3,12:18
0,3,12:18
1,3,12:18
2,3,12:18
3,3,12:17
-3,4,12:18
-2,4,12:18
3,4,12:18
-2,5,12:18
-2,6,12:18
2,-5,13:18
-2,-4,13:18
3,-4,13:18
-2,-3,13:18
0,-3,13:18
1,-3,13:18
2,-3,13:18
3,-3,13:18
4,-3,13:18
5,-3,13:18
6,-3,13:18
-4,-2,13:18
-3,-2,13:18
-2,-2,13:18
-1,-2,13:17
0,-2,13:18
1,-2,13:18
2,-2,13:18
3,-2,13:18
-5,-1,13:18
-4,-1,13:18
-3,-1,13:17
-2,-1,13:17
-1,-1,13:18
0,-1,13:18
1,-1,13:18
2,-1,13:17
3,-1,13:18
-3,0,13:18
-2,0,13:18
-1,0,13:18
0,0,13:17.0
1,0,13:17.0
2,0,13:18
-3,1,13:18
-2,1,13:17
-1,1,13:18
0,1,13:18
1,1,13:17.0
2,1,13:17
3,1,13:18
4,1,13:18
5,1,13:18
6,1,13:18
-3,2,13:18
-2,2,13:18
-1,2,13:17
0,2,13:17
1,2,13:18
2,2,13:18
3,2,13:18
4,2,13:18
5,2,13:18
-5,3,13:18
-4,3,13:18
-3,3,13:18
-2,3,13:18
-1,3,13:18
0,3,13:18
1,3,13:18
2,3,13:18
3,3,13:18
-3,4,13:18
-2,4,13:18
2,4,13:18
3,4,13:18
-2,5,13:18
-1,5,13:18
-2,6,13:18
-1,6,13:18
2,-5,14:18
-2,-4,14:18
2,-4,14:18
3,-4,14:18
-2,-3,14:18
1,-3,14:18
2,-3,14:17.0
3,-3,14:18
4,-3,14:18
-3,-2,14:18
-2,-2,14:18
-1,-2,14:18
0,-2,14:18
1,-2,14:18
2,-2,14:18
3,-2,14:18
4,-2,14:18
5,-2,14:18
-3,-1,14:18
-2,-1,14:18
-1,-1,14:17
0,-1,14:17.0
1,-1,14:18
2,-1,14:18
-2,0,14:18
-1,0,14:18
0,0,14:17.0
1,0,14:17.0
2,0,14:18
-2,1,14:18
-1,1,14:17
0,1,14:17
1,1,14:18
2,1,14:18
3,1,14:18
-2,2,14:18
-1,2,14:18
0,2,14:18
1,2,14:18
2,2,14:18
3,2,14:18
4,2,14:18
-4,3,14:18
-3,3,14:18
-2,3,14:18
-1,3,14:18
2,3,14:18
3,3,14:18
-2,4,14:18
-1,4,14:17
2,4,14:18
-2,5,14:18
-1,5,14:18
2,-4,15:18
-2,-3,15:18
-1,-3,15:18
2,-3,15:18
-2,-2,15:18
-1,-2,15:18
0,-2,15:18
1,-2,15:18
2,-2,15:17.0
3,-2,15:18
4,-2,15:18
-3,-1,15:18
-2,-1,15:18
-1,-1,15:18
0,-1,15:18
1,-1,15:17.0
2,-1,15:18
-1,0,15:18
0,0,15:17.0
1,0,15:17.0
2,0,15:18
-2,1,15:18
-1,1,15:18
0,1,15:18
1,1,15:18
2,1,15:17
3,1,15:18
4,1,15:18
-4,2,15:18
-3,2,15:18
-2,2,15:18
-1,2,15:17
0,2,15:18
2,2,15:18
-2,3,15:18
-1,3,15:18
2,3,15:18
-2,4,15:18
-1,4,15:18
-1,-3,16:18
1,-3,16:18
-1,-2,16:18
1,-2,16:18
2,-2,16:18
3,-2,16:18
4,-2,16:18
-4,-1,16:18
-3,-1,16:18
-2,-1,16:18
-1,-1,16:18
0,-1,16:18
1,-1,16:18
2,-1,16:18
3,-1,16:18
4,-1,16:18
-3,0,16:18
-2,0,16:17
-1,0,16:18
0,0,16:17.0
1,0,16:17.0
-3,1,16:18
-2,1,16:18
-1,1,16:17
0,1,16:18
1,1,16:17.0
2,1,16:18
3,1,16:18
4,1,16:18
-4,2,16:18
-3,2,16:18
-2,2,16:18
-1,2,16:18
1,2,16:18
2,2,16:18
-1,3,16:18
2,3,16:18
0,-3,17:18
1,-3,17:18
-1,-2,17:18
0,-2,17:17
1,-2,17:18
2,-2,17:18
4,-2,17:18
-4,-1,17:18
-3,-1,17:18
-2,-1,17:18
-1,-1,17:18
0,-1,17:18
1,-1,17:18
2,-1,17:18
3,-1,17:18
4,-1,17:18
-3,0,17:18
-2,0,17:17.0
-1,0,17:17
0,0,17:17.0
1,0,17:17.0
2,0,17:18
4,0,17:18
-3,1,17:18
-2,1,17:18
-1,1,17:18
0,1,17:18
1,1,17:18
2,1,17:18
4,1,17:18
-3,2,17:18
-1,2,17:18
0,2,17:18
1,2,17:18
2,2,17:18
-1,3,17:18
1,3,17:18
0,-3,18:18
-1,-2,18:18
0,-2,18:18
1,-2,18:18
-3,-1,18:18
-2,-1,18:18
-1,-1,18:18
0,-1,18:17
1,-1,18:18
2,-1,18:18
3,-1,18:18
-3,0,18:18
-2,0,18:18
-1,0,18:18
0,0,18:17.0
1,0,18:17.0
2,0,18:18
-3,1,18:18
-2,1,18:18
-1,1,18:18
0,1,18:17.0
1,1,18:17.0
2,1,18:18
3,1,18:18
-3,2,18:18
-1,2,18:18
0,2,18:18
1,2,18:18
0,3,18:18
1,3,18:18
0,-2,19:18
-3,-1,19:18
-1,-1,19:18
0,-1,19:18
1,-1,19:18
2,-1,19:18
3,-1,19:18
-2,0,19:18
-1,0,19:17
0,0,19:17.0
1,0,19:18
2,0,19:18
-2,1,19:18
-1,1,19:18
0,1,19:18
1,1,19:18
3,1,19:18
0,2,19:18
1,2,19:18
-2,-1,20:18
0,-1,20:18
1,-1,20:18
2,-1,20:18
-1,0,20:18
0,0,20:17.0
1,0,20:17.0
2,0,20:18
-2,1,20:18
-1,1,20:18
0,1,20:18
1,1,20:18
2,1,20:18
0,-2,21:18
1,-2,21:18
-2,-1,21:18
-1,-1,21:18
0,-1,21:18
1,-1,21:18
2,-1,21:18
-2,0,21:18
-1,0,21:18
0,0,21:17.0
1,0,21:18
2,0,21:18
-2,1,21:18
-1,1,21:18
0,1,21:18
1,1,21:18
2,1,21:18
0,2,21:18
0,-2,22:18
1,-2,22:18
0,-1,22:18
1,-1,22:18
2,-1,22:18
-1,0,22:18
0,0,22:17.0
1,0,22:18
2,0,22:18
-1,1,22:18
0,1,22:18
1,1,22:18
-1,2,22:18
0,2,22:18
1,2,22:18
0,-1,23:18
-1,0,23:18
0,0,23:17.0
1,0,23:18
0,1,23:18
1,1,23:18
0,0,24:17.0
1,0,24:18
0,0,25:17.0
