[META]
version=2.0
spawnOnBlockType=2,3
spawnSunlight=True
spawnDarkness=True
spawnWater=False
spawnLava=False
underFill=False
randomRotation=True
dig=True
tree=True
branch=False
needsFoundation=True
rarity=30
collisionPercentage=2
spawnElevationMin=0
spawnElevationMax=220
spawnInBiome=WoWForest
[DATA]
-1,-1,0:17.0
2,-1,0:17.0
-1,2,0:17.0
2,2,0:17.0
-1,-1,1:17.0
2,-1,1:17.0
0,0,1:17.0
1,0,1:17.0
0,1,1:17.0
1,1,1:17.0
-1,2,1:17.0
2,2,1:17.0
0,0,2:17.0
1,0,2:17.0
0,1,2:17.0
1,1,2:17.0
3,1,2:18
-1,-2,3:18
0,-2,3:18
1,-2,3:18
0,-1,3:18
1,-1,3:18
2,-1,3:18
3,-1,3:18
-2,0,3:18
-1,0,3:18
0,0,3:17.0
1,0,3:17.0
2,0,3:18
3,0,3:18
-2,1,3:18
-1,1,3:18
0,1,3:17.0
1,1,3:17.0
2,1,3:18
3,1,3:18
-2,2,3:18
0,2,3:18
1,2,3:18
2,2,3:18
0,3,3:18
-1,-2,4:18
0,-2,4:18
1,-2,4:18
0,-1,4:18
1,-1,4:18
2,-1,4:18
-2,0,4:18
-1,0,4:18
0,0,4:17.0
1,0,4:17.0
2,0,4:18
3,0,4:18
-1,1,4:18
0,1,4:18
1,1,4:17.0
3,1,4:18
0,2,4:18
1,2,4:18
2,2,4:18
-1,-2,5:18
1,-2,5:18
-1,-1,5:18
0,-1,5:18
1,-1,5:18
2,-1,5:18
-2,0,5:18
-1,0,5:18
0,0,5:17.0
1,0,5:17.0
2,0,5:18
-1,1,5:18
0,1,5:18
1,1,5:18
2,1,5:18
0,2,5:18
1,2,5:18
2,2,5:18
1,-2,6:18
-1,-1,6:18
0,-1,6:18
1,-1,6:18
2,-1,6:18
-1,0,6:18
0,0,6:17.0
1,0,6:18
2,0,6:18
-1,1,6:18
0,1,6:18
1,1,6:18
2,1,6:18
0,2,6:18
2,2,6:18
1,-2,7:18
-1,-1,7:18
0,-1,7:18
1,-1,7:18
2,-1,7:18
-1,0,7:18
0,0,7:17.0
1,0,7:17.0
2,0,7:18
-1,1,7:18
0,1,7:18
1,1,7:18
2,1,7:18
0,2,7:18
0,-1,8:18
1,-1,8:18
2,-1,8:18
-1,0,8:18
0,0,8:17.0
1,0,8:18
2,0,8:18
-1,1,8:18
0,1,8:18
1,1,8:18
-1,-1,9:18
0,-1,9:18
1,-1,9:18
-1,0,9:18
0,0,9:17.0
1,0,9:18
0,1,9:18
1,1,9:18
0,-1,10:18
1,-1,10:18
-1,0,10:18
0,0,10:17.0
1,0,10:18
0,1,10:18
1,1,10:18
0,-1,11:18
-1,0,11:18
0,0,11:17.0
1,0,11:18
0,1,11:18
1,1,11:18
-1,0,12:18
0,0,12:17.0
1,0,12:18
0,0,13:17.0
1,0,13:18
0,0,14:17.0
