[META]
version=2.0
spawnOnBlockType=3,2,12,1
spawnSunlight=True
spawnDarkness=True
spawnWater=False
spawnLava=False
underFill=False
randomRotation=True
dig=True
tree=True
branch=False
needsFoundation=True
rarity=750
collisionPercentage=20
spawnElevationMin=0
spawnElevationMax=140
spawnInBiome=Mystic
spawnAboveGround=False
spawnUnderGround=False
collisionBlockType=All
groupId=
diggingBranch=false
branchLimit=6
groupFrequencyMin=1
groupFrequencyMax=5
groupSeperationMin=0
groupSeperationMax=5
[DATA]
0,0,0:17.0
0,1,0:17.0
-1,-1,0:17.0
1,-1,0:17.0
1,-1,-1:17.0
0,0,-1:17.0
-1,-1,-1:17.0
-1,-2,-1:17.0
-2,-2,-1:17.0
2,-1,-1:17.0
0,1,-1:17.0
0,2,-1:17.0
-1,2,-1:17.0
-1,3,-1:17.0
1,2,-1:17.0
-1,-1,1:17.0
0,1,1:17.0
1,-1,1:17.0
-1,-1,2:17.0
0,1,2:17.0
1,-1,2:17.0
-1,-1,3:17.0
-2,-1,3:17.0
-2,-2,3:17.0
0,1,3:17.0
0,2,3:17.0
1,-1,3:17.0
2,-1,3:17.0
2,-1,4:17.0
0,2,4:17.0
-2,-2,4:17.0
-1,-2,4:35.6
-2,-3,4:35.6
-3,-2,4:35.6
-1,2,4:35.6
0,3,4:35.6
1,2,4:35.6
1,-1,4:35.6
2,-2,4:35.6
3,-1,4:35.6
2,0,4:35.6
-2,-1,4:35.6
0,1,4:35.6
-2,0,4:35.4
2,1,4:35.4
-2,-2,5:17.0
2,-1,5:17.0
0,2,5:17.0
-2,-2,6:17.0
-2,-3,6:17.0
-3,-3,6:17.0
-2,-1,6:17.0
-1,-1,6:17.0
0,2,6:17.0
-1,2,6:17.0
-1,3,6:17.0
2,-1,6:17.0
2,0,6:17.0
2,-2,6:17.0
3,-2,6:17.0
1,0,6:17.0
-2,-4,6:17.0
-2,-5,6:17.0
2,-3,6:17.0
2,-4,6:17.0
-1,-4,6:17.0
1,-3,6:17.0
-2,3,6:17.0
-3,3,6:17.0
-3,4,6:17.0
-1,4,6:17.0
0,4,6:17.0
1,4,6:17.0
2,4,6:17.0
1,5,6:17.0
-2,-6,6:35.6
-3,-5,6:35.6
-1,-5,6:35.6
0,-4,6:35.6
0,-3,6:35.6
-4,-3,6:35.6
-3,-2,6:35.6
-2,0,6:35.6
-3,2,6:35.6
-4,3,6:35.6
-3,5,6:35.6
-1,5,6:35.6
1,6,6:35.6
-1,1,6:35.6
1,2,6:35.6
2,3,6:35.6
3,4,6:35.6
2,5,6:35.6
0,3,6:35.6
-1,-2,6:35.6
1,-1,6:35.6
0,0,6:35.6
1,1,6:35.6
3,0,6:35.6
3,-3,6:35.6
3,-4,6:35.6
2,-5,6:35.6
4,-2,6:35.6
-3,-3,7:17.0
-1,-1,7:17.0
0,2,7:17.0
-1,3,7:17.0
-1,4,7:17.0
3,-2,7:17.0
2,0,7:17.0
-2,-5,7:35.6
-1,-4,7:35.6
-2,-1,7:35.6
-2,-2,7:35.6
1,0,7:35.6
2,-2,7:35.6
2,-4,7:35.6
1,-3,7:35.6
2,4,7:35.6
1,5,7:35.6
-3,3,7:35.6
-3,4,7:35.6
-1,2,7:35.6
0,4,7:35.6
-3,-4,7:35.4
3,-1,7:35.4
0,5,7:35.4
-1,4,8:17.0
0,2,8:17.0
-3,-3,8:17.0
-1,-1,8:17.0
2,0,8:17.0
3,-2,8:17.0
2,-2,8:17.0
3,-3,8:17.0
2,1,8:17.0
1,0,8:17.0
-1,2,8:17.0
-2,2,8:17.0
-1,5,8:17.0
-2,5,8:17.0
-3,-4,8:17.0
-4,-4,8:17.0
-3,-2,8:17.0
-3,-1,8:17.0
-1,-2,8:17.0
-1,-3,8:17.0
-3,2,8:17.0
-3,3,8:17.0
-5,-5,8:35.6
-5,-4,8:35.6
-4,-3,8:35.6
-4,-5,8:35.6
-4,-1,8:35.6
-3,0,8:35.6
-2,-1,8:35.6
-2,-3,8:35.6
0,-3,8:35.6
-1,-4,8:35.6
1,-2,8:35.6
1,-1,8:35.6
2,-1,8:35.6
3,-1,8:35.6
3,1,8:35.6
2,2,8:35.6
1,1,8:35.6
0,3,8:35.6
-2,3,8:35.6
-3,4,8:35.6
-4,3,8:35.6
-4,2,8:35.6
-3,1,8:35.6
-1,1,8:35.6
-3,5,8:35.6
-2,6,8:35.6
0,5,8:35.6
0,6,8:35.6
3,-4,8:35.6
2,-3,8:35.6
4,-3,8:35.6
-4,-4,9:17.0
-3,-1,9:17.0
-3,3,9:17.0
0,2,9:17.0
-2,5,9:17.0
-1,4,9:17.0
-1,-3,9:17.0
-1,-1,9:17.0
2,1,9:17.0
1,0,9:17.0
2,-2,9:17.0
3,-3,9:17.0
-3,-4,9:35.6
-4,-5,9:35.6
-5,-4,9:35.6
-4,-3,9:35.6
-3,-2,9:35.6
-2,-1,9:35.6
-3,0,9:35.6
-4,-1,9:35.6
-3,2,9:35.6
-4,3,9:35.6
-3,4,9:35.6
-2,3,9:35.6
-2,4,9:35.6
-3,5,9:35.6
-2,6,9:35.6
-1,5,9:35.6
-1,3,9:35.6
0,4,9:35.6
-1,2,9:35.6
0,3,9:35.6
1,2,9:35.6
0,1,9:35.6
-1,0,9:35.6
0,-1,9:35.6
-1,-2,9:35.6
0,-3,9:35.6
-1,-4,9:35.6
-2,-3,9:35.6
1,-2,9:35.6
2,-3,9:35.6
3,-4,9:35.6
4,-3,9:35.6
3,-2,9:35.6
2,-1,9:35.6
1,-1,9:35.6
2,0,9:35.6
0,0,9:35.6
1,1,9:35.6
2,2,9:35.6
3,1,9:35.6
-4,0,9:35.4
0,-4,9:35.4
2,3,9:35.4
-1,6,9:35.4
-4,-4,10:35.6
-3,-2,10:35.6
-3,-1,10:35.6
-1,-1,10:35.6
0,0,10:35.6
-1,-3,10:35.6
2,-2,10:35.6
1,0,10:35.6
3,-3,10:35.6
2,1,10:35.6
0,2,10:35.6
-3,3,10:35.6
-1,4,10:35.6
-2,5,10:35.6
-3,-2,11:35.6
-4,-4,11:35.6
2,-2,11:35.6
0,2,11:35.6
-2,5,11:35.6
-1,-1,11:35.6
-3,3,11:35.6
2,1,11:35.6
