[META]
version=2.0
spawnOnBlockType=13
spawnSunlight=True
spawnDarkness=True
spawnWater=False
spawnLava=False
underFill=True
randomRotation=True
dig=True
tree=False
branch=False
needsFoundation=True
rarity=2
collisionPercentage=0
spawnElevationMin=0
spawnElevationMax=72
spawnInBiome=DesertGravel
[DATA]
0,-12,0:45
0,-13,0:45
0,-14,0:45
-5,-14,0:45
-4,-14,0:45
-3,-14,0:45
-2,-14,0:45
-1,-14,0:45
-5,-20,0:45
-5,-19,0:45
-5,-18,0:45
-5,-17,0:45
-5,-16,0:45
-5,-15,0:45
-8,-20,0:45
-7,-20,0:45
-6,-20,0:45
-11,-20,0:45
-10,-20,0:45
-9,-20,0:45
-12,-20,0:45
-13,-20,0:45
-13,-19,0:45
-13,-18,0:45
-13,-17,0:45
-13,-16,0:45
-13,-15,0:45
-13,-14,0:45
-13,-13,0:45
-13,-12,0:45
-13,-11,0:45
-13,-10,0:45
-13,-9,0:45
-13,-8,0:45
-13,-7,0:45
-13,-6,0:45
-13,-5,0:45
-13,-4,0:45
-13,-3,0:45
-13,-2,0:45
-13,-1,0:45
-13,0,0:45
-12,0,0:45
-11,0,0:45
-10,0,0:45
-9,0,0:45
-8,0,0:45
-7,0,0:45
-6,0,0:45
-5,0,0:45
-5,-1,0:45
-5,-2,0:45
-5,-3,0:45
-5,-4,0:45
-5,-5,0:45
-5,-6,0:45
-5,-7,0:45
-4,-7,0:45
-3,-7,0:45
-2,-7,0:45
-1,-7,0:45
0,-7,0:45
0,-8,0:45
0,-9,0:45
4,7,0:45
5,6,0:45
6,5,0:45
8,4,0:45
9,4,0:45
10,4,0:45
7,4,0:45
11,5,0:45
12,6,0:45
13,7,0:45
13,8,0:45
13,9,0:45
13,10,0:45
12,11,0:45
11,12,0:45
10,13,0:45
9,13,0:45
8,13,0:45
7,13,0:45
6,12,0:45
5,11,0:45
4,10,0:45
-4,14,0:45
-4,13,0:45
-4,12,0:45
-4,11,0:45
-4,10,0:45
-13,10,0:45
-12,10,0:45
-11,10,0:45
-10,10,0:45
-9,10,0:45
-8,10,0:45
-7,10,0:45
-6,10,0:45
-5,10,0:45
-13,11,0:45
-13,12,0:45
-13,13,0:45
-13,14,0:45
-13,15,0:45
-13,16,0:45
-13,17,0:45
-13,18,0:45
-13,19,0:45
-13,20,0:45
-13,21,0:45
-12,21,0:45
-11,21,0:45
-10,21,0:45
-9,21,0:45
-8,21,0:45
-7,21,0:45
-6,21,0:45
-5,21,0:45
-4,21,0:45
-4,17,0:45
-4,18,0:45
-4,19,0:45
-4,20,0:45
-7,14,0:51
-6,14,0:51
-12,18,0:51
-11,18,0:51
-7,18,0:51
-6,18,0:51
-5,18,0:51
-12,12,0:51
-11,13,0:51
-6,13,0:51
-7,19,0:51
-12,19,0:51
-6,19,0:51
-5,19,0:51
6,6,0:51
7,6,0:51
7,5,0:51
7,7,0:51
8,7,0:51
8,6,0:51
8,5,0:51
8,12,0:17.0
9,12,0:17.0
10,12,0:17.0
9,9,0:17.0
10,9,0:17.0
11,9,0:17.0
12,9,0:17.0
10,6,0:17.0
11,6,0:17.0
-11,-17,0:13
-11,-16,0:13
-11,-15,0:13
-10,-15,0:13
-9,-15,0:13
-9,-14,0:13
-9,-7,0:13
-9,-6,0:13
-8,-6,0:13
-8,-5,0:13
-7,-5,0:13
-7,-4,0:13
-7,-12,0:13
-6,-12,0:13
-5,-12,0:13
-8,12,0:13
-8,13,0:13
-9,13,0:13
-9,14,0:13
-9,15,0:13
-9,16,0:13
7,8,0:13
7,9,0:13
8,9,0:13
8,10,0:13
9,10,0:13
9,11,0:13
-11,10,-1:45
-10,10,-1:45
-9,10,-1:45
-8,10,-1:45
-7,10,-1:45
-6,10,-1:45
-5,10,-1:45
-4,10,-1:45
-4,11,-1:45
-4,12,-1:45
-4,13,-1:45
-4,14,-1:45
-4,17,-1:45
-4,18,-1:45
-4,19,-1:45
-4,20,-1:45
-4,21,-1:45
-5,21,-1:45
-6,21,-1:45
-7,21,-1:45
-8,21,-1:45
-9,21,-1:45
-10,21,-1:45
-11,21,-1:45
-12,21,-1:45
-12,10,-1:45
-11,-20,-1:45
-10,-20,-1:45
-9,-20,-1:45
-8,-20,-1:45
-7,-20,-1:45
-6,-20,-1:45
-5,-20,-1:45
-5,-19,-1:45
-5,-18,-1:45
-5,-17,-1:45
-5,-16,-1:45
-5,-15,-1:45
-5,-14,-1:45
-4,-14,-1:45
-3,-14,-1:45
-2,-14,-1:45
-1,-14,-1:45
0,-14,-1:45
0,-13,-1:45
0,-12,-1:45
0,-11,-1:45
0,-10,-1:45
0,-9,-1:45
0,-8,-1:45
0,-7,-1:45
-1,-7,-1:45
-2,-7,-1:45
-3,-7,-1:45
-4,-7,-1:45
-5,-7,-1:45
-5,-6,-1:45
-5,-5,-1:45
-5,-4,-1:45
-5,-3,-1:45
-5,-2,-1:45
-5,-1,-1:45
-5,0,-1:45
-6,0,-1:45
-7,0,-1:45
-9,0,-1:45
-10,0,-1:45
-11,0,-1:45
-12,0,-1:45
-13,0,-1:45
-13,-1,-1:45
-13,-2,-1:45
-13,-3,-1:45
-13,-4,-1:45
-13,-5,-1:45
-13,-6,-1:45
-13,-7,-1:45
-13,-8,-1:45
-13,-9,-1:45
-13,-10,-1:45
-13,-11,-1:45
-13,-12,-1:45
-13,-13,-1:45
-13,-14,-1:45
-13,-15,-1:45
-13,-16,-1:45
-13,-17,-1:45
-13,-18,-1:45
-13,-19,-1:45
-13,-20,-1:45
-12,-20,-1:45
-8,0,-1:45
-13,10,-1:45
-13,11,-1:45
-13,12,-1:45
-13,13,-1:45
-13,14,-1:45
-13,15,-1:45
-13,16,-1:45
-13,17,-1:45
-13,18,-1:45
-13,19,-1:45
-13,20,-1:45
-13,21,-1:45
7,4,-1:45
8,4,-1:45
9,4,-1:45
10,4,-1:45
11,5,-1:45
12,6,-1:45
13,7,-1:45
13,8,-1:45
13,9,-1:45
13,10,-1:45
12,11,-1:45
11,12,-1:45
10,13,-1:45
9,13,-1:45
8,13,-1:45
7,13,-1:45
6,12,-1:45
5,11,-1:45
4,10,-1:45
4,9,-1:45
4,8,-1:45
4,7,-1:45
6,5,-1:45
5,6,-1:45
-4,15,-1:45
-4,16,-1:45
-8,18,-1:17.0
-7,18,-1:17.0
-6,18,-1:17.0
-5,18,-1:17.0
-12,18,-1:17.0
-11,18,-1:17.0
-12,12,-1:17.0
-11,12,-1:17.0
-10,12,-1:17.0
-7,14,-1:17.0
-6,14,-1:17.0
-5,14,-1:17.0
-11,-20,1:45
-12,-20,1:45
-13,-20,1:45
-8,-20,1:45
-7,-20,1:45
-6,-20,1:45
-5,-20,1:45
-5,-19,1:45
-5,-18,1:45
-5,-15,1:45
-5,-14,1:45
-4,-14,1:45
-3,-14,1:45
-2,-14,1:45
-1,-14,1:45
0,-14,1:45
0,-13,1:45
0,-12,1:45
0,-9,1:45
0,-8,1:45
0,-7,1:45
-1,-7,1:45
-2,-7,1:45
-3,-7,1:45
-4,-7,1:45
-5,-7,1:45
-5,-6,1:45
-5,-5,1:45
-5,-2,1:45
-5,-1,1:45
-5,0,1:45
-8,0,1:45
-7,0,1:45
-6,0,1:45
-11,0,1:45
-12,0,1:45
-13,0,1:45
-13,-4,1:45
-13,-3,1:45
-13,-2,1:45
-13,-1,1:45
-13,-7,1:45
-13,-8,1:45
-13,-9,1:45
-13,-10,1:45
-13,-11,1:45
-13,-12,1:45
-13,-13,1:45
-13,-19,1:45
-13,-18,1:45
-13,-17,1:45
-13,-16,1:45
-13,10,1:45
-12,10,1:45
-11,10,1:45
-10,10,1:45
-9,10,1:45
-8,10,1:45
-7,10,1:45
-6,10,1:45
-5,10,1:45
-4,10,1:45
-4,11,1:45
-4,14,1:45
-4,17,1:45
-4,20,1:45
-13,21,1:45
-12,21,1:45
-11,21,1:45
-10,21,1:45
-9,21,1:45
-8,21,1:45
-7,21,1:45
-6,21,1:45
-5,21,1:45
-4,21,1:45
-13,14,1:45
-13,13,1:45
-13,12,1:45
-13,11,1:45
-13,17,1:45
-13,18,1:45
-13,19,1:45
-13,20,1:45
4,7,1:45
5,6,1:45
6,5,1:45
7,4,1:45
10,4,1:45
11,5,1:45
12,6,1:45
13,7,1:45
13,10,1:45
12,11,1:45
11,12,1:45
10,13,1:45
7,13,1:45
6,12,1:45
5,11,1:45
4,10,1:45
10,9,1:51
11,9,1:51
12,9,1:51
13,9,1:51
9,12,1:51
9,13,1:51
10,12,1:51
8,12,1:51
8,13,1:51
11,6,1:51
10,6,1:51
9,4,1:51
-5,-3,1:51
-5,-4,1:51
-4,13,1:51
-4,18,1:51
-10,0,1:51
-9,0,1:51
-10,-20,1:51
-13,-15,1:51
-5,-16,1:51
-6,-17,1:51
-6,-16,1:51
-6,-15,1:51
-11,-19,1:51
-10,-19,1:51
-9,-19,1:51
-12,-16,1:51
-12,-15,1:51
-12,-14,1:51
-11,-1,1:51
-10,-1,1:51
-9,-1,1:51
-8,-1,1:51
-13,-20,2:45
-12,-20,2:45
-11,-20,2:45
-13,-19,2:45
-13,-18,2:45
-13,-17,2:45
-13,-16,2:45
-13,-13,2:45
-13,-12,2:45
-13,-11,2:45
-13,-10,2:45
-13,-9,2:45
-13,-8,2:45
-13,-7,2:45
-13,-4,2:45
-13,-3,2:45
-13,-2,2:45
-13,-1,2:45
-13,0,2:45
-12,0,2:45
-11,0,2:45
-8,0,2:45
-7,0,2:45
-6,0,2:45
-5,0,2:45
-5,-2,2:45
-5,-1,2:45
-5,-5,2:45
-5,-6,2:45
-5,-7,2:45
-4,-7,2:45
-3,-7,2:45
-2,-7,2:45
-1,-7,2:45
0,-7,2:45
0,-9,2:45
0,-8,2:45
0,-12,2:45
0,-13,2:45
0,-14,2:45
-5,-14,2:45
-4,-14,2:45
-3,-14,2:45
-2,-14,2:45
-1,-14,2:45
-5,-15,2:45
-8,-20,2:45
-7,-20,2:45
-6,-20,2:45
-5,-20,2:45
-5,-19,2:45
-5,-18,2:45
-13,10,2:45
-13,11,2:45
-13,12,2:45
-13,13,2:45
-13,14,2:45
-13,17,2:45
-13,18,2:45
-13,19,2:45
-13,20,2:45
-13,21,2:45
-12,21,2:45
-11,21,2:45
-10,21,2:45
-9,21,2:45
-8,21,2:45
-7,21,2:45
-6,21,2:45
-5,21,2:45
-4,21,2:45
-4,17,2:45
-4,20,2:45
-4,14,2:45
-4,11,2:45
-12,10,2:45
-11,10,2:45
-10,10,2:45
-9,10,2:45
-8,10,2:45
-7,10,2:45
-6,10,2:45
-5,10,2:45
-4,10,2:45
4,7,2:45
5,6,2:45
6,5,2:45
7,4,2:45
10,4,2:45
11,5,2:45
12,6,2:45
13,7,2:45
13,10,2:45
12,11,2:45
11,12,2:45
10,13,2:45
7,13,2:45
6,12,2:45
5,11,2:45
4,10,2:45
-13,10,3:45
-13,11,3:45
-13,12,3:45
-13,13,3:45
-13,14,3:45
-13,15,3:45
-13,16,3:45
-13,17,3:45
-13,18,3:45
-13,19,3:45
-13,20,3:45
-13,21,3:45
-12,21,3:45
-11,21,3:45
-10,21,3:45
-9,21,3:45
-8,21,3:45
-4,20,3:45
-4,17,3:45
-4,18,3:45
-4,19,3:45
-4,21,3:45
-7,21,3:45
-6,21,3:45
-5,21,3:45
-4,14,3:45
-4,13,3:45
-4,12,3:45
-4,11,3:45
-12,10,3:45
-11,10,3:45
-10,10,3:45
-9,10,3:45
-8,10,3:45
-7,10,3:45
-6,10,3:45
-5,10,3:45
-4,10,3:45
4,7,3:45
5,6,3:45
6,5,3:45
7,4,3:45
8,4,3:45
9,4,3:45
10,4,3:45
11,5,3:45
12,6,3:45
13,7,3:45
13,8,3:45
13,9,3:45
13,10,3:45
12,11,3:45
11,12,3:45
10,13,3:45
7,13,3:45
8,13,3:45
9,13,3:45
6,12,3:45
5,11,3:45
4,10,3:45
-5,-7,3:45
-5,-6,3:45
-5,-5,3:45
-5,-4,3:45
-5,-3,3:45
-5,-2,3:45
-5,-1,3:45
-5,0,3:45
-4,-7,3:45
-3,-7,3:45
-2,-7,3:45
-1,-7,3:45
0,-7,3:45
0,-9,3:45
0,-8,3:45
0,-14,3:45
0,-13,3:45
0,-12,3:45
-5,-14,3:45
-4,-14,3:45
-3,-14,3:45
-2,-14,3:45
-1,-14,3:45
-5,-15,3:45
-5,-20,3:45
-5,-19,3:45
-5,-18,3:45
-8,-20,3:45
-7,-20,3:45
-6,-20,3:45
-13,-20,3:45
-12,-20,3:45
-11,-20,3:45
-13,-19,3:45
-13,-18,3:45
-13,-17,3:45
-13,-16,3:45
-13,-13,3:45
-13,-12,3:45
-13,-11,3:45
-13,-10,3:45
-13,-9,3:45
-13,-8,3:45
-13,-7,3:45
-13,-4,3:45
-13,-3,3:45
-13,-2,3:45
-13,-1,3:45
-13,0,3:45
-12,0,3:45
-11,0,3:45
-8,0,3:45
-7,0,3:45
-6,0,3:45
-5,-17,3:45
-5,-16,3:45
-10,-20,3:45
-9,-20,3:45
-13,-15,3:45
-13,-14,3:45
-13,-6,3:45
-13,-5,3:45
-10,0,3:45
-9,0,3:45
0,-14,4:45
0,-13,4:45
0,-12,4:45
0,-11,4:45
0,-10,4:45
0,-9,4:45
0,-8,4:45
0,-7,4:45
-5,-7,4:17.1
-4,-7,4:45
-3,-7,4:45
-2,-7,4:45
-1,-7,4:45
-5,-6,4:45
-5,-5,4:45
-5,-4,4:45
-5,-3,4:45
-5,-2,4:45
-5,-1,4:45
-5,0,4:45
1,-12,4:45
1,-11,4:45
1,-10,4:45
1,-9,4:45
-13,0,4:45
-12,0,4:45
-11,0,4:45
-10,0,4:45
-9,0,4:45
-8,0,4:45
-7,0,4:45
-6,0,4:45
-13,-11,4:45
-13,-10,4:45
-13,-9,4:45
-13,-8,4:45
-13,-7,4:45
-13,-6,4:45
-13,-5,4:45
-13,-4,4:45
-13,-3,4:45
-13,-2,4:45
-13,-1,4:45
-13,-20,4:45
-13,-19,4:45
-13,-18,4:45
-13,-17,4:45
-13,-16,4:45
-13,-15,4:45
-13,-14,4:45
-13,-13,4:45
-13,-12,4:45
-12,-20,4:45
-11,-20,4:45
-10,-20,4:45
-9,-20,4:45
-8,-20,4:45
-7,-20,4:45
-6,-20,4:45
-5,-20,4:45
-5,-19,4:45
-5,-18,4:45
-5,-17,4:45
-5,-16,4:45
-5,-15,4:45
-4,-14,4:45
-3,-14,4:45
-2,-14,4:45
-1,-14,4:45
-13,10,4:45
-13,11,4:45
-13,12,4:45
-13,13,4:45
-13,14,4:45
-13,15,4:45
-13,16,4:45
-13,17,4:45
-13,18,4:45
-13,19,4:45
-13,20,4:45
-13,21,4:45
-12,21,4:45
-11,21,4:45
-10,21,4:45
-9,21,4:45
-8,21,4:45
-7,21,4:45
-6,21,4:45
-5,21,4:45
-4,21,4:45
-4,17,4:45
-4,18,4:45
-4,19,4:45
-4,20,4:45
-4,14,4:45
-4,13,4:45
-4,12,4:45
-4,11,4:45
-4,10,4:45
-12,10,4:45
-11,10,4:45
-10,10,4:45
-9,10,4:45
-8,10,4:45
-7,10,4:45
-6,10,4:45
-5,10,4:45
4,7,4:45
4,8,4:45
4,9,4:45
4,10,4:45
5,6,4:45
6,5,4:45
7,4,4:45
8,4,4:45
9,4,4:45
10,4,4:45
11,5,4:45
12,6,4:45
13,7,4:45
13,8,4:45
13,9,4:45
13,10,4:45
12,11,4:45
11,12,4:45
7,13,4:45
8,13,4:45
9,13,4:45
10,13,4:45
6,12,4:45
5,11,4:45
-5,-14,4:17.1
-5,-13,4:17.1
-5,-12,4:17.1
-5,-11,4:17.1
-5,-10,4:17.1
-5,-9,4:17.1
-5,-8,4:17.1
-13,-18,5:17.1
-12,-18,5:17.1
-11,-18,5:17.1
-10,-18,5:17.1
-9,-18,5:17.1
-8,-18,5:17.1
-7,-18,5:17.1
-6,-18,5:17.1
-5,-18,5:17.1
-13,-6,5:17.1
-12,-6,5:17.1
-11,-6,5:17.1
-10,-6,5:17.1
-9,-6,5:17.1
-8,-6,5:17.1
-7,-6,5:17.1
-6,-6,5:17.1
-5,-6,5:17.1
-13,-15,5:17.1
-12,-15,5:17.1
-11,-15,5:17.1
-10,-15,5:17.1
-9,-15,5:17.1
-8,-15,5:17.1
-7,-15,5:17.1
-6,-15,5:17.1
-5,-15,5:17.1
-13,-3,5:17.1
-12,-3,5:17.1
-11,-3,5:17.1
-10,-3,5:17.1
-9,-3,5:17.1
-8,-3,5:17.1
-7,-3,5:17.1
-6,-3,5:17.1
-5,-3,5:17.1
-14,-3,5:17.1
-14,-6,5:17.1
-4,-6,5:17.1
-4,-3,5:17.1
-4,-15,5:17.1
-4,-18,5:17.1
-14,-18,5:17.1
-14,-15,5:17.1
-14,-12,5:17.1
-13,-12,5:17.1
-12,-12,5:17.1
-11,-12,5:17.1
-10,-12,5:17.1
-9,-12,5:17.1
-8,-12,5:17.1
-7,-12,5:17.1
-6,-12,5:17.1
-5,-12,5:17.1
-4,-12,5:17.1
-3,-12,5:17.1
-2,-12,5:17.1
-1,-12,5:17.1
0,-12,5:17.1
1,-12,5:17.1
-14,-9,5:17.1
-13,-9,5:17.1
-12,-9,5:17.1
-11,-9,5:17.1
-10,-9,5:17.1
-9,-9,5:17.1
-8,-9,5:17.1
-7,-9,5:17.1
-6,-9,5:17.1
-5,-9,5:17.1
-4,-9,5:17.1
-3,-9,5:17.1
-2,-9,5:17.1
-1,-9,5:17.1
0,-9,5:17.1
1,-9,5:17.1
-14,-20,5:17.1
-13,-20,5:17.1
-12,-20,5:17.1
-11,-20,5:17.1
-10,-20,5:17.1
-9,-20,5:17.1
-8,-20,5:17.1
-7,-20,5:17.1
-6,-20,5:17.1
-5,-20,5:17.1
-4,-20,5:17.1
-14,0,5:17.1
-13,0,5:17.1
-12,0,5:17.1
-11,0,5:17.1
-10,0,5:17.1
-9,0,5:17.1
-8,0,5:17.1
-7,0,5:17.1
-6,0,5:17.1
-5,0,5:17.1
-4,0,5:17.1
-5,-14,5:51
-5,-13,5:51
-5,-7,5:51
-12,-20,6:17.1
-12,-19,6:17.1
-12,-18,6:17.1
-12,-17,6:17.1
-12,-16,6:17.1
-12,-15,6:17.1
-12,-14,6:17.1
-12,-13,6:17.1
-12,-12,6:17.1
-12,-11,6:17.1
-12,-10,6:17.1
-12,-9,6:17.1
-12,-8,6:17.1
-12,-7,6:17.1
-12,-6,6:17.1
-12,-5,6:17.1
-12,-4,6:17.1
-12,-3,6:17.1
-12,-1,6:17.1
-12,0,6:17.1
-12,-2,6:17.1
-6,-20,6:17.1
-6,-19,6:17.1
-6,-18,6:17.1
-6,-17,6:17.1
-6,-16,6:17.1
-6,-15,6:17.1
-6,-14,6:17.1
-6,-13,6:17.1
-6,-12,6:17.1
-6,-11,6:17.1
-6,-10,6:17.1
-6,-9,6:17.1
-6,-8,6:17.1
-6,-7,6:17.1
-6,-6,6:17.1
-6,-5,6:17.1
-6,-4,6:17.1
-6,-3,6:17.1
-6,-1,6:17.1
-6,-2,6:17.1
-6,0,6:17.1
-10,-3,6:51
-11,-3,6:51
-7,0,6:51
-4,0,6:51
-5,0,6:51
-13,-12,6:51
-11,-12,6:51
-13,-15,6:51
-11,-18,6:51
-10,-18,6:51
-9,-18,6:51
-5,-12,6:51
-4,-12,6:51
-3,-12,6:51
-2,-12,6:51
-2,-9,6:51
-14,0,6:51
-13,0,6:51
-5,-20,6:51
-7,-20,6:51
-12,0,7:17.1
-11,0,7:17.1
-10,0,7:17.1
-9,0,7:17.1
-8,0,7:17.1
-7,0,7:17.1
-6,0,7:17.1
-12,-20,7:17.1
-11,-20,7:17.1
-10,-20,7:17.1
-9,-20,7:17.1
-8,-20,7:17.1
-7,-20,7:17.1
-6,-20,7:17.1
-12,-14,7:51
-12,-13,7:51
-12,-12,7:51
-6,-5,7:51
-9,-20,8:17.1
-9,-19,8:17.1
-9,-18,8:17.1
-9,-17,8:17.1
-9,-16,8:17.1
-9,-15,8:17.1
-9,-14,8:17.1
-9,-13,8:17.1
-9,-12,8:17.1
-9,-11,8:17.1
-9,-10,8:17.1
-9,-9,8:17.1
-9,-8,8:17.1
-9,-7,8:17.1
-9,-6,8:17.1
-9,-5,8:17.1
-9,-4,8:17.1
-9,-3,8:17.1
-9,-2,8:17.1
-9,-1,8:17.1
-9,0,8:17.1
-9,1,8:17.1
-9,-21,8:17.1
-12,0,8:51
-11,0,8:51
-10,0,8:51
-7,-20,8:51
