[META]
version=2.0
spawnOnBlockType=1,2,3,12
spawnSunlight=True
spawnDarkness=True
spawnWater=True
spawnLava=False
underFill=True
randomRotation=True
dig=True
tree=False
branch=False
needsFoundation=True
rarity=75
collisionPercentage=8
spawnElevationMin=63
spawnElevationMax=69
spawnInBiome=TallForest
[DATA]
-2,-1,0:8.8
-2,-2,0:8.8
-1,-2,0:8.8
0,-2,0:8.8
1,-2,0:8.8
1,-1,0:8.8
1,0,0:8.8
0,0,0:12
-1,0,0:8.8
-2,0,0:8.8
-1,-1,0:8.8
0,-1,0:8.8
-1,1,0:8.8
0,1,0:12
0,2,0:8.8
1,1,0:12
1,2,0:8.8
2,2,0:8.8
2,3,0:8.8
3,3,0:8.8
4,3,0:12
5,3,0:12
4,2,0:8.8
3,2,0:8.8
3,1,0:8.8
2,1,0:8.8
2,0,0:8.8
3,0,0:8.8
4,0,0:8.8
4,-1,0:8.8
5,-1,0:8.8
5,-2,0:12
5,-3,0:8.8
3,-1,0:8.8
-1,2,0:8.8
-1,3,0:8.8
-1,4,0:8.8
-2,4,0:8.8
-3,4,0:8.8
-3,3,0:8.8
-2,3,0:8.8
-2,2,0:8.8
-2,1,0:8.8
-3,-2,0:8.8
-3,-3,0:12
-4,-4,0:12
-5,-4,0:8.8
-5,-5,0:8.8
-6,-5,0:8.8
-3,-4,0:12
-2,-3,0:8.8
-2,-4,0:8.8
-1,-4,0:8.8
-1,-3,0:8.8
-3,5,0:12
-4,5,0:12
-4,6,0:8.8
-7,-6,1:8.8
-7,-5,1:8.8
-6,-5,1:8.8
-6,-4,1:8.8
-6,-6,1:8.8
-5,-6,1:8.8
-5,-5,1:8.8
-4,-5,1:8.8
-3,-5,1:8.8
-2,-5,1:8.8
-1,-5,1:8.8
-1,-4,1:8.8
0,-4,1:8.8
0,-3,1:8.8
1,-3,1:8.8
1,-2,1:8.8
2,-2,1:8.8
2,-1,1:8.8
3,-1,1:8.8
3,-2,1:8.8
4,-2,1:8.8
4,-3,1:8.8
5,-3,1:8.8
5,-4,1:8.8
6,-4,1:8.8
6,-3,1:8.8
6,-2,1:8.8
6,-1,1:8.8
5,-1,1:8.8
5,-2,1:12
4,-1,1:8.8
5,0,1:8.8
4,0,1:8.8
4,1,1:8.8
5,1,1:8.8
5,2,1:8.8
6,2,1:8.8
6,3,1:8.8
7,3,1:8.8
7,4,1:8.8
6,4,1:8.8
5,4,1:8.8
4,4,1:8.8
3,4,1:8.8
2,4,1:8.8
2,3,1:8.8
1,3,1:8.8
0,3,1:8.8
0,4,1:8.8
-1,4,1:8.8
-1,5,1:8.8
-2,5,1:8.8
-2,6,1:8.8
-3,6,1:8.8
-4,7,1:8.8
-5,7,1:8.8
-5,6,1:8.8
-5,5,1:8.8
-4,5,1:12
-4,4,1:8.8
-4,6,1:8.8
-3,5,1:12
-3,4,1:8.8
-3,3,1:8.8
-2,3,1:8.8
-2,2,1:8.8
-2,1,1:8.8
-3,1,1:8.8
-3,0,1:8.8
-2,0,1:8.8
-1,0,1:8.8
-1,1,1:8.8
-1,2,1:8.8
-1,3,1:8.8
-2,4,1:8.8
0,2,1:8.8
1,2,1:8.8
2,2,1:8.8
2,1,1:8.8
3,1,1:8.8
3,0,1:8.8
2,0,1:8.8
1,0,1:8.8
0,0,1:12
0,1,1:12
1,1,1:12
3,2,1:8.8
4,2,1:8.8
5,3,1:12
4,3,1:12
3,3,1:8.8
-2,-1,1:8.8
-2,-2,1:8.8
-3,-1,1:8.8
-3,-2,1:8.8
-4,-2,1:8.8
-4,-3,1:8.8
-5,-3,1:8.8
-5,-4,1:8.8
-4,-4,1:12
-3,-4,1:12
-2,-4,1:8.8
-1,-3,1:8.8
0,-2,1:8.8
-1,-2,1:8.8
-2,-3,1:8.8
-3,-3,1:12
1,-1,1:8.8
0,-1,1:8.8
-1,-1,1:8.8
5,-2,-1:3
0,0,-1:3
0,1,-1:3
1,1,-1:3
4,3,-1:3
5,3,-1:3
-4,5,-1:3
-3,5,-1:3
-4,-4,-1:3
-3,-4,-1:3
-3,-3,-1:3
-4,-4,2:83
-3,-4,2:83
-3,-3,2:83
0,0,2:83
0,1,2:83
1,1,2:83
5,-2,2:83
5,3,2:83
4,3,2:83
-3,5,2:83
-4,5,2:83
-4,-4,3:83
-3,-4,3:83
-3,-3,3:83
0,0,3:83
0,1,3:83
1,1,3:83
5,-2,3:83
4,3,3:83
5,3,3:83
-4,5,3:83
-3,5,3:83
