[META]
version=2.0
spawnOnBlockType=2,3
spawnSunlight=True
spawnDarkness=True
spawnWater=False
spawnLava=False
underFill=False
randomRotation=True
dig=True
tree=True
branch=False
needsFoundation=True
rarity=30
collisionPercentage=2
spawnElevationMin=0
spawnElevationMax=220
spawnInBiome=WoWForest
[DATA]
0,-5,0:17.0
0,-4,0:17.0
-4,-3,0:17.0
4,-3,0:17.0
-5,-2,0:17.0
-4,-2,0:17.0
4,-2,0:17.0
5,-2,0:17.0
-4,2,0:17.0
4,2,0:17.0
5,2,0:17.0
-4,3,0:17.0
-3,3,0:17.0
0,4,0:17.0
1,4,0:17.0
0,5,0:17.0
1,5,0:17.0
0,-5,1:17.0
-1,-4,1:17.0
0,-4,1:17.0
-4,-3,1:17.0
4,-3,1:17.0
-4,-2,1:17.0
4,-2,1:17.0
0,0,1:17.0
-4,2,1:17.0
-3,2,1:17.0
4,2,1:17.0
5,2,1:17.0
-4,3,1:17.0
-3,3,1:17.0
1,3,1:17.0
0,4,1:17.0
1,4,1:17.0
1,5,1:17.0
-1,-4,2:17.0
0,-4,2:17.0
-4,-3,2:17.0
-1,-3,2:17.0
0,-3,2:17.0
1,-3,2:17.0
-4,-2,2:17.0
-3,-2,2:17.0
0,-2,2:17.0
3,-2,2:17.0
4,-2,2:17.0
1,-1,2:17.0
4,-1,2:17.0
0,0,2:17.0
0,1,2:17.0
4,1,2:17.0
-4,2,2:17.0
-3,2,2:17.0
3,2,2:17.0
4,2,2:17.0
5,2,2:17.0
-4,3,2:17.0
-3,3,2:17.0
0,3,2:17.0
1,3,2:17.0
4,3,2:17.0
0,4,2:17.0
1,4,2:17.0
0,-4,3:17.0
-1,-3,3:17.0
0,-3,3:17.0
1,-3,3:17.0
-4,-2,3:17.0
-3,-2,3:17.0
-2,-2,3:17.0
-1,-2,3:17.0
0,-2,3:17.0
1,-2,3:17.0
2,-2,3:17.0
3,-2,3:17.0
4,-2,3:17.0
-4,-1,3:17.0
-3,-1,3:17.0
-2,-1,3:17.0
-1,-1,3:17.0
0,-1,3:17.0
1,-1,3:17.0
2,-1,3:17.0
3,-1,3:17.0
4,-1,3:17.0
-2,0,3:17.0
-1,0,3:17.0
0,0,3:17.0
1,0,3:17.0
2,0,3:17.0
3,0,3:17.0
-3,1,3:17.0
-2,1,3:17.0
-1,1,3:17.0
0,1,3:17.0
1,1,3:17.0
2,1,3:17.0
3,1,3:17.0
4,1,3:17.0
-4,2,3:17.0
-3,2,3:17.0
-2,2,3:17.0
-1,2,3:17.0
0,2,3:17.0
1,2,3:17.0
2,2,3:17.0
3,2,3:17.0
4,2,3:17.0
-4,3,3:17.0
-3,3,3:17.0
-2,3,3:17.0
-1,3,3:17.0
0,3,3:17.0
1,3,3:17.0
3,3,3:17.0
0,4,3:17.0
1,4,3:17.0
2,-8,4:18.3
-3,-2,4:17.0
-2,-2,4:17.0
-1,-2,4:17.0
0,-2,4:17.0
1,-2,4:17.0
-3,-1,4:17.0
-2,-1,4:17.0
-1,-1,4:17.0
1,-1,4:17.0
2,-1,4:17.0
3,-1,4:17.0
-3,0,4:17.0
-2,0,4:17.0
-1,0,4:17.0
0,0,4:17.0
1,0,4:17.0
2,0,4:17.0
3,0,4:17.0
-3,1,4:17.0
-2,1,4:17.0
-1,1,4:17.0
0,1,4:17.0
1,1,4:17.0
2,1,4:17.0
3,1,4:17.0
-3,2,4:17.0
-2,2,4:17.0
-1,2,4:17.0
1,2,4:17.0
2,2,4:17.0
3,2,4:17.0
-2,3,4:17.0
-1,3,4:17.0
0,3,4:17.0
1,3,4:17.0
2,3,4:17.0
0,4,4:17.0
0,-1,4:17.0
0,2,4:17.0
2,-8,5:18.3
1,-7,5:18.3
0,-2,5:17.0
-2,-1,5:17.0
-1,-1,5:17.0
0,-1,5:17.0
1,-1,5:17.0
2,-1,5:17.0
-3,0,5:17.0
-2,0,5:17.0
2,0,5:17.0
-3,1,5:17.0
-2,1,5:17.0
2,1,5:17.0
-3,2,5:17.0
-2,2,5:17.0
1,2,5:17.0
2,2,5:17.0
-1,3,5:17.0
0,3,5:17.0
1,3,5:17.0
6,8,5:18.3
1,0,5:17.0
0,0,5:17.0
-1,0,5:17.0
-1,1,5:17.0
0,1,5:17.0
1,1,5:17.0
0,2,5:17.0
-1,2,5:17.0
2,-8,6:18.3
1,-7,6:18.3
-2,-1,6:17.0
-1,-1,6:17.0
0,-1,6:17.0
1,-1,6:17.0
-2,0,6:17.0
1,0,6:17.0
2,0,6:17.0
-2,1,6:17.0
1,1,6:17.0
2,1,6:17.0
-2,2,6:17.0
-1,2,6:17.0
1,2,6:17.0
2,2,6:17.0
-1,3,6:17.0
0,3,6:17.0
6,8,6:18.3
-1,0,6:17.0
0,0,6:17.0
0,1,6:17.0
-1,1,6:17.0
0,2,6:17.0
2,-8,7:18.3
3,-8,7:18.3
1,-7,7:18.3
7,-5,7:18.3
6,-4,7:18.3
-2,0,7:17.0
-1,0,7:17.0
0,0,7:17.0
1,0,7:17.0
-2,1,7:17.0
1,1,7:17.0
-2,2,7:17.0
-1,2,7:17.0
0,2,7:17.0
1,2,7:17.0
0,3,7:17.0
6,7,7:18.3
6,8,7:18.3
1,10,7:18.3
-1,1,7:17.0
0,1,7:17.0
4,-9,8:18.3
2,-8,8:18.3
3,-8,8:18.3
1,-7,8:18.3
1,-6,8:18.3
1,-5,8:18.3
7,-5,8:18.3
6,-4,8:18.3
-1,0,8:17.0
0,0,8:17.0
1,0,8:17.0
-2,1,8:17.0
-1,1,8:17.0
1,1,8:17.0
-1,2,8:17.0
0,2,8:17.0
-6,4,8:18.3
5,6,8:18.3
5,7,8:18.3
6,7,8:18.3
6,8,8:18.3
6,9,8:18.3
1,10,8:18.3
2,10,8:18.3
2,11,8:18.3
0,1,8:17.0
4,-9,9:18.3
2,-8,9:18.3
3,-8,9:18.3
1,-7,9:18.3
7,-7,9:18.3
1,-6,9:18.3
7,-6,9:18.3
1,-5,9:18.3
7,-5,9:18.3
6,-4,9:18.3
-6,-1,9:18.3
-1,0,9:17.0
0,0,9:17.0
-2,1,9:17.0
-1,1,9:17.0
1,1,9:17.0
-1,2,9:17.0
0,2,9:17.0
-6,4,9:18.3
4,5,9:18.3
4,6,9:18.3
5,6,9:18.3
5,7,9:18.3
6,7,9:18.3
6,8,9:18.3
1,9,9:18.3
6,9,9:18.3
1,10,9:18.3
2,10,9:18.3
2,11,9:18.3
0,1,9:17.0
5,-10,10:18.3
3,-9,10:18.3
4,-9,10:18.3
2,-8,10:18.3
3,-8,10:18.3
7,-8,10:18.3
1,-7,10:18.3
7,-7,10:18.3
1,-6,10:18.3
7,-6,10:18.3
1,-5,10:18.3
7,-5,10:18.3
0,-4,10:18.3
6,-4,10:18.3
-7,-1,10:18.3
-6,-1,10:18.3
-1,0,10:17.0
0,0,10:17.0
-1,1,10:17.0
0,1,10:17.0
1,1,10:17.0
-1,2,10:17.0
0,2,10:17.0
-7,3,10:18.3
-5,3,10:18.3
-4,3,10:18.3
-6,4,10:18.3
4,5,10:18.3
4,6,10:18.3
5,6,10:18.3
5,7,10:18.3
6,7,10:18.3
1,8,10:18.3
6,8,10:18.3
1,9,10:18.3
6,9,10:18.3
1,10,10:18.3
2,10,10:18.3
6,10,10:18.3
2,11,10:18.3
3,11,10:18.3
6,11,10:18.3
7,11,10:18.3
5,-10,11:18.3
3,-9,11:18.3
4,-9,11:18.3
7,-9,11:18.3
2,-8,11:18.3
3,-8,11:18.3
7,-8,11:18.3
1,-7,11:18.3
7,-7,11:18.3
1,-6,11:18.3
4,-6,11:18.3
7,-6,11:18.3
1,-5,11:18.3
7,-5,11:18.3
0,-4,11:18.3
6,-4,11:18.3
4,-2,11:18.3
-7,-1,11:18.3
-6,-1,11:18.3
-5,-1,11:18.3
-1,0,11:17.0
0,0,11:17.0
-1,1,11:17.0
0,1,11:17.0
1,1,11:17.0
-1,2,11:17.0
0,2,11:17.0
-7,3,11:18.3
-5,3,11:18.3
-4,3,11:18.3
-6,4,11:18.3
3,4,11:18.3
4,5,11:18.3
5,6,11:18.3
1,7,11:18.3
5,7,11:18.3
6,7,11:18.3
1,8,11:18.3
6,8,11:18.3
1,9,11:18.3
6,9,11:18.3
1,10,11:18.3
2,10,11:18.3
6,10,11:18.3
2,11,11:18.3
3,11,11:18.3
6,11,11:18.3
7,11,11:18.3
4,12,11:18.3
6,-11,12:18.3
7,-11,12:18.3
5,-10,12:18.3
7,-10,12:18.3
3,-9,12:18.3
4,-9,12:18.3
7,-9,12:18.3
2,-8,12:18.3
3,-8,12:18.3
6,-8,12:18.3
7,-8,12:18.3
1,-7,12:18.3
2,-7,12:18.3
7,-7,12:18.3
1,-6,12:18.3
4,-6,12:18.3
7,-6,12:18.3
1,-5,12:18.3
7,-5,12:18.3
0,-4,12:18.3
6,-4,12:18.3
0,-3,12:18.3
4,-2,12:18.3
-8,-1,12:18.3
-7,-1,12:18.3
-6,-1,12:18.3
-5,-1,12:18.3
-4,-1,12:18.3
-1,0,12:17.0
0,0,12:17.0
-1,1,12:17.0
0,1,12:17.0
-1,2,12:17.0
0,2,12:17.0
-9,3,12:18.3
-8,3,12:18.3
-7,3,12:18.3
-6,3,12:18.3
-5,3,12:18.3
-4,3,12:18.3
-3,3,12:18.3
-6,4,12:18.3
3,4,12:18.3
4,5,12:18.3
0,6,12:18.3
5,6,12:18.3
1,7,12:18.3
5,7,12:18.3
6,7,12:18.3
1,8,12:18.3
6,8,12:18.3
1,9,12:18.3
6,9,12:18.3
1,10,12:18.3
2,10,12:18.3
6,10,12:18.3
2,11,12:18.3
3,11,12:18.3
6,11,12:18.3
7,11,12:18.3
4,12,12:18.3
7,12,12:18.3
6,-11,13:18.3
7,-11,13:18.3
5,-10,13:18.3
6,-10,13:18.3
7,-10,13:18.3
3,-9,13:18.3
4,-9,13:18.3
7,-9,13:18.3
2,-8,13:18.3
3,-8,13:18.3
6,-8,13:18.3
7,-8,13:18.3
1,-7,13:18.3
2,-7,13:18.3
7,-7,13:18.3
1,-6,13:18.3
2,-6,13:18.3
4,-6,13:18.3
7,-6,13:18.3
1,-5,13:18.3
6,-5,13:18.3
7,-5,13:18.3
0,-4,13:18.3
4,-4,13:18.3
6,-4,13:18.3
0,-3,13:18.3
0,-2,13:18.3
4,-2,13:18.3
-8,-1,13:18.3
-7,-1,13:18.3
-6,-1,13:18.3
-5,-1,13:18.3
-4,-1,13:18.3
3,-1,13:18.3
-9,0,13:18.3
-1,0,13:17.0
0,0,13:17.0
-1,1,13:17.0
0,1,13:17.0
-7,2,13:18.3
-1,2,13:17.0
0,2,13:17.0
-9,3,13:18.3
-8,3,13:18.3
-7,3,13:18.3
-6,3,13:18.3
-5,3,13:18.3
-4,3,13:18.3
-3,3,13:18.3
2,3,13:18.3
3,3,13:18.3
-6,4,13:18.3
-5,4,13:18.3
3,4,13:18.3
4,5,13:18.3
0,6,13:18.3
3,6,13:18.3
5,6,13:18.3
0,7,13:18.3
1,7,13:18.3
5,7,13:18.3
6,7,13:18.3
1,8,13:18.3
6,8,13:18.3
1,9,13:18.3
6,9,13:18.3
1,10,13:18.3
2,10,13:18.3
3,10,13:18.3
6,10,13:18.3
2,11,13:18.3
3,11,13:18.3
4,11,13:18.3
6,11,13:18.3
4,12,13:18.3
5,12,13:18.3
6,12,13:18.3
7,12,13:18.3
5,13,13:18.3
5,-10,14:18.3
6,-10,14:18.3
3,-9,14:18.3
4,-9,14:18.3
5,-9,14:18.3
6,-9,14:17.0
7,-9,14:18.3
2,-8,14:18.3
3,-8,14:18.3
6,-8,14:18.3
7,-8,14:18.3
1,-7,14:18.3
2,-7,14:18.3
3,-7,14:18.3
7,-7,14:18.3
1,-6,14:18.3
2,-6,14:18.3
4,-6,14:18.3
6,-6,14:18.3
7,-6,14:18.3
1,-5,14:18.3
2,-5,14:18.3
5,-5,14:18.3
6,-5,14:18.3
7,-5,14:18.3
0,-4,14:18.3
1,-4,14:18.3
4,-4,14:18.3
6,-4,14:18.3
0,-3,14:18.3
3,-3,14:18.3
0,-2,14:18.3
4,-2,14:18.3
-8,-1,14:18.3
-7,-1,14:18.3
-6,-1,14:18.3
-5,-1,14:18.3
-4,-1,14:18.3
-3,-1,14:18.3
0,-1,14:18.3
3,-1,14:18.3
-10,0,14:18.3
-9,0,14:18.3
-7,0,14:18.3
-2,0,14:18.3
-1,0,14:17.0
0,0,14:17.0
2,0,14:18.3
-5,1,14:18.3
-1,1,14:17.0
0,1,14:17.0
-10,2,14:18.3
-8,2,14:18.3
-7,2,14:18.3
-2,2,14:18.3
-1,2,14:17.0
0,2,14:17.0
2,2,14:18.3
-9,3,14:18.3
-8,3,14:18.3
-7,3,14:18.3
-6,3,14:18.3
-5,3,14:18.3
-4,3,14:18.3
-3,3,14:18.3
2,3,14:18.3
3,3,14:18.3
-6,4,14:18.3
-5,4,14:18.3
0,4,14:18.3
3,4,14:18.3
0,5,14:18.3
4,5,14:18.3
0,6,14:18.3
3,6,14:18.3
5,6,14:18.3
0,7,14:18.3
1,7,14:18.3
5,7,14:18.3
6,7,14:18.3
1,8,14:18.3
4,8,14:18.3
6,8,14:18.3
1,9,14:18.3
2,9,14:18.3
6,9,14:18.3
1,10,14:18.3
2,10,14:18.3
3,10,14:18.3
6,10,14:18.3
3,11,14:18.3
4,11,14:18.3
5,11,14:18.3
6,11,14:18.3
4,12,14:18.3
5,12,14:18.3
6,12,14:18.3
7,12,14:18.3
5,13,14:18.3
6,13,14:18.3
7,13,14:18.3
4,-9,15:18.3
5,-9,15:18.3
6,-9,15:18.3
2,-8,15:18.3
3,-8,15:18.3
4,-8,15:18.3
5,-8,15:17.0
6,-8,15:18.3
1,-7,15:18.3
2,-7,15:18.3
3,-7,15:18.3
4,-7,15:18.3
6,-7,15:18.3
1,-6,15:18.3
2,-6,15:18.3
4,-6,15:18.3
6,-6,15:18.3
1,-5,15:18.3
2,-5,15:18.3
3,-5,15:18.3
5,-5,15:18.3
6,-5,15:18.3
0,-4,15:18.3
1,-4,15:18.3
4,-4,15:18.3
6,-4,15:18.3
0,-3,15:18.3
1,-3,15:18.3
3,-3,15:18.3
4,-3,15:18.3
5,-3,15:18.3
0,-2,15:18.3
2,-2,15:18.3
3,-2,15:18.3
4,-2,15:18.3
-8,-1,15:18.3
-7,-1,15:18.3
-6,-1,15:18.3
-5,-1,15:18.3
-4,-1,15:18.3
-3,-1,15:18.3
-2,-1,15:18.3
0,-1,15:18.3
3,-1,15:18.3
-10,0,15:18.3
-9,0,15:18.3
-7,0,15:18.3
-2,0,15:18.3
-1,0,15:17
0,0,15:17.0
2,0,15:18.3
-11,1,15:18.3
-5,1,15:18.3
-1,1,15:17.0
0,1,15:17.0
1,1,15:18.3
-11,2,15:18.3
-10,2,15:18.3
-9,2,15:18.3
-8,2,15:18.3
-7,2,15:18.3
-6,2,15:18.3
-2,2,15:18.3
-1,2,15:18.3
0,2,15:17.0
2,2,15:18.3
-9,3,15:18.3
-8,3,15:18.3
-7,3,15:18.3
-6,3,15:18.3
-5,3,15:18.3
-4,3,15:18.3
-3,3,15:18.3
2,3,15:18.3
3,3,15:18.3
-6,4,15:18.3
-5,4,15:18.3
0,4,15:18.3
3,4,15:18.3
0,5,15:18.3
4,5,15:18.3
0,6,15:18.3
1,6,15:18.3
3,6,15:18.3
4,6,15:18.3
5,6,15:18.3
0,7,15:18.3
1,7,15:18.3
5,7,15:18.3
6,7,15:18.3
1,8,15:18.3
2,8,15:18.3
4,8,15:18.3
5,8,15:18.3
6,8,15:18.3
1,9,15:18.3
2,9,15:18.3
6,9,15:18.3
1,10,15:18.3
2,10,15:18.3
3,10,15:18.3
5,10,15:18.3
6,10,15:18.3
3,11,15:18.3
4,11,15:18.3
5,11,15:18.3
6,11,15:18.3
4,12,15:18.3
5,12,15:18.3
6,12,15:18.3
7,12,15:18.3
5,13,15:18.3
6,13,15:18.3
7,13,15:18.3
6,14,15:18.3
7,14,15:18.3
3,-8,16:18.3
4,-8,16:18.3
5,-8,16:18.3
6,-8,16:18.3
2,-7,16:18.3
3,-7,16:18.3
4,-7,16:18.3
5,-7,16:17.0
6,-7,16:18.3
1,-6,16:18.3
2,-6,16:17.0
3,-6,16:17.0
4,-6,16:18.3
5,-6,16:17.0
6,-6,16:18.3
1,-5,16:18.3
2,-5,16:18.3
3,-5,16:18.3
5,-5,16:18.3
6,-5,16:18.3
0,-4,16:18.3
1,-4,16:18.3
2,-4,16:18.3
4,-4,16:18.3
5,-4,16:18.3
6,-4,16:18.3
-5,-3,16:18.3
0,-3,16:18.3
1,-3,16:18.3
3,-3,16:18.3
4,-3,16:18.3
5,-3,16:18.3
-5,-2,16:18.3
0,-2,16:18.3
1,-2,16:18.3
2,-2,16:18.3
3,-2,16:18.3
4,-2,16:18.3
5,-2,16:18.3
-8,-1,16:18.3
-7,-1,16:18.3
-6,-1,16:18.3
-5,-1,16:18.3
-4,-1,16:18.3
-3,-1,16:18.3
-2,-1,16:18.3
-1,-1,16:18.3
0,-1,16:17
1,-1,16:17.0
2,-1,16:18.3
3,-1,16:18.3
-10,0,16:18.3
-9,0,16:18.3
-8,0,16:18.3
-7,0,16:18.3
-2,0,16:18.3
-1,0,16:18.3
0,0,16:17.0
1,0,16:18.3
2,0,16:18.3
-11,1,16:18.3
-10,1,16:18.3
-5,1,16:18.3
-2,1,16:17
-1,1,16:17.0
0,1,16:17.0
1,1,16:18.3
-11,2,16:18.3
-10,2,16:18.3
-9,2,16:18.3
-8,2,16:18.3
-7,2,16:18.3
-6,2,16:18.3
-4,2,16:18.3
-3,2,16:18.3
-2,2,16:18.3
-1,2,16:18.3
0,2,16:18.3
1,2,16:18.3
2,2,16:18.3
-9,3,16:18.3
-8,3,16:18.3
-7,3,16:18.3
-6,3,16:18.3
-5,3,16:18.3
-4,3,16:18.3
-3,3,16:18.3
0,3,16:18.3
2,3,16:18.3
3,3,16:18.3
-6,4,16:18.3
-5,4,16:18.3
0,4,16:18.3
2,4,16:18.3
3,4,16:18.3
0,5,16:18.3
3,5,16:18.3
4,5,16:18.3
0,6,16:18.3
1,6,16:18.3
3,6,16:18.3
4,6,16:18.3
5,6,16:18.3
0,7,16:18.3
1,7,16:18.3
4,7,16:18.3
5,7,16:18.3
1,8,16:18.3
2,8,16:18.3
3,8,16:17
4,8,16:18.3
5,8,16:18.3
1,9,16:18.3
2,9,16:18.3
3,9,16:17
4,9,16:17
5,9,16:18.3
6,9,16:18.3
1,10,16:18.3
2,10,16:18.3
3,10,16:18.3
4,10,16:17.0
5,10,16:18.3
6,10,16:18.3
3,11,16:18.3
4,11,16:18.3
5,11,16:17.0
6,11,16:18.3
4,12,16:18.3
5,12,16:18.3
6,12,16:18.3
5,13,16:18.3
6,13,16:18.3
7,13,16:18.3
7,14,16:18.3
4,-8,17:18.3
5,-8,17:18.3
2,-7,17:18.3
3,-7,17:18.3
4,-7,17:18.3
5,-7,17:18.3
2,-6,17:18.3
3,-6,17:18.3
4,-6,17:18.3
5,-6,17:18.3
1,-5,17:18.3
2,-5,17:18.3
3,-5,17:18.3
4,-5,17:17.0
5,-5,17:18.3
1,-4,17:18.3
2,-4,17:18.3
4,-4,17:18.3
5,-4,17:18.3
-5,-3,17:18.3
0,-3,17:18.3
1,-3,17:18.3
3,-3,17:18.3
4,-3,17:18.3
5,-3,17:18.3
6,-3,17:18.3
-6,-2,17:18.3
-5,-2,17:18.3
-4,-2,17:18.3
0,-2,17:18.3
1,-2,17:18.3
2,-2,17:18.3
3,-2,17:18.3
4,-2,17:18.3
5,-2,17:18.3
-8,-1,17:18.3
-7,-1,17:18.3
-6,-1,17:18.3
-5,-1,17:18.3
-4,-1,17:18.3
-3,-1,17:18.3
-2,-1,17:18.3
-1,-1,17:18.3
0,-1,17:18.3
1,-1,17:17
2,-1,17:18.3
3,-1,17:18.3
-10,0,17:18.3
-9,0,17:18.3
-8,0,17:18.3
-7,0,17:18.3
-2,0,17:18.3
-1,0,17:18.3
0,0,17:18.3
1,0,17:18.3
2,0,17:18.3
-12,1,17:18.3
-11,1,17:18.3
-10,1,17:17
-9,1,17:17
-8,1,17:17.0
-5,1,17:18.3
-2,1,17:17
-1,1,17:17
0,1,17:17.0
1,1,17:18.3
-12,2,17:18.3
-11,2,17:18.3
-10,2,17:18.3
-9,2,17:18.3
-8,2,17:18.3
-7,2,17:18.3
-6,2,17:18.3
-5,2,17:18.3
-4,2,17:18.3
-3,2,17:18.3
-2,2,17:18.3
-1,2,17:18.3
0,2,17:17
1,2,17:17
2,2,17:18.3
-9,3,17:18.3
-8,3,17:18.3
-7,3,17:18.3
-6,3,17:18.3
-5,3,17:18.3
-4,3,17:18.3
-3,3,17:18.3
-2,3,17:18.3
-1,3,17:18.3
0,3,17:18.3
1,3,17:17
2,3,17:18.3
-6,4,17:18.3
-5,4,17:18.3
0,4,17:18.3
1,4,17:17
2,4,17:18.3
3,4,17:18.3
0,5,17:18.3
1,5,17:17
2,5,17:17.0
3,5,17:18.3
4,5,17:18.3
0,6,17:18.3
1,6,17:18.3
2,6,17:17.0
3,6,17:18.3
4,6,17:18.3
0,7,17:18.3
1,7,17:18.3
2,7,17:17
3,7,17:17.0
4,7,17:18.3
1,8,17:18.3
2,8,17:18.3
3,8,17:17.0
4,8,17:18.3
5,8,17:18.3
2,9,17:18.3
3,9,17:18.3
5,9,17:18.3
3,10,17:18.3
4,10,17:18.3
5,10,17:18.3
4,11,17:18.3
5,11,17:18.3
3,-7,18:18.3
4,-7,18:18.3
5,-7,18:18.3
2,-6,18:18.3
3,-6,18:18.3
4,-6,18:18.3
5,-6,18:18.3
2,-5,18:18.3
3,-5,18:18.3
4,-5,18:17
5,-5,18:18.3
1,-4,18:18.3
2,-4,18:18.3
3,-4,18:17.0
4,-4,18:18.3
5,-4,18:18.3
6,-4,18:18.3
-5,-3,18:18.3
1,-3,18:18.3
2,-3,18:17
3,-3,18:18.3
4,-3,18:18.3
5,-3,18:18.3
6,-3,18:18.3
-8,-2,18:18.3
-7,-2,18:18.3
-6,-2,18:18.3
-5,-2,18:18.3
-4,-2,18:18.3
0,-2,18:18.3
1,-2,18:18.3
2,-2,18:17
3,-2,18:18.3
5,-2,18:18.3
-10,-1,18:18.3
-7,-1,18:18.3
-6,-1,18:18.3
-5,-1,18:18.3
-4,-1,18:18.3
-3,-1,18:18.3
-2,-1,18:18.3
-1,-1,18:18.3
0,-1,18:18.3
1,-1,18:17
2,-1,18:18.3
3,-1,18:18.3
4,-1,18:18.3
-10,0,18:18.3
-9,0,18:18.3
-8,0,18:18.3
-7,0,18:18.3
-6,0,18:17
-5,0,18:17
-4,0,18:17
-3,0,18:17
-2,0,18:18.3
-1,0,18:18.3
0,0,18:18.3
1,0,18:18.3
2,0,18:18.3
-12,1,18:18.3
-11,1,18:18.3
-10,1,18:18.3
-9,1,18:18.3
-8,1,18:18.3
-7,1,18:17
-6,1,18:17
-5,1,18:18.3
-4,1,18:18.3
-3,1,18:17
-2,1,18:17
-1,1,18:17
0,1,18:17.0
1,1,18:18.3
-12,2,18:18.3
-11,2,18:18.3
-10,2,18:18.3
-9,2,18:18.3
-8,2,18:18.3
-7,2,18:18.3
-6,2,18:18.3
-5,2,18:18.3
-4,2,18:18.3
-3,2,18:18.3
-2,2,18:18.3
-1,2,18:18.3
0,2,18:18.3
1,2,18:18.3
-8,3,18:18.3
-7,3,18:18.3
-6,3,18:18.3
-5,3,18:18.3
-4,3,18:18.3
-3,3,18:18.3
-2,3,18:18.3
-1,3,18:18.3
0,3,18:18.3
1,3,18:18.3
2,3,18:18.3
-5,4,18:18.3
0,4,18:18.3
1,4,18:18.3
2,4,18:18.3
3,4,18:18.3
0,5,18:18.3
1,5,18:18.3
2,5,18:18.3
3,5,18:18.3
4,5,18:18.3
0,6,18:18.3
1,6,18:18.3
2,6,18:18.3
3,6,18:18.3
2,7,18:18.3
3,7,18:18.3
4,7,18:18.3
2,8,18:18.3
3,8,18:18.3
4,8,18:18.3
3,9,18:18.3
4,9,18:18.3
5,9,18:18.3
4,10,18:18.3
5,10,18:18.3
5,-7,19:18.3
6,-7,19:18.3
3,-6,19:18.3
4,-6,19:18.3
5,-6,19:18.3
2,-5,19:18.3
3,-5,19:18.3
4,-5,19:18.3
7,-5,19:18.3
2,-4,19:18.3
3,-4,19:18.3
4,-4,19:18.3
6,-4,19:18.3
-5,-3,19:18.3
1,-3,19:18.3
2,-3,19:18.3
3,-3,19:18.3
5,-3,19:18.3
6,-3,19:18.3
-10,-2,19:18.3
-9,-2,19:18.3
-8,-2,19:18.3
-7,-2,19:18.3
-6,-2,19:18.3
-5,-2,19:18.3
-4,-2,19:18.3
-3,-2,19:18.3
1,-2,19:18.3
2,-2,19:18.3
5,-2,19:18.3
-10,-1,19:18.3
-9,-1,19:18.3
-6,-1,19:18.3
-5,-1,19:18.3
-4,-1,19:18.3
-3,-1,19:18.3
-2,-1,19:18.3
-1,-1,19:18.3
0,-1,19:18.3
1,-1,19:18.3
3,-1,19:18.3
4,-1,19:18.3
-10,0,19:18.3
-9,0,19:18.3
-8,0,19:18.3
-7,0,19:18.3
-6,0,19:18.3
-4,0,19:18.3
-3,0,19:18.3
-1,0,19:18.3
0,0,19:18.3
1,0,19:18.3
2,0,19:18.3
-10,1,19:18.3
-9,1,19:18.3
-8,1,19:18.3
-7,1,19:18.3
-5,1,19:18.3
-4,1,19:18.3
-2,1,19:18.3
-1,1,19:17.0
0,1,19:18.3
1,1,19:18.3
2,1,19:18.3
-8,2,19:18.3
-7,2,19:18.3
-6,2,19:18.3
-5,2,19:18.3
-4,2,19:18.3
-3,2,19:18.3
-2,2,19:18.3
-1,2,19:18.3
0,2,19:18.3
1,2,19:18.3
-7,3,19:18.3
-6,3,19:18.3
-5,3,19:18.3
-4,3,19:18.3
-3,3,19:18.3
-2,3,19:18.3
-1,3,19:18.3
2,3,19:18.3
3,3,19:18.3
0,4,19:18.3
3,4,19:18.3
4,4,19:18.3
0,5,19:18.3
2,5,19:18.3
4,5,19:18.3
0,6,19:18.3
3,6,19:18.3
4,6,19:18.3
0,7,19:18.3
3,7,19:18.3
5,-7,20:18.3
6,-7,20:18.3
3,-6,20:18.3
4,-6,20:18.3
5,-6,20:18.3
7,-6,20:18.3
2,-5,20:18.3
3,-5,20:18.3
6,-5,20:18.3
7,-5,20:18.3
2,-4,20:18.3
3,-4,20:18.3
6,-4,20:18.3
1,-3,20:18.3
2,-3,20:18.3
5,-3,20:18.3
6,-3,20:18.3
-10,-2,20:18.3
-9,-2,20:18.3
-8,-2,20:18.3
-7,-2,20:18.3
-6,-2,20:18.3
-5,-2,20:18.3
-4,-2,20:18.3
-3,-2,20:18.3
1,-2,20:18.3
5,-2,20:18.3
-11,-1,20:18.3
-10,-1,20:18.3
-9,-1,20:18.3
-8,-1,20:18.3
-6,-1,20:18.3
-3,-1,20:18.3
-2,-1,20:18.3
0,-1,20:18.3
3,-1,20:18.3
4,-1,20:18.3
-10,0,20:18.3
-9,0,20:18.3
-6,0,20:18.3
-5,0,20:18.3
-4,0,20:18.3
-3,0,20:18.3
-1,0,20:18.3
0,0,20:18.3
3,0,20:18.3
-8,1,20:18.3
-7,1,20:18.3
-6,1,20:18.3
-5,1,20:18.3
-4,1,20:18.3
-2,1,20:18.3
-1,1,20:17.0
0,1,20:18.3
1,1,20:18.3
2,1,20:18.3
-7,2,20:18.3
-6,2,20:18.3
-5,2,20:18.3
-4,2,20:18.3
-3,2,20:18.3
-2,2,20:18.3
2,3,20:18.3
3,3,20:18.3
0,4,20:18.3
3,4,20:18.3
4,4,20:18.3
0,5,20:18.3
4,5,20:18.3
0,6,20:18.3
4,6,20:18.3
0,7,20:18.3
1,7,20:18.3
4,7,20:18.3
7,-8,21:18.3
5,-7,21:18.3
6,-7,21:18.3
7,-7,21:18.3
4,-6,21:18.3
5,-6,21:18.3
7,-6,21:18.3
2,-5,21:18.3
3,-5,21:18.3
6,-5,21:18.3
7,-5,21:18.3
2,-4,21:18.3
4,-4,21:18.3
6,-4,21:18.3
1,-3,21:18.3
5,-3,21:18.3
6,-3,21:18.3
-9,-2,21:18.3
-8,-2,21:18.3
-7,-2,21:18.3
-6,-2,21:18.3
-5,-2,21:18.3
-4,-2,21:18.3
-3,-2,21:18.3
1,-2,21:18.3
5,-2,21:18.3
-10,-1,21:18.3
-9,-1,21:18.3
-8,-1,21:18.3
-6,-1,21:18.3
-3,-1,21:18.3
-2,-1,21:18.3
0,-1,21:18.3
3,-1,21:18.3
4,-1,21:18.3
-9,0,21:18.3
-8,0,21:18.3
-5,0,21:18.3
-4,0,21:18.3
-1,0,21:18.3
0,0,21:17.0
2,0,21:18.3
3,0,21:18.3
-8,1,21:18.3
-7,1,21:18.3
-6,1,21:17
-5,1,21:18.3
-4,1,21:18.3
-3,1,21:18.3
-2,1,21:17
-1,1,21:17.0
0,1,21:17.0
-7,2,21:18.3
-6,2,21:18.3
-5,2,21:18.3
-4,2,21:18.3
-3,2,21:18.3
-2,2,21:18.3
2,2,21:18.3
0,3,21:18.3
2,3,21:18.3
3,3,21:18.3
0,4,21:18.3
3,4,21:18.3
4,4,21:18.3
0,5,21:18.3
4,5,21:18.3
0,6,21:18.3
4,6,21:18.3
0,7,21:18.3
1,7,21:18.3
4,7,21:18.3
1,8,21:18.3
2,8,21:18.3
7,-8,22:18.3
8,-8,22:18.3
6,-7,22:18.3
7,-7,22:18.3
8,-7,22:18.3
4,-6,22:18.3
5,-6,22:18.3
6,-6,22:17
7,-6,22:18.3
2,-5,22:18.3
3,-5,22:18.3
4,-5,22:18.3
5,-5,22:17.0
6,-5,22:18.3
7,-5,22:18.3
2,-4,22:18.3
4,-4,22:18.3
6,-4,22:18.3
1,-3,22:18.3
5,-3,22:18.3
6,-3,22:18.3
-8,-2,22:18.3
-7,-2,22:18.3
-6,-2,22:18.3
-5,-2,22:18.3
-4,-2,22:18.3
-3,-2,22:18.3
1,-2,22:18.3
5,-2,22:18.3
-9,-1,22:18.3
-8,-1,22:18.3
-7,-1,22:17.0
-6,-1,22:18.3
-5,-1,22:18.3
-3,-1,22:18.3
-2,-1,22:18.3
0,-1,22:18.3
3,-1,22:18.3
4,-1,22:18.3
5,-1,22:18.3
-9,0,22:18.3
-8,0,22:18.3
-6,0,22:17
-4,0,22:18.3
-3,0,22:18.3
-1,0,22:18.3
0,0,22:18.3
2,0,22:18.3
3,0,22:18.3
-8,1,22:18.3
-7,1,22:18.3
-5,1,22:17
-4,1,22:17
-3,1,22:17.0
-2,1,22:18.3
-1,1,22:17.0
0,1,22:17.0
1,1,22:18.3
-6,2,22:18.3
-5,2,22:18.3
-4,2,22:18.3
-3,2,22:18.3
-2,2,22:18.3
-1,2,22:18.3
0,2,22:17
1,2,22:18.3
2,2,22:18.3
-1,3,22:18.3
0,3,22:18.3
2,3,22:18.3
3,3,22:18.3
-1,4,22:18.3
0,4,22:18.3
3,4,22:18.3
4,4,22:18.3
0,5,22:18.3
4,5,22:18.3
0,6,22:18.3
3,6,22:18.3
4,6,22:18.3
0,7,22:18.3
1,7,22:18.3
4,7,22:18.3
1,8,22:18.3
2,8,22:18.3
4,8,22:18.3
2,9,22:18.3
6,-7,23:18.3
7,-7,23:18.3
5,-6,23:18.3
6,-6,23:18.3
7,-6,23:18.3
3,-5,23:18.3
4,-5,23:18.3
5,-5,23:18.3
6,-5,23:18.3
7,-5,23:18.3
2,-4,23:18.3
3,-4,23:18.3
4,-4,23:18.3
5,-4,23:17.0
6,-4,23:18.3
1,-3,23:18.3
2,-3,23:18.3
3,-3,23:17.0
4,-3,23:17.0
5,-3,23:18.3
6,-3,23:18.3
-6,-2,23:18.3
-5,-2,23:18.3
-4,-2,23:18.3
0,-2,23:18.3
1,-2,23:18.3
2,-2,23:17
3,-2,23:17
4,-2,23:18.3
5,-2,23:18.3
-8,-1,23:18.3
-7,-1,23:18.3
-6,-1,23:18.3
-5,-1,23:18.3
-4,-1,23:18.3
-3,-1,23:18.3
-2,-1,23:18.3
-1,-1,23:18.3
0,-1,23:18.3
1,-1,23:17
3,-1,23:18.3
4,-1,23:18.3
-8,0,23:18.3
-7,0,23:18.3
-6,0,23:18.3
-4,0,23:18.3
-3,0,23:18.3
-2,0,23:18.3
-1,0,23:18.3
0,0,23:18.3
1,0,23:17
2,0,23:18.3
3,0,23:18.3
-7,1,23:18.3
-6,1,23:18.3
-5,1,23:18.3
-4,1,23:18.3
-3,1,23:18.3
-2,1,23:18.3
-1,1,23:18.3
0,1,23:17.0
1,1,23:18.3
-6,2,23:18.3
-5,2,23:18.3
-4,2,23:18.3
-3,2,23:18.3
-2,2,23:18.3
-1,2,23:18.3
0,2,23:18.3
1,2,23:18.3
2,2,23:18.3
-1,3,23:18.3
0,3,23:18.3
2,3,23:18.3
3,3,23:18.3
-1,4,23:18.3
0,4,23:18.3
3,4,23:18.3
0,5,23:18.3
2,5,23:18.3
4,5,23:18.3
0,6,23:18.3
1,6,23:18.3
3,6,23:18.3
4,6,23:18.3
1,7,23:18.3
2,7,23:18.3
4,7,23:18.3
1,8,23:18.3
2,8,23:18.3
4,8,23:18.3
2,9,23:18.3
3,9,23:18.3
4,9,23:18.3
6,-6,24:18.3
4,-5,24:18.3
5,-5,24:18.3
6,-5,24:18.3
3,-4,24:18.3
4,-4,24:18.3
5,-4,24:18.3
1,-3,24:18.3
2,-3,24:18.3
3,-3,24:18.3
4,-3,24:18.3
5,-3,24:18.3
0,-2,24:18.3
1,-2,24:18.3
2,-2,24:18.3
3,-2,24:18.3
4,-2,24:18.3
-7,-1,24:18.3
-6,-1,24:18.3
-5,-1,24:18.3
-4,-1,24:18.3
-3,-1,24:18.3
-2,-1,24:18.3
0,-1,24:18.3
1,-1,24:18.3
2,-1,24:18.3
3,-1,24:18.3
-7,0,24:18.3
-6,0,24:18.3
-5,0,24:18.3
-4,0,24:18.3
-3,0,24:18.3
-2,0,24:18.3
-1,0,24:18.3
0,0,24:18.3
1,0,24:18.3
2,0,24:18.3
3,0,24:18.3
-6,1,24:18.3
-5,1,24:18.3
-4,1,24:18.3
-3,1,24:18.3
-2,1,24:18.3
-1,1,24:18.3
0,1,24:17.0
1,1,24:18.3
2,1,24:18.3
-3,2,24:18.3
-2,2,24:18.3
-1,2,24:18.3
0,2,24:18.3
1,2,24:18.3
2,2,24:18.3
-1,3,24:18.3
0,3,24:18.3
2,3,24:18.3
3,3,24:18.3
-1,4,24:18.3
0,4,24:18.3
3,4,24:18.3
0,5,24:18.3
2,5,24:18.3
3,5,24:18.3
4,5,24:18.3
0,6,24:18.3
1,6,24:18.3
3,6,24:18.3
4,6,24:18.3
1,7,24:18.3
2,7,24:18.3
3,7,24:17.0
4,7,24:18.3
1,8,24:18.3
2,8,24:18.3
3,8,24:17
4,8,24:18.3
2,9,24:18.3
3,9,24:18.3
4,9,24:18.3
3,10,24:18.3
4,10,24:18.3
1,-3,25:18.3
0,-2,25:18.3
1,-2,25:18.3
2,-2,25:18.3
-6,-1,25:18.3
-5,-1,25:18.3
-4,-1,25:18.3
0,-1,25:18.3
2,-1,25:18.3
-6,0,25:18.3
-4,0,25:18.3
-3,0,25:18.3
-2,0,25:18.3
-1,0,25:18.3
0,0,25:18.3
1,0,25:18.3
-5,1,25:18.3
-4,1,25:18.3
-3,1,25:18.3
-2,1,25:18.3
-1,1,25:18.3
0,1,25:17
1,1,25:18.3
2,1,25:18.3
-3,2,25:18.3
-2,2,25:18.3
-1,2,25:18.3
0,2,25:18.3
1,2,25:18.3
2,2,25:18.3
-1,3,25:18.3
0,3,25:18.3
2,3,25:18.3
3,3,25:18.3
-1,4,25:18.3
0,4,25:18.3
2,4,25:18.3
3,4,25:18.3
0,5,25:18.3
1,5,25:17
2,5,25:18.3
3,5,25:18.3
0,6,25:18.3
1,6,25:18.3
2,6,25:17
3,6,25:18.3
1,7,25:18.3
2,7,25:18.3
3,7,25:18.3
2,8,25:18.3
3,8,25:18.3
4,8,25:18.3
3,9,25:18.3
4,9,25:18.3
4,10,25:18.3
2,-4,26:18.3
1,-3,26:18.3
2,-3,26:18.3
1,-2,26:18.3
2,-2,26:18.3
-1,-1,26:18.3
0,-1,26:18.3
1,-1,26:18.3
2,-1,26:18.3
-3,0,26:18.3
-1,0,26:18.3
0,0,26:18.3
1,0,26:18.3
-1,1,26:18.3
0,1,26:17.0
1,1,26:18.3
-3,2,26:18.3
-1,2,26:18.3
0,2,26:18.3
1,2,26:17
0,3,26:18.3
1,3,26:17
2,3,26:18.3
3,3,26:18.3
0,4,26:18.3
1,4,26:17
2,4,26:18.3
3,4,26:18.3
0,5,26:18.3
1,5,26:18.3
2,5,26:18.3
3,5,26:18.3
1,6,26:18.3
2,6,26:18.3
3,6,26:18.3
2,7,26:18.3
3,7,26:18.3
2,8,26:18.3
3,8,26:18.3
2,-4,27:18.3
1,-3,27:18.3
2,-3,27:18.3
1,-2,27:18.3
2,-2,27:18.3
0,-1,27:18.3
1,-1,27:18.3
-3,0,27:18.3
-1,0,27:18.3
0,0,27:18.3
1,0,27:18.3
-1,1,27:17.0
0,1,27:18.3
-4,2,27:18.3
-3,2,27:18.3
-2,2,27:18.3
2,2,27:18.3
0,3,27:18.3
1,3,27:18.3
2,3,27:18.3
0,4,27:18.3
1,4,27:18.3
2,4,27:18.3
3,4,27:18.3
1,5,27:18.3
2,5,27:18.3
3,5,27:18.3
1,6,27:18.3
2,6,27:18.3
2,7,27:18.3
