[META]
version=2.0
spawnOnBlockType=10,11,87
spawnSunlight=True
spawnDarkness=True
spawnWater=False
spawnLava=False
underFill=True
randomRotation=True
dig=True
tree=False
branch=False
needsFoundation=True
rarity=30
collisionPercentage=12
spawnElevationMin=0
spawnElevationMax=200
spawnInBiome=Nethers,NethersCave,NethersMedium
[DATA]
0,1,0:49
-2,2,0:49
-1,2,0:49
0,2,0:49
1,2,0:49
2,2,0:49
-2,3,0:49
-1,3,0:49
0,3,0:49
1,3,0:49
2,3,0:49
-3,4,0:49
-2,4,0:49
-1,4,0:49
0,4,0:49
1,4,0:49
2,4,0:49
3,4,0:49
-5,5,0:49
-4,5,0:49
-3,5,0:49
-2,5,0:49
-1,5,0:49
0,5,0:49
1,5,0:49
2,5,0:49
3,5,0:49
4,5,0:49
5,5,0:49
-5,6,0:49
-4,6,0:49
-3,6,0:49
-2,6,0:49
-1,6,0:49
0,6,0:49
1,6,0:49
2,6,0:49
3,6,0:49
4,6,0:49
5,6,0:49
-6,7,0:49
-5,7,0:49
-4,7,0:49
-3,7,0:49
-2,7,0:49
-1,7,0:49
0,7,0:49
1,7,0:49
2,7,0:49
3,7,0:49
4,7,0:49
5,7,0:49
6,7,0:49
-5,8,0:49
-4,8,0:49
-3,8,0:49
-2,8,0:49
-1,8,0:49
0,8,0:49
1,8,0:49
2,8,0:49
3,8,0:49
4,8,0:49
5,8,0:49
-5,9,0:49
-4,9,0:49
-3,9,0:49
-2,9,0:49
-1,9,0:49
0,9,0:49
1,9,0:49
2,9,0:49
3,9,0:49
4,9,0:49
5,9,0:49
-3,10,0:49
-2,10,0:49
-1,10,0:49
0,10,0:49
1,10,0:49
2,10,0:49
3,10,0:49
-2,11,0:49
-1,11,0:49
0,11,0:49
1,11,0:49
2,11,0:49
-2,12,0:49
-1,12,0:49
0,12,0:49
1,12,0:49
2,12,0:49
0,13,0:49
-2,2,1:49
-1,2,1:49
0,2,1:49
1,2,1:49
2,2,1:49
-2,3,1:49
-1,3,1:49
0,3,1:49
1,3,1:49
2,3,1:49
-2,4,1:49
-1,4,1:49
0,4,1:49
1,4,1:49
2,4,1:49
-5,5,1:49
-4,5,1:49
-3,5,1:49
-2,5,1:49
-1,5,1:49
0,5,1:49
1,5,1:49
2,5,1:49
3,5,1:49
4,5,1:49
5,5,1:49
-5,6,1:49
-4,6,1:49
-3,6,1:49
-2,6,1:49
-1,6,1:49
0,6,1:49
1,6,1:49
2,6,1:49
3,6,1:49
4,6,1:49
5,6,1:49
-5,7,1:49
-4,7,1:49
-3,7,1:49
-2,7,1:49
-1,7,1:49
0,7,1:49
1,7,1:49
2,7,1:49
3,7,1:49
4,7,1:49
5,7,1:49
-5,8,1:49
-4,8,1:49
-3,8,1:49
-2,8,1:49
-1,8,1:49
0,8,1:49
1,8,1:49
2,8,1:49
3,8,1:49
4,8,1:49
5,8,1:49
-5,9,1:49
-4,9,1:49
-3,9,1:49
-2,9,1:49
-1,9,1:49
0,9,1:49
1,9,1:49
2,9,1:49
3,9,1:49
4,9,1:49
5,9,1:49
-2,10,1:49
-1,10,1:49
0,10,1:49
1,10,1:49
2,10,1:49
-2,11,1:49
-1,11,1:49
0,11,1:49
1,11,1:49
2,11,1:49
-2,12,1:49
-1,12,1:49
0,12,1:49
1,12,1:49
2,12,1:49
-1,2,2:49
0,2,2:49
1,2,2:49
-2,3,2:49
-1,3,2:49
0,3,2:49
1,3,2:49
2,3,2:49
-2,4,2:49
-1,4,2:49
0,4,2:49
1,4,2:49
2,4,2:49
-4,5,2:49
-3,5,2:49
-2,5,2:49
-1,5,2:49
0,5,2:49
1,5,2:49
2,5,2:49
3,5,2:49
4,5,2:49
-5,6,2:49
-4,6,2:49
-3,6,2:49
-2,6,2:49
-1,6,2:49
0,6,2:49
1,6,2:49
2,6,2:49
3,6,2:49
4,6,2:49
5,6,2:49
-5,7,2:49
-4,7,2:49
-3,7,2:49
-2,7,2:49
-1,7,2:49
0,7,2:49
1,7,2:49
2,7,2:49
3,7,2:49
4,7,2:49
5,7,2:49
-5,8,2:49
-4,8,2:49
-3,8,2:49
-2,8,2:49
-1,8,2:49
0,8,2:49
1,8,2:49
2,8,2:49
3,8,2:49
4,8,2:49
5,8,2:49
-4,9,2:49
-3,9,2:49
-2,9,2:49
-1,9,2:49
0,9,2:49
1,9,2:49
2,9,2:49
3,9,2:49
4,9,2:49
-2,10,2:49
-1,10,2:49
0,10,2:49
1,10,2:49
2,10,2:49
-2,11,2:49
-1,11,2:49
0,11,2:49
1,11,2:49
2,11,2:49
-1,12,2:49
0,12,2:49
1,12,2:49
0,4,3:49
1,4,3:49
2,4,3:49
-2,5,3:49
-1,5,3:49
0,5,3:49
1,5,3:49
2,5,3:49
3,5,3:49
-2,6,3:49
-1,6,3:49
0,6,3:49
1,6,3:49
2,6,3:49
3,6,3:49
-3,7,3:49
-2,7,3:49
-1,7,3:49
0,7,3:49
1,7,3:49
2,7,3:49
3,7,3:49
-2,8,3:49
-1,8,3:49
0,8,3:49
1,8,3:49
2,8,3:49
-2,9,3:49
-1,9,3:49
0,9,3:49
1,9,3:49
2,9,3:49
0,10,3:49
-1,4,4:49
0,4,4:49
1,4,4:49
2,4,4:49
3,4,4:49
-2,5,4:49
-1,5,4:49
0,5,4:49
1,5,4:49
2,5,4:49
3,5,4:49
-2,6,4:49
-1,6,4:49
0,6,4:49
1,6,4:49
2,6,4:49
3,6,4:49
-2,7,4:49
-1,7,4:49
0,7,4:49
1,7,4:49
2,7,4:49
3,7,4:49
-2,8,4:49
-1,8,4:49
0,8,4:49
1,8,4:49
2,8,4:49
3,8,4:49
-2,9,4:49
-1,9,4:49
0,9,4:49
1,9,4:49
2,9,4:49
1,3,5:49
2,3,5:49
3,3,5:49
-1,4,5:49
0,4,5:49
1,4,5:49
2,4,5:49
3,4,5:49
4,4,5:49
-1,5,5:49
0,5,5:49
1,5,5:49
2,5,5:49
3,5,5:49
4,5,5:49
-2,6,5:49
-1,6,5:49
0,6,5:49
1,6,5:49
2,6,5:49
3,6,5:49
4,6,5:49
-2,7,5:49
-1,7,5:49
0,7,5:49
1,7,5:49
2,7,5:49
3,7,5:49
-2,8,5:49
-1,8,5:49
0,8,5:49
1,8,5:49
2,8,5:49
3,8,5:49
-1,9,5:49
0,9,5:49
1,9,5:49
0,3,6:49
1,3,6:49
2,3,6:49
3,3,6:49
4,3,6:49
-1,4,6:49
0,4,6:49
1,4,6:49
2,4,6:49
3,4,6:49
4,4,6:49
-1,5,6:49
0,5,6:49
1,5,6:49
2,5,6:49
3,5,6:49
4,5,6:49
-1,6,6:49
0,6,6:49
1,6,6:49
2,6,6:49
3,6,6:49
4,6,6:49
-1,7,6:49
0,7,6:49
1,7,6:49
2,7,6:49
3,7,6:49
4,7,6:49
-1,8,6:49
0,8,6:49
1,8,6:49
2,8,6:49
3,8,6:49
2,2,7:49
3,2,7:49
4,2,7:49
5,2,7:49
0,3,7:49
1,3,7:49
2,3,7:49
3,3,7:49
4,3,7:49
5,3,7:49
6,3,7:49
0,4,7:49
1,4,7:49
2,4,7:49
3,4,7:49
4,4,7:49
5,4,7:49
6,4,7:49
-1,5,7:49
0,5,7:49
1,5,7:49
2,5,7:49
3,5,7:49
4,5,7:49
5,5,7:49
6,5,7:49
-1,6,7:49
0,6,7:49
1,6,7:49
2,6,7:49
3,6,7:49
4,6,7:49
5,6,7:49
-1,7,7:49
0,7,7:49
1,7,7:49
2,7,7:49
3,7,7:49
4,7,7:49
0,8,7:49
1,8,7:49
2,8,7:49
2,2,8:49
3,2,8:49
4,2,8:49
5,2,8:49
6,2,8:49
0,3,8:49
1,3,8:49
2,3,8:49
3,3,8:49
4,3,8:49
5,3,8:49
6,3,8:49
0,4,8:49
1,4,8:49
2,4,8:49
3,4,8:49
4,4,8:49
5,4,8:49
6,4,8:49
0,5,8:49
1,5,8:49
2,5,8:49
3,5,8:49
4,5,8:49
5,5,8:49
6,5,8:49
0,6,8:49
1,6,8:49
2,6,8:49
3,6,8:49
4,6,8:49
5,6,8:49
6,6,8:49
0,7,8:49
1,7,8:49
2,7,8:49
3,7,8:49
4,7,8:49
3,1,9:49
4,1,9:49
5,1,9:49
2,2,9:49
3,2,9:49
4,2,9:49
5,2,9:49
6,2,9:49
1,3,9:49
2,3,9:49
3,3,9:49
4,3,9:49
5,3,9:49
6,3,9:49
0,4,9:49
1,4,9:49
2,4,9:49
3,4,9:49
4,4,9:49
5,4,9:49
6,4,9:49
7,4,9:49
0,5,9:49
1,5,9:49
2,5,9:49
3,5,9:49
4,5,9:49
5,5,9:49
6,5,9:49
0,6,9:49
1,6,9:49
2,6,9:49
3,6,9:49
4,6,9:49
5,6,9:49
6,6,9:49
1,7,9:49
2,7,9:49
3,7,9:49
4,7,9:49
2,1,10:49
3,1,10:49
4,1,10:49
5,1,10:49
6,1,10:49
2,2,10:49
3,2,10:49
4,2,10:49
5,2,10:49
6,2,10:49
2,3,10:49
3,3,10:49
4,3,10:49
5,3,10:49
6,3,10:49
2,4,10:49
3,4,10:49
4,4,10:49
5,4,10:49
6,4,10:49
2,5,10:49
3,5,10:49
4,5,10:49
5,5,10:49
6,5,10:49
2,6,10:49
3,6,10:49
4,6,10:49
5,6,10:49
6,6,10:49
3,0,11:49
4,0,11:49
5,0,11:49
2,1,11:49
3,1,11:49
4,1,11:49
5,1,11:49
6,1,11:49
2,2,11:49
3,2,11:49
4,2,11:49
5,2,11:49
6,2,11:49
1,3,11:49
2,3,11:49
3,3,11:49
4,3,11:49
5,3,11:49
6,3,11:49
7,3,11:49
2,4,11:49
3,4,11:49
4,4,11:49
5,4,11:49
6,4,11:49
2,5,11:49
3,5,11:49
4,5,11:49
5,5,11:49
6,5,11:49
3,6,11:49
4,6,11:49
5,6,11:49
2,0,12:49
3,0,12:49
4,0,12:49
5,0,12:49
6,0,12:49
2,1,12:49
3,1,12:49
4,1,12:49
5,1,12:49
6,1,12:49
2,2,12:49
3,2,12:49
4,2,12:49
5,2,12:49
6,2,12:49
2,3,12:49
3,3,12:49
4,3,12:49
5,3,12:49
6,3,12:49
2,4,12:49
3,4,12:49
4,4,12:49
5,4,12:49
6,4,12:49
2,5,12:49
3,5,12:49
4,5,12:49
5,5,12:49
6,5,12:49
4,-1,13:49
2,0,13:49
3,0,13:49
4,0,13:49
5,0,13:49
6,0,13:49
1,1,13:49
2,1,13:49
3,1,13:49
4,1,13:49
5,1,13:49
6,1,13:49
1,2,13:49
2,2,13:49
3,2,13:49
4,2,13:49
5,2,13:49
6,2,13:49
7,2,13:49
1,3,13:49
2,3,13:49
3,3,13:49
4,3,13:49
5,3,13:49
6,3,13:49
2,4,13:49
3,4,13:49
4,4,13:49
5,4,13:49
6,4,13:49
3,5,13:49
4,5,13:49
5,5,13:49
1,0,14:49
2,0,14:49
3,0,14:49
4,0,14:49
5,0,14:49
6,0,14:49
1,1,14:49
2,1,14:49
3,1,14:49
4,1,14:49
5,1,14:49
6,1,14:49
1,2,14:49
2,2,14:49
3,2,14:49
4,2,14:49
5,2,14:49
6,2,14:49
1,3,14:49
2,3,14:49
3,3,14:49
4,3,14:49
5,3,14:49
6,3,14:49
1,4,14:49
2,4,14:49
3,4,14:49
4,4,14:49
5,4,14:49
6,4,14:49
2,-1,15:49
3,-1,15:49
4,-1,15:49
1,0,15:49
2,0,15:49
3,0,15:49
4,0,15:49
5,0,15:49
1,1,15:49
2,1,15:49
3,1,15:49
4,1,15:49
5,1,15:49
6,1,15:49
0,2,15:49
1,2,15:49
2,2,15:49
3,2,15:49
4,2,15:49
5,2,15:49
6,2,15:49
1,3,15:49
2,3,15:49
3,3,15:49
4,3,15:49
5,3,15:49
6,3,15:49
1,4,15:49
2,4,15:49
3,4,15:49
4,4,15:49
5,4,15:49
3,5,15:49
1,-1,16:49
2,-1,16:49
3,-1,16:49
4,-1,16:49
5,-1,16:49
1,0,16:49
2,0,16:49
3,0,16:49
4,0,16:49
5,0,16:49
1,1,16:49
2,1,16:49
3,1,16:49
4,1,16:49
5,1,16:49
1,2,16:49
2,2,16:49
3,2,16:49
4,2,16:49
5,2,16:49
1,3,16:49
2,3,16:49
3,3,16:49
4,3,16:49
5,3,16:49
1,4,16:49
2,4,16:49
3,4,16:49
4,4,16:49
5,4,16:49
1,-2,17:49
2,-2,17:49
3,-2,17:49
0,-1,17:49
1,-1,17:49
2,-1,17:49
3,-1,17:49
4,-1,17:49
5,-1,17:49
0,0,17:49
1,0,17:49
2,0,17:49
3,0,17:49
4,0,17:49
5,0,17:49
0,1,17:49
1,1,17:49
2,1,17:49
3,1,17:49
4,1,17:49
5,1,17:49
6,1,17:49
1,2,17:49
2,2,17:49
3,2,17:49
4,2,17:49
5,2,17:49
1,3,17:49
2,3,17:49
3,3,17:49
4,3,17:49
5,3,17:49
2,4,17:49
3,4,17:49
4,4,17:49
0,-2,18:49
1,-2,18:49
2,-2,18:49
3,-2,18:49
4,-2,18:49
0,-1,18:49
1,-1,18:49
2,-1,18:49
3,-1,18:49
4,-1,18:49
5,-1,18:49
0,0,18:49
1,0,18:49
2,0,18:49
3,0,18:49
4,0,18:49
5,0,18:49
0,1,18:49
1,1,18:49
2,1,18:49
3,1,18:49
4,1,18:49
5,1,18:49
0,2,18:49
1,2,18:49
2,2,18:49
3,2,18:49
4,2,18:49
5,2,18:49
1,3,18:49
2,3,18:49
3,3,18:49
4,3,18:49
5,3,18:49
2,-3,19:49
0,-2,19:49
1,-2,19:49
2,-2,19:49
3,-2,19:49
4,-2,19:49
-1,-1,19:49
0,-1,19:49
1,-1,19:49
2,-1,19:49
3,-1,19:49
4,-1,19:49
-1,0,19:49
0,0,19:49
1,0,19:49
2,0,19:49
3,0,19:49
4,0,19:49
5,0,19:49
-1,1,19:49
0,1,19:49
1,1,19:49
2,1,19:49
3,1,19:49
4,1,19:49
5,1,19:49
0,2,19:49
1,2,19:49
2,2,19:49
3,2,19:49
4,2,19:49
5,2,19:49
2,3,19:49
3,3,19:49
4,3,19:49
-1,-2,20:49
0,-2,20:49
1,-2,20:49
2,-2,20:49
3,-2,20:49
4,-2,20:49
-1,-1,20:49
0,-1,20:49
1,-1,20:49
2,-1,20:49
3,-1,20:49
4,-1,20:49
-1,0,20:49
0,0,20:49
1,0,20:49
2,0,20:49
3,0,20:49
4,0,20:49
-1,1,20:49
0,1,20:49
1,1,20:49
2,1,20:49
3,1,20:49
4,1,20:49
-1,2,20:49
0,2,20:49
1,2,20:49
2,2,20:49
3,2,20:49
4,2,20:49
1,-3,21:49
-1,-2,21:49
0,-2,21:49
1,-2,21:49
2,-2,21:49
3,-2,21:49
-2,-1,21:49
-1,-1,21:49
0,-1,21:49
1,-1,21:49
2,-1,21:49
3,-1,21:49
4,-1,21:49
-3,0,21:49
-2,0,21:49
-1,0,21:49
0,0,21:49
1,0,21:49
2,0,21:49
3,0,21:49
4,0,21:49
-3,1,21:49
-2,1,21:49
-1,1,21:49
0,1,21:49
1,1,21:49
2,1,21:49
3,1,21:49
4,1,21:49
-3,2,21:49
-2,2,21:49
-1,2,21:49
0,2,21:49
1,2,21:49
2,2,21:49
3,2,21:49
-2,3,21:49
-1,3,21:49
0,3,21:49
1,3,21:49
-1,-2,22:49
0,-2,22:49
1,-2,22:49
2,-2,22:49
3,-2,22:49
-3,-1,22:49
-2,-1,22:49
-1,-1,22:49
0,-1,22:49
1,-1,22:49
2,-1,22:49
3,-1,22:49
-3,0,22:49
-2,0,22:49
-1,0,22:49
0,0,22:49
1,0,22:49
2,0,22:49
3,0,22:49
-3,1,22:49
-2,1,22:49
-1,1,22:49
0,1,22:49
1,1,22:49
2,1,22:49
3,1,22:49
-3,2,22:49
-2,2,22:49
-1,2,22:49
0,2,22:49
1,2,22:49
2,2,22:49
3,2,22:49
-3,3,22:49
-2,3,22:49
-1,3,22:49
0,3,22:49
1,3,22:49
-1,-2,23:49
0,-2,23:49
1,-2,23:49
2,-2,23:49
-3,-1,23:49
-2,-1,23:49
-1,-1,23:49
0,-1,23:49
1,-1,23:49
2,-1,23:49
3,-1,23:49
-4,0,23:49
-3,0,23:49
-2,0,23:49
-1,0,23:49
0,0,23:49
1,0,23:49
2,0,23:49
3,0,23:49
-5,1,23:49
-4,1,23:49
-3,1,23:49
-2,1,23:49
-1,1,23:49
0,1,23:49
1,1,23:49
2,1,23:49
3,1,23:49
-5,2,23:49
-4,2,23:49
-3,2,23:49
-2,2,23:49
-1,2,23:49
0,2,23:49
1,2,23:49
2,2,23:49
-5,3,23:49
-4,3,23:49
-3,3,23:49
-2,3,23:49
-1,3,23:49
0,3,23:49
1,3,23:49
-4,4,23:49
-3,4,23:49
-2,4,23:49
-1,4,23:49
-3,-1,24:49
-2,-1,24:49
-1,-1,24:49
0,-1,24:49
1,-1,24:49
-5,0,24:49
-4,0,24:49
-3,0,24:49
-2,0,24:49
-1,0,24:49
0,0,24:49
1,0,24:49
-5,1,24:49
-4,1,24:49
-3,1,24:49
-2,1,24:49
-1,1,24:49
0,1,24:49
1,1,24:49
-5,2,24:49
-4,2,24:49
-3,2,24:49
-2,2,24:49
-1,2,24:49
0,2,24:49
1,2,24:49
-5,3,24:49
-4,3,24:49
-3,3,24:49
-2,3,24:49
-1,3,24:49
0,3,24:49
1,3,24:49
-5,4,24:49
-4,4,24:49
-3,4,24:49
-2,4,24:49
-1,4,24:49
-3,-1,25:49
-2,-1,25:49
-1,-1,25:49
0,-1,25:49
-6,0,25:49
-5,0,25:49
-4,0,25:49
-3,0,25:49
-2,0,25:49
-1,0,25:49
0,0,25:49
1,0,25:49
-7,1,25:49
-6,1,25:49
-5,1,25:49
-4,1,25:49
-3,1,25:49
-2,1,25:49
-1,1,25:49
0,1,25:49
1,1,25:49
-7,2,25:49
-6,2,25:49
-5,2,25:49
-4,2,25:49
-3,2,25:49
-2,2,25:49
-1,2,25:49
0,2,25:49
1,2,25:49
-7,3,25:49
-6,3,25:49
-5,3,25:49
-4,3,25:49
-3,3,25:49
-2,3,25:49
-1,3,25:49
0,3,25:49
-6,4,25:49
-5,4,25:49
-4,4,25:49
-3,4,25:49
-2,4,25:49
-1,4,25:49
-3,5,25:49
-7,0,26:49
-6,0,26:49
-5,0,26:49
-4,0,26:49
-3,0,26:49
-2,0,26:49
-1,0,26:49
-7,1,26:49
-6,1,26:49
-5,1,26:49
-4,1,26:49
-3,1,26:49
-2,1,26:49
-1,1,26:49
-7,2,26:49
-6,2,26:49
-5,2,26:49
-4,2,26:49
-3,2,26:49
-2,2,26:49
-1,2,26:49
-7,3,26:49
-6,3,26:49
-5,3,26:49
-4,3,26:49
-3,3,26:49
-2,3,26:49
-1,3,26:49
-7,4,26:49
-6,4,26:49
-5,4,26:49
-4,4,26:49
-3,4,26:49
-2,4,26:49
-1,4,26:49
-7,-1,27:49
-6,-1,27:49
-5,-1,27:49
-8,0,27:49
-7,0,27:49
-6,0,27:49
-5,0,27:49
-4,0,27:49
-3,0,27:49
-2,0,27:49
-8,1,27:49
-7,1,27:49
-6,1,27:49
-5,1,27:49
-4,1,27:49
-3,1,27:49
-2,1,27:49
-1,1,27:49
-8,2,27:49
-7,2,27:49
-6,2,27:49
-5,2,27:49
-4,2,27:49
-3,2,27:49
-2,2,27:49
-1,2,27:49
-7,3,27:49
-6,3,27:49
-5,3,27:49
-4,3,27:49
-3,3,27:49
-2,3,27:49
-1,3,27:49
-7,4,27:49
-6,4,27:49
-5,4,27:49
-4,4,27:49
-3,4,27:49
-2,4,27:49
-5,5,27:49
-8,-1,28:49
-7,-1,28:49
-6,-1,28:49
-5,-1,28:49
-4,-1,28:49
-8,0,28:49
-7,0,28:49
-6,0,28:49
-5,0,28:49
-4,0,28:49
-3,0,28:49
-8,1,28:49
-7,1,28:49
-6,1,28:49
-5,1,28:49
-4,1,28:49
-3,1,28:49
-8,2,28:49
-7,2,28:49
-6,2,28:49
-5,2,28:49
-4,2,28:49
-3,2,28:49
-8,3,28:49
-7,3,28:49
-6,3,28:49
-5,3,28:49
-4,3,28:49
-3,3,28:49
-7,4,28:49
-6,4,28:49
-5,4,28:49
-4,4,28:49
-3,4,28:49
-8,-3,29:49
-7,-3,29:49
-6,-3,29:49
-9,-2,29:49
-8,-2,29:49
-7,-2,29:49
-6,-2,29:49
-5,-2,29:49
-9,-1,29:49
-8,-1,29:49
-7,-1,29:49
-6,-1,29:49
-5,-1,29:49
-4,-1,29:49
-9,0,29:49
-8,0,29:49
-7,0,29:49
-6,0,29:49
-5,0,29:49
-4,0,29:49
-9,1,29:49
-8,1,29:49
-7,1,29:49
-6,1,29:49
-5,1,29:49
-4,1,29:49
-3,1,29:49
-8,2,29:49
-7,2,29:49
-6,2,29:49
-5,2,29:49
-4,2,29:49
-3,2,29:49
-8,3,29:49
-7,3,29:49
-6,3,29:49
-5,3,29:49
-4,3,29:49
-3,3,29:49
-6,4,29:49
-5,4,29:49
-4,4,29:49
-9,-3,30:49
-8,-3,30:49
-7,-3,30:49
-6,-3,30:49
-5,-3,30:49
-9,-2,30:49
-8,-2,30:49
-7,-2,30:49
-6,-2,30:49
-5,-2,30:49
-9,-1,30:49
-8,-1,30:49
-7,-1,30:49
-6,-1,30:49
-5,-1,30:49
-4,-1,30:49
-9,0,30:49
-8,0,30:49
-7,0,30:49
-6,0,30:49
-5,0,30:49
-4,0,30:49
-9,1,30:49
-8,1,30:49
-7,1,30:49
-6,1,30:49
-5,1,30:49
-4,1,30:49
-8,2,30:49
-7,2,30:49
-6,2,30:49
-5,2,30:49
-4,2,30:49
-8,3,30:49
-7,3,30:49
-6,3,30:49
-5,3,30:49
-4,3,30:49
-8,-5,31:49
-7,-5,31:49
-6,-5,31:49
-9,-4,31:49
-8,-4,31:49
-7,-4,31:49
-6,-4,31:49
-5,-4,31:49
-9,-3,31:49
-8,-3,31:49
-7,-3,31:49
-6,-3,31:49
-5,-3,31:49
-9,-2,31:49
-8,-2,31:49
-7,-2,31:49
-6,-2,31:49
-5,-2,31:49
-10,-1,31:49
-9,-1,31:49
-8,-1,31:49
-7,-1,31:49
-6,-1,31:49
-5,-1,31:49
-4,-1,31:49
-9,0,31:49
-8,0,31:49
-7,0,31:49
-6,0,31:49
-5,0,31:49
-4,0,31:49
-9,1,31:49
-8,1,31:49
-7,1,31:49
-6,1,31:49
-5,1,31:49
-4,1,31:49
-8,2,31:49
-7,2,31:49
-6,2,31:49
-5,2,31:49
-4,2,31:49
-7,3,31:49
-6,3,31:49
-5,3,31:49
-9,-5,32:49
-8,-5,32:49
-7,-5,32:49
-6,-5,32:49
-5,-5,32:49
-9,-4,32:49
-8,-4,32:49
-7,-4,32:49
-6,-4,32:49
-5,-4,32:49
-9,-3,32:49
-8,-3,32:49
-7,-3,32:49
-6,-3,32:49
-5,-3,32:49
-9,-2,32:49
-8,-2,32:49
-7,-2,32:49
-6,-2,32:49
-5,-2,32:49
-9,-1,32:49
-8,-1,32:49
-7,-1,32:49
-6,-1,32:49
-5,-1,32:49
-9,0,32:49
-8,0,32:49
-7,0,32:49
-6,0,32:49
-5,0,32:49
-9,1,32:49
-8,1,32:49
-7,1,32:49
-6,1,32:49
-5,1,32:49
-8,-6,33:49
-7,-6,33:49
-6,-6,33:49
-9,-5,33:49
-8,-5,33:49
-7,-5,33:49
-6,-5,33:49
-5,-5,33:49
-9,-4,33:49
-8,-4,33:49
-7,-4,33:49
-6,-4,33:49
-5,-4,33:49
-10,-3,33:49
-9,-3,33:49
-8,-3,33:49
-7,-3,33:49
-6,-3,33:49
-5,-3,33:49
-4,-3,33:49
-9,-2,33:49
-8,-2,33:49
-7,-2,33:49
-6,-2,33:49
-5,-2,33:49
-9,-1,33:49
-8,-1,33:49
-7,-1,33:49
-6,-1,33:49
-5,-1,33:49
-9,0,33:49
-8,0,33:49
-7,0,33:49
-6,0,33:49
-5,0,33:49
-8,1,33:49
-7,1,33:49
-6,1,33:49
-9,-6,34:49
-8,-6,34:49
-7,-6,34:49
-6,-6,34:49
-5,-6,34:49
-9,-5,34:49
-8,-5,34:49
-7,-5,34:49
-6,-5,34:49
-5,-5,34:49
-9,-4,34:49
-8,-4,34:49
-7,-4,34:49
-6,-4,34:49
-5,-4,34:49
-9,-3,34:49
-8,-3,34:49
-7,-3,34:49
-6,-3,34:49
-5,-3,34:49
-9,-2,34:49
-8,-2,34:49
-7,-2,34:49
-6,-2,34:49
-5,-2,34:49
-9,-1,34:49
-8,-1,34:49
-7,-1,34:49
-6,-1,34:49
-5,-1,34:49
-8,-7,35:49
-7,-7,35:49
-6,-7,35:49
-9,-6,35:49
-8,-6,35:49
-7,-6,35:49
-6,-6,35:49
-5,-6,35:49
-9,-5,35:49
-8,-5,35:49
-7,-5,35:49
-6,-5,35:49
-5,-5,35:49
-10,-4,35:49
-9,-4,35:49
-8,-4,35:49
-7,-4,35:49
-6,-4,35:49
-5,-4,35:49
-4,-4,35:49
-9,-3,35:49
-8,-3,35:49
-7,-3,35:49
-6,-3,35:49
-5,-3,35:49
-9,-2,35:49
-8,-2,35:49
-7,-2,35:49
-6,-2,35:49
-5,-2,35:49
-8,-1,35:49
-7,-1,35:49
-6,-1,35:49
-7,-8,36:49
-6,-8,36:49
-8,-7,36:49
-7,-7,36:49
-6,-7,36:49
-9,-6,36:49
-8,-6,36:49
-7,-6,36:49
-6,-6,36:49
-5,-6,36:49
-9,-5,36:49
-8,-5,36:49
-7,-5,36:49
-6,-5,36:49
-5,-5,36:49
-9,-4,36:49
-8,-4,36:49
-7,-4,36:49
-6,-4,36:49
-5,-4,36:49
-9,-3,36:49
-8,-3,36:49
-7,-3,36:49
-6,-3,36:49
-5,-3,36:49
-9,-2,36:49
-8,-2,36:49
-7,-2,36:49
-6,-2,36:49
-5,-2,36:49
-7,-8,37:49
-6,-8,37:49
-8,-7,37:49
-7,-7,37:49
-6,-7,37:49
-8,-6,37:49
-7,-6,37:49
-6,-6,37:49
-9,-5,37:49
-8,-5,37:49
-7,-5,37:49
-6,-5,37:49
-5,-5,37:49
-9,-4,37:49
-8,-4,37:49
-7,-4,37:49
-6,-4,37:49
-5,-4,37:49
-9,-3,37:49
-8,-3,37:49
-7,-3,37:49
-6,-3,37:49
-5,-3,37:49
-8,-2,37:49
-7,-2,37:49
-6,-2,37:49
-8,-9,38:49
-7,-9,38:49
-6,-9,38:49
-8,-8,38:49
-7,-8,38:49
-6,-8,38:49
-8,-7,38:49
-7,-7,38:49
-6,-7,38:49
-8,-6,38:49
-7,-6,38:49
-6,-6,38:49
-8,-5,38:49
-7,-5,38:49
-6,-5,38:49
-7,-4,38:49
-7,-10,39:49
-8,-9,39:49
-7,-9,39:49
-6,-9,39:49
-8,-8,39:49
-7,-8,39:49
-6,-8,39:49
-8,-7,39:49
-7,-7,39:49
-6,-7,39:49
-8,-6,39:49
-7,-6,39:49
-6,-6,39:49
-7,-5,39:49
-7,-10,40:49
-7,-9,40:49
-7,-8,40:49
-7,-9,41:49
