[META]
version=2.0
spawnOnBlockType=10,11,87
spawnSunlight=True
spawnDarkness=True
spawnWater=False
spawnLava=False
underFill=True
randomRotation=True
dig=True
tree=False
branch=False
needsFoundation=True
rarity=20
collisionPercentage=15
spawnElevationMin=0
spawnElevationMax=200
spawnInBiome=Nethers,NethersCave,NethersMedium
[DATA]
0,-12,0:49
3,-12,0:49
5,-12,0:49
6,-12,0:49
7,-12,0:49
-2,-11,0:49
-1,-11,0:49
0,-11,0:49
1,-11,0:49
2,-11,0:49
3,-11,0:49
4,-11,0:49
5,-11,0:49
6,-11,0:49
7,-11,0:49
8,-11,0:49
4,-12,1:49
5,-12,1:49
6,-12,1:49
7,-12,1:49
8,-12,1:49
-2,-11,1:49
-1,-11,1:49
0,-11,1:49
1,-11,1:49
2,-11,1:49
3,-11,1:49
4,-11,1:49
5,-11,1:49
6,-11,1:49
7,-11,1:49
8,-11,1:49
-2,-10,1:49
-1,-10,1:49
0,-10,1:49
1,-10,1:49
2,-10,1:49
3,-10,1:49
4,-10,1:49
5,-10,1:49
6,-10,1:49
7,-10,1:49
8,-10,1:49
-2,-9,1:49
-1,-9,1:49
0,-9,1:49
1,-9,1:49
2,-9,1:49
3,-9,1:49
4,-9,1:49
5,-9,1:49
6,-9,1:49
7,-9,1:49
8,-9,1:49
9,-9,1:49
10,-9,1:49
-2,-8,1:49
-1,-8,1:49
0,-8,1:49
1,-8,1:49
2,-8,1:49
3,-8,1:49
4,-8,1:49
5,-8,1:49
6,-8,1:49
7,-8,1:49
8,-8,1:49
9,-8,1:49
10,-8,1:49
-2,-7,1:49
-1,-7,1:49
0,-7,1:49
1,-7,1:49
2,-7,1:49
3,-7,1:49
4,-7,1:49
5,-7,1:49
6,-7,1:49
7,-7,1:49
8,-7,1:49
9,-7,1:49
10,-7,1:49
0,-6,1:49
1,-6,1:49
2,-6,1:49
3,-6,1:49
4,-6,1:49
5,-6,1:49
6,-6,1:49
7,-6,1:49
8,-6,1:49
9,-6,1:49
10,-6,1:49
1,-5,1:49
2,-5,1:49
3,-5,1:49
4,-5,1:49
5,-5,1:49
6,-5,1:49
7,-5,1:49
8,-5,1:49
9,-5,1:49
10,-5,1:49
1,-4,1:49
2,-4,1:49
3,-4,1:49
4,-4,1:49
5,-4,1:49
6,-4,1:49
7,-4,1:49
8,-4,1:49
9,-4,1:49
3,-3,1:49
5,-3,1:49
6,-3,1:49
7,-3,1:49
8,-3,1:49
9,-3,1:49
7,-2,1:49
6,-13,2:49
4,-12,2:49
5,-12,2:49
6,-12,2:49
7,-12,2:49
8,-12,2:49
-1,-11,2:49
0,-11,2:49
1,-11,2:49
2,-11,2:49
3,-11,2:49
4,-11,2:49
5,-11,2:49
6,-11,2:49
7,-11,2:49
8,-11,2:49
-2,-10,2:49
-1,-10,2:49
0,-10,2:49
1,-10,2:49
2,-10,2:49
3,-10,2:49
4,-10,2:49
5,-10,2:49
6,-10,2:49
7,-10,2:49
8,-10,2:49
9,-10,2:49
-2,-9,2:49
-1,-9,2:49
0,-9,2:49
1,-9,2:49
2,-9,2:49
3,-9,2:49
4,-9,2:49
5,-9,2:49
6,-9,2:49
7,-9,2:49
8,-9,2:49
9,-9,2:49
-2,-8,2:49
-1,-8,2:49
0,-8,2:49
1,-8,2:49
2,-8,2:49
3,-8,2:49
4,-8,2:49
5,-8,2:49
6,-8,2:49
7,-8,2:49
8,-8,2:49
9,-8,2:49
10,-8,2:49
-1,-7,2:49
0,-7,2:49
1,-7,2:49
2,-7,2:49
3,-7,2:49
4,-7,2:49
5,-7,2:49
6,-7,2:49
7,-7,2:49
8,-7,2:49
9,-7,2:49
10,-7,2:49
1,-6,2:49
2,-6,2:49
3,-6,2:49
4,-6,2:49
5,-6,2:49
6,-6,2:49
7,-6,2:49
8,-6,2:49
9,-6,2:49
10,-6,2:49
1,-5,2:49
2,-5,2:49
3,-5,2:49
4,-5,2:49
5,-5,2:49
6,-5,2:49
7,-5,2:49
8,-5,2:49
9,-5,2:49
1,-4,2:49
2,-4,2:49
3,-4,2:49
4,-4,2:49
5,-4,2:49
6,-4,2:49
7,-4,2:49
8,-4,2:49
9,-4,2:49
5,-3,2:49
6,-3,2:49
7,-3,2:49
8,-3,2:49
9,-3,2:49
4,-12,3:49
5,-12,3:49
6,-12,3:49
7,-12,3:49
8,-12,3:49
4,-11,3:49
5,-11,3:49
6,-11,3:49
7,-11,3:49
8,-11,3:49
2,-10,3:49
3,-10,3:49
4,-10,3:49
5,-10,3:49
6,-10,3:49
7,-10,3:49
8,-10,3:49
0,-9,3:49
2,-9,3:49
3,-9,3:49
4,-9,3:49
5,-9,3:49
6,-9,3:49
7,-9,3:49
8,-9,3:49
2,-8,3:49
3,-8,3:49
4,-8,3:49
5,-8,3:49
6,-8,3:49
7,-8,3:49
8,-8,3:49
1,-7,3:49
2,-7,3:49
3,-7,3:49
4,-7,3:49
5,-7,3:49
6,-7,3:49
7,-7,3:49
8,-7,3:49
1,-6,3:49
2,-6,3:49
3,-6,3:49
4,-6,3:49
5,-6,3:49
6,-6,3:49
7,-6,3:49
8,-6,3:49
9,-6,3:49
1,-5,3:49
2,-5,3:49
3,-5,3:49
4,-5,3:49
5,-5,3:49
6,-5,3:49
7,-5,3:49
8,-5,3:49
9,-5,3:49
2,-4,3:49
3,-4,3:49
4,-4,3:49
5,-4,3:49
6,-4,3:49
7,-4,3:49
8,-4,3:49
9,-4,3:49
6,-3,3:49
7,-3,3:49
8,-3,3:49
5,-12,4:49
6,-12,4:49
7,-12,4:49
4,-11,4:49
5,-11,4:49
6,-11,4:49
7,-11,4:49
8,-11,4:49
3,-10,4:49
4,-10,4:49
5,-10,4:49
6,-10,4:49
7,-10,4:49
8,-10,4:49
2,-9,4:49
3,-9,4:49
4,-9,4:49
5,-9,4:49
6,-9,4:49
7,-9,4:49
8,-9,4:49
2,-8,4:49
3,-8,4:49
4,-8,4:49
5,-8,4:49
6,-8,4:49
7,-8,4:49
2,-7,4:49
3,-7,4:49
4,-7,4:49
5,-7,4:49
6,-7,4:49
7,-7,4:49
8,-7,4:49
3,-6,4:49
4,-6,4:49
5,-6,4:49
6,-6,4:49
7,-6,4:49
8,-6,4:49
3,-5,4:49
4,-5,4:49
5,-5,4:49
6,-5,4:49
7,-5,4:49
8,-5,4:49
5,-4,4:49
6,-4,4:49
7,-4,4:49
6,-10,5:49
3,-9,5:49
4,-9,5:49
5,-9,5:49
6,-9,5:49
7,-9,5:49
3,-8,5:49
4,-8,5:49
5,-8,5:49
6,-8,5:49
7,-8,5:49
8,-8,5:49
3,-7,5:49
4,-7,5:49
5,-7,5:49
6,-7,5:49
7,-7,5:49
8,-7,5:49
3,-6,5:49
4,-6,5:49
5,-6,5:49
6,-6,5:49
7,-6,5:49
8,-6,5:49
3,-5,5:49
4,-5,5:49
5,-5,5:49
6,-5,5:49
7,-5,5:49
8,-5,5:49
4,-4,5:49
5,-4,5:49
6,-4,5:49
7,-4,5:49
8,-4,5:49
4,-9,6:49
5,-9,6:49
6,-9,6:49
3,-8,6:49
4,-8,6:49
5,-8,6:49
6,-8,6:49
7,-8,6:49
8,-8,6:49
3,-7,6:49
4,-7,6:49
5,-7,6:49
6,-7,6:49
7,-7,6:49
8,-7,6:49
3,-6,6:49
4,-6,6:49
5,-6,6:49
6,-6,6:49
7,-6,6:49
8,-6,6:49
9,-6,6:49
4,-5,6:49
5,-5,6:49
6,-5,6:49
7,-5,6:49
8,-5,6:49
4,-4,6:49
5,-4,6:49
6,-4,6:49
7,-4,6:49
8,-4,6:49
6,-3,6:49
4,-8,7:49
5,-8,7:49
6,-8,7:49
7,-8,7:49
8,-8,7:49
4,-7,7:49
5,-7,7:49
6,-7,7:49
7,-7,7:49
8,-7,7:49
4,-6,7:49
5,-6,7:49
6,-6,7:49
7,-6,7:49
8,-6,7:49
4,-5,7:49
5,-5,7:49
6,-5,7:49
7,-5,7:49
8,-5,7:49
4,-4,7:49
5,-4,7:49
6,-4,7:49
7,-4,7:49
8,-4,7:49
4,-8,8:49
5,-8,8:49
6,-8,8:49
7,-8,8:49
8,-8,8:49
4,-7,8:49
5,-7,8:49
6,-7,8:49
7,-7,8:49
8,-7,8:49
4,-6,8:49
5,-6,8:49
6,-6,8:49
7,-6,8:49
8,-6,8:49
4,-5,8:49
5,-5,8:49
6,-5,8:49
7,-5,8:49
8,-5,8:49
4,-4,8:49
5,-4,8:49
6,-4,8:49
7,-4,8:49
8,-4,8:49
19,-12,9:49
20,-12,9:49
19,-11,9:49
20,-11,9:49
19,-10,9:49
20,-10,9:49
6,-9,9:49
4,-8,9:49
5,-8,9:49
6,-8,9:49
7,-8,9:49
8,-8,9:49
4,-7,9:49
5,-7,9:49
6,-7,9:49
7,-7,9:49
8,-7,9:49
3,-6,9:49
4,-6,9:49
5,-6,9:49
6,-6,9:49
7,-6,9:49
8,-6,9:49
9,-6,9:49
4,-5,9:49
5,-5,9:49
6,-5,9:49
7,-5,9:49
8,-5,9:49
4,-4,9:49
5,-4,9:49
6,-4,9:49
7,-4,9:49
8,-4,9:49
6,-3,9:49
19,-12,10:49
20,-12,10:49
18,-11,10:49
19,-11,10:49
20,-11,10:49
19,-10,10:49
20,-10,10:49
4,-8,10:49
5,-8,10:49
6,-8,10:49
7,-8,10:49
8,-8,10:49
4,-7,10:49
5,-7,10:49
6,-7,10:49
7,-7,10:49
8,-7,10:49
4,-6,10:49
5,-6,10:49
6,-6,10:49
7,-6,10:49
8,-6,10:49
4,-5,10:49
5,-5,10:49
6,-5,10:49
7,-5,10:49
8,-5,10:49
4,-4,10:49
5,-4,10:49
6,-4,10:49
7,-4,10:49
8,-4,10:49
18,-12,11:49
19,-12,11:49
20,-12,11:49
17,-11,11:49
18,-11,11:49
19,-11,11:49
20,-11,11:49
21,-11,11:49
17,-10,11:49
18,-10,11:49
19,-10,11:49
20,-10,11:49
21,-10,11:49
17,-9,11:49
18,-9,11:49
19,-9,11:49
20,-9,11:49
21,-9,11:49
4,-8,11:49
5,-8,11:49
6,-8,11:49
7,-8,11:49
8,-8,11:49
18,-8,11:49
19,-8,11:49
20,-8,11:49
4,-7,11:49
5,-7,11:49
6,-7,11:49
7,-7,11:49
8,-7,11:49
4,-6,11:49
5,-6,11:49
6,-6,11:49
7,-6,11:49
8,-6,11:49
4,-5,11:49
5,-5,11:49
6,-5,11:49
7,-5,11:49
8,-5,11:49
4,-4,11:49
5,-4,11:49
6,-4,11:49
7,-4,11:49
8,-4,11:49
17,-12,12:49
18,-12,12:49
19,-12,12:49
20,-12,12:49
21,-12,12:49
17,-11,12:49
18,-11,12:49
19,-11,12:49
20,-11,12:49
21,-11,12:49
17,-10,12:49
18,-10,12:49
19,-10,12:49
20,-10,12:49
21,-10,12:49
6,-9,12:49
17,-9,12:49
18,-9,12:49
19,-9,12:49
20,-9,12:49
21,-9,12:49
4,-8,12:49
5,-8,12:49
6,-8,12:49
7,-8,12:49
8,-8,12:49
17,-8,12:49
18,-8,12:49
19,-8,12:49
20,-8,12:49
21,-8,12:49
4,-7,12:49
5,-7,12:49
6,-7,12:49
7,-7,12:49
8,-7,12:49
3,-6,12:49
4,-6,12:49
5,-6,12:49
6,-6,12:49
7,-6,12:49
8,-6,12:49
9,-6,12:49
4,-5,12:49
5,-5,12:49
6,-5,12:49
7,-5,12:49
8,-5,12:49
4,-4,12:49
5,-4,12:49
6,-4,12:49
7,-4,12:49
8,-4,12:49
5,-3,12:49
6,-3,12:49
7,-3,12:49
19,-13,13:49
17,-12,13:49
18,-12,13:49
19,-12,13:49
20,-12,13:49
21,-12,13:49
17,-11,13:49
18,-11,13:49
19,-11,13:49
20,-11,13:49
21,-11,13:49
16,-10,13:49
17,-10,13:49
18,-10,13:49
19,-10,13:49
20,-10,13:49
21,-10,13:49
22,-10,13:49
17,-9,13:49
18,-9,13:49
19,-9,13:49
20,-9,13:49
21,-9,13:49
4,-8,13:49
5,-8,13:49
6,-8,13:49
7,-8,13:49
8,-8,13:49
17,-8,13:49
18,-8,13:49
19,-8,13:49
20,-8,13:49
21,-8,13:49
4,-7,13:49
5,-7,13:49
6,-7,13:49
7,-7,13:49
8,-7,13:49
19,-7,13:49
4,-6,13:49
5,-6,13:49
6,-6,13:49
7,-6,13:49
8,-6,13:49
4,-5,13:49
5,-5,13:49
6,-5,13:49
7,-5,13:49
8,-5,13:49
4,-4,13:49
5,-4,13:49
6,-4,13:49
7,-4,13:49
8,-4,13:49
4,-3,13:49
5,-3,13:49
6,-3,13:49
7,-3,13:49
8,-3,13:49
17,-12,14:49
18,-12,14:49
19,-12,14:49
20,-12,14:49
21,-12,14:49
17,-11,14:49
18,-11,14:49
19,-11,14:49
20,-11,14:49
21,-11,14:49
17,-10,14:49
18,-10,14:49
19,-10,14:49
20,-10,14:49
21,-10,14:49
17,-9,14:49
18,-9,14:49
19,-9,14:49
20,-9,14:49
21,-9,14:49
5,-8,14:49
6,-8,14:49
7,-8,14:49
17,-8,14:49
18,-8,14:49
19,-8,14:49
20,-8,14:49
21,-8,14:49
4,-7,14:49
5,-7,14:49
6,-7,14:49
7,-7,14:49
8,-7,14:49
4,-6,14:49
5,-6,14:49
6,-6,14:49
7,-6,14:49
8,-6,14:49
9,-6,14:49
3,-5,14:49
4,-5,14:49
5,-5,14:49
6,-5,14:49
7,-5,14:49
8,-5,14:49
9,-5,14:49
10,-5,14:49
4,-4,14:49
5,-4,14:49
6,-4,14:49
7,-4,14:49
8,-4,14:49
9,-4,14:49
10,-4,14:49
4,-3,14:49
5,-3,14:49
6,-3,14:49
7,-3,14:49
8,-3,14:49
9,-3,14:49
10,-3,14:49
6,-2,14:49
7,-2,14:49
8,-2,14:49
9,-2,14:49
17,-12,15:49
18,-12,15:49
19,-12,15:49
20,-12,15:49
21,-12,15:49
17,-11,15:49
18,-11,15:49
19,-11,15:49
20,-11,15:49
21,-11,15:49
17,-10,15:49
18,-10,15:49
19,-10,15:49
20,-10,15:49
21,-10,15:49
17,-9,15:49
18,-9,15:49
19,-9,15:49
20,-9,15:49
21,-9,15:49
17,-8,15:49
18,-8,15:49
19,-8,15:49
20,-8,15:49
21,-8,15:49
4,-7,15:49
5,-7,15:49
6,-7,15:49
7,-7,15:49
8,-7,15:49
4,-6,15:49
5,-6,15:49
6,-6,15:49
7,-6,15:49
8,-6,15:49
9,-6,15:49
10,-6,15:49
4,-5,15:49
5,-5,15:49
6,-5,15:49
7,-5,15:49
8,-5,15:49
9,-5,15:49
10,-5,15:49
4,-4,15:49
5,-4,15:49
6,-4,15:49
7,-4,15:49
8,-4,15:49
9,-4,15:49
10,-4,15:49
4,-3,15:49
5,-3,15:49
6,-3,15:49
7,-3,15:49
8,-3,15:49
9,-3,15:49
10,-3,15:49
6,-2,15:49
7,-2,15:49
8,-2,15:49
9,-2,15:49
10,-2,15:49
19,-13,16:49
17,-12,16:49
18,-12,16:49
19,-12,16:49
20,-12,16:49
21,-12,16:49
17,-11,16:49
18,-11,16:49
19,-11,16:49
20,-11,16:49
21,-11,16:49
16,-10,16:49
17,-10,16:49
18,-10,16:49
19,-10,16:49
20,-10,16:49
21,-10,16:49
22,-10,16:49
17,-9,16:49
18,-9,16:49
19,-9,16:49
20,-9,16:49
21,-9,16:49
17,-8,16:49
18,-8,16:49
19,-8,16:49
20,-8,16:49
21,-8,16:49
5,-7,16:49
6,-7,16:49
7,-7,16:49
8,-7,16:49
17,-7,16:49
18,-7,16:49
19,-7,16:49
20,-7,16:49
21,-7,16:49
4,-6,16:49
5,-6,16:49
6,-6,16:49
7,-6,16:49
8,-6,16:49
9,-6,16:49
10,-6,16:49
11,-6,16:49
17,-6,16:49
18,-6,16:49
19,-6,16:49
20,-6,16:49
4,-5,16:49
5,-5,16:49
6,-5,16:49
7,-5,16:49
8,-5,16:49
9,-5,16:49
10,-5,16:49
11,-5,16:49
12,-5,16:49
4,-4,16:49
5,-4,16:49
6,-4,16:49
7,-4,16:49
8,-4,16:49
9,-4,16:49
10,-4,16:49
11,-4,16:49
12,-4,16:49
5,-3,16:49
6,-3,16:49
7,-3,16:49
8,-3,16:49
9,-3,16:49
10,-3,16:49
11,-3,16:49
12,-3,16:49
6,-2,16:49
7,-2,16:49
8,-2,16:49
9,-2,16:49
10,-2,16:49
11,-2,16:49
8,-1,16:49
17,-12,17:49
18,-12,17:49
19,-12,17:49
20,-12,17:49
21,-12,17:49
17,-11,17:49
18,-11,17:49
19,-11,17:49
20,-11,17:49
21,-11,17:49
17,-10,17:49
18,-10,17:49
19,-10,17:49
20,-10,17:49
21,-10,17:49
17,-9,17:49
18,-9,17:49
19,-9,17:49
20,-9,17:49
21,-9,17:49
16,-8,17:49
17,-8,17:49
18,-8,17:49
19,-8,17:49
20,-8,17:49
21,-8,17:49
15,-7,17:49
16,-7,17:49
17,-7,17:49
18,-7,17:49
19,-7,17:49
20,-7,17:49
21,-7,17:49
6,-6,17:49
7,-6,17:49
8,-6,17:49
9,-6,17:49
10,-6,17:49
11,-6,17:49
12,-6,17:49
15,-6,17:49
16,-6,17:49
17,-6,17:49
18,-6,17:49
19,-6,17:49
20,-6,17:49
21,-6,17:49
6,-5,17:49
7,-5,17:49
8,-5,17:49
9,-5,17:49
10,-5,17:49
11,-5,17:49
12,-5,17:49
15,-5,17:49
16,-5,17:49
17,-5,17:49
18,-5,17:49
19,-5,17:49
6,-4,17:49
7,-4,17:49
8,-4,17:49
9,-4,17:49
10,-4,17:49
11,-4,17:49
12,-4,17:49
15,-4,17:49
16,-4,17:49
17,-4,17:49
18,-4,17:49
6,-3,17:49
7,-3,17:49
8,-3,17:49
9,-3,17:49
10,-3,17:49
11,-3,17:49
12,-3,17:49
6,-2,17:49
7,-2,17:49
8,-2,17:49
9,-2,17:49
10,-2,17:49
11,-2,17:49
12,-2,17:49
18,-12,18:49
19,-12,18:49
20,-12,18:49
17,-11,18:49
18,-11,18:49
19,-11,18:49
20,-11,18:49
21,-11,18:49
17,-10,18:49
18,-10,18:49
19,-10,18:49
20,-10,18:49
21,-10,18:49
17,-9,18:49
18,-9,18:49
19,-9,18:49
20,-9,18:49
21,-9,18:49
15,-8,18:49
16,-8,18:49
17,-8,18:49
18,-8,18:49
19,-8,18:49
20,-8,18:49
21,-8,18:49
22,-8,18:49
10,-7,18:49
15,-7,18:49
16,-7,18:49
17,-7,18:49
18,-7,18:49
19,-7,18:49
20,-7,18:49
21,-7,18:49
7,-6,18:49
8,-6,18:49
9,-6,18:49
10,-6,18:49
11,-6,18:49
12,-6,18:49
13,-6,18:49
14,-6,18:49
15,-6,18:49
16,-6,18:49
17,-6,18:49
18,-6,18:49
19,-6,18:49
20,-6,18:49
21,-6,18:49
6,-5,18:49
7,-5,18:49
8,-5,18:49
9,-5,18:49
10,-5,18:49
11,-5,18:49
12,-5,18:49
13,-5,18:49
14,-5,18:49
15,-5,18:49
16,-5,18:49
17,-5,18:49
18,-5,18:49
19,-5,18:49
6,-4,18:49
7,-4,18:49
8,-4,18:49
9,-4,18:49
10,-4,18:49
11,-4,18:49
12,-4,18:49
13,-4,18:49
14,-4,18:49
15,-4,18:49
16,-4,18:49
17,-4,18:49
18,-4,18:49
19,-4,18:49
6,-3,18:49
7,-3,18:49
8,-3,18:49
9,-3,18:49
10,-3,18:49
11,-3,18:49
12,-3,18:49
13,-3,18:49
14,-3,18:49
15,-3,18:49
16,-3,18:49
17,-3,18:49
7,-2,18:49
8,-2,18:49
9,-2,18:49
10,-2,18:49
11,-2,18:49
12,-2,18:49
13,-2,18:49
14,-2,18:49
15,-2,18:49
16,-2,18:49
10,-1,18:49
19,-12,19:49
19,-11,19:49
17,-10,19:49
18,-10,19:49
19,-10,19:49
20,-10,19:49
21,-10,19:49
17,-9,19:49
18,-9,19:49
19,-9,19:49
20,-9,19:49
21,-9,19:49
15,-8,19:49
16,-8,19:49
17,-8,19:49
18,-8,19:49
19,-8,19:49
20,-8,19:49
21,-8,19:49
15,-7,19:49
16,-7,19:49
17,-7,19:49
18,-7,19:49
19,-7,19:49
20,-7,19:49
21,-7,19:49
8,-6,19:49
9,-6,19:49
10,-6,19:49
11,-6,19:49
12,-6,19:49
13,-6,19:49
14,-6,19:49
15,-6,19:49
16,-6,19:49
17,-6,19:49
18,-6,19:49
19,-6,19:49
20,-6,19:49
21,-6,19:49
8,-5,19:49
9,-5,19:49
10,-5,19:49
11,-5,19:49
12,-5,19:49
13,-5,19:49
14,-5,19:49
15,-5,19:49
16,-5,19:49
17,-5,19:49
18,-5,19:49
19,-5,19:49
8,-4,19:49
9,-4,19:49
10,-4,19:49
11,-4,19:49
12,-4,19:49
13,-4,19:49
14,-4,19:49
15,-4,19:49
16,-4,19:49
17,-4,19:49
18,-4,19:49
19,-4,19:49
8,-3,19:49
9,-3,19:49
10,-3,19:49
11,-3,19:49
12,-3,19:49
13,-3,19:49
14,-3,19:49
15,-3,19:49
16,-3,19:49
17,-3,19:49
8,-2,19:49
9,-2,19:49
10,-2,19:49
11,-2,19:49
12,-2,19:49
13,-2,19:49
14,-2,19:49
15,-2,19:49
16,-2,19:49
17,-2,19:49
19,-11,20:49
18,-10,20:49
19,-10,20:49
20,-10,20:49
17,-9,20:49
18,-9,20:49
19,-9,20:49
20,-9,20:49
21,-9,20:49
15,-8,20:49
16,-8,20:49
17,-8,20:49
18,-8,20:49
19,-8,20:49
20,-8,20:49
21,-8,20:49
12,-7,20:49
15,-7,20:49
16,-7,20:49
17,-7,20:49
18,-7,20:49
19,-7,20:49
20,-7,20:49
21,-7,20:49
9,-6,20:49
10,-6,20:49
11,-6,20:49
12,-6,20:49
13,-6,20:49
14,-6,20:49
15,-6,20:49
16,-6,20:49
17,-6,20:49
18,-6,20:49
19,-6,20:49
20,-6,20:49
8,-5,20:49
9,-5,20:49
10,-5,20:49
11,-5,20:49
12,-5,20:49
13,-5,20:49
14,-5,20:49
15,-5,20:49
16,-5,20:49
17,-5,20:49
18,-5,20:49
19,-5,20:49
8,-4,20:49
9,-4,20:49
10,-4,20:49
11,-4,20:49
12,-4,20:49
13,-4,20:49
14,-4,20:49
15,-4,20:49
16,-4,20:49
17,-4,20:49
18,-4,20:49
19,-4,20:49
8,-3,20:49
9,-3,20:49
10,-3,20:49
11,-3,20:49
12,-3,20:49
13,-3,20:49
14,-3,20:49
15,-3,20:49
16,-3,20:49
17,-3,20:49
9,-2,20:49
10,-2,20:49
11,-2,20:49
12,-2,20:49
13,-2,20:49
14,-2,20:49
15,-2,20:49
16,-2,20:49
17,-2,20:49
12,-1,20:49
15,-1,20:49
19,-9,21:49
16,-8,21:49
17,-8,21:49
18,-8,21:49
19,-8,21:49
15,-7,21:49
16,-7,21:49
17,-7,21:49
18,-7,21:49
19,-7,21:49
10,-6,21:49
11,-6,21:49
12,-6,21:49
13,-6,21:49
14,-6,21:49
15,-6,21:49
16,-6,21:49
17,-6,21:49
18,-6,21:49
19,-6,21:49
10,-5,21:49
11,-5,21:49
12,-5,21:49
13,-5,21:49
14,-5,21:49
15,-5,21:49
16,-5,21:49
17,-5,21:49
18,-5,21:49
19,-5,21:49
10,-4,21:49
11,-4,21:49
12,-4,21:49
13,-4,21:49
14,-4,21:49
15,-4,21:49
16,-4,21:49
17,-4,21:49
18,-4,21:49
10,-3,21:49
11,-3,21:49
12,-3,21:49
13,-3,21:49
14,-3,21:49
15,-3,21:49
16,-3,21:49
17,-3,21:49
10,-2,21:49
11,-2,21:49
12,-2,21:49
13,-2,21:49
14,-2,21:49
15,-2,21:49
16,-2,21:49
17,-2,21:49
11,-6,22:49
12,-6,22:49
13,-6,22:49
14,-6,22:49
15,-6,22:49
16,-6,22:49
17,-6,22:49
10,-5,22:49
11,-5,22:49
12,-5,22:49
13,-5,22:49
14,-5,22:49
15,-5,22:49
16,-5,22:49
17,-5,22:49
10,-4,22:49
11,-4,22:49
12,-4,22:49
13,-4,22:49
14,-4,22:49
15,-4,22:49
16,-4,22:49
17,-4,22:49
10,-3,22:49
11,-3,22:49
12,-3,22:49
13,-3,22:49
14,-3,22:49
15,-3,22:49
16,-3,22:49
17,-3,22:49
11,-2,22:49
12,-2,22:49
13,-2,22:49
14,-2,22:49
15,-2,22:49
16,-2,22:49
12,-4,23:49
15,-4,23:49
