[META]
version=2.0
spawnOnBlockType=10,11,87
spawnSunlight=True
spawnDarkness=True
spawnWater=False
spawnLava=False
underFill=True
randomRotation=True
dig=True
tree=False
branch=False
needsFoundation=True
rarity=25
collisionPercentage=20
spawnElevationMin=0
spawnElevationMax=200
spawnInBiome=Nethers,NethersCave,NethersMedium
[DATA]
-14,-1,0:49
-13,-1,0:49
-12,-1,0:49
-15,0,0:49
-14,0,0:49
-13,0,0:49
-12,0,0:49
-11,0,0:49
-15,1,0:49
-14,1,0:49
-13,1,0:49
-12,1,0:49
-11,1,0:49
-15,2,0:49
-14,2,0:49
-13,2,0:49
-12,2,0:49
-11,2,0:49
-14,3,0:49
-13,3,0:49
-12,3,0:49
-13,21,0:49
-15,22,0:49
-14,22,0:49
-13,22,0:49
-12,22,0:49
-11,22,0:49
-15,23,0:49
-14,23,0:49
-13,23,0:49
-12,23,0:49
-11,23,0:49
-16,24,0:49
-15,24,0:49
-14,24,0:49
-13,24,0:49
-12,24,0:49
-11,24,0:49
-10,24,0:49
-15,25,0:49
-14,25,0:49
-13,25,0:49
-12,25,0:49
-11,25,0:49
-15,26,0:49
-14,26,0:49
-13,26,0:49
-12,26,0:49
-11,26,0:49
-13,27,0:49
-15,-1,1:49
-14,-1,1:49
-13,-1,1:49
-12,-1,1:49
-11,-1,1:49
-15,0,1:49
-14,0,1:49
-13,0,1:49
-12,0,1:49
-11,0,1:49
-15,1,1:49
-14,1,1:49
-13,1,1:49
-12,1,1:49
-11,1,1:49
-15,2,1:49
-14,2,1:49
-13,2,1:49
-12,2,1:49
-11,2,1:49
-15,3,1:49
-14,3,1:49
-13,3,1:49
-12,3,1:49
-11,3,1:49
-15,22,1:49
-14,22,1:49
-13,22,1:49
-12,22,1:49
-11,22,1:49
-15,23,1:49
-14,23,1:49
-13,23,1:49
-12,23,1:49
-11,23,1:49
-15,24,1:49
-14,24,1:49
-13,24,1:49
-12,24,1:49
-11,24,1:49
-15,25,1:49
-14,25,1:49
-13,25,1:49
-12,25,1:49
-11,25,1:49
-15,26,1:49
-14,26,1:49
-13,26,1:49
-12,26,1:49
-11,26,1:49
-13,-2,2:49
-15,-1,2:49
-14,-1,2:49
-13,-1,2:49
-12,-1,2:49
-11,-1,2:49
-15,0,2:49
-14,0,2:49
-13,0,2:49
-12,0,2:49
-11,0,2:49
-16,1,2:49
-15,1,2:49
-14,1,2:49
-13,1,2:49
-12,1,2:49
-11,1,2:49
-10,1,2:49
-15,2,2:49
-14,2,2:49
-13,2,2:49
-12,2,2:49
-11,2,2:49
-15,3,2:49
-14,3,2:49
-13,3,2:49
-12,3,2:49
-11,3,2:49
-15,4,2:49
-14,4,2:49
-13,4,2:49
-12,4,2:49
-11,4,2:49
-14,5,2:49
-13,5,2:49
-12,5,2:49
-15,22,2:49
-14,22,2:49
-13,22,2:49
-12,22,2:49
-11,22,2:49
-15,23,2:49
-14,23,2:49
-13,23,2:49
-12,23,2:49
-11,23,2:49
-15,24,2:49
-14,24,2:49
-13,24,2:49
-12,24,2:49
-11,24,2:49
-15,25,2:49
-14,25,2:49
-13,25,2:49
-12,25,2:49
-11,25,2:49
-15,26,2:49
-14,26,2:49
-13,26,2:49
-12,26,2:49
-11,26,2:49
-15,-1,3:49
-14,-1,3:49
-13,-1,3:49
-12,-1,3:49
-11,-1,3:49
-15,0,3:49
-14,0,3:49
-13,0,3:49
-12,0,3:49
-11,0,3:49
-15,1,3:49
-14,1,3:49
-13,1,3:49
-12,1,3:49
-11,1,3:49
-15,2,3:49
-14,2,3:49
-13,2,3:49
-12,2,3:49
-11,2,3:49
-15,3,3:49
-14,3,3:49
-13,3,3:49
-12,3,3:49
-11,3,3:49
-15,4,3:49
-14,4,3:49
-13,4,3:49
-12,4,3:49
-11,4,3:49
-15,5,3:49
-14,5,3:49
-13,5,3:49
-12,5,3:49
-11,5,3:49
-14,21,3:49
-13,21,3:49
-12,21,3:49
-15,22,3:49
-14,22,3:49
-13,22,3:49
-12,22,3:49
-11,22,3:49
-15,23,3:49
-14,23,3:49
-13,23,3:49
-12,23,3:49
-11,23,3:49
-16,24,3:49
-15,24,3:49
-14,24,3:49
-13,24,3:49
-12,24,3:49
-11,24,3:49
-10,24,3:49
-15,25,3:49
-14,25,3:49
-13,25,3:49
-12,25,3:49
-11,25,3:49
-15,26,3:49
-14,26,3:49
-13,26,3:49
-12,26,3:49
-11,26,3:49
-13,27,3:49
-14,-1,4:49
-13,-1,4:49
-12,-1,4:49
-15,0,4:49
-14,0,4:49
-13,0,4:49
-12,0,4:49
-11,0,4:49
-15,1,4:49
-14,1,4:49
-13,1,4:49
-12,1,4:49
-11,1,4:49
-15,2,4:49
-14,2,4:49
-13,2,4:49
-12,2,4:49
-11,2,4:49
-16,3,4:49
-15,3,4:49
-14,3,4:49
-13,3,4:49
-12,3,4:49
-11,3,4:49
-10,3,4:49
-15,4,4:49
-14,4,4:49
-13,4,4:49
-12,4,4:49
-11,4,4:49
-15,5,4:49
-14,5,4:49
-13,5,4:49
-12,5,4:49
-11,5,4:49
-15,6,4:49
-14,6,4:49
-13,6,4:49
-12,6,4:49
-11,6,4:49
-14,7,4:49
-13,7,4:49
-12,7,4:49
-15,21,4:49
-14,21,4:49
-13,21,4:49
-12,21,4:49
-11,21,4:49
-15,22,4:49
-14,22,4:49
-13,22,4:49
-12,22,4:49
-11,22,4:49
-15,23,4:49
-14,23,4:49
-13,23,4:49
-12,23,4:49
-11,23,4:49
-15,24,4:49
-14,24,4:49
-13,24,4:49
-12,24,4:49
-11,24,4:49
-15,25,4:49
-14,25,4:49
-13,25,4:49
-12,25,4:49
-11,25,4:49
-15,26,4:49
-14,26,4:49
-13,26,4:49
-12,26,4:49
-11,26,4:49
-15,1,5:49
-14,1,5:49
-13,1,5:49
-12,1,5:49
-11,1,5:49
-15,2,5:49
-14,2,5:49
-13,2,5:49
-12,2,5:49
-11,2,5:49
-15,3,5:49
-14,3,5:49
-13,3,5:49
-12,3,5:49
-11,3,5:49
-15,4,5:49
-14,4,5:49
-13,4,5:49
-12,4,5:49
-11,4,5:49
-15,5,5:49
-14,5,5:49
-13,5,5:49
-12,5,5:49
-11,5,5:49
-15,6,5:49
-14,6,5:49
-13,6,5:49
-12,6,5:49
-11,6,5:49
-15,7,5:49
-14,7,5:49
-13,7,5:49
-12,7,5:49
-11,7,5:49
-15,8,5:49
-14,8,5:49
-13,8,5:49
-12,8,5:49
-11,8,5:49
-14,9,5:49
-13,9,5:49
-12,9,5:49
-14,20,5:49
-13,20,5:49
-12,20,5:49
-15,21,5:49
-14,21,5:49
-13,21,5:49
-12,21,5:49
-11,21,5:49
-15,22,5:49
-14,22,5:49
-13,22,5:49
-12,22,5:49
-11,22,5:49
-16,23,5:49
-15,23,5:49
-14,23,5:49
-13,23,5:49
-12,23,5:49
-11,23,5:49
-10,23,5:49
-15,24,5:49
-14,24,5:49
-13,24,5:49
-12,24,5:49
-11,24,5:49
-15,25,5:49
-14,25,5:49
-13,25,5:49
-12,25,5:49
-11,25,5:49
-14,26,5:49
-13,26,5:49
-12,26,5:49
-14,1,6:49
-13,1,6:49
-12,1,6:49
-15,2,6:49
-14,2,6:49
-13,2,6:49
-12,2,6:49
-11,2,6:49
-15,3,6:49
-14,3,6:49
-13,3,6:49
-12,3,6:49
-11,3,6:49
-15,4,6:49
-14,4,6:49
-13,4,6:49
-12,4,6:49
-11,4,6:49
-16,5,6:49
-15,5,6:49
-14,5,6:49
-13,5,6:49
-12,5,6:49
-11,5,6:49
-10,5,6:49
-15,6,6:49
-14,6,6:49
-13,6,6:49
-12,6,6:49
-11,6,6:49
-15,7,6:49
-14,7,6:49
-13,7,6:49
-12,7,6:49
-11,7,6:49
-15,8,6:49
-14,8,6:49
-13,8,6:49
-12,8,6:49
-11,8,6:49
-15,9,6:49
-14,9,6:49
-13,9,6:49
-12,9,6:49
-11,9,6:49
-15,10,6:49
-14,10,6:49
-13,10,6:49
-12,10,6:49
-11,10,6:49
-14,11,6:49
-13,11,6:49
-12,11,6:49
-15,20,6:49
-14,20,6:49
-13,20,6:49
-12,20,6:49
-11,20,6:49
-15,21,6:49
-14,21,6:49
-13,21,6:49
-12,21,6:49
-11,21,6:49
-15,22,6:49
-14,22,6:49
-13,22,6:49
-12,22,6:49
-11,22,6:49
-15,23,6:49
-14,23,6:49
-13,23,6:49
-12,23,6:49
-11,23,6:49
-15,24,6:49
-14,24,6:49
-13,24,6:49
-12,24,6:49
-11,24,6:49
-15,25,6:49
-14,25,6:49
-13,25,6:49
-12,25,6:49
-11,25,6:49
-15,3,7:49
-14,3,7:49
-13,3,7:49
-12,3,7:49
-11,3,7:49
-15,4,7:49
-14,4,7:49
-13,4,7:49
-12,4,7:49
-11,4,7:49
-15,5,7:49
-14,5,7:49
-13,5,7:49
-12,5,7:49
-11,5,7:49
-15,6,7:49
-14,6,7:49
-13,6,7:49
-12,6,7:49
-11,6,7:49
-16,7,7:49
-15,7,7:49
-14,7,7:49
-13,7,7:49
-12,7,7:49
-11,7,7:49
-10,7,7:49
-15,8,7:49
-14,8,7:49
-13,8,7:49
-12,8,7:49
-11,8,7:49
-15,9,7:49
-14,9,7:49
-13,9,7:49
-12,9,7:49
-11,9,7:49
-15,10,7:49
-14,10,7:49
-13,10,7:49
-12,10,7:49
-11,10,7:49
-15,11,7:49
-14,11,7:49
-13,11,7:49
-12,11,7:49
-11,11,7:49
-15,12,7:49
-14,12,7:49
-13,12,7:49
-12,12,7:49
-11,12,7:49
-14,13,7:49
-13,13,7:49
-12,13,7:49
-13,16,7:49
-14,19,7:49
-13,19,7:49
-12,19,7:49
-15,20,7:49
-14,20,7:49
-13,20,7:49
-12,20,7:49
-11,20,7:49
-15,21,7:49
-14,21,7:49
-13,21,7:49
-12,21,7:49
-11,21,7:49
-16,22,7:49
-15,22,7:49
-14,22,7:49
-13,22,7:49
-12,22,7:49
-11,22,7:49
-10,22,7:49
-15,23,7:49
-14,23,7:49
-13,23,7:49
-12,23,7:49
-11,23,7:49
-15,24,7:49
-14,24,7:49
-13,24,7:49
-12,24,7:49
-11,24,7:49
-14,25,7:49
-13,25,7:49
-12,25,7:49
-14,3,8:49
-13,3,8:49
-12,3,8:49
-15,4,8:49
-14,4,8:49
-13,4,8:49
-12,4,8:49
-11,4,8:49
-15,5,8:49
-14,5,8:49
-13,5,8:49
-12,5,8:49
-11,5,8:49
-15,6,8:49
-14,6,8:49
-13,6,8:49
-12,6,8:49
-11,6,8:49
-15,7,8:49
-14,7,8:49
-13,7,8:49
-12,7,8:49
-11,7,8:49
-15,8,8:49
-14,8,8:49
-13,8,8:49
-12,8,8:49
-11,8,8:49
-16,9,8:49
-15,9,8:49
-14,9,8:49
-13,9,8:49
-12,9,8:49
-11,9,8:49
-10,9,8:49
-15,10,8:49
-14,10,8:49
-13,10,8:49
-12,10,8:49
-11,10,8:49
-15,11,8:49
-14,11,8:49
-13,11,8:49
-12,11,8:49
-11,11,8:49
-15,12,8:49
-14,12,8:49
-13,12,8:49
-12,12,8:49
-11,12,8:49
-15,13,8:49
-14,13,8:49
-13,13,8:49
-12,13,8:49
-11,13,8:49
-15,14,8:49
-14,14,8:49
-13,14,8:49
-12,14,8:49
-11,14,8:49
-15,15,8:49
-14,15,8:49
-13,15,8:49
-12,15,8:49
-11,15,8:49
-15,16,8:49
-14,16,8:49
-13,16,8:49
-12,16,8:49
-11,16,8:49
-15,17,8:49
-14,17,8:49
-13,17,8:49
-12,17,8:49
-11,17,8:49
-15,18,8:49
-14,18,8:49
-13,18,8:49
-12,18,8:49
-11,18,8:49
-15,19,8:49
-14,19,8:49
-13,19,8:49
-12,19,8:49
-11,19,8:49
-15,20,8:49
-14,20,8:49
-13,20,8:49
-12,20,8:49
-11,20,8:49
-15,21,8:49
-14,21,8:49
-13,21,8:49
-12,21,8:49
-11,21,8:49
-15,22,8:49
-14,22,8:49
-13,22,8:49
-12,22,8:49
-11,22,8:49
-15,23,8:49
-14,23,8:49
-13,23,8:49
-12,23,8:49
-11,23,8:49
-15,24,8:49
-14,24,8:49
-13,24,8:49
-12,24,8:49
-11,24,8:49
-14,5,9:49
-13,5,9:49
-12,5,9:49
-15,6,9:49
-14,6,9:49
-13,6,9:49
-12,6,9:49
-11,6,9:49
-15,7,9:49
-14,7,9:49
-13,7,9:49
-12,7,9:49
-11,7,9:49
-15,8,9:49
-14,8,9:49
-13,8,9:49
-12,8,9:49
-11,8,9:49
-15,9,9:49
-14,9,9:49
-13,9,9:49
-12,9,9:49
-11,9,9:49
-15,10,9:49
-14,10,9:49
-13,10,9:49
-12,10,9:49
-11,10,9:49
-16,11,9:49
-15,11,9:49
-14,11,9:49
-13,11,9:49
-12,11,9:49
-11,11,9:49
-10,11,9:49
-15,12,9:49
-14,12,9:49
-13,12,9:49
-12,12,9:49
-11,12,9:49
-15,13,9:49
-14,13,9:49
-13,13,9:49
-12,13,9:49
-11,13,9:49
-15,14,9:49
-14,14,9:49
-13,14,9:49
-12,14,9:49
-11,14,9:49
-15,15,9:49
-14,15,9:49
-13,15,9:49
-12,15,9:49
-11,15,9:49
-15,16,9:49
-14,16,9:49
-13,16,9:49
-12,16,9:49
-11,16,9:49
-15,17,9:49
-14,17,9:49
-13,17,9:49
-12,17,9:49
-11,17,9:49
-15,18,9:49
-14,18,9:49
-13,18,9:49
-12,18,9:49
-11,18,9:49
-15,19,9:49
-14,19,9:49
-13,19,9:49
-12,19,9:49
-11,19,9:49
-15,20,9:49
-14,20,9:49
-13,20,9:49
-12,20,9:49
-11,20,9:49
-16,21,9:49
-15,21,9:49
-14,21,9:49
-13,21,9:49
-12,21,9:49
-11,21,9:49
-10,21,9:49
-15,22,9:49
-14,22,9:49
-13,22,9:49
-12,22,9:49
-11,22,9:49
-15,23,9:49
-14,23,9:49
-13,23,9:49
-12,23,9:49
-11,23,9:49
-14,24,9:49
-13,24,9:49
-12,24,9:49
-14,7,10:49
-13,7,10:49
-12,7,10:49
-15,8,10:49
-14,8,10:49
-13,8,10:49
-12,8,10:49
-11,8,10:49
-15,9,10:49
-14,9,10:49
-13,9,10:49
-12,9,10:49
-11,9,10:49
-15,10,10:49
-14,10,10:49
-13,10,10:49
-12,10,10:49
-11,10,10:49
-15,11,10:49
-14,11,10:49
-13,11,10:49
-12,11,10:49
-11,11,10:49
-15,12,10:49
-14,12,10:49
-13,12,10:49
-12,12,10:49
-11,12,10:49
-16,13,10:49
-15,13,10:49
-14,13,10:49
-13,13,10:49
-12,13,10:49
-11,13,10:49
-10,13,10:49
-15,14,10:49
-14,14,10:49
-13,14,10:49
-12,14,10:49
-11,14,10:49
-15,15,10:49
-14,15,10:49
-13,15,10:49
-12,15,10:49
-11,15,10:49
-16,16,10:49
-15,16,10:49
-14,16,10:49
-13,16,10:49
-12,16,10:49
-11,16,10:49
-10,16,10:49
-15,17,10:49
-14,17,10:49
-13,17,10:49
-12,17,10:49
-11,17,10:49
-15,18,10:49
-14,18,10:49
-13,18,10:49
-12,18,10:49
-11,18,10:49
-16,19,10:49
-15,19,10:49
-14,19,10:49
-13,19,10:49
-12,19,10:49
-11,19,10:49
-10,19,10:49
-15,20,10:49
-14,20,10:49
-13,20,10:49
-12,20,10:49
-11,20,10:49
-15,21,10:49
-14,21,10:49
-13,21,10:49
-12,21,10:49
-11,21,10:49
-15,22,10:49
-14,22,10:49
-13,22,10:49
-12,22,10:49
-11,22,10:49
-15,23,10:49
-14,23,10:49
-13,23,10:49
-12,23,10:49
-11,23,10:49
-14,9,11:49
-13,9,11:49
-12,9,11:49
-15,10,11:49
-14,10,11:49
-13,10,11:49
-12,10,11:49
-11,10,11:49
-15,11,11:49
-14,11,11:49
-13,11,11:49
-12,11,11:49
-11,11,11:49
-15,12,11:49
-14,12,11:49
-13,12,11:49
-12,12,11:49
-11,12,11:49
-15,13,11:49
-14,13,11:49
-13,13,11:49
-12,13,11:49
-11,13,11:49
-15,14,11:49
-14,14,11:49
-13,14,11:49
-12,14,11:49
-11,14,11:49
-15,15,11:49
-14,15,11:49
-13,15,11:49
-12,15,11:49
-11,15,11:49
-15,16,11:49
-14,16,11:49
-13,16,11:49
-12,16,11:49
-11,16,11:49
-15,17,11:49
-14,17,11:49
-13,17,11:49
-12,17,11:49
-11,17,11:49
-15,18,11:49
-14,18,11:49
-13,18,11:49
-12,18,11:49
-11,18,11:49
-15,19,11:49
-14,19,11:49
-13,19,11:49
-12,19,11:49
-11,19,11:49
-15,20,11:49
-14,20,11:49
-13,20,11:49
-12,20,11:49
-11,20,11:49
-15,21,11:49
-14,21,11:49
-13,21,11:49
-12,21,11:49
-11,21,11:49
-15,22,11:49
-14,22,11:49
-13,22,11:49
-12,22,11:49
-11,22,11:49
-14,23,11:49
-13,23,11:49
-12,23,11:49
-14,11,12:49
-13,11,12:49
-12,11,12:49
-15,12,12:49
-14,12,12:49
-13,12,12:49
-12,12,12:49
-11,12,12:49
-15,13,12:49
-14,13,12:49
-13,13,12:49
-12,13,12:49
-11,13,12:49
-15,14,12:49
-14,14,12:49
-13,14,12:49
-12,14,12:49
-11,14,12:49
-15,15,12:49
-14,15,12:49
-13,15,12:49
-12,15,12:49
-11,15,12:49
-15,16,12:49
-14,16,12:49
-13,16,12:49
-12,16,12:49
-11,16,12:49
-15,17,12:49
-14,17,12:49
-13,17,12:49
-12,17,12:49
-11,17,12:49
-15,18,12:49
-14,18,12:49
-13,18,12:49
-12,18,12:49
-11,18,12:49
-15,19,12:49
-14,19,12:49
-13,19,12:49
-12,19,12:49
-11,19,12:49
-15,20,12:49
-14,20,12:49
-13,20,12:49
-12,20,12:49
-11,20,12:49
-14,21,12:49
-13,21,12:49
-12,21,12:49
-13,13,13:49
-13,14,13:49
-13,15,13:49
-13,16,13:49
-13,17,13:49
-13,18,13:49
-13,19,13:49
