[META]
version=2.0
spawnOnBlockType=13
spawnSunlight=True
spawnDarkness=False
spawnWater=False
spawnLava=False
underFill=True
randomRotation=True
dig=True
tree=False
branch=False
needsFoundation=True
rarity=1
collisionPercentage=2
spawnElevationMin=0
spawnElevationMax=128
spawnInBiome=Flat
[DATA]
-9,-9,0:4
-8,-9,0:4
-7,-9,0:4
-6,-9,0:4
-5,-9,0:1
-4,-9,0:48
-3,-9,0:48
-2,-9,0:1
-1,-9,0:48
0,-9,0:1
1,-9,0:48
2,-9,0:48
3,-9,0:1
4,-9,0:4
5,-9,0:4
6,-9,0:48
7,-9,0:4
8,-9,0:4
-9,-8,0:1
-8,-8,0:1
-7,-8,0:1
-6,-8,0:48
-5,-8,0:4
-4,-8,0:4
-3,-8,0:48
-2,-8,0:4
-1,-8,0:1
0,-8,0:4
1,-8,0:4
2,-8,0:1
3,-8,0:48
4,-8,0:1
5,-8,0:4
6,-8,0:4
7,-8,0:4
8,-8,0:1
-9,-7,0:4
-8,-7,0:1
-7,-7,0:4
-6,-7,0:1
-5,-7,0:1
-4,-7,0:4
-3,-7,0:4
-2,-7,0:4
-1,-7,0:1
0,-7,0:1
1,-7,0:4
2,-7,0:4
3,-7,0:4
4,-7,0:48
5,-7,0:4
6,-7,0:4
7,-7,0:4
8,-7,0:4
-9,-6,0:4
-8,-6,0:4
-7,-6,0:4
-6,-6,0:4
-5,-6,0:4
-4,-6,0:48
-3,-6,0:4
-2,-6,0:4
-1,-6,0:48
0,-6,0:4
1,-6,0:4
2,-6,0:1
3,-6,0:4
4,-6,0:48
5,-6,0:4
6,-6,0:4
7,-6,0:4
8,-6,0:4
-9,-5,0:4
-8,-5,0:4
-7,-5,0:4
-6,-5,0:4
-5,-5,0:1
-4,-5,0:4
-3,-5,0:4
-2,-5,0:4
-1,-5,0:48
0,-5,0:4
1,-5,0:48
2,-5,0:4
3,-5,0:48
4,-5,0:48
5,-5,0:4
6,-5,0:1
7,-5,0:48
8,-5,0:4
-9,-4,0:48
-8,-4,0:4
-7,-4,0:4
-6,-4,0:4
-5,-4,0:1
-4,-4,0:4
-3,-4,0:4
-2,-4,0:4
-1,-4,0:4
0,-4,0:4
1,-4,0:4
2,-4,0:4
3,-4,0:1
4,-4,0:4
5,-4,0:4
6,-4,0:4
7,-4,0:4
8,-4,0:1
-9,-3,0:48
-8,-3,0:48
-7,-3,0:4
-6,-3,0:4
-5,-3,0:4
-4,-3,0:4
-3,-3,0:48
-2,-3,0:4
-1,-3,0:4
0,-3,0:4
1,-3,0:48
2,-3,0:4
3,-3,0:4
4,-3,0:4
5,-3,0:4
6,-3,0:1
7,-3,0:4
8,-3,0:4
-9,-2,0:4
-8,-2,0:4
-7,-2,0:1
-6,-2,0:4
-5,-2,0:4
-4,-2,0:1
-3,-2,0:4
-2,-2,0:1
-1,-2,0:48
0,-2,0:1
1,-2,0:1
2,-2,0:48
3,-2,0:4
4,-2,0:4
5,-2,0:4
6,-2,0:4
7,-2,0:1
8,-2,0:48
-9,-1,0:4
-8,-1,0:4
-7,-1,0:4
-6,-1,0:4
-5,-1,0:4
-4,-1,0:1
-3,-1,0:4
-2,-1,0:1
-1,-1,0:48
0,-1,0:4
1,-1,0:1
2,-1,0:48
3,-1,0:4
4,-1,0:4
5,-1,0:4
6,-1,0:1
7,-1,0:4
8,-1,0:4
-9,0,0:4
-8,0,0:4
-7,0,0:4
-6,0,0:48
-5,0,0:4
-4,0,0:1
-3,0,0:4
-2,0,0:4
-1,0,0:4
0,0,0:4
1,0,0:48
2,0,0:4
3,0,0:4
4,0,0:4
5,0,0:1
6,0,0:4
7,0,0:1
8,0,0:48
-9,1,0:4
-8,1,0:4
-7,1,0:48
-6,1,0:4
-5,1,0:4
-4,1,0:48
-3,1,0:4
-2,1,0:1
-1,1,0:4
0,1,0:1
1,1,0:4
2,1,0:48
3,1,0:4
4,1,0:48
5,1,0:4
6,1,0:4
7,1,0:4
8,1,0:4
-9,2,0:1
-8,2,0:4
-7,2,0:4
-6,2,0:4
-5,2,0:1
-4,2,0:48
-3,2,0:4
-2,2,0:4
-1,2,0:4
0,2,0:4
1,2,0:4
2,2,0:4
3,2,0:48
4,2,0:4
5,2,0:48
6,2,0:4
7,2,0:4
8,2,0:1
-9,3,0:4
-8,3,0:4
-7,3,0:4
-6,3,0:4
-5,3,0:4
-4,3,0:4
-3,3,0:4
-2,3,0:4
1,3,0:4
2,3,0:1
3,3,0:1
4,3,0:4
5,3,0:4
6,3,0:4
7,3,0:4
8,3,0:4
-9,4,0:4
-8,4,0:4
-7,4,0:4
-6,4,0:4
-5,4,0:1
-4,4,0:4
-3,4,0:4
-2,4,0:4
1,4,0:4
2,4,0:4
3,4,0:4
4,4,0:4
5,4,0:4
6,4,0:4
7,4,0:48
8,4,0:4
-9,5,0:4
-8,5,0:4
-7,5,0:1
-6,5,0:4
-5,5,0:4
-4,5,0:48
-3,5,0:4
-2,5,0:1
1,5,0:4
2,5,0:1
3,5,0:1
4,5,0:48
5,5,0:4
6,5,0:1
7,5,0:48
8,5,0:4
-9,6,0:4
-8,6,0:48
-7,6,0:48
-6,6,0:4
-5,6,0:4
-4,6,0:48
-3,6,0:4
-2,6,0:4
-1,6,0:53.2
0,6,0:53.2
1,6,0:4
2,6,0:1
3,6,0:1
4,6,0:4
5,6,0:4
6,6,0:4
7,6,0:4
8,6,0:1
-9,7,0:1
-8,7,0:1
-7,7,0:4
-6,7,0:4
-5,7,0:48
-4,7,0:4
-3,7,0:4
-2,7,0:4
-1,7,0:4
0,7,0:4
1,7,0:4
2,7,0:4
3,7,0:4
4,7,0:4
5,7,0:48
6,7,0:1
7,7,0:48
8,7,0:4
-9,8,0:48
-8,8,0:4
-7,8,0:48
-6,8,0:48
-5,8,0:4
-4,8,0:4
-3,8,0:4
-2,8,0:4
-1,8,0:4
0,8,0:4
1,8,0:1
2,8,0:1
3,8,0:48
4,8,0:4
5,8,0:4
6,8,0:1
7,8,0:4
8,8,0:4
-8,-8,1:98.2
-7,-8,1:98.1
-6,-8,1:98.1
-5,-8,1:102
-4,-8,1:102
-3,-8,1:102
-2,-8,1:98.2
-1,-8,1:98.1
0,-8,1:98.2
1,-8,1:98.2
2,-8,1:102
3,-8,1:102
4,-8,1:102
5,-8,1:98.0
6,-8,1:98.1
7,-8,1:98.1
-8,-7,1:98.1
-2,-7,1:48
1,-7,1:48
7,-7,1:98.1
-8,-6,1:98.0
-2,-6,1:1
1,-6,1:48
7,-6,1:98.2
-8,-5,1:102
-2,-5,1:1
1,-5,1:48
7,-5,1:102
-8,-4,1:102
-2,-4,1:48
1,-4,1:48
7,-4,1:102
-8,-3,1:102
-3,-3,1:52
-2,-3,1:4
-1,-3,1:5.0
0,-3,1:5.0
1,-3,1:1
7,-3,1:102
-8,-2,1:98.1
-2,-2,1:4
-1,-2,1:53.3
0,-2,1:53.3
1,-2,1:48
7,-2,1:98.2
-8,-1,1:98.1
7,-1,1:98.2
-8,0,1:98.0
7,0,1:98.1
-8,1,1:98.0
7,1,1:98.1
-8,2,1:102
7,2,1:102
-8,3,1:102
7,3,1:102
-8,4,1:102
7,4,1:102
-8,5,1:98.1
7,5,1:98.0
-8,6,1:98.2
7,6,1:98.0
-8,7,1:98.0
-7,7,1:98.1
-6,7,1:98.2
-5,7,1:102
-4,7,1:102
-3,7,1:102
-2,7,1:98.0
-1,7,1:98.2
0,7,1:98.0
1,7,1:98.0
2,7,1:102
3,7,1:102
4,7,1:102
5,7,1:98.2
6,7,1:98.2
7,7,1:98.0
-8,-8,2:98.2
-7,-8,2:98.1
-6,-8,2:98.1
-5,-8,2:102
-4,-8,2:102
-3,-8,2:102
-2,-8,2:98.2
-1,-8,2:98.0
0,-8,2:98.0
1,-8,2:98.1
2,-8,2:102
3,-8,2:102
4,-8,2:102
5,-8,2:98.2
6,-8,2:98.2
7,-8,2:98.1
-8,-7,2:98.1
-2,-7,2:4
1,-7,2:48
7,-7,2:98.1
-8,-6,2:98.1
-2,-6,2:48
1,-6,2:48
7,-6,2:98.1
-8,-5,2:102
-2,-5,2:4
1,-5,2:4
7,-5,2:102
-8,-4,2:102
-2,-4,2:48
-1,-4,2:5.0
0,-4,2:5.0
1,-4,2:4
7,-4,2:102
-8,-3,2:102
-2,-3,2:48
-1,-3,2:53.3
0,-3,2:53.3
1,-3,2:4
7,-3,2:102
-8,-2,2:98.1
7,-2,2:98.2
-8,-1,2:98.2
7,-1,2:98.1
-8,0,2:98.0
7,0,2:98.1
-8,1,2:98.2
7,1,2:98.0
-8,2,2:102
7,2,2:102
-8,3,2:102
7,3,2:102
-8,4,2:102
7,4,2:102
-8,5,2:98.1
7,5,2:98.1
-8,6,2:98.1
7,6,2:98.2
-8,7,2:98.0
-7,7,2:98.1
-6,7,2:98.2
-5,7,2:102
-4,7,2:102
-3,7,2:102
-2,7,2:98.0
-1,7,2:98.2
0,7,2:98.1
1,7,2:98.0
2,7,2:102
3,7,2:102
4,7,2:102
5,7,2:98.1
6,7,2:98.2
7,7,2:98.2
-8,-8,3:98.0
-7,-8,3:98.2
-6,-8,3:98.2
-5,-8,3:102
-4,-8,3:102
-3,-8,3:102
-2,-8,3:98.0
-1,-8,3:98.0
0,-8,3:98.0
1,-8,3:98.0
2,-8,3:102
3,-8,3:102
4,-8,3:102
5,-8,3:98.0
6,-8,3:98.2
7,-8,3:98.2
-8,-7,3:98.1
-2,-7,3:1
1,-7,3:1
7,-7,3:98.0
-8,-6,3:98.1
-2,-6,3:1
1,-6,3:4
7,-6,3:98.0
-8,-5,3:102
-2,-5,3:4
-1,-5,3:5.0
0,-5,3:5.0
1,-5,3:1
7,-5,3:102
-8,-4,3:102
-2,-4,3:4
-1,-4,3:53.3
0,-4,3:53.3
1,-4,3:4
7,-4,3:102
-8,-3,3:102
7,-3,3:102
-8,-2,3:98.1
7,-2,3:98.1
-8,-1,3:98.2
7,-1,3:98.1
-8,0,3:98.0
7,0,3:98.2
-8,1,3:98.1
7,1,3:98.1
-8,2,3:102
7,2,3:102
-8,3,3:102
7,3,3:102
-8,4,3:102
7,4,3:102
-8,5,3:98.2
7,5,3:98.0
-8,6,3:98.1
7,6,3:98.1
-8,7,3:98.1
-7,7,3:98.0
-6,7,3:98.1
-5,7,3:102
-4,7,3:102
-3,7,3:102
-2,7,3:98.0
-1,7,3:98.0
0,7,3:98.0
1,7,3:98.2
2,7,3:102
3,7,3:102
4,7,3:102
5,7,3:98.2
6,7,3:98.2
7,7,3:98.0
-8,-8,4:98.2
-7,-8,4:98.2
-6,-8,4:98.1
-5,-8,4:102
-4,-8,4:102
-3,-8,4:102
-2,-8,4:98.0
-1,-8,4:98.1
0,-8,4:98.2
1,-8,4:98.0
2,-8,4:102
3,-8,4:102
4,-8,4:102
5,-8,4:98.2
6,-8,4:98.0
7,-8,4:98.0
-8,-7,4:98.0
-6,-7,4:76.3
-2,-7,4:4
1,-7,4:4
5,-7,4:76.3
7,-7,4:98.1
-8,-6,4:98.0
-2,-6,4:48
-1,-6,4:5.0
0,-6,4:5.0
1,-6,4:4
7,-6,4:98.2
-8,-5,4:102
-2,-5,4:1
-1,-5,4:53.3
0,-5,4:53.3
1,-5,4:48
7,-5,4:102
-8,-4,4:102
7,-4,4:102
-8,-3,4:102
7,-3,4:102
-8,-2,4:98.2
-7,-2,4:76.1
6,-2,4:76.2
7,-2,4:98.0
-8,-1,4:98.0
7,-1,4:98.2
-8,0,4:98.2
7,0,4:98.2
-8,1,4:98.1
-7,1,4:76.1
6,1,4:76.2
7,1,4:98.1
-8,2,4:102
7,2,4:102
-8,3,4:102
7,3,4:102
-8,4,4:102
7,4,4:102
-8,5,4:98.1
7,5,4:98.0
-8,6,4:98.0
-2,6,4:76.4
1,6,4:76.4
7,6,4:98.1
-8,7,4:98.1
-7,7,4:98.0
-6,7,4:98.2
-5,7,4:102
-4,7,4:102
-3,7,4:102
-2,7,4:98.1
-1,7,4:98.0
0,7,4:98.0
1,7,4:98.0
2,7,4:102
3,7,4:102
4,7,4:102
5,7,4:98.0
6,7,4:98.1
7,7,4:98.1
-9,-9,5:4
-8,-9,5:1
-7,-9,5:48
-6,-9,5:1
-5,-9,5:4
-4,-9,5:48
-3,-9,5:48
-2,-9,5:4
-1,-9,5:4
0,-9,5:1
1,-9,5:4
2,-9,5:4
3,-9,5:4
4,-9,5:4
5,-9,5:1
6,-9,5:4
7,-9,5:1
8,-9,5:4
-9,-8,5:4
-8,-8,5:1
-7,-8,5:4
-6,-8,5:4
-5,-8,5:4
-4,-8,5:48
-3,-8,5:4
-2,-8,5:1
-1,-8,5:48
0,-8,5:48
1,-8,5:48
2,-8,5:48
3,-8,5:4
4,-8,5:48
5,-8,5:4
6,-8,5:4
7,-8,5:4
8,-8,5:1
-9,-7,5:4
-8,-7,5:48
-7,-7,5:4
-6,-7,5:1
-5,-7,5:4
-4,-7,5:4
-3,-7,5:4
-2,-7,5:4
-1,-7,5:48
0,-7,5:48
1,-7,5:4
2,-7,5:4
3,-7,5:4
4,-7,5:1
5,-7,5:1
6,-7,5:4
7,-7,5:4
8,-7,5:48
-9,-6,5:48
-8,-6,5:1
-7,-6,5:4
-6,-6,5:4
-5,-6,5:1
-4,-6,5:4
-3,-6,5:48
-2,-6,5:1
-1,-6,5:53.3
0,-6,5:53.3
1,-6,5:4
2,-6,5:4
3,-6,5:4
4,-6,5:4
5,-6,5:4
6,-6,5:4
7,-6,5:48
8,-6,5:48
-9,-5,5:48
-8,-5,5:4
-7,-5,5:4
-6,-5,5:4
-5,-5,5:1
-4,-5,5:4
-3,-5,5:1
-2,-5,5:1
1,-5,5:4
2,-5,5:4
3,-5,5:4
4,-5,5:1
5,-5,5:4
6,-5,5:48
7,-5,5:4
8,-5,5:48
-9,-4,5:1
-8,-4,5:4
-7,-4,5:48
-6,-4,5:4
-5,-4,5:4
-4,-4,5:4
-3,-4,5:4
-2,-4,5:1
1,-4,5:4
2,-4,5:4
3,-4,5:1
4,-4,5:4
5,-4,5:4
6,-4,5:1
7,-4,5:1
8,-4,5:48
-9,-3,5:48
-8,-3,5:4
-7,-3,5:4
-6,-3,5:4
-5,-3,5:1
-4,-3,5:4
-3,-3,5:48
-2,-3,5:4
1,-3,5:48
2,-3,5:1
3,-3,5:48
4,-3,5:4
5,-3,5:4
6,-3,5:1
7,-3,5:4
8,-3,5:1
-9,-2,5:1
-8,-2,5:48
-7,-2,5:4
-6,-2,5:4
-5,-2,5:4
-4,-2,5:4
-3,-2,5:4
-2,-2,5:48
-1,-2,5:4
0,-2,5:4
1,-2,5:4
2,-2,5:4
3,-2,5:4
4,-2,5:1
5,-2,5:4
6,-2,5:4
7,-2,5:4
8,-2,5:4
-9,-1,5:48
-8,-1,5:48
-7,-1,5:4
-6,-1,5:4
-5,-1,5:48
-4,-1,5:4
-3,-1,5:48
-2,-1,5:4
-1,-1,5:1
0,-1,5:4
1,-1,5:4
2,-1,5:48
3,-1,5:4
4,-1,5:4
5,-1,5:1
6,-1,5:4
7,-1,5:48
8,-1,5:4
-9,0,5:4
-8,0,5:48
-7,0,5:48
-6,0,5:48
-5,0,5:4
-4,0,5:48
-3,0,5:4
-2,0,5:4
-1,0,5:4
0,0,5:4
1,0,5:4
2,0,5:4
3,0,5:4
4,0,5:4
5,0,5:4
6,0,5:48
7,0,5:1
8,0,5:4
-9,1,5:4
-8,1,5:1
-7,1,5:4
-6,1,5:4
-5,1,5:4
-4,1,5:4
-3,1,5:1
-2,1,5:4
-1,1,5:4
0,1,5:4
1,1,5:1
2,1,5:4
3,1,5:1
4,1,5:4
5,1,5:4
6,1,5:4
7,1,5:4
8,1,5:4
-9,2,5:4
-8,2,5:4
-7,2,5:4
-6,2,5:4
-5,2,5:4
-4,2,5:4
-3,2,5:48
-2,2,5:1
-1,2,5:4
0,2,5:48
1,2,5:4
2,2,5:4
3,2,5:4
4,2,5:4
5,2,5:4
6,2,5:4
7,2,5:1
8,2,5:48
-9,3,5:4
-8,3,5:1
-7,3,5:4
-6,3,5:4
-5,3,5:4
-4,3,5:4
-3,3,5:4
-2,3,5:48
-1,3,5:48
0,3,5:1
1,3,5:4
2,3,5:4
3,3,5:48
4,3,5:4
5,3,5:1
6,3,5:4
7,3,5:48
8,3,5:4
-9,4,5:1
-8,4,5:4
-7,4,5:1
-6,4,5:4
-5,4,5:4
-4,4,5:4
-3,4,5:4
-2,4,5:4
-1,4,5:4
0,4,5:4
1,4,5:4
2,4,5:4
3,4,5:4
4,4,5:4
5,4,5:4
6,4,5:1
7,4,5:4
8,4,5:4
-9,5,5:48
-8,5,5:4
-7,5,5:4
-6,5,5:4
-5,5,5:48
-4,5,5:4
-3,5,5:4
-2,5,5:4
-1,5,5:4
0,5,5:48
1,5,5:4
2,5,5:4
3,5,5:4
4,5,5:4
5,5,5:4
6,5,5:1
7,5,5:4
8,5,5:4
-9,6,5:4
-8,6,5:4
-7,6,5:4
-6,6,5:4
-5,6,5:4
-4,6,5:4
-3,6,5:1
-2,6,5:48
-1,6,5:4
0,6,5:48
1,6,5:1
2,6,5:1
3,6,5:1
4,6,5:4
5,6,5:1
6,6,5:1
7,6,5:4
8,6,5:4
-9,7,5:4
-8,7,5:4
-7,7,5:4
-6,7,5:4
-5,7,5:1
-4,7,5:4
-3,7,5:1
-2,7,5:4
-1,7,5:4
0,7,5:1
1,7,5:4
2,7,5:4
3,7,5:4
4,7,5:4
5,7,5:4
6,7,5:4
7,7,5:1
8,7,5:4
-9,8,5:48
-8,8,5:48
-7,8,5:4
-6,8,5:4
-5,8,5:48
-4,8,5:4
-3,8,5:48
-2,8,5:1
-1,8,5:4
0,8,5:4
1,8,5:4
2,8,5:4
3,8,5:4
4,8,5:1
5,8,5:4
6,8,5:4
7,8,5:4
8,8,5:4
-9,-9,6:98.0
-8,-9,6:98.0
-7,-9,6:98.0
-6,-9,6:98.0
-5,-9,6:98.0
-4,-9,6:98.0
-3,-9,6:98.0
-2,-9,6:98.0
-1,-9,6:98.0
0,-9,6:98.0
1,-9,6:98.0
2,-9,6:98.0
3,-9,6:98.0
4,-9,6:98.0
5,-9,6:98.0
6,-9,6:98.0
7,-9,6:98.0
8,-9,6:98.0
-8,-8,6:1
7,-8,6:1
-8,-7,6:1
-7,-7,6:98.0
-6,-7,6:98.0
-5,-7,6:98.0
-4,-7,6:98.0
-3,-7,6:98.0
-2,-7,6:98.0
-1,-7,6:98.0
0,-7,6:98.0
1,-7,6:98.0
2,-7,6:98.0
3,-7,6:98.0
4,-7,6:98.0
5,-7,6:98.0
6,-7,6:98.0
7,-7,6:1
-8,-6,6:1
-7,-6,6:98.0
-6,-6,6:30
6,-6,6:98.0
7,-6,6:1
-8,-5,6:1
-7,-5,6:98.0
5,-5,6:89
6,-5,6:98.0
7,-5,6:1
-8,-4,6:1
-7,-4,6:98.0
6,-4,6:98.0
7,-4,6:1
-8,-3,6:1
-7,-3,6:98.0
4,-3,6:55
6,-3,6:98.0
7,-3,6:1
-8,-2,6:1
-7,-2,6:98.0
3,-2,6:55
4,-2,6:55
6,-2,6:98.0
7,-2,6:1
-8,-1,6:1
-7,-1,6:98.0
-5,-1,6:55
6,-1,6:98.0
7,-1,6:1
-8,0,6:1
-7,0,6:98.0
-1,0,6:55
6,0,6:98.0
7,0,6:1
-8,1,6:1
-7,1,6:98.0
-1,1,6:55
6,1,6:98.0
7,1,6:1
-7,2,6:98.0
-1,2,6:55
6,2,6:98.0
7,2,6:1
-8,3,6:1
-7,3,6:98.0
-5,3,6:89
1,3,6:55
4,3,6:55
6,3,6:98.0
7,3,6:1
-8,4,6:1
-7,4,6:98.0
6,4,6:98.0
7,4,6:1
-8,5,6:1
-7,5,6:98.0
6,5,6:98.0
7,5,6:1
-8,6,6:1
-7,6,6:98.0
-6,6,6:98.0
-5,6,6:98.0
-4,6,6:98.0
-3,6,6:98.0
-2,6,6:98.0
-1,6,6:98.0
0,6,6:98.0
1,6,6:98.0
2,6,6:98.0
3,6,6:98.0
4,6,6:98.0
5,6,6:98.0
6,6,6:98.0
7,6,6:1
-8,7,6:1
7,7,6:1
-9,8,6:98.0
-8,8,6:98.0
-7,8,6:98.0
-6,8,6:98.0
-5,8,6:98.0
-4,8,6:98.0
-3,8,6:98.0
-2,8,6:98.0
-1,8,6:98.0
0,8,6:98.0
1,8,6:98.0
2,8,6:98.0
3,8,6:98.0
4,8,6:98.0
5,8,6:98.0
6,8,6:98.0
7,8,6:98.0
8,8,6:98.0
-9,-9,7:98.0
-8,-9,7:98.0
-7,-9,7:98.0
-6,-9,7:98.0
-5,-9,7:98.0
-4,-9,7:98.0
-3,-9,7:98.0
-2,-9,7:98.0
-1,-9,7:98.0
0,-9,7:98.0
1,-9,7:98.0
2,-9,7:98.0
3,-9,7:98.0
4,-9,7:98.0
5,-9,7:98.0
6,-9,7:98.0
7,-9,7:98.0
8,-9,7:98.0
-8,-8,7:1
7,-8,7:1
-8,-7,7:1
7,-7,7:1
-8,-6,7:1
7,-6,7:1
-8,-5,7:1
7,-5,7:1
-8,-4,7:1
7,-4,7:1
-8,-3,7:1
7,-3,7:1
-8,-2,7:1
7,-2,7:1
-8,-1,7:1
7,-1,7:1
7,0,7:1
7,1,7:1
7,2,7:1
-8,3,7:1
7,3,7:1
-8,4,7:1
7,4,7:1
-8,5,7:1
6,5,7:89
7,5,7:1
-8,6,7:1
7,6,7:1
-8,7,7:1
7,7,7:1
-9,8,7:98.0
-8,8,7:98.0
-7,8,7:98.0
-6,8,7:98.0
-5,8,7:98.0
-4,8,7:98.0
-3,8,7:98.0
-2,8,7:98.0
-1,8,7:98.0
0,8,7:98.0
1,8,7:98.0
2,8,7:98.0
3,8,7:98.0
4,8,7:98.0
5,8,7:98.0
6,8,7:98.0
7,8,7:98.0
8,8,7:98.0
