[META]
version=2.0
spawnOnBlockType=13
spawnSunlight=True
spawnDarkness=False
spawnWater=False
spawnLava=False
underFill=True
randomRotation=True
dig=True
tree=False
branch=False
needsFoundation=True
rarity=2
collisionPercentage=2
spawnElevationMin=0
spawnElevationMax=128
spawnInBiome=Flat
[DATA]
-8,-8,0:43.0
-7,-8,0:43.0
-6,-8,0:43.0
-5,-8,0:43.0
-4,-8,0:43.0
-3,-8,0:43.0
-2,-8,0:43.0
-1,-8,0:43.0
0,-8,0:43.0
1,-8,0:43.0
2,-8,0:43.0
3,-8,0:43.0
4,-8,0:43.0
5,-8,0:43.0
6,-8,0:43.0
7,-8,0:43.0
8,-8,0:43.0
-8,-7,0:43.0
-7,-7,0:4
-6,-7,0:4
-5,-7,0:4
-4,-7,0:4
-3,-7,0:4
-2,-7,0:4
-1,-7,0:4
0,-7,0:4
1,-7,0:4
2,-7,0:4
3,-7,0:4
4,-7,0:4
5,-7,0:4
6,-7,0:4
7,-7,0:4
8,-7,0:43.0
-8,-6,0:43.0
-7,-6,0:4
-6,-6,0:1
-5,-6,0:48
-4,-6,0:4
-3,-6,0:4
-2,-6,0:1
-1,-6,0:48
0,-6,0:48
1,-6,0:1
2,-6,0:1
3,-6,0:48
4,-6,0:48
5,-6,0:4
6,-6,0:1
7,-6,0:4
8,-6,0:43.0
-8,-5,0:43.0
-7,-5,0:4
-6,-5,0:4
-5,-5,0:48
-4,-5,0:1
-3,-5,0:4
-2,-5,0:4
-1,-5,0:1
0,-5,0:1
1,-5,0:48
2,-5,0:1
3,-5,0:48
4,-5,0:4
5,-5,0:4
6,-5,0:4
7,-5,0:4
8,-5,0:43.0
-8,-4,0:43.0
-7,-4,0:4
-6,-4,0:48
-5,-4,0:48
-4,-4,0:48
-3,-4,0:1
-2,-4,0:4
-1,-4,0:48
0,-4,0:1
1,-4,0:4
2,-4,0:4
3,-4,0:48
4,-4,0:1
5,-4,0:1
6,-4,0:4
7,-4,0:4
8,-4,0:43.0
-8,-3,0:43.0
-7,-3,0:4
-6,-3,0:1
-5,-3,0:48
-4,-3,0:48
-3,-3,0:4
-2,-3,0:1
-1,-3,0:48
0,-3,0:48
1,-3,0:1
2,-3,0:1
3,-3,0:48
4,-3,0:48
5,-3,0:48
6,-3,0:1
7,-3,0:4
8,-3,0:43.0
-8,-2,0:43.0
-7,-2,0:4
-6,-2,0:1
-5,-2,0:1
-4,-2,0:48
-3,-2,0:1
-2,-2,0:4
-1,-2,0:4
0,-2,0:4
1,-2,0:4
2,-2,0:1
3,-2,0:4
4,-2,0:48
5,-2,0:48
6,-2,0:4
7,-2,0:4
8,-2,0:43.0
-8,-1,0:43.0
-7,-1,0:4
-6,-1,0:4
-5,-1,0:4
-4,-1,0:1
-3,-1,0:1
-2,-1,0:1
-1,-1,0:48
0,-1,0:48
1,-1,0:1
2,-1,0:1
3,-1,0:4
4,-1,0:48
5,-1,0:1
6,-1,0:48
7,-1,0:4
8,-1,0:43.0
-8,0,0:43.0
-7,0,0:4
-6,0,0:48
-5,0,0:48
-4,0,0:4
-3,0,0:48
-2,0,0:1
-1,0,0:48
0,0,0:4
1,0,0:1
2,0,0:1
3,0,0:1
4,0,0:1
5,0,0:48
6,0,0:48
7,0,0:4
8,0,0:43.0
-8,1,0:43.0
-7,1,0:4
-6,1,0:4
-5,1,0:1
-4,1,0:4
-3,1,0:48
-2,1,0:1
-1,1,0:4
0,1,0:1
1,1,0:48
2,1,0:1
3,1,0:4
4,1,0:48
5,1,0:1
6,1,0:4
7,1,0:4
8,1,0:43.0
-8,2,0:43.0
-7,2,0:4
-6,2,0:1
-5,2,0:48
-4,2,0:48
-3,2,0:48
-2,2,0:48
-1,2,0:1
0,2,0:4
1,2,0:48
2,2,0:1
3,2,0:1
4,2,0:1
5,2,0:48
6,2,0:4
7,2,0:4
8,2,0:43.0
-8,3,0:43.0
-7,3,0:4
-6,3,0:1
-5,3,0:4
-4,3,0:1
-3,3,0:4
-2,3,0:1
-1,3,0:4
0,3,0:4
1,3,0:1
2,3,0:48
3,3,0:48
4,3,0:1
5,3,0:48
6,3,0:1
7,3,0:4
8,3,0:43.0
-8,4,0:43.0
-7,4,0:4
-6,4,0:48
-5,4,0:48
-4,4,0:1
-3,4,0:48
-2,4,0:48
-1,4,0:48
0,4,0:1
1,4,0:4
2,4,0:4
3,4,0:4
4,4,0:1
5,4,0:48
6,4,0:4
7,4,0:4
8,4,0:43.0
-8,5,0:43.0
-7,5,0:4
-6,5,0:48
-5,5,0:1
-4,5,0:4
-3,5,0:4
-2,5,0:48
-1,5,0:4
0,5,0:48
1,5,0:48
2,5,0:1
3,5,0:1
4,5,0:48
5,5,0:1
6,5,0:4
7,5,0:4
8,5,0:43.0
-8,6,0:43.0
-7,6,0:4
-6,6,0:4
-5,6,0:48
-4,6,0:4
-3,6,0:1
-2,6,0:48
-1,6,0:4
0,6,0:4
1,6,0:48
2,6,0:1
3,6,0:1
4,6,0:1
5,6,0:4
6,6,0:1
7,6,0:4
8,6,0:43.0
-8,7,0:43.0
-7,7,0:4
-6,7,0:4
-5,7,0:4
-4,7,0:4
-3,7,0:4
-2,7,0:4
-1,7,0:4
0,7,0:4
1,7,0:4
2,7,0:4
3,7,0:4
4,7,0:4
5,7,0:4
6,7,0:4
7,7,0:4
8,7,0:43.0
-8,8,0:43.0
-7,8,0:43.0
-6,8,0:43.0
-5,8,0:43.0
-4,8,0:43.0
-3,8,0:43.0
-2,8,0:43.0
-1,8,0:43.0
0,8,0:43.0
1,8,0:43.0
2,8,0:43.0
3,8,0:43.0
4,8,0:43.0
5,8,0:43.0
6,8,0:43.0
7,8,0:43.0
8,8,0:43.0
-8,-8,1:98.0
8,-8,1:98.2
-7,-7,1:48
-6,-7,1:20
-5,-7,1:48
-4,-7,1:20
-3,-7,1:4
-2,-7,1:20
-1,-7,1:4
0,-7,1:20
1,-7,1:48
2,-7,1:20
3,-7,1:4
4,-7,1:20
5,-7,1:1
6,-7,1:20
7,-7,1:48
-7,-6,1:20
7,-6,1:20
-7,-5,1:4
7,-5,1:48
-7,-4,1:20
7,-4,1:20
-7,-3,1:1
7,-3,1:1
-7,-2,1:20
7,-2,1:20
-7,-1,1:4
7,-1,1:1
-7,0,1:20
7,0,1:20
-7,1,1:1
7,1,1:4
-7,2,1:20
7,2,1:20
-7,3,1:1
7,3,1:48
-7,4,1:20
7,4,1:20
-7,5,1:4
7,5,1:4
-7,6,1:20
7,6,1:20
-7,7,1:1
-6,7,1:20
-5,7,1:1
-4,7,1:20
-3,7,1:1
-2,7,1:20
-1,7,1:4
0,7,1:20
1,7,1:1
2,7,1:20
3,7,1:4
4,7,1:20
5,7,1:48
6,7,1:20
7,7,1:1
-8,8,1:98.2
8,8,1:98.2
-8,-8,2:98.0
8,-8,2:98.0
-7,-7,2:1
-6,-7,2:20
-5,-7,2:48
-4,-7,2:20
-3,-7,2:48
-2,-7,2:20
-1,-7,2:4
0,-7,2:20
1,-7,2:4
2,-7,2:20
3,-7,2:1
4,-7,2:20
5,-7,2:48
6,-7,2:20
7,-7,2:1
-7,-6,2:20
7,-6,2:20
-7,-5,2:1
7,-5,2:4
-7,-4,2:20
7,-4,2:20
-7,-3,2:4
7,-3,2:48
-7,-2,2:20
7,-2,2:20
-7,-1,2:4
7,-1,2:48
-7,0,2:20
7,0,2:20
-7,1,2:48
7,1,2:1
-7,2,2:20
7,2,2:20
-7,3,2:48
7,3,2:48
-7,4,2:20
7,4,2:20
-7,5,2:4
7,5,2:48
-7,6,2:20
7,6,2:20
-7,7,2:4
-6,7,2:20
-5,7,2:4
-4,7,2:20
-3,7,2:1
-2,7,2:20
-1,7,2:48
0,7,2:20
1,7,2:1
2,7,2:20
3,7,2:4
4,7,2:20
5,7,2:4
6,7,2:20
7,7,2:1
-8,8,2:98.2
8,8,2:98.0
-8,-8,3:98.1
8,-8,3:98.2
-7,-7,3:48
-6,-7,3:20
-5,-7,3:4
-4,-7,3:20
-3,-7,3:48
-2,-7,3:20
-1,-7,3:4
0,-7,3:20
1,-7,3:48
2,-7,3:20
3,-7,3:48
4,-7,3:20
5,-7,3:48
6,-7,3:20
7,-7,3:48
-7,-6,3:20
7,-6,3:20
-7,-5,3:4
7,-5,3:48
-7,-4,3:20
7,-4,3:20
-7,-3,3:48
7,-3,3:1
-7,-2,3:20
7,-2,3:20
-7,-1,3:48
7,-1,3:48
-7,0,3:20
7,0,3:20
-7,1,3:4
7,1,3:4
-7,2,3:20
-7,3,3:48
-7,4,3:20
-7,5,3:1
7,5,3:48
-7,6,3:20
7,6,3:20
-7,7,3:1
-6,7,3:20
-5,7,3:1
-4,7,3:20
-3,7,3:1
-2,7,3:20
-1,7,3:48
0,7,3:20
1,7,3:1
2,7,3:20
6,7,3:20
7,7,3:48
-8,8,3:98.0
8,8,3:98.2
-8,-8,4:43.0
-7,-8,4:43.0
-6,-8,4:43.0
-5,-8,4:43.0
-4,-8,4:43.0
-3,-8,4:43.0
-2,-8,4:43.0
-1,-8,4:43.0
0,-8,4:43.0
1,-8,4:43.0
2,-8,4:43.0
3,-8,4:43.0
4,-8,4:43.0
5,-8,4:43.0
6,-8,4:43.0
7,-8,4:43.0
8,-8,4:43.0
-8,-7,4:43.0
-7,-7,4:4
-6,-7,4:4
-5,-7,4:4
-4,-7,4:4
-3,-7,4:4
-2,-7,4:4
-1,-7,4:4
0,-7,4:4
1,-7,4:4
2,-7,4:4
3,-7,4:4
4,-7,4:4
5,-7,4:4
6,-7,4:4
7,-7,4:4
8,-7,4:43.0
-8,-6,4:43.0
-7,-6,4:4
-6,-6,4:48
-5,-6,4:1
-4,-6,4:4
-3,-6,4:4
-2,-6,4:48
-1,-6,4:48
0,-6,4:1
1,-6,4:4
2,-6,4:48
3,-6,4:1
4,-6,4:48
5,-6,4:1
6,-6,4:48
7,-6,4:4
8,-6,4:43.0
-8,-5,4:43.0
-7,-5,4:4
-6,-5,4:48
-5,-5,4:1
-4,-5,4:1
-3,-5,4:48
-2,-5,4:1
-1,-5,4:1
0,-5,4:48
1,-5,4:4
2,-5,4:48
3,-5,4:4
4,-5,4:1
5,-5,4:1
6,-5,4:4
7,-5,4:4
8,-5,4:43.0
-8,-4,4:43.0
-7,-4,4:4
-6,-4,4:4
-5,-4,4:1
-4,-4,4:48
-3,-4,4:48
-2,-4,4:4
-1,-4,4:48
0,-4,4:48
1,-4,4:1
2,-4,4:48
3,-4,4:48
4,-4,4:1
5,-4,4:1
6,-4,4:1
7,-4,4:4
8,-4,4:43.0
-8,-3,4:43.0
-7,-3,4:4
-6,-3,4:4
-5,-3,4:48
-4,-3,4:1
-3,-3,4:48
-2,-3,4:48
-1,-3,4:1
0,-3,4:4
1,-3,4:48
2,-3,4:1
3,-3,4:48
4,-3,4:4
5,-3,4:4
6,-3,4:1
7,-3,4:4
8,-3,4:43.0
-8,-2,4:43.0
-7,-2,4:4
-6,-2,4:1
-5,-2,4:48
-4,-2,4:48
-3,-2,4:1
-2,-2,4:48
-1,-2,4:1
0,-2,4:1
1,-2,4:4
2,-2,4:48
3,-2,4:4
4,-2,4:1
5,-2,4:1
6,-2,4:1
7,-2,4:4
8,-2,4:43.0
-8,-1,4:43.0
-7,-1,4:4
-6,-1,4:48
-5,-1,4:1
-4,-1,4:4
-3,-1,4:48
-2,-1,4:1
-1,-1,4:1
0,-1,4:1
1,-1,4:4
2,-1,4:48
3,-1,4:4
4,-1,4:1
5,-1,4:1
6,-1,4:1
7,-1,4:4
8,-1,4:43.0
-8,0,4:43.0
-7,0,4:4
-6,0,4:48
-5,0,4:1
-4,0,4:4
-3,0,4:4
-2,0,4:1
-1,0,4:1
0,0,4:1
1,0,4:1
2,0,4:1
3,0,4:1
4,0,4:1
5,0,4:4
6,0,4:48
7,0,4:4
8,0,4:43.0
-8,1,4:43.0
-7,1,4:4
-6,1,4:4
-5,1,4:48
-4,1,4:1
-3,1,4:1
-2,1,4:48
-1,1,4:48
0,1,4:4
1,1,4:4
2,1,4:4
3,1,4:48
4,1,4:4
-8,2,4:43.0
-7,2,4:4
-6,2,4:1
-5,2,4:48
-4,2,4:1
-3,2,4:48
-2,2,4:4
-1,2,4:1
0,2,4:48
1,2,4:1
2,2,4:48
3,2,4:4
4,2,4:4
-8,3,4:43.0
-7,3,4:4
-6,3,4:4
-5,3,4:4
-4,3,4:4
-3,3,4:1
-2,3,4:48
-1,3,4:1
0,3,4:48
1,3,4:1
2,3,4:1
3,3,4:1
4,3,4:4
-8,4,4:43.0
-7,4,4:4
-6,4,4:4
-5,4,4:1
-4,4,4:1
-3,4,4:1
-2,4,4:1
-1,4,4:4
0,4,4:48
1,4,4:4
2,4,4:4
3,4,4:4
4,4,4:48
-8,5,4:43.0
-7,5,4:4
-6,5,4:1
-5,5,4:4
-4,5,4:48
-3,5,4:4
-2,5,4:48
-1,5,4:1
0,5,4:4
1,5,4:1
-8,6,4:43.0
-7,6,4:4
-6,6,4:1
-5,6,4:1
-4,6,4:1
-3,6,4:1
-2,6,4:1
-1,6,4:4
0,6,4:4
1,6,4:1
7,6,4:4
8,6,4:43.0
-8,7,4:43.0
-7,7,4:4
-6,7,4:4
-5,7,4:4
-4,7,4:4
-3,7,4:4
-2,7,4:4
-1,7,4:4
0,7,4:4
1,7,4:4
-8,8,4:43.0
-7,8,4:43.0
-6,8,4:43.0
-5,8,4:43.0
-4,8,4:43.0
-3,8,4:43.0
-2,8,4:43.0
-1,8,4:43.0
0,8,4:43.0
1,8,4:43.0
-8,-8,5:98.1
8,-8,5:98.1
-7,-7,5:1
-6,-7,5:20
-5,-7,5:48
-4,-7,5:20
-3,-7,5:4
-2,-7,5:20
-1,-7,5:48
0,-7,5:20
1,-7,5:1
2,-7,5:20
3,-7,5:1
4,-7,5:20
5,-7,5:48
6,-7,5:20
7,-7,5:48
-7,-6,5:20
7,-6,5:20
-7,-5,5:4
7,-5,5:4
-7,-4,5:20
7,-4,5:20
-7,-3,5:1
7,-3,5:4
-7,-2,5:20
7,-2,5:20
-7,-1,5:48
7,-1,5:1
-7,0,5:20
-7,1,5:1
-7,2,5:20
-7,3,5:4
-7,4,5:20
-7,5,5:1
-7,6,5:20
-7,7,5:4
-6,7,5:20
-5,7,5:48
-4,7,5:20
-3,7,5:1
-2,7,5:20
-1,7,5:48
0,7,5:20
-8,8,5:98.2
-8,-8,6:98.1
8,-8,6:98.2
-7,-7,6:4
-6,-7,6:20
-5,-7,6:48
-4,-7,6:20
-3,-7,6:1
-2,-7,6:20
-1,-7,6:4
0,-7,6:20
1,-7,6:48
2,-7,6:20
3,-7,6:48
4,-7,6:20
5,-7,6:48
6,-7,6:20
7,-7,6:4
-7,-6,6:20
7,-6,6:20
-7,-5,6:4
7,-5,6:4
-7,-4,6:20
7,-4,6:20
-7,-3,6:1
7,-3,6:4
-7,-2,6:20
7,-2,6:20
-7,-1,6:48
7,-1,6:48
-7,0,6:20
-7,1,6:4
-7,2,6:20
-7,3,6:4
-7,4,6:20
-7,5,6:4
-7,6,6:20
-7,7,6:4
-6,7,6:20
-5,7,6:48
-4,7,6:20
-3,7,6:48
-2,7,6:20
-1,7,6:1
0,7,6:20
-8,8,6:98.2
-8,-8,7:98.2
8,-8,7:98.1
-7,-7,7:48
-6,-7,7:20
-5,-7,7:1
-4,-7,7:20
-3,-7,7:4
-2,-7,7:20
-1,-7,7:4
0,-7,7:20
1,-7,7:48
2,-7,7:20
3,-7,7:4
4,-7,7:20
5,-7,7:1
6,-7,7:20
7,-7,7:4
-7,-6,7:20
7,-6,7:20
-7,-5,7:4
7,-5,7:48
-7,-4,7:20
7,-4,7:20
-7,-3,7:4
7,-3,7:48
-7,-2,7:20
7,-2,7:20
-7,-1,7:1
7,-1,7:4
-7,0,7:20
-7,1,7:4
-7,2,7:20
-7,3,7:1
-7,4,7:20
-7,5,7:48
-7,6,7:20
-7,7,7:1
-6,7,7:20
-5,7,7:1
-4,7,7:20
-3,7,7:48
-2,7,7:20
-1,7,7:1
0,7,7:20
-8,8,7:98.1
-8,-8,8:43.0
-7,-8,8:43.0
-6,-8,8:43.0
-5,-8,8:43.0
-4,-8,8:43.0
-3,-8,8:43.0
-2,-8,8:43.0
-1,-8,8:43.0
0,-8,8:43.0
1,-8,8:43.0
2,-8,8:43.0
3,-8,8:43.0
4,-8,8:43.0
5,-8,8:43.0
6,-8,8:43.0
7,-8,8:43.0
8,-8,8:43.0
-8,-7,8:43.0
-7,-7,8:4
-6,-7,8:4
-5,-7,8:4
-4,-7,8:4
-3,-7,8:4
-2,-7,8:4
-1,-7,8:4
0,-7,8:4
1,-7,8:4
2,-7,8:4
3,-7,8:4
4,-7,8:4
5,-7,8:4
6,-7,8:4
7,-7,8:4
8,-7,8:43.0
-8,-6,8:43.0
-7,-6,8:4
-6,-6,8:48
-5,-6,8:1
-4,-6,8:4
-3,-6,8:48
-2,-6,8:4
-1,-6,8:1
0,-6,8:1
1,-6,8:48
2,-6,8:4
3,-6,8:4
4,-6,8:1
5,-6,8:48
6,-6,8:4
7,-6,8:4
8,-6,8:43.0
-8,-5,8:43.0
-7,-5,8:4
-6,-5,8:1
-5,-5,8:4
-4,-5,8:48
-3,-5,8:48
-2,-5,8:48
-1,-5,8:1
0,-5,8:1
1,-5,8:4
2,-5,8:1
3,-5,8:1
4,-5,8:1
5,-5,8:1
6,-5,8:48
7,-5,8:4
8,-5,8:43.0
-8,-4,8:43.0
-7,-4,8:4
-6,-4,8:4
-5,-4,8:1
-4,-4,8:48
-3,-4,8:1
-2,-4,8:4
-1,-4,8:4
0,-4,8:48
1,-4,8:1
2,-4,8:4
3,-4,8:1
4,-4,8:48
5,-4,8:1
6,-4,8:4
7,-4,8:4
8,-4,8:43.0
-8,-3,8:43.0
-7,-3,8:4
-6,-3,8:4
-5,-3,8:48
-4,-3,8:48
-3,-3,8:4
-2,-3,8:4
-1,-3,8:48
0,-3,8:1
1,-3,8:48
2,-3,8:4
3,-3,8:48
4,-3,8:4
5,-3,8:48
6,-3,8:48
7,-3,8:4
8,-3,8:43.0
-8,-2,8:43.0
-7,-2,8:4
-6,-2,8:1
-5,-2,8:1
-4,-2,8:4
-3,-2,8:4
-2,-2,8:4
-1,-2,8:48
0,-2,8:1
1,-2,8:4
2,-2,8:1
3,-2,8:1
4,-2,8:4
5,-2,8:1
6,-2,8:4
7,-2,8:4
8,-2,8:43.0
-8,-1,8:43.0
-7,-1,8:4
-6,-1,8:48
-5,-1,8:4
-4,-1,8:1
-3,-1,8:1
-2,-1,8:48
-1,-1,8:4
0,-1,8:4
1,-1,8:1
2,-1,8:1
3,-1,8:48
4,-1,8:48
5,-1,8:1
6,-1,8:4
7,-1,8:4
8,-1,8:43.0
-8,0,8:43.0
-7,0,8:4
-6,0,8:4
-5,0,8:4
-4,0,8:4
-3,0,8:4
-2,0,8:1
-1,0,8:48
0,0,8:1
1,0,8:4
2,0,8:1
3,0,8:48
4,0,8:48
5,0,8:48
6,0,8:1
7,0,8:4
8,0,8:43.0
-8,1,8:43.0
-7,1,8:4
-6,1,8:1
-5,1,8:1
-4,1,8:1
-3,1,8:48
-2,1,8:1
-1,1,8:4
0,1,8:48
1,1,8:1
2,1,8:4
3,1,8:1
4,1,8:4
-8,2,8:43.0
-7,2,8:4
-6,2,8:48
-5,2,8:1
-4,2,8:48
-3,2,8:48
-2,2,8:4
-1,2,8:48
0,2,8:1
1,2,8:4
2,2,8:1
3,2,8:4
4,2,8:48
-8,3,8:43.0
-7,3,8:4
-6,3,8:1
-5,3,8:1
-4,3,8:48
-3,3,8:1
-2,3,8:4
-1,3,8:4
0,3,8:48
1,3,8:1
2,3,8:1
3,3,8:48
4,3,8:1
-8,4,8:43.0
-7,4,8:4
-6,4,8:4
-5,4,8:4
-4,4,8:4
-3,4,8:1
-2,4,8:4
-1,4,8:48
0,4,8:4
1,4,8:48
2,4,8:1
3,4,8:1
4,4,8:1
-8,5,8:43.0
-7,5,8:4
-6,5,8:1
-5,5,8:1
-4,5,8:4
-3,5,8:1
-2,5,8:48
-1,5,8:4
0,5,8:1
1,5,8:48
-8,6,8:43.0
-7,6,8:4
-6,6,8:1
-5,6,8:4
-4,6,8:48
-3,6,8:4
-2,6,8:48
-1,6,8:4
0,6,8:1
1,6,8:4
-8,7,8:43.0
-7,7,8:4
-6,7,8:4
-5,7,8:4
-4,7,8:4
-3,7,8:4
-2,7,8:4
-1,7,8:4
0,7,8:4
1,7,8:4
-8,8,8:43.0
-7,8,8:43.0
-6,8,8:43.0
-5,8,8:43.0
-4,8,8:43.0
-3,8,8:43.0
-2,8,8:43.0
-1,8,8:43.0
0,8,8:43.0
1,8,8:43.0
-8,-8,9:98.2
8,-8,9:98.2
-7,-7,9:48
-6,-7,9:20
-5,-7,9:1
-4,-7,9:20
-3,-7,9:48
-2,-7,9:20
-1,-7,9:1
0,-7,9:20
1,-7,9:4
2,-7,9:20
3,-7,9:1
4,-7,9:20
5,-7,9:4
6,-7,9:20
7,-7,9:4
-7,-6,9:20
7,-6,9:20
-7,-5,9:4
7,-5,9:1
-7,-4,9:20
7,-4,9:20
-7,-3,9:48
7,-3,9:1
-7,-2,9:20
7,-2,9:20
-7,-1,9:1
7,-1,9:48
-7,0,9:20
7,0,9:20
-7,1,9:48
7,1,9:1
-7,2,9:20
-7,3,9:48
-7,4,9:20
-7,5,9:48
7,5,9:1
-7,6,9:20
-7,7,9:48
-6,7,9:20
-5,7,9:1
-4,7,9:20
-3,7,9:48
-2,7,9:20
-1,7,9:48
0,7,9:20
1,7,9:4
2,7,9:20
-8,8,9:98.1
-8,-8,10:98.1
8,-8,10:98.2
-7,-7,10:1
-6,-7,10:20
-5,-7,10:1
-4,-7,10:20
-3,-7,10:4
-2,-7,10:20
-1,-7,10:4
0,-7,10:20
1,-7,10:1
2,-7,10:20
3,-7,10:1
4,-7,10:20
5,-7,10:1
6,-7,10:20
7,-7,10:1
-7,-6,10:20
7,-6,10:20
-7,-5,10:48
7,-5,10:1
-7,-4,10:20
7,-4,10:20
-7,-3,10:1
7,-3,10:48
-7,-2,10:20
7,-2,10:20
-7,-1,10:48
7,-1,10:1
-7,0,10:20
7,0,10:20
-7,1,10:4
7,1,10:48
-7,2,10:20
7,2,10:20
-7,3,10:1
7,3,10:48
-7,4,10:20
7,4,10:20
-7,5,10:48
7,5,10:48
-7,6,10:20
7,6,10:20
-7,7,10:4
-6,7,10:20
-5,7,10:1
-4,7,10:20
-3,7,10:48
-2,7,10:20
-1,7,10:1
0,7,10:20
1,7,10:4
2,7,10:20
3,7,10:4
4,7,10:20
5,7,10:4
6,7,10:20
-8,8,10:98.0
-8,-8,11:98.2
8,-8,11:98.2
-7,-7,11:4
-6,-7,11:20
-5,-7,11:1
-4,-7,11:20
-3,-7,11:4
-2,-7,11:20
-1,-7,11:48
0,-7,11:20
1,-7,11:4
2,-7,11:20
3,-7,11:48
4,-7,11:20
5,-7,11:1
6,-7,11:20
7,-7,11:1
-7,-6,11:20
7,-6,11:20
-7,-5,11:1
7,-5,11:1
-7,-4,11:20
7,-4,11:20
-7,-3,11:48
7,-3,11:1
-7,-2,11:20
7,-2,11:20
-7,-1,11:4
7,-1,11:1
-7,0,11:20
7,0,11:20
-7,1,11:4
7,1,11:4
-7,2,11:20
7,2,11:20
-7,3,11:4
7,3,11:1
-7,4,11:20
7,4,11:20
-7,5,11:48
7,5,11:4
-7,6,11:20
7,6,11:20
-7,7,11:4
-6,7,11:20
-5,7,11:4
-4,7,11:20
-3,7,11:48
-2,7,11:20
-1,7,11:1
0,7,11:20
1,7,11:48
2,7,11:20
3,7,11:4
4,7,11:20
5,7,11:48
6,7,11:20
7,7,11:1
-8,8,11:98.1
8,8,11:98.2
-8,-8,12:43.0
-7,-8,12:43.0
-6,-8,12:43.0
-5,-8,12:43.0
-4,-8,12:43.0
-3,-8,12:43.0
-2,-8,12:43.0
-1,-8,12:43.0
0,-8,12:43.0
1,-8,12:43.0
2,-8,12:43.0
3,-8,12:43.0
4,-8,12:43.0
5,-8,12:43.0
6,-8,12:43.0
7,-8,12:43.0
8,-8,12:43.0
-8,-7,12:43.0
-7,-7,12:4
-6,-7,12:4
-5,-7,12:4
-4,-7,12:4
-3,-7,12:4
-2,-7,12:4
-1,-7,12:4
0,-7,12:4
1,-7,12:4
2,-7,12:4
3,-7,12:4
4,-7,12:4
5,-7,12:4
6,-7,12:4
7,-7,12:4
8,-7,12:43.0
-8,-6,12:43.0
-7,-6,12:4
-6,-6,12:48
-5,-6,12:48
-4,-6,12:48
-3,-6,12:48
-2,-6,12:1
-1,-6,12:1
0,-6,12:4
1,-6,12:4
2,-6,12:1
3,-6,12:1
4,-6,12:1
5,-6,12:1
6,-6,12:1
7,-6,12:4
8,-6,12:43.0
-8,-5,12:43.0
-7,-5,12:4
-6,-5,12:4
-5,-5,12:48
-4,-5,12:48
-3,-5,12:1
-2,-5,12:48
-1,-5,12:4
0,-5,12:1
1,-5,12:4
2,-5,12:4
3,-5,12:4
4,-5,12:48
5,-5,12:4
6,-5,12:4
7,-5,12:4
8,-5,12:43.0
-8,-4,12:43.0
-7,-4,12:4
-6,-4,12:4
-5,-4,12:4
-4,-4,12:48
-3,-4,12:4
-2,-4,12:4
-1,-4,12:4
0,-4,12:4
1,-4,12:4
2,-4,12:1
3,-4,12:4
4,-4,12:48
5,-4,12:4
6,-4,12:1
7,-4,12:4
8,-4,12:43.0
-8,-3,12:43.0
-7,-3,12:4
-6,-3,12:1
-5,-3,12:1
-4,-3,12:4
-3,-3,12:4
-2,-3,12:48
-1,-3,12:1
0,-3,12:1
1,-3,12:4
2,-3,12:4
3,-3,12:4
4,-3,12:48
5,-3,12:1
6,-3,12:1
7,-3,12:4
8,-3,12:43.0
-8,-2,12:43.0
-7,-2,12:4
-6,-2,12:48
-5,-2,12:48
-4,-2,12:4
-3,-2,12:4
-2,-2,12:1
-1,-2,12:1
0,-2,12:48
1,-2,12:4
2,-2,12:4
3,-2,12:48
4,-2,12:4
5,-2,12:1
6,-2,12:4
7,-2,12:4
8,-2,12:43.0
-8,-1,12:43.0
-7,-1,12:4
-6,-1,12:48
-5,-1,12:4
-4,-1,12:1
-3,-1,12:1
-2,-1,12:1
-1,-1,12:48
0,-1,12:48
1,-1,12:4
2,-1,12:4
3,-1,12:1
4,-1,12:48
5,-1,12:1
6,-1,12:4
7,-1,12:4
8,-1,12:43.0
-8,0,12:43.0
-7,0,12:4
-6,0,12:1
-5,0,12:1
-4,0,12:4
-3,0,12:4
-2,0,12:4
-1,0,12:4
0,0,12:4
1,0,12:1
2,0,12:1
3,0,12:48
4,0,12:1
5,0,12:4
6,0,12:1
7,0,12:4
8,0,12:43.0
-8,1,12:43.0
-7,1,12:4
-6,1,12:48
-5,1,12:4
-4,1,12:1
-3,1,12:4
-2,1,12:48
-1,1,12:48
0,1,12:4
1,1,12:4
2,1,12:4
3,1,12:1
4,1,12:4
5,1,12:48
6,1,12:4
7,1,12:4
8,1,12:43.0
-8,2,12:43.0
-7,2,12:4
-6,2,12:48
-5,2,12:4
-4,2,12:48
-3,2,12:1
-2,2,12:48
-1,2,12:1
0,2,12:1
1,2,12:4
2,2,12:4
3,2,12:48
4,2,12:1
5,2,12:48
6,2,12:1
7,2,12:4
8,2,12:43.0
-8,3,12:43.0
-7,3,12:4
-6,3,12:1
-5,3,12:48
-4,3,12:48
-3,3,12:1
-2,3,12:48
-1,3,12:1
0,3,12:4
1,3,12:1
2,3,12:1
3,3,12:4
4,3,12:4
5,3,12:4
6,3,12:48
7,3,12:4
8,3,12:43.0
-8,4,12:43.0
-7,4,12:4
-6,4,12:4
-5,4,12:1
-4,4,12:48
-3,4,12:48
-2,4,12:48
-1,4,12:1
0,4,12:48
1,4,12:4
2,4,12:1
3,4,12:48
4,4,12:4
5,4,12:48
6,4,12:4
7,4,12:4
8,4,12:43.0
-8,5,12:43.0
-7,5,12:4
-6,5,12:48
-5,5,12:4
-4,5,12:48
-3,5,12:1
-2,5,12:1
-1,5,12:4
0,5,12:1
1,5,12:4
2,5,12:1
3,5,12:4
4,5,12:48
5,5,12:48
6,5,12:1
7,5,12:4
8,5,12:43.0
-8,6,12:43.0
-7,6,12:4
-6,6,12:48
-5,6,12:48
-4,6,12:1
-3,6,12:48
-2,6,12:1
-1,6,12:48
0,6,12:48
1,6,12:48
2,6,12:1
3,6,12:4
4,6,12:48
5,6,12:4
6,6,12:1
7,6,12:4
8,6,12:43.0
-8,7,12:43.0
-7,7,12:4
-6,7,12:4
-5,7,12:4
-4,7,12:4
-3,7,12:4
-2,7,12:4
-1,7,12:4
0,7,12:4
1,7,12:4
2,7,12:4
3,7,12:4
4,7,12:4
5,7,12:4
6,7,12:4
7,7,12:4
8,7,12:43.0
-8,8,12:43.0
-7,8,12:43.0
-6,8,12:43.0
-5,8,12:43.0
-4,8,12:43.0
-3,8,12:43.0
-2,8,12:43.0
-1,8,12:43.0
0,8,12:43.0
1,8,12:43.0
2,8,12:43.0
3,8,12:43.0
4,8,12:43.0
5,8,12:43.0
6,8,12:43.0
7,8,12:43.0
8,8,12:43.0
-8,-8,13:98.0
8,-8,13:98.1
-7,-7,13:1
-6,-7,13:20
-5,-7,13:48
-4,-7,13:20
-3,-7,13:1
-2,-7,13:20
-1,-7,13:48
0,-7,13:20
1,-7,13:4
2,-7,13:20
3,-7,13:1
4,-7,13:20
5,-7,13:48
6,-7,13:20
7,-7,13:1
-7,-6,13:20
7,-6,13:20
-7,-5,13:4
7,-5,13:48
-7,-4,13:20
7,-4,13:20
-7,-3,13:48
7,-3,13:48
-7,-2,13:20
7,-2,13:20
-7,-1,13:1
7,-1,13:48
-7,0,13:20
7,0,13:20
-7,1,13:4
7,1,13:1
-7,2,13:20
7,2,13:20
-7,3,13:4
7,3,13:48
-7,4,13:20
7,4,13:20
-7,5,13:48
7,5,13:4
-7,6,13:20
7,6,13:20
-7,7,13:1
-6,7,13:20
-5,7,13:4
-4,7,13:20
-3,7,13:1
-2,7,13:20
-1,7,13:48
0,7,13:20
1,7,13:4
2,7,13:20
3,7,13:48
4,7,13:20
5,7,13:1
6,7,13:20
7,7,13:1
-8,8,13:98.2
8,8,13:98.2
-8,-8,14:98.1
-7,-7,14:48
-6,-7,14:20
-5,-7,14:48
-4,-7,14:20
-3,-7,14:1
-2,-7,14:20
-1,-7,14:4
0,-7,14:20
1,-7,14:1
2,-7,14:20
3,-7,14:4
4,-7,14:20
5,-7,14:48
6,-7,14:20
-7,-6,14:20
7,-6,14:20
-7,-5,14:1
7,-5,14:1
-7,-4,14:20
7,-4,14:20
-7,-3,14:48
7,-3,14:1
-7,-2,14:20
7,-2,14:20
-7,-1,14:1
7,-1,14:1
-7,0,14:20
7,0,14:20
-7,1,14:48
7,1,14:1
-7,2,14:20
7,2,14:20
-7,3,14:4
7,3,14:1
-7,4,14:20
7,4,14:20
-7,5,14:48
7,5,14:48
-7,6,14:20
7,6,14:20
-7,7,14:4
-6,7,14:20
-5,7,14:48
-4,7,14:20
-3,7,14:48
-2,7,14:20
-1,7,14:1
0,7,14:20
1,7,14:1
2,7,14:20
3,7,14:48
4,7,14:20
5,7,14:4
6,7,14:20
7,7,14:48
-8,8,14:98.1
8,8,14:98.2
-8,-8,15:98.0
-7,-7,15:4
-6,-7,15:20
-5,-7,15:4
-4,-7,15:20
-3,-7,15:1
-2,-7,15:20
-1,-7,15:48
0,-7,15:20
1,-7,15:1
2,-7,15:20
3,-7,15:1
4,-7,15:20
5,-7,15:4
-7,-6,15:20
-7,-5,15:4
7,-5,15:1
-7,-4,15:20
7,-4,15:20
-7,-3,15:48
7,-3,15:4
-7,-2,15:20
7,-2,15:20
-7,-1,15:4
7,-1,15:1
-7,0,15:20
7,0,15:20
-7,1,15:48
7,1,15:48
-7,2,15:20
7,2,15:20
-7,3,15:4
7,3,15:1
-7,4,15:20
7,4,15:20
-7,5,15:48
7,5,15:4
-7,6,15:20
7,6,15:20
-7,7,15:4
-6,7,15:20
-5,7,15:4
-4,7,15:20
-3,7,15:48
-2,7,15:20
-1,7,15:1
0,7,15:20
1,7,15:48
2,7,15:20
3,7,15:1
4,7,15:20
5,7,15:4
6,7,15:20
7,7,15:1
-8,8,15:98.1
8,8,15:98.1
-8,-8,16:43.0
-7,-8,16:43.0
-6,-8,16:43.0
-5,-8,16:43.0
-4,-8,16:43.0
-3,-8,16:43.0
-2,-8,16:43.0
-1,-8,16:43.0
0,-8,16:43.0
1,-8,16:43.0
2,-8,16:43.0
3,-8,16:43.0
4,-8,16:43.0
-8,-7,16:43.0
-7,-7,16:4
-6,-7,16:4
-5,-7,16:4
-4,-7,16:4
-3,-7,16:4
-2,-7,16:4
-1,-7,16:4
0,-7,16:4
1,-7,16:4
2,-7,16:4
3,-7,16:4
4,-7,16:4
-8,-6,16:43.0
-7,-6,16:4
-6,-6,16:48
-5,-6,16:1
-4,-6,16:4
-3,-6,16:48
-2,-6,16:4
-1,-6,16:1
0,-6,16:48
1,-6,16:4
2,-6,16:48
3,-6,16:48
4,-6,16:4
5,-6,16:1
-8,-5,16:43.0
-7,-5,16:4
-6,-5,16:48
-5,-5,16:1
-4,-5,16:4
-3,-5,16:1
-2,-5,16:1
-1,-5,16:1
0,-5,16:48
1,-5,16:48
2,-5,16:1
3,-5,16:1
4,-5,16:48
5,-5,16:48
6,-5,16:48
-8,-4,16:43.0
-7,-4,16:4
-6,-4,16:4
-5,-4,16:48
-4,-4,16:1
-3,-4,16:48
-2,-4,16:1
-1,-4,16:48
0,-4,16:48
1,-4,16:48
2,-4,16:48
3,-4,16:1
4,-4,16:1
5,-4,16:1
6,-4,16:1
7,-4,16:4
8,-4,16:43.0
-8,-3,16:43.0
-7,-3,16:4
-6,-3,16:4
-5,-3,16:1
-4,-3,16:4
-3,-3,16:1
-2,-3,16:48
-1,-3,16:4
0,-3,16:1
1,-3,16:48
2,-3,16:4
3,-3,16:1
4,-3,16:48
5,-3,16:48
6,-3,16:1
7,-3,16:4
8,-3,16:43.0
-8,-2,16:43.0
-7,-2,16:4
-6,-2,16:48
-5,-2,16:1
-4,-2,16:4
-3,-2,16:48
-2,-2,16:1
-1,-2,16:48
0,-2,16:4
1,-2,16:4
2,-2,16:4
3,-2,16:4
4,-2,16:48
5,-2,16:48
6,-2,16:48
7,-2,16:4
8,-2,16:43.0
-8,-1,16:43.0
-7,-1,16:4
-6,-1,16:48
-5,-1,16:4
-4,-1,16:48
-3,-1,16:48
-2,-1,16:1
-1,-1,16:4
0,-1,16:4
1,-1,16:48
2,-1,16:1
3,-1,16:48
4,-1,16:4
5,-1,16:1
6,-1,16:1
7,-1,16:4
8,-1,16:43.0
-8,0,16:43.0
-7,0,16:4
-6,0,16:4
-5,0,16:4
-4,0,16:48
-3,0,16:4
-2,0,16:4
-1,0,16:4
0,0,16:1
1,0,16:1
2,0,16:48
3,0,16:1
4,0,16:4
5,0,16:48
6,0,16:4
7,0,16:4
8,0,16:43.0
-8,1,16:43.0
-7,1,16:4
-6,1,16:4
-5,1,16:48
-4,1,16:1
-3,1,16:4
-2,1,16:1
-1,1,16:48
0,1,16:1
1,1,16:48
2,1,16:1
3,1,16:48
4,1,16:4
5,1,16:48
6,1,16:1
7,1,16:4
8,1,16:43.0
-8,2,16:43.0
-7,2,16:4
-6,2,16:4
-5,2,16:4
-4,2,16:1
-3,2,16:4
-2,2,16:4
-1,2,16:1
0,2,16:4
1,2,16:48
2,2,16:4
3,2,16:4
4,2,16:1
5,2,16:48
6,2,16:1
7,2,16:4
8,2,16:43.0
-8,3,16:43.0
-7,3,16:4
-6,3,16:1
-5,3,16:4
-4,3,16:1
-3,3,16:1
-2,3,16:1
-1,3,16:4
0,3,16:4
1,3,16:1
2,3,16:4
3,3,16:48
4,3,16:4
5,3,16:48
6,3,16:48
7,3,16:4
8,3,16:43.0
-8,4,16:43.0
-7,4,16:4
-6,4,16:1
-5,4,16:1
-4,4,16:48
-3,4,16:48
-2,4,16:4
-1,4,16:48
0,4,16:4
1,4,16:1
2,4,16:1
3,4,16:48
4,4,16:1
5,4,16:1
6,4,16:1
7,4,16:4
8,4,16:43.0
-8,5,16:43.0
-7,5,16:4
-6,5,16:1
-5,5,16:4
-4,5,16:4
-3,5,16:48
-2,5,16:4
-1,5,16:1
0,5,16:48
1,5,16:1
2,5,16:48
3,5,16:1
4,5,16:48
5,5,16:1
6,5,16:4
7,5,16:4
8,5,16:43.0
-8,6,16:43.0
-7,6,16:4
-6,6,16:4
-5,6,16:4
-4,6,16:1
-3,6,16:1
-2,6,16:48
-1,6,16:4
0,6,16:1
1,6,16:1
2,6,16:4
3,6,16:48
4,6,16:1
5,6,16:48
6,6,16:1
7,6,16:4
8,6,16:43.0
-8,7,16:43.0
-7,7,16:4
-6,7,16:4
-5,7,16:4
-4,7,16:4
-3,7,16:4
-2,7,16:4
-1,7,16:4
0,7,16:4
1,7,16:4
2,7,16:4
3,7,16:4
4,7,16:4
5,7,16:4
6,7,16:4
7,7,16:4
8,7,16:43.0
-8,8,16:43.0
-7,8,16:43.0
-6,8,16:43.0
-5,8,16:43.0
-4,8,16:43.0
-3,8,16:43.0
-2,8,16:43.0
-1,8,16:43.0
0,8,16:43.0
1,8,16:43.0
2,8,16:43.0
3,8,16:43.0
4,8,16:43.0
5,8,16:43.0
6,8,16:43.0
7,8,16:43.0
8,8,16:43.0
-8,-8,17:98.0
-7,-7,17:48
-6,-7,17:20
-5,-7,17:48
-4,-7,17:20
-3,-7,17:1
-2,-7,17:20
-1,-7,17:4
0,-7,17:20
1,-7,17:4
2,-7,17:20
3,-7,17:1
4,-7,17:20
-7,-6,17:20
-7,-5,17:1
-7,-4,17:20
7,-4,17:20
-7,-3,17:48
7,-3,17:1
-7,-2,17:20
7,-2,17:20
-7,-1,17:4
7,-1,17:4
-7,0,17:20
7,0,17:20
-7,1,17:48
7,1,17:1
-7,2,17:20
7,2,17:20
-7,3,17:4
7,3,17:48
-7,4,17:20
7,4,17:20
-7,5,17:48
7,5,17:48
-7,6,17:20
7,6,17:20
-7,7,17:4
-6,7,17:20
-5,7,17:1
-4,7,17:20
-3,7,17:1
-2,7,17:20
-1,7,17:48
0,7,17:20
1,7,17:4
2,7,17:20
3,7,17:4
4,7,17:20
5,7,17:1
6,7,17:20
7,7,17:4
-8,8,17:98.1
8,8,17:98.2
-8,-8,18:98.0
-7,-7,18:48
-6,-7,18:20
-5,-7,18:48
-4,-7,18:20
-3,-7,18:4
-2,-7,18:20
-1,-7,18:48
0,-7,18:20
1,-7,18:1
2,-7,18:20
3,-7,18:48
4,-7,18:20
-7,-6,18:20
-7,-5,18:1
-7,-4,18:20
7,-4,18:20
-7,-3,18:1
7,-3,18:48
-7,-2,18:20
7,-2,18:20
-7,-1,18:4
7,-1,18:48
-7,0,18:20
7,0,18:20
-7,1,18:1
7,1,18:4
-7,2,18:20
7,2,18:20
-7,3,18:4
7,3,18:4
-7,4,18:20
7,4,18:20
-7,5,18:4
7,5,18:1
-7,6,18:20
7,6,18:20
-7,7,18:4
-6,7,18:20
-5,7,18:1
-4,7,18:20
-3,7,18:48
-2,7,18:20
-1,7,18:48
0,7,18:20
1,7,18:48
2,7,18:20
3,7,18:48
4,7,18:20
5,7,18:1
6,7,18:20
7,7,18:48
-8,8,18:98.2
8,8,18:98.0
-8,-8,19:43.0
-7,-7,19:1
-6,-7,19:20
-5,-7,19:4
-4,-7,19:20
-3,-7,19:1
-2,-7,19:20
-1,-7,19:4
0,-7,19:20
1,-7,19:4
2,-7,19:20
3,-7,19:4
-7,-6,19:20
-7,-5,19:1
-7,-4,19:20
7,-4,19:20
8,-4,19:43.0
-7,-3,19:4
7,-3,19:4
-7,-2,19:20
7,-2,19:20
-7,-1,19:1
7,-1,19:1
-7,0,19:20
7,0,19:20
-7,1,19:1
7,1,19:4
-7,2,19:20
7,2,19:20
-7,3,19:1
7,3,19:4
-7,4,19:20
7,4,19:20
-7,5,19:48
7,5,19:1
-7,6,19:20
7,6,19:20
-7,7,19:1
-6,7,19:20
-5,7,19:1
-4,7,19:20
-3,7,19:4
-2,7,19:20
-1,7,19:4
0,7,19:20
1,7,19:48
2,7,19:20
3,7,19:1
4,7,19:20
5,7,19:4
6,7,19:20
7,7,19:4
-8,8,19:98.2
8,8,19:98.2
-8,-8,20:98.1
-7,-7,20:4
-6,-7,20:4
-5,-7,20:4
-4,-7,20:4
-3,-7,20:4
-2,-7,20:4
-1,-7,20:4
0,-7,20:4
1,-7,20:4
2,-7,20:4
-7,-6,20:4
-6,-6,20:48
-5,-6,20:4
-4,-6,20:4
-3,-6,20:1
-2,-6,20:1
-1,-6,20:48
0,-6,20:4
1,-6,20:48
2,-6,20:48
-7,-5,20:4
-6,-5,20:4
-5,-5,20:1
-4,-5,20:48
-3,-5,20:48
-2,-5,20:48
-1,-5,20:1
0,-5,20:4
1,-5,20:48
2,-5,20:1
3,-5,20:4
-7,-4,20:4
-6,-4,20:48
-5,-4,20:48
-4,-4,20:1
-3,-4,20:4
-2,-4,20:48
-1,-4,20:48
0,-4,20:1
1,-4,20:1
2,-4,20:48
3,-4,20:1
4,-4,20:4
-7,-3,20:4
-6,-3,20:1
-5,-3,20:48
-4,-3,20:48
-3,-3,20:4
-2,-3,20:4
-1,-3,20:1
0,-3,20:48
1,-3,20:48
2,-3,20:4
3,-3,20:1
4,-3,20:4
5,-3,20:1
6,-3,20:4
7,-3,20:4
-7,-2,20:4
-6,-2,20:4
-5,-2,20:48
-4,-2,20:48
-3,-2,20:48
-2,-2,20:4
-1,-2,20:1
0,-2,20:4
1,-2,20:4
2,-2,20:1
3,-2,20:4
4,-2,20:4
5,-2,20:1
6,-2,20:1
7,-2,20:4
-7,-1,20:4
-6,-1,20:1
-5,-1,20:4
-4,-1,20:4
-3,-1,20:1
-2,-1,20:4
-1,-1,20:4
0,-1,20:1
1,-1,20:1
2,-1,20:48
3,-1,20:1
4,-1,20:4
5,-1,20:4
6,-1,20:4
7,-1,20:4
-8,0,20:43.0
-7,0,20:4
-6,0,20:4
-5,0,20:4
-4,0,20:1
-3,0,20:1
-2,0,20:48
-1,0,20:48
0,0,20:4
1,0,20:48
2,0,20:48
3,0,20:4
4,0,20:48
5,0,20:1
6,0,20:4
7,0,20:4
8,0,20:43.0
-8,1,20:43.0
-7,1,20:4
-6,1,20:1
-5,1,20:4
-4,1,20:48
-3,1,20:4
-2,1,20:1
-1,1,20:4
0,1,20:48
1,1,20:4
2,1,20:4
3,1,20:48
4,1,20:1
5,1,20:1
6,1,20:1
7,1,20:4
8,1,20:43.0
-8,2,20:43.0
-7,2,20:4
-6,2,20:1
-5,2,20:48
-4,2,20:48
-3,2,20:4
-2,2,20:48
-1,2,20:4
0,2,20:4
1,2,20:1
2,2,20:48
3,2,20:4
4,2,20:4
5,2,20:48
6,2,20:1
7,2,20:4
8,2,20:43.0
-8,3,20:43.0
-7,3,20:4
-6,3,20:4
-5,3,20:48
-4,3,20:1
-3,3,20:1
-2,3,20:1
-1,3,20:48
0,3,20:48
1,3,20:4
2,3,20:1
3,3,20:48
4,3,20:4
5,3,20:4
6,3,20:1
7,3,20:4
8,3,20:43.0
-8,4,20:43.0
-7,4,20:4
-6,4,20:4
-5,4,20:1
-4,4,20:48
-3,4,20:48
-2,4,20:1
-1,4,20:1
0,4,20:48
1,4,20:4
2,4,20:1
3,4,20:1
4,4,20:1
5,4,20:1
6,4,20:4
7,4,20:4
8,4,20:43.0
-8,5,20:43.0
-7,5,20:4
-6,5,20:1
-5,5,20:4
-4,5,20:48
-3,5,20:48
-2,5,20:1
-1,5,20:48
0,5,20:1
1,5,20:4
2,5,20:48
3,5,20:1
4,5,20:4
5,5,20:48
6,5,20:1
7,5,20:4
8,5,20:43.0
-8,6,20:43.0
-7,6,20:4
-6,6,20:48
-5,6,20:4
-4,6,20:48
-3,6,20:1
-2,6,20:1
-1,6,20:1
0,6,20:1
1,6,20:48
2,6,20:48
3,6,20:4
4,6,20:48
5,6,20:48
6,6,20:48
7,6,20:4
8,6,20:43.0
-8,7,20:43.0
-7,7,20:4
-6,7,20:4
-5,7,20:4
-4,7,20:4
-3,7,20:4
-2,7,20:4
-1,7,20:4
0,7,20:4
1,7,20:4
2,7,20:4
3,7,20:4
4,7,20:4
5,7,20:4
6,7,20:4
7,7,20:4
8,7,20:43.0
-8,8,20:43.0
-7,8,20:43.0
-6,8,20:43.0
-5,8,20:43.0
-4,8,20:43.0
-3,8,20:43.0
-2,8,20:43.0
-1,8,20:43.0
0,8,20:43.0
1,8,20:43.0
2,8,20:43.0
3,8,20:43.0
4,8,20:43.0
5,8,20:43.0
6,8,20:43.0
7,8,20:43.0
8,8,20:43.0
-8,-8,21:43.0
4,-8,21:43.0
-7,-7,21:48
-6,-7,21:20
-5,-7,21:1
-4,-7,21:20
-3,-7,21:48
-2,-7,21:20
-1,-7,21:1
0,-7,21:20
1,-7,21:4
2,-7,21:20
-7,-6,21:20
-7,-5,21:4
-7,-4,21:20
8,-4,21:43.0
-7,-3,21:4
7,-3,21:1
-7,-2,21:20
7,-2,21:20
-7,-1,21:48
7,-1,21:48
-7,0,21:20
7,0,21:20
-7,1,21:48
7,1,21:4
-7,2,21:20
7,2,21:20
-7,3,21:4
7,3,21:4
-7,4,21:20
7,4,21:20
-7,5,21:48
7,5,21:48
-7,6,21:20
7,6,21:20
-7,7,21:1
-6,7,21:20
-5,7,21:48
-4,7,21:20
-3,7,21:48
-2,7,21:20
-1,7,21:1
0,7,21:20
1,7,21:1
2,7,21:20
3,7,21:4
4,7,21:20
5,7,21:4
6,7,21:20
7,7,21:1
-8,8,21:98.1
8,8,21:98.2
-7,-8,22:43.0
-6,-8,22:43.0
-5,-8,22:43.0
-4,-8,22:43.0
-3,-8,22:43.0
-2,-8,22:43.0
-1,-8,22:43.0
0,-8,22:43.0
1,-8,22:43.0
2,-8,22:43.0
3,-8,22:43.0
-8,-7,22:43.0
-7,-7,22:4
-6,-7,22:20
-5,-7,22:1
-4,-7,22:20
-3,-7,22:1
-2,-7,22:20
-1,-7,22:48
0,-7,22:20
1,-7,22:48
2,-7,22:20
4,-7,22:4
-8,-6,22:43.0
-7,-6,22:20
-8,-5,22:43.0
-7,-5,22:48
6,-5,22:48
-8,-4,22:43.0
-7,-4,22:20
7,-4,22:4
-8,-3,22:43.0
-7,-3,22:1
7,-3,22:4
8,-3,22:43.0
-8,-2,22:43.0
-7,-2,22:20
7,-2,22:20
8,-2,22:43.0
-8,-1,22:43.0
-7,-1,22:4
7,-1,22:4
8,-1,22:43.0
-7,0,22:20
7,0,22:20
-7,1,22:1
7,1,22:4
-7,2,22:20
7,2,22:20
-7,3,22:4
7,3,22:1
-7,4,22:20
7,4,22:20
-7,5,22:48
7,5,22:4
-7,6,22:20
7,6,22:20
-7,7,22:48
-6,7,22:20
-5,7,22:48
-4,7,22:20
-3,7,22:4
-2,7,22:20
-1,7,22:48
0,7,22:20
1,7,22:4
2,7,22:20
3,7,22:48
4,7,22:20
5,7,22:48
6,7,22:20
7,7,22:4
-8,8,22:98.1
8,8,22:98.0
-7,-7,23:4
-6,-7,23:20
-5,-7,23:4
-4,-7,23:20
-3,-7,23:4
-2,-7,23:20
-1,-7,23:1
0,-7,23:20
1,-7,23:1
2,-7,23:20
3,-7,23:4
-7,-6,23:20
4,-6,23:1
-7,-5,23:1
4,-5,23:1
5,-5,23:48
-7,-4,23:20
6,-4,23:48
-7,-3,23:48
7,-3,23:4
-7,-2,23:20
7,-2,23:20
-7,-1,23:4
7,-1,23:48
-7,0,23:20
7,0,23:20
-7,1,23:48
7,1,23:4
-7,2,23:20
7,2,23:20
-7,3,23:4
7,3,23:1
-7,4,23:20
7,4,23:20
-7,5,23:48
7,5,23:4
-7,6,23:20
7,6,23:20
-7,7,23:1
-6,7,23:20
-5,7,23:4
-4,7,23:20
-3,7,23:1
-2,7,23:20
-1,7,23:1
0,7,23:20
1,7,23:4
2,7,23:20
3,7,23:1
4,7,23:20
5,7,23:1
6,7,23:20
7,7,23:48
-8,8,23:98.2
8,8,23:98.2
-8,-8,24:1
-8,-7,24:1
-7,-7,24:1
-6,-7,24:4
-5,-7,24:4
-4,-7,24:4
-3,-7,24:4
-2,-7,24:4
-1,-7,24:4
0,-7,24:4
1,-7,24:4
2,-7,24:4
-7,-6,24:4
-6,-6,24:4
-5,-6,24:1
-4,-6,24:1
-3,-6,24:1
-2,-6,24:4
-1,-6,24:48
0,-6,24:48
1,-6,24:1
2,-6,24:48
3,-6,24:1
-7,-5,24:4
-6,-5,24:48
-5,-5,24:1
-4,-5,24:48
-3,-5,24:1
-2,-5,24:48
-1,-5,24:4
0,-5,24:1
1,-5,24:48
2,-5,24:4
3,-5,24:4
-7,-4,24:4
-6,-4,24:1
-5,-4,24:1
-4,-4,24:48
-3,-4,24:1
-2,-4,24:48
-1,-4,24:4
0,-4,24:1
1,-4,24:48
2,-4,24:1
3,-4,24:48
4,-4,24:4
5,-4,24:48
-7,-3,24:4
-6,-3,24:4
-5,-3,24:4
-4,-3,24:48
-3,-3,24:4
-2,-3,24:4
-1,-3,24:1
0,-3,24:1
1,-3,24:48
2,-3,24:1
3,-3,24:1
4,-3,24:48
5,-3,24:1
6,-3,24:1
-7,-2,24:4
-6,-2,24:48
-5,-2,24:4
-4,-2,24:1
-3,-2,24:4
-2,-2,24:48
-1,-2,24:1
0,-2,24:48
1,-2,24:48
2,-2,24:48
3,-2,24:48
4,-2,24:1
5,-2,24:4
6,-2,24:4
7,-2,24:4
-7,-1,24:4
-6,-1,24:4
-5,-1,24:4
-4,-1,24:1
-3,-1,24:48
-2,-1,24:4
-1,-1,24:48
0,-1,24:4
1,-1,24:48
2,-1,24:4
3,-1,24:1
4,-1,24:48
5,-1,24:1
6,-1,24:1
7,-1,24:4
-8,0,24:43.0
-7,0,24:4
-6,0,24:48
-5,0,24:4
-4,0,24:48
-3,0,24:4
-2,0,24:4
-1,0,24:1
0,0,24:48
1,0,24:1
2,0,24:1
3,0,24:1
4,0,24:4
5,0,24:4
6,0,24:48
7,0,24:4
8,0,24:43.0
-8,1,24:43.0
-7,1,24:4
-6,1,24:4
-5,1,24:4
-4,1,24:1
-3,1,24:1
-2,1,24:1
-1,1,24:48
0,1,24:1
1,1,24:1
2,1,24:1
3,1,24:1
4,1,24:48
5,1,24:1
6,1,24:48
7,1,24:4
8,1,24:43.0
-8,2,24:43.0
-7,2,24:4
-6,2,24:48
-5,2,24:48
-4,2,24:1
-3,2,24:1
-2,2,24:48
-1,2,24:1
0,2,24:1
1,2,24:4
2,2,24:4
3,2,24:48
4,2,24:1
5,2,24:48
6,2,24:4
7,2,24:4
8,2,24:43.0
-8,3,24:43.0
-7,3,24:4
-6,3,24:1
-5,3,24:48
-4,3,24:1
-3,3,24:48
-2,3,24:1
-1,3,24:1
0,3,24:48
1,3,24:48
2,3,24:1
3,3,24:48
4,3,24:1
5,3,24:1
6,3,24:1
7,3,24:4
8,3,24:43.0
-8,4,24:43.0
-7,4,24:4
-6,4,24:1
-5,4,24:1
-4,4,24:1
-3,4,24:48
-2,4,24:48
-1,4,24:4
0,4,24:48
1,4,24:4
2,4,24:48
3,4,24:1
4,4,24:48
5,4,24:48
6,4,24:48
7,4,24:4
8,4,24:43.0
-8,5,24:43.0
-7,5,24:4
-6,5,24:1
-5,5,24:4
-4,5,24:1
-3,5,24:48
-2,5,24:1
-1,5,24:4
0,5,24:4
1,5,24:1
2,5,24:4
3,5,24:48
4,5,24:1
5,5,24:48
6,5,24:48
7,5,24:4
8,5,24:43.0
-8,6,24:43.0
-7,6,24:4
-6,6,24:1
-5,6,24:4
-4,6,24:48
-3,6,24:48
-2,6,24:4
-1,6,24:4
0,6,24:4
1,6,24:4
2,6,24:48
3,6,24:1
4,6,24:1
5,6,24:48
6,6,24:4
7,6,24:4
8,6,24:43.0
-8,7,24:43.0
-7,7,24:4
-6,7,24:4
-5,7,24:4
-4,7,24:4
-3,7,24:4
-2,7,24:4
-1,7,24:4
0,7,24:4
1,7,24:4
2,7,24:4
3,7,24:4
4,7,24:4
5,7,24:4
6,7,24:4
7,7,24:4
8,7,24:43.0
-8,8,24:43.0
-7,8,24:43.0
-6,8,24:43.0
-5,8,24:43.0
-4,8,24:43.0
-3,8,24:43.0
-2,8,24:43.0
-1,8,24:43.0
0,8,24:43.0
1,8,24:43.0
2,8,24:43.0
3,8,24:43.0
4,8,24:43.0
5,8,24:43.0
6,8,24:43.0
7,8,24:43.0
8,8,24:43.0
