[META]
version=2.0
spawnOnBlockType=13
spawnSunlight=True
spawnDarkness=False
spawnWater=False
spawnLava=False
underFill=True
randomRotation=True
dig=True
tree=False
branch=False
needsFoundation=True
rarity=1
collisionPercentage=2
spawnElevationMin=0
spawnElevationMax=128
spawnInBiome=Flat
[DATA]
-8,-8,0:98.0
-7,-8,0:102
-6,-8,0:98.2
-5,-8,0:102
-4,-8,0:98.2
-3,-8,0:102
-2,-8,0:98.2
-1,-8,0:102
0,-8,0:98.0
1,-8,0:102
2,-8,0:98.1
3,-8,0:102
-8,-7,0:102
-7,-7,0:1
-6,-7,0:1
-5,-7,0:4
-4,-7,0:4
-3,-7,0:4
-2,-7,0:4
-1,-7,0:1
0,-7,0:1
1,-7,0:4
2,-7,0:4
-8,-6,0:98.0
-7,-6,0:4
-6,-6,0:4
-5,-6,0:4
-4,-6,0:4
-3,-6,0:4
-2,-6,0:4
-1,-6,0:1
0,-6,0:1
1,-6,0:4
2,-6,0:4
-8,-5,0:102
-7,-5,0:4
-6,-5,0:4
-5,-5,0:4
-4,-5,0:4
-3,-5,0:4
-2,-5,0:1
-1,-5,0:4
0,-5,0:4
1,-5,0:1
2,-5,0:1
-8,-4,0:98.0
-7,-4,0:4
-6,-4,0:1
-5,-4,0:4
-4,-4,0:4
-3,-4,0:4
-2,-4,0:1
-1,-4,0:4
0,-4,0:1
1,-4,0:1
2,-4,0:4
4,-4,0:4
-8,-3,0:102
-7,-3,0:4
-6,-3,0:4
-5,-3,0:4
-4,-3,0:1
-3,-3,0:4
-2,-3,0:4
-1,-3,0:1
0,-3,0:1
1,-3,0:4
2,-3,0:1
-8,-2,0:98.0
-7,-2,0:1
-6,-2,0:4
-5,-2,0:1
-4,-2,0:1
-3,-2,0:1
-2,-2,0:1
-1,-2,0:4
0,-2,0:1
1,-2,0:1
2,-2,0:4
3,-2,0:1
6,-2,0:1
-8,-1,0:102
-7,-1,0:1
-6,-1,0:1
-5,-1,0:1
-4,-1,0:4
-3,-1,0:4
-2,-1,0:4
-1,-1,0:4
0,-1,0:1
1,-1,0:4
2,-1,0:1
3,-1,0:4
4,-1,0:1
-8,0,0:98.1
-7,0,0:1
-6,0,0:4
-5,0,0:4
-4,0,0:1
-3,0,0:1
-2,0,0:4
-1,0,0:1
0,0,0:4
1,0,0:1
2,0,0:1
3,0,0:1
4,0,0:1
5,0,0:1
6,0,0:4
-8,1,0:102
-7,1,0:1
-6,1,0:4
-5,1,0:4
-4,1,0:1
-3,1,0:1
-2,1,0:1
-1,1,0:4
0,1,0:4
1,1,0:1
2,1,0:1
3,1,0:4
4,1,0:4
5,1,0:4
6,1,0:1
7,1,0:4
-8,2,0:98.0
-7,2,0:4
-6,2,0:1
-5,2,0:4
-4,2,0:1
-3,2,0:4
-2,2,0:1
-1,2,0:1
0,2,0:1
1,2,0:1
2,2,0:1
3,2,0:4
4,2,0:4
5,2,0:4
6,2,0:1
7,2,0:1
-8,3,0:102
-7,3,0:1
-6,3,0:1
-5,3,0:1
-4,3,0:1
-3,3,0:1
-2,3,0:1
-1,3,0:4
0,3,0:1
1,3,0:4
2,3,0:1
3,3,0:1
4,3,0:1
5,3,0:1
6,3,0:4
7,3,0:1
-8,4,0:98.1
-7,4,0:4
-6,4,0:1
-5,4,0:4
-4,4,0:1
-3,4,0:1
-2,4,0:4
-1,4,0:4
0,4,0:1
1,4,0:4
2,4,0:1
3,4,0:4
4,4,0:4
5,4,0:4
6,4,0:1
7,4,0:4
8,4,0:98.0
-8,5,0:102
-7,5,0:1
-6,5,0:1
-5,5,0:4
-4,5,0:1
-3,5,0:4
-2,5,0:1
-1,5,0:1
0,5,0:1
1,5,0:1
2,5,0:4
3,5,0:1
4,5,0:4
5,5,0:4
6,5,0:1
7,5,0:4
8,5,0:102
-8,6,0:98.1
-6,6,0:4
-5,6,0:1
-4,6,0:4
-3,6,0:4
-2,6,0:4
-1,6,0:4
0,6,0:1
1,6,0:1
2,6,0:1
3,6,0:1
4,6,0:4
5,6,0:1
6,6,0:1
8,6,0:98.1
-8,7,0:102
-7,7,0:1
-5,7,0:1
-4,7,0:1
-3,7,0:1
-2,7,0:1
-1,7,0:1
0,7,0:4
1,7,0:4
2,7,0:1
3,7,0:4
4,7,0:1
5,7,0:4
7,7,0:4
-8,8,0:98.0
-7,8,0:102
-6,8,0:98.2
-5,8,0:102
-4,8,0:98.1
-3,8,0:102
-2,8,0:98.2
-1,8,0:102
0,8,0:98.0
1,8,0:102
2,8,0:98.2
3,8,0:102
4,8,0:98.0
5,8,0:102
6,8,0:98.0
-7,-8,1:102
-6,-8,1:98.1
-5,-8,1:102
-4,-8,1:98.1
-3,-8,1:102
-2,-8,1:4
-1,-8,1:4
0,-8,1:4
1,-8,1:48
2,-8,1:98.0
3,-8,1:4
4,-8,1:48
5,-8,1:102
-8,-7,1:48
4,-7,1:1
-8,-6,1:4
-8,-5,1:48
-8,-4,1:48
-8,-3,1:4
-8,-2,1:4
-8,-1,1:4
-8,0,1:4
-8,1,1:4
-8,2,1:48
-8,3,1:4
-8,4,1:48
-8,5,1:48
-8,6,1:48
-7,6,1:4
7,6,1:1
-8,7,1:102
-6,7,1:1
6,7,1:1
-8,8,1:98.2
-7,8,1:102
-6,8,1:4
-5,8,1:48
-4,8,1:48
-3,8,1:48
-2,8,1:48
-1,8,1:48
0,8,1:48
1,8,1:48
2,8,1:4
3,8,1:4
4,8,1:4
5,8,1:4
-7,-8,2:102
-6,-8,2:98.2
-5,-8,2:102
-4,-8,2:98.0
-3,-8,2:102
-2,-8,2:98.1
-1,-8,2:102
0,-8,2:98.2
1,-8,2:102
2,-8,2:4
3,-8,2:102
4,-8,2:98.2
8,-8,2:48
-8,-7,2:102
-8,-6,2:98.2
3,-6,2:1
-8,-5,2:102
3,-5,2:4
-8,-4,2:98.0
-8,-3,2:102
4,-3,2:4
-8,-2,2:98.2
5,-2,2:4
-8,-1,2:102
7,-1,2:1
-8,0,2:98.1
-8,1,2:102
-8,2,2:98.1
-8,3,2:102
-8,4,2:98.2
-8,5,2:102
-8,6,2:98.0
-8,7,2:48
-7,8,2:4
-6,8,2:98.1
-5,8,2:102
-4,8,2:98.1
-3,8,2:102
-2,8,2:98.2
-1,8,2:102
0,8,2:98.2
1,8,2:102
2,8,2:98.0
3,8,2:102
4,8,2:98.1
5,8,2:102
8,8,2:48
-7,-8,3:4
-6,-8,3:4
-5,-8,3:48
-4,-8,3:4
-3,-8,3:48
-2,-8,3:98.0
-1,-8,3:4
0,-8,3:48
1,-8,3:4
2,-8,3:98.1
8,-8,3:98.0
-8,-7,3:102
3,-7,3:4
-8,-6,3:48
-8,-5,3:48
-8,-4,3:4
3,-4,3:1
-8,-3,3:48
-8,-2,3:4
-8,-1,3:48
6,-1,3:1
-8,0,3:48
-8,1,3:48
-8,2,3:4
-8,3,3:4
-8,4,3:4
-8,5,3:48
-8,6,3:4
-8,7,3:102
-7,8,3:102
-6,8,3:48
-5,8,3:4
-4,8,3:4
-3,8,3:4
-2,8,3:4
-1,8,3:48
0,8,3:48
1,8,3:4
2,8,3:4
3,8,3:4
4,8,3:48
5,8,3:48
8,8,3:98.1
-1,-8,4:102
0,-8,4:98.2
1,-8,4:102
8,-8,4:98.0
-8,-6,4:98.0
-8,-5,4:102
-8,-4,4:98.1
-8,-3,4:102
3,-3,4:1
-8,-2,4:98.1
4,-2,4:4
-8,-1,4:102
5,-1,4:1
-8,0,4:98.2
7,0,4:1
-8,1,4:102
-8,2,4:98.2
-8,3,4:102
-8,4,4:98.0
-8,5,4:102
-8,6,4:98.1
-6,8,4:98.1
-5,8,4:102
-4,8,4:98.2
-3,8,4:102
-2,8,4:98.1
-1,8,4:102
0,8,4:98.2
1,8,4:102
2,8,4:98.2
3,8,4:102
4,8,4:98.0
5,8,4:102
8,8,4:98.2
7,-8,5:48
8,-8,5:4
2,-7,5:1
8,-7,5:48
2,-6,5:4
2,-5,5:1
2,-4,5:4
3,-2,5:4
4,-1,5:4
6,0,5:4
7,1,5:1
7,7,5:4
8,7,5:48
7,8,5:4
8,8,5:4
6,-8,6:98.1
7,-8,6:102
8,-8,6:4
-7,-7,6:4
-6,-7,6:4
-5,-7,6:1
-4,-7,6:4
-3,-7,6:1
-2,-7,6:4
-1,-7,6:1
0,-7,6:1
1,-7,6:4
8,-7,6:102
-7,-6,6:1
-6,-6,6:1
-5,-6,6:4
-4,-6,6:1
-3,-6,6:4
-2,-6,6:4
-1,-6,6:4
0,-6,6:4
1,-6,6:4
-7,-5,6:1
-6,-5,6:1
-5,-5,6:4
-4,-5,6:4
-3,-5,6:1
-2,-5,6:4
-1,-5,6:1
0,-5,6:4
1,-5,6:1
-7,-4,6:4
-6,-4,6:1
-5,-4,6:4
-4,-4,6:1
-3,-4,6:1
-2,-4,6:1
-1,-4,6:1
0,-4,6:1
1,-4,6:4
-7,-3,6:4
-6,-3,6:4
-5,-3,6:1
-4,-3,6:4
-3,-3,6:1
-2,-3,6:1
-1,-3,6:1
0,-3,6:4
1,-3,6:4
2,-3,6:1
-7,-2,6:1
-6,-2,6:1
-5,-2,6:1
-4,-2,6:1
-3,-2,6:1
-2,-2,6:1
-1,-2,6:1
0,-2,6:1
1,-2,6:1
2,-2,6:1
-7,-1,6:4
-6,-1,6:4
-5,-1,6:4
-4,-1,6:1
-3,-1,6:4
-2,-1,6:4
-1,-1,6:1
0,-1,6:1
1,-1,6:4
2,-1,6:1
3,-1,6:1
-7,0,6:1
-6,0,6:4
-5,0,6:4
-4,0,6:4
-3,0,6:4
-2,0,6:1
-1,0,6:1
0,0,6:1
1,0,6:1
2,0,6:4
3,0,6:1
4,0,6:1
5,0,6:4
-7,1,6:1
-6,1,6:1
-5,1,6:4
-4,1,6:4
-3,1,6:1
-2,1,6:4
-1,1,6:1
0,1,6:1
1,1,6:4
2,1,6:4
3,1,6:4
4,1,6:1
5,1,6:1
6,1,6:1
-7,2,6:1
-6,2,6:1
-5,2,6:1
-4,2,6:4
-3,2,6:4
-2,2,6:4
-1,2,6:4
0,2,6:1
1,2,6:1
2,2,6:4
3,2,6:1
4,2,6:1
5,2,6:1
6,2,6:4
7,2,6:4
-7,3,6:4
-6,3,6:1
-5,3,6:1
-4,3,6:1
-3,3,6:4
-2,3,6:1
-1,3,6:1
0,3,6:4
1,3,6:4
2,3,6:1
3,3,6:1
4,3,6:4
5,3,6:4
6,3,6:4
7,3,6:4
8,3,6:102
-7,4,6:1
-6,4,6:4
-5,4,6:4
-4,4,6:1
-3,4,6:1
-2,4,6:4
-1,4,6:1
0,4,6:4
1,4,6:4
2,4,6:4
3,4,6:1
4,4,6:1
5,4,6:4
6,4,6:1
7,4,6:4
8,4,6:98.2
-7,5,6:4
-6,5,6:4
-5,5,6:1
-4,5,6:4
-3,5,6:4
-2,5,6:1
-1,5,6:4
0,5,6:4
1,5,6:1
2,5,6:1
3,5,6:1
4,5,6:1
5,5,6:4
6,5,6:4
7,5,6:1
8,5,6:102
-6,6,6:4
-5,6,6:4
-4,6,6:4
-3,6,6:1
-2,6,6:4
-1,6,6:1
0,6,6:4
1,6,6:1
2,6,6:1
3,6,6:1
4,6,6:4
5,6,6:1
6,6,6:4
8,6,6:98.1
-7,7,6:4
-5,7,6:4
-4,7,6:4
-3,7,6:4
-2,7,6:1
-1,7,6:1
0,7,6:1
1,7,6:1
2,7,6:1
3,7,6:1
4,7,6:4
5,7,6:1
8,7,6:102
6,8,6:98.0
7,8,6:102
8,8,6:48
