[META]
version=2.0
spawnOnBlockType=13
spawnSunlight=True
spawnDarkness=False
spawnWater=False
spawnLava=False
underFill=True
randomRotation=True
dig=True
tree=False
branch=False
needsFoundation=True
rarity=2
collisionPercentage=2
spawnElevationMin=0
spawnElevationMax=128
spawnInBiome=Flat
[DATA]
-7,-7,0:43.0
-6,-7,0:43.0
-5,-7,0:43.0
-4,-7,0:43.0
-3,-7,0:43.0
-2,-7,0:43.0
-1,-7,0:43.0
0,-7,0:43.0
1,-7,0:43.0
-7,-6,0:43.0
-6,-6,0:98.0
-5,-6,0:98.0
-4,-6,0:98.0
-3,-6,0:98.0
-2,-6,0:98.0
-1,-6,0:98.0
0,-6,0:98.0
1,-6,0:98.0
-7,-5,0:43.0
-6,-5,0:98.0
-5,-5,0:1
-4,-5,0:1
-3,-5,0:1
-2,-5,0:1
-1,-5,0:1
0,-5,0:1
1,-5,0:1
-7,-4,0:43.0
-6,-4,0:98.0
-5,-4,0:1
-4,-4,0:1
-3,-4,0:1
-2,-4,0:1
-1,-4,0:1
0,-4,0:1
1,-4,0:1
2,-4,0:1
-7,-3,0:43.0
-6,-3,0:98.0
-5,-3,0:1
-4,-3,0:1
-3,-3,0:1
-2,-3,0:1
-1,-3,0:1
0,-3,0:1
1,-3,0:1
2,-3,0:1
3,-3,0:1
7,-3,0:43.0
-7,-2,0:43.0
-6,-2,0:98.0
-5,-2,0:1
-4,-2,0:1
-3,-2,0:1
-2,-2,0:1
-1,-2,0:1
0,-2,0:1
1,-2,0:1
2,-2,0:1
3,-2,0:1
4,-2,0:1
5,-2,0:1
6,-2,0:98.0
7,-2,0:43.0
-7,-1,0:43.0
-6,-1,0:98.0
-5,-1,0:1
-4,-1,0:1
-3,-1,0:1
-2,-1,0:1
-1,-1,0:1
0,-1,0:1
1,-1,0:1
2,-1,0:1
3,-1,0:1
4,-1,0:1
5,-1,0:1
6,-1,0:98.0
7,-1,0:43.0
-7,0,0:43.0
-6,0,0:98.0
-5,0,0:1
-4,0,0:1
-3,0,0:1
-2,0,0:1
-1,0,0:1
0,0,0:1
1,0,0:1
2,0,0:1
3,0,0:1
4,0,0:1
5,0,0:1
6,0,0:98.0
7,0,0:43.0
-7,1,0:43.0
-6,1,0:98.0
-5,1,0:1
-4,1,0:1
-3,1,0:1
-2,1,0:1
-1,1,0:1
0,1,0:1
1,1,0:1
2,1,0:1
3,1,0:1
4,1,0:1
5,1,0:1
6,1,0:98.0
7,1,0:43.0
-7,2,0:43.0
-6,2,0:98.0
-5,2,0:1
-4,2,0:1
-3,2,0:1
-2,2,0:1
-1,2,0:1
0,2,0:1
1,2,0:1
2,2,0:1
3,2,0:1
4,2,0:1
5,2,0:1
6,2,0:98.0
7,2,0:43.0
-7,3,0:43.0
-6,3,0:98.0
-5,3,0:1
-4,3,0:1
-3,3,0:1
-2,3,0:1
-1,3,0:1
0,3,0:1
1,3,0:1
2,3,0:1
3,3,0:1
4,3,0:1
5,3,0:1
6,3,0:98.0
7,3,0:43.0
-7,4,0:44.5
-6,4,0:98.0
-4,4,0:43.0
-3,4,0:1
-2,4,0:1
-1,4,0:1
0,4,0:1
1,4,0:1
2,4,0:1
3,4,0:1
4,4,0:1
5,4,0:1
6,4,0:98.0
7,4,0:43.0
-7,5,0:44.5
-6,5,0:98.0
-4,5,0:43.0
-3,5,0:1
-2,5,0:1
-1,5,0:1
0,5,0:1
1,5,0:1
2,5,0:1
3,5,0:1
4,5,0:1
5,5,0:1
6,5,0:98.0
7,5,0:43.0
-7,6,0:44.5
-6,6,0:98.0
-5,6,0:98.0
-4,6,0:98.0
-3,6,0:98.0
-2,6,0:98.0
-1,6,0:98.0
0,6,0:98.0
1,6,0:98.0
2,6,0:98.0
3,6,0:98.0
4,6,0:98.0
5,6,0:98.0
6,6,0:98.0
7,6,0:43.0
-7,7,0:43.0
-6,7,0:44.5
-5,7,0:44.5
-4,7,0:44.5
-3,7,0:43.0
-2,7,0:43.0
-1,7,0:43.0
0,7,0:43.0
1,7,0:43.0
2,7,0:43.0
3,7,0:43.0
4,7,0:43.0
5,7,0:43.0
6,7,0:43.0
7,7,0:43.0
-7,-7,1:4
-5,-7,1:1
-3,-7,1:4
-1,-7,1:48
-6,-6,1:20
-5,-6,1:98.0
-4,-6,1:20
-3,-6,1:98.1
-2,-6,1:20
-1,-6,1:98.2
0,-6,1:20
-7,-5,1:4
-6,-5,1:98.2
7,-3,1:48
6,-2,1:20
-7,-1,1:48
-6,-1,1:98.1
6,-1,1:98.0
7,-1,1:4
-6,0,1:20
6,0,1:20
-7,1,1:4
-6,1,1:98.2
6,1,1:98.2
7,1,1:1
-6,2,1:20
6,2,1:20
-7,3,1:43.0
-6,3,1:98.1
-5,3,1:4
-4,3,1:4
-3,3,1:4
6,3,1:98.2
7,3,1:48
-7,4,1:44.5
-6,4,1:4
-4,4,1:43.0
6,4,1:20
-7,5,1:44.5
-6,5,1:4
-3,5,1:4
6,5,1:98.2
7,5,1:48
-7,6,1:44.5
-6,6,1:1
-5,6,1:1
-4,6,1:1
-3,6,1:98.1
-2,6,1:20
-1,6,1:98.1
0,6,1:20
1,6,1:98.1
2,6,1:20
3,6,1:98.2
4,6,1:20
5,6,1:98.0
6,6,1:20
-7,7,1:43.0
-6,7,1:44.5
-5,7,1:44.5
-4,7,1:44.5
-3,7,1:43.0
-1,7,1:4
1,7,1:4
3,7,1:4
5,7,1:4
7,7,1:48
-7,-7,2:1
-5,-7,2:4
-3,-7,2:4
-1,-7,2:4
-6,-6,2:20
-5,-6,2:98.1
-4,-6,2:20
-3,-6,2:98.0
-2,-6,2:20
-1,-6,2:98.1
6,-3,2:98.0
7,-3,2:48
6,-2,2:20
6,-1,2:98.1
7,-1,2:4
-6,0,2:20
6,0,2:20
-7,1,2:4
-6,1,2:98.1
6,1,2:98.0
7,1,2:48
-6,2,2:20
6,2,2:20
-7,3,2:43.0
-6,3,2:98.0
-5,3,2:4
-4,3,2:1
-3,3,2:1
6,3,2:98.2
7,3,2:1
-7,4,2:44.5
-6,4,2:1
-5,4,2:43.0
6,4,2:20
-7,5,2:44.5
-6,5,2:1
-3,5,2:4
6,5,2:98.2
7,5,2:4
-7,6,2:44.5
-6,6,2:1
-5,6,2:4
-4,6,2:4
-3,6,2:98.1
-2,6,2:20
-1,6,2:98.2
0,6,2:20
1,6,2:98.1
2,6,2:20
3,6,2:98.0
4,6,2:20
5,6,2:98.1
6,6,2:20
-7,7,2:43.0
-6,7,2:44.5
-5,7,2:44.5
-4,7,2:44.5
-3,7,2:43.0
-1,7,2:1
1,7,2:1
3,7,2:4
5,7,2:4
7,7,2:1
-7,-7,3:1
-5,-7,3:1
-3,-7,3:1
-1,-7,3:1
7,-7,3:1
-4,-6,3:20
-3,-6,3:98.0
-2,-6,3:20
-1,-6,3:98.2
7,-5,3:4
6,-4,3:20
6,-3,3:98.1
7,-3,3:48
6,-2,3:20
6,-1,3:98.0
7,-1,3:4
6,0,3:20
-7,1,3:48
-6,1,3:98.1
6,1,3:98.0
7,1,3:1
-6,2,3:20
6,2,3:20
-7,3,3:43.0
-6,3,3:98.0
-5,3,3:4
-4,3,3:4
-3,3,3:1
6,3,3:98.1
7,3,3:1
-7,4,3:44.5
-6,4,3:1
6,4,3:20
-7,5,3:44.5
-6,5,3:1
-5,5,3:43.0
-3,5,3:1
6,5,3:98.0
7,5,3:1
-7,6,3:44.5
-6,6,3:4
-5,6,3:4
-4,6,3:1
-3,6,3:98.2
-2,6,3:20
-1,6,3:98.2
0,6,3:20
1,6,3:98.2
2,6,3:20
3,6,3:98.2
4,6,3:20
5,6,3:98.2
6,6,3:20
-7,7,3:43.0
-6,7,3:44.5
-5,7,3:44.5
-4,7,3:44.5
-3,7,3:43.0
-1,7,3:1
1,7,3:1
3,7,3:1
5,7,3:4
7,7,3:1
-7,-7,4:48
-5,-7,4:4
-3,-7,4:48
-1,-7,4:4
7,-7,4:48
-4,-6,4:20
-3,-6,4:98.2
-2,-6,4:20
-1,-6,4:98.1
6,-5,4:98.2
7,-5,4:1
6,-4,4:20
6,-3,4:98.0
7,-3,4:4
6,-2,4:20
6,-1,4:98.0
7,-1,4:1
6,0,4:20
-7,1,4:48
-6,1,4:98.0
6,1,4:98.1
7,1,4:1
-6,2,4:20
6,2,4:20
-7,3,4:43.0
-6,3,4:98.1
-5,3,4:1
-4,3,4:4
-3,3,4:4
6,3,4:98.2
7,3,4:48
-7,4,4:44.5
-6,4,4:1
-3,4,4:1
6,4,4:20
-7,5,4:44.5
-6,5,4:4
-4,5,4:43.0
-3,5,4:1
6,5,4:98.2
7,5,4:48
-7,6,4:44.5
-6,6,4:4
-5,6,4:1
-4,6,4:4
-3,6,4:98.1
-2,6,4:20
-1,6,4:98.0
0,6,4:20
1,6,4:98.1
2,6,4:20
3,6,4:98.1
4,6,4:20
5,6,4:98.1
6,6,4:20
-7,7,4:43.0
-6,7,4:44.5
-5,7,4:44.5
-4,7,4:44.5
-3,7,4:43.0
-1,7,4:1
1,7,4:48
3,7,4:48
5,7,4:1
7,7,4:48
-7,-7,5:48
-5,-7,5:4
-3,-7,5:48
-1,-7,5:4
7,-7,5:1
-4,-6,5:20
-3,-6,5:98.0
-2,-6,5:20
-1,-6,5:98.2
0,-6,5:20
6,-6,5:20
6,-5,5:98.2
7,-5,5:4
6,-4,5:20
6,-3,5:98.2
7,-3,5:1
6,-2,5:20
6,-1,5:98.2
7,-1,5:48
6,0,5:20
-7,1,5:1
-6,1,5:98.2
6,1,5:98.1
7,1,5:4
-6,2,5:20
6,2,5:20
-7,3,5:43.0
-6,3,5:98.2
-5,3,5:4
-4,3,5:4
-3,3,5:1
6,3,5:98.1
7,3,5:1
-7,4,5:44.5
-6,4,5:4
-4,4,5:43.0
-3,4,5:1
6,4,5:20
-7,5,5:44.5
-6,5,5:4
-3,5,5:4
6,5,5:98.1
7,5,5:1
-7,6,5:44.5
-6,6,5:4
-5,6,5:4
-4,6,5:4
-3,6,5:98.1
-2,6,5:20
-1,6,5:98.0
0,6,5:20
1,6,5:98.0
2,6,5:20
3,6,5:98.0
4,6,5:20
5,6,5:98.0
6,6,5:20
-7,7,5:43.0
-6,7,5:44.5
-5,7,5:44.5
-4,7,5:44.5
-3,7,5:43.0
-1,7,5:4
1,7,5:1
3,7,5:48
5,7,5:1
7,7,5:4
-3,-7,6:48
-1,-7,6:4
1,-7,6:4
5,-7,6:1
7,-7,6:1
-4,-6,6:20
-3,-6,6:98.0
-2,-6,6:20
-1,-6,6:98.0
0,-6,6:20
1,-6,6:98.0
5,-6,6:98.0
6,-6,6:20
6,-5,6:98.1
7,-5,6:4
6,-4,6:20
6,-3,6:98.0
7,-3,6:1
6,-2,6:20
6,-1,6:98.0
7,-1,6:48
-6,0,6:20
6,0,6:20
-7,1,6:1
-6,1,6:98.1
6,1,6:98.2
7,1,6:4
-6,2,6:20
6,2,6:20
-7,3,6:43.0
-6,3,6:98.0
-5,3,6:1
-4,3,6:1
-3,3,6:4
6,3,6:98.2
7,3,6:4
-7,4,6:44.5
-6,4,6:4
-5,4,6:43.0
-3,4,6:1
6,4,6:20
-7,5,6:44.5
-6,5,6:1
-5,5,6:76.1
-3,5,6:4
6,5,6:98.0
7,5,6:4
-7,6,6:44.5
-6,6,6:1
-5,6,6:1
-4,6,6:1
-3,6,6:98.0
-2,6,6:20
-1,6,6:98.0
0,6,6:20
1,6,6:98.0
2,6,6:20
3,6,6:98.2
4,6,6:20
5,6,6:98.0
6,6,6:20
-7,7,6:43.0
-6,7,6:44.5
-5,7,6:44.5
-4,7,6:44.5
-3,7,6:43.0
-1,7,6:1
1,7,6:1
3,7,6:1
5,7,6:1
7,7,6:1
-4,-7,7:43.0
-3,-7,7:43.0
-2,-7,7:43.0
-1,-7,7:43.0
0,-7,7:43.0
1,-7,7:43.0
2,-7,7:43.0
3,-7,7:43.0
4,-7,7:43.0
5,-7,7:43.0
6,-7,7:43.0
7,-7,7:43.0
-3,-6,7:98.0
-2,-6,7:98.0
-1,-6,7:98.0
0,-6,7:98.0
1,-6,7:98.0
2,-6,7:98.0
3,-6,7:98.0
4,-6,7:98.0
5,-6,7:98.0
6,-6,7:98.0
7,-6,7:43.0
-3,-5,7:1
-2,-5,7:1
-1,-5,7:1
0,-5,7:1
1,-5,7:1
2,-5,7:1
3,-5,7:1
4,-5,7:1
5,-5,7:1
6,-5,7:98.0
7,-5,7:43.0
-3,-4,7:1
-2,-4,7:1
-1,-4,7:1
0,-4,7:1
1,-4,7:1
2,-4,7:1
3,-4,7:1
4,-4,7:1
5,-4,7:1
6,-4,7:98.0
7,-4,7:43.0
-4,-3,7:1
-3,-3,7:1
-2,-3,7:1
-1,-3,7:1
0,-3,7:1
1,-3,7:1
2,-3,7:1
3,-3,7:1
4,-3,7:1
5,-3,7:1
6,-3,7:98.0
7,-3,7:43.0
-4,-2,7:1
-3,-2,7:1
-2,-2,7:1
-1,-2,7:1
0,-2,7:1
1,-2,7:1
2,-2,7:1
3,-2,7:1
4,-2,7:1
5,-2,7:1
6,-2,7:98.0
7,-2,7:43.0
-7,-1,7:43.0
-6,-1,7:98.0
-5,-1,7:1
-4,-1,7:1
-3,-1,7:1
-2,-1,7:1
-1,-1,7:1
0,-1,7:1
1,-1,7:1
2,-1,7:1
3,-1,7:1
4,-1,7:1
5,-1,7:1
6,-1,7:98.0
7,-1,7:43.0
-7,0,7:43.0
-6,0,7:98.0
-5,0,7:1
-4,0,7:1
-3,0,7:1
-2,0,7:1
-1,0,7:1
0,0,7:1
1,0,7:1
2,0,7:1
3,0,7:1
4,0,7:1
5,0,7:1
6,0,7:98.0
7,0,7:43.0
-7,1,7:43.0
-6,1,7:98.0
-5,1,7:1
-4,1,7:1
-3,1,7:1
-2,1,7:1
-1,1,7:1
0,1,7:1
1,1,7:1
2,1,7:1
3,1,7:1
4,1,7:1
5,1,7:1
6,1,7:98.0
7,1,7:43.0
-7,2,7:43.0
-6,2,7:98.0
-5,2,7:1
-4,2,7:1
-3,2,7:1
-2,2,7:1
-1,2,7:1
0,2,7:1
1,2,7:1
2,2,7:1
3,2,7:1
4,2,7:1
5,2,7:1
6,2,7:98.0
7,2,7:43.0
-7,3,7:43.0
-6,3,7:98.0
-5,3,7:1
-4,3,7:1
-3,3,7:1
-2,3,7:1
-1,3,7:1
0,3,7:1
1,3,7:1
2,3,7:1
3,3,7:1
4,3,7:1
5,3,7:1
6,3,7:98.0
7,3,7:43.0
-7,4,7:44.5
-6,4,7:98.0
-3,4,7:1
-2,4,7:1
-1,4,7:1
0,4,7:1
1,4,7:1
2,4,7:1
3,4,7:1
4,4,7:1
5,4,7:1
6,4,7:98.0
7,4,7:43.0
-7,5,7:44.5
-6,5,7:98.0
-5,5,7:43.0
-3,5,7:1
-2,5,7:1
-1,5,7:1
0,5,7:1
1,5,7:1
2,5,7:1
3,5,7:1
4,5,7:1
5,5,7:1
6,5,7:98.0
7,5,7:43.0
-7,6,7:44.5
-6,6,7:98.0
-5,6,7:98.0
-4,6,7:98.0
-3,6,7:98.0
-2,6,7:98.0
-1,6,7:98.0
0,6,7:98.0
1,6,7:98.0
2,6,7:98.0
3,6,7:98.0
4,6,7:98.0
5,6,7:98.0
6,6,7:98.0
7,6,7:43.0
-7,7,7:43.0
-6,7,7:44.5
-5,7,7:44.5
-4,7,7:44.5
-3,7,7:43.0
-2,7,7:43.0
-1,7,7:43.0
0,7,7:43.0
1,7,7:43.0
2,7,7:43.0
3,7,7:43.0
4,7,7:43.0
5,7,7:43.0
6,7,7:43.0
7,7,7:43.0
-3,-7,8:4
-1,-7,8:48
1,-7,8:1
3,-7,8:48
5,-7,8:4
7,-7,8:48
-3,-6,8:98.1
-2,-6,8:20
-1,-6,8:98.2
0,-6,8:20
1,-6,8:98.2
2,-6,8:20
3,-6,8:98.2
4,-6,8:20
5,-6,8:98.0
6,-6,8:20
6,-5,8:98.0
7,-5,8:1
6,-4,8:20
6,-3,8:98.2
7,-3,8:48
6,-2,8:20
-7,-1,8:48
-6,-1,8:98.1
6,-1,8:98.0
7,-1,8:4
-6,0,8:20
6,0,8:20
-7,1,8:4
-6,1,8:98.2
6,1,8:98.2
7,1,8:1
-6,2,8:20
6,2,8:20
-7,3,8:43.0
-6,3,8:98.1
-5,3,8:4
-4,3,8:4
-3,3,8:4
6,3,8:98.2
7,3,8:48
-7,4,8:44.5
-6,4,8:4
-3,4,8:43.0
6,4,8:20
-7,5,8:44.5
-6,5,8:4
-4,5,8:43.0
-3,5,8:4
6,5,8:98.2
7,5,8:48
-7,6,8:44.5
-6,6,8:1
-5,6,8:1
-4,6,8:1
-3,6,8:98.1
-2,6,8:20
-1,6,8:98.1
0,6,8:20
1,6,8:98.1
2,6,8:20
3,6,8:98.2
4,6,8:20
5,6,8:98.0
6,6,8:20
-7,7,8:43.0
-6,7,8:44.5
-5,7,8:44.5
-4,7,8:44.5
-3,7,8:43.0
-1,7,8:4
1,7,8:4
3,7,8:4
5,7,8:4
7,7,8:48
-3,-7,9:4
-1,-7,9:4
1,-7,9:1
3,-7,9:4
5,-7,9:1
7,-7,9:1
-3,-6,9:98.0
-2,-6,9:20
-1,-6,9:98.1
0,-6,9:20
1,-6,9:98.1
2,-6,9:20
3,-6,9:98.0
4,-6,9:20
5,-6,9:98.1
6,-6,9:20
6,-5,9:98.2
7,-5,9:48
6,-4,9:20
6,-3,9:98.0
7,-3,9:48
6,-2,9:20
-7,-1,9:48
-6,-1,9:98.0
6,-1,9:98.1
7,-1,9:4
-6,0,9:20
6,0,9:20
-7,1,9:4
-6,1,9:98.1
6,1,9:98.0
7,1,9:48
-6,2,9:20
6,2,9:20
-7,3,9:43.0
-6,3,9:98.0
-5,3,9:4
-4,3,9:1
-3,3,9:1
6,3,9:98.2
7,3,9:1
-7,4,9:44.5
-6,4,9:1
-4,4,9:43.0
6,4,9:20
-7,5,9:44.5
-6,5,9:1
-3,5,9:4
6,5,9:98.2
7,5,9:4
-7,6,9:44.5
-6,6,9:1
-5,6,9:4
-4,6,9:4
-3,6,9:98.1
-2,6,9:20
-1,6,9:98.2
0,6,9:20
1,6,9:98.1
2,6,9:20
3,6,9:98.0
4,6,9:20
5,6,9:98.1
6,6,9:20
-7,7,9:43.0
-6,7,9:44.5
-5,7,9:44.5
-4,7,9:44.5
-3,7,9:43.0
-1,7,9:1
1,7,9:1
3,7,9:4
5,7,9:4
7,7,9:1
-3,-7,10:1
-1,-7,10:1
1,-7,10:1
3,-7,10:1
5,-7,10:48
7,-7,10:1
-4,-6,10:20
-3,-6,10:98.0
-2,-6,10:20
-1,-6,10:98.2
0,-6,10:20
1,-6,10:98.0
2,-6,10:20
3,-6,10:98.2
4,-6,10:20
5,-6,10:98.2
6,-6,10:20
6,-5,10:98.0
7,-5,10:4
6,-4,10:20
6,-3,10:98.1
7,-3,10:48
-6,-2,10:20
6,-2,10:20
-7,-1,10:4
-6,-1,10:98.1
6,-1,10:98.0
7,-1,10:4
-6,0,10:20
6,0,10:20
-7,1,10:48
-6,1,10:98.1
6,1,10:98.0
7,1,10:1
-6,2,10:20
6,2,10:20
-7,3,10:43.0
-6,3,10:98.0
-5,3,10:4
-4,3,10:4
-3,3,10:1
6,3,10:98.1
7,3,10:1
-7,4,10:44.5
-6,4,10:1
-5,4,10:43.0
6,4,10:20
-7,5,10:44.5
-6,5,10:1
-3,5,10:1
6,5,10:98.0
7,5,10:1
-7,6,10:44.5
-6,6,10:4
-5,6,10:4
-4,6,10:1
-3,6,10:98.2
-2,6,10:20
-1,6,10:98.2
0,6,10:20
1,6,10:98.2
2,6,10:20
3,6,10:98.2
4,6,10:20
5,6,10:98.2
6,6,10:20
-7,7,10:43.0
-6,7,10:44.5
-5,7,10:44.5
-4,7,10:44.5
-3,7,10:43.0
-1,7,10:1
1,7,10:1
3,7,10:1
5,7,10:4
7,7,10:1
-1,-7,11:4
1,-7,11:4
3,-7,11:4
5,-7,11:4
7,-7,11:48
-2,-6,11:20
-1,-6,11:98.1
0,-6,11:20
1,-6,11:98.2
2,-6,11:20
3,-6,11:98.1
4,-6,11:20
5,-6,11:98.1
6,-6,11:20
6,-5,11:98.2
7,-5,11:1
6,-4,11:20
6,-3,11:98.0
7,-3,11:4
-6,-2,11:20
6,-2,11:20
-7,-1,11:4
-6,-1,11:98.0
6,-1,11:98.0
7,-1,11:1
-6,0,11:20
6,0,11:20
-7,1,11:48
-6,1,11:98.0
6,1,11:98.1
7,1,11:1
-6,2,11:20
6,2,11:20
-7,3,11:43.0
-6,3,11:98.1
-5,3,11:1
-4,3,11:4
-3,3,11:4
6,3,11:98.2
7,3,11:48
-7,4,11:44.5
-6,4,11:1
6,4,11:20
-7,5,11:44.5
-6,5,11:4
-5,5,11:43.0
-3,5,11:1
6,5,11:98.2
7,5,11:48
-7,6,11:44.5
-6,6,11:4
-5,6,11:1
-4,6,11:4
-3,6,11:98.1
-2,6,11:20
-1,6,11:98.0
0,6,11:20
1,6,11:98.1
2,6,11:20
3,6,11:98.1
4,6,11:20
5,6,11:98.1
6,6,11:20
-7,7,11:43.0
-6,7,11:44.5
-5,7,11:44.5
-4,7,11:44.5
-3,7,11:43.0
-1,7,11:1
1,7,11:48
3,7,11:48
5,7,11:1
7,7,11:48
-1,-7,12:4
1,-7,12:48
3,-7,12:1
5,-7,12:1
7,-7,12:1
-1,-6,12:98.2
0,-6,12:20
1,-6,12:98.0
2,-6,12:20
3,-6,12:98.1
4,-6,12:20
5,-6,12:98.1
6,-6,12:20
6,-5,12:98.2
7,-5,12:4
6,-4,12:20
6,-3,12:98.2
7,-3,12:1
6,-2,12:20
-7,-1,12:4
-6,-1,12:98.2
6,-1,12:98.2
7,-1,12:48
-6,0,12:20
6,0,12:20
-7,1,12:1
-6,1,12:98.2
6,1,12:98.1
7,1,12:4
-6,2,12:20
6,2,12:20
-7,3,12:43.0
-6,3,12:98.2
-5,3,12:4
-4,3,12:4
-3,3,12:1
6,3,12:98.1
7,3,12:1
-7,4,12:44.5
-6,4,12:4
-3,4,12:1
6,4,12:20
-7,5,12:44.5
-6,5,12:4
-4,5,12:43.0
-3,5,12:4
6,5,12:98.1
7,5,12:1
-7,6,12:44.5
-6,6,12:4
-5,6,12:4
-4,6,12:4
-3,6,12:98.1
-2,6,12:20
-1,6,12:98.0
0,6,12:20
1,6,12:98.0
2,6,12:20
3,6,12:98.0
4,6,12:20
5,6,12:98.0
6,6,12:20
-7,7,12:43.0
-6,7,12:44.5
-5,7,12:44.5
-4,7,12:44.5
-3,7,12:43.0
-1,7,12:4
1,7,12:1
3,7,12:48
5,7,12:1
7,7,12:4
1,-7,13:4
3,-7,13:1
5,-7,13:1
7,-7,13:1
0,-6,13:20
1,-6,13:98.0
2,-6,13:20
3,-6,13:98.0
4,-6,13:20
5,-6,13:98.0
6,-6,13:20
6,-5,13:98.1
7,-5,13:4
6,-4,13:20
6,-3,13:98.0
7,-3,13:1
6,-2,13:20
-7,-1,13:1
-6,-1,13:98.2
6,-1,13:98.0
7,-1,13:48
-6,0,13:20
6,0,13:20
-7,1,13:1
-6,1,13:98.1
6,1,13:98.2
7,1,13:4
-6,2,13:20
6,2,13:20
-7,3,13:43.0
-6,3,13:98.0
-5,3,13:1
-4,3,13:1
-3,3,13:4
6,3,13:98.2
7,3,13:4
-7,4,13:44.5
-6,4,13:4
-4,4,13:43.0
-3,4,13:1
6,4,13:20
-7,5,13:44.5
-6,5,13:1
-3,5,13:4
6,5,13:98.0
7,5,13:4
-7,6,13:44.5
-6,6,13:1
-5,6,13:1
-4,6,13:1
-3,6,13:98.0
-2,6,13:20
-1,6,13:98.0
0,6,13:20
1,6,13:98.0
2,6,13:20
3,6,13:98.2
4,6,13:20
5,6,13:98.0
6,6,13:20
-7,7,13:43.0
-6,7,13:44.5
-5,7,13:44.5
-4,7,13:44.5
-3,7,13:43.0
-1,7,13:1
1,7,13:1
3,7,13:1
5,7,13:1
7,7,13:1
0,-7,14:43.0
1,-7,14:43.0
2,-7,14:43.0
3,-7,14:43.0
4,-7,14:43.0
5,-7,14:43.0
6,-7,14:43.0
7,-7,14:43.0
0,-6,14:98.0
1,-6,14:98.0
2,-6,14:98.0
3,-6,14:98.0
4,-6,14:98.0
5,-6,14:98.0
6,-6,14:98.0
7,-6,14:43.0
-1,-5,14:1
0,-5,14:1
1,-5,14:1
2,-5,14:1
3,-5,14:1
4,-5,14:1
5,-5,14:1
6,-5,14:98.0
7,-5,14:43.0
-2,-4,14:1
-1,-4,14:1
0,-4,14:1
1,-4,14:1
2,-4,14:1
3,-4,14:1
4,-4,14:1
5,-4,14:1
6,-4,14:98.0
7,-4,14:43.0
-4,-3,14:1
-3,-3,14:1
-2,-3,14:1
-1,-3,14:1
0,-3,14:1
1,-3,14:1
2,-3,14:1
3,-3,14:1
4,-3,14:1
5,-3,14:1
6,-3,14:98.0
7,-3,14:43.0
-5,-2,14:1
-4,-2,14:1
-3,-2,14:1
-2,-2,14:1
-1,-2,14:1
0,-2,14:1
1,-2,14:1
2,-2,14:1
3,-2,14:1
4,-2,14:1
5,-2,14:1
6,-2,14:98.0
7,-2,14:43.0
-7,-1,14:43.0
-6,-1,14:98.0
-5,-1,14:1
-4,-1,14:1
-3,-1,14:1
-2,-1,14:1
-1,-1,14:1
0,-1,14:1
1,-1,14:1
2,-1,14:1
3,-1,14:1
4,-1,14:1
5,-1,14:1
6,-1,14:98.0
7,-1,14:43.0
-7,0,14:43.0
-6,0,14:98.0
-5,0,14:1
-4,0,14:1
-3,0,14:1
-2,0,14:1
-1,0,14:1
0,0,14:1
1,0,14:1
2,0,14:1
3,0,14:1
4,0,14:1
5,0,14:1
6,0,14:98.0
7,0,14:43.0
-7,1,14:43.0
-6,1,14:98.0
-5,1,14:1
-4,1,14:1
-3,1,14:1
-2,1,14:1
-1,1,14:1
0,1,14:1
1,1,14:1
2,1,14:1
3,1,14:1
4,1,14:1
5,1,14:1
6,1,14:98.0
7,1,14:43.0
-7,2,14:43.0
-6,2,14:98.0
-5,2,14:1
-4,2,14:1
-3,2,14:1
-2,2,14:1
-1,2,14:1
0,2,14:1
1,2,14:1
2,2,14:1
3,2,14:1
4,2,14:1
5,2,14:1
6,2,14:98.0
7,2,14:43.0
-7,3,14:43.0
-6,3,14:98.0
-5,3,14:1
-4,3,14:1
-3,3,14:1
-2,3,14:1
-1,3,14:1
0,3,14:1
1,3,14:1
2,3,14:1
3,3,14:1
4,3,14:1
5,3,14:1
6,3,14:98.0
7,3,14:43.0
-7,4,14:43.0
-6,4,14:98.0
-5,4,14:43.0
-3,4,14:1
-2,4,14:1
-1,4,14:1
0,4,14:1
1,4,14:1
2,4,14:1
3,4,14:1
4,4,14:1
5,4,14:1
6,4,14:98.0
7,4,14:43.0
-7,5,14:43.0
-6,5,14:98.0
-3,5,14:1
-2,5,14:1
-1,5,14:1
0,5,14:1
1,5,14:1
2,5,14:1
3,5,14:1
4,5,14:1
5,5,14:1
6,5,14:98.0
7,5,14:43.0
-7,6,14:43.0
-6,6,14:98.0
-5,6,14:98.0
-4,6,14:98.0
-3,6,14:98.0
-2,6,14:98.0
-1,6,14:98.0
0,6,14:98.0
1,6,14:98.0
2,6,14:98.0
3,6,14:98.0
4,6,14:98.0
5,6,14:98.0
6,6,14:98.0
7,6,14:43.0
-7,7,14:43.0
-6,7,14:43.0
-5,7,14:43.0
-4,7,14:43.0
-3,7,14:43.0
-2,7,14:43.0
-1,7,14:43.0
0,7,14:43.0
1,7,14:43.0
2,7,14:43.0
3,7,14:43.0
4,7,14:43.0
5,7,14:43.0
6,7,14:43.0
7,7,14:43.0
