[META]
version=2.0
spawnOnBlockType=1,2,3
spawnSunlight=True
spawnDarkness=False
spawnWater=False
spawnLava=False
underFill=True
randomRotation=True
dig=True
tree=False
branch=False
needsFoundation=True
rarity=120
collisionPercentage=2
spawnElevationMin=0
spawnElevationMax=250
spawnInBiome=FloatingCityCenter,FloatingCityBorder3
[DATA]
-7,-7,0:98.2
-6,-7,0:98.0
-5,-7,0:98.1
-4,-7,0:98.0
-3,-7,0:98.0
-2,-7,0:98.2
-1,-7,0:98.2
0,-7,0:98.2
1,-7,0:98.0
2,-7,0:98.0
3,-7,0:98.0
4,-7,0:98.1
5,-7,0:98.2
6,-7,0:98.1
7,-7,0:98.2
-7,-6,0:98.1
6,-6,0:13
7,-6,0:98.2
-7,-5,0:98.1
7,-5,0:98.0
-7,-4,0:98.1
-6,-4,0:4
7,-4,0:98.0
-7,-3,0:98.1
-6,-3,0:13
7,-3,0:98.2
-7,-2,0:98.2
-6,-2,0:13
7,-2,0:98.2
-7,-1,0:98.2
-6,-1,0:4
-5,-1,0:13
7,-1,0:98.0
-7,0,0:98.0
-6,0,0:13
-5,0,0:13
7,0,0:98.0
-7,1,0:98.2
-6,1,0:13
-5,1,0:13
6,1,0:4
7,1,0:98.2
-7,2,0:98.2
-6,2,0:4
6,2,0:13
7,2,0:98.0
-7,3,0:98.1
6,3,0:13
7,3,0:98.1
-7,4,0:98.0
7,4,0:98.0
-7,5,0:98.0
7,5,0:98.1
-7,6,0:98.2
6,6,0:4
7,6,0:98.0
-7,7,0:98.1
-6,7,0:98.2
-5,7,0:98.2
-4,7,0:98.0
-3,7,0:98.0
-2,7,0:98.0
-1,7,0:98.0
0,7,0:98.0
1,7,0:98.1
2,7,0:98.2
3,7,0:98.2
4,7,0:98.1
5,7,0:98.1
6,7,0:98.2
7,7,0:98.0
-7,-7,1:4
-6,-7,1:4
-5,-7,1:102
-4,-7,1:102
-3,-7,1:4
-2,-7,1:102
-1,-7,1:102
0,-7,1:4
1,-7,1:102
2,-7,1:102
3,-7,1:4
4,-7,1:102
5,-7,1:102
6,-7,1:4
7,-7,1:98.1
-7,-6,1:4
6,-6,1:13
7,-6,1:1
-7,-5,1:102
7,-5,1:102
-7,-4,1:102
7,-4,1:102
-7,-3,1:4
7,-3,1:1
-7,-2,1:102
-6,-2,1:13
7,-2,1:102
-7,-1,1:102
-6,-1,1:4
-5,-1,1:4
7,-1,1:102
-7,0,1:4
-6,0,1:13
-5,0,1:13
7,0,1:4
-7,1,1:102
-6,1,1:13
-5,1,1:4
7,1,1:102
-7,2,1:102
-6,2,1:13
7,2,1:102
-7,3,1:1
7,3,1:1
-7,4,1:102
7,4,1:102
-7,5,1:102
7,5,1:102
-7,6,1:4
7,6,1:1
-7,7,1:98.2
-6,7,1:4
-5,7,1:102
-4,7,1:102
-3,7,1:1
-2,7,1:102
0,7,1:4
1,7,1:102
2,7,1:102
3,7,1:1
4,7,1:102
5,7,1:102
6,7,1:1
7,7,1:98.2
-7,-7,2:98.1
-6,-7,2:1
-5,-7,2:102
-4,-7,2:102
-3,-7,2:4
-2,-7,2:102
-1,-7,2:102
0,-7,2:1
1,-7,2:102
2,-7,2:102
3,-7,2:4
4,-7,2:102
5,-7,2:102
6,-7,2:4
7,-7,2:98.0
-7,-6,2:4
6,-6,2:13
7,-6,2:4
-7,-5,2:102
7,-5,2:102
-7,-4,2:102
7,-4,2:102
-7,-3,2:4
7,-3,2:1
-7,-2,2:102
-6,-2,2:13
7,-2,2:102
-7,-1,2:102
-6,-1,2:13
-5,-1,2:4
7,-1,2:102
-7,0,2:1
-6,0,2:13
-5,0,2:13
7,0,2:4
-7,1,2:102
-6,1,2:4
-5,1,2:13
7,1,2:102
-7,2,2:102
-6,2,2:4
7,2,2:102
-7,3,2:1
7,3,2:1
-7,4,2:102
7,4,2:102
-7,5,2:102
7,5,2:102
-7,6,2:4
7,6,2:1
-7,7,2:98.2
-6,7,2:1
-5,7,2:102
-4,7,2:102
-3,7,2:1
-2,7,2:102
0,7,2:4
1,7,2:102
2,7,2:102
3,7,2:1
4,7,2:102
5,7,2:102
6,7,2:4
7,7,2:98.1
-7,-7,3:98.0
-6,-7,3:1
-5,-7,3:102
-4,-7,3:102
-3,-7,3:1
-2,-7,3:102
-1,-7,3:102
0,-7,3:1
1,-7,3:102
2,-7,3:102
3,-7,3:4
4,-7,3:102
5,-7,3:102
6,-7,3:4
7,-7,3:98.0
-7,-6,3:1
7,-6,3:4
-7,-5,3:102
7,-5,3:102
-7,-4,3:102
7,-4,3:102
-7,-3,3:4
7,-3,3:1
-7,-2,3:102
7,-2,3:102
-7,-1,3:102
-6,-1,3:4
7,-1,3:102
-7,0,3:4
-6,0,3:4
7,0,3:1
-7,1,3:102
-6,1,3:13
7,1,3:102
-7,2,3:102
7,2,3:102
-7,3,3:1
7,3,3:1
-7,4,3:102
7,4,3:102
-7,5,3:102
7,5,3:102
-7,6,3:4
7,6,3:1
-7,7,3:98.0
-6,7,3:4
-5,7,3:102
-4,7,3:102
-3,7,3:4
-2,7,3:102
-1,7,3:102
0,7,3:1
1,7,3:102
2,7,3:102
3,7,3:4
4,7,3:102
5,7,3:102
6,7,3:4
7,7,3:98.2
-7,-7,4:98.2
-6,-7,4:98.2
-5,-7,4:98.1
-4,-7,4:98.0
-3,-7,4:98.1
-2,-7,4:98.0
-1,-7,4:98.2
0,-7,4:98.2
1,-7,4:98.1
2,-7,4:98.1
3,-7,4:98.2
4,-7,4:98.1
5,-7,4:98.2
6,-7,4:98.0
7,-7,4:98.1
-7,-6,4:98.1
-6,-6,4:4
-5,-6,4:4
-4,-6,4:1
-3,-6,4:4
-2,-6,4:4
-1,-6,4:4
0,-6,4:4
1,-6,4:1
2,-6,4:1
3,-6,4:4
4,-6,4:1
5,-6,4:1
6,-6,4:1
7,-6,4:98.2
-7,-5,4:98.0
-6,-5,4:4
-5,-5,4:4
-4,-5,4:4
-3,-5,4:4
-2,-5,4:4
-1,-5,4:1
0,-5,4:1
1,-5,4:4
2,-5,4:4
3,-5,4:4
4,-5,4:1
5,-5,4:4
6,-5,4:4
7,-5,4:98.1
-7,-4,4:98.2
-6,-4,4:4
-5,-4,4:1
-4,-4,4:1
-3,-4,4:1
-2,-4,4:1
-1,-4,4:4
0,-4,4:1
1,-4,4:4
2,-4,4:4
3,-4,4:1
4,-4,4:4
5,-4,4:4
6,-4,4:4
7,-4,4:98.0
-7,-3,4:98.0
-6,-3,4:1
-5,-3,4:1
-4,-3,4:1
-3,-3,4:1
-2,-3,4:4
-1,-3,4:1
0,-3,4:1
1,-3,4:4
2,-3,4:4
3,-3,4:4
4,-3,4:1
5,-3,4:1
6,-3,4:1
7,-3,4:98.2
-7,-2,4:98.1
-6,-2,4:1
-5,-2,4:4
-4,-2,4:4
-3,-2,4:4
-2,-2,4:1
-1,-2,4:4
0,-2,4:4
1,-2,4:1
2,-2,4:4
3,-2,4:4
4,-2,4:4
5,-2,4:4
6,-2,4:1
7,-2,4:98.0
-7,-1,4:98.2
-6,-1,4:4
-5,-1,4:1
-4,-1,4:4
-3,-1,4:4
-2,-1,4:1
-1,-1,4:4
0,-1,4:1
1,-1,4:1
2,-1,4:1
3,-1,4:4
4,-1,4:1
5,-1,4:1
6,-1,4:4
7,-1,4:98.2
-7,0,4:98.0
-6,0,4:4
-5,0,4:1
-4,0,4:4
-3,0,4:4
-2,0,4:4
-1,0,4:1
0,0,4:1
1,0,4:4
2,0,4:1
3,0,4:4
4,0,4:1
5,0,4:1
6,0,4:1
7,0,4:98.2
-7,1,4:98.1
-6,1,4:1
-5,1,4:4
-4,1,4:4
-3,1,4:1
-2,1,4:4
-1,1,4:1
0,1,4:1
1,1,4:1
2,1,4:1
3,1,4:1
4,1,4:4
5,1,4:4
6,1,4:4
7,1,4:98.2
-7,2,4:98.0
-6,2,4:4
-5,2,4:1
-4,2,4:1
-3,2,4:4
-2,2,4:4
-1,2,4:1
0,2,4:4
1,2,4:4
2,2,4:1
3,2,4:1
4,2,4:1
5,2,4:4
6,2,4:1
7,2,4:98.1
-7,3,4:98.2
-6,3,4:1
-5,3,4:1
-4,3,4:4
-3,3,4:4
-2,3,4:4
-1,3,4:1
0,3,4:1
1,3,4:1
2,3,4:1
3,3,4:1
4,3,4:1
5,3,4:1
6,3,4:4
7,3,4:98.1
-7,4,4:98.2
-6,4,4:1
-5,4,4:1
-4,4,4:4
-3,4,4:1
-2,4,4:4
-1,4,4:1
0,4,4:1
1,4,4:4
2,4,4:4
3,4,4:4
4,4,4:1
5,4,4:4
6,4,4:4
7,4,4:98.1
-7,5,4:98.0
-6,5,4:1
-5,5,4:4
-4,5,4:4
-3,5,4:4
-2,5,4:4
-1,5,4:4
0,5,4:1
1,5,4:1
2,5,4:4
3,5,4:1
4,5,4:1
5,5,4:4
6,5,4:4
7,5,4:98.2
-7,6,4:98.0
-6,6,4:4
-5,6,4:1
-4,6,4:1
-3,6,4:4
-2,6,4:4
-1,6,4:1
0,6,4:1
1,6,4:1
2,6,4:4
3,6,4:1
4,6,4:4
5,6,4:1
6,6,4:1
7,6,4:98.1
-7,7,4:98.2
-6,7,4:98.0
-5,7,4:98.2
-4,7,4:98.1
-3,7,4:98.1
-2,7,4:98.1
-1,7,4:98.2
0,7,4:98.1
1,7,4:98.0
2,7,4:98.2
3,7,4:98.2
4,7,4:98.0
5,7,4:98.2
6,7,4:98.0
7,7,4:98.0
-7,-7,5:98.0
-6,-7,5:98.1
-5,-7,5:98.1
-4,-7,5:98.0
-3,-7,5:98.0
-2,-7,5:98.0
-1,-7,5:98.1
0,-7,5:98.1
1,-7,5:98.2
2,-7,5:98.1
3,-7,5:98.0
4,-7,5:98.1
5,-7,5:98.2
6,-7,5:98.1
7,-7,5:98.0
-7,-6,5:98.1
-2,-6,5:4
2,-6,5:1
7,-6,5:98.1
-7,-5,5:98.1
-2,-5,5:4
2,-5,5:1
7,-5,5:98.0
-7,-4,5:98.0
-2,-4,5:4
-1,-4,5:4
0,-4,5:4
1,-4,5:4
2,-4,5:4
7,-4,5:98.1
-7,-3,5:98.1
7,-3,5:98.2
-7,-2,5:98.0
7,-2,5:98.0
7,-1,5:98.1
7,0,5:98.2
7,1,5:98.0
-7,2,5:98.0
7,2,5:98.2
-7,3,5:98.1
7,3,5:98.0
-7,4,5:98.2
5,4,5:52
7,4,5:98.2
-7,5,5:98.2
7,5,5:98.0
-7,6,5:98.1
7,6,5:98.0
-7,7,5:98.2
-6,7,5:98.2
-5,7,5:98.1
-4,7,5:98.0
-3,7,5:98.1
-2,7,5:98.2
-1,7,5:98.0
0,7,5:98.2
1,7,5:98.0
2,7,5:98.1
3,7,5:98.1
4,7,5:98.1
5,7,5:98.0
6,7,5:98.0
7,7,5:98.1
-7,-7,6:98.1
-6,-7,6:1
-5,-7,6:102
-4,-7,6:102
-3,-7,6:4
-2,-7,6:102
-1,-7,6:102
0,-7,6:4
1,-7,6:102
2,-7,6:102
3,-7,6:1
4,-7,6:102
5,-7,6:102
6,-7,6:4
7,-7,6:98.1
-7,-6,6:4
-2,-6,6:4
1,-6,6:1
7,-6,6:1
-7,-5,6:102
-2,-5,6:4
1,-5,6:1
7,-5,6:102
-7,-4,6:102
-2,-4,6:4
-1,-4,6:4
0,-4,6:4
1,-4,6:4
7,-4,6:102
-7,-3,6:1
7,-3,6:4
-7,-2,6:102
7,-2,6:102
7,-1,6:102
7,0,6:1
-7,1,6:102
7,1,6:102
-7,2,6:102
7,2,6:102
-7,3,6:4
7,3,6:4
-7,4,6:102
7,4,6:102
-7,5,6:102
7,5,6:102
-7,6,6:4
7,6,6:1
-7,7,6:98.1
-6,7,6:1
-5,7,6:102
-4,7,6:102
-3,7,6:4
-2,7,6:102
-1,7,6:102
0,7,6:4
1,7,6:102
2,7,6:102
3,7,6:1
4,7,6:102
5,7,6:102
6,7,6:1
7,7,6:98.2
-7,-7,7:98.1
-6,-7,7:1
-5,-7,7:102
-4,-7,7:102
-3,-7,7:1
-2,-7,7:102
-1,-7,7:102
0,-7,7:1
1,-7,7:102
2,-7,7:102
3,-7,7:4
4,-7,7:102
5,-7,7:102
6,-7,7:1
7,-7,7:98.0
-7,-6,7:4
-2,-6,7:4
0,-6,7:1
7,-6,7:1
-7,-5,7:102
-2,-5,7:4
0,-5,7:1
7,-5,7:102
-7,-4,7:102
-2,-4,7:4
-1,-4,7:4
0,-4,7:4
7,-4,7:102
-7,-3,7:4
7,-3,7:4
-7,-2,7:102
7,-2,7:102
-7,-1,7:102
7,-1,7:102
7,0,7:4
-7,1,7:102
7,1,7:102
-7,2,7:102
7,2,7:102
-7,3,7:4
7,3,7:1
-7,4,7:102
7,4,7:102
-7,5,7:102
7,5,7:102
-7,6,7:1
7,6,7:4
-7,7,7:98.1
-6,7,7:1
-5,7,7:102
-4,7,7:102
-3,7,7:4
-2,7,7:102
-1,7,7:102
0,7,7:1
1,7,7:102
2,7,7:102
3,7,7:4
4,7,7:102
5,7,7:102
6,7,7:4
7,7,7:98.0
-7,-7,8:98.0
-6,-7,8:1
-5,-7,8:102
-4,-7,8:102
-3,-7,8:1
-2,-7,8:102
-1,-7,8:102
0,-7,8:4
1,-7,8:102
2,-7,8:102
3,-7,8:4
4,-7,8:102
5,-7,8:102
6,-7,8:4
7,-7,8:98.1
-7,-6,8:1
-2,-6,8:4
-1,-6,8:1
7,-6,8:4
-7,-5,8:102
-2,-5,8:4
-1,-5,8:1
7,-5,8:102
-7,-4,8:102
-2,-4,8:4
-1,-4,8:4
7,-4,8:102
-7,-3,8:4
7,-3,8:1
-7,-2,8:102
7,-2,8:102
-7,-1,8:102
7,-1,8:102
-7,0,8:4
7,0,8:4
-7,1,8:102
7,1,8:102
-7,2,8:102
7,2,8:102
-7,3,8:4
7,3,8:4
-7,4,8:102
7,4,8:102
-7,5,8:102
7,5,8:102
-7,6,8:1
7,6,8:4
-7,7,8:98.1
-6,7,8:4
-5,7,8:102
-4,7,8:102
-3,7,8:1
-2,7,8:102
-1,7,8:102
0,7,8:1
1,7,8:102
2,7,8:102
3,7,8:1
4,7,8:102
5,7,8:102
6,7,8:4
7,7,8:98.2
-7,-7,9:98.0
-6,-7,9:98.0
-5,-7,9:98.2
-4,-7,9:98.2
-3,-7,9:98.2
-2,-7,9:98.0
-1,-7,9:98.1
0,-7,9:98.2
1,-7,9:98.2
2,-7,9:98.0
3,-7,9:98.1
4,-7,9:98.1
5,-7,9:98.1
6,-7,9:98.1
7,-7,9:98.0
-7,-6,9:98.0
-6,-6,9:4
-5,-6,9:4
-4,-6,9:4
-3,-6,9:1
-2,-6,9:4
2,-6,9:4
3,-6,9:4
4,-6,9:4
5,-6,9:4
6,-6,9:4
7,-6,9:98.2
-7,-5,9:98.0
-6,-5,9:4
-5,-5,9:1
-4,-5,9:4
-3,-5,9:1
-2,-5,9:4
2,-5,9:4
3,-5,9:1
4,-5,9:1
5,-5,9:1
6,-5,9:4
7,-5,9:98.1
-7,-4,9:98.0
-6,-4,9:4
-5,-4,9:4
-4,-4,9:4
-3,-4,9:4
-2,-4,9:1
-1,-4,9:1
0,-4,9:1
1,-4,9:4
2,-4,9:4
3,-4,9:1
4,-4,9:1
5,-4,9:1
6,-4,9:1
7,-4,9:98.0
-7,-3,9:98.2
-6,-3,9:4
-5,-3,9:4
-4,-3,9:4
-3,-3,9:4
-2,-3,9:4
-1,-3,9:1
0,-3,9:4
1,-3,9:1
2,-3,9:1
3,-3,9:1
4,-3,9:4
5,-3,9:1
6,-3,9:4
7,-3,9:98.2
-7,-2,9:98.2
-6,-2,9:4
-5,-2,9:4
-4,-2,9:1
-3,-2,9:1
-2,-2,9:1
-1,-2,9:4
0,-2,9:1
1,-2,9:4
2,-2,9:1
3,-2,9:4
4,-2,9:1
5,-2,9:1
6,-2,9:1
7,-2,9:98.2
-7,-1,9:98.2
-6,-1,9:4
-5,-1,9:4
-4,-1,9:1
-3,-1,9:1
-2,-1,9:4
-1,-1,9:4
0,-1,9:1
1,-1,9:4
2,-1,9:4
3,-1,9:4
4,-1,9:4
5,-1,9:4
6,-1,9:1
7,-1,9:98.0
-7,0,9:98.1
-6,0,9:4
-5,0,9:1
-4,0,9:1
-3,0,9:4
-2,0,9:1
-1,0,9:4
0,0,9:4
1,0,9:1
2,0,9:1
3,0,9:4
4,0,9:4
5,0,9:1
6,0,9:1
7,0,9:98.2
-7,1,9:98.0
-6,1,9:4
-5,1,9:4
-4,1,9:4
-3,1,9:4
-2,1,9:4
-1,1,9:4
0,1,9:4
1,1,9:4
2,1,9:4
3,1,9:1
4,1,9:4
5,1,9:4
6,1,9:4
7,1,9:98.0
-7,2,9:98.0
-6,2,9:1
-5,2,9:1
-4,2,9:1
-3,2,9:4
-2,2,9:1
-1,2,9:4
0,2,9:1
1,2,9:4
2,2,9:1
3,2,9:4
4,2,9:4
5,2,9:1
6,2,9:4
7,2,9:98.0
-7,3,9:98.1
-6,3,9:4
-5,3,9:4
-4,3,9:4
-3,3,9:1
-2,3,9:1
-1,3,9:1
0,3,9:1
1,3,9:1
2,3,9:1
3,3,9:4
4,3,9:1
5,3,9:4
6,3,9:4
7,3,9:98.2
-7,4,9:98.0
-6,4,9:4
-5,4,9:4
-4,4,9:1
-3,4,9:1
-2,4,9:1
-1,4,9:4
0,4,9:1
1,4,9:4
2,4,9:1
3,4,9:4
4,4,9:4
5,4,9:4
6,4,9:1
7,4,9:98.0
-7,5,9:98.1
-6,5,9:1
-5,5,9:1
-4,5,9:1
-3,5,9:1
-2,5,9:4
-1,5,9:1
0,5,9:4
1,5,9:1
2,5,9:4
3,5,9:4
4,5,9:4
5,5,9:1
6,5,9:4
7,5,9:98.2
-7,6,9:98.2
-6,6,9:1
-5,6,9:4
-4,6,9:1
-3,6,9:4
-2,6,9:4
-1,6,9:1
0,6,9:4
1,6,9:4
2,6,9:1
3,6,9:1
4,6,9:4
5,6,9:4
6,6,9:1
7,6,9:98.1
-7,7,9:98.1
-6,7,9:98.1
-5,7,9:98.2
-4,7,9:98.2
-3,7,9:98.0
-2,7,9:98.1
-1,7,9:98.1
0,7,9:98.1
1,7,9:98.0
2,7,9:98.1
3,7,9:98.0
4,7,9:98.1
5,7,9:98.0
6,7,9:98.0
7,7,9:98.0
-7,-7,10:98.0
-6,-7,10:98.0
-5,-7,10:98.2
-4,-7,10:98.0
-3,-7,10:98.1
-2,-7,10:98.0
-1,-7,10:98.0
0,-7,10:98.1
1,-7,10:98.0
2,-7,10:98.1
3,-7,10:98.2
4,-7,10:98.1
5,-7,10:98.2
6,-7,10:98.0
7,-7,10:98.1
-7,-6,10:98.1
7,-6,10:98.0
-7,-5,10:98.0
7,-5,10:98.1
-7,-4,10:98.2
7,-4,10:98.0
-7,-3,10:98.2
7,-3,10:98.0
-7,-2,10:98.1
7,-2,10:98.1
-7,-1,10:98.0
7,-1,10:98.1
-7,0,10:98.0
7,0,10:98.0
-7,1,10:98.2
7,1,10:98.1
-7,2,10:98.0
7,2,10:98.2
-7,3,10:98.0
7,3,10:98.2
-7,4,10:98.2
-2,4,10:4
-1,4,10:4
0,4,10:4
1,4,10:4
2,4,10:4
7,4,10:98.2
-7,5,10:98.0
-2,5,10:1
2,5,10:4
7,5,10:98.2
-7,6,10:98.0
-2,6,10:1
2,6,10:4
7,6,10:98.2
-7,7,10:98.2
-6,7,10:98.1
-5,7,10:98.2
-4,7,10:98.0
-3,7,10:98.1
-2,7,10:98.0
-1,7,10:98.1
0,7,10:98.1
1,7,10:98.1
2,7,10:98.2
3,7,10:98.0
4,7,10:98.2
5,7,10:98.2
6,7,10:98.2
7,7,10:98.0
-7,-7,11:98.0
-6,-7,11:1
-5,-7,11:102
-4,-7,11:102
-3,-7,11:4
-2,-7,11:102
-1,-7,11:102
0,-7,11:4
1,-7,11:102
2,-7,11:102
3,-7,11:1
4,-7,11:102
5,-7,11:102
6,-7,11:1
7,-7,11:98.0
-7,-6,11:1
7,-6,11:1
-7,-5,11:102
7,-5,11:102
-7,-4,11:102
7,-4,11:102
-7,-3,11:1
7,-3,11:1
-7,-2,11:102
7,-2,11:102
-7,-1,11:102
7,-1,11:102
-7,0,11:4
7,0,11:1
-7,1,11:102
7,1,11:102
-7,2,11:102
7,2,11:102
-7,3,11:1
7,3,11:4
-7,4,11:102
-1,4,11:4
0,4,11:4
1,4,11:4
2,4,11:4
7,4,11:102
-7,5,11:102
-1,5,11:1
2,5,11:4
7,5,11:102
-7,6,11:1
-1,6,11:1
2,6,11:4
7,6,11:1
-7,7,11:98.0
-6,7,11:1
-5,7,11:102
-4,7,11:102
-3,7,11:4
-2,7,11:102
-1,7,11:102
0,7,11:4
1,7,11:102
2,7,11:102
3,7,11:1
4,7,11:102
5,7,11:102
6,7,11:4
7,7,11:98.2
-7,-7,12:98.2
-6,-7,12:1
-5,-7,12:102
-4,-7,12:102
-3,-7,12:1
-2,-7,12:102
-1,-7,12:102
0,-7,12:1
1,-7,12:102
2,-7,12:102
3,-7,12:4
4,-7,12:102
5,-7,12:102
6,-7,12:1
7,-7,12:98.0
-7,-6,12:1
7,-6,12:1
-7,-5,12:102
7,-5,12:102
-7,-4,12:102
7,-4,12:102
-7,-3,12:1
7,-3,12:1
-7,-2,12:102
7,-2,12:102
-7,-1,12:102
7,-1,12:102
-7,0,12:1
7,0,12:1
-7,1,12:102
7,1,12:102
-7,2,12:102
7,2,12:102
-7,3,12:1
7,3,12:1
-7,4,12:102
0,4,12:4
1,4,12:4
2,4,12:4
7,4,12:102
-7,5,12:102
0,5,12:1
2,5,12:4
7,5,12:102
-7,6,12:4
0,6,12:1
2,6,12:4
7,6,12:1
-7,7,12:98.0
-6,7,12:4
-5,7,12:102
-4,7,12:102
-3,7,12:1
-2,7,12:102
-1,7,12:102
0,7,12:4
1,7,12:102
2,7,12:102
3,7,12:1
4,7,12:102
5,7,12:102
6,7,12:1
7,7,12:98.0
-7,-7,13:98.0
-6,-7,13:4
-5,-7,13:102
-4,-7,13:102
-3,-7,13:1
-2,-7,13:102
-1,-7,13:102
0,-7,13:4
1,-7,13:102
2,-7,13:102
3,-7,13:1
4,-7,13:102
5,-7,13:102
6,-7,13:4
7,-7,13:98.1
-7,-6,13:1
7,-6,13:4
-7,-5,13:102
7,-5,13:102
-7,-4,13:102
7,-4,13:102
-7,-3,13:4
-7,-2,13:102
7,-2,13:102
-7,-1,13:102
7,-1,13:102
-7,0,13:1
7,0,13:4
-7,1,13:102
7,1,13:102
-7,2,13:102
7,2,13:102
-7,3,13:1
7,3,13:4
-7,4,13:102
1,4,13:4
2,4,13:4
7,4,13:102
-7,5,13:102
1,5,13:1
2,5,13:4
7,5,13:102
-7,6,13:4
1,6,13:1
2,6,13:4
7,6,13:4
-7,7,13:98.2
-6,7,13:1
-5,7,13:102
-4,7,13:102
-3,7,13:1
-2,7,13:102
-1,7,13:102
0,7,13:4
1,7,13:102
2,7,13:102
3,7,13:4
4,7,13:102
5,7,13:102
6,7,13:1
7,7,13:98.1
-7,-7,14:98.1
-6,-7,14:98.1
-5,-7,14:98.2
-4,-7,14:98.1
-3,-7,14:98.2
-2,-7,14:98.0
-1,-7,14:98.0
0,-7,14:98.0
1,-7,14:98.2
2,-7,14:98.1
3,-7,14:98.0
4,-7,14:98.1
5,-7,14:98.0
6,-7,14:98.2
7,-7,14:98.2
-7,-6,14:98.1
-6,-6,14:1
-5,-6,14:4
-4,-6,14:4
-3,-6,14:1
-2,-6,14:1
-1,-6,14:4
0,-6,14:1
1,-6,14:1
2,-6,14:1
3,-6,14:1
4,-6,14:4
5,-6,14:4
6,-6,14:1
7,-6,14:98.2
-7,-5,14:98.2
-6,-5,14:1
-5,-5,14:4
-4,-5,14:4
-3,-5,14:4
-2,-5,14:1
-1,-5,14:4
0,-5,14:4
1,-5,14:1
2,-5,14:4
3,-5,14:1
4,-5,14:4
5,-5,14:1
6,-5,14:4
7,-5,14:98.0
-7,-4,14:98.0
-6,-4,14:4
-5,-4,14:1
-4,-4,14:4
-3,-4,14:1
-2,-4,14:1
-1,-4,14:1
0,-4,14:4
1,-4,14:4
2,-4,14:1
3,-4,14:1
4,-4,14:4
5,-4,14:4
6,-4,14:4
-7,-3,14:98.1
-6,-3,14:4
-5,-3,14:1
-4,-3,14:4
-3,-3,14:4
-2,-3,14:1
-1,-3,14:1
0,-3,14:4
1,-3,14:4
2,-3,14:1
3,-3,14:1
4,-3,14:4
5,-3,14:1
6,-3,14:4
-7,-2,14:98.0
-6,-2,14:1
-5,-2,14:1
-4,-2,14:1
-3,-2,14:4
-2,-2,14:1
-1,-2,14:4
0,-2,14:4
1,-2,14:1
2,-2,14:1
3,-2,14:1
4,-2,14:4
5,-2,14:1
6,-2,14:4
7,-2,14:98.1
-7,-1,14:98.2
-6,-1,14:1
-5,-1,14:1
-4,-1,14:4
-3,-1,14:4
-2,-1,14:4
-1,-1,14:4
0,-1,14:1
1,-1,14:1
2,-1,14:4
3,-1,14:4
4,-1,14:4
5,-1,14:1
6,-1,14:1
7,-1,14:98.1
-7,0,14:98.2
-6,0,14:1
-5,0,14:4
-4,0,14:1
-3,0,14:4
-2,0,14:4
-1,0,14:1
0,0,14:1
1,0,14:1
2,0,14:1
3,0,14:4
4,0,14:1
5,0,14:1
6,0,14:4
7,0,14:98.2
-7,1,14:98.1
-6,1,14:1
-5,1,14:4
-4,1,14:4
-3,1,14:1
-2,1,14:4
-1,1,14:1
0,1,14:1
1,1,14:1
2,1,14:4
3,1,14:1
4,1,14:4
5,1,14:4
6,1,14:1
7,1,14:98.1
-7,2,14:98.0
-6,2,14:1
-5,2,14:4
-4,2,14:1
-3,2,14:4
-2,2,14:4
-1,2,14:1
0,2,14:4
1,2,14:1
2,2,14:1
3,2,14:1
4,2,14:4
5,2,14:4
6,2,14:1
7,2,14:98.1
-7,3,14:98.2
-6,3,14:4
-5,3,14:1
-4,3,14:4
-3,3,14:1
-2,3,14:1
-1,3,14:1
0,3,14:1
1,3,14:4
2,3,14:1
3,3,14:4
4,3,14:4
5,3,14:4
6,3,14:4
7,3,14:98.0
-7,4,14:98.2
-6,4,14:1
-5,4,14:4
-4,4,14:4
-3,4,14:1
-2,4,14:4
-1,4,14:4
0,4,14:4
1,4,14:1
2,4,14:1
3,4,14:1
4,4,14:4
5,4,14:1
6,4,14:1
7,4,14:98.1
-7,5,14:98.2
-6,5,14:4
-5,5,14:4
-4,5,14:4
-3,5,14:1
-2,5,14:1
2,5,14:4
3,5,14:4
4,5,14:1
5,5,14:4
6,5,14:4
7,5,14:98.1
-7,6,14:98.0
-6,6,14:4
-5,6,14:1
-4,6,14:1
-3,6,14:4
-2,6,14:4
2,6,14:4
3,6,14:4
4,6,14:1
5,6,14:1
6,6,14:1
7,6,14:98.2
-7,7,14:98.1
-6,7,14:98.1
-5,7,14:98.1
-4,7,14:98.0
-3,7,14:98.2
-2,7,14:98.2
-1,7,14:98.0
0,7,14:98.1
1,7,14:98.2
2,7,14:98.1
3,7,14:98.1
4,7,14:98.0
5,7,14:98.0
6,7,14:98.1
7,7,14:98.2
-7,-7,15:98.0
-6,-7,15:98.2
-5,-7,15:98.1
-4,-7,15:98.2
-3,-7,15:98.1
-2,-7,15:98.2
-1,-7,15:98.2
0,-7,15:98.0
1,-7,15:98.2
2,-7,15:98.0
3,-7,15:98.2
4,-7,15:98.0
5,-7,15:98.2
6,-7,15:98.1
7,-7,15:98.0
-7,-6,15:98.1
4,-6,15:4
5,-6,15:4
6,-6,15:4
7,-6,15:98.2
-7,-5,15:98.0
1,-5,15:44.3
3,-5,15:44.3
4,-5,15:4
5,-5,15:4
6,-5,15:44.3
7,-5,15:98.1
-7,-4,15:98.1
1,-4,15:44.3
2,-4,15:4
3,-4,15:44.3
4,-4,15:44.3
5,-4,15:44.3
6,-4,15:44.3
-7,-3,15:98.2
2,-3,15:44.3
3,-3,15:4
4,-3,15:4
5,-3,15:4
6,-3,15:44.3
-7,-2,15:98.1
2,-2,15:44.3
3,-2,15:4
4,-2,15:4
5,-2,15:43.3
6,-2,15:4
7,-2,15:44.3
-7,-1,15:98.0
1,-1,15:44.3
2,-1,15:4
3,-1,15:44.3
4,-1,15:4
5,-1,15:4
6,-1,15:4
7,-1,15:98.2
-7,0,15:98.1
2,0,15:44.3
3,0,15:4
4,0,15:44.3
5,0,15:4
6,0,15:44.3
7,0,15:98.2
-7,1,15:98.2
3,1,15:44.3
5,1,15:44.3
7,1,15:98.2
-7,2,15:98.0
7,2,15:98.2
-7,3,15:98.2
7,3,15:98.1
-7,4,15:98.1
7,4,15:98.1
-7,5,15:98.1
7,5,15:98.0
-7,6,15:98.2
7,6,15:98.0
-7,7,15:98.2
-6,7,15:98.0
-5,7,15:98.2
-4,7,15:98.0
-3,7,15:98.1
-2,7,15:98.2
-1,7,15:98.2
0,7,15:98.0
1,7,15:98.0
2,7,15:98.2
3,7,15:98.0
4,7,15:98.0
5,7,15:98.1
6,7,15:98.0
7,7,15:98.0
-7,-7,16:98.0
-6,-7,16:1
-5,-7,16:102
-4,-7,16:102
-3,-7,16:1
-2,-7,16:102
-1,-7,16:102
0,-7,16:4
1,-7,16:102
2,-7,16:102
3,-7,16:4
4,-7,16:102
5,-7,16:102
6,-7,16:1
7,-7,16:98.2
-7,-6,16:1
6,-6,16:52
7,-6,16:4
-7,-5,16:102
7,-5,16:102
-7,-4,16:102
-7,-3,16:1
4,-3,16:44.3
-7,-2,16:102
3,-2,16:44.3
4,-2,16:43.3
5,-2,16:44.3
-7,-1,16:102
7,-1,16:102
-7,0,16:4
5,0,16:44.3
7,0,16:1
-7,1,16:102
7,1,16:102
-7,2,16:102
7,2,16:102
-7,3,16:4
7,3,16:1
-7,4,16:102
7,4,16:102
-7,5,16:102
7,5,16:102
-7,6,16:1
7,6,16:4
-7,7,16:98.1
-6,7,16:1
-5,7,16:102
-4,7,16:102
-3,7,16:1
-2,7,16:102
-1,7,16:102
0,7,16:1
1,7,16:102
2,7,16:102
3,7,16:4
4,7,16:102
5,7,16:102
6,7,16:1
7,7,16:98.1
-7,-7,17:98.2
-6,-7,17:1
-5,-7,17:102
-4,-7,17:102
-3,-7,17:4
-2,-7,17:102
-1,-7,17:102
0,-7,17:4
1,-7,17:102
2,-7,17:102
3,-7,17:4
4,-7,17:102
5,-7,17:102
6,-7,17:4
7,-7,17:98.0
-7,-6,17:4
7,-6,17:1
-7,-5,17:102
-7,-4,17:102
-7,-3,17:4
-7,-2,17:102
-7,-1,17:102
-7,0,17:1
7,0,17:1
-7,1,17:102
7,1,17:102
-7,2,17:102
7,2,17:102
-7,3,17:1
7,3,17:4
-7,4,17:102
7,4,17:102
-7,5,17:102
7,5,17:102
-7,6,17:1
7,6,17:4
-7,7,17:98.1
-6,7,17:4
-5,7,17:102
-4,7,17:102
-3,7,17:4
-2,7,17:102
-1,7,17:102
0,7,17:1
1,7,17:102
2,7,17:102
3,7,17:4
4,7,17:102
5,7,17:102
6,7,17:4
7,7,17:98.1
-7,-7,18:98.1
-6,-7,18:1
-5,-7,18:102
-4,-7,18:102
-3,-7,18:1
-2,-7,18:102
-1,-7,18:102
0,-7,18:4
1,-7,18:102
2,-7,18:102
3,-7,18:1
4,-7,18:102
5,-7,18:102
6,-7,18:4
7,-7,18:98.1
-7,-6,18:1
7,-6,18:1
-7,-5,18:102
-7,-4,18:102
-7,-3,18:1
-7,-2,18:102
-7,-1,18:102
-7,0,18:1
7,0,18:4
-7,1,18:102
7,1,18:102
-7,2,18:102
7,2,18:102
-7,3,18:1
7,3,18:4
-7,4,18:102
7,4,18:102
-7,5,18:102
7,5,18:102
-7,6,18:1
7,6,18:1
-7,7,18:98.2
-6,7,18:4
-5,7,18:102
-4,7,18:102
-3,7,18:4
-2,7,18:102
-1,7,18:102
0,7,18:1
1,7,18:102
2,7,18:102
3,7,18:4
4,7,18:102
5,7,18:102
6,7,18:4
7,7,18:98.0
-7,-7,19:98.0
-6,-7,19:98.2
-5,-7,19:98.1
-4,-7,19:98.0
-3,-7,19:98.2
-2,-7,19:98.0
-1,-7,19:98.1
0,-7,19:98.1
1,-7,19:98.2
2,-7,19:98.2
3,-7,19:98.1
4,-7,19:98.0
5,-7,19:98.0
6,-7,19:98.2
7,-7,19:98.2
-7,-6,19:98.2
-6,-6,19:4
-5,-6,19:4
-4,-6,19:1
-3,-6,19:4
-2,-6,19:4
-1,-6,19:1
0,-6,19:1
1,-6,19:1
2,-6,19:1
3,-6,19:4
4,-6,19:1
5,-6,19:4
6,-6,19:1
7,-6,19:98.1
-7,-5,19:98.1
-6,-5,19:4
-5,-5,19:1
-4,-5,19:1
-3,-5,19:4
-2,-5,19:4
-1,-5,19:1
0,-5,19:1
1,-5,19:4
2,-5,19:1
3,-5,19:4
4,-5,19:1
5,-5,19:1
-7,-4,19:98.1
-6,-4,19:1
-5,-4,19:1
-4,-4,19:4
-3,-4,19:4
-2,-4,19:4
-1,-4,19:4
0,-4,19:1
1,-4,19:1
2,-4,19:1
3,-4,19:1
4,-4,19:4
-7,-3,19:98.0
-6,-3,19:4
-5,-3,19:1
-4,-3,19:1
-3,-3,19:4
-2,-3,19:4
-1,-3,19:1
0,-3,19:4
1,-3,19:4
2,-3,19:1
3,-3,19:4
-7,-2,19:98.2
-6,-2,19:4
-5,-2,19:4
-4,-2,19:1
-3,-2,19:1
-2,-2,19:1
-1,-2,19:1
0,-2,19:4
1,-2,19:4
2,-2,19:1
-7,-1,19:98.1
-6,-1,19:4
-5,-1,19:4
-4,-1,19:1
-3,-1,19:1
-2,-1,19:1
-1,-1,19:4
0,-1,19:4
1,-1,19:1
2,-1,19:4
3,-1,19:4
-7,0,19:98.2
-6,0,19:1
-5,0,19:1
-4,0,19:4
-3,0,19:1
-2,0,19:4
-1,0,19:1
0,0,19:4
1,0,19:4
2,0,19:1
3,0,19:1
4,0,19:4
5,0,19:4
6,0,19:4
7,0,19:98.2
-7,1,19:98.2
-6,1,19:1
-5,1,19:1
-4,1,19:1
-3,1,19:4
-2,1,19:4
-1,1,19:1
0,1,19:4
1,1,19:4
2,1,19:1
3,1,19:4
4,1,19:4
5,1,19:4
6,1,19:1
7,1,19:98.1
-7,2,19:98.1
-6,2,19:1
-5,2,19:4
-4,2,19:1
-3,2,19:4
-2,2,19:4
-1,2,19:4
0,2,19:1
1,2,19:1
2,2,19:1
3,2,19:1
4,2,19:1
5,2,19:4
6,2,19:1
7,2,19:98.0
-7,3,19:98.0
-6,3,19:1
-5,3,19:4
-4,3,19:4
-3,3,19:1
-2,3,19:1
-1,3,19:1
0,3,19:1
1,3,19:4
2,3,19:4
3,3,19:1
4,3,19:1
5,3,19:1
6,3,19:1
7,3,19:98.2
-7,4,19:98.0
-6,4,19:1
-5,4,19:4
-4,4,19:1
-3,4,19:1
-2,4,19:4
-1,4,19:1
0,4,19:4
1,4,19:1
2,4,19:4
3,4,19:1
4,4,19:1
5,4,19:4
6,4,19:4
7,4,19:98.1
-7,5,19:98.1
-6,5,19:1
-5,5,19:1
-4,5,19:1
-3,5,19:1
-2,5,19:1
-1,5,19:1
0,5,19:4
1,5,19:1
2,5,19:1
3,5,19:4
4,5,19:4
5,5,19:1
6,5,19:4
7,5,19:98.1
-7,6,19:98.1
-6,6,19:4
-5,6,19:4
-4,6,19:4
-3,6,19:1
-2,6,19:1
-1,6,19:4
0,6,19:4
1,6,19:4
2,6,19:4
3,6,19:4
4,6,19:4
5,6,19:1
6,6,19:1
7,6,19:98.2
-7,7,19:98.2
-6,7,19:98.1
-5,7,19:98.2
-4,7,19:98.0
-3,7,19:98.0
-2,7,19:98.2
-1,7,19:98.1
0,7,19:98.2
1,7,19:98.2
2,7,19:98.0
3,7,19:98.2
4,7,19:98.2
5,7,19:98.2
6,7,19:98.2
7,7,19:98.0
-7,-7,20:98.1
-6,-7,20:98.2
-5,-7,20:98.1
-4,-7,20:98.2
-3,-7,20:98.0
-2,-7,20:98.2
-1,-7,20:98.0
0,-7,20:98.1
1,-7,20:98.2
2,-7,20:98.0
3,-7,20:98.0
4,-7,20:98.2
5,-7,20:98.0
6,-7,20:98.1
7,-7,20:98.1
-7,-6,20:98.2
2,-6,20:44.3
7,-6,20:98.2
-7,-5,20:98.1
0,-5,20:44.3
1,-5,20:44.3
2,-5,20:44.3
7,-5,20:98.1
-7,-4,20:98.0
-2,-4,20:44.3
-1,-4,20:44.3
0,-4,20:44.3
1,-4,20:44.3
2,-4,20:44.3
3,-4,20:44.3
-7,-3,20:98.2
-6,-3,20:44.3
-3,-3,20:44.3
-2,-3,20:4
-1,-3,20:4
0,-3,20:44.3
1,-3,20:44.3
2,-3,20:44.3
3,-3,20:44.3
-7,-2,20:98.1
-6,-2,20:44.3
-5,-2,20:44.3
-4,-2,20:44.3
-3,-2,20:4
-2,-2,20:4
-1,-2,20:4
0,-2,20:4
1,-2,20:44.3
2,-2,20:44.3
-7,-1,20:98.1
-6,-1,20:44.3
-5,-1,20:44.3
-4,-1,20:4
-3,-1,20:4
-2,-1,20:4
-1,-1,20:4
0,-1,20:4
1,-1,20:4
2,-1,20:44.3
3,-1,20:44.3
-7,0,20:98.1
-5,0,20:44.3
-4,0,20:44.3
-3,0,20:4
-2,0,20:4
-1,0,20:4
0,0,20:4
1,0,20:4
2,0,20:4
3,0,20:44.3
4,0,20:44.3
-7,1,20:98.0
-4,1,20:44.3
-3,1,20:4
-2,1,20:4
-1,1,20:4
0,1,20:4
1,1,20:4
2,1,20:4
3,1,20:44.3
4,1,20:44.3
7,1,20:98.2
-7,2,20:98.2
-4,2,20:44.3
-3,2,20:44.3
-2,2,20:4
-1,2,20:4
0,2,20:4
1,2,20:4
2,2,20:4
3,2,20:4
4,2,20:44.3
5,2,20:44.3
7,2,20:98.0
-7,3,20:98.2
-3,3,20:44.3
-2,3,20:44.3
-1,3,20:44.3
0,3,20:4
1,3,20:4
2,3,20:4
3,3,20:4
4,3,20:44.3
7,3,20:98.2
-7,4,20:98.0
-4,4,20:44.3
-3,4,20:44.3
-2,4,20:44.3
0,4,20:44.3
1,4,20:4
2,4,20:4
3,4,20:44.3
7,4,20:98.0
-7,5,20:98.1
1,5,20:44.3
7,5,20:98.0
-7,6,20:98.2
7,6,20:98.1
-7,7,20:98.2
-6,7,20:98.2
-5,7,20:98.1
-4,7,20:98.2
-3,7,20:98.0
-2,7,20:98.1
-1,7,20:98.1
0,7,20:98.0
1,7,20:98.2
2,7,20:98.0
3,7,20:98.2
4,7,20:98.0
5,7,20:98.2
6,7,20:98.1
7,7,20:98.0
-7,-7,21:98.2
-6,-7,21:4
-5,-7,21:102
-4,-7,21:102
-3,-7,21:1
-2,-7,21:102
-1,-7,21:102
0,-7,21:1
1,-7,21:102
2,-7,21:102
3,-7,21:1
4,-7,21:102
5,-7,21:102
6,-7,21:4
7,-7,21:98.2
-7,-6,21:1
7,-6,21:1
-7,-5,21:102
7,-5,21:102
-7,-4,21:102
-7,-3,21:4
-7,-2,21:102
-2,-2,21:44.3
-1,-2,21:44.3
-7,-1,21:102
-3,-1,21:44.3
-2,-1,21:44.3
-1,-1,21:4
0,-1,21:44.3
-7,0,21:1
-2,0,21:44.3
-1,0,21:4
0,0,21:4
1,0,21:44.3
-7,1,21:102
-3,1,21:44.3
-2,1,21:44.3
-1,1,21:44.3
0,1,21:4
1,1,21:4
7,1,21:102
-7,2,21:102
-1,2,21:44.3
0,2,21:44.3
1,2,21:44.3
2,2,21:44.3
7,2,21:102
-7,3,21:1
0,3,21:44.3
2,3,21:44.3
7,3,21:1
-7,4,21:102
7,4,21:102
-7,5,21:102
7,5,21:102
-7,6,21:4
7,6,21:4
-7,7,21:98.1
-6,7,21:4
-5,7,21:102
-4,7,21:102
-3,7,21:1
-2,7,21:102
-1,7,21:102
0,7,21:4
1,7,21:102
2,7,21:102
3,7,21:4
4,7,21:102
5,7,21:102
6,7,21:1
7,7,21:98.0
-7,-7,22:98.0
-6,-7,22:1
-5,-7,22:102
-4,-7,22:102
-3,-7,22:1
-2,-7,22:102
-1,-7,22:102
0,-7,22:4
1,-7,22:102
2,-7,22:102
3,-7,22:4
4,-7,22:102
5,-7,22:102
6,-7,22:1
7,-7,22:98.0
-7,-6,22:1
7,-6,22:4
-7,-5,22:102
7,-5,22:102
-7,-4,22:102
-7,-3,22:1
-7,-2,22:102
-7,-1,22:102
-7,0,22:1
-7,1,22:102
7,1,22:102
-7,2,22:102
7,2,22:102
-7,3,22:1
7,3,22:1
-7,4,22:102
7,4,22:102
-7,5,22:102
7,5,22:102
-7,6,22:1
7,6,22:1
-7,7,22:98.0
-6,7,22:4
-5,7,22:102
-4,7,22:102
-3,7,22:1
-2,7,22:102
-1,7,22:102
0,7,22:1
1,7,22:102
2,7,22:102
3,7,22:4
4,7,22:102
5,7,22:102
6,7,22:4
7,7,22:98.0
-7,-7,23:98.1
-6,-7,23:1
-5,-7,23:102
-4,-7,23:102
-3,-7,23:1
-2,-7,23:102
-1,-7,23:102
0,-7,23:4
1,-7,23:102
2,-7,23:102
3,-7,23:1
4,-7,23:102
5,-7,23:102
6,-7,23:1
7,-7,23:98.0
-7,-6,23:1
7,-6,23:1
-7,-5,23:102
-7,-4,23:102
-7,-3,23:1
-7,-2,23:102
-7,-1,23:102
-7,0,23:4
7,0,23:4
-7,1,23:102
7,1,23:102
-7,2,23:102
7,2,23:102
-7,3,23:4
7,3,23:1
-7,4,23:102
7,4,23:102
-7,5,23:102
7,5,23:102
-7,6,23:4
7,6,23:4
-7,7,23:98.0
-6,7,23:1
-5,7,23:102
-4,7,23:102
-3,7,23:1
-2,7,23:102
-1,7,23:102
0,7,23:4
1,7,23:102
2,7,23:102
3,7,23:1
4,7,23:102
5,7,23:102
6,7,23:1
7,7,23:98.0
-7,-7,24:98.1
-6,-7,24:98.2
-5,-7,24:98.1
-4,-7,24:98.2
-3,-7,24:98.1
-2,-7,24:98.2
-1,-7,24:98.1
0,-7,24:98.2
1,-7,24:98.0
2,-7,24:98.1
3,-7,24:98.0
4,-7,24:98.1
5,-7,24:98.2
6,-7,24:98.1
7,-7,24:98.0
-7,-6,24:98.1
-6,-6,24:4
-5,-6,24:4
-4,-6,24:1
-3,-6,24:1
-2,-6,24:4
-1,-6,24:4
0,-6,24:1
1,-6,24:1
2,-6,24:4
3,-6,24:1
4,-6,24:1
5,-6,24:4
6,-6,24:4
7,-6,24:98.0
-7,-5,24:98.1
-6,-5,24:4
-5,-5,24:4
-4,-5,24:4
-3,-5,24:1
-2,-5,24:1
-1,-5,24:4
0,-5,24:1
1,-5,24:1
2,-5,24:1
3,-5,24:4
4,-5,24:1
-7,-4,24:98.0
-6,-4,24:4
-5,-4,24:4
-4,-4,24:4
-3,-4,24:4
-1,-4,24:1
0,-4,24:4
1,-4,24:1
2,-4,24:4
-7,-3,24:98.1
-6,-3,24:4
-5,-3,24:4
-7,-2,24:98.2
-6,-2,24:4
-5,-2,24:1
-7,-1,24:98.2
-6,-1,24:1
-7,0,24:98.2
-6,0,24:1
-5,0,24:4
6,0,24:4
7,0,24:98.1
-7,1,24:98.2
-6,1,24:4
-5,1,24:1
-4,1,24:1
7,1,24:98.2
-7,2,24:98.2
-6,2,24:4
-5,2,24:4
7,2,24:98.1
-7,3,24:98.1
-6,3,24:1
-5,3,24:1
-4,3,24:4
6,3,24:1
7,3,24:98.0
-7,4,24:98.0
-6,4,24:4
-5,4,24:4
-4,4,24:4
-3,4,24:4
5,4,24:4
6,4,24:1
7,4,24:98.1
-7,5,24:98.2
-6,5,24:1
-5,5,24:4
-4,5,24:4
4,5,24:1
5,5,24:4
6,5,24:1
7,5,24:98.0
-7,6,24:98.2
-6,6,24:4
-5,6,24:4
-4,6,24:4
-3,6,24:1
-2,6,24:1
0,6,24:4
1,6,24:4
2,6,24:4
3,6,24:1
4,6,24:1
5,6,24:1
6,6,24:4
7,6,24:98.2
-7,7,24:98.1
-6,7,24:98.1
-5,7,24:98.2
-4,7,24:98.0
-3,7,24:98.2
-2,7,24:98.2
-1,7,24:98.2
0,7,24:98.1
1,7,24:98.2
2,7,24:98.2
3,7,24:98.2
4,7,24:98.2
5,7,24:98.0
6,7,24:98.0
7,7,24:98.0
-6,-7,25:98.0
-5,-7,25:98.1
-4,-7,25:98.1
-3,-7,25:98.2
-2,-7,25:1
-1,-7,25:4
0,-7,25:4
1,-7,25:4
2,-7,25:1
3,-7,25:98.2
4,-7,25:98.2
5,-7,25:98.1
6,-7,25:98.1
-7,-6,25:98.2
7,-6,25:98.2
-7,-5,25:98.1
-7,-4,25:98.1
-7,-3,25:98.0
-7,-1,25:4
-7,0,25:4
7,0,25:4
-7,1,25:4
7,1,25:4
-7,2,25:4
7,2,25:1
-7,3,25:98.2
7,3,25:98.1
-7,4,25:98.1
7,4,25:98.1
-7,5,25:98.0
7,5,25:98.0
-7,6,25:98.0
7,6,25:98.0
-6,7,25:98.2
-5,7,25:98.0
-4,7,25:98.0
-3,7,25:98.2
-2,7,25:4
-1,7,25:4
0,7,25:4
1,7,25:4
2,7,25:1
3,7,25:98.1
4,7,25:98.2
5,7,25:98.2
6,7,25:98.1
-5,-7,26:98.0
-4,-7,26:98.1
-3,-7,26:98.1
-2,-7,26:4
-1,-7,26:4
0,-7,26:4
1,-7,26:4
2,-7,26:4
3,-7,26:98.2
5,-7,26:98.0
-7,-5,26:98.0
-7,-4,26:98.0
-7,-3,26:98.0
-7,-1,26:4
-7,0,26:4
-7,1,26:4
7,1,26:4
-7,2,26:4
7,2,26:4
-7,3,26:98.1
7,3,26:98.1
-7,4,26:98.1
7,4,26:98.2
-7,5,26:98.1
7,5,26:98.2
-5,7,26:98.2
-4,7,26:98.0
-3,7,26:98.0
-2,7,26:1
0,7,26:4
1,7,26:4
2,7,26:4
3,7,26:98.2
4,7,26:98.0
5,7,26:98.2
-5,-7,27:98.1
-4,-7,27:98.0
-3,-7,27:98.0
-2,-7,27:4
-1,-7,27:4
0,-7,27:4
2,-7,27:1
5,-7,27:98.2
-7,-5,27:98.2
-7,-4,27:98.2
-7,2,27:4
7,2,27:4
-7,3,27:98.1
7,3,27:98.0
-7,4,27:98.0
7,4,27:98.0
-7,5,27:98.2
7,5,27:98.0
-5,7,27:98.2
-4,7,27:98.0
2,7,27:4
3,7,27:98.0
4,7,27:98.2
5,7,27:98.2
-4,-7,28:98.1
-3,-7,28:98.1
-2,-7,28:4
-1,-7,28:4
7,2,28:1
-7,3,28:98.2
7,3,28:98.1
-7,4,28:98.0
7,4,28:98.1
3,7,28:98.0
4,7,28:98.1
-4,-7,29:98.2
-3,-7,29:98.0
-2,-7,29:1
7,2,29:4
7,3,29:98.1
-7,4,29:98.1
7,4,29:98.1
4,7,29:98.2
