[META]
version=2.0
spawnOnBlockType=13
spawnSunlight=True
spawnDarkness=False
spawnWater=False
spawnLava=False
underFill=True
randomRotation=True
dig=True
tree=False
branch=False
needsFoundation=True
rarity=3
collisionPercentage=2
spawnElevationMin=0
spawnElevationMax=128
spawnInBiome=Flat
[DATA]
-7,-7,0:13
-6,-7,0:4
-5,-7,0:4
-4,-7,0:13
-3,-7,0:4
-2,-7,0:48
-1,-7,0:13
0,-7,0:4
1,-7,0:4
2,-7,0:4
3,-7,0:13
4,-7,0:4
5,-7,0:13
6,-7,0:4
7,-7,0:48
-7,-6,0:13
-6,-6,0:13
-5,-6,0:4
-4,-6,0:13
-3,-6,0:1
-2,-6,0:4
-1,-6,0:1
0,-6,0:4
1,-6,0:4
2,-6,0:1
3,-6,0:13
4,-6,0:13
5,-6,0:13
6,-6,0:1
7,-6,0:4
-7,-5,0:4
-6,-5,0:13
-5,-5,0:31.1
2,-5,0:31.1
3,-5,0:31.1
5,-5,0:31.1
6,-5,0:1
7,-5,0:48
-7,-4,0:13
-6,-4,0:13
-5,-4,0:37
-3,-4,0:31.1
0,-4,0:31.1
6,-4,0:4
7,-4,0:48
-7,-3,0:4
-3,-3,0:31.1
1,-3,0:31.1
6,-3,0:98.0
7,-3,0:48
-7,-2,0:13
-6,-2,0:1
2,-2,0:31.1
7,-2,0:71.6
-7,-1,0:48
-6,-1,0:4
4,-1,0:31.1
5,-1,0:31.1
6,-1,0:98.0
7,-1,0:48
-7,0,0:13
-6,0,0:4
-1,0,0:31.1
1,0,0:31.1
4,0,0:31.1
6,0,0:1
7,0,0:48
-7,1,0:13
-6,1,0:4
-5,1,0:31.1
-3,1,0:31.1
1,1,0:31.1
3,1,0:37
6,1,0:4
7,1,0:48
-7,2,0:4
-6,2,0:1
-2,2,0:31.1
-1,2,0:37
0,2,0:31.1
1,2,0:31.1
4,2,0:31.1
6,2,0:4
7,2,0:4
-7,3,0:13
-6,3,0:4
-3,3,0:52
-2,3,0:98.0
-1,3,0:98.0
0,3,0:98.0
1,3,0:98.0
2,3,0:98.0
4,3,0:31.1
5,3,0:31.1
6,3,0:4
7,3,0:4
-7,4,0:4
-6,4,0:13
-4,4,0:4
-3,4,0:4
-2,4,0:4
2,4,0:67.1
3,4,0:31.1
4,4,0:4
5,4,0:13
6,4,0:1
7,4,0:48
-7,5,0:4
-6,5,0:13
-5,5,0:4
-4,5,0:13
-3,5,0:13
-2,5,0:13
-1,5,0:4
0,5,0:4
1,5,0:13
2,5,0:67.1
3,5,0:4
4,5,0:4
5,5,0:4
6,5,0:1
7,5,0:48
-7,6,0:13
-6,6,0:4
-5,6,0:4
-4,6,0:1
-3,6,0:4
-2,6,0:4
-1,6,0:1
0,6,0:1
1,6,0:4
2,6,0:1
3,6,0:1
4,6,0:1
5,6,0:4
6,6,0:1
7,6,0:48
-7,7,0:4
-6,7,0:48
-5,7,0:4
-4,7,0:4
-3,7,0:48
-2,7,0:4
-1,7,0:48
0,7,0:4
1,7,0:4
2,7,0:48
3,7,0:4
4,7,0:4
5,7,0:4
6,7,0:48
7,7,0:4
-7,-7,1:4
-6,-7,1:13
-5,-7,1:13
-4,-7,1:4
-1,-7,1:13
0,-7,1:13
1,-7,1:13
2,-7,1:13
3,-7,1:4
4,-7,1:13
5,-7,1:4
6,-7,1:13
7,-7,1:48
-7,-6,1:13
-6,-6,1:98.2
-5,-6,1:98.3
-4,-6,1:102
-3,-6,1:98.1
-2,-6,1:102
-1,-6,1:98.0
0,-6,1:102
1,-6,1:98.0
2,-6,1:102
3,-6,1:4
4,-6,1:4
5,-6,1:13
6,-6,1:98.2
-7,-5,1:4
-6,-5,1:98.0
6,-5,1:98.1
-7,-4,1:4
-6,-4,1:102
6,-4,1:102
-7,-3,1:13
-6,-3,1:98.0
6,-3,1:98.0
7,-3,1:97.2
-6,-2,1:102
6,-2,1:69.4
7,-2,1:71.8
-6,-1,1:98.3
6,-1,1:98.0
7,-1,1:98.0
-6,0,1:102
6,0,1:102
-6,1,1:98.2
6,1,1:98.0
-6,2,1:102
6,2,1:102
-6,3,1:98.1
-2,3,1:98.0
-1,3,1:98.0
0,3,1:98.0
1,3,1:98.0
6,3,1:98.1
-7,4,1:4
-6,4,1:102
-4,4,1:4
-3,4,1:4
-2,4,1:13
1,4,1:67.1
3,4,1:4
4,4,1:13
5,4,1:13
6,4,1:102
-7,5,1:4
-6,5,1:98.1
-5,5,1:4
-4,5,1:13
-3,5,1:13
-2,5,1:13
-1,5,1:13
0,5,1:13
1,5,1:67.1
2,5,1:13
3,5,1:13
4,5,1:13
5,5,1:4
6,5,1:98.1
-7,6,1:4
-6,6,1:98.3
-5,6,1:98.0
-4,6,1:102
-3,6,1:98.0
-2,6,1:102
-1,6,1:98.0
0,6,1:102
1,6,1:98.2
2,6,1:102
3,6,1:98.0
4,6,1:102
5,6,1:98.0
6,6,1:98.0
-7,7,1:48
-5,7,1:4
-4,7,1:4
-3,7,1:4
-2,7,1:4
-1,7,1:4
0,7,1:13
1,7,1:4
2,7,1:4
3,7,1:13
4,7,1:4
5,7,1:13
6,7,1:13
7,7,1:4
-7,-7,2:4
-6,-7,2:4
0,-7,2:4
1,-7,2:4
2,-7,2:4
3,-7,2:4
4,-7,2:13
5,-7,2:13
7,-7,2:4
-7,-6,2:13
-6,-6,2:98.0
-5,-6,2:98.3
-4,-6,2:102
-3,-6,2:98.1
-2,-6,2:102
-1,-6,2:98.3
0,-6,2:102
1,-6,2:98.2
2,-6,2:102
3,-6,2:98.1
4,-6,2:102
5,-6,2:98.2
6,-6,2:98.0
-7,-5,2:4
-6,-5,2:98.3
6,-5,2:98.2
-6,-4,2:102
6,-4,2:102
-6,-3,2:98.3
6,-3,2:98.0
7,-3,2:98.0
-6,-2,2:102
6,-2,2:98.0
7,-2,2:98.0
-6,-1,2:98.2
6,-1,2:98.0
7,-1,2:98.0
-6,0,2:102
6,0,2:102
-6,1,2:98.2
6,1,2:98.3
-6,2,2:102
6,2,2:102
-6,3,2:98.0
-2,3,2:98.0
-1,3,2:98.0
0,3,2:98.0
6,3,2:98.1
-6,4,2:102
-4,4,2:13
-3,4,2:4
-2,4,2:4
0,4,2:67.1
3,4,2:13
4,4,2:13
5,4,2:4
6,4,2:102
-6,5,2:98.0
-5,5,2:13
-4,5,2:4
-3,5,2:4
-2,5,2:13
-1,5,2:4
0,5,2:67.1
1,5,2:4
2,5,2:13
3,5,2:13
4,5,2:4
5,5,2:4
6,5,2:98.0
-6,6,2:98.1
-5,6,2:98.0
-4,6,2:102
-3,6,2:98.0
-2,6,2:102
-1,6,2:98.3
0,6,2:102
1,6,2:98.3
2,6,2:102
3,6,2:98.0
4,6,2:102
5,6,2:98.1
6,6,2:98.2
-7,7,2:4
-5,7,2:13
-4,7,2:13
-3,7,2:4
-2,7,2:13
-1,7,2:13
0,7,2:13
1,7,2:4
2,7,2:13
3,7,2:13
4,7,2:4
5,7,2:4
6,7,2:4
7,7,2:48
-7,-7,3:48
0,-7,3:4
1,-7,3:4
2,-7,3:4
7,-7,3:4
-7,-6,3:13
-6,-6,3:98.3
-5,-6,3:98.3
-4,-6,3:102
-3,-6,3:98.1
-2,-6,3:102
-1,-6,3:98.2
0,-6,3:102
1,-6,3:98.3
2,-6,3:102
3,-6,3:98.0
4,-6,3:102
5,-6,3:98.0
6,-6,3:98.1
-6,-5,3:98.0
6,-5,3:98.1
-6,-4,3:102
6,-4,3:102
-6,-3,3:98.1
6,-3,3:98.0
-6,-2,3:102
6,-2,3:102
-6,-1,3:98.2
6,-1,3:98.2
-6,0,3:102
6,0,3:102
-6,1,3:98.1
6,1,3:98.2
-6,2,3:102
6,2,3:102
-6,3,3:98.1
-2,3,3:98.0
-1,3,3:98.0
6,3,3:98.0
-6,4,3:102
-1,4,3:67.1
6,4,3:102
-6,5,3:98.1
-4,5,3:4
-3,5,3:13
-2,5,3:4
-1,5,3:67.1
3,5,3:4
4,5,3:13
5,5,3:4
6,5,3:98.1
-6,6,3:98.0
-5,6,3:98.1
-4,6,3:102
-3,6,3:98.3
-2,6,3:102
-1,6,3:98.2
0,6,3:102
1,6,3:98.3
2,6,3:102
3,6,3:98.2
4,6,3:102
5,6,3:98.0
6,6,3:98.3
-7,7,3:48
-4,7,3:4
-3,7,3:4
-2,7,3:4
-1,7,3:4
0,7,3:13
1,7,3:4
2,7,3:13
3,7,3:13
4,7,3:4
5,7,3:4
7,7,3:4
-7,-7,4:48
0,-7,4:4
1,-7,4:4
2,-7,4:13
7,-7,4:48
-6,-6,4:98.0
-5,-6,4:98.1
-4,-6,4:102
-3,-6,4:98.2
-2,-6,4:102
-1,-6,4:98.0
0,-6,4:102
1,-6,4:98.3
2,-6,4:102
3,-6,4:98.2
4,-6,4:102
5,-6,4:98.1
6,-6,4:98.3
-6,-5,4:98.0
6,-5,4:98.0
-6,-4,4:102
6,-4,4:102
-6,-3,4:98.1
6,-3,4:98.2
-6,-2,4:102
6,-2,4:102
-6,-1,4:98.2
6,-1,4:98.0
-6,0,4:102
6,0,4:102
-6,1,4:98.3
6,1,4:98.3
-6,2,4:102
6,2,4:102
-6,3,4:98.2
-2,3,4:98.0
6,3,4:98.3
-6,4,4:102
-2,4,4:67.1
6,4,4:102
-6,5,4:98.2
-2,5,4:67.1
6,5,4:98.2
-6,6,4:98.0
-5,6,4:98.0
-4,6,4:102
-3,6,4:98.1
-2,6,4:102
-1,6,4:98.2
0,6,4:102
1,6,4:98.0
2,6,4:102
3,6,4:98.3
4,6,4:102
5,6,4:98.2
6,6,4:98.0
-7,7,4:4
-3,7,4:13
-2,7,4:13
-1,7,4:4
7,7,4:48
-7,-7,5:4
7,-7,5:4
-6,-6,5:98.0
-5,-6,5:98.0
-4,-6,5:102
-3,-6,5:98.1
-2,-6,5:102
-1,-6,5:98.1
0,-6,5:102
1,-6,5:98.3
2,-6,5:102
3,-6,5:98.3
4,-6,5:102
5,-6,5:98.3
6,-6,5:98.2
-6,-5,5:98.1
-5,-5,5:1
-4,-5,5:4
-3,-5,5:1
-2,-5,5:4
-1,-5,5:1
0,-5,5:4
1,-5,5:4
2,-5,5:1
3,-5,5:1
4,-5,5:1
5,-5,5:4
6,-5,5:98.1
-6,-4,5:102
-5,-4,5:4
-4,-4,5:1
-3,-4,5:1
-2,-4,5:1
-1,-4,5:4
0,-4,5:4
1,-4,5:1
2,-4,5:4
3,-4,5:1
4,-4,5:4
5,-4,5:4
6,-4,5:102
-6,-3,5:98.2
-5,-3,5:4
-4,-3,5:4
-3,-3,5:1
-2,-3,5:4
-1,-3,5:1
0,-3,5:4
1,-3,5:1
2,-3,5:4
3,-3,5:1
4,-3,5:4
5,-3,5:1
6,-3,5:98.3
-6,-2,5:102
-5,-2,5:4
-4,-2,5:4
-3,-2,5:4
-2,-2,5:1
-1,-2,5:1
0,-2,5:4
1,-2,5:1
2,-2,5:1
3,-2,5:1
4,-2,5:1
5,-2,5:1
6,-2,5:102
-6,-1,5:98.1
-5,-1,5:4
-4,-1,5:4
-3,-1,5:1
-2,-1,5:4
-1,-1,5:1
0,-1,5:4
1,-1,5:1
2,-1,5:4
3,-1,5:1
4,-1,5:1
5,-1,5:1
6,-1,5:98.3
-6,0,5:102
-5,0,5:1
-4,0,5:4
-3,0,5:1
-2,0,5:4
-1,0,5:1
0,0,5:1
1,0,5:4
2,0,5:4
3,0,5:4
4,0,5:1
5,0,5:1
6,0,5:102
-6,1,5:98.1
-5,1,5:4
-4,1,5:4
-3,1,5:1
-2,1,5:4
-1,1,5:1
0,1,5:4
1,1,5:4
2,1,5:4
3,1,5:4
4,1,5:4
5,1,5:4
6,1,5:98.3
-6,2,5:102
-5,2,5:4
-4,2,5:1
-3,2,5:4
-2,2,5:1
-1,2,5:1
0,2,5:4
1,2,5:4
2,2,5:1
3,2,5:4
4,2,5:1
5,2,5:4
6,2,5:102
-6,3,5:98.3
-5,3,5:4
-4,3,5:4
-3,3,5:1
-2,3,5:1
-1,3,5:4
0,3,5:4
1,3,5:1
2,3,5:1
3,3,5:1
4,3,5:1
5,3,5:4
6,3,5:98.0
-6,4,5:102
-5,4,5:4
-4,4,5:1
-3,4,5:67.1
1,4,5:4
2,4,5:4
3,4,5:4
4,4,5:1
5,4,5:1
6,4,5:102
-6,5,5:98.1
-5,5,5:4
-4,5,5:1
-3,5,5:67.1
1,5,5:4
2,5,5:4
3,5,5:1
4,5,5:4
5,5,5:1
6,5,5:98.2
-6,6,5:98.2
-5,6,5:98.2
-4,6,5:102
-3,6,5:98.2
-1,6,5:98.3
0,6,5:102
1,6,5:98.0
2,6,5:102
3,6,5:98.3
4,6,5:102
5,6,5:98.1
6,6,5:98.3
-7,7,5:4
7,7,5:48
-7,-7,6:48
7,-7,6:4
-6,-6,6:98.0
-5,-6,6:98.0
-4,-6,6:102
-3,-6,6:98.3
-2,-6,6:102
-1,-6,6:98.0
0,-6,6:102
1,-6,6:98.1
2,-6,6:102
3,-6,6:98.2
4,-6,6:102
5,-6,6:98.0
6,-6,6:98.1
-6,-5,6:98.3
-5,-5,6:47
-4,-5,6:68.4
-3,-5,6:44.2
-2,-5,6:68.5
-1,-5,6:98.0
6,-5,6:98.1
-6,-4,6:102
-1,-4,6:98.0
5,-4,6:44.2
6,-4,6:44.2
7,-4,6:44.2
-6,-3,6:98.0
-4,-3,6:1
-3,-3,6:1
-2,-3,6:1
-1,-3,6:98.0
6,-3,6:98.1
-6,-2,6:102
-1,-2,6:98.0
6,-2,6:102
-6,-1,6:98.1
-1,-1,6:64.6
6,-1,6:98.3
-6,0,6:102
-5,0,6:54.2
-4,0,6:47
-3,0,6:118.0
-2,0,6:18
-1,0,6:98.0
6,0,6:102
-6,1,6:98.2
-5,1,6:98.0
-4,1,6:98.0
-3,1,6:98.0
-2,1,6:98.0
-1,1,6:98.0
6,1,6:98.3
-6,2,6:102
6,2,6:102
-6,3,6:98.1
6,3,6:98.2
-6,4,6:102
6,4,6:102
-6,5,6:98.3
6,5,6:98.0
-6,6,6:98.3
-5,6,6:98.1
-4,6,6:102
-3,6,6:98.2
-1,6,6:98.0
0,6,6:102
1,6,6:98.1
2,6,6:102
3,6,6:98.1
4,6,6:102
5,6,6:98.1
6,6,6:98.0
-7,7,6:4
7,7,6:48
-7,-7,7:4
7,-7,7:48
-6,-6,7:98.1
-5,-6,7:98.1
-4,-6,7:102
-3,-6,7:98.0
-2,-6,7:102
-1,-6,7:98.0
0,-6,7:102
1,-6,7:98.2
2,-6,7:102
3,-6,7:98.3
4,-6,7:102
5,-6,7:98.0
6,-6,7:98.1
-6,-5,7:98.1
-5,-5,7:47
-1,-5,7:98.0
6,-5,7:98.0
-6,-4,7:102
-1,-4,7:102
-6,-3,7:98.1
-1,-3,7:98.0
6,-3,7:98.0
-6,-2,7:102
-1,-2,7:98.0
6,-2,7:102
-6,-1,7:98.0
-1,-1,7:64.8
6,-1,7:98.3
-6,0,7:102
-4,0,7:47
-2,0,7:18
-1,0,7:98.0
6,0,7:102
-6,1,7:98.0
-5,1,7:98.0
-4,1,7:98.0
-3,1,7:102
-2,1,7:98.0
-1,1,7:98.0
0,1,7:76.1
6,1,7:98.0
-6,2,7:102
6,2,7:102
-6,3,7:98.2
6,3,7:98.0
-6,4,7:102
6,4,7:102
-6,5,7:98.2
6,5,7:98.2
-6,6,7:98.3
-5,6,7:98.0
-4,6,7:102
-3,6,7:98.2
-2,6,7:102
-1,6,7:98.2
0,6,7:102
1,6,7:98.0
2,6,7:102
3,6,7:98.2
4,6,7:102
5,6,7:98.0
6,6,7:98.2
-7,7,7:4
7,7,7:4
-7,-7,8:4
7,-7,8:4
-6,-6,8:98.2
-5,-6,8:98.1
-4,-6,8:102
-3,-6,8:98.2
-2,-6,8:102
-1,-6,8:98.3
0,-6,8:102
1,-6,8:98.2
2,-6,8:102
3,-6,8:98.1
4,-6,8:102
5,-6,8:98.3
6,-6,8:98.0
-6,-5,8:98.3
-1,-5,8:98.0
6,-5,8:98.2
-6,-4,8:102
-1,-4,8:98.0
-6,-3,8:98.2
-1,-3,8:98.0
6,-3,8:98.0
-6,-2,8:102
-1,-2,8:98.0
6,-2,8:102
-6,-1,8:98.3
-1,-1,8:98.0
6,-1,8:98.2
-6,0,8:102
-1,0,8:98.0
6,0,8:102
-6,1,8:98.1
-5,1,8:98.0
-4,1,8:98.0
-3,1,8:98.0
-2,1,8:98.0
-1,1,8:98.0
6,1,8:98.1
-6,2,8:102
6,2,8:102
-6,3,8:98.2
6,3,8:98.2
-6,4,8:102
6,4,8:102
-6,5,8:98.0
6,5,8:98.1
-6,6,8:98.1
-5,6,8:98.0
-4,6,8:102
-3,6,8:98.3
-2,6,8:102
-1,6,8:98.0
0,6,8:102
1,6,8:98.2
2,6,8:102
3,6,8:98.0
4,6,8:102
5,6,8:98.1
6,6,8:98.2
-7,7,8:4
7,7,8:4
-7,-7,9:4
7,-7,9:4
-6,-6,9:98.3
-5,-6,9:98.2
-4,-6,9:102
-3,-6,9:98.2
-2,-6,9:102
-1,-6,9:98.2
0,-6,9:102
1,-6,9:98.1
2,-6,9:102
3,-6,9:98.3
4,-6,9:102
5,-6,9:98.0
6,-6,9:98.1
-6,-5,9:98.1
-5,-5,9:30
-1,-5,9:98.0
6,-5,9:98.2
-6,-4,9:102
-1,-4,9:98.0
6,-4,9:102
-6,-3,9:98.3
-1,-3,9:98.0
6,-3,9:98.3
-6,-2,9:102
-1,-2,9:98.0
6,-2,9:102
-6,-1,9:98.1
-1,-1,9:98.0
6,-1,9:98.2
-6,0,9:102
-1,0,9:98.0
6,0,9:102
-6,1,9:98.2
-5,1,9:98.0
-4,1,9:98.0
-3,1,9:98.0
-2,1,9:98.0
-1,1,9:98.0
6,1,9:98.2
-6,2,9:102
6,2,9:102
-6,3,9:98.1
6,3,9:98.2
-6,4,9:102
6,4,9:102
-6,5,9:98.3
6,5,9:98.1
-6,6,9:98.2
-5,6,9:98.1
-4,6,9:102
-3,6,9:98.0
-2,6,9:102
-1,6,9:98.2
0,6,9:102
1,6,9:98.0
2,6,9:102
6,6,9:98.2
-7,7,9:48
7,7,9:48
-7,-7,10:48
7,-7,10:48
-6,-6,10:98.3
-5,-6,10:98.2
-4,-6,10:102
-3,-6,10:98.1
-2,-6,10:102
-1,-6,10:98.0
0,-6,10:102
1,-6,10:98.0
2,-6,10:102
3,-6,10:98.2
4,-6,10:102
5,-6,10:98.0
6,-6,10:98.0
-6,-5,10:98.2
-5,-5,10:1
-4,-5,10:1
-3,-5,10:4
-2,-5,10:1
-1,-5,10:4
0,-5,10:4
1,-5,10:4
2,-5,10:4
3,-5,10:1
4,-5,10:4
5,-5,10:4
6,-5,10:98.3
-6,-4,10:102
-5,-4,10:1
-4,-4,10:1
-3,-4,10:1
-2,-4,10:1
-1,-4,10:4
0,-4,10:1
1,-4,10:1
2,-4,10:1
3,-4,10:1
4,-4,10:1
5,-4,10:4
6,-4,10:102
-6,-3,10:98.0
-5,-3,10:4
-4,-3,10:4
-3,-3,10:1
-2,-3,10:1
-1,-3,10:4
0,-3,10:1
1,-3,10:1
2,-3,10:4
3,-3,10:4
4,-3,10:1
5,-3,10:4
6,-3,10:98.3
-6,-2,10:102
-5,-2,10:1
-4,-2,10:4
-3,-2,10:4
-2,-2,10:4
-1,-2,10:4
0,-2,10:1
1,-2,10:1
2,-2,10:1
3,-2,10:1
4,-2,10:4
5,-2,10:4
6,-2,10:102
-6,-1,10:98.3
-5,-1,10:1
-4,-1,10:4
-3,-1,10:1
-2,-1,10:4
-1,-1,10:1
0,-1,10:1
1,-1,10:4
2,-1,10:1
3,-1,10:4
4,-1,10:4
5,-1,10:1
6,-1,10:98.1
-6,0,10:102
-5,0,10:1
-4,0,10:4
-3,0,10:1
-2,0,10:1
-1,0,10:4
0,0,10:1
1,0,10:1
2,0,10:4
3,0,10:4
4,0,10:4
5,0,10:4
6,0,10:102
-6,1,10:98.2
-5,1,10:4
-4,1,10:4
-3,1,10:4
-2,1,10:1
-1,1,10:4
0,1,10:1
1,1,10:4
2,1,10:1
3,1,10:4
4,1,10:4
5,1,10:1
6,1,10:98.1
-6,2,10:102
-5,2,10:1
-4,2,10:1
-3,2,10:1
-2,2,10:4
-1,2,10:1
0,2,10:1
1,2,10:1
2,2,10:4
3,2,10:1
4,2,10:4
5,2,10:4
6,2,10:102
-6,3,10:98.1
-5,3,10:1
-4,3,10:1
-3,3,10:1
-2,3,10:4
-1,3,10:1
0,3,10:4
1,3,10:4
2,3,10:1
3,3,10:4
4,3,10:1
5,3,10:1
6,3,10:98.0
-6,4,10:102
-5,4,10:4
-4,4,10:1
-3,4,10:1
-2,4,10:4
-1,4,10:1
0,4,10:1
1,4,10:1
2,4,10:1
6,4,10:102
-6,5,10:98.1
-5,5,10:1
-4,5,10:1
-3,5,10:1
-2,5,10:1
-1,5,10:4
0,5,10:4
1,5,10:4
-6,6,10:98.1
-5,6,10:98.2
-4,6,10:102
-3,6,10:98.1
-2,6,10:102
-1,6,10:98.2
0,6,10:102
1,6,10:98.3
-7,7,10:4
7,7,10:48
-7,-7,11:48
7,-7,11:48
-6,-6,11:98.1
-5,-6,11:98.3
-4,-6,11:102
-3,-6,11:98.2
-2,-6,11:102
-1,-6,11:98.2
0,-6,11:102
1,-6,11:98.0
2,-6,11:102
3,-6,11:98.2
4,-6,11:102
5,-6,11:98.2
6,-6,11:98.2
-6,-5,11:98.0
6,-5,11:98.3
-6,-4,11:102
6,-4,11:102
-6,-3,11:98.0
6,-3,11:98.1
-6,-2,11:102
6,-2,11:102
-6,-1,11:98.3
6,-1,11:98.0
-6,0,11:102
6,0,11:102
-6,1,11:98.3
6,1,11:98.1
-6,2,11:102
6,2,11:102
-6,3,11:98.0
6,3,11:98.1
-6,4,11:102
6,4,11:102
-6,5,11:98.2
-6,6,11:98.3
-5,6,11:98.0
-4,6,11:102
-3,6,11:98.3
-2,6,11:102
-1,6,11:98.3
0,6,11:102
1,6,11:98.2
-7,7,11:48
7,7,11:48
-7,-7,12:4
7,-7,12:48
-6,-6,12:98.0
-5,-6,12:98.3
-4,-6,12:102
-3,-6,12:98.1
-2,-6,12:102
-1,-6,12:98.0
0,-6,12:102
1,-6,12:98.2
2,-6,12:102
3,-6,12:98.2
4,-6,12:102
5,-6,12:98.2
6,-6,12:98.0
-6,-5,12:98.3
6,-5,12:98.0
-6,-4,12:102
6,-4,12:102
-6,-3,12:98.1
6,-3,12:98.2
-6,-2,12:102
6,-2,12:102
-6,-1,12:98.0
6,-1,12:98.0
-6,0,12:102
6,0,12:102
-6,1,12:98.3
6,1,12:98.2
-6,2,12:102
6,2,12:102
-6,3,12:98.1
6,3,12:98.0
-6,4,12:102
6,4,12:102
-6,5,12:98.3
-6,6,12:98.3
-5,6,12:98.0
-4,6,12:102
-7,7,12:48
7,7,12:48
-7,-7,13:48
7,-7,13:4
-6,-6,13:98.0
-5,-6,13:98.0
-4,-6,13:102
-3,-6,13:98.1
-2,-6,13:102
-1,-6,13:98.2
0,-6,13:102
1,-6,13:98.3
2,-6,13:102
3,-6,13:98.3
4,-6,13:102
5,-6,13:98.2
6,-6,13:98.2
-6,-5,13:98.2
6,-5,13:98.1
-6,-4,13:102
6,-4,13:102
-6,-3,13:98.2
6,-3,13:98.2
-6,-2,13:102
6,-2,13:102
-6,-1,13:98.1
6,-1,13:98.2
-6,0,13:102
6,0,13:102
-6,1,13:98.0
6,1,13:98.1
-6,2,13:102
6,2,13:102
-6,3,13:98.2
6,3,13:98.3
-6,4,13:102
6,4,13:102
6,5,13:98.2
6,6,13:98.2
-7,7,13:4
7,7,13:48
-7,-7,14:4
7,-7,14:48
-6,-6,14:98.2
-5,-6,14:98.3
-4,-6,14:102
-3,-6,14:98.2
-2,-6,14:102
-1,-6,14:98.1
0,-6,14:102
1,-6,14:98.1
2,-6,14:102
3,-6,14:98.2
4,-6,14:102
5,-6,14:98.3
6,-6,14:98.2
-6,-5,14:98.2
6,-5,14:98.0
-6,-4,14:102
6,-4,14:102
-6,-3,14:98.0
6,-3,14:98.0
-6,-2,14:102
6,-2,14:102
-6,-1,14:98.1
6,-1,14:98.0
-6,0,14:102
6,0,14:102
-6,1,14:98.2
6,1,14:98.1
6,2,14:102
6,3,14:98.2
6,4,14:102
6,5,14:98.2
4,6,14:102
5,6,14:98.0
6,6,14:98.3
7,7,14:48
-7,-7,15:48
7,-7,15:48
-6,-6,15:98.2
-5,-6,15:98.3
-4,-6,15:102
-3,-6,15:98.0
-2,-6,15:102
-1,-6,15:98.1
0,-6,15:102
1,-6,15:98.0
2,-6,15:102
3,-6,15:98.1
4,-6,15:102
5,-6,15:98.3
6,-6,15:98.2
-6,-5,15:98.1
-5,-5,15:1
-4,-5,15:1
-3,-5,15:1
-2,-5,15:1
-1,-5,15:4
0,-5,15:1
1,-5,15:4
2,-5,15:4
3,-5,15:4
4,-5,15:1
5,-5,15:4
6,-5,15:98.1
-6,-4,15:102
-5,-4,15:4
-4,-4,15:1
-3,-4,15:4
-2,-4,15:1
-1,-4,15:1
0,-4,15:1
1,-4,15:4
2,-4,15:1
3,-4,15:1
4,-4,15:1
5,-4,15:1
6,-4,15:102
-6,-3,15:98.0
-5,-3,15:1
-4,-3,15:4
-3,-3,15:4
-2,-3,15:1
-1,-3,15:4
0,-3,15:4
1,-3,15:1
2,-3,15:1
3,-3,15:4
4,-3,15:4
5,-3,15:1
6,-3,15:98.2
-6,-2,15:102
-5,-2,15:4
-4,-2,15:4
-3,-2,15:4
-2,-2,15:4
-1,-2,15:4
0,-2,15:4
1,-2,15:1
2,-2,15:1
3,-2,15:4
4,-2,15:1
5,-2,15:1
6,-2,15:102
-6,-1,15:98.1
-5,-1,15:4
-4,-1,15:1
-3,-1,15:4
-2,-1,15:4
-1,-1,15:1
0,-1,15:4
1,-1,15:1
2,-1,15:1
3,-1,15:1
4,-1,15:4
5,-1,15:1
6,-1,15:98.1
-6,0,15:102
-5,0,15:4
-4,0,15:1
-3,0,15:1
-2,0,15:1
-1,0,15:4
0,0,15:1
1,0,15:1
2,0,15:1
3,0,15:4
4,0,15:1
5,0,15:1
6,0,15:102
-6,1,15:98.0
-2,1,15:1
-1,1,15:1
0,1,15:1
1,1,15:1
2,1,15:1
3,1,15:4
4,1,15:1
5,1,15:1
6,1,15:98.2
-1,2,15:1
0,2,15:4
1,2,15:4
2,2,15:4
3,2,15:4
4,2,15:1
5,2,15:1
6,2,15:102
-1,3,15:1
0,3,15:4
1,3,15:1
2,3,15:1
3,3,15:1
4,3,15:1
5,3,15:4
6,3,15:98.3
3,4,15:4
4,4,15:4
5,4,15:4
6,4,15:102
4,5,15:1
5,5,15:1
6,5,15:98.2
4,6,15:102
5,6,15:98.2
6,6,15:98.0
7,7,15:48
-7,-7,16:48
7,-7,16:48
-6,-6,16:98.0
-5,-6,16:98.3
-4,-6,16:102
-3,-6,16:98.3
-2,-6,16:102
-1,-6,16:98.2
0,-6,16:102
1,-6,16:98.3
2,-6,16:102
3,-6,16:98.0
4,-6,16:102
5,-6,16:98.0
6,-6,16:98.1
-6,-5,16:98.3
6,-5,16:98.2
-6,-4,16:102
6,-4,16:102
-6,-3,16:98.2
6,-3,16:98.0
-6,-2,16:102
6,-2,16:102
-6,-1,16:98.0
6,-1,16:98.1
-6,0,16:102
6,0,16:102
-6,1,16:98.1
6,1,16:98.1
6,2,16:102
6,3,16:98.0
6,4,16:102
6,5,16:98.0
3,6,16:98.3
4,6,16:102
5,6,16:98.0
6,6,16:98.3
7,7,16:4
-7,-7,17:4
7,-7,17:4
-6,-6,17:98.2
-5,-6,17:98.1
-4,-6,17:102
-3,-6,17:98.0
-2,-6,17:102
-1,-6,17:98.3
0,-6,17:102
1,-6,17:98.0
2,-6,17:102
3,-6,17:98.3
4,-6,17:102
5,-6,17:98.2
6,-6,17:98.2
-6,-5,17:98.0
6,-5,17:98.0
-6,-4,17:102
6,-4,17:102
-6,-3,17:98.2
6,-3,17:98.2
-6,-2,17:102
6,-2,17:102
-6,-1,17:98.0
6,-1,17:98.2
-6,0,17:102
6,0,17:102
-6,1,17:98.0
6,1,17:98.1
-6,2,17:102
6,2,17:102
-6,3,17:98.2
6,3,17:98.3
-6,4,17:102
6,4,17:102
6,5,17:98.0
-3,6,17:98.0
-2,6,17:102
-1,6,17:98.3
0,6,17:102
1,6,17:98.2
2,6,17:102
3,6,17:98.3
4,6,17:102
5,6,17:98.2
6,6,17:98.2
-7,7,17:48
7,7,17:4
-7,-7,18:48
7,-7,18:48
-6,-6,18:98.1
-5,-6,18:98.3
-4,-6,18:102
-3,-6,18:98.3
-2,-6,18:102
-1,-6,18:98.3
0,-6,18:102
1,-6,18:98.1
2,-6,18:102
3,-6,18:98.2
4,-6,18:102
5,-6,18:98.2
6,-6,18:98.2
-6,-5,18:98.1
6,-5,18:98.3
-6,-4,18:102
6,-4,18:102
-6,-3,18:98.0
6,-3,18:98.3
-6,-2,18:102
6,-2,18:102
-6,-1,18:98.2
6,-1,18:98.0
-6,0,18:102
6,0,18:102
-6,1,18:98.1
6,1,18:98.1
-6,2,18:102
6,2,18:102
-6,3,18:98.2
6,3,18:98.2
-6,4,18:102
6,4,18:102
-6,5,18:98.3
6,5,18:98.1
-6,6,18:98.3
-5,6,18:98.1
-4,6,18:102
-3,6,18:98.0
-2,6,18:102
-1,6,18:98.1
0,6,18:102
1,6,18:98.2
2,6,18:102
3,6,18:98.1
4,6,18:102
5,6,18:98.2
6,6,18:98.2
-7,7,18:4
7,7,18:4
-7,-7,19:48
7,-7,19:48
-6,-6,19:98.0
-5,-6,19:98.1
-4,-6,19:102
-3,-6,19:98.0
-2,-6,19:102
-1,-6,19:98.0
0,-6,19:102
1,-6,19:98.3
2,-6,19:102
3,-6,19:98.3
4,-6,19:102
5,-6,19:98.2
6,-6,19:98.2
-6,-5,19:98.3
6,-5,19:98.0
-6,-4,19:102
6,-4,19:102
-6,-3,19:98.1
6,-3,19:98.2
-6,-2,19:102
6,-2,19:102
-6,-1,19:98.3
6,-1,19:98.2
-6,0,19:102
6,0,19:102
-6,1,19:98.2
6,1,19:98.1
-6,2,19:102
6,2,19:102
-6,3,19:98.2
6,3,19:98.3
-6,4,19:102
6,4,19:102
-6,5,19:98.1
6,5,19:98.1
-6,6,19:98.3
-5,6,19:98.2
-4,6,19:102
-3,6,19:98.0
-2,6,19:102
-1,6,19:98.1
0,6,19:102
1,6,19:98.0
2,6,19:102
3,6,19:98.0
4,6,19:102
5,6,19:98.0
6,6,19:98.1
-7,7,19:48
7,7,19:4
-7,-7,20:48
7,-7,20:4
-6,-6,20:98.3
-5,-6,20:98.0
-4,-6,20:102
-3,-6,20:98.3
-2,-6,20:102
-1,-6,20:98.3
0,-6,20:102
1,-6,20:98.2
2,-6,20:102
3,-6,20:98.0
4,-6,20:102
5,-6,20:98.0
6,-6,20:98.0
-6,-5,20:98.0
-5,-5,20:4
-4,-5,20:4
-3,-5,20:4
-2,-5,20:1
-1,-5,20:4
0,-5,20:4
1,-5,20:4
2,-5,20:4
3,-5,20:1
4,-5,20:1
5,-5,20:4
6,-5,20:98.2
-6,-4,20:102
-5,-4,20:1
-4,-4,20:1
-3,-4,20:4
-2,-4,20:1
-1,-4,20:4
0,-4,20:1
1,-4,20:1
2,-4,20:1
3,-4,20:1
4,-4,20:1
5,-4,20:4
6,-4,20:102
-6,-3,20:98.2
-5,-3,20:4
-4,-3,20:4
-3,-3,20:1
-2,-3,20:4
-1,-3,20:1
0,-3,20:1
1,-3,20:1
2,-3,20:4
3,-3,20:4
4,-3,20:4
5,-3,20:4
6,-3,20:98.2
-6,-2,20:102
-5,-2,20:4
-4,-2,20:4
-3,-2,20:4
-2,-2,20:1
-1,-2,20:1
0,-2,20:1
1,-2,20:4
2,-2,20:1
3,-2,20:4
4,-2,20:1
5,-2,20:1
6,-2,20:102
-6,-1,20:98.3
-5,-1,20:4
-4,-1,20:1
-3,-1,20:4
-2,-1,20:4
-1,-1,20:1
0,-1,20:4
1,-1,20:1
2,-1,20:1
3,-1,20:4
4,-1,20:1
5,-1,20:1
6,-1,20:98.1
-6,0,20:102
-5,0,20:1
-4,0,20:1
-3,0,20:4
-2,0,20:1
-1,0,20:4
0,0,20:1
1,0,20:4
2,0,20:4
3,0,20:1
4,0,20:4
5,0,20:4
6,0,20:102
-6,1,20:98.1
-5,1,20:1
-4,1,20:1
-3,1,20:1
-2,1,20:1
-1,1,20:1
0,1,20:4
1,1,20:1
2,1,20:4
3,1,20:4
4,1,20:4
5,1,20:1
6,1,20:98.1
-6,2,20:102
-5,2,20:1
-4,2,20:4
-3,2,20:1
-2,2,20:1
-1,2,20:4
0,2,20:1
1,2,20:4
2,2,20:1
3,2,20:1
4,2,20:1
5,2,20:1
6,2,20:102
-6,3,20:98.0
-5,3,20:1
-4,3,20:4
-3,3,20:4
-2,3,20:1
-1,3,20:1
0,3,20:4
1,3,20:4
2,3,20:4
3,3,20:1
4,3,20:4
5,3,20:4
6,3,20:98.3
-6,4,20:102
-5,4,20:1
-4,4,20:4
-3,4,20:4
-2,4,20:1
-1,4,20:1
0,4,20:1
1,4,20:4
2,4,20:4
3,4,20:1
4,4,20:4
5,4,20:1
6,4,20:102
-6,5,20:98.2
-5,5,20:4
-4,5,20:1
-3,5,20:4
-2,5,20:4
-1,5,20:1
0,5,20:1
1,5,20:4
2,5,20:1
3,5,20:4
4,5,20:4
5,5,20:4
6,5,20:98.2
-6,6,20:98.3
-5,6,20:98.0
-4,6,20:102
-3,6,20:98.0
-2,6,20:102
-1,6,20:98.1
0,6,20:102
1,6,20:98.1
2,6,20:102
3,6,20:98.1
4,6,20:102
5,6,20:98.0
6,6,20:98.3
-7,7,20:4
7,7,20:4
-7,-7,21:48
7,-7,21:48
-6,-6,21:98.0
-5,-6,21:98.3
-4,-6,21:102
-3,-6,21:98.3
-2,-6,21:102
-1,-6,21:98.3
0,-6,21:102
1,-6,21:98.2
2,-6,21:102
3,-6,21:98.1
4,-6,21:102
5,-6,21:98.0
6,-6,21:98.0
-6,-5,21:98.3
6,-5,21:98.0
-6,-4,21:102
6,-4,21:102
-6,-3,21:98.2
6,-3,21:98.0
-6,-2,21:102
6,-2,21:102
-6,-1,21:98.0
6,-1,21:98.3
-6,0,21:102
6,0,21:102
-6,1,21:98.1
6,1,21:98.3
-6,2,21:102
6,2,21:102
-6,3,21:98.2
6,3,21:98.0
-6,4,21:102
6,4,21:102
-6,5,21:98.0
6,5,21:98.2
-6,6,21:98.1
-5,6,21:98.2
-4,6,21:102
-3,6,21:98.2
-2,6,21:102
-1,6,21:98.3
0,6,21:102
1,6,21:98.3
2,6,21:102
3,6,21:98.1
4,6,21:102
5,6,21:98.0
6,6,21:98.2
-7,7,21:4
7,7,21:4
-7,-7,22:4
7,-7,22:48
-6,-6,22:98.2
-5,-6,22:98.3
-4,-6,22:102
-3,-6,22:98.2
-2,-6,22:102
-1,-6,22:98.1
0,-6,22:102
1,-6,22:98.3
2,-6,22:102
3,-6,22:98.2
4,-6,22:102
5,-6,22:98.2
6,-6,22:98.2
-6,-5,22:98.0
6,-5,22:98.2
-6,-4,22:102
6,-4,22:102
-6,-3,22:98.3
6,-3,22:98.3
-6,-2,22:102
6,-2,22:102
-6,-1,22:98.1
6,-1,22:98.1
-6,0,22:102
6,0,22:102
-6,1,22:98.0
6,1,22:98.1
-6,2,22:102
6,2,22:102
-6,3,22:98.3
6,3,22:98.1
-6,4,22:102
6,4,22:102
-6,5,22:98.3
6,5,22:98.1
-6,6,22:98.1
-5,6,22:98.0
-4,6,22:102
-3,6,22:98.3
-2,6,22:102
-1,6,22:98.3
0,6,22:102
1,6,22:98.0
2,6,22:102
3,6,22:98.0
4,6,22:102
5,6,22:98.2
6,6,22:98.2
-7,7,22:4
7,7,22:48
-7,-7,23:4
7,-7,23:4
-6,-6,23:98.2
-5,-6,23:98.0
-4,-6,23:102
-3,-6,23:98.0
-2,-6,23:102
-1,-6,23:98.1
0,-6,23:102
1,-6,23:98.0
2,-6,23:102
3,-6,23:98.1
4,-6,23:102
5,-6,23:98.2
6,-6,23:98.0
-6,-5,23:98.0
6,-5,23:98.3
-6,-4,23:102
6,-4,23:102
-6,-3,23:98.0
6,-3,23:98.2
-6,-2,23:102
6,-2,23:102
-6,-1,23:98.3
6,-1,23:98.3
-6,0,23:102
6,0,23:102
-6,1,23:98.2
6,1,23:98.0
-6,2,23:102
6,2,23:102
-6,3,23:98.1
6,3,23:98.1
-6,4,23:102
6,4,23:102
-6,5,23:98.0
6,5,23:98.2
-6,6,23:98.1
-5,6,23:98.3
-4,6,23:102
-3,6,23:98.0
-2,6,23:102
-1,6,23:98.0
0,6,23:102
1,6,23:98.0
2,6,23:102
3,6,23:98.2
4,6,23:102
5,6,23:98.3
6,6,23:98.2
-7,7,23:48
7,7,23:4
-7,-7,24:48
7,-7,24:48
-6,-6,24:98.1
-5,-6,24:98.0
-4,-6,24:102
-3,-6,24:98.2
-2,-6,24:102
-1,-6,24:98.1
0,-6,24:102
1,-6,24:98.0
2,-6,24:102
3,-6,24:98.1
4,-6,24:102
5,-6,24:98.3
6,-6,24:98.0
-6,-5,24:98.2
6,-5,24:98.3
-6,-4,24:102
6,-4,24:102
-6,-3,24:98.3
6,-3,24:98.1
-6,-2,24:102
6,-2,24:102
-6,-1,24:98.2
6,-1,24:98.0
-6,0,24:102
6,0,24:102
-6,1,24:98.3
6,1,24:98.3
-6,2,24:102
6,2,24:102
-6,3,24:98.3
6,3,24:98.2
-6,4,24:102
6,4,24:102
-6,5,24:98.2
6,5,24:98.3
-6,6,24:98.0
-5,6,24:98.1
-4,6,24:102
-3,6,24:98.1
-2,6,24:102
-1,6,24:98.3
0,6,24:102
1,6,24:98.1
2,6,24:102
3,6,24:98.3
4,6,24:102
5,6,24:98.2
6,6,24:98.3
-7,7,24:4
7,7,24:48
-7,-7,25:4
7,-7,25:4
-6,-6,25:98.3
-5,-6,25:98.0
-4,-6,25:102
-3,-6,25:98.1
-2,-6,25:102
-1,-6,25:98.3
0,-6,25:102
1,-6,25:98.3
2,-6,25:102
3,-6,25:98.1
4,-6,25:102
5,-6,25:98.3
6,-6,25:98.3
-6,-5,25:98.2
-5,-5,25:1
-4,-5,25:4
-3,-5,25:4
-2,-5,25:4
-1,-5,25:1
0,-5,25:4
1,-5,25:4
2,-5,25:1
3,-5,25:1
4,-5,25:1
5,-5,25:1
6,-5,25:98.3
-6,-4,25:102
-5,-4,25:1
-4,-4,25:4
-3,-4,25:1
-2,-4,25:1
-1,-4,25:4
0,-4,25:1
1,-4,25:1
2,-4,25:4
3,-4,25:4
4,-4,25:1
5,-4,25:1
6,-4,25:102
-6,-3,25:98.3
-5,-3,25:1
-4,-3,25:1
-3,-3,25:4
-2,-3,25:1
-1,-3,25:1
0,-3,25:1
1,-3,25:1
2,-3,25:1
3,-3,25:4
4,-3,25:1
5,-3,25:1
6,-3,25:98.2
-6,-2,25:102
-5,-2,25:1
-4,-2,25:1
-3,-2,25:1
-2,-2,25:1
-1,-2,25:1
0,-2,25:1
1,-2,25:1
2,-2,25:4
3,-2,25:1
4,-2,25:1
5,-2,25:1
6,-2,25:102
-6,-1,25:98.0
-5,-1,25:1
-4,-1,25:1
-3,-1,25:1
-2,-1,25:4
-1,-1,25:4
0,-1,25:1
1,-1,25:1
2,-1,25:4
3,-1,25:1
4,-1,25:1
5,-1,25:4
6,-1,25:98.2
-6,0,25:102
-5,0,25:4
-4,0,25:4
-3,0,25:4
-2,0,25:4
-1,0,25:4
0,0,25:1
1,0,25:1
2,0,25:4
3,0,25:4
4,0,25:4
5,0,25:4
6,0,25:102
-6,1,25:98.2
-5,1,25:1
-4,1,25:4
-3,1,25:1
-2,1,25:4
-1,1,25:1
0,1,25:1
1,1,25:4
2,1,25:1
3,1,25:4
4,1,25:1
5,1,25:4
6,1,25:98.0
-6,2,25:102
-5,2,25:1
-4,2,25:1
-3,2,25:1
-2,2,25:4
-1,2,25:1
0,2,25:1
1,2,25:4
2,2,25:4
3,2,25:1
4,2,25:1
5,2,25:4
6,2,25:102
-6,3,25:98.1
-5,3,25:1
-4,3,25:1
-3,3,25:1
-2,3,25:1
-1,3,25:4
0,3,25:4
1,3,25:4
2,3,25:1
3,3,25:4
4,3,25:4
5,3,25:4
6,3,25:98.3
-6,4,25:102
-5,4,25:1
-4,4,25:1
-3,4,25:1
-2,4,25:4
-1,4,25:4
0,4,25:4
1,4,25:4
2,4,25:1
3,4,25:4
4,4,25:1
5,4,25:4
6,4,25:102
-6,5,25:98.0
-5,5,25:4
-4,5,25:4
-3,5,25:4
-2,5,25:1
-1,5,25:1
0,5,25:4
1,5,25:1
2,5,25:1
3,5,25:1
4,5,25:1
5,5,25:4
6,5,25:98.0
-6,6,25:98.0
-5,6,25:98.1
-4,6,25:102
-3,6,25:98.2
-2,6,25:102
-1,6,25:98.2
0,6,25:102
1,6,25:98.1
2,6,25:102
3,6,25:98.0
4,6,25:102
5,6,25:98.2
6,6,25:98.3
-7,7,25:4
7,7,25:48
-7,-7,26:48
7,-7,26:4
-6,-6,26:98.0
-5,-6,26:98.0
-4,-6,26:102
-3,-6,26:98.3
-2,-6,26:102
-1,-6,26:98.1
0,-6,26:102
1,-6,26:98.1
2,-6,26:102
3,-6,26:98.2
4,-6,26:102
5,-6,26:98.1
6,-6,26:98.1
-6,-5,26:98.3
6,-5,26:98.3
-6,-4,26:102
6,-4,26:102
-6,-3,26:98.2
6,-3,26:98.0
-6,-2,26:102
6,-2,26:102
-6,-1,26:98.2
6,-1,26:98.0
-6,0,26:102
6,0,26:102
-6,1,26:98.0
6,1,26:98.0
-6,2,26:102
6,2,26:102
-6,3,26:98.2
6,3,26:98.0
-6,4,26:102
6,4,26:102
-6,5,26:98.3
6,5,26:98.2
-6,6,26:98.0
-5,6,26:98.2
-4,6,26:102
-3,6,26:98.2
-2,6,26:102
-1,6,26:98.0
0,6,26:102
1,6,26:98.0
2,6,26:102
3,6,26:98.3
4,6,26:102
5,6,26:98.1
6,6,26:98.3
-7,7,26:4
7,7,26:4
-7,-7,27:48
7,-7,27:48
-6,-6,27:98.1
-5,-6,27:98.0
-4,-6,27:102
-3,-6,27:98.0
-2,-6,27:102
-1,-6,27:98.1
0,-6,27:102
1,-6,27:98.2
2,-6,27:102
3,-6,27:98.2
4,-6,27:102
5,-6,27:98.1
6,-6,27:98.3
-6,-5,27:98.1
6,-5,27:98.0
-6,-4,27:102
6,-4,27:102
-6,-3,27:98.1
6,-3,27:98.2
-6,-2,27:102
6,-2,27:102
-6,-1,27:98.1
6,-1,27:98.1
-6,0,27:102
6,0,27:102
-6,1,27:98.0
6,1,27:98.1
-6,2,27:102
6,2,27:102
-6,3,27:98.1
6,3,27:98.2
-6,4,27:102
6,4,27:102
-6,5,27:98.0
6,5,27:98.1
-6,6,27:98.0
-5,6,27:98.0
-4,6,27:102
-3,6,27:98.1
-2,6,27:102
-1,6,27:98.3
0,6,27:102
1,6,27:98.3
2,6,27:102
3,6,27:98.2
4,6,27:102
5,6,27:98.1
6,6,27:98.1
-7,7,27:48
7,7,27:4
-7,-7,28:4
7,-7,28:48
-6,-6,28:98.2
-5,-6,28:98.1
-4,-6,28:102
-3,-6,28:98.2
-2,-6,28:102
-1,-6,28:98.2
0,-6,28:102
1,-6,28:98.3
2,-6,28:102
3,-6,28:98.3
4,-6,28:102
5,-6,28:98.0
6,-6,28:98.0
-6,-5,28:98.3
6,-5,28:98.0
-6,-4,28:102
6,-4,28:102
-6,-3,28:98.2
6,-3,28:98.1
-6,-2,28:102
6,-2,28:102
-6,-1,28:98.1
6,-1,28:98.0
-6,0,28:102
6,0,28:102
-6,1,28:98.0
6,1,28:98.1
-6,2,28:102
6,2,28:102
-6,3,28:98.2
6,3,28:98.2
-6,4,28:102
6,4,28:102
-6,5,28:98.2
6,5,28:98.0
-6,6,28:98.1
-5,6,28:98.0
-4,6,28:102
-3,6,28:98.0
-2,6,28:102
-1,6,28:98.3
0,6,28:102
1,6,28:98.3
2,6,28:102
3,6,28:98.0
4,6,28:102
5,6,28:98.0
6,6,28:98.3
-7,7,28:4
7,7,28:4
-7,-7,29:48
7,-7,29:4
-6,-6,29:98.1
-5,-6,29:98.3
-4,-6,29:102
-3,-6,29:98.3
-2,-6,29:102
-1,-6,29:98.2
0,-6,29:102
1,-6,29:98.0
2,-6,29:102
3,-6,29:98.3
4,-6,29:102
5,-6,29:98.3
6,-6,29:98.1
-6,-5,29:98.2
6,-5,29:98.1
-6,-4,29:102
6,-4,29:102
-6,-3,29:98.0
6,-3,29:98.1
-6,-2,29:102
6,-2,29:102
-6,-1,29:98.1
6,-1,29:98.1
-6,0,29:102
6,0,29:102
-6,1,29:98.1
6,1,29:98.2
-6,2,29:102
6,2,29:102
-6,3,29:98.0
6,3,29:98.2
-6,4,29:102
6,4,29:102
-6,5,29:98.1
6,5,29:98.1
-6,6,29:98.1
-5,6,29:98.1
-4,6,29:102
-3,6,29:98.2
-2,6,29:102
-1,6,29:98.3
0,6,29:102
1,6,29:98.1
2,6,29:102
3,6,29:98.1
4,6,29:102
5,6,29:98.3
6,6,29:98.1
-7,7,29:4
7,7,29:4
-7,-7,30:4
-6,-6,30:98.1
-5,-6,30:98.2
-4,-6,30:102
-3,-6,30:98.2
-2,-6,30:102
-1,-6,30:98.3
0,-6,30:102
1,-6,30:98.3
2,-6,30:102
3,-6,30:98.2
4,-6,30:102
-6,-5,30:98.1
-5,-5,30:1
-4,-5,30:1
-3,-5,30:1
-2,-5,30:1
-1,-5,30:1
0,-5,30:4
1,-5,30:4
2,-5,30:1
3,-5,30:1
4,-5,30:1
-6,-4,30:102
-5,-4,30:1
-4,-4,30:1
-3,-4,30:1
-2,-4,30:1
-1,-4,30:1
0,-4,30:1
1,-4,30:1
2,-4,30:4
3,-4,30:1
4,-4,30:1
5,-4,30:1
6,-4,30:102
-6,-3,30:98.3
-5,-3,30:4
-4,-3,30:1
-3,-3,30:1
-2,-3,30:1
-1,-3,30:4
0,-3,30:4
1,-3,30:1
2,-3,30:1
3,-3,30:1
4,-3,30:4
5,-3,30:4
6,-3,30:98.3
-6,-2,30:102
-5,-2,30:1
-4,-2,30:1
-3,-2,30:1
-2,-2,30:4
-1,-2,30:1
0,-2,30:1
1,-2,30:4
2,-2,30:1
3,-2,30:4
4,-2,30:1
5,-2,30:4
6,-2,30:102
-6,-1,30:98.1
-5,-1,30:4
-4,-1,30:1
-3,-1,30:1
-2,-1,30:4
-1,-1,30:4
0,-1,30:1
1,-1,30:4
2,-1,30:1
3,-1,30:1
4,-1,30:4
5,-1,30:4
6,-1,30:98.0
-6,0,30:102
-5,0,30:4
-4,0,30:4
-3,0,30:1
-2,0,30:4
-1,0,30:4
0,0,30:1
1,0,30:4
2,0,30:4
3,0,30:1
4,0,30:1
5,0,30:4
6,0,30:102
-6,1,30:98.3
-5,1,30:1
-4,1,30:4
-3,1,30:4
-2,1,30:4
-1,1,30:4
0,1,30:4
1,1,30:1
2,1,30:1
3,1,30:1
4,1,30:4
5,1,30:4
6,1,30:98.3
-6,2,30:102
-5,2,30:1
-4,2,30:4
-3,2,30:1
-2,2,30:1
-1,2,30:4
0,2,30:4
1,2,30:4
2,2,30:1
3,2,30:1
4,2,30:4
5,2,30:4
6,2,30:102
-6,3,30:98.2
-5,3,30:1
-4,3,30:1
-3,3,30:4
-2,3,30:1
-1,3,30:4
0,3,30:4
1,3,30:1
2,3,30:4
3,3,30:1
4,3,30:4
5,3,30:1
6,3,30:98.3
-6,4,30:102
-5,4,30:4
-4,4,30:1
-3,4,30:4
-2,4,30:1
-1,4,30:1
0,4,30:4
1,4,30:1
2,4,30:4
3,4,30:1
4,4,30:1
5,4,30:1
6,4,30:102
-6,5,30:98.3
-5,5,30:1
-4,5,30:4
-3,5,30:1
-2,5,30:1
-1,5,30:4
0,5,30:4
1,5,30:1
2,5,30:4
3,5,30:4
4,5,30:4
5,5,30:1
6,5,30:98.2
-6,6,30:98.2
-5,6,30:98.0
-4,6,30:102
-3,6,30:98.3
-2,6,30:102
-1,6,30:98.1
0,6,30:102
1,6,30:98.1
2,6,30:102
3,6,30:98.0
4,6,30:102
5,6,30:98.3
6,6,30:98.3
-7,7,30:48
7,7,30:4
-7,-7,31:48
-6,-6,31:98.3
-5,-6,31:98.1
-4,-6,31:102
-3,-6,31:98.1
-2,-6,31:102
-1,-6,31:98.2
0,-6,31:102
1,-6,31:98.0
2,-6,31:102
3,-6,31:98.3
-6,-5,31:98.3
-6,-4,31:102
-6,-3,31:98.2
6,-3,31:98.3
-6,-2,31:102
6,-2,31:102
-6,-1,31:98.2
6,-1,31:98.2
-6,0,31:102
6,0,31:102
-6,1,31:98.0
6,1,31:98.2
-6,2,31:102
6,2,31:102
-6,3,31:98.1
6,3,31:98.1
-6,4,31:102
6,4,31:102
-6,5,31:98.3
6,5,31:98.0
-6,6,31:98.2
-5,6,31:98.1
-4,6,31:102
-3,6,31:98.1
-2,6,31:102
-1,6,31:98.3
0,6,31:102
1,6,31:98.3
2,6,31:102
3,6,31:98.2
4,6,31:102
5,6,31:98.0
6,6,31:98.0
-7,7,31:48
7,7,31:48
-7,-7,32:48
-6,-6,32:98.0
-5,-6,32:98.1
-4,-6,32:102
-3,-6,32:98.3
-2,-6,32:102
-1,-6,32:98.3
0,-6,32:102
1,-6,32:98.3
2,-6,32:102
-6,-5,32:98.3
-6,-4,32:102
-6,-3,32:98.3
-6,-2,32:102
6,-2,32:102
-6,-1,32:98.2
6,-1,32:98.0
-6,0,32:102
6,0,32:102
-6,1,32:98.1
6,1,32:98.1
-6,2,32:102
6,2,32:102
-6,3,32:98.3
6,3,32:98.0
-6,4,32:102
6,4,32:102
-6,5,32:98.3
6,5,32:98.1
-6,6,32:98.2
-5,6,32:98.2
-4,6,32:102
-3,6,32:98.2
-2,6,32:102
-1,6,32:98.2
0,6,32:102
1,6,32:98.1
2,6,32:102
3,6,32:98.0
4,6,32:102
5,6,32:98.2
6,6,32:98.2
-7,7,32:4
7,7,32:48
-7,-7,33:4
-6,-6,33:98.2
-5,-6,33:98.3
-4,-6,33:102
-3,-6,33:98.0
-2,-6,33:102
-1,-6,33:98.1
0,-6,33:102
1,-6,33:98.2
2,-6,33:102
-6,-5,33:98.0
-6,-4,33:102
-6,-3,33:98.3
-6,-2,33:102
6,-2,33:102
-6,-1,33:98.3
6,-1,33:98.0
-6,0,33:102
6,0,33:102
-6,1,33:98.2
6,1,33:98.0
-6,2,33:102
6,2,33:102
-6,3,33:98.0
6,3,33:98.2
-6,4,33:102
6,4,33:102
-6,5,33:98.1
6,5,33:98.0
-6,6,33:98.1
-5,6,33:98.2
-4,6,33:102
-3,6,33:98.3
-2,6,33:102
-1,6,33:98.1
0,6,33:102
1,6,33:98.3
2,6,33:102
3,6,33:98.2
4,6,33:102
5,6,33:98.1
6,6,33:98.3
-7,7,33:48
7,7,33:4
-7,-7,34:4
-6,-6,34:98.3
-5,-6,34:98.0
-4,-6,34:102
-3,-6,34:98.0
-2,-6,34:102
-1,-6,34:98.0
0,-6,34:102
1,-6,34:98.2
-6,-5,34:98.1
-6,-4,34:102
-6,-3,34:98.2
-6,-2,34:102
6,-2,34:102
-6,-1,34:98.1
6,-1,34:98.1
-6,0,34:102
6,0,34:102
-6,1,34:98.3
6,1,34:98.3
-6,2,34:102
6,2,34:102
-6,3,34:98.2
6,3,34:98.3
-6,4,34:102
6,4,34:102
-6,5,34:98.0
6,5,34:98.1
-6,6,34:98.1
-5,6,34:98.3
-4,6,34:102
-3,6,34:98.2
-2,6,34:102
-1,6,34:98.0
0,6,34:102
1,6,34:98.1
2,6,34:102
3,6,34:98.0
4,6,34:102
5,6,34:98.1
6,6,34:98.3
-7,7,34:48
7,7,34:48
-7,-7,35:4
-6,-6,35:98.2
-5,-6,35:98.0
-4,-6,35:102
-3,-6,35:98.3
-2,-6,35:102
-1,-6,35:98.2
0,-6,35:102
-6,-5,35:98.2
-5,-5,35:1
-4,-5,35:4
-3,-5,35:4
-2,-5,35:1
-1,-5,35:4
0,-5,35:1
-6,-4,35:102
-5,-4,35:1
-4,-4,35:1
-3,-4,35:1
-2,-4,35:1
-1,-4,35:1
0,-4,35:4
1,-4,35:4
-6,-3,35:98.2
-5,-3,35:1
-4,-3,35:1
-3,-3,35:1
-2,-3,35:4
-1,-3,35:1
0,-3,35:1
1,-3,35:1
2,-3,35:1
6,-3,35:98.1
-6,-2,35:102
-5,-2,35:1
-4,-2,35:1
-3,-2,35:1
-2,-2,35:1
-1,-2,35:1
0,-2,35:4
1,-2,35:4
2,-2,35:1
3,-2,35:1
4,-2,35:1
5,-2,35:1
6,-2,35:102
-6,-1,35:98.3
-5,-1,35:4
-4,-1,35:4
-3,-1,35:4
-2,-1,35:1
-1,-1,35:4
0,-1,35:1
1,-1,35:4
2,-1,35:1
3,-1,35:4
4,-1,35:4
5,-1,35:1
6,-1,35:98.1
-6,0,35:102
-5,0,35:4
-4,0,35:1
-3,0,35:1
-2,0,35:1
-1,0,35:1
0,0,35:4
1,0,35:1
2,0,35:4
3,0,35:1
4,0,35:4
5,0,35:4
6,0,35:102
-6,1,35:98.0
-5,1,35:1
-4,1,35:1
-3,1,35:4
-2,1,35:4
-1,1,35:1
0,1,35:4
1,1,35:4
2,1,35:4
3,1,35:4
4,1,35:4
5,1,35:4
6,1,35:98.3
-6,2,35:102
-5,2,35:4
-4,2,35:4
-3,2,35:1
-2,2,35:1
-1,2,35:1
0,2,35:1
1,2,35:4
2,2,35:1
3,2,35:1
4,2,35:4
5,2,35:1
6,2,35:102
-6,3,35:98.1
-5,3,35:1
-4,3,35:4
-3,3,35:1
-2,3,35:4
-1,3,35:4
0,3,35:4
1,3,35:1
2,3,35:1
3,3,35:4
4,3,35:4
5,3,35:4
6,3,35:98.1
-6,4,35:102
-5,4,35:4
-4,4,35:4
-3,4,35:1
-2,4,35:4
-1,4,35:1
0,4,35:1
1,4,35:4
2,4,35:4
3,4,35:4
4,4,35:1
5,4,35:4
6,4,35:102
-6,5,35:98.3
-5,5,35:1
-4,5,35:4
-3,5,35:1
-2,5,35:1
-1,5,35:4
0,5,35:1
1,5,35:4
2,5,35:4
3,5,35:1
4,5,35:4
5,5,35:1
6,5,35:98.1
-6,6,35:98.2
-5,6,35:98.0
-4,6,35:102
-3,6,35:98.3
-2,6,35:102
-1,6,35:98.1
0,6,35:102
1,6,35:98.3
2,6,35:102
3,6,35:98.3
4,6,35:102
5,6,35:98.1
6,6,35:98.3
-7,7,35:4
7,7,35:4
-7,-7,36:48
-6,-6,36:98.1
-5,-6,36:98.3
-4,-6,36:102
-3,-6,36:98.2
-2,-6,36:102
-1,-6,36:98.1
0,-6,36:102
-6,-5,36:98.1
-3,-5,36:65.3
-6,-4,36:102
-6,-3,36:98.0
6,-3,36:98.1
-6,-2,36:102
6,-2,36:102
-6,-1,36:98.1
6,-1,36:98.0
-6,0,36:102
6,0,36:102
-6,1,36:98.0
6,1,36:98.2
-6,2,36:102
6,2,36:102
-6,3,36:98.0
6,3,36:98.3
-6,4,36:102
6,4,36:102
-6,5,36:98.2
6,5,36:98.1
-6,6,36:98.0
-5,6,36:98.2
-4,6,36:102
-3,6,36:98.1
-2,6,36:102
-1,6,36:98.2
0,6,36:102
1,6,36:98.2
2,6,36:102
3,6,36:98.2
4,6,36:102
5,6,36:98.0
6,6,36:98.1
-7,7,36:4
7,7,36:4
-7,-7,37:48
-6,-6,37:98.3
-5,-6,37:98.0
-4,-6,37:102
-3,-6,37:98.0
-2,-6,37:102
-1,-6,37:98.2
0,-6,37:102
-6,-5,37:98.0
-3,-5,37:65.3
-6,-4,37:102
-6,-3,37:98.2
6,-3,37:98.2
-6,-2,37:102
6,-2,37:102
-6,-1,37:98.1
6,-1,37:98.2
-6,0,37:102
6,0,37:102
-6,1,37:98.2
6,1,37:98.2
-6,2,37:102
6,2,37:102
-6,3,37:98.1
6,3,37:98.1
-6,4,37:102
6,4,37:102
-6,5,37:98.2
6,5,37:98.0
-6,6,37:98.2
-5,6,37:98.2
-4,6,37:102
-3,6,37:98.0
-2,6,37:102
-1,6,37:98.2
0,6,37:102
1,6,37:98.2
2,6,37:102
3,6,37:98.3
4,6,37:102
5,6,37:98.2
6,6,37:98.0
-7,7,37:48
7,7,37:4
-7,-7,38:4
-6,-6,38:98.3
-5,-6,38:98.3
-4,-6,38:102
-3,-6,38:98.3
-2,-6,38:102
-1,-6,38:98.2
0,-6,38:102
-6,-5,38:98.2
-3,-5,38:65.3
-6,-4,38:102
-6,-3,38:98.3
6,-3,38:98.0
-6,-2,38:102
6,-2,38:102
-6,-1,38:98.1
6,-1,38:98.2
-6,0,38:102
6,0,38:102
-6,1,38:98.2
6,1,38:98.1
-6,2,38:102
6,2,38:102
-6,3,38:98.2
6,3,38:98.2
-6,4,38:102
6,4,38:102
-6,5,38:98.1
6,5,38:98.0
-6,6,38:98.0
-5,6,38:98.3
-4,6,38:102
-3,6,38:98.3
-2,6,38:102
-1,6,38:98.0
0,6,38:102
1,6,38:98.3
2,6,38:102
3,6,38:98.2
4,6,38:102
5,6,38:98.1
6,6,38:98.3
-7,7,38:48
7,7,38:4
-7,-7,39:4
-6,-6,39:98.2
-5,-6,39:98.1
-4,-6,39:102
-3,-6,39:98.2
-2,-6,39:102
-1,-6,39:98.1
0,-6,39:102
-6,-5,39:98.3
-3,-5,39:65.3
-6,-4,39:102
-6,-3,39:98.3
6,-3,39:98.2
-6,-2,39:102
6,-2,39:102
-6,-1,39:98.3
6,-1,39:98.2
-6,0,39:102
6,0,39:102
-6,1,39:98.2
6,1,39:98.0
-6,2,39:102
6,2,39:102
-6,3,39:98.2
6,3,39:98.1
-6,4,39:102
6,4,39:102
-6,5,39:98.1
6,5,39:98.1
-6,6,39:98.0
-5,6,39:98.0
-4,6,39:102
-3,6,39:98.1
-2,6,39:102
-1,6,39:98.2
0,6,39:102
1,6,39:98.0
2,6,39:102
3,6,39:98.0
4,6,39:102
5,6,39:98.3
6,6,39:98.2
-7,7,39:4
7,7,39:4
-7,-7,40:4
-6,-6,40:98.0
-5,-6,40:98.0
-4,-6,40:102
-3,-6,40:98.2
-2,-6,40:102
-1,-6,40:98.0
0,-6,40:102
-6,-5,40:98.1
-5,-5,40:1
-4,-5,40:1
-2,-5,40:1
-1,-5,40:1
0,-5,40:1
-6,-4,40:102
-5,-4,40:1
-4,-4,40:1
-3,-4,40:1
-2,-4,40:1
-1,-4,40:1
0,-4,40:1
1,-4,40:1
-6,-3,40:98.1
-5,-3,40:1
-4,-3,40:1
-3,-3,40:4
-2,-3,40:1
-1,-3,40:4
0,-3,40:4
1,-3,40:4
2,-3,40:4
6,-3,40:98.0
-6,-2,40:102
-5,-2,40:4
-4,-2,40:1
-3,-2,40:4
-2,-2,40:1
-1,-2,40:4
0,-2,40:4
1,-2,40:4
2,-2,40:4
3,-2,40:4
4,-2,40:1
5,-2,40:4
6,-2,40:102
-6,-1,40:98.3
-5,-1,40:1
-4,-1,40:1
-3,-1,40:1
-2,-1,40:1
-1,-1,40:4
0,-1,40:4
1,-1,40:1
2,-1,40:4
3,-1,40:1
4,-1,40:4
5,-1,40:1
6,-1,40:98.3
-6,0,40:102
-5,0,40:1
-4,0,40:1
-3,0,40:4
-2,0,40:1
-1,0,40:1
0,0,40:1
1,0,40:1
2,0,40:1
3,0,40:1
4,0,40:1
5,0,40:4
6,0,40:102
-6,1,40:98.3
-5,1,40:4
-4,1,40:4
-3,1,40:1
-2,1,40:4
-1,1,40:4
0,1,40:4
1,1,40:1
2,1,40:1
3,1,40:4
4,1,40:1
5,1,40:1
6,1,40:98.2
-6,2,40:102
-5,2,40:4
-4,2,40:1
-3,2,40:4
-2,2,40:4
-1,2,40:1
0,2,40:4
1,2,40:4
2,2,40:4
3,2,40:4
4,2,40:1
5,2,40:1
6,2,40:102
-6,3,40:98.1
-5,3,40:1
-4,3,40:1
-3,3,40:4
-2,3,40:4
-1,3,40:1
0,3,40:4
1,3,40:4
2,3,40:1
3,3,40:1
4,3,40:1
5,3,40:1
6,3,40:98.2
-6,4,40:102
-5,4,40:4
-4,4,40:1
-3,4,40:4
-2,4,40:4
-1,4,40:4
0,4,40:1
1,4,40:4
2,4,40:1
3,4,40:4
4,4,40:1
5,4,40:1
6,4,40:102
-6,5,40:98.2
-5,5,40:1
-4,5,40:4
-3,5,40:1
-2,5,40:1
-1,5,40:4
0,5,40:1
1,5,40:1
2,5,40:1
3,5,40:4
4,5,40:1
5,5,40:4
6,5,40:98.3
-6,6,40:98.2
-5,6,40:98.1
-4,6,40:102
-3,6,40:98.1
-2,6,40:102
-1,6,40:98.2
0,6,40:102
1,6,40:98.3
2,6,40:102
3,6,40:98.3
4,6,40:102
5,6,40:98.1
6,6,40:98.1
-7,7,40:48
7,7,40:48
-7,-7,41:4
-6,-6,41:98.2
-5,-6,41:98.3
-4,-6,41:102
-3,-6,41:98.3
-2,-6,41:102
-1,-6,41:98.3
0,-6,41:102
-6,-5,41:98.0
-6,-4,41:102
-6,-3,41:98.2
-5,-3,41:65.5
6,-3,41:98.2
-6,-2,41:102
6,-2,41:102
-6,-1,41:98.0
6,-1,41:98.3
-6,0,41:102
6,0,41:102
-6,1,41:98.0
6,1,41:98.3
-6,2,41:102
6,2,41:102
-6,3,41:98.1
6,3,41:98.0
-6,4,41:102
6,4,41:102
-6,5,41:98.3
6,5,41:98.0
-6,6,41:98.3
-5,6,41:98.0
-4,6,41:102
-3,6,41:98.3
-2,6,41:102
-1,6,41:98.3
0,6,41:102
1,6,41:98.2
2,6,41:102
3,6,41:98.2
4,6,41:102
5,6,41:98.2
6,6,41:98.3
-7,7,41:48
7,7,41:48
-7,-7,42:48
-6,-6,42:98.1
-5,-6,42:98.3
-4,-6,42:102
-3,-6,42:98.0
-2,-6,42:102
-1,-6,42:98.3
0,-6,42:102
1,-6,42:98.1
-6,-5,42:98.0
-6,-4,42:102
-6,-3,42:98.3
-5,-3,42:65.5
6,-3,42:98.3
-6,-2,42:102
6,-2,42:102
-6,-1,42:98.2
6,-1,42:98.0
-6,0,42:102
6,0,42:102
-6,1,42:98.3
6,1,42:98.2
-6,2,42:102
6,2,42:102
-6,3,42:98.0
6,3,42:98.2
-6,4,42:102
6,4,42:102
-6,5,42:98.2
6,5,42:98.2
-6,6,42:98.1
-5,6,42:98.0
-4,6,42:102
-3,6,42:98.1
-2,6,42:102
-1,6,42:98.2
0,6,42:102
1,6,42:98.0
2,6,42:102
3,6,42:98.1
4,6,42:102
5,6,42:98.1
6,6,42:98.2
-7,7,42:48
7,7,42:4
-7,-7,43:4
-6,-6,43:98.0
-5,-6,43:98.0
-4,-6,43:102
-3,-6,43:98.0
-2,-6,43:102
-1,-6,43:98.2
0,-6,43:102
1,-6,43:98.1
2,-6,43:102
-6,-5,43:98.0
-6,-4,43:102
-6,-3,43:98.1
-5,-3,43:65.5
6,-3,43:98.1
-6,-2,43:102
6,-2,43:102
-6,-1,43:98.2
6,-1,43:98.0
-6,0,43:102
6,0,43:102
-6,1,43:98.0
6,1,43:98.0
-6,2,43:102
6,2,43:102
-6,3,43:98.0
6,3,43:98.3
-6,4,43:102
6,4,43:102
-6,5,43:98.2
6,5,43:98.2
-6,6,43:98.1
-5,6,43:98.1
-4,6,43:102
-3,6,43:98.1
-2,6,43:102
-1,6,43:98.3
0,6,43:102
1,6,43:98.1
2,6,43:102
3,6,43:98.2
4,6,43:102
5,6,43:98.2
6,6,43:98.2
-7,7,43:4
7,7,43:48
-7,-7,44:48
-6,-6,44:98.1
-5,-6,44:98.2
-4,-6,44:102
-3,-6,44:98.3
-2,-6,44:102
-1,-6,44:98.1
0,-6,44:102
1,-6,44:98.1
2,-6,44:102
-6,-5,44:98.2
-6,-4,44:102
-6,-3,44:98.0
-5,-3,44:65.5
-6,-2,44:102
6,-2,44:102
-6,-1,44:98.3
6,-1,44:98.1
-6,0,44:102
6,0,44:102
-6,1,44:98.2
6,1,44:98.3
-6,2,44:102
6,2,44:102
-6,3,44:98.3
6,3,44:98.3
-6,4,44:102
6,4,44:102
-6,5,44:98.2
6,5,44:98.0
-6,6,44:98.2
-5,6,44:98.1
-4,6,44:102
-3,6,44:98.0
-2,6,44:102
-1,6,44:98.2
0,6,44:102
1,6,44:98.1
2,6,44:102
3,6,44:98.0
4,6,44:102
5,6,44:98.0
6,6,44:98.1
-7,7,44:48
7,7,44:48
-7,-7,45:48
-6,-6,45:98.1
-5,-6,45:98.0
-4,-6,45:102
-3,-6,45:98.2
-2,-6,45:102
-1,-6,45:98.0
0,-6,45:102
1,-6,45:98.3
2,-6,45:102
-6,-5,45:98.3
-5,-5,45:1
-4,-5,45:4
-3,-5,45:1
-2,-5,45:4
-1,-5,45:4
0,-5,45:4
1,-5,45:1
2,-5,45:1
-6,-4,45:102
-5,-4,45:1
-4,-4,45:1
-3,-4,45:4
-2,-4,45:4
-1,-4,45:4
0,-4,45:4
1,-4,45:4
2,-4,45:4
3,-4,45:1
-6,-3,45:98.3
-5,-3,45:65.5
-4,-3,45:4
-3,-3,45:4
-2,-3,45:1
-1,-3,45:1
0,-3,45:4
1,-3,45:1
2,-3,45:4
3,-3,45:4
4,-3,45:1
-6,-2,45:102
-5,-2,45:4
-4,-2,45:1
-3,-2,45:1
-2,-2,45:1
-1,-2,45:4
0,-2,45:4
1,-2,45:4
2,-2,45:4
3,-2,45:1
4,-2,45:4
5,-2,45:4
6,-2,45:102
-6,-1,45:98.0
-5,-1,45:4
-4,-1,45:4
-3,-1,45:1
-2,-1,45:1
-1,-1,45:1
0,-1,45:4
1,-1,45:1
2,-1,45:1
3,-1,45:4
4,-1,45:4
5,-1,45:1
6,-1,45:98.1
-6,0,45:102
-5,0,45:1
-4,0,45:1
-3,0,45:4
-2,0,45:4
-1,0,45:4
0,0,45:4
1,0,45:1
2,0,45:4
3,0,45:4
4,0,45:4
5,0,45:4
6,0,45:102
-6,1,45:98.0
-5,1,45:4
-4,1,45:1
-3,1,45:1
-2,1,45:4
-1,1,45:4
0,1,45:4
1,1,45:4
2,1,45:1
3,1,45:4
4,1,45:1
5,1,45:1
6,1,45:98.1
-6,2,45:102
-5,2,45:4
-4,2,45:4
-3,2,45:4
-2,2,45:1
-1,2,45:4
0,2,45:4
1,2,45:4
2,2,45:1
3,2,45:1
4,2,45:4
5,2,45:1
6,2,45:102
-6,3,45:98.0
-5,3,45:1
-4,3,45:4
-3,3,45:4
-2,3,45:4
-1,3,45:1
0,3,45:1
1,3,45:1
2,3,45:1
3,3,45:4
4,3,45:1
5,3,45:1
6,3,45:98.3
-6,4,45:102
-5,4,45:1
-4,4,45:4
-3,4,45:1
-2,4,45:1
-1,4,45:1
0,4,45:1
1,4,45:4
2,4,45:1
3,4,45:1
4,4,45:1
5,4,45:1
6,4,45:102
-6,5,45:98.0
-5,5,45:1
-4,5,45:1
-3,5,45:4
-2,5,45:1
-1,5,45:1
0,5,45:1
1,5,45:4
2,5,45:1
3,5,45:1
4,5,45:1
5,5,45:1
6,5,45:98.1
-6,6,45:98.2
-5,6,45:98.0
-4,6,45:102
-3,6,45:98.2
-2,6,45:102
-1,6,45:98.1
0,6,45:102
1,6,45:98.1
2,6,45:102
3,6,45:98.1
4,6,45:102
5,6,45:98.1
6,6,45:98.0
-7,7,45:48
7,7,45:4
-7,-7,46:4
-6,-6,46:98.3
-5,-6,46:98.2
-4,-6,46:102
-3,-6,46:98.1
-2,-6,46:102
-1,-6,46:98.1
0,-6,46:102
1,-6,46:98.2
2,-6,46:102
-6,-5,46:98.2
-6,-4,46:102
-6,-3,46:98.1
-6,-2,46:102
6,-2,46:102
-6,-1,46:98.1
6,-1,46:98.3
-6,0,46:102
6,0,46:102
-6,1,46:98.0
6,1,46:98.0
-6,2,46:102
6,2,46:102
-6,3,46:98.0
6,3,46:98.3
-6,4,46:102
6,4,46:102
-6,5,46:98.2
6,5,46:98.1
-6,6,46:98.1
-5,6,46:98.3
-4,6,46:102
-3,6,46:98.2
-2,6,46:102
-1,6,46:98.1
0,6,46:102
1,6,46:98.2
2,6,46:102
3,6,46:98.3
4,6,46:102
5,6,46:98.0
6,6,46:98.2
-7,7,46:4
7,7,46:4
-7,-7,47:48
-6,-6,47:98.2
-5,-6,47:98.3
-4,-6,47:102
-3,-6,47:98.1
-2,-6,47:102
-1,-6,47:98.1
0,-6,47:102
1,-6,47:98.2
2,-6,47:102
3,-6,47:98.2
-6,-5,47:98.0
-6,-4,47:102
-6,-3,47:98.2
-5,-3,47:65.5
6,-3,47:98.3
-6,-2,47:102
6,-2,47:102
-6,-1,47:98.1
6,-1,47:98.2
-6,0,47:102
6,0,47:102
-6,1,47:98.2
6,1,47:98.3
-6,2,47:102
6,2,47:102
-6,3,47:98.2
6,3,47:98.1
-6,4,47:102
6,4,47:102
-6,5,47:98.3
6,5,47:98.1
-6,6,47:98.0
-5,6,47:98.3
-4,6,47:102
-3,6,47:98.0
-2,6,47:102
-1,6,47:98.3
0,6,47:102
1,6,47:98.3
2,6,47:102
3,6,47:98.1
4,6,47:102
5,6,47:98.1
6,6,47:98.1
-7,7,47:48
7,7,47:48
-7,-7,48:4
-6,-6,48:98.3
-5,-6,48:98.0
-4,-6,48:102
-3,-6,48:98.3
-2,-6,48:102
-1,-6,48:98.0
0,-6,48:102
1,-6,48:98.2
2,-6,48:102
3,-6,48:98.2
4,-6,48:102
-6,-5,48:98.0
-6,-4,48:102
6,-4,48:102
-6,-3,48:98.3
-5,-3,48:65.5
6,-3,48:98.3
-6,-2,48:102
6,-2,48:102
-6,-1,48:98.1
6,-1,48:98.0
-6,0,48:102
6,0,48:102
-6,1,48:98.1
6,1,48:98.2
-6,2,48:102
6,2,48:102
-6,3,48:98.2
6,3,48:98.0
-6,4,48:102
6,4,48:102
-6,5,48:98.0
6,5,48:98.0
-6,6,48:98.2
-5,6,48:98.3
-4,6,48:102
-3,6,48:98.1
-2,6,48:102
-1,6,48:98.1
0,6,48:102
1,6,48:98.3
2,6,48:102
3,6,48:98.1
4,6,48:102
5,6,48:98.1
6,6,48:98.3
-7,7,48:4
7,7,48:4
-7,-7,49:4
7,-7,49:4
-6,-6,49:98.1
-5,-6,49:98.3
-4,-6,49:102
-3,-6,49:98.1
-2,-6,49:102
-1,-6,49:98.2
0,-6,49:102
1,-6,49:98.3
2,-6,49:102
3,-6,49:98.1
4,-6,49:102
5,-6,49:98.2
6,-6,49:98.1
-6,-5,49:98.0
6,-5,49:98.1
-6,-4,49:102
6,-4,49:102
-6,-3,49:98.2
-5,-3,49:65.5
6,-3,49:98.1
-6,-2,49:102
6,-2,49:102
-6,-1,49:98.2
6,-1,49:98.3
-6,0,49:102
6,0,49:102
-6,1,49:98.2
6,1,49:98.0
-6,2,49:102
6,2,49:102
-6,3,49:98.0
6,3,49:98.1
-6,4,49:102
6,4,49:102
-6,5,49:98.0
6,5,49:98.3
-6,6,49:98.1
-5,6,49:98.3
-4,6,49:102
-3,6,49:98.2
-2,6,49:102
-1,6,49:98.0
0,6,49:102
1,6,49:98.3
2,6,49:102
3,6,49:98.0
4,6,49:102
5,6,49:98.0
6,6,49:98.2
-7,7,49:48
7,7,49:4
-7,-7,50:4
7,-7,50:4
-6,-6,50:98.3
-5,-6,50:98.2
-4,-6,50:102
-3,-6,50:98.2
-2,-6,50:102
-1,-6,50:98.1
0,-6,50:102
1,-6,50:98.1
2,-6,50:102
3,-6,50:98.2
4,-6,50:102
5,-6,50:98.3
6,-6,50:98.0
-6,-5,50:98.1
-5,-5,50:4
-4,-5,50:4
-3,-5,50:1
-2,-5,50:1
-1,-5,50:1
0,-5,50:4
1,-5,50:4
2,-5,50:4
4,-5,50:1
5,-5,50:4
6,-5,50:98.1
-6,-4,50:102
-5,-4,50:1
-4,-4,50:4
-3,-4,50:1
-2,-4,50:4
-1,-4,50:4
0,-4,50:4
1,-4,50:1
2,-4,50:4
3,-4,50:1
4,-4,50:1
5,-4,50:4
6,-4,50:102
-6,-3,50:98.3
-5,-3,50:65.5
-4,-3,50:4
-3,-3,50:1
-2,-3,50:4
-1,-3,50:1
0,-3,50:1
1,-3,50:4
2,-3,50:1
3,-3,50:1
4,-3,50:1
5,-3,50:4
6,-3,50:98.2
-6,-2,50:102
-5,-2,50:4
-4,-2,50:4
-3,-2,50:1
-2,-2,50:1
-1,-2,50:4
0,-2,50:1
1,-2,50:1
2,-2,50:4
3,-2,50:4
4,-2,50:1
5,-2,50:4
6,-2,50:102
-6,-1,50:98.3
-5,-1,50:1
-4,-1,50:1
-3,-1,50:4
-2,-1,50:1
-1,-1,50:1
0,-1,50:4
1,-1,50:4
2,-1,50:4
3,-1,50:4
4,-1,50:4
5,-1,50:1
6,-1,50:98.0
-6,0,50:102
-5,0,50:1
-4,0,50:4
-3,0,50:1
-2,0,50:4
-1,0,50:4
0,0,50:4
1,0,50:1
2,0,50:4
3,0,50:1
4,0,50:1
5,0,50:4
6,0,50:102
-6,1,50:98.2
-5,1,50:4
-4,1,50:1
-3,1,50:1
-2,1,50:1
-1,1,50:1
0,1,50:4
1,1,50:4
2,1,50:1
3,1,50:1
4,1,50:4
5,1,50:4
6,1,50:98.1
-6,2,50:102
-5,2,50:4
-4,2,50:1
-3,2,50:4
-2,2,50:4
-1,2,50:1
0,2,50:1
1,2,50:1
2,2,50:4
3,2,50:4
4,2,50:4
5,2,50:4
6,2,50:102
-6,3,50:98.0
-5,3,50:4
-4,3,50:4
-3,3,50:4
-2,3,50:1
-1,3,50:1
0,3,50:1
1,3,50:4
2,3,50:1
3,3,50:1
4,3,50:4
5,3,50:1
6,3,50:98.0
-6,4,50:102
-5,4,50:1
-4,4,50:4
-3,4,50:1
-2,4,50:1
-1,4,50:1
0,4,50:1
1,4,50:1
2,4,50:1
3,4,50:4
4,4,50:4
5,4,50:4
6,4,50:102
-6,5,50:98.0
-5,5,50:1
-4,5,50:1
-3,5,50:1
-2,5,50:4
-1,5,50:4
0,5,50:1
1,5,50:1
2,5,50:1
3,5,50:4
4,5,50:1
5,5,50:1
6,5,50:98.1
-6,6,50:98.1
-5,6,50:98.3
-4,6,50:102
-3,6,50:98.2
-2,6,50:102
-1,6,50:98.3
0,6,50:102
1,6,50:98.1
2,6,50:102
3,6,50:98.2
4,6,50:102
5,6,50:98.1
6,6,50:98.2
-7,7,50:4
7,7,50:4
-7,-7,51:48
7,-7,51:4
-6,-6,51:98.3
-5,-6,51:98.0
-4,-6,51:102
-3,-6,51:98.1
-2,-6,51:102
-1,-6,51:98.3
0,-6,51:102
1,-6,51:98.2
2,-6,51:102
3,-6,51:98.0
4,-6,51:102
5,-6,51:98.0
6,-6,51:98.2
-6,-5,51:98.0
3,-5,51:65.3
6,-5,51:98.2
-6,-4,51:102
6,-4,51:102
-6,-3,51:98.3
6,-3,51:98.2
-6,-2,51:102
6,-2,51:102
-6,-1,51:98.2
6,-1,51:98.0
-6,0,51:102
6,0,51:102
-6,1,51:98.2
6,1,51:98.0
-6,2,51:102
6,2,51:102
-6,3,51:98.1
6,3,51:98.1
-6,4,51:102
6,4,51:102
-6,5,51:98.1
6,5,51:98.3
-6,6,51:98.1
-5,6,51:98.1
-4,6,51:102
-3,6,51:98.0
-2,6,51:102
-1,6,51:98.1
0,6,51:102
1,6,51:98.2
2,6,51:102
3,6,51:98.2
4,6,51:102
5,6,51:98.2
6,6,51:98.2
-7,7,51:48
7,7,51:4
-7,-7,52:48
7,-7,52:4
-6,-6,52:98.3
-5,-6,52:98.0
-4,-6,52:102
-3,-6,52:98.2
-2,-6,52:102
-1,-6,52:98.3
0,-6,52:102
1,-6,52:98.0
2,-6,52:102
3,-6,52:98.1
4,-6,52:102
5,-6,52:98.0
6,-6,52:98.2
-6,-5,52:98.0
3,-5,52:65.3
6,-5,52:98.0
-6,-4,52:102
6,-4,52:102
-6,-3,52:98.1
6,-3,52:98.0
-6,-2,52:102
6,-2,52:102
-6,-1,52:98.0
6,-1,52:98.2
-6,0,52:102
6,0,52:102
-6,1,52:98.2
6,1,52:98.2
-6,2,52:102
6,2,52:102
-6,3,52:98.0
6,3,52:98.2
-6,4,52:102
6,4,52:102
-6,5,52:98.3
6,5,52:98.1
-6,6,52:98.1
-5,6,52:98.2
-4,6,52:102
-3,6,52:98.3
-2,6,52:102
-1,6,52:98.2
0,6,52:102
1,6,52:98.0
2,6,52:102
3,6,52:98.2
4,6,52:102
5,6,52:98.3
6,6,52:98.0
-7,7,52:4
7,7,52:4
-7,-7,53:4
7,-7,53:48
-6,-6,53:98.2
-5,-6,53:98.0
-4,-6,53:102
-3,-6,53:98.1
-2,-6,53:102
-1,-6,53:98.3
0,-6,53:102
1,-6,53:98.1
2,-6,53:102
3,-6,53:98.0
4,-6,53:102
5,-6,53:98.0
6,-6,53:98.0
-6,-5,53:98.3
3,-5,53:65.3
6,-5,53:98.2
-6,-4,53:102
6,-4,53:102
-6,-3,53:98.2
6,-3,53:98.2
-6,-2,53:102
6,-2,53:102
-6,-1,53:98.0
6,-1,53:98.3
-6,0,53:102
6,0,53:102
-6,1,53:98.1
6,1,53:98.3
-6,2,53:102
6,2,53:102
-6,3,53:98.1
6,3,53:98.0
-6,4,53:102
6,4,53:102
-6,5,53:98.1
6,5,53:98.1
-6,6,53:98.1
-5,6,53:98.1
-4,6,53:102
-3,6,53:98.3
-2,6,53:102
-1,6,53:98.3
0,6,53:102
1,6,53:98.2
2,6,53:102
3,6,53:98.3
4,6,53:102
5,6,53:98.1
6,6,53:98.0
-7,7,53:4
7,7,53:48
-7,-7,54:4
7,-7,54:48
-6,-6,54:98.0
-5,-6,54:98.3
-4,-6,54:102
-3,-6,54:98.3
-2,-6,54:102
-1,-6,54:98.1
0,-6,54:102
1,-6,54:98.0
2,-6,54:102
3,-6,54:98.2
4,-6,54:102
5,-6,54:98.0
6,-6,54:98.0
-6,-5,54:98.1
3,-5,54:65.3
6,-5,54:98.0
-6,-4,54:102
6,-4,54:102
-6,-3,54:98.0
6,-3,54:98.3
-6,-2,54:102
6,-2,54:102
-6,-1,54:98.1
6,-1,54:98.3
-6,0,54:102
6,0,54:102
-6,1,54:98.2
6,1,54:98.0
-6,2,54:102
6,2,54:102
-6,3,54:98.2
6,3,54:98.2
-6,4,54:102
6,4,54:102
-6,5,54:98.2
6,5,54:98.0
-6,6,54:98.2
-5,6,54:98.0
-4,6,54:102
-3,6,54:98.0
-2,6,54:102
-1,6,54:98.0
0,6,54:102
1,6,54:98.3
2,6,54:102
3,6,54:98.1
4,6,54:102
5,6,54:98.3
6,6,54:98.1
-7,7,54:4
7,7,54:48
-7,-7,55:4
7,-7,55:48
-6,-6,55:98.0
-5,-6,55:98.2
-4,-6,55:102
-3,-6,55:98.1
-2,-6,55:102
-1,-6,55:98.0
0,-6,55:102
1,-6,55:98.0
2,-6,55:102
3,-6,55:98.0
4,-6,55:102
5,-6,55:98.2
6,-6,55:98.1
-6,-5,55:98.2
-5,-5,55:4
-4,-5,55:4
-3,-5,55:4
-2,-5,55:1
-1,-5,55:1
0,-5,55:4
1,-5,55:1
2,-5,55:1
3,-5,55:65.3
4,-5,55:1
5,-5,55:1
6,-5,55:98.3
-6,-4,55:102
-5,-4,55:4
-4,-4,55:1
-3,-4,55:4
-2,-4,55:4
-1,-4,55:1
0,-4,55:1
1,-4,55:1
2,-4,55:1
3,-4,55:1
4,-4,55:1
5,-4,55:4
6,-4,55:102
-6,-3,55:98.0
-5,-3,55:1
-4,-3,55:1
-3,-3,55:1
-2,-3,55:1
-1,-3,55:1
0,-3,55:4
1,-3,55:4
2,-3,55:1
3,-3,55:1
4,-3,55:4
5,-3,55:1
6,-3,55:98.1
-6,-2,55:102
-5,-2,55:1
-4,-2,55:1
-3,-2,55:1
-2,-2,55:1
-1,-2,55:4
0,-2,55:4
1,-2,55:1
2,-2,55:1
3,-2,55:1
4,-2,55:4
5,-2,55:4
6,-2,55:102
-6,-1,55:98.1
-5,-1,55:1
-4,-1,55:1
-3,-1,55:4
-2,-1,55:4
-1,-1,55:4
0,-1,55:4
1,-1,55:1
2,-1,55:4
3,-1,55:4
4,-1,55:1
5,-1,55:4
6,-1,55:98.0
-6,0,55:102
-5,0,55:4
-4,0,55:1
-3,0,55:1
-2,0,55:1
-1,0,55:1
0,0,55:4
1,0,55:1
2,0,55:4
3,0,55:4
4,0,55:4
5,0,55:1
6,0,55:102
-6,1,55:98.1
-5,1,55:4
-4,1,55:4
-3,1,55:1
-2,1,55:4
-1,1,55:1
0,1,55:1
1,1,55:4
2,1,55:1
3,1,55:1
4,1,55:4
5,1,55:1
6,1,55:98.2
-6,2,55:102
-5,2,55:4
-4,2,55:1
-3,2,55:1
-2,2,55:4
-1,2,55:1
0,2,55:4
1,2,55:1
2,2,55:1
3,2,55:4
4,2,55:4
5,2,55:4
6,2,55:102
-6,3,55:98.1
-5,3,55:1
-4,3,55:1
-3,3,55:4
-2,3,55:4
-1,3,55:4
0,3,55:1
1,3,55:4
2,3,55:4
3,3,55:4
4,3,55:4
5,3,55:1
6,3,55:98.2
-6,4,55:102
-5,4,55:1
-4,4,55:1
-3,4,55:4
-2,4,55:1
-1,4,55:4
0,4,55:4
1,4,55:1
2,4,55:4
3,4,55:1
4,4,55:4
5,4,55:1
6,4,55:102
-6,5,55:98.0
-5,5,55:1
-4,5,55:1
-3,5,55:1
-2,5,55:4
-1,5,55:1
0,5,55:1
1,5,55:1
2,5,55:4
3,5,55:4
4,5,55:1
5,5,55:4
6,5,55:98.1
-6,6,55:98.1
-5,6,55:98.2
-4,6,55:102
-3,6,55:98.1
-2,6,55:102
-1,6,55:98.3
0,6,55:102
1,6,55:98.0
2,6,55:102
3,6,55:98.2
4,6,55:102
5,6,55:98.2
6,6,55:98.0
-7,7,55:4
7,7,55:4
-7,-7,56:48
7,-7,56:4
-6,-6,56:98.0
-5,-6,56:98.0
-4,-6,56:102
-3,-6,56:98.0
-2,-6,56:102
-1,-6,56:98.0
0,-6,56:102
1,-6,56:98.3
2,-6,56:102
3,-6,56:98.2
4,-6,56:102
5,-6,56:98.1
6,-6,56:98.3
-6,-5,56:98.1
3,-5,56:65.3
6,-5,56:98.2
-6,-4,56:102
6,-4,56:102
-6,-3,56:98.0
6,-3,56:98.3
-6,-2,56:102
6,-2,56:102
-6,-1,56:98.0
6,-1,56:98.3
-6,0,56:102
6,0,56:102
-6,1,56:98.3
6,1,56:98.2
-6,2,56:102
6,2,56:102
-6,3,56:98.2
6,3,56:98.2
-6,4,56:102
6,4,56:102
-6,5,56:98.2
6,5,56:98.3
-6,6,56:98.2
-5,6,56:98.3
-4,6,56:102
-3,6,56:98.0
-2,6,56:102
-1,6,56:98.1
0,6,56:102
1,6,56:98.1
2,6,56:102
3,6,56:98.1
4,6,56:102
5,6,56:98.2
6,6,56:98.0
-7,7,56:48
7,7,56:48
-7,-7,57:4
7,-7,57:4
-6,-6,57:98.2
-5,-6,57:98.0
-4,-6,57:102
-3,-6,57:98.1
-2,-6,57:102
-1,-6,57:98.1
0,-6,57:102
1,-6,57:98.2
2,-6,57:102
3,-6,57:98.3
4,-6,57:102
5,-6,57:98.2
6,-6,57:98.2
-6,-5,57:98.3
3,-5,57:65.3
6,-5,57:98.0
-6,-4,57:102
6,-4,57:102
-6,-3,57:98.3
6,-3,57:98.0
-6,-2,57:102
6,-2,57:102
-6,-1,57:98.1
6,-1,57:98.1
-6,0,57:102
6,0,57:102
-6,1,57:98.2
6,1,57:98.0
-6,2,57:102
6,2,57:102
-6,3,57:98.0
6,3,57:98.1
-6,4,57:102
6,4,57:102
-6,5,57:98.1
6,5,57:98.0
-6,6,57:98.3
-5,6,57:98.0
-4,6,57:102
-3,6,57:98.1
-2,6,57:102
-1,6,57:98.1
0,6,57:102
1,6,57:98.3
2,6,57:102
3,6,57:98.3
4,6,57:102
5,6,57:98.0
6,6,57:98.3
-7,7,57:48
7,7,57:4
-7,-7,58:4
7,-7,58:48
-6,-6,58:98.2
-5,-6,58:98.3
-4,-6,58:102
-3,-6,58:98.0
-2,-6,58:102
-1,-6,58:98.0
0,-6,58:102
1,-6,58:98.2
2,-6,58:102
3,-6,58:98.1
4,-6,58:102
5,-6,58:98.2
6,-6,58:98.3
-6,-5,58:98.2
3,-5,58:65.3
6,-5,58:98.0
-6,-4,58:102
6,-4,58:102
-6,-3,58:98.0
6,-3,58:98.2
-6,-2,58:102
6,-2,58:102
-6,-1,58:98.1
6,-1,58:98.1
-6,0,58:102
6,0,58:102
-6,1,58:98.3
6,1,58:98.2
-6,2,58:102
6,2,58:102
-6,3,58:98.2
6,3,58:98.1
-6,4,58:102
6,4,58:102
-6,5,58:98.0
6,5,58:98.3
-6,6,58:98.0
-5,6,58:98.3
-4,6,58:102
-3,6,58:98.0
-2,6,58:102
-1,6,58:98.1
0,6,58:102
1,6,58:98.0
2,6,58:102
3,6,58:98.1
4,6,58:102
5,6,58:98.1
6,6,58:98.1
-7,7,58:4
7,7,58:48
-7,-7,59:48
7,-7,59:4
-6,-6,59:98.3
-5,-6,59:98.1
-4,-6,59:102
-3,-6,59:98.3
-2,-6,59:102
-1,-6,59:98.2
0,-6,59:102
1,-6,59:98.2
2,-6,59:102
3,-6,59:98.1
4,-6,59:102
5,-6,59:98.0
6,-6,59:98.3
-6,-5,59:98.1
3,-5,59:65.3
6,-5,59:98.0
-6,-4,59:102
6,-4,59:102
-6,-3,59:98.0
6,-3,59:98.1
-6,-2,59:102
6,-2,59:102
-6,-1,59:98.1
6,-1,59:98.1
-6,0,59:102
6,0,59:102
-6,1,59:98.1
6,1,59:98.1
-6,2,59:102
6,2,59:102
-6,3,59:98.2
6,3,59:98.3
-6,4,59:102
6,4,59:102
-6,5,59:98.1
6,5,59:98.3
-6,6,59:98.1
-5,6,59:98.1
-4,6,59:102
-3,6,59:98.3
-2,6,59:102
-1,6,59:98.1
0,6,59:102
1,6,59:98.0
2,6,59:102
3,6,59:98.0
4,6,59:102
5,6,59:98.1
6,6,59:98.3
-7,7,59:48
7,7,59:4
-7,-7,60:4
-6,-7,60:48
-5,-7,60:4
-4,-7,60:4
-3,-7,60:4
-2,-7,60:4
-1,-7,60:4
0,-7,60:4
1,-7,60:4
2,-7,60:4
3,-7,60:4
4,-7,60:4
5,-7,60:4
6,-7,60:48
7,-7,60:48
-7,-6,60:4
-6,-6,60:98.3
-5,-6,60:98.1
-4,-6,60:102
-3,-6,60:98.2
-2,-6,60:102
-1,-6,60:98.3
0,-6,60:102
1,-6,60:98.2
2,-6,60:102
3,-6,60:98.3
4,-6,60:102
5,-6,60:98.0
6,-6,60:98.1
7,-6,60:4
-7,-5,60:48
-6,-5,60:98.0
-5,-5,60:4
-4,-5,60:1
-3,-5,60:1
-2,-5,60:1
-1,-5,60:1
0,-5,60:1
1,-5,60:4
2,-5,60:4
3,-5,60:65.3
4,-5,60:1
5,-5,60:1
6,-5,60:98.1
7,-5,60:4
-7,-4,60:48
-6,-4,60:102
-5,-4,60:4
-4,-4,60:4
-3,-4,60:4
-2,-4,60:4
-1,-4,60:4
0,-4,60:1
1,-4,60:4
5,-4,60:4
6,-4,60:102
7,-4,60:4
-7,-3,60:48
-6,-3,60:98.0
-5,-3,60:4
-4,-3,60:4
-3,-3,60:4
-2,-3,60:1
-1,-3,60:1
0,-3,60:4
1,-3,60:1
5,-3,60:1
6,-3,60:98.2
7,-3,60:4
-7,-2,60:4
-6,-2,60:102
-5,-2,60:1
-4,-2,60:1
-3,-2,60:4
-2,-2,60:1
-1,-2,60:4
0,-2,60:4
4,-2,60:1
5,-2,60:1
6,-2,60:102
7,-2,60:48
-7,-1,60:48
-6,-1,60:98.2
-5,-1,60:4
-4,-1,60:1
-3,-1,60:4
-2,-1,60:4
-1,-1,60:4
0,-1,60:4
2,-1,60:1
3,-1,60:1
4,-1,60:1
5,-1,60:1
6,-1,60:98.3
7,-1,60:48
-7,0,60:48
-6,0,60:102
-5,0,60:1
-4,0,60:4
-3,0,60:4
-2,0,60:4
-1,0,60:4
0,0,60:1
1,0,60:1
2,0,60:1
3,0,60:1
4,0,60:1
5,0,60:1
6,0,60:102
7,0,60:4
-7,1,60:48
-6,1,60:98.0
-5,1,60:1
-4,1,60:4
-3,1,60:4
-2,1,60:4
-1,1,60:4
0,1,60:1
1,1,60:4
2,1,60:4
3,1,60:1
4,1,60:1
5,1,60:1
6,1,60:98.0
7,1,60:48
-7,2,60:4
-6,2,60:102
-5,2,60:4
-4,2,60:4
-3,2,60:4
-2,2,60:1
-1,2,60:1
0,2,60:1
1,2,60:4
2,2,60:1
3,2,60:1
4,2,60:4
5,2,60:1
6,2,60:102
7,2,60:4
-7,3,60:4
-6,3,60:98.2
-5,3,60:1
-4,3,60:4
-3,3,60:1
-2,3,60:4
-1,3,60:1
0,3,60:4
1,3,60:1
2,3,60:1
3,3,60:1
4,3,60:4
5,3,60:1
6,3,60:98.0
7,3,60:48
-7,4,60:48
-6,4,60:102
-5,4,60:1
-4,4,60:1
-3,4,60:1
-2,4,60:4
-1,4,60:1
0,4,60:4
1,4,60:1
2,4,60:4
3,4,60:1
4,4,60:4
5,4,60:4
6,4,60:102
7,4,60:4
-7,5,60:48
-6,5,60:98.2
-5,5,60:1
-4,5,60:4
-3,5,60:4
-2,5,60:1
-1,5,60:4
0,5,60:1
1,5,60:4
2,5,60:4
3,5,60:1
4,5,60:4
5,5,60:1
6,5,60:98.0
7,5,60:48
-7,6,60:48
-6,6,60:98.0
-5,6,60:98.1
-4,6,60:102
-3,6,60:98.2
-2,6,60:102
-1,6,60:98.2
0,6,60:102
1,6,60:98.1
2,6,60:102
3,6,60:98.2
4,6,60:102
5,6,60:98.2
6,6,60:98.0
7,6,60:48
-7,7,60:48
-6,7,60:4
-5,7,60:4
-4,7,60:4
-3,7,60:4
-2,7,60:48
-1,7,60:4
0,7,60:4
1,7,60:4
2,7,60:48
3,7,60:48
4,7,60:48
5,7,60:4
6,7,60:4
7,7,60:48
