[META]
version=2.0
spawnOnBlockType=13
spawnSunlight=True
spawnDarkness=False
spawnWater=False
spawnLava=False
underFill=True
randomRotation=True
dig=True
tree=False
branch=False
needsFoundation=True
rarity=2
collisionPercentage=2
spawnElevationMin=0
spawnElevationMax=128
spawnInBiome=Flat
[DATA]
-7,-8,0:98.1
-6,-8,0:4
-5,-8,0:4
-4,-8,0:4
-3,-8,0:4
-2,-8,0:4
-1,-8,0:4
0,-8,0:4
1,-8,0:4
2,-8,0:4
3,-8,0:4
4,-8,0:4
5,-8,0:4
6,-8,0:4
7,-8,0:98.3
-7,-7,0:98.1
-6,-7,0:4
1,-7,0:98.0
2,-7,0:98.0
3,-7,0:98.1
7,-7,0:4
8,-7,0:98.3
-7,-6,0:98.2
-6,-6,0:4
1,-6,0:98.1
2,-6,0:98.0
3,-6,0:98.1
8,-6,0:4
-7,-5,0:98.3
-6,-5,0:4
-5,-5,0:44.5
1,-5,0:98.0
2,-5,0:98.3
3,-5,0:98.2
8,-5,0:4
-7,-4,0:98.3
-6,-4,0:4
-5,-4,0:44.5
1,-4,0:98.3
2,-4,0:98.1
3,-4,0:98.1
8,-4,0:4
-7,-3,0:98.1
-6,-3,0:4
-5,-3,0:44.5
8,-3,0:4
-7,-2,0:98.3
-6,-2,0:98.0
-5,-2,0:44.5
8,-2,0:4
-7,-1,0:98.1
-6,-1,0:4
-5,-1,0:44.5
8,-1,0:4
-7,0,0:98.1
-6,0,0:4
-5,0,0:44.5
1,0,0:98.3
2,0,0:98.3
3,0,0:98.0
8,0,0:4
-7,1,0:98.0
-6,1,0:4
-5,1,0:44.5
1,1,0:98.3
2,1,0:98.0
3,1,0:98.0
8,1,0:4
-7,2,0:98.2
-6,2,0:4
1,2,0:98.2
2,2,0:98.0
3,2,0:98.0
8,2,0:4
-7,3,0:98.3
-6,3,0:4
1,3,0:98.3
2,3,0:98.1
3,3,0:98.0
7,3,0:4
8,3,0:98.3
-7,4,0:98.2
-6,4,0:4
-5,4,0:4
-4,4,0:4
-3,4,0:4
-2,4,0:4
-1,4,0:4
0,4,0:4
1,4,0:4
2,4,0:4
3,4,0:4
4,4,0:4
5,4,0:4
6,4,0:4
7,4,0:98.0
-7,5,0:98.3
-6,5,0:98.2
-5,5,0:98.0
-4,5,0:98.0
-3,5,0:98.0
-2,5,0:98.1
-1,5,0:98.3
0,5,0:98.2
1,5,0:98.3
2,5,0:98.0
3,5,0:98.0
4,5,0:98.1
5,5,0:98.3
6,5,0:98.1
-6,-8,1:4
-5,-8,1:102
-4,-8,1:4
-3,-8,1:4
-2,-8,1:4
-1,-8,1:102
0,-8,1:102
1,-8,1:4
2,-8,1:4
3,-8,1:4
4,-8,1:102
5,-8,1:4
7,-8,1:20
-6,-7,1:102
1,-7,1:98.3
2,-7,1:98.1
3,-7,1:98.1
8,-7,1:20
-6,-6,1:4
1,-6,1:98.1
2,-6,1:98.3
3,-6,1:98.0
-7,-5,1:98.0
-6,-5,1:1
1,-5,1:98.0
2,-5,1:98.0
3,-5,1:98.0
8,-5,1:4
8,-4,1:102
8,-3,1:102
8,-2,1:102
8,-1,1:102
8,0,1:102
-7,1,1:98.0
-6,1,1:48
1,1,1:98.3
2,1,1:98.2
3,1,1:98.0
8,1,1:4
-6,2,1:4
1,2,1:98.0
2,2,1:98.1
3,2,1:98.1
-6,3,1:102
1,3,1:98.2
2,3,1:98.1
3,3,1:98.1
8,3,1:20
-6,4,1:4
-5,4,1:102
-4,4,1:4
-3,4,1:4
-2,4,1:4
-1,4,1:102
0,4,1:102
1,4,1:4
2,4,1:4
3,4,1:4
4,4,1:102
5,4,1:4
7,4,1:20
-7,5,1:1
-3,5,1:1
2,5,1:4
6,5,1:4
-6,-8,2:4
-5,-8,2:102
-4,-8,2:4
-3,-8,2:4
-2,-8,2:4
-1,-8,2:102
0,-8,2:102
1,-8,2:4
2,-8,2:4
3,-8,2:4
4,-8,2:102
5,-8,2:4
7,-8,2:20
-6,-7,2:102
1,-7,2:98.1
2,-7,2:98.2
3,-7,2:98.3
8,-7,2:20
-6,-6,2:4
1,-6,2:98.2
2,-6,2:98.1
3,-6,2:98.2
-7,-5,2:98.0
-6,-5,2:1
8,-5,2:4
8,-4,2:102
8,-3,2:102
8,-2,2:102
8,-1,2:102
8,0,2:102
-7,1,2:98.0
-6,1,2:1
8,1,2:4
-6,2,2:4
1,2,2:98.0
2,2,2:98.2
3,2,2:98.0
-6,3,2:102
1,3,2:98.0
2,3,2:98.0
3,3,2:98.3
8,3,2:20
-6,4,2:4
-5,4,2:102
-4,4,2:4
-3,4,2:4
-2,4,2:4
-1,4,2:102
0,4,2:102
1,4,2:4
2,4,2:4
3,4,2:4
4,4,2:102
5,4,2:4
7,4,2:20
-7,5,2:1
-3,5,2:1
2,5,2:1
6,5,2:48
-6,-8,3:4
-5,-8,3:102
-4,-8,3:4
-3,-8,3:4
-2,-8,3:4
-1,-8,3:102
0,-8,3:102
1,-8,3:4
2,-8,3:4
3,-8,3:4
4,-8,3:102
5,-8,3:4
7,-8,3:20
-6,-7,3:102
1,-7,3:98.3
2,-7,3:98.2
3,-7,3:98.0
8,-7,3:20
-6,-6,3:4
-7,-5,3:98.0
-6,-5,3:48
8,-5,3:4
8,-4,3:102
8,-3,3:102
8,-2,3:102
8,-1,3:102
8,0,3:102
-7,1,3:98.0
-6,1,3:4
8,1,3:4
-6,2,3:4
-6,3,3:102
1,3,3:98.2
2,3,3:98.0
3,3,3:98.0
8,3,3:20
-6,4,3:4
-5,4,3:102
-4,4,3:4
-3,4,3:4
-2,4,3:4
-1,4,3:102
0,4,3:102
1,4,3:4
2,4,3:4
3,4,3:4
4,4,3:102
5,4,3:4
7,4,3:20
-7,5,3:1
-3,5,3:1
2,5,3:4
6,5,3:4
-7,-8,4:98.3
-6,-8,4:98.3
-5,-8,4:98.1
-4,-8,4:98.1
-3,-8,4:98.0
-2,-8,4:98.1
-1,-8,4:98.2
0,-8,4:98.1
1,-8,4:98.3
2,-8,4:98.2
3,-8,4:98.3
4,-8,4:98.3
5,-8,4:98.2
6,-8,4:98.3
7,-8,4:98.2
8,-8,4:98.0
-7,-7,4:98.0
-6,-7,4:98.1
-5,-7,4:98.2
-4,-7,4:98.1
-3,-7,4:98.3
-2,-7,4:98.0
-1,-7,4:98.0
0,-7,4:98.3
4,-7,4:98.3
5,-7,4:98.2
6,-7,4:98.2
7,-7,4:98.1
8,-7,4:98.3
-7,-6,4:98.0
-6,-6,4:98.3
-5,-6,4:98.2
-4,-6,4:98.2
-3,-6,4:98.2
-2,-6,4:98.0
-1,-6,4:98.1
0,-6,4:98.3
4,-6,4:98.2
5,-6,4:98.0
6,-6,4:98.0
7,-6,4:98.1
8,-6,4:98.1
-7,-5,4:98.3
-6,-5,4:98.0
-5,-5,4:98.1
-4,-5,4:98.0
-3,-5,4:98.0
-2,-5,4:98.3
-1,-5,4:98.1
0,-5,4:98.0
4,-5,4:98.3
5,-5,4:98.0
6,-5,4:98.3
7,-5,4:98.0
8,-5,4:98.3
-7,-4,4:98.2
-6,-4,4:98.3
-5,-4,4:98.3
-4,-4,4:98.1
-3,-4,4:98.2
-2,-4,4:98.3
-1,-4,4:98.0
0,-4,4:98.0
1,-4,4:98.0
2,-4,4:98.1
3,-4,4:98.1
4,-4,4:98.2
5,-4,4:98.3
6,-4,4:98.2
7,-4,4:98.0
8,-4,4:98.1
-7,-3,4:98.2
-6,-3,4:98.2
-5,-3,4:98.1
-4,-3,4:98.2
-3,-3,4:98.3
-2,-3,4:98.3
-1,-3,4:98.0
0,-3,4:98.0
1,-3,4:98.2
2,-3,4:98.3
3,-3,4:98.0
4,-3,4:98.0
5,-3,4:98.0
6,-3,4:98.0
7,-3,4:98.1
8,-3,4:98.2
-7,-2,4:98.0
-6,-2,4:98.1
-5,-2,4:98.3
-4,-2,4:98.1
-3,-2,4:98.0
-2,-2,4:98.2
-1,-2,4:98.1
0,-2,4:98.2
1,-2,4:98.0
2,-2,4:98.2
3,-2,4:98.3
4,-2,4:98.3
5,-2,4:98.0
6,-2,4:98.1
7,-2,4:98.3
8,-2,4:98.3
-7,-1,4:98.0
-6,-1,4:98.3
-5,-1,4:98.0
-4,-1,4:98.2
-3,-1,4:98.1
-2,-1,4:98.0
-1,-1,4:98.1
0,-1,4:98.2
1,-1,4:98.2
2,-1,4:98.2
3,-1,4:98.3
4,-1,4:98.0
5,-1,4:98.1
6,-1,4:98.1
7,-1,4:98.3
8,-1,4:98.3
-7,0,4:98.1
-6,0,4:98.0
-5,0,4:98.1
-4,0,4:98.0
-3,0,4:98.2
-2,0,4:98.1
-1,0,4:98.3
0,0,4:98.0
1,0,4:98.2
2,0,4:98.2
3,0,4:98.3
4,0,4:98.1
5,0,4:98.3
6,0,4:98.0
7,0,4:98.1
8,0,4:98.3
-7,1,4:98.3
-6,1,4:98.3
-5,1,4:98.3
-4,1,4:98.1
-3,1,4:98.1
-2,1,4:98.3
-1,1,4:98.3
0,1,4:98.3
4,1,4:98.0
5,1,4:98.2
6,1,4:98.2
7,1,4:98.0
8,1,4:98.1
-7,2,4:98.3
-6,2,4:98.0
-5,2,4:98.2
-4,2,4:98.2
-3,2,4:98.3
-2,2,4:98.2
-1,2,4:98.1
0,2,4:98.3
4,2,4:98.3
5,2,4:98.2
6,2,4:98.1
7,2,4:98.2
8,2,4:98.0
-7,3,4:98.0
-6,3,4:98.0
-5,3,4:98.3
-4,3,4:98.0
-3,3,4:98.3
-2,3,4:98.0
-1,3,4:98.3
0,3,4:98.2
4,3,4:98.2
5,3,4:98.0
6,3,4:98.2
7,3,4:98.1
8,3,4:98.3
-7,4,4:98.1
-6,4,4:98.3
-5,4,4:98.3
-4,4,4:98.2
-3,4,4:98.0
-2,4,4:98.3
-1,4,4:98.2
0,4,4:98.0
1,4,4:98.2
2,4,4:98.0
3,4,4:98.2
4,4,4:98.3
5,4,4:98.2
6,4,4:98.1
7,4,4:98.3
8,4,4:98.0
-7,5,4:98.0
-6,5,4:98.3
-5,5,4:98.1
-4,5,4:98.3
-3,5,4:98.1
-2,5,4:98.1
-1,5,4:98.0
0,5,4:98.1
1,5,4:98.2
2,5,4:98.3
3,5,4:98.0
4,5,4:98.3
5,5,4:98.3
6,5,4:98.1
7,5,4:98.0
-7,-8,5:98.0
-6,-8,5:4
-5,-8,5:4
-4,-8,5:4
-3,-8,5:4
-2,-8,5:4
-1,-8,5:4
0,-8,5:4
1,-8,5:4
2,-8,5:4
3,-8,5:4
4,-8,5:4
5,-8,5:4
6,-8,5:4
7,-8,5:98.3
-7,-7,5:98.0
-6,-7,5:4
-4,-7,5:68.2
-3,-7,5:18
-2,-7,5:98.2
7,-7,5:4
8,-7,5:98.0
-7,-6,5:98.3
-6,-6,5:4
-4,-6,5:109.1
-3,-6,5:48
-2,-6,5:98.3
8,-6,5:4
-7,-5,5:98.2
-6,-5,5:4
-4,-5,5:68.3
-3,-5,5:1
-2,-5,5:98.3
8,-5,5:4
-7,-4,5:98.3
-6,-4,5:4
-3,-4,5:47
-2,-4,5:98.2
8,-4,5:4
-7,-3,5:98.2
-6,-3,5:4
-2,-3,5:98.3
3,-3,5:98.2
4,-3,5:98.1
5,-3,5:98.1
6,-3,5:98.3
8,-3,5:4
-7,-2,5:98.1
-6,-2,5:4
-2,-2,5:64.6
3,-2,5:98.2
4,-2,5:98.0
5,-2,5:98.3
6,-2,5:98.1
8,-2,5:4
-7,-1,5:98.3
-6,-1,5:4
-2,-1,5:98.3
3,-1,5:98.1
4,-1,5:98.0
5,-1,5:98.1
6,-1,5:98.0
8,-1,5:4
-7,0,5:98.3
-6,0,5:4
-3,0,5:118.0
-2,0,5:98.3
8,0,5:4
-7,1,5:98.1
-6,1,5:4
-4,1,5:68.2
-3,1,5:48
-2,1,5:98.3
8,1,5:4
-7,2,5:98.3
-6,2,5:4
-4,2,5:109.1
-3,2,5:1
-2,2,5:98.2
8,2,5:4
-7,3,5:98.3
-6,3,5:4
-4,3,5:68.3
-3,3,5:18
-2,3,5:98.0
7,3,5:4
8,3,5:98.0
-7,4,5:98.0
-6,4,5:4
-5,4,5:4
-4,4,5:4
-3,4,5:4
-2,4,5:4
-1,4,5:4
0,4,5:4
1,4,5:4
2,4,5:4
3,4,5:4
4,4,5:4
5,4,5:4
6,4,5:4
7,4,5:98.0
-7,5,5:98.3
-6,5,5:98.2
-5,5,5:98.2
-4,5,5:98.2
-3,5,5:98.1
-2,5,5:98.2
-1,5,5:98.2
0,5,5:98.1
1,5,5:98.3
2,5,5:98.0
3,5,5:98.2
4,5,5:98.1
5,5,5:98.1
6,5,5:98.2
-6,-8,6:4
-5,-8,6:102
-4,-8,6:4
-3,-8,6:4
-2,-8,6:4
-1,-8,6:102
0,-8,6:102
1,-8,6:4
2,-8,6:4
3,-8,6:4
4,-8,6:102
5,-8,6:4
7,-8,6:20
-6,-7,6:102
-3,-7,6:18
-2,-7,6:98.1
8,-7,6:20
-6,-6,6:4
-2,-6,6:102
-6,-5,6:4
-2,-5,6:102
8,-5,6:4
-7,-4,6:1
-6,-4,6:48
-3,-4,6:47
-2,-4,6:98.1
8,-4,6:102
-6,-3,6:102
-2,-3,6:98.2
4,-3,6:98.0
5,-3,6:98.0
6,-3,6:98.2
8,-3,6:102
-6,-2,6:102
-2,-2,6:64.8
4,-2,6:98.3
5,-2,6:98.3
6,-2,6:98.2
8,-2,6:102
-6,-1,6:102
-2,-1,6:98.2
4,-1,6:98.0
5,-1,6:98.3
6,-1,6:98.2
8,-1,6:102
-7,0,6:48
-6,0,6:1
-2,0,6:98.1
8,0,6:102
-6,1,6:1
-2,1,6:102
8,1,6:4
-6,2,6:4
-2,2,6:102
-6,3,6:102
-3,3,6:18
-2,3,6:98.1
8,3,6:20
-6,4,6:4
-5,4,6:102
-4,4,6:4
-3,4,6:4
-2,4,6:4
-1,4,6:102
0,4,6:102
1,4,6:4
2,4,6:4
3,4,6:4
4,4,6:102
5,4,6:4
7,4,6:20
-7,5,6:4
-3,5,6:48
2,5,6:4
6,5,6:1
-6,-8,7:4
-5,-8,7:102
-4,-8,7:4
-3,-8,7:4
-2,-8,7:4
-1,-8,7:102
0,-8,7:102
1,-8,7:4
2,-8,7:4
3,-8,7:4
4,-8,7:102
5,-8,7:4
7,-8,7:20
-6,-7,7:102
-3,-7,7:18
-2,-7,7:98.3
8,-7,7:20
-6,-6,7:4
-2,-6,7:98.3
-6,-5,7:48
-2,-5,7:98.0
8,-5,7:4
-7,-4,7:48
-6,-4,7:4
-2,-4,7:98.0
8,-4,7:102
-6,-3,7:102
-2,-3,7:98.2
5,-3,7:98.1
6,-3,7:98.3
8,-3,7:102
-6,-2,7:102
-2,-2,7:98.3
5,-2,7:98.3
6,-2,7:98.0
8,-2,7:102
-6,-1,7:102
-2,-1,7:98.2
5,-1,7:98.0
6,-1,7:98.2
8,-1,7:102
-7,0,7:48
-6,0,7:48
-2,0,7:98.3
8,0,7:102
-6,1,7:1
-2,1,7:98.1
8,1,7:4
-6,2,7:4
-2,2,7:98.0
-6,3,7:102
-3,3,7:18
-2,3,7:98.3
8,3,7:20
-6,4,7:4
-5,4,7:102
-4,4,7:4
-3,4,7:4
-2,4,7:4
-1,4,7:102
0,4,7:102
1,4,7:4
2,4,7:4
3,4,7:4
4,4,7:102
5,4,7:4
7,4,7:20
-7,5,7:48
-3,5,7:48
2,5,7:1
6,5,7:4
-6,-8,8:4
-5,-8,8:102
-4,-8,8:4
-3,-8,8:4
-2,-8,8:4
-1,-8,8:102
0,-8,8:102
1,-8,8:4
2,-8,8:4
3,-8,8:4
4,-8,8:102
5,-8,8:4
7,-8,8:20
-6,-7,8:102
-2,-7,8:98.3
8,-7,8:20
-6,-6,8:4
-2,-6,8:98.1
-6,-5,8:48
-2,-5,8:98.3
8,-5,8:4
-7,-4,8:48
-6,-4,8:1
-2,-4,8:98.1
8,-4,8:102
-6,-3,8:102
-2,-3,8:98.2
6,-3,8:98.3
8,-3,8:102
-6,-2,8:102
-2,-2,8:98.1
6,-2,8:98.2
8,-2,8:102
-6,-1,8:102
-2,-1,8:98.0
6,-1,8:98.3
8,-1,8:102
-7,0,8:4
-6,0,8:48
-2,0,8:98.0
8,0,8:102
-6,1,8:1
-2,1,8:98.0
8,1,8:4
-6,2,8:4
-2,2,8:98.0
-6,3,8:102
-2,3,8:98.1
8,3,8:20
-6,4,8:4
-5,4,8:102
-4,4,8:4
-3,4,8:4
-2,4,8:4
-1,4,8:102
0,4,8:102
1,4,8:4
2,4,8:4
3,4,8:4
4,4,8:102
5,4,8:4
7,4,8:20
-7,5,8:4
-3,5,8:4
2,5,8:4
6,5,8:48
-7,-8,9:98.1
-6,-8,9:98.0
-5,-8,9:98.2
-4,-8,9:98.3
-3,-8,9:98.3
-2,-8,9:98.0
-1,-8,9:98.3
0,-8,9:98.3
1,-8,9:98.0
2,-8,9:98.0
3,-8,9:98.2
4,-8,9:98.2
5,-8,9:98.2
6,-8,9:98.3
7,-8,9:98.1
8,-8,9:98.3
-7,-7,9:98.3
-6,-7,9:98.3
-5,-7,9:98.3
-4,-7,9:98.3
-3,-7,9:98.1
-2,-7,9:98.3
-1,-7,9:98.0
0,-7,9:98.0
1,-7,9:98.3
2,-7,9:98.2
3,-7,9:98.2
4,-7,9:98.2
5,-7,9:98.1
6,-7,9:98.0
7,-7,9:98.1
8,-7,9:98.1
-7,-6,9:98.0
-6,-6,9:98.1
-5,-6,9:98.0
-4,-6,9:98.2
-3,-6,9:98.3
-2,-6,9:98.3
-1,-6,9:98.3
0,-6,9:98.2
1,-6,9:98.3
2,-6,9:98.2
3,-6,9:98.1
4,-6,9:98.2
5,-6,9:98.3
6,-6,9:98.1
7,-6,9:98.3
8,-6,9:98.3
-7,-5,9:98.0
-6,-5,9:98.2
-5,-5,9:98.0
-4,-5,9:98.2
-3,-5,9:98.2
-2,-5,9:98.3
-1,-5,9:98.0
0,-5,9:98.2
1,-5,9:98.2
2,-5,9:98.0
3,-5,9:98.0
4,-5,9:98.1
5,-5,9:98.3
6,-5,9:98.2
7,-5,9:98.0
8,-5,9:98.1
-7,-4,9:98.1
-6,-4,9:98.2
-5,-4,9:98.0
-4,-4,9:98.3
-3,-4,9:98.0
-2,-4,9:98.2
-1,-4,9:98.3
0,-4,9:98.0
1,-4,9:98.3
2,-4,9:98.1
3,-4,9:98.3
4,-4,9:98.0
5,-4,9:98.1
6,-4,9:98.1
7,-4,9:98.1
8,-4,9:98.3
-7,-3,9:98.0
-6,-3,9:98.0
-5,-3,9:98.1
-4,-3,9:98.1
-3,-3,9:98.3
-2,-3,9:98.0
-1,-3,9:98.2
0,-3,9:98.3
1,-3,9:98.3
2,-3,9:98.0
3,-3,9:98.1
7,-3,9:98.3
8,-3,9:98.3
-7,-2,9:98.1
-6,-2,9:98.0
-5,-2,9:98.3
-4,-2,9:98.3
-3,-2,9:98.2
-2,-2,9:98.1
-1,-2,9:98.2
0,-2,9:98.3
1,-2,9:98.0
2,-2,9:98.0
3,-2,9:98.2
7,-2,9:98.1
8,-2,9:98.1
-7,-1,9:98.3
-6,-1,9:98.2
-5,-1,9:98.1
-4,-1,9:98.0
-3,-1,9:98.2
-2,-1,9:98.2
-1,-1,9:98.0
0,-1,9:98.2
1,-1,9:98.0
2,-1,9:98.0
3,-1,9:98.1
7,-1,9:98.3
8,-1,9:98.0
-7,0,9:98.3
-6,0,9:98.0
-5,0,9:98.0
-4,0,9:98.3
-3,0,9:98.2
-2,0,9:98.2
-1,0,9:98.0
0,0,9:98.1
1,0,9:98.1
2,0,9:98.0
3,0,9:98.2
4,0,9:98.1
5,0,9:98.1
6,0,9:98.1
7,0,9:98.1
8,0,9:98.1
-7,1,9:98.0
-6,1,9:98.0
-5,1,9:98.1
-4,1,9:98.0
-3,1,9:98.1
-2,1,9:98.3
-1,1,9:98.3
0,1,9:98.2
1,1,9:98.1
2,1,9:98.1
3,1,9:98.3
4,1,9:98.2
5,1,9:98.3
6,1,9:98.0
7,1,9:98.1
8,1,9:98.3
-7,2,9:98.1
-6,2,9:98.1
-5,2,9:98.1
-4,2,9:98.2
-3,2,9:98.1
-2,2,9:98.1
-1,2,9:98.0
0,2,9:98.3
1,2,9:98.1
2,2,9:98.1
3,2,9:98.0
4,2,9:98.0
5,2,9:98.1
6,2,9:98.0
7,2,9:98.2
8,2,9:98.2
-7,3,9:98.1
-6,3,9:98.2
-5,3,9:98.0
-4,3,9:98.0
-3,3,9:98.3
-2,3,9:98.0
-1,3,9:98.3
0,3,9:98.3
1,3,9:98.1
2,3,9:98.1
3,3,9:98.0
4,3,9:98.0
5,3,9:98.1
6,3,9:98.0
7,3,9:98.1
8,3,9:98.3
-7,4,9:98.0
-6,4,9:98.1
-5,4,9:98.0
-4,4,9:98.3
-3,4,9:98.2
-2,4,9:98.1
-1,4,9:98.3
0,4,9:98.1
1,4,9:98.1
2,4,9:98.0
3,4,9:98.3
4,4,9:98.3
5,4,9:98.1
6,4,9:98.0
7,4,9:98.0
8,4,9:98.2
-7,5,9:98.1
-6,5,9:98.1
-5,5,9:98.0
-4,5,9:98.3
-3,5,9:98.1
-2,5,9:98.1
-1,5,9:98.0
0,5,9:98.1
1,5,9:98.0
2,5,9:98.2
3,5,9:98.0
4,5,9:98.2
5,5,9:98.0
6,5,9:98.3
7,5,9:98.0
-7,-8,10:98.1
-6,-8,10:4
-5,-8,10:4
-4,-8,10:4
-3,-8,10:4
-2,-8,10:4
-1,-8,10:4
0,-8,10:4
1,-8,10:4
2,-8,10:4
3,-8,10:4
4,-8,10:4
5,-8,10:4
6,-8,10:4
7,-8,10:98.3
-7,-7,10:98.3
-6,-7,10:4
1,-7,10:98.0
2,-7,10:98.3
3,-7,10:98.2
7,-7,10:4
8,-7,10:98.3
-7,-6,10:98.1
-6,-6,10:4
1,-6,10:98.2
2,-6,10:98.2
3,-6,10:98.3
8,-6,10:4
-7,-5,10:98.3
-6,-5,10:4
1,-5,10:98.3
2,-5,10:98.2
3,-5,10:98.1
8,-5,10:4
-7,-4,10:98.1
-6,-4,10:4
1,-4,10:98.0
2,-4,10:98.2
3,-4,10:98.1
8,-4,10:4
-7,-3,10:98.2
-6,-3,10:4
8,-3,10:4
-7,-2,10:98.3
-6,-2,10:4
8,-2,10:4
-7,-1,10:98.1
-6,-1,10:4
8,-1,10:4
-7,0,10:98.2
-6,0,10:4
1,0,10:98.3
2,0,10:98.3
3,0,10:98.1
8,0,10:4
-7,1,10:98.3
-6,1,10:4
1,1,10:98.0
2,1,10:98.3
3,1,10:98.1
8,1,10:4
-7,2,10:98.2
-6,2,10:4
1,2,10:98.2
2,2,10:98.0
3,2,10:98.3
8,2,10:4
-7,3,10:98.1
-6,3,10:4
1,3,10:98.0
2,3,10:98.3
3,3,10:98.1
7,3,10:4
8,3,10:98.3
-7,4,10:98.2
-6,4,10:4
-5,4,10:4
-4,4,10:4
-3,4,10:4
-2,4,10:4
-1,4,10:4
0,4,10:4
1,4,10:4
2,4,10:4
3,4,10:4
4,4,10:4
5,4,10:4
6,4,10:4
7,4,10:98.1
-7,5,10:98.0
-6,5,10:98.3
-5,5,10:98.2
-4,5,10:98.2
-3,5,10:98.3
-2,5,10:98.0
-1,5,10:98.3
0,5,10:98.1
1,5,10:98.1
2,5,10:98.2
3,5,10:98.3
4,5,10:98.0
5,5,10:98.1
6,5,10:98.1
-6,-8,11:4
-5,-8,11:102
-4,-8,11:4
-3,-8,11:4
-2,-8,11:4
-1,-8,11:102
0,-8,11:102
1,-8,11:4
2,-8,11:4
3,-8,11:4
4,-8,11:102
5,-8,11:4
7,-8,11:20
-6,-7,11:102
1,-7,11:98.2
2,-7,11:98.0
3,-7,11:98.0
8,-7,11:20
-6,-6,11:4
1,-6,11:98.0
2,-6,11:98.2
3,-6,11:98.1
-6,-5,11:4
1,-5,11:98.0
2,-5,11:98.1
3,-5,11:98.2
8,-5,11:4
-7,-4,11:48
-6,-4,11:48
8,-4,11:102
-6,-3,11:102
8,-3,11:102
-6,-2,11:102
8,-2,11:102
-6,-1,11:102
8,-1,11:102
-7,0,11:4
-6,0,11:48
8,0,11:102
-6,1,11:4
1,1,11:98.0
2,1,11:98.0
3,1,11:98.1
8,1,11:4
-6,2,11:4
1,2,11:98.0
2,2,11:98.0
3,2,11:98.0
-6,3,11:102
1,3,11:98.3
2,3,11:98.1
3,3,11:98.1
8,3,11:20
-6,4,11:4
-5,4,11:102
-4,4,11:4
-3,4,11:4
-2,4,11:4
-1,4,11:102
0,4,11:102
1,4,11:4
2,4,11:4
3,4,11:4
4,4,11:102
5,4,11:4
7,4,11:20
-7,5,11:4
-3,5,11:1
2,5,11:48
6,5,11:48
-6,-8,12:4
-5,-8,12:102
-4,-8,12:4
-3,-8,12:4
-2,-8,12:4
-1,-8,12:102
0,-8,12:102
1,-8,12:4
2,-8,12:4
3,-8,12:4
4,-8,12:102
5,-8,12:4
7,-8,12:20
-6,-7,12:102
1,-7,12:98.1
2,-7,12:98.2
3,-7,12:98.3
8,-7,12:20
-6,-6,12:4
1,-6,12:98.3
2,-6,12:98.3
3,-6,12:98.1
-6,-5,12:48
8,-5,12:4
-7,-4,12:48
-6,-4,12:48
8,-4,12:102
-6,-3,12:102
8,-3,12:102
-6,-2,12:102
8,-2,12:102
-6,-1,12:102
8,-1,12:102
-7,0,12:48
-6,0,12:48
8,0,12:102
-6,1,12:4
8,1,12:4
-6,2,12:4
1,2,12:98.1
2,2,12:98.3
3,2,12:98.0
-6,3,12:102
1,3,12:98.2
2,3,12:98.2
3,3,12:98.1
8,3,12:20
-6,4,12:4
-5,4,12:102
-4,4,12:4
-3,4,12:4
-2,4,12:4
-1,4,12:102
0,4,12:102
1,4,12:4
2,4,12:4
3,4,12:4
4,4,12:102
5,4,12:4
7,4,12:20
-7,5,12:48
-3,5,12:1
2,5,12:48
6,5,12:1
-6,-8,13:4
-5,-8,13:102
-4,-8,13:4
-3,-8,13:4
-2,-8,13:4
-1,-8,13:102
0,-8,13:102
1,-8,13:4
2,-8,13:4
3,-8,13:4
4,-8,13:102
5,-8,13:4
7,-8,13:20
-6,-7,13:102
1,-7,13:98.3
2,-7,13:98.1
3,-7,13:98.2
8,-7,13:20
-6,-6,13:4
-6,-5,13:48
8,-5,13:4
-7,-4,13:4
-6,-4,13:48
8,-4,13:102
-6,-3,13:102
8,-3,13:102
-6,-2,13:102
8,-2,13:102
-6,-1,13:102
8,-1,13:102
-7,0,13:4
-6,0,13:1
8,0,13:102
-6,1,13:1
8,1,13:4
-6,2,13:4
-6,3,13:102
1,3,13:98.0
2,3,13:98.2
3,3,13:98.1
8,3,13:20
-6,4,13:4
-5,4,13:102
-4,4,13:4
-3,4,13:4
-2,4,13:4
-1,4,13:102
0,4,13:102
1,4,13:4
2,4,13:4
3,4,13:4
4,4,13:102
5,4,13:4
7,4,13:20
-7,5,13:48
-3,5,13:1
2,5,13:4
6,5,13:4
-7,-8,14:98.1
-6,-8,14:98.0
-5,-8,14:98.0
-4,-8,14:98.0
-3,-8,14:98.2
-2,-8,14:98.1
-1,-8,14:98.3
0,-8,14:98.1
1,-8,14:98.0
2,-8,14:98.2
3,-8,14:98.0
4,-8,14:98.3
5,-8,14:98.2
6,-8,14:98.3
7,-8,14:98.2
8,-8,14:98.3
-7,-7,14:98.3
-6,-7,14:98.1
-5,-7,14:98.0
-4,-7,14:98.3
-3,-7,14:98.1
-2,-7,14:98.1
-1,-7,14:98.0
0,-7,14:98.0
4,-7,14:98.2
5,-7,14:98.1
6,-7,14:98.1
7,-7,14:98.0
8,-7,14:98.1
-7,-6,14:98.1
-6,-6,14:98.3
-5,-6,14:98.2
-4,-6,14:98.1
-3,-6,14:98.1
-2,-6,14:98.0
-1,-6,14:98.2
0,-6,14:98.1
4,-6,14:98.2
5,-6,14:98.2
6,-6,14:98.2
7,-6,14:98.1
8,-6,14:98.3
-7,-5,14:98.1
-6,-5,14:98.2
-5,-5,14:98.0
-4,-5,14:98.0
-3,-5,14:98.0
-2,-5,14:98.0
-1,-5,14:98.3
0,-5,14:98.2
4,-5,14:98.0
5,-5,14:98.3
6,-5,14:98.2
7,-5,14:98.1
8,-5,14:98.0
-7,-4,14:98.2
-6,-4,14:98.3
-5,-4,14:98.3
-4,-4,14:98.1
-3,-4,14:98.0
-2,-4,14:98.2
-1,-4,14:98.3
0,-4,14:98.3
1,-4,14:98.1
2,-4,14:98.0
3,-4,14:98.1
4,-4,14:98.0
5,-4,14:98.3
6,-4,14:98.3
7,-4,14:98.3
8,-4,14:98.0
-7,-3,14:98.2
-6,-3,14:98.3
-5,-3,14:98.3
-4,-3,14:98.2
-3,-3,14:98.1
-2,-3,14:98.2
-1,-3,14:98.1
0,-3,14:98.3
1,-3,14:98.3
2,-3,14:98.2
3,-3,14:98.2
4,-3,14:98.1
5,-3,14:98.0
6,-3,14:98.1
7,-3,14:98.3
8,-3,14:98.0
-7,-2,14:98.0
-6,-2,14:98.2
-5,-2,14:98.0
-4,-2,14:98.3
-3,-2,14:98.3
-2,-2,14:98.2
-1,-2,14:98.2
0,-2,14:98.3
1,-2,14:98.3
2,-2,14:98.1
3,-2,14:98.2
4,-2,14:98.3
5,-2,14:98.0
6,-2,14:98.1
7,-2,14:98.3
8,-2,14:98.0
-7,-1,14:98.3
-6,-1,14:98.1
-5,-1,14:98.1
-4,-1,14:98.2
-3,-1,14:98.1
-2,-1,14:98.0
-1,-1,14:98.3
0,-1,14:98.3
1,-1,14:98.1
2,-1,14:98.1
3,-1,14:98.0
4,-1,14:98.2
5,-1,14:98.1
6,-1,14:98.3
7,-1,14:98.1
8,-1,14:98.1
-7,0,14:98.3
-6,0,14:98.1
-5,0,14:98.1
-4,0,14:98.2
-3,0,14:98.3
-2,0,14:98.1
-1,0,14:98.2
0,0,14:98.3
1,0,14:98.1
2,0,14:98.2
3,0,14:98.1
4,0,14:98.2
5,0,14:98.2
6,0,14:98.1
7,0,14:98.0
8,0,14:98.2
-7,1,14:98.3
-6,1,14:98.1
-5,1,14:98.0
-4,1,14:98.0
-3,1,14:98.0
-2,1,14:98.2
-1,1,14:98.3
0,1,14:98.1
4,1,14:98.0
5,1,14:98.1
6,1,14:98.3
7,1,14:98.3
8,1,14:98.0
-7,2,14:98.2
-6,2,14:98.1
-5,2,14:98.1
-4,2,14:98.1
-3,2,14:98.1
-2,2,14:98.3
-1,2,14:98.2
0,2,14:98.0
4,2,14:98.3
5,2,14:98.1
6,2,14:98.1
7,2,14:98.2
8,2,14:98.2
-7,3,14:98.3
-6,3,14:98.0
-5,3,14:98.1
-4,3,14:98.1
-3,3,14:98.2
-2,3,14:98.0
-1,3,14:98.3
0,3,14:98.3
4,3,14:98.0
5,3,14:98.1
6,3,14:98.0
7,3,14:98.1
8,3,14:98.0
-7,4,14:98.2
-6,4,14:98.0
-5,4,14:98.3
-4,4,14:98.0
-3,4,14:98.0
-2,4,14:98.2
-1,4,14:98.0
0,4,14:98.0
1,4,14:98.0
2,4,14:98.2
3,4,14:98.2
4,4,14:98.2
5,4,14:98.3
6,4,14:98.0
7,4,14:98.0
8,4,14:98.3
-7,5,14:98.3
-6,5,14:98.1
-5,5,14:98.3
-4,5,14:98.3
-3,5,14:98.1
-2,5,14:98.1
-1,5,14:98.2
0,5,14:98.2
1,5,14:98.0
2,5,14:98.3
3,5,14:98.3
4,5,14:98.0
5,5,14:98.2
6,5,14:98.3
7,5,14:98.0
-7,-8,15:98.3
-6,-8,15:4
-5,-8,15:4
-4,-8,15:4
-3,-8,15:4
-2,-8,15:4
-1,-8,15:4
0,-8,15:4
1,-8,15:4
2,-8,15:4
3,-8,15:4
4,-8,15:4
5,-8,15:4
6,-8,15:4
7,-8,15:98.3
-7,-7,15:98.2
-6,-7,15:4
-3,-7,15:18
-2,-7,15:98.0
7,-7,15:4
8,-7,15:98.2
-7,-6,15:98.3
-6,-6,15:4
-5,-6,15:68.4
-4,-6,15:53.3
-3,-6,15:43.0
-2,-6,15:98.2
8,-6,15:4
-7,-5,15:98.3
-6,-5,15:4
-3,-5,15:43.0
-2,-5,15:98.2
8,-5,15:4
-7,-4,15:98.0
-6,-4,15:4
-5,-4,15:107.6
-4,-4,15:43.0
-3,-4,15:43.0
-2,-4,15:98.1
8,-4,15:4
-7,-3,15:98.3
-6,-3,15:4
-2,-3,15:98.1
3,-3,15:98.3
4,-3,15:98.2
5,-3,15:98.1
6,-3,15:98.1
8,-3,15:4
-7,-2,15:98.2
-6,-2,15:4
-2,-2,15:64.6
3,-2,15:98.0
4,-2,15:98.2
5,-2,15:98.3
6,-2,15:98.2
8,-2,15:4
-7,-1,15:98.1
-6,-1,15:4
-2,-1,15:98.2
3,-1,15:98.1
4,-1,15:98.1
5,-1,15:98.2
6,-1,15:98.3
8,-1,15:4
-7,0,15:98.1
-6,0,15:4
-3,0,15:47
-2,0,15:98.1
8,0,15:4
-7,1,15:98.2
-6,1,15:4
-3,1,15:116
-2,1,15:98.1
8,1,15:4
-7,2,15:98.1
-6,2,15:4
-3,2,15:116
-2,2,15:98.0
8,2,15:4
-7,3,15:98.0
-6,3,15:4
-4,3,15:47
-3,3,15:18
-2,3,15:98.2
7,3,15:4
8,3,15:98.3
-7,4,15:98.0
-6,4,15:4
-5,4,15:4
-4,4,15:4
-3,4,15:4
-2,4,15:4
-1,4,15:4
0,4,15:4
1,4,15:4
2,4,15:4
3,4,15:4
4,4,15:4
5,4,15:4
6,4,15:4
7,4,15:98.0
-7,5,15:98.2
-6,5,15:98.2
-5,5,15:98.1
-4,5,15:98.0
-3,5,15:98.2
-2,5,15:98.0
-1,5,15:98.0
0,5,15:98.3
1,5,15:98.2
2,5,15:98.1
3,5,15:98.1
4,5,15:98.1
5,5,15:98.2
6,5,15:98.1
-6,-8,16:4
-5,-8,16:102
-4,-8,16:4
-3,-8,16:4
-2,-8,16:4
-1,-8,16:102
0,-8,16:102
1,-8,16:4
2,-8,16:4
3,-8,16:4
4,-8,16:102
5,-8,16:4
7,-8,16:20
-6,-7,16:102
-3,-7,16:18
-2,-7,16:98.0
8,-7,16:20
-6,-6,16:4
-2,-6,16:102
-6,-5,16:1
-2,-5,16:102
8,-5,16:4
-7,-4,16:4
-6,-4,16:4
-4,-4,16:109.3
-2,-4,16:98.3
8,-4,16:102
-6,-3,16:102
-2,-3,16:98.3
4,-3,16:98.0
5,-3,16:98.1
6,-3,16:98.1
8,-3,16:102
-6,-2,16:102
-2,-2,16:64.8
4,-2,16:98.2
5,-2,16:98.1
6,-2,16:98.2
8,-2,16:102
-6,-1,16:102
-2,-1,16:98.2
4,-1,16:98.3
5,-1,16:98.3
6,-1,16:98.1
8,-1,16:102
-7,0,16:1
-6,0,16:1
-3,0,16:47
-2,0,16:98.1
8,0,16:102
-6,1,16:1
-2,1,16:102
8,1,16:4
-6,2,16:4
-2,2,16:102
-6,3,16:102
-4,3,16:47
-3,3,16:18
-2,3,16:98.3
8,3,16:20
-6,4,16:4
-5,4,16:102
-4,4,16:4
-3,4,16:4
-2,4,16:4
-1,4,16:102
0,4,16:102
1,4,16:4
2,4,16:4
3,4,16:4
4,4,16:102
5,4,16:4
7,4,16:20
-7,5,16:48
-3,5,16:1
2,5,16:4
6,5,16:4
-6,-8,17:4
-5,-8,17:102
-4,-8,17:4
-3,-8,17:4
-2,-8,17:4
-1,-8,17:102
0,-8,17:102
1,-8,17:4
2,-8,17:4
3,-8,17:4
4,-8,17:102
5,-8,17:4
7,-8,17:20
-6,-7,17:102
-3,-7,17:18
-2,-7,17:98.0
8,-7,17:20
-6,-6,17:4
-2,-6,17:98.1
-6,-5,17:1
-2,-5,17:98.0
8,-5,17:4
-7,-4,17:4
-6,-4,17:4
-2,-4,17:98.3
8,-4,17:102
-6,-3,17:102
-2,-3,17:98.3
5,-3,17:98.2
6,-3,17:98.3
8,-3,17:102
-6,-2,17:102
-2,-2,17:98.3
-1,-2,17:68.5
5,-2,17:98.2
6,-2,17:98.3
8,-2,17:102
-6,-1,17:102
-2,-1,17:98.3
5,-1,17:98.0
6,-1,17:98.2
8,-1,17:102
-7,0,17:48
-6,0,17:48
-2,0,17:98.2
8,0,17:102
-6,1,17:48
-2,1,17:98.3
8,1,17:4
-6,2,17:4
-2,2,17:98.2
-6,3,17:102
-3,3,17:18
-2,3,17:98.2
8,3,17:20
-6,4,17:4
-5,4,17:102
-4,4,17:4
-3,4,17:4
-2,4,17:4
-1,4,17:102
0,4,17:102
1,4,17:4
2,4,17:4
3,4,17:4
4,4,17:102
5,4,17:4
7,4,17:20
-7,5,17:4
-3,5,17:1
2,5,17:1
6,5,17:1
-6,-8,18:4
-5,-8,18:102
-4,-8,18:4
-3,-8,18:4
-2,-8,18:4
-1,-8,18:102
0,-8,18:102
1,-8,18:4
2,-8,18:4
3,-8,18:4
4,-8,18:102
5,-8,18:4
7,-8,18:20
-6,-7,18:102
-2,-7,18:98.0
8,-7,18:20
-6,-6,18:4
-2,-6,18:98.2
-6,-5,18:1
-2,-5,18:98.3
8,-5,18:4
-7,-4,18:1
-6,-4,18:1
-2,-4,18:98.2
8,-4,18:102
-6,-3,18:102
-2,-3,18:98.3
6,-3,18:98.1
8,-3,18:102
-6,-2,18:102
-2,-2,18:98.2
6,-2,18:98.3
8,-2,18:102
-6,-1,18:102
-2,-1,18:98.1
6,-1,18:98.1
8,-1,18:102
-7,0,18:4
-6,0,18:48
-2,0,18:98.1
8,0,18:102
-6,1,18:4
-2,1,18:98.1
8,1,18:4
-6,2,18:4
-2,2,18:98.1
-6,3,18:102
-2,3,18:98.3
8,3,18:20
-6,4,18:4
-5,4,18:102
-4,4,18:4
-3,4,18:4
-2,4,18:4
-1,4,18:102
0,4,18:102
1,4,18:4
2,4,18:4
3,4,18:4
4,4,18:102
5,4,18:4
7,4,18:20
-7,5,18:1
-3,5,18:1
2,5,18:1
6,5,18:48
-7,-8,19:98.1
-6,-8,19:98.0
-5,-8,19:98.3
-4,-8,19:98.3
-3,-8,19:98.1
-2,-8,19:98.0
-1,-8,19:98.0
0,-8,19:98.2
1,-8,19:98.1
2,-8,19:98.2
3,-8,19:98.3
4,-8,19:98.2
5,-8,19:98.2
6,-8,19:98.0
7,-8,19:98.0
8,-8,19:98.3
-7,-7,19:98.0
-6,-7,19:98.2
-5,-7,19:98.3
-4,-7,19:98.1
-3,-7,19:98.1
-2,-7,19:98.1
-1,-7,19:98.3
0,-7,19:98.2
1,-7,19:98.2
2,-7,19:98.0
3,-7,19:98.1
4,-7,19:98.2
5,-7,19:98.2
6,-7,19:98.1
7,-7,19:98.2
8,-7,19:98.3
-7,-6,19:98.0
-6,-6,19:98.3
-5,-6,19:98.3
-4,-6,19:98.2
-3,-6,19:98.3
-2,-6,19:98.0
-1,-6,19:98.1
0,-6,19:98.1
1,-6,19:98.3
2,-6,19:98.2
3,-6,19:98.1
4,-6,19:98.3
5,-6,19:98.3
6,-6,19:98.0
7,-6,19:98.2
8,-6,19:98.3
-7,-5,19:98.2
-6,-5,19:98.3
-5,-5,19:98.2
-4,-5,19:98.1
-3,-5,19:98.2
-2,-5,19:98.2
-1,-5,19:98.2
0,-5,19:98.1
1,-5,19:98.0
2,-5,19:98.3
3,-5,19:98.0
4,-5,19:98.3
5,-5,19:98.2
6,-5,19:98.2
7,-5,19:98.0
8,-5,19:98.0
-7,-4,19:98.3
-6,-4,19:98.2
-5,-4,19:98.1
-4,-4,19:98.3
-3,-4,19:98.1
-2,-4,19:98.1
-1,-4,19:98.1
0,-4,19:98.3
1,-4,19:98.0
2,-4,19:98.1
3,-4,19:98.3
4,-4,19:98.1
5,-4,19:98.0
6,-4,19:98.3
7,-4,19:98.0
8,-4,19:98.0
-7,-3,19:98.2
-6,-3,19:98.3
-5,-3,19:98.2
-4,-3,19:98.2
-3,-3,19:98.0
-2,-3,19:98.3
-1,-3,19:98.3
0,-3,19:98.2
1,-3,19:98.2
2,-3,19:98.0
3,-3,19:98.0
7,-3,19:98.2
8,-3,19:98.1
-7,-2,19:98.0
-6,-2,19:98.1
-5,-2,19:98.0
-4,-2,19:98.0
-3,-2,19:98.2
-2,-2,19:98.2
-1,-2,19:98.0
0,-2,19:98.1
1,-2,19:98.1
2,-2,19:98.0
3,-2,19:98.1
7,-2,19:98.0
8,-2,19:98.0
-7,-1,19:98.0
-6,-1,19:98.2
-5,-1,19:98.0
-4,-1,19:98.1
-3,-1,19:98.1
-2,-1,19:98.2
-1,-1,19:98.0
0,-1,19:98.2
1,-1,19:98.2
2,-1,19:98.3
3,-1,19:98.1
7,-1,19:98.3
8,-1,19:98.0
-7,0,19:98.3
-6,0,19:98.1
-5,0,19:98.2
-4,0,19:98.2
-3,0,19:98.0
-2,0,19:98.2
-1,0,19:98.3
0,0,19:98.0
1,0,19:98.3
2,0,19:98.3
3,0,19:98.0
4,0,19:98.3
5,0,19:98.0
6,0,19:98.1
7,0,19:98.0
8,0,19:98.0
-7,1,19:98.2
-6,1,19:98.1
-5,1,19:98.3
-4,1,19:98.2
-3,1,19:98.0
-2,1,19:98.1
-1,1,19:98.2
0,1,19:98.3
1,1,19:98.3
2,1,19:98.2
3,1,19:98.3
4,1,19:98.0
5,1,19:98.3
6,1,19:98.2
7,1,19:98.0
8,1,19:98.0
-7,2,19:98.2
-6,2,19:98.1
-5,2,19:98.3
-4,2,19:98.2
-3,2,19:98.3
-2,2,19:98.2
-1,2,19:98.3
0,2,19:98.1
1,2,19:98.0
2,2,19:98.2
3,2,19:98.3
4,2,19:98.3
5,2,19:98.0
6,2,19:98.2
7,2,19:98.1
8,2,19:98.0
-7,3,19:98.0
-6,3,19:98.2
-5,3,19:98.3
-4,3,19:98.2
-3,3,19:98.0
-2,3,19:98.3
-1,3,19:98.0
0,3,19:98.1
1,3,19:98.1
2,3,19:98.0
3,3,19:98.3
4,3,19:98.2
5,3,19:98.2
6,3,19:98.2
7,3,19:98.0
8,3,19:98.2
-7,4,19:98.2
-6,4,19:98.1
-5,4,19:98.3
-4,4,19:98.3
-3,4,19:98.2
-2,4,19:98.3
-1,4,19:98.3
0,4,19:98.2
1,4,19:98.0
2,4,19:98.3
3,4,19:98.2
4,4,19:98.0
5,4,19:98.3
6,4,19:98.2
7,4,19:98.3
8,4,19:98.2
-7,5,19:98.2
-6,5,19:98.2
-5,5,19:98.1
-4,5,19:98.3
-3,5,19:98.0
-2,5,19:98.0
-1,5,19:98.1
0,5,19:98.2
1,5,19:98.2
2,5,19:98.2
3,5,19:98.1
4,5,19:98.3
5,5,19:98.3
6,5,19:98.0
7,5,19:98.2
