[META]
version=2.0
spawnOnBlockType=13
spawnSunlight=True
spawnDarkness=False
spawnWater=False
spawnLava=False
underFill=True
randomRotation=True
dig=True
tree=False
branch=False
needsFoundation=True
rarity=2
collisionPercentage=2
spawnElevationMin=0
spawnElevationMax=128
spawnInBiome=Flat
[DATA]
-7,-7,0:43.0
-6,-7,0:43.0
-5,-7,0:43.0
-4,-7,0:43.0
-3,-7,0:43.0
-2,-7,0:43.0
-1,-7,0:43.0
0,-7,0:43.0
1,-7,0:43.0
2,-7,0:43.0
3,-7,0:43.0
4,-7,0:43.0
5,-7,0:43.0
6,-7,0:43.0
-7,-6,0:43.0
-6,-6,0:98.0
-5,-6,0:98.0
-4,-6,0:98.0
-3,-6,0:98.0
-2,-6,0:98.0
-1,-6,0:98.0
0,-6,0:98.0
1,-6,0:98.0
2,-6,0:98.0
3,-6,0:98.0
4,-6,0:98.0
5,-6,0:98.0
6,-6,0:98.0
-7,-5,0:43.0
-6,-5,0:98.0
-5,-5,0:1
-4,-5,0:1
-3,-5,0:1
-2,-5,0:1
-1,-5,0:1
0,-5,0:1
1,-5,0:1
2,-5,0:1
3,-5,0:1
4,-5,0:1
5,-5,0:1
6,-5,0:98.0
-7,-4,0:43.0
-6,-4,0:98.0
-5,-4,0:1
-4,-4,0:1
-3,-4,0:1
-2,-4,0:1
-1,-4,0:1
0,-4,0:1
1,-4,0:1
2,-4,0:1
3,-4,0:1
4,-4,0:1
5,-4,0:1
6,-4,0:98.0
-7,-3,0:43.0
-6,-3,0:98.0
-5,-3,0:1
-4,-3,0:1
-3,-3,0:1
-2,-3,0:1
-1,-3,0:1
0,-3,0:1
1,-3,0:1
2,-3,0:1
3,-3,0:1
4,-3,0:1
5,-3,0:1
6,-3,0:98.0
-7,-2,0:43.0
-6,-2,0:98.0
-5,-2,0:1
-4,-2,0:1
-3,-2,0:1
-2,-2,0:1
-1,-2,0:1
0,-2,0:1
1,-2,0:1
2,-2,0:1
3,-2,0:1
4,-2,0:1
5,-2,0:1
6,-2,0:98.0
-7,-1,0:43.0
-6,-1,0:98.0
-5,-1,0:1
-4,-1,0:1
-3,-1,0:1
-2,-1,0:1
-1,-1,0:1
0,-1,0:1
1,-1,0:1
2,-1,0:1
3,-1,0:1
4,-1,0:1
5,-1,0:1
6,-1,0:98.0
-7,0,0:43.0
-6,0,0:98.0
-5,0,0:1
-4,0,0:1
-3,0,0:1
-2,0,0:1
-1,0,0:1
0,0,0:1
1,0,0:1
2,0,0:1
3,0,0:1
4,0,0:1
5,0,0:1
6,0,0:98.0
-7,1,0:43.0
-6,1,0:98.0
-5,1,0:1
-4,1,0:1
-3,1,0:1
-2,1,0:1
-1,1,0:1
0,1,0:1
1,1,0:1
2,1,0:1
3,1,0:1
4,1,0:1
5,1,0:1
6,1,0:98.0
-7,2,0:43.0
-6,2,0:98.0
-5,2,0:1
-4,2,0:1
-3,2,0:1
-2,2,0:1
-1,2,0:1
0,2,0:1
1,2,0:1
2,2,0:1
3,2,0:1
4,2,0:1
5,2,0:1
6,2,0:98.0
-7,3,0:43.0
-6,3,0:98.0
-5,3,0:1
-4,3,0:1
-3,3,0:1
-2,3,0:1
-1,3,0:1
0,3,0:1
1,3,0:1
2,3,0:1
3,3,0:1
4,3,0:1
5,3,0:1
6,3,0:98.0
-7,4,0:43.0
-6,4,0:98.0
-5,4,0:43.0
-3,4,0:1
-2,4,0:1
-1,4,0:1
0,4,0:1
1,4,0:1
2,4,0:1
3,4,0:1
4,4,0:1
5,4,0:1
6,4,0:98.0
-7,5,0:43.0
-6,5,0:98.0
-3,5,0:1
-2,5,0:1
-1,5,0:1
0,5,0:1
1,5,0:1
2,5,0:1
3,5,0:1
4,5,0:1
5,5,0:1
6,5,0:98.0
-7,6,0:43.0
-6,6,0:98.0
-5,6,0:98.0
-4,6,0:98.0
-3,6,0:98.0
-2,6,0:98.0
-1,6,0:98.0
0,6,0:98.0
1,6,0:98.0
2,6,0:98.0
3,6,0:98.0
4,6,0:98.0
5,6,0:98.0
6,6,0:98.0
-1,-7,1:35.14
0,-7,1:35.14
1,-7,1:35.14
-7,-1,1:35.14
-7,0,1:35.14
-1,0,1:20
0,0,1:43.0
5,0,1:43.0
-7,1,1:35.14
-6,2,1:1
-5,2,1:1
-3,2,1:1
-6,3,1:1
-3,3,1:1
-6,4,1:1
-3,4,1:1
-6,5,1:1
-3,5,1:1
0,5,1:43.0
5,5,1:43.0
-6,6,1:1
-5,6,1:1
-4,6,1:1
-3,6,1:1
-2,-7,2:35.14
2,-7,2:35.14
-7,-2,2:35.14
0,-1,2:20
0,0,2:101
5,0,2:101
-7,2,2:35.14
-6,2,2:1
-5,2,2:1
-3,2,2:1
-6,3,2:1
-3,3,2:1
-6,4,2:1
-3,4,2:1
-6,5,2:1
-3,5,2:1
0,5,2:101
5,5,2:101
-6,6,2:1
-5,6,2:1
-4,6,2:1
-3,6,2:1
2,-7,3:35.14
-7,-2,3:35.14
0,0,3:101
1,0,3:20
5,0,3:101
-6,2,3:98.0
-5,2,3:98.0
-4,2,3:98.0
-3,2,3:98.0
-6,3,3:98.0
-5,3,3:98.0
-4,3,3:98.0
-3,3,3:98.0
-6,4,3:98.0
-5,4,3:98.0
-4,4,3:98.0
-3,4,3:98.0
-6,5,3:98.0
-5,5,3:98.0
-4,5,3:98.0
-3,5,3:98.0
0,5,3:101
5,5,3:101
-6,6,3:98.0
-5,6,3:98.0
-4,6,3:98.0
-3,6,3:98.0
-2,-7,4:35.14
2,-7,4:35.14
-7,-2,4:35.14
0,0,4:101
1,0,4:101
4,0,4:101
5,0,4:101
0,1,4:101
1,1,4:101
4,1,4:101
5,1,4:101
-7,2,4:35.14
0,4,4:101
1,4,4:101
4,4,4:101
5,4,4:101
0,5,4:101
1,5,4:101
4,5,4:101
5,5,4:101
-1,-7,5:35.14
0,-7,5:35.14
1,-7,5:35.14
-7,-1,5:35.14
-7,0,5:35.14
-7,1,5:35.14
1,1,5:101
4,1,5:101
0,2,5:20
6,3,5:43.0
1,4,5:101
4,4,5:101
5,4,5:43.0
4,5,5:43.0
3,6,5:43.0
1,1,6:101
4,1,6:101
6,2,6:43.0
1,3,6:20
5,3,6:43.0
1,4,6:101
4,4,6:43.0
3,5,6:43.0
2,6,6:43.0
1,1,7:101
4,1,7:101
6,1,7:43.0
5,2,7:43.0
4,3,7:43.0
-1,4,7:20
0,4,7:20
1,4,7:101
3,4,7:43.0
2,5,7:43.0
1,6,7:43.0
6,0,8:43.0
1,1,8:101
4,1,8:101
5,1,8:43.0
4,2,8:43.0
3,3,8:43.0
1,4,8:101
2,4,8:43.0
4,4,8:43.0
-1,5,8:20
1,5,8:43.0
5,5,8:44.8
-1,6,8:20
0,6,8:43.0
5,0,9:43.0
1,1,9:101
2,1,9:101
4,1,9:43.0
1,2,9:101
2,2,9:101
3,2,9:43.0
2,3,9:43.0
1,4,9:43.0
0,5,9:43.0
5,5,9:44.0
6,6,9:43.0
4,0,10:43.0
3,1,10:43.0
2,2,10:43.0
1,3,10:43.0
0,4,10:43.0
6,6,10:54.4
