[META]
version=2.0
spawnOnBlockType=2
spawnSunlight=True
spawnDarkness=True
spawnWater=True
spawnLava=False
underFill=False
randomRotation=False
dig=True
tree=True
branch=False
needsFoundation=False
rarity=100
collisionPercentage=100
spawnElevationMin=70
spawnElevationMax=79
spawnInBiome=TemperateSwampland,TemperateSwamplandBorder,TemperateWoodlandWetland
[DATA]
1,-1,-1:17.8
0,0,-1:17.0
1,0,-1:17.0
2,0,-1:17.4
0,1,-1:17.0
0,2,-1:17.8
1,-4,0:106.1
2,-3,0:106.2
-2,-2,0:106.8
2,-2,0:106.1
0,-1,0:106.1
4,-1,0:106.1
-4,0,0:106.8
-1,0,0:106.8
0,0,0:17.0
1,0,0:17.0
2,0,0:106.2
-4,1,0:106.8
0,1,0:17.0
1,1,0:106.4
0,2,0:106.4
5,2,0:106.2
0,3,0:106.4
4,3,0:106.4
2,5,0:106.4
1,-4,1:106.1
2,-3,1:106.2
-2,-2,1:106.8
2,-2,1:106.1
0,-1,1:106.1
4,-1,1:106.1
-4,0,1:106.8
-1,0,1:106.8
0,0,1:17.0
1,0,1:17.0
2,0,1:106.2
-4,1,1:106.8
0,1,1:17.0
1,1,1:106.4
0,2,1:106.4
5,2,1:106.2
0,3,1:106.4
4,3,1:106.4
2,5,1:106.4
1,-4,2:106.1
2,-3,2:106.2
-2,-2,2:106.8
2,-2,2:106.1
0,-1,2:106.1
4,-1,2:106.1
-4,0,2:106.8
-1,0,2:106.8
0,0,2:17.0
1,0,2:17.0
2,0,2:106.2
-4,1,2:106.8
0,1,2:17.0
1,1,2:106.4
0,2,2:106.4
5,2,2:106.2
0,3,2:106.4
4,3,2:106.4
2,5,2:106.4
1,-4,3:106.1
2,-3,3:106.2
-2,-2,3:106.8
2,-2,3:106.1
0,-1,3:106.1
4,-1,3:106.1
-4,0,3:106.8
-1,0,3:106.8
0,0,3:17.0
1,0,3:17.0
2,0,3:106.2
-4,1,3:106.8
0,1,3:17.0
1,1,3:106.4
0,2,3:106.4
5,2,3:106.2
0,3,3:106.4
4,3,3:106.4
2,5,3:106.4
1,-4,4:106.1
2,-3,4:106.2
-2,-2,4:106.8
2,-2,4:106.1
0,-1,4:106.1
4,-1,4:106.1
-4,0,4:106.8
-1,0,4:106.8
0,0,4:17.0
1,0,4:17.0
2,0,4:106.2
-4,1,4:106.8
0,1,4:17.0
0,2,4:106.4
5,2,4:106.2
0,3,4:106.4
4,3,4:106.4
2,5,4:106.4
1,-4,5:106.1
0,-3,5:18
2,-3,5:106.2
-2,-2,5:106.8
-1,-2,5:18
0,-2,5:17.8
2,-2,5:106.1
-2,-1,5:18
-1,-1,5:17.4
0,-1,5:17.8
1,-1,5:18
2,-1,5:18
4,-1,5:106.1
-4,0,5:106.8
-2,0,5:18
-1,0,5:17.8
0,0,5:17.0
1,0,5:17.0
2,0,5:18
3,0,5:18
-4,1,5:106.8
-2,1,5:18
-1,1,5:18
0,1,5:17.0
1,1,5:17.4
2,1,5:17.4
3,1,5:17.4
4,1,5:18
0,2,5:18
1,2,5:18
2,2,5:17.8
3,2,5:18
5,2,5:106.2
0,3,5:106.4
2,3,5:18
3,3,5:18
4,3,5:106.4
2,5,5:106.4
0,-4,6:18
1,-4,6:106.1
-1,-3,6:18
0,-3,6:17.8
1,-3,6:18
2,-3,6:106.2
-1,-2,6:18
0,-2,6:18
1,-2,6:18
-2,-1,6:18
-1,-1,6:18
0,-1,6:18
1,-1,6:18
4,-1,6:106.1
-4,0,6:106.8
-3,0,6:18
-2,0,6:17.0
-1,0,6:17.0
0,0,6:17.0
1,0,6:18
2,0,6:18
3,0,6:18
4,0,6:18
-4,1,6:106.8
-3,1,6:18
-2,1,6:17.0
-1,1,6:18
0,1,6:18
1,1,6:18
2,1,6:18
3,1,6:18
4,1,6:17.0
5,1,6:18
-2,2,6:18
-1,2,6:18
0,2,6:18
1,2,6:18
2,2,6:18
3,2,6:18
4,2,6:18
5,2,6:106.2
1,3,6:18
2,3,6:17.0
3,3,6:18
4,3,6:106.4
2,4,6:18
2,5,6:106.4
0,-3,7:18
0,-2,7:18
-1,-1,7:18
0,-1,7:18
-2,0,7:18
-1,0,7:18
0,0,7:18
-2,1,7:18
-1,1,7:18
0,1,7:18
1,1,7:18
2,1,7:18
3,1,7:18
4,1,7:18
-2,2,7:18
2,2,7:18
2,3,7:18
