[META]
version=2.0
spawnOnBlockType=8,9
spawnSunlight=True
spawnDarkness=True
spawnWater=True
spawnLava=False
underFill=False
randomRotation=False
dig=True
tree=True
branch=False
needsFoundation=False
rarity=100
collisionPercentage=100
spawnElevationMin=70
spawnElevationMax=79
spawnInBiome=TemperateSwampland,TemperateSwamplandBorder,TemperateWoodlandWetland
[DATA]
-2,-2,-2:17.0
3,-2,-2:17.0
0,-4,-1:17.0
-2,-2,-1:17.0
3,-2,-1:17.0
3,2,-1:17.0
-1,-5,0:18
0,-5,0:18
-1,-4,0:18
0,-4,0:17.0
1,-4,0:18
0,-3,0:17.8
1,-3,0:18
-2,-2,0:17.0
-1,-2,0:17.4
0,-2,0:17.4
1,-2,0:17.4
2,-2,0:17.4
3,-2,0:17.0
0,-1,0:18
3,2,0:17.0
-1,-4,1:18
0,-4,1:18
-1,-3,1:18
0,-3,1:18
1,-3,1:18
-2,-2,1:17.0
-1,-2,1:18
0,-2,1:18
1,-2,1:18
3,-2,1:17.0
3,-1,1:17.8
3,0,1:17.8
3,1,1:17.8
3,2,1:17.0
-2,-3,2:18
-1,-3,2:18
-3,-2,2:18
-2,-2,2:17.0
-1,-2,2:18
3,-2,2:17.0
-2,-1,2:18
-1,-1,2:18
3,1,2:18
2,2,2:18
3,2,2:17.0
4,2,2:18
3,3,2:18
-2,-2,3:18
3,-2,3:17.0
-2,-1,3:18
3,2,3:18
2,-2,4:18
3,-2,4:17.0
2,-1,4:18
3,-1,4:18
2,-5,5:18
3,-5,5:18
1,-4,5:18
2,-4,5:17.8
3,-4,5:17.4
4,-4,5:18
1,-3,5:18
2,-3,5:17.8
3,-3,5:18
4,-3,5:18
5,-3,5:18
1,-2,5:18
2,-2,5:17.4
3,-2,5:17.0
4,-2,5:18
5,-2,5:18
1,-1,5:18
2,-1,5:18
3,-1,5:17.8
4,-1,5:18
5,-1,5:18
2,0,5:18
3,0,5:17.8
4,0,5:17.4
5,0,5:18
2,1,5:18
3,1,5:18
4,1,5:18
2,-4,6:18
3,-4,6:18
2,-3,6:18
3,-3,6:18
4,-3,6:18
2,-2,6:18
3,-2,6:18
4,-2,6:18
2,-1,6:18
3,-1,6:18
4,-1,6:18
3,0,6:18
4,0,6:18
