[META]
version=2.0
spawnOnBlockType=1,2,3,12
spawnSunlight=True
spawnDarkness=True
spawnWater=False
spawnLava=False
underFill=True
randomRotation=True
dig=True
tree=False
branch=False
needsFoundation=True
rarity=1000
collisionPercentage=100
spawnElevationMin=0
spawnElevationMax=228
spawnInBiome=TallForest
[DATA]
-26,5,0:106.2
-24,5,0:106.2
-9,7,0:17.1
-9,8,0:17.1
-8,7,0:17.1
-7,7,0:17.1
-6,-8,0:17.1
-6,-4,0:39
-6,4,0:17.1
-6,5,0:17.1
-6,6,0:17.1
-6,7,0:17.1
-6,8,0:106.2
-5,-8,0:17.1
-5,-7,0:17.1
-5,-5,0:17.1
-5,-1,0:39
-5,0,0:17.0
-5,1,0:17.0
-5,2,0:17.0
-5,3,0:17.0
-5,6,0:17.1
-5,7,0:106.5
-4,-7,0:17.1
-4,-6,0:17.1
-4,-5,0:17.1
-4,-4,0:17.1
-4,-1,0:17.0
-4,4,0:17.0
-4,6,0:17.1
-4,8,0:106.2
-3,-4,0:17.1
-3,-3,0:17.1
-3,-2,0:17.0
-3,5,0:17.0
-3,6,0:17.1
-2,-4,0:17.1
-2,-3,0:17.0
-2,6,0:17.0
-1,-3,0:17.0
-1,5,0:65.4
-1,6,0:17.0
0,-3,0:17.0
0,5,0:65.4
0,6,0:17.0
1,-4,0:17.1
1,-3,0:17.0
1,6,0:17.0
2,-4,0:17.1
2,-3,0:17.1
2,-2,0:17.0
2,5,0:17.0
2,6,0:17.1
2,7,0:17.1
2,8,0:106.2
3,-3,0:17.1
3,-2,0:106.14
3,-1,0:17.0
3,0,0:50.4
3,3,0:50.4
3,4,0:17.0
3,5,0:17.1
3,6,0:17.1
3,7,0:17.1
3,8,0:106.2
4,-3,0:17.1
4,-2,0:106.2
4,-1,0:106.12
4,0,0:17.0
4,1,0:64.3
4,2,0:64.6
4,3,0:17.0
4,4,0:106.4
4,6,0:17.1
4,7,0:106.4
4,8,0:106.4
5,-4,0:39
5,-3,0:17.1
5,-2,0:17.1
5,0,0:50.3
5,3,0:50.3
5,6,0:17.1
5,7,0:17.1
6,-4,0:17.1
6,-3,0:17.1
6,0,0:106.4
6,2,0:106.4
6,6,0:17.1
6,7,0:17.1
6,8,0:17.1
8,-2,0:106.8
9,-1,0:106.4
9,17,0:106.4
9,18,0:106.4
10,5,0:106.1
11,6,0:106.2
12,6,0:106.2
13,16,0:37
15,12,0:37
17,18,0:37
17,20,0:37
-26,5,1:106.2
-25,5,1:106.2
-24,5,1:106.2
-9,7,1:17.1
-7,7,1:17.1
-6,5,1:17.1
-5,-7,1:17.1
-5,-5,1:39
-5,0,1:17.0
-5,1,1:17.0
-5,2,1:17.0
-5,3,1:17.0
-5,7,1:106.1
-4,-1,1:17.0
-4,1,1:50.3
-4,2,1:50.3
-4,4,1:17.0
-4,6,1:17.1
-4,8,1:106.2
-3,-2,1:17.0
-3,5,1:17.0
-3,6,1:106.8
-2,-4,1:17.1
-2,-3,1:17.0
-2,5,1:50.2
-2,6,1:17.0
-1,-3,1:17.0
-1,-2,1:50.1
-1,5,1:65.4
-1,6,1:17.0
0,-3,1:17.0
0,-2,1:50.1
0,5,1:65.4
0,6,1:17.0
1,-3,1:17.0
1,5,1:50.4
1,6,1:17.0
2,-2,1:17.0
2,5,1:17.0
2,6,1:17.1
2,7,1:39
3,-1,1:17.0
3,0,1:50.4
3,3,1:50.4
3,4,1:17.0
3,5,1:39
3,6,1:39
4,-3,1:17.1
4,-1,1:106.8
4,0,1:17.0
4,1,1:64.11
4,2,1:64.14
4,3,1:17.0
4,4,1:106.4
4,7,1:106.4
4,8,1:106.4
5,0,1:50.3
5,3,1:50.3
5,6,1:17.1
6,-4,1:39
6,0,1:106.4
6,2,1:106.4
6,8,1:39
8,-2,1:106.8
9,-1,1:106.4
9,17,1:106.4
9,18,1:106.4
10,5,1:106.1
11,6,1:106.2
12,6,1:106.2
-26,5,2:106.2
-25,5,2:106.2
-24,5,2:106.2
-10,-6,2:106.8
-6,1,2:50.4
-6,2,2:50.4
-6,5,2:39
-5,0,2:17.0
-5,1,2:17.0
-5,2,2:17.0
-5,3,2:17.0
-5,7,2:106.1
-4,-1,2:17.0
-4,4,2:17.0
-4,6,2:106.8
-4,8,2:106.2
-3,-2,2:17.0
-3,5,2:17.0
-3,6,2:106.8
-2,-4,2:39
-2,-3,2:17.0
-2,6,2:17.0
-1,-3,2:17.0
-1,5,2:65.4
-1,6,2:17.0
0,-3,2:17.0
0,5,2:65.4
0,6,2:17.0
1,-3,2:17.0
1,6,2:17.0
2,-2,2:17.0
2,5,2:17.0
2,6,2:39
3,-1,2:17.0
3,4,2:17.0
4,-1,2:106.8
4,0,2:17.0
4,1,2:17.0
4,2,2:17.0
4,3,2:17.0
4,4,2:106.4
4,7,2:106.4
4,8,2:106.4
5,0,2:106.4
5,1,2:68.3
5,2,2:68.3
6,0,2:106.4
6,2,2:106.4
8,-2,2:106.8
8,19,2:106.2
9,-1,2:106.4
9,17,2:106.4
9,18,2:106.4
10,5,2:106.1
11,6,2:106.2
12,6,2:106.2
24,5,2:106.2
-26,5,3:106.2
-25,5,3:106.2
-24,5,3:106.2
-10,-6,3:106.8
-8,-6,3:106.8
-5,0,3:17.0
-5,1,3:17.0
-5,2,3:17.0
-5,3,3:17.0
-5,7,3:106.1
-4,-1,3:17.0
-4,4,3:17.0
-4,6,3:106.8
-4,8,3:106.2
-3,-2,3:17.0
-3,5,3:17.0
-3,6,3:106.8
-2,-3,3:17.0
-2,6,3:17.0
-1,-3,3:17.0
-1,5,3:65.4
-1,6,3:17.0
0,-3,3:17.0
0,5,3:65.4
0,6,3:17.0
1,-3,3:17.0
1,6,3:17.0
2,-2,3:17.0
2,5,3:17.0
3,-1,3:17.0
3,4,3:17.0
4,-1,3:106.8
4,0,3:17.0
4,1,3:17.0
4,2,3:17.0
4,3,3:17.0
4,4,3:106.4
4,7,3:106.4
4,8,3:106.4
5,0,3:106.4
6,0,3:106.4
6,2,3:106.4
8,-2,3:106.8
8,19,3:106.2
9,-1,3:106.4
9,17,3:106.4
9,18,3:106.4
10,5,3:106.1
11,6,3:106.2
12,6,3:106.2
24,5,3:106.2
-26,5,4:106.2
-25,5,4:106.2
-24,5,4:106.2
-10,-6,4:106.8
-8,-6,4:106.8
-5,0,4:17.0
-5,1,4:17.0
-5,2,4:17.0
-5,3,4:17.0
-5,7,4:106.1
-4,-1,4:17.0
-4,4,4:17.0
-4,6,4:106.8
-4,8,4:106.2
-3,-2,4:17.0
-3,5,4:17.0
-3,6,4:106.8
-2,-3,4:17.0
-2,2,4:44.2
-2,3,4:44.2
-2,4,4:53.3
-2,5,4:44.2
-2,6,4:17.0
-1,-3,4:17.0
-1,2,4:44.2
-1,3,4:44.2
-1,4,4:44.2
-1,5,4:65.4
-1,6,4:17.0
-1,7,4:50.1
0,-3,4:17.0
0,2,4:44.2
0,3,4:44.2
0,4,4:44.2
0,5,4:65.4
0,6,4:17.0
0,7,4:50.1
1,-3,4:17.0
1,2,4:44.2
1,3,4:44.2
1,4,4:44.2
1,5,4:44.2
1,6,4:17.0
2,-2,4:17.0
2,2,4:44.2
2,3,4:44.2
2,4,4:44.2
2,5,4:17.0
3,-1,4:17.0
3,4,4:17.0
4,-1,4:106.8
4,0,4:17.0
4,1,4:17.0
4,2,4:17.0
4,3,4:17.0
4,4,4:106.4
4,7,4:106.4
4,8,4:106.4
5,0,4:106.4
6,0,4:106.4
6,2,4:106.4
8,-2,4:106.8
8,19,4:106.2
9,-1,4:106.4
9,17,4:106.4
9,18,4:106.4
10,5,4:106.1
11,6,4:106.2
12,6,4:106.2
24,5,4:106.2
-26,5,5:106.2
-25,5,5:106.2
-24,5,5:106.2
-10,-6,5:106.8
-8,-6,5:106.8
-6,-31,5:106.1
-5,-32,5:106.8
-5,0,5:17.0
-5,1,5:17.0
-5,2,5:17.0
-5,3,5:17.0
-5,7,5:106.1
-4,-31,5:106.4
-4,-1,5:17.0
-4,4,5:17.0
-4,6,5:106.8
-4,8,5:106.2
-3,-2,5:17.0
-3,3,5:44.2
-3,4,5:53.3
-3,5,5:17.0
-3,6,5:106.8
-2,-3,5:17.0
-2,6,5:17.0
-1,-3,5:17.0
-1,6,5:17.0
0,-3,5:17.0
0,6,5:17.0
1,-3,5:17.0
1,6,5:17.0
2,-2,5:17.0
2,5,5:17.0
3,-1,5:17.0
3,4,5:17.0
4,-1,5:106.8
4,0,5:17.0
4,1,5:17.0
4,2,5:17.0
4,3,5:17.0
4,4,5:106.4
4,7,5:106.4
4,8,5:106.4
5,0,5:106.4
6,0,5:106.4
6,2,5:106.4
8,-2,5:106.8
8,19,5:106.2
9,-1,5:106.4
9,17,5:106.4
9,18,5:106.4
10,5,5:106.1
11,6,5:106.2
12,6,5:106.2
24,5,5:106.2
-26,5,6:106.2
-25,5,6:106.2
-24,5,6:106.2
-10,-6,6:106.8
-9,-6,6:106.8
-8,-6,6:106.8
-6,-31,6:106.1
-5,-32,6:106.8
-5,0,6:17.0
-5,1,6:17.0
-5,2,6:17.0
-5,3,6:17.0
-5,7,6:106.1
-4,-31,6:106.4
-4,-1,6:17.0
-4,3,6:44.2
-4,4,6:17.0
-4,6,6:106.8
-4,8,6:106.2
-3,-2,6:17.0
-3,3,6:53.1
-3,5,6:17.0
-3,6,6:106.8
-2,-3,6:17.0
-2,3,6:44.2
-2,6,6:17.0
-1,-4,6:50.2
-1,-3,6:17.0
-1,6,6:17.0
0,-4,6:50.2
0,-3,6:17.0
0,6,6:17.0
1,-3,6:17.0
1,6,6:17.0
2,-2,6:17.0
2,5,6:17.0
3,-1,6:17.0
3,4,6:17.0
4,-1,6:106.8
4,0,6:17.0
4,1,6:17.0
4,2,6:17.0
4,3,6:17.0
4,4,6:106.4
4,7,6:106.4
4,8,6:106.4
5,0,6:106.4
6,0,6:106.4
6,2,6:106.4
8,-2,6:106.8
8,19,6:106.2
9,-1,6:106.4
9,17,6:106.4
9,18,6:106.4
10,5,6:106.1
11,6,6:106.2
12,6,6:106.2
24,5,6:106.2
-26,5,7:106.2
-25,5,7:106.2
-24,5,7:106.2
-10,-6,7:106.8
-9,-6,7:106.8
-8,-6,7:106.8
-6,-31,7:106.1
-5,-32,7:106.8
-5,0,7:17.0
-5,1,7:17.0
-5,2,7:17.0
-5,3,7:17.0
-5,7,7:106.1
-4,-31,7:106.4
-4,-1,7:17.0
-4,2,7:44.2
-4,4,7:17.0
-4,6,7:106.8
-4,8,7:106.2
-3,-2,7:17.0
-3,2,7:53.1
-3,5,7:17.0
-3,6,7:106.8
-2,-3,7:17.0
-2,2,7:44.2
-2,6,7:17.0
-1,-3,7:17.0
-1,5,7:50.2
-1,6,7:17.0
0,-3,7:17.0
0,5,7:50.2
0,6,7:17.0
1,-3,7:17.0
1,6,7:17.0
2,-2,7:17.0
2,5,7:17.0
3,-1,7:17.0
3,4,7:17.0
4,-4,7:106.4
4,-1,7:106.8
4,0,7:17.0
4,1,7:17.0
4,2,7:17.0
4,3,7:17.0
4,4,7:106.4
4,7,7:106.4
4,8,7:106.4
5,0,7:106.4
6,0,7:106.4
6,2,7:106.4
8,-2,7:106.8
8,19,7:106.2
9,-1,7:106.4
9,17,7:106.4
9,18,7:106.4
10,5,7:106.1
11,6,7:106.2
12,6,7:106.2
24,5,7:106.2
25,4,7:106.4
-26,5,8:106.2
-25,5,8:106.2
-24,5,8:106.2
-10,-6,8:106.8
-9,-6,8:106.8
-8,-6,8:106.8
-6,-31,8:106.1
-5,-32,8:106.8
-5,0,8:17.0
-5,1,8:17.0
-5,2,8:17.0
-5,3,8:17.0
-5,7,8:106.1
-4,-31,8:106.4
-4,-1,8:17.0
-4,1,8:44.2
-4,4,8:17.0
-4,6,8:106.8
-4,8,8:106.2
-3,-2,8:17.0
-3,1,8:53.1
-3,5,8:17.0
-3,6,8:106.8
-2,-3,8:17.0
-2,1,8:44.2
-2,6,8:17.0
-1,-3,8:17.0
-1,-2,8:50.1
-1,6,8:17.0
0,-3,8:17.0
0,-2,8:50.1
0,6,8:17.0
0,12,8:106.2
1,-3,8:17.0
1,6,8:17.0
1,12,8:106.2
2,-2,8:17.0
2,5,8:17.0
3,-1,8:17.0
3,4,8:17.0
4,-4,8:106.4
4,-1,8:106.8
4,0,8:17.0
4,1,8:17.0
4,2,8:17.0
4,3,8:17.0
4,4,8:106.4
4,7,8:106.4
4,8,8:106.4
4,9,8:106.4
5,0,8:106.4
6,0,8:106.4
6,2,8:106.4
8,-2,8:106.8
8,19,8:106.2
9,-1,8:106.4
9,17,8:106.4
9,18,8:106.4
10,5,8:106.1
11,6,8:106.2
12,6,8:106.2
24,5,8:106.2
25,4,8:106.4
-26,5,9:106.2
-25,5,9:106.2
-24,5,9:106.2
-10,-6,9:106.8
-9,-6,9:106.8
-8,-6,9:106.8
-6,-31,9:106.1
-6,1,9:50.4
-6,2,9:50.4
-5,-32,9:106.8
-5,0,9:17.0
-5,1,9:17.0
-5,2,9:17.0
-5,3,9:17.0
-5,7,9:106.1
-4,-31,9:106.4
-4,-1,9:17.0
-4,0,9:44.2
-4,4,9:17.0
-4,6,9:106.8
-4,8,9:106.2
-3,-2,9:17.0
-3,0,9:53.1
-3,5,9:17.0
-3,6,9:106.8
-2,-3,9:17.0
-2,0,9:44.2
-2,6,9:17.0
-1,-3,9:17.0
-1,6,9:17.0
0,-3,9:17.0
0,6,9:17.0
0,12,9:106.2
1,-3,9:17.0
1,6,9:17.0
1,12,9:106.2
2,-2,9:17.0
2,5,9:17.0
3,-1,9:17.0
3,4,9:17.0
4,-4,9:106.4
4,-1,9:106.8
4,0,9:17.0
4,1,9:17.0
4,2,9:17.0
4,3,9:17.0
4,4,9:106.4
4,7,9:106.4
4,8,9:106.4
4,9,9:106.4
5,0,9:106.4
5,1,9:50.3
5,2,9:50.3
6,0,9:106.4
6,2,9:106.4
8,-2,9:106.8
8,19,9:106.2
9,-1,9:106.4
9,17,9:106.4
9,18,9:106.4
10,5,9:106.1
11,6,9:106.2
12,6,9:106.2
24,5,9:106.2
25,4,9:106.4
-26,5,10:106.2
-25,5,10:106.2
-24,5,10:106.2
-10,-6,10:106.8
-9,-6,10:106.8
-8,-6,10:106.8
-6,-31,10:106.1
-5,-32,10:106.8
-5,0,10:17.0
-5,1,10:17.0
-5,2,10:17.0
-5,3,10:17.0
-5,7,10:106.1
-4,-31,10:106.4
-4,-1,10:17.0
-4,4,10:17.0
-4,6,10:106.8
-4,8,10:106.2
-3,-2,10:17.0
-3,-1,10:53.1
-3,5,10:17.0
-3,6,10:106.8
-2,-3,10:17.0
-2,-1,10:44.2
-2,6,10:17.0
-1,-3,10:17.0
-1,6,10:17.0
0,-3,10:17.0
0,6,10:17.0
0,12,10:106.2
1,-3,10:17.0
1,6,10:17.0
1,12,10:106.2
2,-2,10:17.0
2,5,10:17.0
3,-1,10:17.0
3,1,10:50.4
3,2,10:50.4
3,4,10:17.0
4,-4,10:106.4
4,-1,10:106.8
4,0,10:17.0
4,1,10:17.0
4,2,10:17.0
4,3,10:17.0
4,4,10:106.4
4,7,10:106.4
4,8,10:106.4
4,9,10:106.4
5,-12,10:106.4
5,-11,10:106.4
5,0,10:106.4
5,2,10:106.4
6,0,10:106.4
6,2,10:106.4
8,-2,10:106.8
8,19,10:106.2
9,-1,10:106.4
9,17,10:106.4
9,18,10:106.4
10,5,10:106.1
11,6,10:106.2
12,6,10:106.2
24,5,10:106.2
25,4,10:106.4
-26,5,11:106.2
-25,5,11:106.2
-24,5,11:106.2
-10,-6,11:106.8
-9,-6,11:106.8
-8,-6,11:106.8
-6,-31,11:106.1
-5,-32,11:106.8
-5,0,11:17.0
-5,1,11:17.0
-5,2,11:17.0
-5,3,11:17.0
-5,7,11:106.1
-4,-31,11:106.4
-4,-1,11:17.0
-4,1,11:50.3
-4,2,11:50.3
-4,4,11:17.0
-4,6,11:106.8
-4,8,11:106.2
-3,-2,11:17.0
-3,5,11:17.0
-3,6,11:106.8
-2,-3,11:17.0
-2,-2,11:44.2
-2,-1,11:53.2
-2,0,11:44.2
-2,6,11:17.0
-1,-3,11:17.0
-1,6,11:17.0
0,-3,11:17.0
0,6,11:17.0
0,12,11:106.2
1,-3,11:17.0
1,6,11:17.0
1,12,11:106.2
2,-2,11:17.0
2,5,11:17.0
3,-1,11:17.0
3,4,11:17.0
4,-4,11:106.4
4,0,11:17.0
4,1,11:17.0
4,2,11:17.0
4,3,11:17.0
4,4,11:106.4
4,7,11:106.4
4,8,11:106.4
4,9,11:106.4
5,-12,11:106.4
5,-11,11:106.4
5,0,11:106.4
5,2,11:106.4
6,0,11:106.4
6,2,11:106.4
8,-2,11:106.8
8,19,11:106.2
9,-1,11:106.4
9,17,11:106.4
9,18,11:106.4
10,5,11:106.1
11,6,11:106.2
12,6,11:106.2
24,5,11:106.2
25,4,11:106.4
-28,-4,12:18
-26,5,12:106.2
-25,5,12:106.2
-24,5,12:106.2
-10,-6,12:106.8
-9,-6,12:106.8
-8,-6,12:106.8
-6,-31,12:106.1
-5,-32,12:106.8
-5,-26,12:18
-5,0,12:17.0
-5,1,12:17.0
-5,2,12:17.0
-5,3,12:17.0
-5,7,12:106.1
-4,-31,12:106.4
-4,-1,12:17.0
-4,4,12:17.0
-4,6,12:106.8
-4,8,12:106.2
-3,-2,12:17.0
-3,5,12:17.0
-3,6,12:106.8
-2,-3,12:17.0
-2,6,12:17.0
-1,-3,12:17.0
-1,-2,12:44.2
-1,-1,12:53.2
-1,0,12:44.2
-1,6,12:17.0
0,-3,12:17.0
0,6,12:17.0
0,12,12:106.2
1,-22,12:106.8
1,-3,12:17.0
1,6,12:17.0
1,12,12:106.2
2,-21,12:106.4
2,-20,12:106.4
2,-2,12:17.0
2,5,12:17.0
3,-1,12:17.0
3,4,12:17.0
4,-4,12:106.4
4,0,12:17.0
4,1,12:17.0
4,2,12:17.0
4,3,12:17.0
4,4,12:106.4
4,7,12:106.4
4,8,12:106.4
4,9,12:106.4
4,29,12:18
5,-12,12:106.4
5,-11,12:106.4
5,0,12:106.4
5,2,12:106.4
6,0,12:106.4
6,2,12:106.4
8,-2,12:106.8
8,19,12:106.2
9,-1,12:106.4
9,17,12:106.4
9,18,12:106.4
10,5,12:106.1
11,6,12:106.2
12,6,12:106.2
24,5,12:106.2
25,4,12:106.4
-29,-4,13:18
-28,-5,13:18
-28,-4,13:18
-28,-3,13:18
-27,-4,13:18
-26,5,13:106.2
-25,5,13:106.2
-24,5,13:106.2
-10,-6,13:106.8
-9,-6,13:106.8
-8,-6,13:106.8
-6,-31,13:106.1
-6,-26,13:18
-5,-32,13:106.8
-5,-27,13:18
-5,-26,13:18
-5,-25,13:18
-5,-3,13:18.0
-5,-2,13:18.0
-5,0,13:17.0
-5,1,13:17.0
-5,2,13:17.0
-5,3,13:17.0
-5,7,13:106.1
-4,-31,13:106.4
-4,-26,13:18
-4,-3,13:18.0
-4,-2,13:18.0
-4,-1,13:17.0
-4,4,13:17.0
-4,6,13:106.8
-4,8,13:106.2
-3,-2,13:17.0
-3,5,13:17.0
-3,6,13:106.8
-2,-3,13:17.0
-2,6,13:17.0
-1,-3,13:17.0
-1,6,13:17.0
0,-3,13:17.0
0,-2,13:44.2
0,-1,13:53.2
0,0,13:44.2
0,6,13:17.0
0,12,13:106.2
1,-22,13:106.8
1,-3,13:17.0
1,6,13:17.0
1,12,13:106.2
2,-21,13:106.4
2,-20,13:106.4
2,-2,13:17.0
2,5,13:17.0
3,-1,13:17.0
3,4,13:17.0
3,29,13:18
4,-4,13:106.4
4,0,13:17.0
4,1,13:17.0
4,2,13:17.0
4,3,13:17.0
4,4,13:106.4
4,7,13:106.4
4,8,13:106.4
4,9,13:106.4
4,28,13:18
4,29,13:18
4,30,13:18
5,-12,13:106.4
5,-11,13:106.4
5,0,13:106.4
5,2,13:106.4
5,29,13:18
6,0,13:106.4
6,2,13:106.4
8,-2,13:106.8
8,19,13:106.2
9,-1,13:106.4
9,17,13:106.4
9,18,13:106.4
10,5,13:106.1
11,6,13:106.2
12,6,13:106.2
24,5,13:106.2
25,4,13:106.4
-30,-5,14:18.0
-30,-4,14:18.0
-30,-3,14:18.0
-29,-6,14:18.0
-29,-5,14:18.0
-29,-4,14:18.0
-29,-3,14:18.0
-29,-2,14:18.0
-28,-6,14:18.0
-28,-5,14:18.0
-28,-4,14:17.0
-28,-3,14:18.0
-28,-2,14:18.0
-27,-6,14:18.0
-27,-5,14:18.0
-27,-4,14:18.0
-27,-3,14:18.0
-27,-2,14:18.0
-26,-6,14:18.0
-26,-5,14:18.0
-26,-4,14:18.0
-26,-3,14:18.0
-26,-2,14:18.0
-26,5,14:106.2
-25,5,14:106.2
-24,5,14:106.2
-10,-6,14:106.8
-9,-6,14:106.8
-8,-6,14:106.8
-7,-27,14:18.0
-7,-26,14:18.0
-7,-25,14:18.0
-7,-24,14:18.0
-6,-31,14:106.1
-6,-28,14:18.0
-6,-27,14:18.0
-6,-26,14:18.0
-6,-25,14:18.0
-6,-24,14:18.0
-6,-3,14:18.0
-6,-2,14:18.0
-5,-32,14:106.8
-5,-28,14:18.0
-5,-27,14:18.0
-5,-26,14:17.0
-5,-25,14:18.0
-5,-24,14:18.0
-5,-4,14:18.0
-5,-3,14:18.0
-5,-2,14:18.0
-5,-1,14:18.0
-5,0,14:17.0
-5,1,14:17.0
-5,2,14:17.0
-5,3,14:17.0
-5,7,14:106.1
-4,-31,14:106.4
-4,-28,14:18.0
-4,-27,14:18.0
-4,-26,14:18.0
-4,-25,14:18.0
-4,-24,14:18.0
-4,-4,14:18.0
-4,-3,14:18.0
-4,-2,14:18.0
-4,-1,14:17.0
-4,4,14:17.0
-4,6,14:106.8
-4,8,14:106.2
-3,-27,14:18.0
-3,-26,14:18.0
-3,-25,14:18.0
-3,-24,14:18.0
-3,-3,14:18.0
-3,-2,14:17.0
-3,5,14:17.0
-3,6,14:106.8
-2,-3,14:17.0
-2,6,14:17.0
-1,-3,14:17.0
-1,6,14:17.0
0,-3,14:17.0
0,6,14:17.0
0,12,14:106.2
1,-22,14:106.8
1,-3,14:17.0
1,-2,14:44.2
1,-1,14:53.2
1,0,14:44.2
1,6,14:17.0
1,12,14:106.2
2,-21,14:106.4
2,-20,14:106.4
2,-2,14:17.0
2,5,14:17.0
2,27,14:18.0
2,28,14:18.0
2,29,14:18.0
2,30,14:18.0
3,-1,14:17.0
3,4,14:17.0
3,27,14:18.0
3,28,14:18.0
3,29,14:18.0
3,30,14:18.0
3,31,14:18.0
4,-4,14:106.4
4,0,14:17.0
4,1,14:17.0
4,2,14:17.0
4,3,14:17.0
4,4,14:106.4
4,7,14:106.4
4,8,14:106.4
4,9,14:106.4
4,27,14:18.0
4,28,14:18.0
4,29,14:17.0
4,30,14:18.0
4,31,14:18.0
5,-12,14:106.4
5,-11,14:106.4
5,0,14:106.4
5,2,14:106.4
5,27,14:18.0
5,28,14:18.0
5,29,14:18.0
5,30,14:18.0
5,31,14:18.0
6,0,14:106.4
6,2,14:106.4
6,27,14:18.0
6,28,14:18.0
6,29,14:18.0
6,30,14:18.0
8,-2,14:106.8
8,19,14:106.2
9,-1,14:106.4
9,17,14:106.4
9,18,14:106.4
10,5,14:106.1
11,6,14:106.2
12,6,14:106.2
24,5,14:106.2
25,4,14:106.4
-30,-6,15:18.0
-30,-5,15:18.0
-30,-4,15:18.0
-30,-3,15:18.0
-29,-6,15:18.0
-29,-5,15:18.0
-29,-4,15:18.0
-29,-3,15:18.0
-29,-2,15:18.0
-28,-6,15:18.0
-28,-5,15:18.0
-28,-4,15:17.0
-28,-3,15:18.0
-28,-2,15:18.0
-27,-6,15:18.0
-27,-5,15:18.0
-27,-4,15:18.0
-27,-3,15:18.0
-27,-2,15:18.0
-26,-6,15:18.0
-26,-5,15:18.0
-26,-4,15:18.0
-26,-3,15:18.0
-26,-2,15:18.0
-26,5,15:106.2
-25,5,15:106.2
-24,5,15:106.2
-14,1,15:18
-10,-6,15:106.8
-9,-6,15:106.8
-8,-6,15:106.8
-7,-28,15:18.0
-7,-27,15:18.0
-7,-26,15:18.0
-7,-25,15:18.0
-7,-24,15:18.0
-7,-3,15:18.0
-7,-2,15:18.0
-6,-31,15:106.1
-6,-28,15:18.0
-6,-27,15:18.0
-6,-26,15:18.0
-6,-25,15:18.0
-6,-24,15:18.0
-6,-4,15:18.0
-6,-3,15:18.0
-6,-2,15:18.0
-6,-1,15:18.0
-6,0,15:17.0
-6,1,15:17.0
-6,2,15:17.0
-5,-32,15:106.8
-5,-28,15:18.0
-5,-27,15:18.0
-5,-26,15:17.0
-5,-25,15:18.0
-5,-24,15:18.0
-5,-5,15:18.0
-5,-4,15:18.0
-5,-3,15:18.0
-5,-2,15:18.0
-5,-1,15:18.0
-5,0,15:17.0
-5,1,15:17.0
-5,2,15:17.0
-5,3,15:17.0
-5,7,15:106.1
-4,-31,15:106.4
-4,-28,15:18.0
-4,-27,15:18.0
-4,-26,15:18.0
-4,-25,15:18.0
-4,-24,15:18.0
-4,-5,15:18.0
-4,-4,15:18.0
-4,-3,15:18.0
-4,-2,15:18.0
-4,-1,15:17.0
-4,1,15:50.3
-4,2,15:50.3
-4,4,15:17.0
-4,6,15:106.8
-4,8,15:106.2
-3,-27,15:18.0
-3,-26,15:18.0
-3,-25,15:18.0
-3,-24,15:18.0
-3,-4,15:18.0
-3,-3,15:18.0
-3,-2,15:17.0
-3,5,15:17.0
-3,6,15:106.8
-2,-21,15:18.0
-2,-20,15:18.0
-2,-4,15:17.0
-2,-3,15:17.0
-2,6,15:17.0
-2,7,15:17.0
-1,-21,15:18.0
-1,-20,15:18.0
-1,-4,15:17.0
-1,-3,15:17.0
-1,-2,15:50.1
-1,1,15:5.0
-1,2,15:5.0
-1,5,15:50.2
-1,6,15:17.0
-1,7,15:17.0
-1,15,15:18
0,-12,15:18
0,-4,15:17.0
0,-3,15:17.0
0,-2,15:50.1
0,1,15:43.2
0,2,15:43.2
0,5,15:50.2
0,6,15:17.0
0,7,15:17.0
0,12,15:106.2
0,23,15:18.0
0,24,15:18.0
1,-22,15:106.8
1,-4,15:17.0
1,-3,15:17.0
1,1,15:44.2
1,2,15:44.2
1,6,15:17.0
1,7,15:17.0
1,12,15:106.2
1,23,15:18.0
1,24,15:18.0
2,-21,15:106.4
2,-20,15:106.4
2,-2,15:17.0
2,-1,15:44.2
2,0,15:44.2
2,1,15:44.2
2,2,15:44.2
2,5,15:17.0
2,27,15:18.0
2,28,15:18.0
2,29,15:18.0
2,30,15:18.0
3,-1,15:17.0
3,0,15:44.2
3,1,15:44.2
3,2,15:44.2
3,4,15:17.0
3,27,15:18.0
3,28,15:18.0
3,29,15:18.0
3,30,15:18.0
3,31,15:18.0
4,-4,15:106.4
4,-1,15:17.0
4,0,15:17.0
4,1,15:17.0
4,2,15:17.0
4,3,15:17.0
4,4,15:106.4
4,7,15:106.4
4,8,15:106.4
4,9,15:106.4
4,27,15:18.0
4,28,15:18.0
4,29,15:17.0
4,30,15:18.0
4,31,15:18.0
5,-12,15:106.4
5,-11,15:106.4
5,0,15:106.4
5,2,15:106.4
5,27,15:18.0
5,28,15:18.0
5,29,15:18.0
5,30,15:18.0
5,31,15:18.0
6,0,15:106.4
6,2,15:106.4
6,27,15:18.0
6,28,15:18.0
6,29,15:18.0
6,30,15:18.0
6,31,15:18.0
8,-2,15:106.8
8,19,15:106.2
9,-1,15:106.4
9,17,15:106.4
9,18,15:106.4
10,5,15:106.1
11,6,15:106.2
12,1,15:18
12,6,15:106.2
15,0,15:18
24,5,15:106.2
25,4,15:106.4
-29,-4,16:18.0
-29,-3,16:18.0
-28,-5,16:18.0
-28,-4,16:17.0
-28,-3,16:18.0
-27,-5,16:18.0
-27,-4,16:18.0
-27,-3,16:18.0
-26,5,16:106.2
-25,5,16:106.2
-24,5,16:106.2
-22,8,16:18
-16,-5,16:18
-14,-1,16:18
-14,1,16:18
-14,2,16:18
-13,0,16:18
-10,-6,16:106.8
-9,-6,16:106.8
-8,-6,16:106.8
-8,23,16:18
-7,-3,16:18.0
-7,-2,16:18.0
-7,-1,16:17.0
-7,0,16:17.0
-7,1,16:17.0
-7,2,16:17.0
-6,-31,16:106.1
-6,-26,16:18.0
-6,-25,16:18.0
-6,-14,16:18
-6,-4,16:18.0
-6,-3,16:18.0
-6,-2,16:18.0
-6,-1,16:18.0
-6,0,16:17.0
-6,1,16:17.0
-6,2,16:17.0
-5,-32,16:106.8
-5,-27,16:18.0
-5,-26,16:17.0
-5,-25,16:18.0
-5,-5,16:18.0
-5,-4,16:18.0
-5,-3,16:18.0
-5,-2,16:18.0
-5,-1,16:18.0
-5,0,16:17.0
-5,1,16:17.0
-5,2,16:17.0
-5,3,16:17.0
-5,7,16:106.1
-4,-31,16:106.4
-4,-27,16:18.0
-4,-26,16:18.0
-4,-25,16:18.0
-4,-5,16:18.0
-4,-4,16:18.0
-4,-3,16:18.0
-4,-2,16:18.0
-4,-1,16:17.0
-4,4,16:17.0
-4,6,16:106.8
-4,8,16:106.2
-3,-21,16:18.0
-3,-20,16:18.0
-3,-4,16:18.0
-3,-3,16:18.0
-3,-2,16:17.0
-3,5,16:17.0
-3,6,16:106.8
-2,-22,16:18.0
-2,-19,16:18.0
-2,-12,16:18
-2,-5,16:17.0
-2,-4,16:17.0
-2,-3,16:17.0
-2,6,16:17.0
-2,7,16:17.0
-2,8,16:17.0
-2,15,16:18
-1,-22,16:18.0
-1,-19,16:18.0
-1,-11,16:18
-1,-5,16:17.0
-1,-4,16:17.0
-1,-3,16:17.0
-1,1,16:5.0
-1,2,16:5.0
-1,6,16:17.0
-1,7,16:17.0
-1,8,16:17.0
-1,15,16:18
-1,23,16:18.0
-1,24,16:18.0
0,-21,16:18.0
0,-20,16:18.0
0,-12,16:18
0,-5,16:17.0
0,-4,16:17.0
0,-3,16:17.0
0,1,16:65.3
0,2,16:65.3
0,6,16:17.0
0,7,16:17.0
0,8,16:17.0
0,12,16:106.2
0,14,16:18
0,22,16:18.0
0,25,16:18.0
1,-22,16:106.8
1,-12,16:18
1,-5,16:17.0
1,-4,16:17.0
1,-3,16:17.0
1,6,16:17.0
1,7,16:17.0
1,8,16:17.0
1,12,16:106.2
1,15,16:18
1,22,16:18.0
1,25,16:18.0
2,-21,16:106.4
2,-20,16:106.4
2,-2,16:17.0
2,5,16:17.0
2,23,16:18.0
2,24,16:18.0
3,-1,16:17.0
3,4,16:17.0
3,28,16:18.0
3,29,16:18.0
3,30,16:18.0
4,-4,16:106.4
4,-1,16:17.0
4,0,16:17.0
4,1,16:17.0
4,2,16:17.0
4,3,16:17.0
4,4,16:106.4
4,7,16:106.4
4,8,16:106.4
4,9,16:106.4
4,28,16:18.0
4,29,16:17.0
4,30,16:18.0
5,-12,16:106.4
5,-11,16:106.4
5,-1,16:17.0
5,0,16:17.0
5,1,16:17.0
5,2,16:17.0
5,17,16:18
5,28,16:18.0
5,29,16:18.0
6,0,16:106.4
6,2,16:106.4
7,-20,16:18
8,-2,16:106.8
8,19,16:106.2
9,-1,16:106.4
9,17,16:106.4
9,18,16:106.4
10,5,16:106.1
11,0,16:18
11,6,16:106.2
12,-1,16:18
12,1,16:18
12,2,16:18
12,6,16:106.2
14,-5,16:18
15,0,16:18
16,0,16:18
20,8,16:18
24,5,16:106.2
25,4,16:106.4
-29,-4,17:18.0
-28,-5,17:18.0
-28,-4,17:18.0
-28,-3,17:18.0
-27,-4,17:18.0
-26,5,17:106.2
-25,5,17:106.2
-24,-8,17:18
-24,5,17:106.2
-23,8,17:18
-22,7,17:18
-22,8,17:18
-22,9,17:18
-21,8,17:18
-17,-5,17:18
-16,-6,17:18
-16,-5,17:18
-16,-4,17:18
-16,0,17:18
-16,1,17:18
-15,-5,17:18
-14,-2,17:18
-14,-1,17:18
-14,0,17:18
-14,1,17:18
-14,2,17:18
-13,0,17:18
-10,-6,17:106.8
-10,-1,17:17.0
-10,0,17:17.0
-10,1,17:17.0
-10,2,17:17.0
-9,-22,17:18
-9,-6,17:106.8
-9,-1,17:17.0
-9,0,17:17.0
-9,1,17:17.0
-9,2,17:17.0
-9,23,17:18
-8,-6,17:106.8
-8,-1,17:17.0
-8,0,17:17.0
-8,1,17:17.0
-8,2,17:17.0
-8,22,17:18
-8,23,17:18
-8,24,17:18
-7,-14,17:18
-7,-1,17:17.0
-7,0,17:17.0
-7,1,17:17.0
-7,2,17:17.0
-7,23,17:18
-6,-31,17:106.1
-6,-26,17:18.0
-6,-15,17:18
-6,-14,17:18
-6,-13,17:18
-6,-3,17:18.0
-6,-2,17:18.0
-6,-1,17:17.0
-6,0,17:17.0
-6,1,17:17.0
-6,2,17:17.0
-6,3,17:17.0
-6,4,17:17.0
-5,-32,17:106.8
-5,-27,17:18.0
-5,-26,17:18.0
-5,-25,17:18.0
-5,-14,17:18
-5,-4,17:18.0
-5,-3,17:18.0
-5,-2,17:18.0
-5,-1,17:18.0
-5,0,17:17.0
-5,1,17:17.0
-5,2,17:17.0
-5,3,17:17.0
-5,7,17:106.1
-4,-31,17:106.4
-4,-26,17:18.0
-4,-21,17:18.0
-4,-20,17:18.0
-4,-4,17:18.0
-4,-3,17:18.0
-4,-2,17:18.0
-4,-1,17:17.0
-4,4,17:17.0
-4,6,17:106.8
-4,7,17:17.0
-4,8,17:106.2
-3,-22,17:18.0
-3,-19,17:18.0
-3,-12,17:18
-3,-4,17:17.0
-3,-3,17:18.0
-3,-2,17:17.0
-3,5,17:17.0
-3,6,17:106.8
-3,7,17:17.0
-2,-23,17:18.0
-2,-18,17:18.0
-2,-12,17:18
-2,-8,17:17.0
-2,-7,17:17.0
-2,-6,17:17.0
-2,-5,17:17.0
-2,-4,17:17.0
-2,-3,17:17.0
-2,6,17:17.0
-2,7,17:17.0
-2,8,17:17.0
-2,9,17:17.0
-2,10,17:17.0
-2,11,17:17.0
-2,15,17:18
-2,23,17:18.0
-2,24,17:18.0
-1,-23,17:18.0
-1,-18,17:18.0
-1,-14,17:18
-1,-12,17:18
-1,-11,17:18
-1,-8,17:17.0
-1,-7,17:17.0
-1,-6,17:17.0
-1,-5,17:17.0
-1,-4,17:17.0
-1,-3,17:17.0
-1,1,17:5.0
-1,2,17:5.0
-1,6,17:17.0
-1,7,17:17.0
-1,8,17:17.0
-1,9,17:17.0
-1,10,17:17.0
-1,11,17:17.0
-1,15,17:18
-1,17,17:18
-1,22,17:18.0
-1,25,17:18.0
0,-22,17:18.0
0,-19,17:18.0
0,-14,17:18
0,-12,17:18
0,-8,17:17.0
0,-7,17:17.0
0,-6,17:17.0
0,-5,17:17.0
0,-4,17:17.0
0,-3,17:17.0
0,1,17:65.3
0,2,17:65.3
0,6,17:17.0
0,7,17:17.0
0,8,17:17.0
0,9,17:17.0
0,10,17:17.0
0,11,17:17.0
0,12,17:106.2
0,13,17:106
0,14,17:18
0,15,17:18
0,17,17:18
0,21,17:18.0
0,26,17:18.0
1,-22,17:106.8
1,-21,17:18.0
1,-20,17:18.0
1,-12,17:18
1,-8,17:17.0
1,-7,17:17.0
1,-6,17:17.0
1,-5,17:17.0
1,-4,17:17.0
1,-3,17:17.0
1,6,17:17.0
1,7,17:17.0
1,8,17:17.0
1,9,17:17.0
1,10,17:17.0
1,11,17:17.0
1,12,17:106.2
1,13,17:106
1,15,17:18
1,21,17:18.0
1,26,17:18.0
2,-21,17:106.4
2,-20,17:106.4
2,-4,17:17.0
2,-2,17:17.0
2,5,17:17.0
2,7,17:17.0
2,15,17:18
2,22,17:18.0
2,25,17:18.0
3,-4,17:17.0
3,-1,17:17.0
3,4,17:17.0
3,23,17:18.0
3,24,17:18.0
3,29,17:18.0
4,-4,17:106.4
4,-2,17:17.0
4,-1,17:17.0
4,0,17:17.0
4,1,17:17.0
4,2,17:17.0
4,3,17:17.0
4,4,17:17.0
4,7,17:106.4
4,8,17:106.4
4,9,17:106.4
4,17,17:18
4,28,17:18.0
4,29,17:18.0
4,30,17:18.0
5,-12,17:106.4
5,-11,17:106.4
5,-1,17:17.0
5,0,17:17.0
5,1,17:17.0
5,2,17:17.0
5,16,17:18
5,17,17:18
5,18,17:18
5,29,17:18.0
6,-20,17:18
6,-1,17:17.0
6,0,17:17.0
6,1,17:17.0
6,2,17:17.0
6,17,17:18
7,-21,17:18
7,-20,17:18
7,-19,17:18
7,0,17:17.0
7,1,17:17.0
7,2,17:17.0
8,-20,17:18
8,-2,17:106.8
8,-1,17:17.0
8,0,17:17.0
8,1,17:17.0
8,2,17:17.0
8,19,17:106.2
8,25,17:18
9,-1,17:106.4
9,17,17:106.4
9,18,17:106.4
10,5,17:106.1
11,0,17:18
11,6,17:106.2
12,-2,17:18
12,-1,17:18
12,0,17:18
12,1,17:18
12,2,17:18
12,6,17:106.2
13,-5,17:18
14,-6,17:18
14,-5,17:18
14,-4,17:18
14,0,17:18
14,1,17:18
15,-5,17:18
15,0,17:18
19,8,17:18
20,7,17:18
20,8,17:18
20,9,17:18
21,8,17:18
22,-8,17:18
24,5,17:106.2
25,4,17:106.4
-32,-4,18:18
-31,-4,18:18
-28,-4,18:17.0
-26,-1,18:18.0
-26,0,18:18.0
-26,5,18:106.2
-25,-8,18:18
-25,-2,18:18.0
-25,5,18:106.2
-24,-9,18:18
-24,-8,18:18
-24,-7,18:18
-24,-3,18:18.0
-24,5,18:106.2
-23,-8,18:18
-23,-4,18:18.0
-23,3,18:18.0
-23,8,18:18
-22,-4,18:18.0
-22,3,18:18.0
-22,7,18:18
-22,8,18:18
-22,9,18:18
-21,-3,18:18.0
-21,2,18:18.0
-21,8,18:18
-20,-2,18:18.0
-20,1,18:18.0
-19,-1,18:18.0
-19,0,18:18.0
-18,-5,18:18
-18,0,18:18
-17,-6,18:18
-17,-5,18:18
-17,-4,18:18
-17,-3,18:17.0
-17,0,18:17.0
-17,1,18:18
-16,-7,18:18
-16,-6,18:18
-16,-5,18:18
-16,-4,18:18
-16,-3,18:18
-16,-1,18:18
-16,0,18:18
-16,1,18:18
-16,2,18:18
-15,-6,18:18
-15,-5,18:18
-15,-4,18:18
-15,-1,18:18
-15,0,18:18
-15,1,18:18
-14,-5,18:18
-14,-4,18:18
-14,-2,18:18
-14,-1,18:18
-14,0,18:17.0
-14,1,18:18
-14,2,18:18
-13,0,18:18
-13,1,18:18
-13,2,18:18
-12,-1,18:17.0
-12,0,18:17.0
-12,1,18:17.0
-12,2,18:17.0
-11,-1,18:17.0
-11,0,18:17.0
-11,1,18:17.0
-11,2,18:17.0
-10,-22,18:18
-10,-6,18:106.8
-10,-1,18:17.0
-10,0,18:17.0
-10,1,18:17.0
-10,2,18:17.0
-9,-23,18:18
-9,-22,18:18
-9,-21,18:18
-9,-6,18:106.8
-9,-1,18:17.0
-9,0,18:17.0
-9,1,18:17.0
-9,2,18:17.0
-9,23,18:18
-8,-22,18:18
-8,-14,18:18
-8,-6,18:106.8
-8,-1,18:17.0
-8,0,18:17.0
-8,1,18:17.0
-8,2,18:17.0
-8,7,18:18
-8,22,18:18
-8,23,18:18
-8,24,18:18
-7,-15,18:18
-7,-14,18:18
-7,-13,18:18
-7,-2,18:17.0
-7,-1,18:17.0
-7,0,18:17.0
-7,1,18:17.0
-7,2,18:17.0
-7,3,18:17.0
-7,23,18:18
-6,-31,18:106.1
-6,-16,18:18
-6,-15,18:18
-6,-14,18:18
-6,-13,18:18
-6,-12,18:18
-6,-2,18:17.0
-6,-1,18:17.0
-6,0,18:17.0
-6,1,18:17.0
-6,2,18:17.0
-6,3,18:17.0
-6,4,18:17.0
-5,-32,18:106.8
-5,-30,18:18
-5,-29,18:18
-5,-26,18:17.0
-5,-21,18:18.0
-5,-20,18:18.0
-5,-15,18:18
-5,-14,18:18
-5,-13,18:18
-5,-3,18:18.0
-5,-2,18:18.0
-5,-1,18:18
-5,0,18:17.0
-5,1,18:17.0
-5,2,18:17.0
-5,3,18:17.0
-4,-31,18:106.4
-4,-22,18:18.0
-4,-19,18:18.0
-4,-14,18:18
-4,-3,18:18.0
-4,-2,18:18.0
-4,-1,18:17.0
-4,4,18:17.0
-4,7,18:17.0
-4,25,18:18.0
-3,-23,18:18.0
-3,-18,18:18.0
-3,-12,18:18
-3,-5,18:17.0
-3,-4,18:17.0
-3,-3,18:17.0
-3,-2,18:17.0
-3,5,18:17.0
-3,7,18:17.0
-3,8,18:17.0
-3,23,18:18.0
-3,24,18:18.0
-2,-24,18:18.0
-2,-17,18:18.0
-2,-14,18:18
-2,-13,18:18
-2,-12,18:18
-2,-10,18:17.0
-2,-9,18:17.0
-2,-8,18:17.0
-2,-7,18:17.0
-2,-6,18:17.0
-2,-5,18:17.0
-2,-4,18:17.0
-2,-3,18:17.0
-2,6,18:17.0
-2,7,18:17.0
-2,8,18:17.0
-2,9,18:17.0
-2,10,18:17.0
-2,11,18:17.0
-2,12,18:17.0
-2,13,18:17.0
-2,14,18:18
-2,15,18:18
-2,17,18:18
-2,22,18:18.0
-2,25,18:18.0
-1,-24,18:18.0
-1,-17,18:18.0
-1,-16,18:18
-1,-15,18:17.0
-1,-14,18:18
-1,-13,18:18
-1,-12,18:17.0
-1,-11,18:18
-1,-10,18:17.0
-1,-9,18:17.0
-1,-8,18:17.0
-1,-7,18:17.0
-1,-6,18:17.0
-1,-5,18:17.0
-1,-4,18:17.0
-1,-3,18:17.0
-1,1,18:5.0
-1,2,18:5.0
-1,6,18:17.0
-1,7,18:17.0
-1,8,18:17.0
-1,9,18:17.0
-1,10,18:17.0
-1,11,18:17.0
-1,12,18:17.0
-1,13,18:17.0
-1,14,18:18
-1,15,18:18
-1,16,18:18
-1,17,18:18
-1,18,18:18
-1,21,18:18.0
-1,26,18:18.0
0,-23,18:18.0
0,-18,18:18.0
0,-15,18:18
0,-14,18:18
0,-13,18:18
0,-12,18:18
0,-11,18:18
0,-10,18:17.0
0,-9,18:17.0
0,-8,18:17.0
0,-7,18:17.0
0,-6,18:17.0
0,-5,18:17.0
0,-4,18:17.0
0,-3,18:17.0
0,1,18:65.3
0,2,18:65.3
0,6,18:17.0
0,7,18:17.0
0,8,18:17.0
0,9,18:17.0
0,10,18:17.0
0,11,18:17.0
0,12,18:17.0
0,13,18:17.0
0,14,18:18
0,15,18:17.0
0,16,18:18
0,17,18:18
0,18,18:17.0
0,19,18:18
0,20,18:18.0
0,27,18:18.0
1,-22,18:18.0
1,-19,18:18.0
1,-14,18:18
1,-12,18:18
1,-11,18:18
1,-10,18:17.0
1,-9,18:17.0
1,-8,18:17.0
1,-7,18:17.0
1,-6,18:17.0
1,-5,18:17.0
1,-4,18:17.0
1,-3,18:17.0
1,6,18:17.0
1,7,18:17.0
1,8,18:17.0
1,9,18:17.0
1,10,18:17.0
1,11,18:17.0
1,12,18:17.0
1,13,18:17.0
1,15,18:18
1,16,18:18
1,17,18:18
1,20,18:18.0
1,27,18:18.0
2,-21,18:18.0
2,-20,18:18.0
2,-5,18:17.0
2,-4,18:17.0
2,-3,18:17.0
2,-2,18:17.0
2,5,18:17.0
2,7,18:17.0
2,8,18:17.0
2,15,18:18
2,21,18:18.0
2,26,18:18.0
3,-4,18:17.0
3,-1,18:17.0
3,4,18:17.0
3,17,18:18
3,22,18:18.0
3,25,18:18.0
4,-2,18:17.0
4,-1,18:17.0
4,0,18:17.0
4,1,18:17.0
4,2,18:17.0
4,3,18:17.0
4,4,18:17.0
4,7,18:106.4
4,8,18:106.4
4,9,18:106.4
4,16,18:18
4,17,18:18
4,18,18:18
4,23,18:18.0
4,24,18:18.0
4,29,18:17.0
4,32,18:18
4,33,18:18
5,-12,18:106.4
5,-11,18:106.4
5,-2,18:17.0
5,-1,18:17.0
5,0,18:17.0
5,1,18:17.0
5,2,18:17.0
5,3,18:17.0
5,15,18:18
5,16,18:18
5,17,18:18
5,18,18:18
5,19,18:18
6,-20,18:18
6,-1,18:17.0
6,0,18:17.0
6,1,18:17.0
6,2,18:17.0
6,7,18:18
6,16,18:18
6,17,18:18
6,18,18:18
7,-21,18:18
7,-20,18:18
7,-19,18:18
7,-1,18:17.0
7,0,18:17.0
7,1,18:17.0
7,2,18:17.0
7,17,18:18
7,25,18:18
8,-20,18:18
8,-1,18:17.0
8,0,18:17.0
8,1,18:17.0
8,2,18:17.0
8,19,18:106.2
8,24,18:18
8,25,18:18
8,26,18:18
9,-1,18:17.0
9,0,18:17.0
9,1,18:17.0
9,2,18:17.0
9,17,18:106.4
9,18,18:106.4
9,25,18:18
10,-1,18:17.0
10,0,18:17.0
10,1,18:17.0
10,2,18:17.0
10,5,18:106.1
11,0,18:18
11,1,18:18
11,2,18:18
11,6,18:106.2
12,-5,18:18
12,-2,18:18
12,-1,18:18
12,0,18:17.0
12,1,18:18
12,2,18:18
12,6,18:106.2
13,-6,18:18
13,-5,18:18
13,-4,18:18
13,-1,18:18
13,0,18:18
13,1,18:18
14,-7,18:18
14,-6,18:18
14,-5,18:18
14,-4,18:18
14,-3,18:18
14,-1,18:18
14,0,18:18
14,1,18:18
14,2,18:18
15,-6,18:18
15,-5,18:18
15,-4,18:18
15,0,18:17.0
15,1,18:18
16,-5,18:18
16,0,18:18
17,-1,18:18.0
17,0,18:18.0
18,-2,18:18.0
18,1,18:18.0
19,-3,18:18.0
19,2,18:18.0
19,8,18:18
20,-4,18:18.0
20,3,18:18.0
20,7,18:18
20,8,18:18
20,9,18:18
21,-8,18:18
21,-4,18:18.0
21,3,18:18.0
21,8,18:18
22,-9,18:18
22,-8,18:18
22,-7,18:18
22,-3,18:18.0
23,-8,18:18
23,-2,18:18.0
24,-1,18:18.0
24,0,18:18.0
24,5,18:106.2
25,4,18:106.4
26,-4,18:17.0
29,-4,18:18
30,-4,18:18
-33,-4,19:18
-32,-5,19:18
-32,-4,19:18
-32,-3,19:18
-31,-5,19:18
-31,-4,19:17.0
-31,-3,19:18
-30,-4,19:17.0
-29,-4,19:17.0
-28,-4,19:17.0
-27,-4,19:17.0
-27,-3,19:17.0
-27,-2,19:17.0
-26,-4,19:17.0
-26,-2,19:17.0
-26,-1,19:18.0
-26,0,19:18.0
-26,4,19:17.0
-26,5,19:106.2
-25,-7,19:17.0
-25,-4,19:17.0
-25,-2,19:18.0
-25,4,19:17.0
-25,5,19:106.2
-24,-8,19:17.0
-24,-7,19:17.0
-24,-6,19:17.0
-24,-4,19:17.0
-24,-3,19:18.0
-24,-2,19:17.0
-24,4,19:17.0
-24,5,19:106.2
-23,-6,19:17.0
-23,-5,19:17.0
-23,-4,19:18.0
-23,-3,19:17.0
-23,-2,19:17.0
-23,-1,19:17.0
-23,0,19:17.0
-23,3,19:18.0
-23,4,19:17.0
-22,-4,19:18.0
-22,0,19:17.0
-22,3,19:18.0
-22,4,19:17.0
-22,5,19:17.0
-22,6,19:17.0
-22,7,19:17.0
-22,8,19:17.0
-21,-6,19:17.0
-21,-5,19:17.0
-21,-4,19:17.0
-21,-3,19:18.0
-21,0,19:17.0
-21,1,19:17.0
-21,2,19:18.0
-21,3,19:17.0
-20,-4,19:17.0
-20,-3,19:17.0
-20,-2,19:18.0
-20,0,19:17.0
-20,1,19:18.0
-19,-4,19:17.0
-19,-3,19:17.0
-19,-1,19:18.0
-19,0,19:18.0
-18,-4,19:17.0
-18,-3,19:17.0
-18,1,19:18
-17,-5,19:18
-17,-4,19:18
-17,-3,19:17.0
-17,-2,19:17.0
-17,-1,19:18
-17,0,19:17.0
-17,1,19:18
-17,2,19:18
-16,-6,19:18
-16,-5,19:18
-16,-4,19:18
-16,-3,19:17.0
-16,-2,19:18
-16,-1,19:18
-16,0,19:18
-16,1,19:18
-16,2,19:18
-16,3,19:18
-15,-5,19:18
-15,-1,19:18
-15,0,19:17.0
-15,1,19:17.0
-15,2,19:18
-14,-4,19:18
-14,-3,19:18
-14,-2,19:17.0
-14,-1,19:17.0
-14,0,19:17.0
-14,1,19:17.0
-14,2,19:17.0
-14,5,19:18
-13,-3,19:18
-13,-2,19:17.0
-13,-1,19:17.0
-13,0,19:17.0
-13,1,19:17.0
-13,2,19:17.0
-13,3,19:17.0
-13,4,19:17.0
-13,5,19:17.0
-13,7,19:18
-12,-3,19:20
-12,-2,19:20
-12,-1,19:17.0
-12,0,19:17.0
-12,1,19:17.0
-12,2,19:17.0
-11,-3,19:20
-11,-2,19:20
-11,-1,19:17.0
-11,0,19:17.0
-11,1,19:17.0
-11,2,19:17.0
-10,-6,19:106.8
-10,-3,19:20
-10,-2,19:20
-10,-1,19:17.0
-10,0,19:17.0
-10,1,19:17.0
-10,2,19:17.0
-9,-22,19:17.0
-9,-6,19:106.8
-9,-3,19:20
-9,-2,19:20
-9,-1,19:17.0
-9,0,19:17.0
-9,1,19:17.0
-9,2,19:17.0
-9,3,19:17.0
-9,6,19:18
-9,7,19:18
-8,-23,19:17.0
-8,-22,19:17.0
-8,-6,19:106.8
-8,-5,19:17.0
-8,-4,19:17.0
-8,-3,19:17.0
-8,-2,19:17.0
-8,-1,19:17.0
-8,0,19:17.0
-8,1,19:17.0
-8,2,19:17.0
-8,7,19:18
-8,23,19:17.0
-7,-22,19:17.0
-7,-21,19:17.0
-7,-19,19:17.0
-7,-14,19:18
-7,-4,19:18
-7,-3,19:18
-7,-2,19:18
-7,-1,19:17.0
-7,0,19:17.0
-7,1,19:17.0
-7,2,19:17.0
-7,3,19:17.0
-7,14,19:18
-7,23,19:17.0
-6,-31,19:106.1
-6,-30,19:18
-6,-29,19:18
-6,-21,19:17.0
-6,-19,19:17.0
-6,-15,19:18
-6,-14,19:18
-6,-13,19:18
-6,-3,19:18
-6,-2,19:18
-6,-1,19:17.0
-6,0,19:17.0
-6,1,19:17.0
-6,2,19:17.0
-6,3,19:17.0
-6,4,19:17.0
-6,23,19:17.0
-5,-32,19:106.8
-5,-31,19:18
-5,-30,19:18
-5,-29,19:17.0
-5,-28,19:17.0
-5,-27,19:17.0
-5,-26,19:17.0
-5,-25,19:17.0
-5,-24,19:17.0
-5,-23,19:17.0
-5,-22,19:17.0
-5,-21,19:18.0
-5,-20,19:18.0
-5,-19,19:17.0
-5,-18,19:17.0
-5,-14,19:18
-5,-1,19:18
-5,0,19:17.0
-5,1,19:17.0
-5,2,19:17.0
-5,3,19:17.0
-5,14,19:17.0
-5,15,19:18
-5,23,19:17.0
-5,25,19:18.0
-4,-31,19:106.4
-4,-30,19:18
-4,-29,19:18
-4,-25,19:17.0
-4,-22,19:18.0
-4,-21,19:17.0
-4,-19,19:18.0
-4,-6,19:17.0
-4,-5,19:18
-4,-4,19:18
-4,-1,19:17.0
-4,0,19:5.0
-4,1,19:5.0
-4,2,19:5.0
-4,3,19:5.0
-4,4,19:17.0
-4,7,19:17.0
-4,14,19:17.0
-4,23,19:17.0
-4,24,19:18.0
-4,25,19:18.0
-4,26,19:18.0
-4,27,19:17.0
-3,-25,19:17.0
-3,-24,19:17.0
-3,-23,19:18.0
-3,-22,19:17.0
-3,-21,19:17.0
-3,-18,19:18.0
-3,-14,19:18
-3,-12,19:17.0
-3,-11,19:17.0
-3,-10,19:20
-3,-9,19:20
-3,-8,19:20
-3,-7,19:20
-3,-6,19:17.0
-3,-2,19:17.0
-3,-1,19:5.0
-3,0,19:44.2
-3,1,19:43.2
-3,2,19:43.2
-3,3,19:44.2
-3,4,19:5.0
-3,5,19:17.0
-3,7,19:17.0
-3,8,19:17.0
-3,10,19:17.0
-3,14,19:17.0
-3,17,19:18
-3,22,19:17.0
-3,23,19:18.0
-3,24,19:18.0
-3,25,19:18.0
-2,-24,19:18.0
-2,-21,19:17.0
-2,-17,19:18.0
-2,-15,19:18
-2,-14,19:18
-2,-13,19:18
-2,-12,19:17.0
-2,-11,19:17.0
-2,-10,19:17.0
-2,-9,19:17.0
-2,-8,19:17.0
-2,-7,19:17.0
-2,-6,19:17.0
-2,-5,19:17.0
-2,-4,19:17.0
-2,-3,19:17.0
-2,-2,19:5.0
-2,-1,19:44.2
-2,0,19:44.2
-2,1,19:44.2
-2,2,19:44.2
-2,3,19:44.2
-2,4,19:44.2
-2,5,19:5.0
-2,6,19:17.0
-2,7,19:17.0
-2,8,19:17.0
-2,9,19:17.0
-2,10,19:17.0
-2,11,19:17.0
-2,12,19:17.0
-2,13,19:17.0
-2,14,19:17.0
-2,15,19:17.0
-2,16,19:18
-2,17,19:18
-2,18,19:18
-2,22,19:18.0
-2,25,19:18.0
-1,-24,19:18.0
-1,-21,19:17.0
-1,-20,19:17.0
-1,-19,19:17.0
-1,-18,19:17.0
-1,-17,19:18.0
-1,-15,19:17.0
-1,-14,19:18
-1,-13,19:17.0
-1,-12,19:17.0
-1,-11,19:17.0
-1,-10,19:17.0
-1,-9,19:17.0
-1,-8,19:17.0
-1,-7,19:89
-1,-6,19:89
-1,-5,19:89
-1,-4,19:89
-1,-3,19:17.0
-1,-2,19:5.0
-1,-1,19:43.2
-1,0,19:44.2
-1,1,19:44.2
-1,2,19:44.2
-1,3,19:44.2
-1,4,19:43.2
-1,5,19:5.0
-1,6,19:17.0
-1,7,19:17.0
-1,8,19:17.0
-1,9,19:17.0
-1,10,19:22
-1,11,19:22
-1,12,19:22
-1,13,19:22
-1,14,19:17.0
-1,15,19:17.0
-1,16,19:17.0
-1,17,19:18
-1,18,19:18
-1,19,19:18
-1,21,19:18.0
-1,22,19:17.0
-1,26,19:18.0
0,-23,19:18.0
0,-19,19:17.0
0,-18,19:18.0
0,-16,19:18
0,-15,19:18
0,-14,19:18
0,-13,19:17.0
0,-12,19:17.0
0,-11,19:17.0
0,-10,19:17.0
0,-9,19:17.0
0,-8,19:17.0
0,-7,19:89
0,-6,19:89
0,-5,19:89
0,-4,19:89
0,-3,19:17.0
0,-2,19:5.0
0,-1,19:43.2
0,0,19:44.2
0,3,19:44.2
0,4,19:43.2
0,5,19:5.0
0,6,19:17.0
0,7,19:17.0
0,8,19:17.0
0,9,19:17.0
0,10,19:22
0,11,19:22
0,12,19:22
0,13,19:22
0,14,19:17.0
0,15,19:17.0
0,16,19:17.0
0,17,19:18
0,18,19:17.0
0,20,19:18.0
0,21,19:17.0
0,22,19:17.0
0,23,19:17.0
0,24,19:17.0
0,27,19:18.0
1,-22,19:18.0
1,-19,19:18.0
1,-15,19:18
1,-14,19:18
1,-13,19:18
1,-12,19:17.0
1,-11,19:17.0
1,-10,19:17.0
1,-9,19:17.0
1,-8,19:17.0
1,-7,19:17.0
1,-6,19:17.0
1,-5,19:17.0
1,-4,19:17.0
1,-3,19:17.0
1,-2,19:5.0
1,-1,19:44.2
1,0,19:44.2
1,1,19:44.2
1,2,19:44.2
1,3,19:44.2
1,4,19:44.2
1,5,19:5.0
1,6,19:17.0
1,7,19:17.0
1,8,19:17.0
1,9,19:17.0
1,10,19:22
1,11,19:22
1,12,19:22
1,13,19:22
1,14,19:17.0
1,15,19:17.0
1,16,19:18
1,17,19:18
1,18,19:18
1,20,19:18.0
1,24,19:17.0
1,27,19:18.0
2,-21,19:18.0
2,-20,19:18.0
2,-19,19:17.0
2,-14,19:18
2,-11,19:17.0
2,-10,19:20
2,-9,19:20
2,-8,19:20
2,-7,19:17.0
2,-6,19:20
2,-5,19:17.0
2,-4,19:17.0
2,-3,19:17.0
2,-2,19:17.0
2,-1,19:5.0
2,0,19:44.2
2,1,19:43.2
2,2,19:43.2
2,3,19:44.2
2,4,19:5.0
2,5,19:17.0
2,9,19:17.0
2,10,19:20
2,11,19:20
2,12,19:20
2,13,19:20
2,14,19:17.0
2,15,19:17.0
2,17,19:18
2,21,19:18.0
2,24,19:17.0
2,25,19:17.0
2,26,19:18.0
2,27,19:17.0
2,28,19:17.0
3,-24,19:17.0
3,-23,19:17.0
3,-22,19:17.0
3,-21,19:17.0
3,-20,19:17.0
3,-11,19:17.0
3,-4,19:17.0
3,-2,19:20
3,-1,19:17.0
3,0,19:5.0
3,1,19:5.0
3,2,19:5.0
3,3,19:5.0
3,4,19:17.0
3,7,19:18
3,8,19:18
3,9,19:17.0
3,10,19:20
3,11,19:20
3,12,19:20
3,13,19:20
3,14,19:20
3,22,19:18.0
3,24,19:17.0
3,25,19:18.0
3,28,19:17.0
3,32,19:18
3,33,19:18
4,-20,19:17.0
4,-12,19:18
4,-11,19:17.0
4,-3,19:18
4,-2,19:20
4,-1,19:17.0
4,0,19:17.0
4,1,19:17.0
4,2,19:17.0
4,3,19:17.0
4,4,19:17.0
4,7,19:106.4
4,8,19:106.4
4,9,19:106.4
4,10,19:20
4,11,19:20
4,12,19:20
4,13,19:20
4,17,19:18
4,21,19:17.0
4,22,19:17.0
4,23,19:18.0
4,24,19:18.0
4,25,19:17.0
4,26,19:17.0
4,27,19:17.0
4,28,19:17.0
4,29,19:17.0
4,30,19:17.0
4,31,19:17.0
4,32,19:17.0
4,33,19:18
4,34,19:18
5,-20,19:17.0
5,-12,19:106.4
5,-11,19:106.4
5,-4,19:18
5,-3,19:18
5,-2,19:20
5,-1,19:17.0
5,0,19:17.0
5,1,19:17.0
5,2,19:17.0
5,3,19:17.0
5,4,19:20
5,10,19:20
5,11,19:20
5,12,19:20
5,13,19:20
5,16,19:18
5,17,19:18
5,18,19:18
5,22,19:17.0
5,24,19:17.0
5,29,19:18
5,32,19:18
5,33,19:18
6,-20,19:17.0
6,-12,19:106
6,-11,19:18
6,-5,19:17.0
6,-4,19:17.0
6,-3,19:17.0
6,-2,19:17.0
6,-1,19:17.0
6,0,19:17.0
6,1,19:17.0
6,2,19:17.0
6,3,19:20
6,7,19:18
6,17,19:18
6,22,19:17.0
6,24,19:17.0
6,25,19:17.0
7,-20,19:17.0
7,-3,19:20
7,-2,19:20
7,-1,19:17.0
7,0,19:17.0
7,1,19:17.0
7,2,19:17.0
7,3,19:17.0
7,6,19:18
7,7,19:18
7,19,19:106
7,25,19:17.0
7,26,19:17.0
8,-3,19:20
8,-2,19:20
8,-1,19:17.0
8,0,19:17.0
8,1,19:17.0
8,2,19:17.0
8,3,19:20
8,19,19:106.2
8,25,19:17.0
9,-3,19:20
9,-2,19:20
9,-1,19:17.0
9,0,19:17.0
9,1,19:17.0
9,2,19:17.0
9,17,19:106.4
9,18,19:106.4
10,-3,19:20
10,-2,19:20
10,-1,19:17.0
10,0,19:17.0
10,1,19:17.0
10,2,19:17.0
10,5,19:106.1
11,-3,19:20
11,-2,19:17.0
11,-1,19:17.0
11,0,19:17.0
11,1,19:17.0
11,2,19:17.0
11,3,19:17.0
11,4,19:17.0
11,5,19:17.0
11,6,19:106.2
11,7,19:18
12,-2,19:17.0
12,-1,19:17.0
12,0,19:17.0
12,1,19:17.0
12,2,19:17.0
12,5,19:18
12,6,19:106.2
13,-5,19:18
13,-1,19:18
13,0,19:17.0
13,1,19:17.0
13,2,19:18
14,-6,19:18
14,-5,19:18
14,-4,19:18
14,-2,19:18
14,-1,19:18
14,0,19:18
14,1,19:18
14,2,19:18
14,3,19:18
15,-5,19:18
15,-1,19:18
15,0,19:17.0
15,1,19:18
15,2,19:18
16,1,19:18
17,-2,19:50.4
17,-1,19:18.0
17,0,19:18.0
18,-4,19:17.0
18,-2,19:17.0
18,0,19:17.0
18,1,19:18.0
19,-6,19:17.0
19,-5,19:17.0
19,-4,19:17.0
19,-3,19:18.0
19,0,19:17.0
19,1,19:17.0
19,2,19:18.0
19,3,19:17.0
20,-4,19:18.0
20,0,19:17.0
20,3,19:18.0
20,4,19:17.0
20,5,19:17.0
20,6,19:17.0
20,7,19:17.0
20,8,19:17.0
21,-6,19:17.0
21,-5,19:17.0
21,-4,19:18.0
21,-3,19:17.0
21,-2,19:17.0
21,-1,19:17.0
21,0,19:17.0
21,3,19:18.0
21,4,19:17.0
22,-8,19:17.0
22,-7,19:17.0
22,-6,19:17.0
22,-4,19:17.0
22,-3,19:18.0
22,-2,19:17.0
22,4,19:17.0
23,-7,19:17.0
23,-4,19:17.0
23,-2,19:18.0
23,4,19:17.0
24,-4,19:17.0
24,-2,19:17.0
24,-1,19:18.0
24,0,19:18.0
24,4,19:17.0
24,5,19:106.2
25,-4,19:17.0
25,-3,19:17.0
25,-2,19:17.0
25,4,19:106.4
26,-4,19:17.0
27,-4,19:17.0
28,-4,19:17.0
29,-5,19:18
29,-4,19:17.0
29,-3,19:18
30,-5,19:18
30,-4,19:18
30,-3,19:18
31,-4,19:18
-32,-4,20:18
-31,-4,20:18
-29,-4,20:17.0
-27,-6,20:18.0
-27,-5,20:18.0
-27,-4,20:18.0
-27,-3,20:18.0
-27,-2,20:18.0
-26,-6,20:18.0
-26,-5,20:18.0
-26,-4,20:18.0
-26,-3,20:18.0
-26,-2,20:18.0
-26,-1,20:17.0
-26,4,20:17.0
-25,-7,20:17.0
-25,-6,20:18.0
-25,-5,20:18.0
-25,-4,20:17.0
-25,-3,20:18.0
-25,-2,20:18.0
-25,-1,20:18.0
-25,0,20:18.0
-24,-8,20:17.0
-24,-6,20:18.0
-24,-5,20:18.0
-24,-4,20:18.0
-24,-3,20:18.0
-24,-2,20:18.0
-23,-6,20:18.0
-23,-5,20:18.0
-23,-4,20:18.0
-23,-3,20:18.0
-23,-1,20:18
-23,0,20:18
-22,-6,20:18.0
-22,-5,20:18.0
-22,-4,20:18.0
-22,-3,20:18.0
-22,-2,20:18.0
-22,-1,20:18
-22,0,20:18
-22,8,20:17.0
-21,-6,20:18
-21,-5,20:18.0
-21,-4,20:41
-21,-3,20:41
-21,-2,20:17.0
-21,-1,20:17.0
-21,0,20:17.0
-21,1,20:18.0
-20,-6,20:18.0
-20,-5,20:18.0
-20,-4,20:41
-20,-3,20:41
-20,-2,20:17.0
-20,-1,20:17.0
-20,0,20:18.0
-19,-6,20:18.0
-19,-5,20:18.0
-19,-4,20:41
-19,-3,20:41
-19,-2,20:17.0
-19,-1,20:17.0
-19,0,20:18.0
-19,1,20:18.0
-18,-7,20:18
-18,-6,20:18.0
-18,-5,20:18.0
-18,-4,20:41
-18,-3,20:41
-18,-2,20:17.0
-18,-1,20:17.0
-18,0,20:18.0
-18,1,20:18.0
-18,2,20:18.0
-17,-8,20:18
-17,-7,20:18
-17,-6,20:18
-17,-5,20:18
-17,-4,20:41
-17,-3,20:41
-17,-2,20:41
-17,-1,20:41
-17,0,20:17.0
-17,1,20:18
-17,2,20:18.0
-16,-8,20:18
-16,-7,20:18
-16,-6,20:18
-16,-5,20:17.0
-16,-4,20:41
-16,-3,20:41
-16,-2,20:41
-16,-1,20:41
-16,0,20:18
-16,1,20:18
-16,2,20:18
-15,-6,20:18
-15,-5,20:17.0
-15,-4,20:17.0
-15,-3,20:17.0
-15,-2,20:17.0
-15,-1,20:17.0
-15,0,20:17.1
-15,1,20:18
-15,2,20:18.0
-15,5,20:18
-14,-3,20:17.0
-14,-2,20:17.0
-14,-1,20:17.0
-14,0,20:44.2
-14,1,20:20
-14,5,20:17.0
-14,6,20:18
-14,7,20:18
-13,-3,20:17.1
-13,-2,20:44.2
-13,-1,20:44.2
-13,0,20:44.2
-13,1,20:17.0
-13,5,20:17.0
-13,6,20:18
-13,7,20:18
-12,-3,20:20
-12,1,20:20
-12,2,20:20
-12,6,20:18
-12,7,20:18
-11,-3,20:20
-11,2,20:20
-10,-6,20:106.8
-10,-3,20:20
-10,2,20:20
-10,7,20:18
-10,8,20:18
-10,9,20:18
-9,-22,20:17.0
-9,-15,20:18
-9,-14,20:18
-9,-6,20:106.8
-9,-3,20:20
-9,2,20:20
-9,3,20:17.0
-9,5,20:17.0
-9,6,20:17.0
-9,7,20:17.0
-9,8,20:18
-8,-23,20:17.0
-8,-16,20:18
-8,-15,20:18
-8,-14,20:18
-8,-6,20:106.8
-8,-5,20:17.0
-8,-3,20:17.0
-8,-2,20:20
-8,2,20:20
-8,6,20:18
-8,7,20:17.0
-8,8,20:18
-8,23,20:17.0
-7,-25,20:18.0
-7,-24,20:18.0
-7,-23,20:18.0
-7,-22,20:18.0
-7,-21,20:18.0
-7,-20,20:18.0
-7,-19,20:18.0
-7,-18,20:18.0
-7,-17,20:18.0
-7,-16,20:18.0
-7,-15,20:18
-7,-14,20:18
-7,-13,20:18
-7,-6,20:17.0
-7,-5,20:17.0
-7,-1,20:20
-7,3,20:20
-7,7,20:18
-7,13,20:18
-7,14,20:18
-7,15,20:18
-7,23,20:50.5
-6,-25,20:18.0
-6,-24,20:18.0
-6,-23,20:18.0
-6,-22,20:18.0
-6,-21,20:18.0
-6,-20,20:18.0
-6,-19,20:18.0
-6,-18,20:18.0
-6,-17,20:18.0
-6,-16,20:18.0
-6,-15,20:18
-6,-14,20:17.0
-6,-13,20:17.0
-6,-6,20:17.0
-6,-4,20:18
-6,-1,20:20
-6,3,20:20
-6,4,20:17.0
-6,13,20:18
-6,14,20:18
-6,15,20:18
-6,25,20:18.0
-5,-30,20:18
-5,-29,20:18
-5,-27,20:17.0
-5,-26,20:50.5
-5,-25,20:18.0
-5,-24,20:18.0
-5,-23,20:17.0
-5,-22,20:18.0
-5,-21,20:18.0
-5,-20,20:18.0
-5,-19,20:18.0
-5,-18,20:17.0
-5,-17,20:18.0
-5,-16,20:18.0
-5,-13,20:17.0
-5,-12,20:18
-5,-1,20:20
-5,0,20:50.4
-5,3,20:20
-5,10,20:18.0
-5,14,20:17.0
-5,15,20:17.0
-5,16,20:18
-5,24,20:18.0
-5,25,20:18.0
-5,26,20:18.0
-4,-25,20:18.0
-4,-24,20:18.0
-4,-23,20:18.0
-4,-22,20:18.0
-4,-21,20:18.0
-4,-20,20:18.0
-4,-19,20:18.0
-4,-18,20:18.0
-4,-17,20:18.0
-4,-16,20:18.0
-4,-15,20:18
-4,-14,20:18
-4,-13,20:17.0
-4,-12,20:17.0
-4,-6,20:17.0
-4,0,20:5.0
-4,1,20:64.3
-4,2,20:64.6
-4,3,20:5.0
-4,7,20:17.0
-4,23,20:18.0
-4,24,20:18.0
-4,25,20:18.0
-4,26,20:18.0
-4,27,20:18.0
-3,-25,20:18.0
-3,-24,20:18.0
-3,-23,20:18.0
-3,-22,20:18.0
-3,-20,20:18.0
-3,-19,20:18.0
-3,-18,20:18.0
-3,-17,20:18.0
-3,-16,20:18.0
-3,-15,20:18
-3,-14,20:18
-3,-13,20:18.0
-3,-12,20:17.0
-3,-10,20:20
-3,-9,20:20
-3,-8,20:20
-3,-7,20:20
-3,-6,20:20
-3,-5,20:20
-3,-4,20:20
-3,-3,20:20
-3,-1,20:5.0
-3,0,20:50.1
-3,3,20:50.2
-3,4,20:5.0
-3,10,20:17.0
-3,24,20:18.0
-3,25,20:18.0
-3,26,20:18.0
-2,-24,20:17.0
-2,-23,20:18.0
-2,-18,20:18.0
-2,-17,20:18.0
-2,-16,20:18.0
-2,-15,20:18.0
-2,-14,20:18
-2,-13,20:18.0
-2,-11,20:20
-2,-10,20:61.5
-2,-7,20:54.3
-2,-6,20:54.3
-2,-5,20:58
-2,-4,20:58
-2,-3,20:50.2
-2,-2,20:5.0
-2,-1,20:50.3
-2,4,20:50.3
-2,5,20:5.0
-2,6,20:20
-2,7,20:20
-2,8,20:20
-2,9,20:20
-2,10,20:20
-2,11,20:20
-2,12,20:20
-2,13,20:20
-2,14,20:20
-2,16,20:18.0
-2,17,20:18
-2,18,20:18.0
-2,19,20:18.0
-2,23,20:18.0
-2,24,20:18.0
-2,25,20:18.0
-1,-23,20:18.0
-1,-18,20:18.0
-1,-17,20:18.0
-1,-16,20:18.0
-1,-15,20:17.0
-1,-14,20:18
-1,-13,20:18
-1,-11,20:20
-1,-10,20:61.5
-1,-2,20:64.5
-1,5,20:64.4
-1,14,20:17.0
-1,16,20:18
-1,17,20:18
-1,18,20:18
-1,19,20:18.0
-1,20,20:18.0
-1,22,20:18.0
-1,25,20:18.0
0,-22,20:18.0
0,-19,20:18.0
0,-17,20:18.0
0,-16,20:18.0
0,-15,20:18
0,-14,20:18
0,-13,20:18
0,-11,20:17.0
0,-10,20:61.5
0,-2,20:64.2
0,5,20:64.3
0,14,20:20
0,16,20:18
0,17,20:18
0,18,20:17.0
0,19,20:18.0
0,20,20:18.0
0,21,20:18.0
0,26,20:18.0
1,-21,20:18.0
1,-20,20:18.0
1,-16,20:18.0
1,-15,20:18.0
1,-14,20:18
1,-13,20:18.0
1,-11,20:20
1,-10,20:61.5
1,-7,20:54.2
1,-6,20:54.2
1,-5,20:58
1,-4,20:58
1,-3,20:50.2
1,-2,20:5.0
1,-1,20:50.4
1,4,20:50.4
1,5,20:5.0
1,6,20:20
1,7,20:20
1,8,20:20
1,9,20:20
1,14,20:20
1,16,20:18.0
1,17,20:18
1,18,20:18.0
1,19,20:18.0
1,20,20:18.0
1,21,20:18.0
1,26,20:18.0
1,27,20:17.0
2,-10,20:20
2,-9,20:20
2,-8,20:20
2,-7,20:17.0
2,-6,20:20
2,-5,20:20
2,-4,20:20
2,-3,20:20
2,-2,20:20
2,-1,20:5.0
2,0,20:50.1
2,3,20:50.2
2,4,20:5.0
2,9,20:20
2,14,20:20
2,15,20:17.0
2,16,20:18.0
2,17,20:18
2,18,20:18
2,19,20:18.0
2,20,20:18.0
2,21,20:18.0
2,22,20:18.0
2,23,20:18.0
2,25,20:18.0
2,26,20:18.0
2,27,20:18.0
2,28,20:18.0
3,-24,20:17.0
3,-4,20:17.0
3,-2,20:20
3,0,20:5.0
3,1,20:64.4
3,2,20:64.1
3,3,20:5.0
3,9,20:17.0
3,10,20:102
3,13,20:102
3,14,20:20
3,15,20:17.0
3,16,20:17.0
3,17,20:18
3,18,20:18
3,19,20:18.0
3,20,20:18.0
3,21,20:18.0
3,22,20:18.0
3,23,20:18.0
3,24,20:18.0
3,25,20:18.0
3,26,20:18.0
3,27,20:18.0
3,28,20:18.0
4,-13,20:18
4,-12,20:17.0
4,-11,20:17.0
4,-6,20:17.0
4,-4,20:18
4,-2,20:20
4,4,20:17.0
4,5,20:50.1
4,7,20:106.4
4,8,20:106.4
4,9,20:106.4
4,10,20:102
4,13,20:102
4,16,20:17.0
4,19,20:18.0
4,20,20:18.0
4,21,20:17.0
4,22,20:18.0
4,23,20:18.0
4,24,20:18.0
4,25,20:18.0
4,26,20:17.0
4,27,20:18.0
4,28,20:18.0
4,29,20:50.5
4,30,20:17.0
4,32,20:18
4,33,20:18
5,-12,20:18
5,-11,20:18
5,-10,20:18
5,-6,20:17.0
5,-5,20:17.0
5,-2,20:20
5,4,20:20
5,7,20:18
5,10,20:102
5,11,20:102
5,12,20:102
5,13,20:102
5,16,20:17.0
5,17,20:17.0
5,18,20:18
5,19,20:18.0
5,20,20:18.0
5,21,20:18.0
5,22,20:18.0
5,23,20:18.0
5,24,20:18.0
5,25,20:18.0
5,26,20:18.0
5,27,20:18.0
5,28,20:18.0
5,29,20:18
6,-12,20:18
6,-11,20:18
6,-10,20:18
6,-5,20:17.0
6,-3,20:17.0
6,-2,20:20
6,4,20:20
6,6,20:18
6,7,20:17.0
6,8,20:18
6,16,20:18
6,17,20:18
6,18,20:18
6,19,20:18.0
6,20,20:18.0
6,21,20:18.0
6,22,20:18.0
6,23,20:18.0
6,24,20:18.0
6,25,20:18.0
6,26,20:18.0
6,27,20:18.0
6,28,20:18.0
7,-20,20:17.0
7,-3,20:20
7,3,20:17.0
7,5,20:17.0
7,6,20:17.0
7,7,20:17.0
7,8,20:18
7,17,20:18
7,18,20:18
7,19,20:18
7,26,20:17.0
8,-3,20:20
8,3,20:20
8,7,20:18
8,8,20:18
8,9,20:18
8,17,20:18
8,18,20:18
8,19,20:106.2
8,25,20:17.0
9,-3,20:20
9,3,20:20
9,17,20:106.4
9,18,20:106.4
10,-3,20:20
10,1,20:54.2
10,2,20:54.2
10,3,20:20
10,6,20:18
10,7,20:18
11,-3,20:20
11,-2,20:44.2
11,-1,20:44.2
11,0,20:44.2
11,1,20:17.0
11,2,20:20
11,5,20:17.0
11,6,20:18
11,7,20:18
12,-3,20:17.0
12,-2,20:17.0
12,-1,20:17.0
12,0,20:44.2
12,1,20:20
12,5,20:17.0
12,6,20:18
12,7,20:18
13,-6,20:18
13,-5,20:17.0
13,-4,20:17.0
13,-3,20:17.0
13,-2,20:18.0
13,-1,20:18.0
13,0,20:18
13,1,20:18
13,2,20:18.0
13,5,20:18
14,-8,20:18
14,-7,20:18
14,-6,20:18
14,-5,20:17.0
14,-4,20:18
14,-2,20:18
14,-1,20:18
14,0,20:18
14,1,20:18
14,2,20:18
15,-8,20:18
15,-7,20:18
15,-6,20:18
15,-5,20:18
15,-4,20:18
15,-2,20:18
15,-1,20:18.0
15,0,20:17.0
15,1,20:18
15,2,20:18.0
16,-7,20:18
16,-6,20:18.0
16,-5,20:18.0
16,-4,20:18.0
16,-3,20:18.0
16,-2,20:18.0
16,-1,20:18.0
16,0,20:18.0
16,1,20:18.0
16,2,20:18.0
17,-6,20:18.0
17,-5,20:18.0
17,-4,20:18.0
17,-3,20:18.0
17,-2,20:18.0
17,-1,20:18.0
17,0,20:18.0
17,1,20:18.0
18,-6,20:18.0
18,-5,20:18.0
18,-4,20:17.0
18,-3,20:18.0
18,-2,20:18.0
18,-1,20:18.0
18,0,20:18.0
19,-6,20:18.0
19,-5,20:18.0
19,-4,20:18.0
19,-3,20:18.0
19,-2,20:18.0
19,1,20:18.0
20,-6,20:18.0
20,-5,20:18.0
20,-4,20:18.0
20,-3,20:18.0
20,-2,20:18.0
20,8,20:17.0
21,-6,20:18.0
21,-5,20:18.0
21,-4,20:18.0
21,-3,20:18.0
22,-8,20:17.0
22,-6,20:18.0
22,-5,20:18.0
22,-4,20:18.0
22,-3,20:18.0
22,-2,20:18.0
23,-7,20:17.0
23,-6,20:18.0
23,-5,20:18.0
23,-4,20:17.0
23,-3,20:18.0
23,-2,20:18.0
23,-1,20:18.0
23,0,20:18.0
23,4,20:106.1
24,-6,20:18.0
24,-5,20:18.0
24,-4,20:18.0
24,-3,20:18.0
24,-2,20:18.0
24,-1,20:17.0
24,4,20:17.0
24,5,20:106.2
25,-6,20:18.0
25,-5,20:18.0
25,-4,20:18.0
25,-3,20:18.0
25,-2,20:18.0
25,4,20:106.4
27,-4,20:17.0
29,-4,20:18
30,-4,20:18
-29,-4,21:17.0
-27,-5,21:18.0
-27,-4,21:18.0
-27,-3,21:18.0
-27,-2,21:18.0
-27,-1,21:18.0
-26,-6,21:18.0
-26,-5,21:18.0
-26,-4,21:18.0
-26,-3,21:18.0
-26,-2,21:18.0
-26,-1,21:17.0
-26,0,21:18.0
-26,4,21:17.0
-25,-9,21:18
-25,-8,21:18
-25,-7,21:17.0
-25,-6,21:18.0
-25,-5,21:18.0
-25,-4,21:17.0
-25,-3,21:18.0
-25,-2,21:18.0
-25,-1,21:18.0
-24,-9,21:18
-24,-8,21:17.0
-24,-7,21:18
-24,-6,21:18.0
-24,-5,21:18.0
-24,-4,21:18.0
-24,-3,21:18.0
-24,-2,21:18.0
-24,-1,21:18.0
-24,0,21:18.0
-24,7,21:18.0
-24,8,21:18.0
-24,9,21:18.0
-23,-8,21:18
-23,-6,21:18.0
-23,-5,21:18.0
-23,-4,21:18.0
-23,-3,21:18.0
-23,-2,21:18.0
-23,0,21:18
-23,1,21:18.0
-23,6,21:18.0
-23,7,21:18.0
-23,8,21:18.0
-23,9,21:18.0
-23,10,21:18.0
-22,-6,21:18.0
-22,-5,21:18.0
-22,-4,21:18.0
-22,-3,21:18.0
-22,-2,21:18.0
-22,-1,21:18
-22,1,21:18.0
-22,6,21:18.0
-22,7,21:18.0
-22,8,21:17.0
-22,9,21:18.0
-22,10,21:18.0
-21,-5,21:20
-21,-3,21:50.2
-21,-2,21:57
-21,-1,21:57
-21,0,21:18.0
-21,6,21:18.0
-21,7,21:18.0
-21,8,21:18.0
-21,9,21:18.0
-21,10,21:18.0
-20,-5,21:20
-20,-2,21:26.3
-20,-1,21:26.11
-20,0,21:18
-20,6,21:18.0
-20,7,21:18.0
-20,8,21:18.0
-20,9,21:18.0
-20,10,21:18.0
-19,-5,21:20
-19,-2,21:26.3
-19,-1,21:26.11
-19,0,21:18.0
-19,1,21:18.0
-18,-5,21:20
-18,-3,21:50.2
-18,-2,21:57
-18,-1,21:57
-18,0,21:18.0
-18,1,21:18.0
-18,2,21:18.0
-17,-5,21:18
-17,0,21:17.0
-17,1,21:18.0
-17,2,21:18.0
-16,-5,21:17.0
-16,0,21:18
-16,1,21:18
-16,2,21:18.0
-15,-5,21:18
-15,1,21:18.0
-15,2,21:18.0
-15,5,21:18
-15,6,21:18
-14,-4,21:20
-14,-3,21:20
-14,1,21:20
-14,5,21:17.0
-14,6,21:17.0
-14,7,21:18
-13,-3,21:20
-13,0,21:50.2
-13,1,21:17.0
-13,5,21:18
-13,6,21:17.0
-13,7,21:18
-12,-3,21:20
-12,1,21:20
-12,2,21:20
-12,5,21:18
-12,6,21:17.0
-12,7,21:17.0
-12,8,21:18
-11,-22,21:18
-11,-5,21:17.0
-11,-3,21:20
-11,2,21:20
-11,5,21:18.0
-11,6,21:18
-11,7,21:18
-10,-23,21:18
-10,-22,21:18
-10,-6,21:106.8
-10,-5,21:17.0
-10,-3,21:20
-10,2,21:20
-10,4,21:18.0
-10,5,21:18.0
-10,6,21:18.0
-10,21,21:18.0
-10,22,21:18.0
-10,23,21:18.0
-10,24,21:18.0
-9,-23,21:18
-9,-22,21:17.0
-9,-21,21:18
-9,-6,21:106.8
-9,-5,21:17.0
-9,-3,21:20
-9,2,21:20
-9,3,21:17.0
-9,4,21:17.0
-9,5,21:17.0
-9,6,21:18
-9,7,21:18
-9,8,21:18
-9,21,21:18.0
-9,22,21:18.0
-9,23,21:18.0
-9,24,21:18.0
-9,25,21:18.0
-8,-23,21:17.0
-8,-22,21:18
-8,-6,21:106.8
-8,-5,21:17.0
-8,-3,21:17.0
-8,-2,21:20
-8,2,21:20
-8,5,21:18
-8,6,21:18
-8,7,21:18
-8,8,21:18
-8,9,21:18
-8,13,21:18
-8,21,21:18.0
-8,22,21:18.0
-8,23,21:17.0
-8,24,21:18.0
-8,25,21:18.0
-7,-24,21:18.0
-7,-23,21:18.0
-7,-22,21:18.0
-7,-21,21:18.0
-7,-20,21:18.0
-7,-19,21:18.0
-7,-18,21:18.0
-7,-17,21:18.0
-7,-16,21:18.0
-7,-1,21:20
-7,3,21:20
-7,8,21:18
-7,13,21:17.0
-7,14,21:18
-7,15,21:18
-7,21,21:18.0
-7,22,21:18.0
-7,23,21:18.0
-7,24,21:18.0
-7,25,21:18.0
-6,-25,21:18.0
-6,-24,21:18.0
-6,-23,21:18.0
-6,-22,21:18.0
-6,-21,21:18.0
-6,-20,21:18.0
-6,-19,21:18.0
-6,-18,21:18.0
-6,-17,21:18.0
-6,-16,21:18.0
-6,-15,21:18
-6,-14,21:17.0
-6,-13,21:18
-6,-1,21:20
-6,3,21:20
-6,4,21:17.0
-6,13,21:17.0
-6,14,21:17.0
-6,15,21:17.0
-6,16,21:18
-6,21,21:18.0
-6,22,21:18.0
-6,23,21:18.0
-6,24,21:18.0
-5,-27,21:17.0
-5,-25,21:18.0
-5,-24,21:18.0
-5,-23,21:17.0
-5,-22,21:18.0
-5,-21,21:18.0
-5,-20,21:18.0
-5,-19,21:18.0
-5,-18,21:17.0
-5,-17,21:18.0
-5,-16,21:18.0
-5,-1,21:20
-5,0,21:50.4
-5,3,21:20
-5,10,21:18.0
-5,12,21:18.0
-5,13,21:18
-5,14,21:18
-5,15,21:17.0
-5,16,21:18
-5,25,21:18.0
-4,-25,21:18.0
-4,-24,21:18.0
-4,-23,21:18.0
-4,-22,21:18.0
-4,-21,21:18.0
-4,-20,21:18.0
-4,-19,21:18.0
-4,-18,21:18.0
-4,-17,21:18.0
-4,-16,21:18.0
-4,-6,21:17.0
-4,0,21:5.0
-4,1,21:64.11
-4,2,21:64.14
-4,3,21:5.0
-4,6,21:18
-4,7,21:17.0
-4,10,21:17.0
-4,11,21:18.0
-4,15,21:18
-4,24,21:18.0
-4,25,21:18.0
-4,26,21:18.0
-4,27,21:17.0
-3,-25,21:18.0
-3,-24,21:18.0
-3,-23,21:18.0
-3,-22,21:18.0
-3,-21,21:18.0
-3,-20,21:18.0
-3,-19,21:18.0
-3,-18,21:18.0
-3,-17,21:18.0
-3,-16,21:18.0
-3,-15,21:18.0
-3,-14,21:18.0
-3,-13,21:18.0
-3,-10,21:20
-3,-9,21:20
-3,-8,21:20
-3,-7,21:20
-3,-6,21:20
-3,-5,21:20
-3,-4,21:20
-3,-3,21:20
-3,-1,21:5.0
-3,4,21:5.0
-3,7,21:50.3
-3,10,21:17.0
-3,25,21:18.0
-2,-25,21:18.0
-2,-24,21:17.0
-2,-23,21:18.0
-2,-22,21:18.0
-2,-19,21:18.0
-2,-17,21:18.0
-2,-16,21:18.0
-2,-15,21:18.0
-2,-14,21:18.0
-2,-13,21:18.0
-2,-11,21:20
-2,-10,21:61.5
-2,-3,21:50.2
-2,-2,21:5.0
-2,5,21:5.0
-2,10,21:50.3
-2,16,21:18.0
-2,17,21:18.0
-2,18,21:18.0
-2,19,21:18.0
-1,-24,21:18.0
-1,-22,21:18.0
-1,-19,21:18.0
-1,-18,21:18
-1,-17,21:18.0
-1,-16,21:18.0
-1,-15,21:17.0
-1,-14,21:18
-1,-13,21:18.0
-1,-11,21:20
-1,-10,21:61.5
-1,-2,21:64.13
-1,5,21:64.12
-1,13,21:50.2
-1,14,21:17.0
-1,16,21:18.0
-1,17,21:18
-1,18,21:18.0
-1,19,21:18.0
-1,20,21:18.0
-1,23,21:18.0
-1,24,21:18.0
0,-21,21:18.0
0,-20,21:18.0
0,-17,21:18.0
0,-16,21:18.0
0,-15,21:18.0
0,-14,21:18
0,-13,21:18.0
0,-11,21:17.0
0,-10,21:61.5
0,-2,21:64.10
0,5,21:64.11
0,14,21:50.3
0,16,21:18.0
0,17,21:18
0,18,21:17.0
0,19,21:18.0
0,20,21:18.0
0,21,21:18
0,22,21:18.0
0,25,21:18.0
0,27,21:18.0
1,-16,21:18.0
1,-15,21:18.0
1,-14,21:18.0
1,-13,21:18.0
1,-11,21:20
1,-10,21:61.5
1,-3,21:50.2
1,-2,21:5.0
1,5,21:5.0
1,6,21:20
1,7,21:20
1,8,21:20
1,9,21:20
1,16,21:18.0
1,17,21:18.0
1,18,21:18.0
1,19,21:18.0
1,20,21:18.0
1,22,21:18.0
1,25,21:18.0
1,26,21:18.0
1,27,21:17.0
1,28,21:18.0
2,-10,21:20
2,-9,21:20
2,-8,21:20
2,-7,21:17.0
2,-6,21:20
2,-5,21:20
2,-4,21:20
2,-3,21:20
2,-2,21:20
2,-1,21:5.0
2,4,21:5.0
2,9,21:20
2,14,21:20
2,16,21:18.0
2,17,21:18.0
2,18,21:18.0
2,19,21:18.0
2,20,21:18.0
2,21,21:18.0
2,22,21:18.0
2,23,21:18.0
2,24,21:18.0
2,25,21:18.0
2,26,21:18.0
2,27,21:18.0
2,28,21:18.0
3,-24,21:17.0
3,-12,21:18
3,-8,21:18.0
3,-7,21:17.0
3,-4,21:17.0
3,-2,21:20
3,0,21:5.0
3,1,21:64.12
3,2,21:64.9
3,3,21:5.0
3,8,21:50.2
3,9,21:17.0
3,10,21:102
3,13,21:102
3,14,21:20
3,19,21:18.0
3,20,21:18.0
3,21,21:18.0
3,22,21:18.0
3,23,21:18.0
3,24,21:18.0
3,25,21:18.0
3,26,21:18.0
3,27,21:18.0
3,28,21:18.0
4,-13,21:18
4,-12,21:17.0
4,-11,21:18
4,-10,21:18
4,-2,21:20
4,4,21:17.0
4,7,21:106.4
4,8,21:106.4
4,9,21:106.4
4,10,21:102
4,13,21:102
4,19,21:18.0
4,20,21:18.0
4,21,21:17.0
4,22,21:18.0
4,23,21:18.0
4,24,21:18.0
4,25,21:18.0
4,26,21:17.0
4,27,21:18.0
4,28,21:18.0
4,30,21:17.0
5,-21,21:18.0
5,-20,21:18.0
5,-19,21:18.0
5,-18,21:18.0
5,-13,21:18
5,-12,21:17.0
5,-11,21:17.0
5,-10,21:17.0
5,-2,21:20
5,4,21:20
5,8,21:18
5,10,21:102
5,11,21:102
5,12,21:102
5,13,21:102
5,16,21:18
5,17,21:17.0
5,18,21:18
5,19,21:18.0
5,20,21:18.0
5,21,21:18.0
5,22,21:18.0
5,23,21:18.0
5,24,21:18.0
5,25,21:18.0
5,26,21:18.0
5,27,21:18.0
5,28,21:18.0
6,-22,21:18.0
6,-21,21:18.0
6,-20,21:18.0
6,-19,21:18.0
6,-18,21:18.0
6,-12,21:18
6,-11,21:18
6,-10,21:17.0
6,-5,21:17.0
6,-3,21:17.0
6,-2,21:20
6,4,21:20
6,5,21:18
6,6,21:18
6,7,21:18
6,8,21:18
6,9,21:18
6,16,21:106.4
6,17,21:106.4
6,19,21:18.0
6,20,21:18.0
6,21,21:18.0
6,22,21:18.0
6,23,21:18.0
6,24,21:18.0
6,25,21:18.0
6,26,21:18.0
6,27,21:18.0
7,-22,21:18.0
7,-21,21:18.0
7,-20,21:17.0
7,-19,21:18.0
7,-18,21:18.0
7,-10,21:18
7,-5,21:17.0
7,-3,21:20
7,3,21:17.0
7,4,21:17.0
7,5,21:17.0
7,6,21:18
7,7,21:18
7,8,21:18
7,25,21:18
7,26,21:17.0
8,-22,21:18.0
8,-21,21:18.0
8,-20,21:18.0
8,-19,21:18.0
8,-18,21:18.0
8,-5,21:17.0
8,-3,21:20
8,3,21:20
8,4,21:18.0
8,5,21:18.0
8,6,21:18.0
8,24,21:18
8,25,21:17.0
8,26,21:18
9,-21,21:18.0
9,-20,21:18.0
9,-19,21:18.0
9,-18,21:18.0
9,-5,21:17.0
9,-3,21:20
9,3,21:20
9,5,21:18.0
9,6,21:18
9,7,21:18
9,25,21:18
9,26,21:18
10,-3,21:20
10,3,21:20
10,5,21:18
10,6,21:17.0
10,7,21:17.0
10,8,21:18
11,-3,21:20
11,1,21:17.0
11,2,21:20
11,5,21:18
11,6,21:17.0
11,7,21:18
12,-3,21:20
12,1,21:20
12,4,21:18
12,5,21:17.0
12,6,21:17.0
12,7,21:18
13,-5,21:18
13,-4,21:18
13,-3,21:17.0
13,-2,21:44.2
13,-1,21:44.2
13,0,21:18.0
13,1,21:18.0
13,2,21:18.0
13,5,21:18
13,6,21:18
14,-5,21:17.0
14,-4,21:18
14,-3,21:17.0
14,-2,21:43.2
14,-1,21:18.0
14,0,21:18
14,1,21:18
14,2,21:18.0
15,-7,21:18
15,-6,21:18
15,-5,21:18
15,-4,21:18
15,-3,21:17.0
15,-2,21:43.2
15,-1,21:18.0
15,0,21:17.0
15,1,21:18.0
15,2,21:18.0
16,-7,21:18
16,-5,21:60.7
16,-4,21:3
16,-3,21:60.7
16,-2,21:60.7
16,-1,21:18.0
16,0,21:18.0
16,1,21:18.0
16,2,21:18.0
17,-7,21:18
17,-5,21:60.7
17,-4,21:3
17,-3,21:60.7
17,-2,21:60.7
17,-1,21:18.0
17,0,21:18.0
17,1,21:18.0
18,-7,21:18
18,-6,21:17.0
18,-5,21:17.0
18,-4,21:17.0
18,-3,21:60.7
18,-2,21:60.7
18,-1,21:18
18,0,21:18
18,6,21:18.0
18,7,21:18.0
18,8,21:18.0
18,9,21:18.0
18,10,21:18.0
19,-7,21:18
19,-5,21:60.7
19,-4,21:3
19,-3,21:60.7
19,-2,21:60.7
19,-1,21:18.0
19,0,21:18.0
19,6,21:18.0
19,7,21:18.0
19,8,21:18.0
19,9,21:18.0
19,10,21:18.0
20,-7,21:18
20,-5,21:60.7
20,-4,21:3
20,-3,21:60.7
20,-2,21:60.7
20,-1,21:18
20,6,21:18.0
20,7,21:18.0
20,8,21:17.0
20,9,21:18.0
20,10,21:18.0
21,-8,21:18
21,-7,21:18
21,-6,21:18.0
21,-5,21:18.0
21,-4,21:18.0
21,-3,21:18.0
21,-2,21:18.0
21,-1,21:18
21,6,21:18.0
21,7,21:18.0
21,8,21:18.0
21,9,21:18.0
21,10,21:18.0
22,-9,21:18
22,-8,21:17.0
22,-7,21:18
22,-6,21:18.0
22,-5,21:18.0
22,-4,21:18.0
22,-3,21:18.0
22,-2,21:18.0
22,-1,21:18.0
22,0,21:18.0
22,7,21:18.0
22,8,21:18.0
22,9,21:18.0
23,-9,21:18
23,-8,21:18
23,-7,21:17.0
23,-6,21:18.0
23,-5,21:18.0
23,-4,21:17.0
23,-3,21:18.0
23,-2,21:18.0
23,-1,21:18.0
24,-6,21:18.0
24,-5,21:18.0
24,-4,21:18.0
24,-3,21:18.0
24,-2,21:18.0
24,-1,21:17.0
24,0,21:18.0
24,4,21:17.0
25,-5,21:18.0
25,-4,21:18.0
25,-3,21:18.0
25,-2,21:18.0
25,-1,21:18.0
26,-4,21:50.4
27,-4,21:17.0
-31,-5,22:18.0
-31,-4,22:18.0
-31,-3,22:18.0
-30,-6,22:18.0
-30,-5,22:18.0
-30,-4,22:18.0
-30,-3,22:18.0
-30,-2,22:18.0
-29,-6,22:18.0
-29,-5,22:18.0
-29,-4,22:17.0
-29,-3,22:18.0
-29,-2,22:18.0
-28,-6,22:18.0
-28,-5,22:18.0
-28,-4,22:18.0
-28,-3,22:18.0
-28,-2,22:18.0
-28,-1,22:18.0
-28,0,22:18.0
-27,-6,22:18.0
-27,-5,22:18.0
-27,-4,22:18.0
-27,-3,22:18.0
-27,-2,22:18.0
-27,-1,22:18.0
-27,0,22:18.0
-27,1,22:18.0
-26,-4,22:18.0
-26,-3,22:18.0
-26,-2,22:18.0
-26,-1,22:17.0
-26,0,22:18.0
-26,1,22:18.0
-26,4,22:17.0
-25,-7,22:17.0
-25,-5,22:18.0
-25,-4,22:17.0
-25,-3,22:18.0
-25,-2,22:18.0
-25,-1,22:18.0
-25,0,22:18.0
-25,1,22:18.0
-24,-8,22:18
-24,-5,22:18.0
-24,-4,22:18.0
-24,-3,22:18.0
-24,-2,22:18.0
-24,-1,22:18.0
-24,0,22:18.0
-24,6,22:18.0
-24,7,22:18.0
-24,8,22:18.0
-24,9,22:18.0
-23,-5,22:20
-23,-4,22:18
-23,-3,22:18
-23,-1,22:18.0
-23,0,22:18.0
-23,6,22:18.0
-23,7,22:18.0
-23,8,22:18.0
-23,9,22:18.0
-23,10,22:18.0
-22,-5,22:20
-22,-4,22:18
-22,-3,22:18
-22,-2,22:18
-22,-1,22:18.0
-22,0,22:18.0
-22,6,22:18.0
-22,7,22:18.0
-22,8,22:17.0
-22,9,22:18.0
-22,10,22:18.0
-21,-5,22:20
-21,0,22:20
-21,6,22:18.0
-21,7,22:18.0
-21,8,22:18.0
-21,9,22:18.0
-21,10,22:18.0
-20,-5,22:20
-20,-1,22:50.2
-20,0,22:17.0
-20,6,22:18.0
-20,7,22:18.0
-20,8,22:18.0
-20,9,22:18.0
-19,-5,22:20
-19,-1,22:50.2
-19,0,22:17.0
-18,-5,22:20
-18,0,22:20
-17,-5,22:18
-17,0,22:17.0
-17,1,22:18.0
-16,-6,22:18
-16,-5,22:17.0
-16,-4,22:50.1
-16,0,22:18.0
-16,1,22:18.0
-15,-5,22:18
-15,1,22:18
-15,6,22:18
-15,7,22:18
-14,-4,22:20
-14,-3,22:20
-14,1,22:20
-14,5,22:18
-14,6,22:18
-13,-3,22:20
-13,1,22:17.0
-13,5,22:18
-13,6,22:18
-12,-3,22:20
-12,1,22:20
-12,2,22:20
-12,4,22:18.0
-12,5,22:18.0
-12,6,22:18
-12,7,22:18
-11,-6,22:18
-11,-5,22:17.0
-11,-3,22:20
-11,2,22:20
-11,3,22:18.0
-11,4,22:18.0
-11,5,22:18.0
-11,6,22:18.0
-11,7,22:18.0
-10,-5,22:18.0
-10,-3,22:20
-10,2,22:20
-10,3,22:18.0
-10,4,22:18.0
-10,5,22:18.0
-10,6,22:18.0
-10,7,22:18.0
-10,22,22:18.0
-10,23,22:18.0
-10,24,22:18.0
-9,-22,22:18
-9,-5,22:18.0
-9,-3,22:20
-9,2,22:20
-9,3,22:18.0
-9,4,22:17.0
-9,5,22:18.0
-9,6,22:18.0
-9,7,22:18
-9,21,22:18.0
-9,22,22:18.0
-9,23,22:18.0
-9,24,22:18.0
-9,25,22:18.0
-8,-23,22:17.0
-8,-5,22:18.0
-8,-4,22:18.0
-8,-3,22:17.0
-8,-2,22:20
-8,2,22:20
-8,4,22:18.0
-8,5,22:18.0
-8,6,22:18.0
-8,7,22:18
-8,21,22:18.0
-8,22,22:18.0
-8,23,22:17.0
-8,24,22:18.0
-8,25,22:18.0
-7,-28,22:18.0
-7,-27,22:18.0
-7,-26,22:18.0
-7,-25,22:18.0
-7,-14,22:18
-7,-5,22:18.0
-7,-4,22:18.0
-7,-3,22:18.0
-7,-1,22:20
-7,3,22:20
-7,13,22:18
-7,16,22:18
-7,21,22:18.0
-7,22,22:18.0
-7,23,22:18.0
-7,24,22:18.0
-7,25,22:18.0
-6,-29,22:18.0
-6,-28,22:18.0
-6,-27,22:18.0
-6,-26,22:18.0
-6,-25,22:18.0
-6,-23,22:18.0
-6,-22,22:18.0
-6,-18,22:18.0
-6,-15,22:18
-6,-14,22:17.0
-6,-13,22:18
-6,-5,22:18.0
-6,-4,22:18.0
-6,-3,22:18.0
-6,-1,22:20
-6,3,22:20
-6,4,22:17.0
-6,10,22:18.0
-6,13,22:18
-6,14,22:18
-6,15,22:18
-6,16,22:18
-6,21,22:18.0
-6,22,22:18.0
-6,23,22:18.0
-6,24,22:18.0
-6,25,22:18.0
-5,-29,22:18.0
-5,-28,22:18.0
-5,-27,22:17.0
-5,-26,22:18.0
-5,-25,22:18.0
-5,-24,22:18.0
-5,-23,22:17.0
-5,-22,22:18.0
-5,-19,22:18.0
-5,-18,22:17.0
-5,-17,22:18.0
-5,-14,22:18
-5,-5,22:18
-5,-1,22:20
-5,0,22:20
-5,1,22:20
-5,2,22:20
-5,3,22:20
-5,9,22:18.0
-5,10,22:18.0
-5,11,22:18.0
-5,12,22:18.0
-5,13,22:18.0
-5,14,22:18
-5,15,22:18
-4,-29,22:18.0
-4,-28,22:18.0
-4,-27,22:18.0
-4,-26,22:18.0
-4,-25,22:18.0
-4,-24,22:18.0
-4,-23,22:18.0
-4,-22,22:18.0
-4,-8,22:18.0
-4,-7,22:18.0
-4,-6,22:17.0
-4,-5,22:18.0
-4,-4,22:18.0
-4,0,22:20
-4,1,22:20
-4,2,22:20
-4,3,22:20
-4,7,22:17.0
-4,9,22:18.0
-4,10,22:18.0
-4,11,22:18.0
-4,12,22:18.0
-4,13,22:18.0
-4,25,22:18.0
-4,27,22:17.0
-3,-28,22:18.0
-3,-27,22:18.0
-3,-26,22:18.0
-3,-25,22:18.0
-3,-24,22:18.0
-3,-23,22:18.0
-3,-22,22:18.0
-3,-10,22:20
-3,-9,22:20
-3,-8,22:18.0
-3,-7,22:18.0
-3,-6,22:18.0
-3,-5,22:18.0
-3,-4,22:18.0
-3,-3,22:20
-3,-1,22:20
-3,1,22:68.3
-3,2,22:68.3
-3,4,22:20
-3,10,22:18.0
-3,11,22:18.0
-3,12,22:18.0
-2,-26,22:18.0
-2,-25,22:18.0
-2,-24,22:17.0
-2,-23,22:18.0
-2,-22,22:18.0
-2,-21,22:18.0
-2,-20,22:18.0
-2,-15,22:18.0
-2,-14,22:18.0
-2,-11,22:20
-2,-10,22:61.5
-2,-2,22:20
-2,5,22:20
-2,6,22:20
-1,-26,22:18.0
-1,-25,22:18.0
-1,-24,22:18.0
-1,-23,22:18.0
-1,-22,22:18.0
-1,-21,22:18.0
-1,-20,22:18.0
-1,-18,22:17.0
-1,-16,22:18.0
-1,-15,22:17.0
-1,-14,22:18.0
-1,-11,22:20
-1,-10,22:61.5
-1,-2,22:20
-1,-1,22:68.5
-1,4,22:68.4
-1,5,22:20
-1,6,22:20
-1,14,22:17.0
-1,17,22:18.0
-1,18,22:18.0
-1,19,22:18.0
-1,26,22:18.0
-1,27,22:18.0
-1,28,22:18.0
0,-25,22:18.0
0,-24,22:18.0
0,-23,22:18.0
0,-16,22:18.0
0,-15,22:18.0
0,-14,22:18.0
0,-11,22:17.0
0,-10,22:61.5
0,-2,22:20
0,-1,22:68.5
0,4,22:68.4
0,5,22:20
0,6,22:20
0,17,22:18.0
0,18,22:17.0
0,19,22:18.0
0,21,22:17.0
0,23,22:18.0
0,24,22:18.0
0,25,22:18.0
0,26,22:18.0
0,27,22:18.0
0,28,22:18.0
0,29,22:18.0
1,-11,22:20
1,-10,22:61.5
1,-2,22:20
1,5,22:20
1,6,22:20
1,7,22:20
1,8,22:20
1,9,22:20
1,17,22:18.0
1,18,22:18.0
1,23,22:18.0
1,24,22:18.0
1,25,22:18.0
1,26,22:18.0
1,27,22:17.0
1,28,22:18.0
1,29,22:18.0
2,-10,22:20
2,-9,22:18.0
2,-8,22:18.0
2,-7,22:18.0
2,-6,22:20
2,-5,22:20
2,-4,22:20
2,-3,22:20
2,-2,22:20
2,-1,22:20
2,1,22:68.2
2,2,22:68.2
2,4,22:20
2,7,22:18.0
2,8,22:18.0
2,9,22:18
2,14,22:20
2,25,22:18.0
2,26,22:18.0
2,27,22:18.0
2,28,22:18.0
2,29,22:18.0
2,30,22:18.0
2,31,22:18.0
3,-24,22:17.0
3,-10,22:18.0
3,-9,22:18.0
3,-8,22:18.0
3,-7,22:17.0
3,-6,22:18.0
3,-4,22:17.0
3,-3,22:18.0
3,-2,22:18.0
3,0,22:20
3,1,22:20
3,2,22:20
3,3,22:20
3,7,22:18.0
3,8,22:18.0
3,9,22:17.0
3,10,22:102
3,13,22:102
3,14,22:20
3,25,22:18.0
3,26,22:18.0
3,27,22:18.0
3,28,22:18.0
3,29,22:18.0
3,30,22:18.0
3,31,22:18.0
3,32,22:18.0
4,-12,22:18
4,-11,22:18
4,-10,22:18.0
4,-4,22:18.0
4,-3,22:18.0
4,-2,22:18.0
4,4,22:17.0
4,7,22:106.4
4,8,22:106.4
4,9,22:106.4
4,10,22:102
4,13,22:102
4,17,22:18
4,20,22:18.0
4,21,22:17.0
4,22,22:18.0
4,25,22:18.0
4,26,22:17.0
4,27,22:18.0
4,28,22:18.0
4,29,22:18.0
4,30,22:17.0
4,31,22:18.0
4,32,22:18.0
5,-22,22:18.0
5,-21,22:18.0
5,-20,22:18.0
5,-19,22:18.0
5,-18,22:18.0
5,-13,22:18
5,-12,22:18
5,-11,22:18
5,-10,22:18
5,-5,22:18.0
5,-4,22:18.0
5,-3,22:18.0
5,-2,22:18.0
5,-1,22:18.0
5,4,22:20
5,10,22:102
5,11,22:102
5,12,22:102
5,13,22:102
5,16,22:18
5,17,22:17.0
5,18,22:18
5,21,22:18.0
5,25,22:18.0
5,26,22:18.0
5,28,22:18.0
5,29,22:18.0
5,30,22:18.0
5,31,22:18.0
5,32,22:18.0
6,-22,22:18.0
6,-21,22:18.0
6,-20,22:18.0
6,-19,22:18.0
6,-18,22:18.0
6,-13,22:18
6,-10,22:18
6,-5,22:18.0
6,-4,22:18.0
6,-3,22:17.0
6,-2,22:18.0
6,-1,22:18.0
6,2,22:18.0
6,4,22:18.0
6,5,22:18.0
6,6,22:18.0
6,7,22:18
6,17,22:18
6,28,22:18.0
6,29,22:18.0
6,30,22:18.0
6,31,22:18.0
7,-22,22:18.0
7,-21,22:18.0
7,-20,22:17.0
7,-19,22:18.0
7,-18,22:18.0
7,-5,22:18.0
7,-4,22:18.0
7,-3,22:18.0
7,-2,22:18.0
7,-1,22:18.0
7,1,22:18.0
7,2,22:18.0
7,3,22:18.0
7,4,22:17.0
7,5,22:18.0
7,6,22:18.0
7,7,22:18
7,26,22:17.0
8,-22,22:18.0
8,-21,22:18.0
8,-20,22:18.0
8,-19,22:18.0
8,-18,22:18.0
8,-5,22:18.0
8,-4,22:18.0
8,-3,22:18.0
8,-2,22:18.0
8,2,22:18.0
8,3,22:18.0
8,4,22:18.0
8,5,22:18.0
8,6,22:18.0
8,7,22:18.0
8,25,22:18
9,-21,22:18.0
9,-20,22:18.0
9,-19,22:18.0
9,-5,22:17.0
9,-3,22:20
9,3,22:18.0
9,4,22:18.0
9,5,22:18.0
9,6,22:18.0
9,7,22:18.0
9,26,22:18.0
9,27,22:18.0
10,-3,22:20
10,3,22:20
10,4,22:18.0
10,5,22:18.0
10,6,22:18
10,7,22:18
10,26,22:18.0
10,27,22:18.0
11,-3,22:20
11,1,22:17.0
11,2,22:20
11,5,22:18
11,6,22:18
12,-3,22:20
12,1,22:20
12,5,22:18
12,6,22:18
13,-5,22:18
13,-4,22:18
13,1,22:20
13,6,22:18
13,7,22:18
14,-6,22:18
14,-5,22:17.0
14,-4,22:18
14,-3,22:106.2
14,0,22:18.0
14,1,22:18.0
15,-7,22:85
15,-5,22:18
15,-4,22:18
15,-3,22:106.2
15,0,22:17.0
15,1,22:18.0
16,-7,22:85
16,-5,22:105.7
16,-4,22:103
16,-3,22:59.7
16,-2,22:59.7
16,0,22:18.0
16,1,22:18.0
17,-7,22:85
17,-5,22:105.7
17,-4,22:103
17,-3,22:59.7
17,-2,22:59.7
18,-7,22:85
18,-3,22:59.7
18,-2,22:59.7
18,0,22:17.0
18,6,22:18.0
18,7,22:18.0
18,8,22:18.0
18,9,22:18.0
19,-7,22:85
19,-5,22:104.7
19,-4,22:86.0
19,-3,22:59.7
19,-2,22:59.7
19,6,22:18.0
19,7,22:18.0
19,8,22:18.0
19,9,22:18.0
19,10,22:18.0
20,-7,22:85
20,-5,22:104.7
20,-4,22:86.0
20,-3,22:59.7
20,-2,22:59.7
20,0,22:18.0
20,6,22:18.0
20,7,22:18.0
20,8,22:17.0
20,9,22:18.0
20,10,22:18.0
21,-7,22:85
21,0,22:18.0
21,6,22:18.0
21,7,22:18.0
21,8,22:18.0
21,9,22:18.0
21,10,22:18.0
22,-8,22:18
22,-7,22:85
22,-6,22:85
22,0,22:18.0
22,6,22:18.0
22,7,22:18.0
22,8,22:18.0
22,9,22:18.0
23,-7,22:17.0
23,-6,22:18
23,-5,22:18.0
23,-4,22:17.0
23,-3,22:18.0
23,-2,22:18.0
23,-1,22:18.0
23,0,22:18.0
23,1,22:18.0
24,-6,22:18
24,-4,22:18.0
24,-3,22:18.0
24,-2,22:18.0
24,-1,22:17.0
24,0,22:18.0
24,1,22:18.0
24,4,22:17.0
25,-6,22:18.0
25,-5,22:18.0
25,-4,22:18.0
25,-3,22:18.0
25,-2,22:18.0
25,-1,22:18.0
25,0,22:18.0
25,1,22:18.0
26,-6,22:18.0
26,-5,22:18.0
26,-4,22:18.0
26,-3,22:18.0
26,-2,22:18.0
26,-1,22:18.0
26,0,22:18.0
27,-6,22:18.0
27,-5,22:18.0
27,-4,22:17.0
27,-3,22:18.0
27,-2,22:18.0
28,-6,22:18.0
28,-5,22:18.0
28,-4,22:18.0
28,-3,22:18.0
28,-2,22:18.0
29,-5,22:18.0
29,-4,22:18.0
29,-3,22:18.0
-31,-6,23:18.0
-31,-5,23:18.0
-31,-4,23:18.0
-31,-3,23:18.0
-30,-6,23:18.0
-30,-5,23:17.0
-30,-4,23:18.0
-30,-3,23:18.0
-30,-2,23:18.0
-29,-6,23:18.0
-29,-5,23:18.0
-29,-4,23:17.0
-29,-3,23:18.0
-29,-2,23:18.0
-28,-6,23:18.0
-28,-5,23:18.0
-28,-4,23:18.0
-28,-3,23:18.0
-28,-2,23:18.0
-28,-1,23:18.0
-28,0,23:18.0
-28,3,23:18.0
-28,4,23:18.0
-28,5,23:18.0
-27,-6,23:18.0
-27,-5,23:18.0
-27,-4,23:18.0
-27,-3,23:18.0
-27,-2,23:18.0
-27,-1,23:18.0
-27,0,23:18.0
-27,1,23:18.0
-27,2,23:18.0
-27,3,23:18.0
-27,4,23:18.0
-27,5,23:18.0
-27,6,23:18.0
-26,-4,23:18.0
-26,-3,23:18.0
-26,-2,23:18.0
-26,-1,23:17.0
-26,0,23:18.0
-26,1,23:18.0
-26,2,23:18.0
-26,3,23:18.0
-26,4,23:17.0
-26,5,23:18.0
-26,6,23:18.0
-25,-7,23:17.0
-25,-5,23:18.0
-25,-4,23:18.0
-25,-3,23:18.0
-25,-2,23:18.0
-25,-1,23:18.0
-25,0,23:18.0
-25,1,23:18.0
-25,2,23:18.0
-25,3,23:18.0
-25,4,23:18.0
-25,5,23:18.0
-25,6,23:18.0
-24,-4,23:18.0
-24,-2,23:18.0
-24,-1,23:18.0
-24,0,23:18.0
-24,2,23:18.0
-24,3,23:18.0
-24,4,23:18.0
-24,5,23:18.0
-23,7,23:18.0
-23,8,23:18.0
-23,9,23:18.0
-22,-5,23:20
-22,-4,23:20
-22,-3,23:20
-22,-2,23:20
-22,-1,23:20
-22,0,23:18.0
-22,1,23:18.0
-22,7,23:18.0
-22,8,23:17.0
-22,9,23:18.0
-21,-5,23:20
-21,0,23:18.0
-21,1,23:18.0
-21,2,23:18.0
-21,8,23:18.0
-21,9,23:18.0
-20,-5,23:20
-20,0,23:17.0
-20,1,23:18.0
-20,2,23:18.0
-19,-5,23:20
-19,0,23:17.0
-19,1,23:18.0
-19,2,23:18.0
-18,-5,23:20
-18,0,23:18.0
-18,1,23:18.0
-18,2,23:18.0
-17,-6,23:18
-17,-5,23:18
-17,-1,23:18.0
-17,0,23:18.0
-17,1,23:18.0
-16,-7,23:18
-16,-6,23:18
-16,-5,23:18
-16,-1,23:18
-16,0,23:18.0
-15,-6,23:18
-15,-5,23:18
-15,-4,23:20
-15,-3,23:20
-15,-1,23:18.0
-15,0,23:18.0
-15,1,23:18.0
-15,2,23:18.0
-15,3,23:18.0
-14,-5,23:18
-14,-4,23:20
-14,-3,23:20
-14,-1,23:18.0
-14,0,23:18.0
-14,1,23:18.0
-14,2,23:18.0
-14,3,23:18.0
-13,-3,23:20
-13,-1,23:18.0
-13,0,23:18.0
-13,1,23:17.0
-13,2,23:18.0
-13,3,23:18.0
-13,6,23:18
-12,-3,23:20
-12,-1,23:18.0
-12,0,23:18.0
-12,1,23:18.0
-12,2,23:18.0
-12,3,23:18.0
-12,4,23:18.0
-12,5,23:18.0
-12,6,23:18.0
-12,7,23:18
-11,-5,23:17.0
-11,-3,23:20
-11,-1,23:18.0
-11,0,23:18.0
-11,1,23:18.0
-11,2,23:18.0
-11,3,23:18.0
-11,4,23:18.0
-11,5,23:18.0
-11,6,23:18.0
-11,7,23:18.0
-10,-4,23:18.0
-10,-3,23:18.0
-10,-2,23:18.0
-10,-1,23:18
-10,0,23:18.0
-10,1,23:18.0
-10,2,23:18.0
-10,3,23:18.0
-10,4,23:18.0
-10,5,23:18.0
-10,6,23:18.0
-10,7,23:18.0
-9,-5,23:18.0
-9,-4,23:18.0
-9,-3,23:18.0
-9,-2,23:18.0
-9,-1,23:18.0
-9,0,23:18.0
-9,1,23:18.0
-9,2,23:18.0
-9,3,23:18.0
-9,4,23:17.0
-9,5,23:18.0
-9,6,23:18.0
-9,7,23:18.0
-9,22,23:18.0
-9,23,23:18.0
-9,24,23:18.0
-8,-23,23:17.0
-8,-14,23:18
-8,-5,23:18.0
-8,-4,23:18.0
-8,-3,23:17.0
-8,-2,23:18.0
-8,-1,23:18.0
-8,0,23:18.0
-8,1,23:18.0
-8,2,23:18.0
-8,3,23:18.0
-8,4,23:18.0
-8,5,23:18.0
-8,6,23:18.0
-8,22,23:18.0
-8,23,23:17.0
-8,24,23:18.0
-7,-29,23:18.0
-7,-28,23:18.0
-7,-27,23:18.0
-7,-26,23:18.0
-7,-25,23:18.0
-7,-15,23:18
-7,-14,23:18
-7,-13,23:18
-7,-5,23:18.0
-7,-4,23:18.0
-7,-3,23:18.0
-7,-2,23:18.0
-7,-1,23:18.0
-7,0,23:18
-7,1,23:18.0
-7,2,23:17.0
-7,3,23:17.0
-7,13,23:18
-7,23,23:18.0
-7,24,23:18.0
-6,-29,23:18.0
-6,-28,23:18.0
-6,-27,23:18.0
-6,-26,23:18.0
-6,-25,23:18.0
-6,-23,23:18.0
-6,-18,23:18.0
-6,-16,23:18
-6,-15,23:18
-6,-14,23:18
-6,-13,23:18
-6,-12,23:18
-6,-5,23:18.0
-6,-4,23:18.0
-6,-3,23:18.0
-6,-2,23:18.0
-6,-1,23:18.0
-6,0,23:18
-6,1,23:18
-6,2,23:18.0
-6,4,23:17.0
-6,6,23:18.0
-6,7,23:18.0
-6,8,23:18.0
-6,10,23:18.0
-6,13,23:18.0
-6,14,23:18
-6,26,23:18.0
-6,27,23:18.0
-6,28,23:18.0
-5,-29,23:18.0
-5,-28,23:18.0
-5,-27,23:17.0
-5,-26,23:18.0
-5,-25,23:18.0
-5,-24,23:18.0
-5,-23,23:18.0
-5,-22,23:18.0
-5,-19,23:18.0
-5,-18,23:18.0
-5,-17,23:18.0
-5,-15,23:18
-5,-14,23:18
-5,-13,23:18
-5,9,23:18.0
-5,10,23:18.0
-5,11,23:18.0
-5,12,23:18.0
-5,13,23:18.0
-5,25,23:18.0
-5,26,23:18.0
-5,27,23:18.0
-5,28,23:18.0
-5,29,23:18.0
-4,-29,23:18.0
-4,-28,23:18.0
-4,-27,23:18.0
-4,-26,23:18.0
-4,-25,23:18.0
-4,-24,23:18.0
-4,-23,23:18.0
-4,-8,23:18.0
-4,-7,23:18.0
-4,-6,23:17.0
-4,-5,23:18.0
-4,-4,23:18.0
-4,7,23:17.0
-4,9,23:18.0
-4,10,23:18.0
-4,11,23:18.0
-4,12,23:18.0
-4,13,23:18.0
-4,25,23:18.0
-4,26,23:18.0
-4,27,23:17.0
-4,28,23:18.0
-4,29,23:18.0
-3,-28,23:18.0
-3,-27,23:18.0
-3,-26,23:18.0
-3,-25,23:18.0
-3,-24,23:18.0
-3,-23,23:18.0
-3,-22,23:18.0
-3,-20,23:18.0
-3,-19,23:18.0
-3,-18,23:18.0
-3,-17,23:18.0
-3,-16,23:18.0
-3,-8,23:18.0
-3,-7,23:18.0
-3,-6,23:18.0
-3,-5,23:18.0
-3,-4,23:18.0
-3,0,23:20
-3,1,23:20
-3,2,23:20
-3,3,23:20
-3,8,23:17.0
-3,9,23:18.0
-3,10,23:18.0
-3,11,23:18.0
-3,12,23:18.0
-3,13,23:18.0
-3,14,23:18.0
-3,15,23:18.0
-3,16,23:18.0
-3,25,23:18.0
-3,26,23:18.0
-3,27,23:18.0
-3,28,23:18.0
-3,29,23:18.0
-2,-26,23:18.0
-2,-25,23:18.0
-2,-24,23:17.0
-2,-23,23:18.0
-2,-22,23:18.0
-2,-20,23:18.0
-2,-19,23:18.0
-2,-18,23:18.0
-2,-17,23:18.0
-2,-16,23:18.0
-2,-15,23:18.0
-2,-13,23:18.0
-2,-12,23:18.0
-2,-11,23:18.0
-2,-10,23:18.0
-2,-9,23:18.0
-2,-8,23:18
-2,-7,23:18.0
-2,-6,23:18.0
-2,-5,23:18.0
-2,-4,23:18.0
-2,-3,23:20
-2,-1,23:20
-2,4,23:20
-2,7,23:20
-2,8,23:17.0
-2,9,23:18.0
-2,10,23:18.0
-2,11,23:18.0
-2,12,23:18.0
-2,13,23:18.0
-2,14,23:18.0
-2,15,23:18.0
-2,16,23:18.0
-2,19,23:18.0
-2,20,23:18.0
-2,21,23:18.0
-2,22,23:18.0
-2,25,23:18.0
-2,26,23:18.0
-2,27,23:18.0
-2,28,23:18.0
-1,-26,23:18.0
-1,-25,23:18.0
-1,-24,23:18.0
-1,-23,23:18.0
-1,-22,23:18.0
-1,-20,23:18.0
-1,-19,23:18.0
-1,-18,23:17.0
-1,-17,23:18.0
-1,-16,23:18.0
-1,-15,23:18.0
-1,-14,23:18.0
-1,-13,23:18.0
-1,-11,23:18.0
-1,-10,23:18.0
-1,-9,23:18.0
-1,-8,23:18.0
-1,-7,23:18.0
-1,-6,23:18.0
-1,-5,23:17.0
-1,-4,23:17.0
-1,-3,23:20
-1,-2,23:20
-1,-1,23:20
-1,4,23:20
-1,7,23:20
-1,8,23:18.0
-1,9,23:18.0
-1,10,23:18.0
-1,11,23:18.0
-1,12,23:18.0
-1,13,23:18.0
-1,14,23:17.0
-1,15,23:18.0
-1,16,23:18.0
-1,18,23:18.0
-1,19,23:18.0
-1,20,23:18.0
-1,21,23:18.0
-1,22,23:18.0
-1,23,23:18.0
-1,26,23:18.0
-1,27,23:18.0
-1,28,23:18.0
0,-25,23:18.0
0,-24,23:18.0
0,-23,23:18.0
0,-20,23:18.0
0,-19,23:18.0
0,-18,23:18.0
0,-17,23:18.0
0,-16,23:18.0
0,-15,23:18.0
0,-13,23:18.0
0,-12,23:18.0
0,-11,23:17.0
0,-10,23:18.0
0,-9,23:18.0
0,-8,23:18.0
0,-7,23:18.0
0,-6,23:18.0
0,-5,23:18.0
0,-4,23:17.0
0,-3,23:18.0
0,-1,23:20
0,4,23:20
0,7,23:20
0,9,23:18.0
0,10,23:18.0
0,11,23:18.0
0,12,23:18.0
0,13,23:18.0
0,14,23:18.0
0,15,23:18.0
0,16,23:18.0
0,17,23:18.0
0,18,23:18.0
0,19,23:18.0
0,20,23:18.0
0,21,23:17.0
0,22,23:18.0
0,23,23:18.0
0,25,23:18.0
0,26,23:18.0
0,27,23:18.0
0,28,23:18.0
0,29,23:18.0
1,-25,23:18.0
1,-24,23:18.0
1,-23,23:18.0
1,-22,23:18.0
1,-19,23:18.0
1,-18,23:18.0
1,-17,23:18.0
1,-16,23:18.0
1,-13,23:18.0
1,-12,23:18.0
1,-11,23:18.0
1,-10,23:18.0
1,-9,23:18.0
1,-8,23:18.0
1,-7,23:18.0
1,-6,23:18.0
1,-5,23:17.0
1,-4,23:18.0
1,-3,23:17.0
1,-1,23:20
1,4,23:20
1,7,23:18.0
1,8,23:18.0
1,9,23:18.0
1,10,23:18.0
1,12,23:18.0
1,13,23:18.0
1,14,23:18.0
1,15,23:18.0
1,16,23:18.0
1,18,23:18.0
1,19,23:18.0
1,20,23:18.0
1,21,23:18.0
1,22,23:18.0
1,23,23:18.0
1,25,23:18.0
1,26,23:18.0
1,27,23:17.0
1,28,23:18.0
1,29,23:18.0
2,-26,23:18.0
2,-25,23:18.0
2,-24,23:18.0
2,-23,23:18.0
2,-22,23:18.0
2,-13,23:18.0
2,-12,23:18.0
2,-11,23:18.0
2,-10,23:18.0
2,-9,23:18.0
2,-8,23:18.0
2,-7,23:18.0
2,-6,23:18.0
2,-5,23:17.0
2,-4,23:18
2,-3,23:17.0
2,0,23:20
2,1,23:20
2,2,23:20
2,3,23:20
2,7,23:18.0
2,8,23:18.0
2,9,23:18.0
2,10,23:20
2,11,23:20
2,12,23:20
2,13,23:20
2,19,23:18.0
2,20,23:18.0
2,21,23:18.0
2,22,23:18.0
2,23,23:18.0
2,25,23:18.0
2,26,23:18.0
2,27,23:18.0
2,28,23:18.0
2,29,23:18.0
2,30,23:18.0
2,31,23:18.0
3,-26,23:18.0
3,-25,23:18.0
3,-24,23:17.0
3,-23,23:18.0
3,-22,23:18.0
3,-10,23:18.0
3,-9,23:18.0
3,-8,23:18.0
3,-7,23:17.0
3,-6,23:18.0
3,-5,23:20
3,-4,23:17.0
3,-3,23:18.0
3,-2,23:18.0
3,-1,23:18.0
3,7,23:18.0
3,8,23:18.0
3,9,23:17.0
3,10,23:20
3,11,23:20
3,12,23:20
3,13,23:20
3,26,23:18.0
3,27,23:18.0
3,28,23:18.0
3,29,23:18.0
3,30,23:18.0
3,31,23:18.0
3,32,23:18.0
4,-26,23:18.0
4,-25,23:18.0
4,-24,23:18.0
4,-23,23:18.0
4,-22,23:18.0
4,-10,23:18.0
4,-5,23:18.0
4,-4,23:18.0
4,-3,23:18.0
4,-2,23:18.0
4,-1,23:18.0
4,2,23:18.0
4,3,23:20
4,4,23:17.0
4,6,23:18.0
4,7,23:18.0
4,8,23:18.0
4,9,23:106.4
4,10,23:20
4,11,23:20
4,12,23:20
4,13,23:20
4,16,23:18
4,17,23:18
4,18,23:18
4,20,23:18.0
4,21,23:18.0
4,22,23:18.0
4,25,23:18.0
4,26,23:18.0
4,27,23:18.0
4,28,23:18.0
4,29,23:18.0
4,30,23:17.0
4,31,23:18.0
4,32,23:18.0
5,-25,23:18.0
5,-24,23:18.0
5,-23,23:18.0
5,-11,23:18
5,-10,23:18.0
5,-5,23:18.0
5,-4,23:18.0
5,-3,23:18.0
5,-2,23:18.0
5,-1,23:18.0
5,1,23:18.0
5,2,23:17.0
5,3,23:17.0
5,10,23:20
5,11,23:20
5,12,23:20
5,13,23:20
5,15,23:18
5,16,23:18
5,17,23:18
5,18,23:18
5,19,23:18
5,21,23:18.0
5,26,23:18.0
5,28,23:18.0
5,29,23:18.0
5,30,23:18.0
5,31,23:18.0
5,32,23:18.0
6,-21,23:18.0
6,-20,23:18.0
6,-10,23:18
6,-5,23:18.0
6,-4,23:18.0
6,-3,23:17.0
6,-2,23:18.0
6,-1,23:18.0
6,0,23:18.0
6,1,23:18.0
6,2,23:18.0
6,3,23:18.0
6,4,23:18.0
6,5,23:18.0
6,6,23:18.0
6,16,23:18
6,17,23:18
6,18,23:18
6,28,23:18.0
6,29,23:18.0
6,30,23:18.0
6,31,23:18.0
6,32,23:18.0
7,-21,23:18.0
7,-20,23:17.0
7,-19,23:18.0
7,-5,23:18.0
7,-4,23:18.0
7,-3,23:18.0
7,-2,23:18.0
7,-1,23:18.0
7,0,23:18.0
7,1,23:18.0
7,2,23:18.0
7,3,23:18.0
7,4,23:17.0
7,5,23:18.0
7,6,23:18.0
7,7,23:18.0
7,17,23:18
7,26,23:17.0
8,-21,23:18.0
8,-20,23:18.0
8,-19,23:18.0
8,-4,23:18.0
8,-3,23:18.0
8,-2,23:18.0
8,0,23:18.0
8,1,23:18.0
8,2,23:18.0
8,3,23:18.0
8,4,23:18.0
8,5,23:18.0
8,6,23:18.0
8,7,23:18.0
8,26,23:18.0
8,27,23:18.0
9,-5,23:17.0
9,-3,23:20
9,-2,23:18
9,-1,23:18.0
9,0,23:18.0
9,1,23:18.0
9,2,23:18.0
9,3,23:18.0
9,4,23:18.0
9,5,23:18.0
9,6,23:18.0
9,7,23:18.0
9,25,23:18.0
9,26,23:18.0
9,27,23:18.0
9,28,23:18.0
10,-3,23:20
10,-2,23:18
10,-1,23:18.0
10,0,23:18.0
10,1,23:18.0
10,2,23:18.0
10,3,23:18.0
10,4,23:18.0
10,5,23:18.0
10,6,23:18.0
10,7,23:18
10,25,23:18.0
10,26,23:18.0
10,27,23:18.0
10,28,23:18.0
11,-3,23:20
11,-2,23:18
11,-1,23:18.0
11,0,23:18.0
11,1,23:17.0
11,2,23:18.0
11,3,23:18.0
11,6,23:18
11,26,23:18.0
11,27,23:18.0
12,-5,23:18
12,-3,23:20
12,-1,23:18
12,0,23:18.0
12,1,23:18.0
12,2,23:18.0
12,3,23:18.0
13,-6,23:18
13,-5,23:18
13,-4,23:18
13,0,23:18.0
13,1,23:18.0
13,2,23:18.0
13,3,23:18.0
14,-7,23:18
14,-6,23:18
14,-5,23:18
14,-4,23:18
14,0,23:18.0
15,-5,23:106.8
15,-4,23:18
15,-3,23:106.2
15,0,23:18.0
15,1,23:18.0
16,-4,23:106.4
16,0,23:18.0
16,1,23:18.0
16,2,23:18.0
17,0,23:18.0
17,1,23:18.0
17,2,23:18.0
18,0,23:17.0
18,1,23:18.0
18,2,23:18.0
19,0,23:18.0
19,1,23:18.0
19,2,23:18.0
19,8,23:18.0
19,9,23:18.0
20,0,23:18.0
20,1,23:18.0
20,7,23:18.0
20,8,23:17.0
20,9,23:18.0
21,7,23:18.0
21,8,23:18.0
21,9,23:18.0
22,0,23:18.0
22,2,23:18.0
22,3,23:18.0
22,4,23:18.0
22,5,23:18.0
23,-7,23:17.0
23,-6,23:18
23,-5,23:18.0
23,-4,23:18.0
23,-3,23:18.0
23,-2,23:18.0
23,-1,23:18.0
23,0,23:18.0
23,1,23:18.0
23,2,23:18.0
23,3,23:18.0
23,4,23:18.0
23,5,23:18.0
23,6,23:18.0
24,-6,23:18
24,-4,23:18.0
24,-3,23:18.0
24,-2,23:18.0
24,-1,23:17.0
24,0,23:18.0
24,1,23:18.0
24,2,23:18.0
24,3,23:18.0
24,4,23:17.0
24,5,23:18.0
24,6,23:18.0
25,-6,23:18.0
25,-5,23:18.0
25,-4,23:18.0
25,-3,23:18.0
25,-2,23:18.0
25,-1,23:18.0
25,0,23:18.0
25,1,23:18.0
25,2,23:18.0
25,3,23:18.0
25,4,23:18.0
25,5,23:18.0
25,6,23:18.0
26,-6,23:18.0
26,-5,23:18.0
26,-4,23:18.0
26,-3,23:18.0
26,-2,23:18.0
26,-1,23:18.0
26,0,23:18.0
26,3,23:18.0
26,4,23:18.0
26,5,23:18.0
27,-6,23:18.0
27,-5,23:18.0
27,-4,23:17.0
27,-3,23:18.0
27,-2,23:18.0
28,-6,23:18.0
28,-5,23:18.0
28,-4,23:18.0
28,-3,23:18.0
28,-2,23:18.0
29,-6,23:18.0
29,-5,23:18.0
29,-4,23:18.0
29,-3,23:18.0
-32,-5,24:18
-31,-6,24:18
-31,-5,24:18
-30,-6,24:18
-30,-5,24:17.0
-30,-4,24:18.0
-30,-3,24:18.0
-29,-5,24:50.3
-29,-4,24:17.0
-29,-3,24:18.0
-28,-6,24:18
-28,-5,24:18
-28,-4,24:18.0
-28,-3,24:18.0
-28,-2,24:18.0
-28,2,24:18.0
-28,3,24:18.0
-28,4,24:18.0
-28,5,24:18.0
-28,6,24:18.0
-27,-6,24:18
-27,-5,24:18
-27,-4,24:18
-27,-3,24:18.0
-27,-1,24:18.0
-27,2,24:18.0
-27,3,24:18.0
-27,4,24:18.0
-27,5,24:18.0
-27,6,24:18.0
-26,-2,24:18.0
-26,-1,24:18.0
-26,0,24:18.0
-26,2,24:18.0
-26,3,24:18.0
-26,4,24:17.0
-26,5,24:18.0
-26,6,24:18.0
-25,-7,24:17.0
-25,-1,24:18.0
-25,2,24:18.0
-25,3,24:18.0
-25,4,24:18.0
-25,5,24:18.0
-25,6,24:18.0
-24,3,24:18.0
-24,4,24:18.0
-24,5,24:18.0
-23,-7,24:18.0
-23,8,24:18.0
-22,-8,24:18.0
-22,-7,24:18.0
-22,-6,24:18.0
-22,-1,24:18.0
-22,0,24:18.0
-22,1,24:18.0
-22,7,24:18.0
-22,8,24:18.0
-22,9,24:18.0
-21,-4,24:20
-21,-3,24:20
-21,-2,24:20
-21,-1,24:18.0
-21,0,24:18.0
-21,1,24:18.0
-21,2,24:18.0
-21,8,24:18.0
-20,-4,24:20
-20,-3,24:20
-20,-2,24:20
-20,-1,24:18.0
-20,0,24:17.0
-20,1,24:18.0
-20,2,24:18.0
-19,-4,24:20
-19,-3,24:20
-19,-2,24:20
-19,-1,24:18.0
-19,0,24:18.0
-19,1,24:18.0
-19,2,24:18.0
-18,-4,24:20
-18,-3,24:20
-18,-2,24:20
-18,-1,24:18.0
-18,0,24:18.0
-18,1,24:18.0
-17,-5,24:18
-17,-4,24:20
-17,-3,24:20
-17,-2,24:20
-16,-6,24:18
-16,-5,24:18
-16,-4,24:18
-16,-3,24:18
-16,-2,24:20
-15,-5,24:18
-15,-2,24:20
-15,-1,24:18.0
-15,0,24:18.0
-15,1,24:18.0
-15,2,24:18.0
-15,3,24:18.0
-14,-2,24:20
-14,-1,24:18.0
-14,0,24:18.0
-14,1,24:18.0
-14,2,24:18.0
-14,3,24:18.0
-13,-6,24:18.0
-13,-5,24:18.0
-13,-4,24:18.0
-13,-3,24:18.0
-13,-2,24:20
-13,-1,24:18.0
-13,0,24:18.0
-13,1,24:17.0
-13,2,24:18.0
-13,3,24:18.0
-12,-7,24:18.0
-12,-6,24:18.0
-12,-5,24:18.0
-12,-4,24:18.0
-12,-3,24:18.0
-12,-2,24:20
-12,-1,24:18.0
-12,0,24:18.0
-12,1,24:18.0
-12,2,24:18.0
-12,3,24:18.0
-11,-7,24:18.0
-11,-6,24:18.0
-11,-5,24:17.0
-11,-4,24:18.0
-11,-3,24:18.0
-11,-2,24:20
-11,-1,24:18.0
-11,0,24:18.0
-11,1,24:18.0
-11,2,24:18.0
-11,3,24:18.0
-11,5,24:18.0
-10,-7,24:18.0
-10,-6,24:18.0
-10,-5,24:18.0
-10,-4,24:18.0
-10,-3,24:18.0
-10,0,24:18.0
-10,1,24:18.0
-10,2,24:18.0
-10,3,24:18.0
-10,4,24:18.0
-10,5,24:18.0
-10,6,24:18.0
-9,-20,24:18.0
-9,-7,24:18.0
-9,-6,24:18.0
-9,-5,24:18.0
-9,-4,24:18.0
-9,-3,24:18.0
-9,0,24:18.0
-9,1,24:18.0
-9,2,24:18.0
-9,3,24:18.0
-9,4,24:17.0
-9,5,24:18.0
-9,23,24:18.0
-8,-23,24:17.0
-8,-21,24:18.0
-8,-20,24:18.0
-8,-19,24:18.0
-8,-10,24:18.0
-8,-4,24:18.0
-8,-3,24:17.0
-8,-2,24:18.0
-8,0,24:18.0
-8,1,24:17.0
-8,2,24:18.0
-8,3,24:18.0
-8,4,24:18.0
-8,22,24:18.0
-8,23,24:18.0
-8,24,24:18.0
-7,-20,24:18.0
-7,-14,24:18
-7,-11,24:18.0
-7,-10,24:18.0
-7,-4,24:18.0
-7,-3,24:18.0
-7,0,24:18
-7,1,24:18.0
-7,2,24:18.0
-7,3,24:17.0
-7,4,24:18.0
-7,23,24:18.0
-6,-28,24:18.0
-6,-27,24:18.0
-6,-15,24:18
-6,-14,24:18
-6,-13,24:18
-6,-11,24:18.0
-6,-10,24:18.0
-6,-9,24:18.0
-6,-8,24:18.0
-6,0,24:18.0
-6,1,24:18.0
-6,2,24:18.0
-6,3,24:18.0
-6,4,24:17.0
-6,6,24:18.0
-6,7,24:18.0
-6,8,24:18.0
-6,9,24:18.0
-6,26,24:18.0
-6,27,24:18.0
-6,28,24:18.0
-6,29,24:18.0
-5,-28,24:18.0
-5,-27,24:17.0
-5,-26,24:18.0
-5,-14,24:18
-5,-11,24:18.0
-5,-10,24:18.0
-5,-9,24:18.0
-5,-6,24:18
-5,8,24:18.0
-5,9,24:18.0
-5,10,24:18.0
-5,25,24:18.0
-5,26,24:18.0
-5,27,24:18.0
-5,28,24:18.0
-5,29,24:18.0
-4,-28,24:18.0
-4,-27,24:18.0
-4,-26,24:18.0
-4,-25,24:18.0
-4,-14,24:18
-4,-11,24:18.0
-4,-10,24:18.0
-4,-9,24:18.0
-4,-8,24:18.0
-4,-7,24:18.0
-4,-6,24:17.0
-4,-5,24:18.0
-4,7,24:17.0
-4,8,24:18.0
-4,9,24:18.0
-4,10,24:18.0
-4,11,24:18.0
-4,25,24:18.0
-4,26,24:18.0
-4,27,24:17.0
-4,28,24:18.0
-4,29,24:18.0
-3,-26,24:18.0
-3,-24,24:18.0
-3,-19,24:18.0
-3,-18,24:18.0
-3,-17,24:18.0
-3,-16,24:18.0
-3,-6,24:18.0
-3,7,24:18.0
-3,8,24:17.0
-3,9,24:18.0
-3,10,24:18.0
-3,11,24:18.0
-3,12,24:18.0
-3,13,24:18.0
-3,14,24:18.0
-3,15,24:18.0
-3,16,24:18.0
-3,25,24:18.0
-3,26,24:18.0
-3,27,24:18.0
-3,28,24:18.0
-3,29,24:18.0
-2,-25,24:18.0
-2,-24,24:18.0
-2,-23,24:18.0
-2,-20,24:18.0
-2,-19,24:18.0
-2,-18,24:18.0
-2,-17,24:18.0
-2,-16,24:18.0
-2,-13,24:18.0
-2,-12,24:18.0
-2,-11,24:18.0
-2,-10,24:18.0
-2,-9,24:18.0
-2,0,24:20
-2,1,24:20
-2,2,24:20
-2,3,24:20
-2,7,24:18.0
-2,8,24:18.0
-2,9,24:18.0
-2,10,24:18.0
-2,11,24:18.0
-2,12,24:18.0
-2,13,24:18.0
-2,14,24:18.0
-2,15,24:18.0
-2,16,24:18.0
-2,20,24:18.0
-2,21,24:18.0
-2,22,24:18.0
-2,26,24:18.0
-2,27,24:18.0
-2,28,24:18.0
-2,29,24:18.0
-1,-24,24:18.0
-1,-20,24:18.0
-1,-19,24:18.0
-1,-18,24:17.0
-1,-17,24:18.0
-1,-16,24:18.0
-1,-13,24:18.0
-1,-12,24:18.0
-1,-11,24:18.0
-1,-10,24:18.0
-1,-9,24:18.0
-1,-8,24:18.0
-1,-7,24:18.0
-1,-6,24:18.0
-1,-5,24:17.0
-1,-4,24:18.0
-1,-3,24:18.0
-1,-2,24:18.0
-1,0,24:20
-1,3,24:20
-1,7,24:18.0
-1,8,24:18.0
-1,9,24:17.0
-1,10,24:18.0
-1,11,24:18.0
-1,12,24:18.0
-1,13,24:18.0
-1,14,24:17.0
-1,15,24:18.0
-1,16,24:18.0
-1,19,24:18.0
-1,20,24:18.0
-1,21,24:18.0
-1,22,24:18.0
-1,23,24:18.0
0,-20,24:18.0
0,-19,24:18.0
0,-18,24:18.0
0,-17,24:18.0
0,-16,24:18.0
0,-13,24:18.0
0,-12,24:18.0
0,-11,24:17.0
0,-10,24:18.0
0,-9,24:18.0
0,-8,24:18.0
0,-7,24:18.0
0,-6,24:17.0
0,-5,24:18.0
0,-4,24:18.0
0,-3,24:18.0
0,-2,24:18.0
0,0,24:20
0,3,24:20
0,7,24:18.0
0,9,24:18.0
0,10,24:18.0
0,11,24:18.0
0,12,24:18.0
0,13,24:18.0
0,14,24:18.0
0,15,24:18.0
0,16,24:18.0
0,19,24:18.0
0,20,24:18.0
0,21,24:17.0
0,22,24:18.0
0,23,24:18.0
0,27,24:18.0
1,-26,24:18.0
1,-25,24:18.0
1,-24,24:18.0
1,-23,24:18.0
1,-19,24:18.0
1,-18,24:18.0
1,-17,24:18.0
1,-13,24:18.0
1,-12,24:18.0
1,-11,24:18.0
1,-10,24:18.0
1,-9,24:18.0
1,-8,24:18.0
1,-7,24:18.0
1,-6,24:18.0
1,-5,24:18.0
1,-4,24:18.0
1,-3,24:18.0
1,-2,24:18.0
1,0,24:20
1,1,24:20
1,2,24:20
1,3,24:20
1,12,24:18.0
1,13,24:18.0
1,14,24:18.0
1,15,24:18.0
1,16,24:18.0
1,19,24:18.0
1,20,24:18.0
1,21,24:18.0
1,22,24:18.0
1,23,24:18.0
1,26,24:18.0
1,27,24:18.0
1,28,24:18.0
2,-26,24:18.0
2,-25,24:18.0
2,-24,24:18.0
2,-23,24:18.0
2,-22,24:18.0
2,-13,24:18.0
2,-12,24:18.0
2,-11,24:18.0
2,-10,24:18.0
2,-9,24:18.0
2,-8,24:18.0
2,-7,24:18.0
2,-6,24:18.0
2,-5,24:17.0
2,-4,24:18.0
2,-3,24:18.0
2,-2,24:18.0
2,6,24:18.0
2,9,24:18.0
2,19,24:18.0
2,20,24:18.0
2,21,24:18.0
2,22,24:18.0
2,27,24:18.0
2,29,24:18.0
3,-26,24:18.0
3,-25,24:18.0
3,-24,24:17.0
3,-23,24:18.0
3,-22,24:18.0
3,-8,24:18.0
3,-7,24:17.0
3,-6,24:18.0
3,-5,24:18.0
3,-4,24:17.0
3,-3,24:18.0
3,-2,24:18.0
3,-1,24:18.0
3,5,24:18.0
3,6,24:17.0
3,8,24:18.0
3,9,24:17.0
3,10,24:18.0
3,11,24:18.0
3,12,24:18.0
3,13,24:18.0
3,14,24:18.0
3,17,24:18
3,28,24:18.0
3,29,24:18.0
3,30,24:18.0
3,31,24:18.0
4,-26,24:18.0
4,-25,24:18.0
4,-24,24:18.0
4,-23,24:18.0
4,-22,24:18.0
4,-9,24:18.0
4,-8,24:18.0
4,0,24:18.0
4,1,24:18.0
4,2,24:18.0
4,3,24:18.0
4,4,24:17.0
4,6,24:18.0
4,7,24:18.0
4,8,24:18.0
4,9,24:18.0
4,12,24:106.2
4,13,24:106
4,14,24:18.0
4,17,24:18
4,29,24:18.0
4,30,24:17.0
4,31,24:18.0
5,-26,24:18.0
5,-25,24:18.0
5,-24,24:18.0
5,-23,24:18.0
5,-4,24:18.0
5,-3,24:18.0
5,1,24:18.0
5,2,24:18.0
5,3,24:17.0
5,4,24:18.0
5,16,24:18
5,17,24:18
5,18,24:18
5,30,24:18.0
5,31,24:18.0
6,-20,24:18.0
6,-4,24:18.0
6,-3,24:17.0
6,-2,24:18.0
6,0,24:18.0
6,1,24:17.0
6,2,24:18.0
6,3,24:18.0
6,4,24:18.0
6,17,24:18
6,23,24:18.0
7,-21,24:18.0
7,-20,24:18.0
7,-19,24:18.0
7,-7,24:18.0
7,-6,24:18.0
7,-5,24:18.0
7,-4,24:18.0
7,-3,24:18.0
7,0,24:18.0
7,1,24:18.0
7,2,24:18.0
7,3,24:18.0
7,4,24:17.0
7,5,24:18.0
7,22,24:18.0
7,23,24:18.0
7,24,24:18.0
7,26,24:18.0
7,27,24:18.0
8,-20,24:18.0
8,-7,24:18.0
8,-6,24:18.0
8,-5,24:18.0
8,-4,24:18.0
8,-3,24:18.0
8,0,24:18.0
8,1,24:18.0
8,2,24:18.0
8,3,24:18.0
8,4,24:18.0
8,5,24:18.0
8,6,24:18.0
8,23,24:18.0
8,25,24:18.0
8,26,24:18.0
8,27,24:18.0
8,28,24:18.0
9,-7,24:18.0
9,-6,24:18.0
9,-5,24:17.0
9,-4,24:18.0
9,-3,24:18.0
9,-2,24:18
9,-1,24:18.0
9,0,24:18.0
9,1,24:18.0
9,2,24:18.0
9,3,24:18.0
9,5,24:18.0
9,24,24:18.0
9,25,24:18.0
9,26,24:18.0
9,27,24:18.0
9,28,24:18.0
9,29,24:18.0
10,-7,24:18.0
10,-6,24:18.0
10,-5,24:18.0
10,-4,24:18.0
10,-3,24:18.0
10,-2,24:18
10,-1,24:18.0
10,0,24:18.0
10,1,24:18.0
10,2,24:18.0
10,3,24:18.0
10,24,24:18.0
10,25,24:18.0
10,26,24:18.0
10,27,24:18.0
10,28,24:18.0
10,29,24:18.0
11,-6,24:18.0
11,-5,24:18.0
11,-4,24:18.0
11,-3,24:18.0
11,-2,24:18
11,-1,24:18.0
11,0,24:18.0
11,1,24:17.0
11,2,24:18.0
11,3,24:18.0
11,25,24:18.0
11,26,24:18.0
11,27,24:18.0
11,28,24:18.0
12,-2,24:18
12,-1,24:18.0
12,0,24:18.0
12,1,24:18.0
12,2,24:18.0
12,3,24:18.0
12,26,24:18.0
12,27,24:18.0
13,-5,24:18
13,-2,24:18
13,-1,24:18.0
13,0,24:18.0
13,1,24:18.0
13,2,24:18.0
13,3,24:18.0
14,-6,24:18
14,-5,24:18
14,-4,24:18
14,-3,24:18
15,-5,24:18
15,-3,24:106.2
16,-4,24:106.4
16,0,24:18.0
16,1,24:18.0
17,0,24:18.0
17,1,24:18.0
17,2,24:18.0
18,0,24:17.0
18,1,24:18.0
18,2,24:18.0
19,0,24:18.0
19,1,24:18.0
19,2,24:18.0
19,8,24:18.0
20,-8,24:18.0
20,-7,24:18.0
20,0,24:18.0
20,1,24:18.0
20,7,24:18.0
20,8,24:18.0
20,9,24:18.0
21,-9,24:18.0
21,-8,24:18.0
21,-7,24:18.0
21,8,24:18.0
22,-10,24:18.0
22,-9,24:18.0
22,3,24:18.0
22,4,24:18.0
22,5,24:18.0
23,-7,24:17.0
23,-1,24:18.0
23,2,24:18.0
23,3,24:18.0
23,4,24:18.0
23,5,24:18.0
23,6,24:18.0
24,-2,24:18.0
24,-1,24:18.0
24,0,24:18.0
24,2,24:18.0
24,3,24:18.0
24,4,24:17.0
24,5,24:18.0
24,6,24:18.0
25,-3,24:18.0
25,-1,24:18.0
25,2,24:18.0
25,3,24:18.0
25,4,24:18.0
25,5,24:18.0
25,6,24:18.0
26,-4,24:18.0
26,-3,24:18.0
26,-2,24:18.0
26,2,24:18.0
26,3,24:18.0
26,4,24:18.0
26,5,24:18.0
26,6,24:18.0
27,-5,24:18.0
27,-4,24:17.0
27,-3,24:18.0
28,-5,24:18.0
28,-4,24:18.0
28,-3,24:18.0
-32,-5,25:18
-31,-6,25:18
-31,-5,25:18
-30,-7,25:18.0
-30,-6,25:18.0
-30,-5,25:17.0
-30,-4,25:18.0
-30,-3,25:18.0
-30,-2,25:18.0
-29,-6,25:18.0
-29,-5,25:18.0
-29,-4,25:18.0
-29,-3,25:18.0
-29,-2,25:18.0
-29,-1,25:18.0
-28,-7,25:18.0
-28,-5,25:18.0
-28,-4,25:18.0
-28,-3,25:18.0
-28,-2,25:18.0
-28,-1,25:18.0
-27,-8,25:18.0
-27,-7,25:17.0
-27,-6,25:18.0
-27,-5,25:18.0
-27,-4,25:18.0
-27,-3,25:18.0
-27,-2,25:18.0
-27,-1,25:18.0
-27,4,25:18.0
-26,-9,25:17.0
-26,-7,25:17.0
-26,-4,25:18.0
-26,-3,25:18.0
-26,-2,25:18.0
-26,3,25:18.0
-26,4,25:17.0
-26,5,25:18.0
-25,-8,25:17.0
-25,-7,25:17.0
-25,-6,25:17.0
-25,-5,25:17.0
-25,3,25:18.0
-25,4,25:18.0
-25,5,25:18.0
-24,-8,25:18.0
-24,-7,25:18.0
-24,-6,25:18.0
-23,-9,25:18.0
-23,-8,25:18.0
-23,-7,25:18.0
-23,-6,25:18.0
-23,-5,25:18.0
-22,-9,25:18.0
-22,-8,25:18.0
-22,-7,25:18.0
-22,-6,25:18.0
-22,-5,25:18.0
-21,-9,25:18.0
-21,-8,25:18.0
-21,-7,25:18.0
-21,-6,25:18.0
-21,-1,25:18.0
-21,0,25:18.0
-21,1,25:18.0
-20,-1,25:18.0
-20,0,25:17.0
-20,1,25:18.0
-19,-1,25:18.0
-19,0,25:18.0
-16,-5,25:18
-16,-3,25:18
-15,-3,25:18
-14,-3,25:18
-14,0,25:18.0
-14,1,25:18.0
-14,2,25:18.0
-13,-7,25:18.0
-13,-6,25:18.0
-13,-5,25:18.0
-13,-4,25:18.0
-13,-3,25:18.0
-13,0,25:18.0
-13,1,25:17.0
-13,2,25:18.0
-12,-7,25:18.0
-12,-6,25:18.0
-12,-5,25:18.0
-12,-4,25:18.0
-12,-3,25:18.0
-12,0,25:18.0
-12,1,25:18.0
-12,2,25:18.0
-11,-7,25:18.0
-11,-6,25:18.0
-11,-5,25:17.0
-11,-4,25:18.0
-11,-3,25:18.0
-11,2,25:18.0
-11,3,25:18.0
-11,4,25:18.0
-11,5,25:18.0
-11,6,25:18.0
-10,-24,25:17.0
-10,-21,25:18.0
-10,-20,25:18.0
-10,-19,25:18.0
-10,-7,25:18.0
-10,-6,25:18.0
-10,-5,25:18.0
-10,-4,25:18.0
-10,-3,25:18.0
-10,0,25:18.0
-10,1,25:18.0
-10,2,25:18.0
-10,3,25:18.0
-10,4,25:18.0
-10,5,25:18.0
-10,6,25:18.0
-9,-25,25:18.0
-9,-23,25:17.0
-9,-22,25:18.0
-9,-21,25:18.0
-9,-20,25:18.0
-9,-19,25:18.0
-9,-18,25:18.0
-9,-7,25:18.0
-9,-6,25:18.0
-9,-5,25:18.0
-9,-4,25:18.0
-9,-3,25:18.0
-9,-1,25:18.0
-9,0,25:18.0
-9,1,25:18.0
-9,2,25:18.0
-9,3,25:18.0
-9,4,25:17.0
-9,5,25:18.0
-9,6,25:18.0
-8,-28,25:18.0
-8,-26,25:18.0
-8,-25,25:17.0
-8,-24,25:17.0
-8,-23,25:17.0
-8,-22,25:18.0
-8,-21,25:18.0
-8,-20,25:18.0
-8,-19,25:18.0
-8,-18,25:18.0
-8,-11,25:18.0
-8,-10,25:18.0
-8,-4,25:18.0
-8,-3,25:18.0
-8,-2,25:18.0
-8,-1,25:18.0
-8,0,25:18.0
-8,1,25:18.0
-8,2,25:18.0
-8,3,25:18.0
-8,4,25:18.0
-8,5,25:17.0
-8,6,25:18.0
-7,-29,25:18.0
-7,-28,25:18.0
-7,-27,25:18.0
-7,-25,25:18.0
-7,-23,25:17.0
-7,-22,25:18.0
-7,-21,25:18.0
-7,-20,25:18.0
-7,-19,25:18.0
-7,-18,25:18.0
-7,-11,25:18.0
-7,-10,25:18.0
-7,-3,25:18.0
-7,-2,25:18.0
-7,-1,25:18.0
-7,0,25:18.0
-7,1,25:18.0
-7,2,25:18.0
-7,3,25:18.0
-7,4,25:17.0
-7,5,25:18.0
-7,6,25:17.0
-7,7,25:18.0
-6,-28,25:18.0
-6,-27,25:18.0
-6,-26,25:18.0
-6,-25,25:18.0
-6,-23,25:17.0
-6,-21,25:18.0
-6,-20,25:18.0
-6,-19,25:18.0
-6,-14,25:18
-6,-11,25:18.0
-6,-10,25:18.0
-6,-9,25:18.0
-6,-8,25:18.0
-6,-7,25:18.0
-6,-2,25:18.0
-6,-1,25:18.0
-6,0,25:18.0
-6,1,25:18.0
-6,2,25:18.0
-6,3,25:18.0
-6,4,25:17.0
-6,5,25:17.0
-6,6,25:18.0
-6,7,25:18.0
-6,8,25:18.0
-6,9,25:18.0
-6,10,25:18.0
-5,-28,25:18.0
-5,-27,25:18.0
-5,-26,25:18.0
-5,-25,25:18.0
-5,-24,25:18.0
-5,-11,25:18.0
-5,-10,25:18.0
-5,-9,25:18.0
-5,3,25:18
-5,4,25:18
-5,8,25:18.0
-5,9,25:18.0
-5,10,25:18.0
-5,11,25:18.0
-5,26,25:18.0
-5,27,25:18.0
-4,-28,25:18.0
-4,-27,25:18.0
-4,-26,25:18.0
-4,-25,25:18.0
-4,-24,25:18.0
-4,-14,25:18
-4,-13,25:18
-4,-12,25:18
-4,-11,25:18.0
-4,-10,25:18.0
-4,-9,25:18.0
-4,-8,25:18.0
-4,-7,25:18.0
-4,-6,25:18.0
-4,-5,25:18.0
-4,4,25:18.0
-4,5,25:18.0
-4,7,25:17.0
-4,8,25:17.0
-4,9,25:18.0
-4,10,25:18.0
-4,11,25:18.0
-4,12,25:18.0
-4,26,25:18.0
-4,27,25:17.0
-4,28,25:18.0
-3,-28,25:18.0
-3,-27,25:18.0
-3,-26,25:18.0
-3,-25,25:18.0
-3,-24,25:18.0
-3,-6,25:18.0
-3,-5,25:18.0
-3,-4,25:18.0
-3,7,25:18.0
-3,8,25:18.0
-3,9,25:18.0
-3,10,25:18.0
-3,11,25:18.0
-3,12,25:18.0
-3,26,25:18.0
-3,27,25:18.0
-2,-27,25:18.0
-2,-26,25:18.0
-2,-25,25:18.0
-2,-19,25:18.0
-2,-18,25:18.0
-2,-17,25:18.0
-2,-7,25:18.0
-2,-6,25:18.0
-2,-5,25:18.0
-2,-4,25:18.0
-2,7,25:18.0
-2,8,25:18.0
-2,9,25:18.0
-2,10,25:18.0
-2,11,25:18.0
-2,12,25:18.0
-2,13,25:18.0
-2,14,25:18.0
-2,15,25:18.0
-1,-19,25:18.0
-1,-18,25:17.0
-1,-17,25:18.0
-1,-12,25:18.0
-1,-11,25:18.0
-1,-10,25:18.0
-1,-8,25:18.0
-1,-7,25:18.0
-1,-6,25:18.0
-1,-5,25:18.0
-1,-4,25:18.0
-1,-3,25:18.0
-1,1,25:20
-1,2,25:20
-1,7,25:18.0
-1,8,25:18.0
-1,9,25:18.0
-1,10,25:18.0
-1,11,25:18.0
-1,13,25:18.0
-1,14,25:17.0
-1,15,25:18.0
-1,21,25:18.0
-1,22,25:18.0
0,-19,25:18.0
0,-18,25:18.0
0,-12,25:18.0
0,-11,25:17.0
0,-10,25:18.0
0,-8,25:18.0
0,-7,25:18.0
0,-6,25:18.0
0,-5,25:18.0
0,-4,25:18.0
0,-3,25:18.0
0,-2,25:18.0
0,1,25:20
0,2,25:20
0,7,25:18.0
0,8,25:18.0
0,9,25:18.0
0,10,25:18.0
0,11,25:18.0
0,13,25:18.0
0,14,25:18.0
0,15,25:18.0
0,20,25:18.0
0,21,25:17.0
0,22,25:18.0
1,-12,25:18.0
1,-11,25:18.0
1,-10,25:18.0
1,-9,25:18.0
1,-8,25:18.0
1,-7,25:18.0
1,-6,25:18.0
1,-5,25:18.0
1,-4,25:18.0
1,-3,25:18.0
1,-2,25:18.0
1,-1,25:18.0
1,5,25:18.0
1,6,25:18.0
1,7,25:18.0
1,8,25:18.0
1,9,25:18.0
1,10,25:18.0
1,20,25:18.0
1,21,25:18.0
1,22,25:18.0
1,28,25:18.0
1,29,25:18.0
1,30,25:18.0
2,-24,25:18.0
2,-23,25:18.0
2,-9,25:18.0
2,-8,25:18.0
2,-7,25:18.0
2,-6,25:18.0
2,-5,25:18.0
2,-4,25:18.0
2,-3,25:18.0
2,-2,25:18.0
2,-1,25:18.0
2,4,25:18.0
2,5,25:18.0
2,6,25:18.0
2,7,25:18.0
2,8,25:18.0
2,9,25:18.0
2,15,25:17.0
2,27,25:18.0
2,28,25:18.0
2,29,25:18.0
2,30,25:18.0
2,31,25:18.0
3,-25,25:18.0
3,-24,25:17.0
3,-23,25:18.0
3,-9,25:18.0
3,-8,25:18.0
3,-7,25:17.0
3,-6,25:18.0
3,-5,25:17.0
3,-4,25:17.0
3,-3,25:18.0
3,-2,25:18.0
3,4,25:18.0
3,5,25:18.0
3,6,25:18.0
3,8,25:18.0
3,9,25:18.0
3,10,25:18.0
3,11,25:18.0
3,12,25:18.0
3,13,25:18.0
3,14,25:18.0
3,15,25:18
3,16,25:18
3,17,25:18
3,27,25:18.0
3,28,25:18.0
3,29,25:18.0
3,30,25:18.0
3,31,25:18.0
4,-24,25:18.0
4,-23,25:18.0
4,-9,25:18.0
4,-8,25:18.0
4,-7,25:18.0
4,-2,25:18.0
4,-1,25:18.0
4,0,25:18.0
4,1,25:18.0
4,2,25:18.0
4,3,25:18.0
4,4,25:17.0
4,5,25:17.0
4,6,25:18.0
4,7,25:18.0
4,8,25:18.0
4,9,25:18.0
4,12,25:106.2
4,13,25:18.0
4,14,25:18.0
4,27,25:18.0
4,28,25:18.0
4,29,25:18.0
4,30,25:18.0
4,31,25:18.0
5,-3,25:18.0
5,-2,25:18.0
5,-1,25:18.0
5,0,25:18.0
5,1,25:18.0
5,2,25:18.0
5,3,25:18.0
5,4,25:17.0
5,5,25:18.0
5,6,25:17.0
5,7,25:18.0
5,14,25:18.0
5,17,25:18
5,22,25:18.0
5,23,25:18.0
5,24,25:18.0
5,26,25:17.0
5,28,25:18.0
5,29,25:18.0
5,30,25:18.0
5,31,25:18.0
6,-4,25:18.0
6,-3,25:18.0
6,-2,25:18.0
6,-1,25:18.0
6,0,25:18.0
6,1,25:18.0
6,2,25:18.0
6,3,25:18.0
6,4,25:18.0
6,5,25:17.0
6,6,25:18.0
6,21,25:18.0
6,22,25:18.0
6,23,25:18.0
6,24,25:18.0
6,25,25:18.0
6,26,25:17.0
6,28,25:18.0
6,30,25:18.0
6,31,25:18.0
6,32,25:18.0
7,-7,25:18.0
7,-6,25:18.0
7,-5,25:18.0
7,-4,25:18.0
7,-3,25:18.0
7,-1,25:18.0
7,0,25:18.0
7,1,25:18.0
7,2,25:18.0
7,3,25:18.0
7,4,25:17.0
7,5,25:18.0
7,6,25:18.0
7,21,25:18.0
7,22,25:18.0
7,23,25:18.0
7,24,25:18.0
7,25,25:18.0
7,26,25:18.0
7,27,25:18.0
7,28,25:17.0
7,29,25:18.0
7,31,25:18.0
8,-7,25:18.0
8,-6,25:18.0
8,-5,25:18.0
8,-4,25:18.0
8,-3,25:18.0
8,0,25:18.0
8,1,25:18.0
8,2,25:18.0
8,3,25:18.0
8,4,25:18.0
8,5,25:18.0
8,6,25:18.0
8,21,25:18.0
8,22,25:18.0
8,23,25:18.0
8,24,25:18.0
8,25,25:18.0
8,26,25:18.0
8,27,25:18.0
8,28,25:18.0
9,-7,25:18.0
9,-6,25:18.0
9,-5,25:17.0
9,-4,25:18.0
9,-3,25:18.0
9,2,25:18.0
9,3,25:18.0
9,4,25:18.0
9,5,25:18.0
9,6,25:18.0
9,22,25:18.0
9,23,25:18.0
9,24,25:18.0
9,25,25:18.0
9,26,25:18.0
9,27,25:18.0
9,28,25:18.0
9,29,25:18.0
10,-7,25:18.0
10,-6,25:18.0
10,-5,25:18.0
10,-4,25:18.0
10,-3,25:18.0
10,0,25:18.0
10,1,25:18.0
10,2,25:18.0
10,24,25:18.0
10,25,25:18.0
10,26,25:18.0
10,27,25:18.0
10,28,25:18.0
10,29,25:18.0
11,-7,25:18.0
11,-6,25:18.0
11,-5,25:18.0
11,-4,25:18.0
11,-3,25:18.0
11,0,25:18.0
11,1,25:17.0
11,2,25:18.0
11,25,25:18.0
11,26,25:18.0
11,27,25:18.0
11,28,25:18.0
12,-3,25:18
12,-1,25:17.0
12,0,25:18.0
12,1,25:18.0
12,2,25:18.0
12,26,25:18.0
12,27,25:18.0
13,-3,25:18
13,0,25:17.0
14,-5,25:18
14,-3,25:18
15,-3,25:106.2
16,-4,25:106.4
17,0,25:18.0
18,-1,25:18.0
18,0,25:17.0
18,1,25:18.0
19,-8,25:18.0
19,-7,25:18.0
19,-1,25:18.0
19,0,25:18.0
19,1,25:18.0
20,-9,25:18.0
20,-8,25:18.0
20,-7,25:18.0
21,-10,25:18.0
21,-9,25:18.0
21,-8,25:18.0
21,-7,25:18.0
22,-11,25:18.0
22,-10,25:18.0
22,-9,25:18.0
22,-8,25:18.0
22,-7,25:18.0
22,-6,25:18.0
23,-10,25:18.0
23,-8,25:17.0
23,-7,25:17.0
23,-6,25:17.0
23,-5,25:17.0
23,3,25:18.0
23,4,25:18.0
23,5,25:18.0
24,-9,25:17.0
24,-7,25:17.0
24,-4,25:18.0
24,-3,25:18.0
24,-2,25:18.0
24,3,25:18.0
24,4,25:17.0
24,5,25:18.0
25,-8,25:18.0
25,-7,25:17.0
25,-6,25:18.0
25,-5,25:18.0
25,-4,25:18.0
25,-3,25:18.0
25,-2,25:18.0
25,-1,25:18.0
25,4,25:18.0
26,-7,25:18.0
26,-5,25:18.0
26,-4,25:18.0
26,-3,25:18.0
26,-2,25:18.0
26,-1,25:18.0
27,-6,25:18.0
27,-5,25:18.0
27,-4,25:18.0
27,-3,25:18.0
27,-2,25:18.0
27,-1,25:18.0
28,-7,25:18.0
28,-6,25:18.0
28,-5,25:18.0
28,-4,25:18.0
28,-3,25:18.0
28,-2,25:18.0
29,-6,25:18.0
-32,-7,26:18
-32,-6,26:18
-32,-5,26:18.0
-31,-7,26:18
-31,-6,26:18
-31,-5,26:18.0
-31,-4,26:18.0
-30,-8,26:18.0
-30,-7,26:18.0
-30,-6,26:18.0
-30,-5,26:18.0
-30,-4,26:18.0
-30,-3,26:18.0
-30,-2,26:18.0
-29,-8,26:18.0
-29,-7,26:18.0
-29,-6,26:18.0
-29,-5,26:18.0
-29,-4,26:18.0
-29,-3,26:18.0
-29,-2,26:18.0
-28,-9,26:18.0
-28,-8,26:18.0
-28,-7,26:18.0
-28,-6,26:18.0
-28,-5,26:18.0
-28,-4,26:18.0
-28,-3,26:18.0
-28,-2,26:18.0
-28,-1,26:18.0
-27,-9,26:18.0
-27,-8,26:18.0
-27,-7,26:18.0
-27,-6,26:18.0
-27,-5,26:18.0
-27,-4,26:18.0
-27,-3,26:18.0
-27,-2,26:18.0
-27,-1,26:18.0
-27,4,26:18.0
-26,-9,26:18.0
-26,-8,26:18.0
-26,-7,26:18.0
-26,-6,26:18.0
-26,-5,26:18.0
-26,-4,26:17.0
-26,-3,26:18.0
-26,-2,26:18.0
-26,3,26:18.0
-26,4,26:18.0
-26,5,26:18.0
-25,-8,26:18.0
-25,-7,26:17.0
-25,-6,26:18.0
-25,-5,26:17.0
-25,-4,26:17.0
-25,-3,26:17.0
-25,-2,26:18.0
-25,4,26:18.0
-24,-8,26:17.0
-24,-7,26:18.0
-24,-6,26:18.0
-24,-3,26:18.0
-23,-9,26:17.0
-23,-8,26:18.0
-23,-7,26:18.0
-23,-6,26:18.0
-23,-5,26:18.0
-22,-9,26:18.0
-22,-8,26:18.0
-22,-7,26:18.0
-22,-6,26:18.0
-21,-9,26:18.0
-21,-8,26:18.0
-21,-7,26:18.0
-21,0,26:18.0
-20,-8,26:18.0
-20,-1,26:18.0
-20,0,26:18.0
-20,1,26:18.0
-19,0,26:18.0
-15,-3,26:18
-14,1,26:18.0
-13,-3,26:18
-13,0,26:18.0
-13,1,26:18.0
-13,2,26:18.0
-12,-24,26:18.0
-12,-5,26:18.0
-12,1,26:18.0
-11,-25,26:18.0
-11,-24,26:17.0
-11,-23,26:18.0
-11,-6,26:18.0
-11,-5,26:17.0
-11,-4,26:18.0
-11,-3,26:18.0
-11,-2,26:18.0
-11,3,26:18.0
-11,4,26:18.0
-11,5,26:18.0
-10,-26,26:18.0
-10,-25,26:18.0
-10,-24,26:18.0
-10,-21,26:17.0
-10,-20,26:18.0
-10,-19,26:18.0
-10,-5,26:18.0
-10,-3,26:18.0
-10,-2,26:18.0
-10,0,26:18.0
-10,1,26:18.0
-10,2,26:18.0
-10,3,26:18.0
-10,4,26:18.0
-10,5,26:18.0
-10,6,26:18.0
-9,-29,26:18.0
-9,-28,26:18.0
-9,-27,26:18.0
-9,-26,26:18.0
-9,-25,26:18.0
-9,-24,26:18.0
-9,-23,26:18.0
-9,-22,26:17.0
-9,-21,26:18.0
-9,-20,26:18.0
-9,-19,26:18.0
-9,-18,26:18.0
-9,-2,26:17.0
-9,-1,26:17.0
-9,0,26:18.0
-9,1,26:18.0
-9,2,26:18.0
-9,3,26:18.0
-9,4,26:17.0
-9,5,26:17.0
-9,6,26:18.0
-9,7,26:18.0
-8,-30,26:18.0
-8,-29,26:18.0
-8,-28,26:18.0
-8,-27,26:18.0
-8,-26,26:18.0
-8,-25,26:18.0
-8,-24,26:18.0
-8,-23,26:17.0
-8,-22,26:18.0
-8,-21,26:18.0
-8,-20,26:18.0
-8,-19,26:18.0
-8,-18,26:18.0
-8,-2,26:18.0
-8,-1,26:18.0
-8,0,26:18.0
-8,1,26:18.0
-8,2,26:18.0
-8,3,26:18.0
-8,4,26:18.0
-8,5,26:18.0
-8,6,26:18.0
-8,7,26:18.0
-8,8,26:18.0
-7,-30,26:18.0
-7,-29,26:18.0
-7,-28,26:18.0
-7,-27,26:18.0
-7,-26,26:18.0
-7,-25,26:18.0
-7,-24,26:18.0
-7,-23,26:18.0
-7,-22,26:18.0
-7,-21,26:18.0
-7,-20,26:18.0
-7,-19,26:18.0
-7,-18,26:18.0
-7,-8,26:18.0
-7,-7,26:18.0
-7,-6,26:18.0
-7,-3,26:18.0
-7,-1,26:18.0
-7,0,26:18.0
-7,1,26:18.0
-7,2,26:18.0
-7,3,26:18.0
-7,4,26:18.0
-7,5,26:17.0
-7,6,26:18.0
-7,7,26:18.0
-7,8,26:18.0
-6,-30,26:18.0
-6,-29,26:18.0
-6,-28,26:18.0
-6,-27,26:18.0
-6,-26,26:18.0
-6,-25,26:18.0
-6,-24,26:18.0
-6,-23,26:17.0
-6,-21,26:18.0
-6,-20,26:18.0
-6,-19,26:18.0
-6,-10,26:18.0
-6,-9,26:18.0
-6,-8,26:18.0
-6,-7,26:18.0
-6,-6,26:18.0
-6,-5,26:18.0
-6,-3,26:18.0
-6,-2,26:18
-6,-1,26:18
-6,0,26:18.0
-6,1,26:18.0
-6,2,26:18.0
-6,3,26:18.0
-6,4,26:17.0
-6,5,26:18.0
-6,6,26:18.0
-6,7,26:18.0
-6,8,26:18.0
-5,-29,26:18.0
-5,-28,26:18.0
-5,-27,26:18.0
-5,-26,26:18.0
-5,-25,26:18.0
-5,-24,26:17.0
-5,-23,26:17.0
-5,-9,26:18.0
-5,0,26:18
-5,1,26:18
-5,2,26:18
-5,4,26:18
-5,9,26:18.0
-5,10,26:18.0
-5,27,26:18.0
-4,-28,26:18.0
-4,-27,26:18.0
-4,-26,26:18.0
-4,-25,26:18.0
-4,-24,26:18.0
-4,-23,26:17.0
-4,-22,26:18.0
-4,-13,26:18
-4,-11,26:18
-4,-9,26:18.0
-4,-8,26:18.0
-4,-5,26:18.0
-4,-4,26:18.0
-4,1,26:18
-4,4,26:18.0
-4,5,26:18.0
-4,6,26:18.0
-4,7,26:17.0
-4,8,26:18.0
-4,9,26:18.0
-4,10,26:18.0
-4,11,26:18.0
-4,26,26:18.0
-4,27,26:18.0
-4,28,26:18.0
-3,-28,26:18.0
-3,-27,26:18.0
-3,-26,26:18.0
-3,-25,26:18.0
-3,-24,26:18.0
-3,-23,26:18.0
-3,-9,26:18.0
-3,-8,26:18.0
-3,-7,26:17.0
-3,-6,26:18.0
-3,5,26:18.0
-3,6,26:18.0
-3,7,26:18.0
-3,8,26:18.0
-3,9,26:18.0
-3,10,26:18.0
-3,27,26:18.0
-2,-27,26:18.0
-2,-26,26:18.0
-2,-25,26:18.0
-2,-18,26:18.0
-2,-7,26:17.0
-2,-6,26:18.0
-2,-5,26:18.0
-2,-4,26:18
-2,7,26:18.0
-2,8,26:18.0
-2,9,26:18.0
-2,10,26:18.0
-2,11,26:18.0
-2,14,26:18.0
-1,-19,26:18.0
-1,-18,26:18.0
-1,-17,26:18.0
-1,-11,26:18.0
-1,-8,26:18.0
-1,-7,26:18.0
-1,-6,26:18.0
-1,-5,26:18.0
-1,-4,26:18.0
-1,7,26:18.0
-1,8,26:18.0
-1,9,26:18.0
-1,10,26:18.0
-1,11,26:18.0
-1,13,26:18.0
-1,14,26:18.0
-1,15,26:18.0
-1,21,26:18.0
0,-18,26:18.0
0,-12,26:18.0
0,-11,26:18.0
0,-10,26:18.0
0,-8,26:18.0
0,-7,26:18.0
0,-6,26:18.0
0,-5,26:18.0
0,-4,26:18.0
0,-3,26:18.0
0,7,26:18.0
0,8,26:18.0
0,9,26:18.0
0,10,26:18.0
0,11,26:18.0
0,13,26:17.0
0,14,26:18.0
0,20,26:18.0
0,21,26:18.0
0,22,26:18.0
1,-11,26:18.0
1,-8,26:18.0
1,-7,26:18.0
1,-6,26:18.0
1,-5,26:18.0
1,-4,26:18.0
1,-3,26:18.0
1,-2,26:18.0
1,5,26:18.0
1,6,26:18.0
1,8,26:18.0
1,9,26:18.0
1,10,26:17.0
1,14,26:18
1,15,26:18
1,21,26:18.0
1,28,26:18.0
1,29,26:18.0
1,30,26:18.0
2,-24,26:18.0
2,-9,26:18.0
2,-8,26:18.0
2,-7,26:18.0
2,-6,26:18.0
2,-5,26:18.0
2,-4,26:18.0
2,-3,26:18.0
2,4,26:18.0
2,5,26:18.0
2,6,26:18.0
2,9,26:18.0
2,10,26:17.0
2,11,26:18.0
2,12,26:18.0
2,14,26:17.0
2,15,26:18
2,26,26:18.0
2,27,26:18.0
2,28,26:18.0
2,29,26:18.0
2,30,26:18.0
2,31,26:18.0
3,-25,26:18.0
3,-24,26:18.0
3,-23,26:18.0
3,-9,26:18.0
3,-8,26:18.0
3,-7,26:17.0
3,-6,26:18.0
3,-5,26:18.0
3,-4,26:17.0
3,-3,26:18.0
3,-2,26:18.0
3,-1,26:18.0
3,4,26:18.0
3,5,26:18.0
3,6,26:18.0
3,7,26:18.0
3,8,26:18.0
3,11,26:18.0
3,12,26:18.0
3,14,26:18
3,16,26:18
3,25,26:18.0
3,26,26:17.0
3,27,26:18.0
3,28,26:18.0
3,29,26:18.0
3,30,26:18.0
3,31,26:18.0
4,-24,26:18.0
4,-9,26:18.0
4,-8,26:18.0
4,-7,26:18.0
4,-6,26:18.0
4,-5,26:18.0
4,-3,26:18.0
4,0,26:18.0
4,1,26:18.0
4,2,26:18.0
4,3,26:18.0
4,4,26:17.0
4,5,26:18.0
4,6,26:18.0
4,7,26:18.0
4,8,26:18.0
4,12,26:106.2
4,26,26:17.0
4,27,26:17.0
4,28,26:18.0
