[META]
version=2.0
spawnOnBlockType=2
spawnSunlight=True
spawnDarkness=True
spawnWater=True
spawnLava=False
underFill=False
randomRotation=False
dig=True
tree=True
branch=False
needsFoundation=False
rarity=100
collisionPercentage=100
spawnElevationMin=70
spawnElevationMax=79
spawnInBiome=TemperateSwampland,TemperateSwamplandBorder,TemperateWoodlandWetland
[DATA]
-2,0,-1:17.4
-1,0,-1:17.0
0,0,-1:17.0
0,1,-1:17.8
-2,-6,0:106.1
-3,-5,0:106.8
-3,-4,0:106.8
-3,-3,0:106.8
-1,0,0:17.0
0,0,0:17.0
-2,-6,1:106.1
-3,-5,1:106.8
-3,-4,1:106.8
-3,-3,1:106.8
-3,0,1:17.0
-2,0,1:17.4
-1,0,1:17.0
-4,4,1:106.8
-3,5,1:106.4
-2,-6,2:106.1
-3,-5,2:106.8
-3,-4,2:106.8
-3,-3,2:106.8
-1,-3,2:18
-1,-2,2:18
-4,-1,2:18
-1,-1,2:17.8
-5,0,2:18
-4,0,2:18
-3,0,2:17.0
-2,0,2:18
-1,0,2:17.0
-4,1,2:18
-3,1,2:18
-2,1,2:18
-4,2,2:18
-3,2,2:18
-2,2,2:18
-4,4,2:106.8
-3,5,2:106.4
-2,-6,3:106.1
-3,-5,3:106.8
-2,-5,3:18
-1,-5,3:18
-3,-4,3:106.8
-2,-4,3:18
-1,-4,3:17.8
0,-4,3:18
-3,-3,3:106.8
-2,-3,3:18
-1,-3,3:17.8
0,-3,3:18
-3,-2,3:18
-2,-2,3:17.4
-1,-2,3:17.8
0,-2,3:18
1,-2,3:18
-2,-1,3:18
-1,-1,3:18
0,-1,3:18
-4,0,3:18
-3,0,3:18
-1,0,3:17.0
-3,1,3:18
-4,4,3:106.8
-3,5,3:106.4
-1,-4,4:18
-1,-3,4:18
0,-3,4:18
-2,-2,4:18
-1,-2,4:18
0,-2,4:18
-1,-1,4:18
0,-1,4:18
-1,0,4:18
-1,1,4:17.8
0,1,4:18
-2,2,4:18
-1,2,4:17.8
0,2,4:18
-1,3,4:18
-4,4,4:106.8
-3,5,4:106.4
-2,5,4:106
-1,1,5:18
0,1,5:18
-3,2,5:18
-2,2,5:18
-1,2,5:17.8
0,2,5:18
-3,3,5:18
-2,3,5:18
-1,3,5:17.8
0,3,5:18
-4,4,5:106.8
-3,4,5:18
-2,4,5:18
-1,4,5:18
0,4,5:18
-3,5,5:106.4
-2,5,5:18
-1,5,5:18
-1,2,6:18
-1,3,6:18
-2,4,6:18
-1,4,6:18
