[META]
version=2.0
spawnOnBlockType=2
spawnSunlight=True
spawnDarkness=True
spawnWater=True
spawnLava=False
underFill=False
randomRotation=False
dig=True
tree=True
branch=False
needsFoundation=False
rarity=100
collisionPercentage=100
spawnElevationMin=70
spawnElevationMax=79
spawnInBiome=TemperateSwampland,TemperateSwamplandBorder,TemperateWoodlandWetland
[DATA]
-2,0,-3:17.0
0,0,-3:17.0
0,-3,-2:17.0
0,-1,-2:17.0
-2,0,-2:17.0
0,0,-2:17.0
1,0,-2:17.0
0,-3,-1:17.8
0,-2,-1:17.8
0,-1,-1:17.0
-2,0,-1:17.4
-1,0,-1:17.4
0,0,-1:17.0
1,0,-1:17.4
0,-1,0:17.0
0,0,0:17.0
0,0,1:17.0
0,1,1:17.0
-1,1,2:17.0
0,1,2:17.0
-3,-5,3:18
-4,-4,3:18
-3,-4,3:17.4
-2,-4,3:18
-3,-3,3:18
-2,-3,3:17.8
-1,-3,3:18
2,-3,3:18
-2,-2,3:18
1,-2,3:18
3,-2,3:18
-1,-1,3:18
3,-1,3:18
-2,0,3:18
-1,0,3:17.8
2,0,3:18
-3,1,3:18
-2,1,3:17.4
-1,1,3:17.0
-4,2,3:18
-3,2,3:17.8
-2,2,3:18
-1,2,3:18
-3,3,3:18
-3,-4,4:18
-2,-3,4:18
-3,-2,4:18
-2,-2,4:17.0
-1,-2,4:18
0,-2,4:18
1,-2,4:18
2,-2,4:18
-2,-1,4:18
-1,-1,4:17.0
0,-1,4:18
1,-1,4:17.4
2,-1,4:18
-2,0,4:18
-1,0,4:17.0
0,0,4:17.4
1,0,4:18
-2,1,4:18
-1,1,4:18
-3,2,4:18
-2,2,4:18
-1,2,4:18
0,2,4:17.8
1,2,4:17.4
2,2,4:18
0,3,4:18
1,3,4:17.8
2,3,4:18
1,4,4:18
-2,-2,5:18
-1,-1,5:18
1,-1,5:18
-1,0,5:18
0,0,5:18
1,0,5:18
-1,1,5:18
0,1,5:17.8
1,1,5:18
-1,2,5:18
0,2,5:17.8
1,2,5:18
2,2,5:18
0,3,5:18
1,3,5:18
0,1,6:18
0,2,6:18
