[META]
version=2.0
spawnOnBlockType=2
spawnSunlight=True
spawnDarkness=True
spawnWater=True
spawnLava=False
underFill=False
randomRotation=False
dig=True
tree=True
branch=False
needsFoundation=False
rarity=100
collisionPercentage=100
spawnElevationMin=70
spawnElevationMax=79
spawnInBiome=TemperateSwampland,TemperateSwamplandBorder,TemperateWoodlandWetland
[DATA]
4,2,-2:17.4
5,2,-2:17.4
-1,-1,-1:17.0
0,0,-1:17.0
1,0,-1:17.0
1,2,-1:17.0
3,2,-1:17.4
4,2,-1:17.8
0,3,-1:17.0
4,3,-1:17.8
-2,4,-1:17.0
1,4,-1:17.0
4,4,-1:17.8
-1,-1,0:17.0
-1,0,0:17.0
0,0,0:17.0
1,0,0:17.8
-1,1,0:17.0
0,1,0:17.0
1,1,0:17.0
0,2,0:17.0
1,2,0:17.0
3,2,0:17.0
0,3,0:17.0
1,3,0:17.8
2,3,0:17.4
3,3,0:17.4
-2,4,0:17.0
1,4,0:17.8
-1,-10,1:106.1
-2,-9,1:106.8
0,-9,1:106.1
1,-8,1:106.2
-1,0,1:17.0
0,0,1:17.0
-1,1,1:17.0
0,1,1:17.0
1,1,1:17.0
0,2,1:17.0
1,2,1:17.0
2,2,1:17.0
3,2,1:17.0
-2,3,1:17.4
-1,3,1:17.4
0,3,1:17.0
-2,4,1:17.8
-1,-10,2:106.1
-2,-9,2:106.8
0,-9,2:106.1
1,-8,2:106.2
0,-1,2:17.0
-1,0,2:17.0
0,0,2:17.0
1,0,2:17.0
-2,1,2:17.0
-1,1,2:17.0
0,1,2:17.0
1,1,2:17.0
0,2,2:17.0
1,2,2:17.0
-1,-10,3:106.1
-2,-9,3:106.8
0,-9,3:106.1
1,-8,3:106.2
-1,-1,3:17.0
0,-1,3:17.0
1,-1,3:17.0
-1,0,3:17.0
0,0,3:17.0
1,0,3:17.0
2,0,3:18
-3,1,3:17.0
-2,1,3:17.0
-1,1,3:17.0
0,1,3:17.0
-1,-10,4:106.1
-2,-9,4:106.8
0,-9,4:106.1
1,-8,4:106.2
5,-5,4:18
4,-4,4:18
5,-4,4:17.8
6,-4,4:18
5,-3,4:18
-1,-1,4:17.0
0,-1,4:17.0
1,-1,4:17.0
-3,0,4:17.0
0,0,4:17.0
1,0,4:17.0
2,0,4:17.0
3,0,4:18
-4,1,4:17.0
-3,1,4:17.0
-2,1,4:17.0
0,1,4:18
1,1,4:18
2,1,4:18
-5,2,4:17.0
-4,2,4:17.0
-3,2,4:18
-2,2,4:18
-5,3,4:18
-4,3,4:17.0
-3,3,4:18
-4,4,4:18
-1,-10,5:106.1
-2,-9,5:106.8
0,-9,5:106.1
1,-8,5:106.2
4,-5,5:18
5,-5,5:18
0,-4,5:18
3,-4,5:18
4,-4,5:18
5,-4,5:17.0
6,-4,5:18
0,-3,5:17.8
1,-3,5:18
2,-3,5:18
3,-3,5:18
4,-3,5:17.4
5,-3,5:17.8
6,-3,5:18
-3,-2,5:18
-2,-2,5:17.4
-1,-2,5:17.4
0,-2,5:17.8
1,-2,5:17.8
4,-2,5:18
5,-2,5:18
-3,-1,5:18
-2,-1,5:18
-1,-1,5:17.0
0,-1,5:17.0
1,-1,5:17.0
2,-1,5:18
-4,0,5:18
-3,0,5:18
-2,0,5:18
-1,0,5:18
0,0,5:17.0
1,0,5:17.0
2,0,5:17.0
3,0,5:18
-4,1,5:18
-3,1,5:18
-2,1,5:18
0,1,5:18
1,1,5:18
2,1,5:17.4
3,1,5:17.4
4,1,5:18
-5,2,5:18
-4,2,5:18
-3,2,5:18
-2,2,5:18
1,2,5:18
2,2,5:18
3,2,5:17.8
4,2,5:18
-4,3,5:18
-3,3,5:18
-2,3,5:18
0,3,5:18
1,3,5:17.4
2,3,5:18
3,3,5:17.4
1,4,5:18
4,4,5:18
3,5,5:18
4,5,5:17.8
5,5,5:18
4,6,5:18
5,6,5:18
-1,-10,6:106.1
-2,-9,6:106.8
0,-9,6:106.1
1,-8,6:106.2
1,-6,6:18
2,-6,6:18
3,-6,6:18
0,-5,6:18
1,-5,6:18
2,-5,6:18
3,-5,6:18
4,-5,6:18
-2,-4,6:18
-1,-4,6:18
0,-4,6:17.8
1,-4,6:18
2,-4,6:18
3,-4,6:18
4,-4,6:18
5,-4,6:18
-2,-3,6:18
-1,-3,6:18
0,-3,6:17.8
1,-3,6:18
2,-3,6:18
3,-3,6:18
4,-3,6:17.4
5,-3,6:18
-2,-2,6:18
-1,-2,6:18
0,-2,6:18
1,-2,6:18
2,-2,6:17.4
3,-2,6:17.4
4,-2,6:17.4
5,-2,6:18
-1,-1,6:18
0,-1,6:18
1,-1,6:17.0
2,-1,6:17.0
3,-1,6:18
4,-1,6:18
-1,0,6:18
0,0,6:17.0
1,0,6:17.0
2,0,6:18
3,0,6:18
-2,1,6:18
-1,1,6:18
0,1,6:18
1,1,6:18
2,1,6:18
3,1,6:18
-2,2,6:18
-1,2,6:18
0,2,6:18
1,2,6:18
2,2,6:18
3,2,6:17.0
4,2,6:18
5,2,6:18
-2,3,6:18
-1,3,6:18
0,3,6:18
1,3,6:17.0
2,3,6:17.0
3,3,6:17.4
4,3,6:17.4
5,3,6:18
0,4,6:18
1,4,6:18
2,4,6:18
3,4,6:18
4,4,6:17.0
5,4,6:18
2,5,6:18
3,5,6:18
4,5,6:17.0
5,5,6:18
3,6,6:18
4,6,6:18
-1,-10,7:106.1
-2,-9,7:106.8
-1,-9,7:18
0,-9,7:106.1
-2,-8,7:18
-1,-8,7:17.8
0,-8,7:18
1,-8,7:106.2
-3,-7,7:18
-2,-7,7:18
-1,-7,7:18
0,-7,7:18
1,-7,7:18
-3,-6,7:18
-2,-6,7:18
0,-6,7:18
1,-6,7:18
-3,-5,7:18
-2,-5,7:18
0,-5,7:17.8
1,-5,7:18
-2,-4,7:18
-1,-4,7:18
0,-4,7:17.8
1,-4,7:18
3,-4,7:18
-1,-3,7:18
0,-3,7:18
1,-3,7:18
2,-3,7:18
4,-3,7:18
0,-2,7:18
1,-2,7:18
2,-2,7:18
3,-2,7:18
4,-2,7:18
-1,-1,7:18
0,-1,7:18
1,-1,7:18
2,-1,7:18
0,0,7:18
1,0,7:18
-1,1,7:18
0,1,7:18
1,1,7:18
1,2,7:18
2,2,7:18
3,2,7:18
4,2,7:18
1,3,7:18
2,3,7:18
3,3,7:18
4,3,7:18
3,4,7:18
4,4,7:18
4,5,7:18
-1,-9,8:18
0,-9,8:106.1
-2,-8,8:18
-1,-8,8:17.0
0,-8,8:18
1,-8,8:106.2
-2,-7,8:18
-1,-7,8:17.8
0,-7,8:18
-3,-6,8:18
-2,-6,8:18
-1,-6,8:17.8
0,-6,8:18
1,-6,8:18
-2,-5,8:18
-1,-5,8:18
0,-5,8:18
-1,-4,8:18
0,-4,8:18
-1,-8,9:18
-1,-7,9:18
-1,-6,9:18
