[META]
version=2.0
spawnOnBlockType=8,9
spawnSunlight=True
spawnDarkness=True
spawnWater=True
spawnLava=False
underFill=False
randomRotation=False
dig=True
tree=True
branch=False
needsFoundation=False
rarity=100
collisionPercentage=100
spawnElevationMin=70
spawnElevationMax=79
spawnInBiome=TemperateSwampland,TemperateSwamplandBorder,TemperateWoodlandWetland
[DATA]
0,-3,-2:17.0
0,0,-2:17.0
-1,2,-2:17.0
0,-3,-1:17.0
-3,0,-1:17.0
0,0,-1:17.0
-1,2,-1:17.0
0,-3,0:17.0
-3,0,0:17.0
0,0,0:17.0
-1,2,0:17.0
0,-3,1:17.0
0,-2,1:17.8
0,-1,1:17.8
-3,0,1:17.0
-2,0,1:17.4
-1,0,1:17.4
0,0,1:17.0
-1,1,1:17.8
-1,2,1:17.0
0,-4,2:18
-1,-3,2:18
0,-3,2:17.0
1,-3,2:18
0,-2,2:18
-3,0,2:17.0
0,0,2:17.0
-1,1,2:18
-2,2,2:18
-1,2,2:18
0,2,2:18
-1,3,2:18
0,-3,3:18
-3,-1,3:18
-4,0,3:18
-3,0,3:18
-2,0,3:18
0,0,3:17.0
-3,1,3:18
-2,1,3:18
-1,2,3:18
-1,-1,4:18
0,-1,4:18
-3,0,4:18
-2,0,4:18
-1,0,4:18
0,0,4:17.0
1,0,4:18
0,1,4:18
1,1,4:18
-1,-1,5:18
0,-1,5:18
1,-1,5:18
-2,0,5:18
-1,0,5:18
0,0,5:17.0
1,0,5:18
2,0,5:18
-1,1,5:18
0,1,5:18
1,1,5:18
2,1,5:18
0,2,5:18
1,2,5:18
0,-1,6:18
-1,0,6:18
0,0,6:18
1,0,6:18
0,1,6:18
1,1,6:18
0,0,7:18
