[META]
ersion=2.0
spawnOnBlockType=2
spawnSunlight=True
spawnDarkness=True
spawnWater=False
spawnLava=False
underFill=False
randomRotation=True
dig=True
tree=True
branch=False
needsFoundation=True
rarity=30
collisionPercentage=1
spawnElevationMin=74
spawnElevationMax=256
spawnInBiome=TemperateLakeBorder,TemperateMarshland,TemperateMarshlandBorder,TemperateSwampland,TemperateswamplandBorder,TemperateWoodlandWetland
[DATA]
0,0,0:17.0
-2,-5,1:106.1
-1,-5,1:106.8
1,-5,1:106.2
3,-5,1:106.1
-3,-4,1:106.8
-1,-4,1:106.9
1,-4,1:106.3
2,-4,1:106.1
4,-4,1:106.2
-4,-3,1:106.8
-2,-3,1:106.4
-1,-3,1:106.8
4,-3,1:106.1
5,-3,1:106.1
-5,-2,1:106.1
-4,-2,1:106.1
-3,-2,1:106.4
3,-2,1:106.8
6,-2,1:106.2
-6,-1,1:106.8
-4,-1,1:106.2
3,-1,1:106.8
5,-1,1:106.2
-5,0,1:106.8
0,0,1:17.0
5,0,1:106.2
-4,1,1:106.8
4,1,1:106.2
-5,2,1:106.1
-4,2,1:106.1
4,2,1:106.2
-6,3,1:106.8
0,3,1:106.2
5,3,1:106.2
-6,4,1:106.8
-3,4,1:106.4
-2,4,1:106.12
0,4,1:106.2
2,4,1:106.14
5,4,1:106.2
-5,5,1:106.4
-4,5,1:106.4
2,5,1:106.2
3,5,1:106.4
4,5,1:106.4
-2,-5,2:106.1
-1,-5,2:106.8
1,-5,2:106.2
3,-5,2:106.1
-3,-4,2:106.8
-1,-4,2:106.9
1,-4,2:106.3
2,-4,2:106.1
4,-4,2:106.2
-4,-3,2:106.8
-2,-3,2:106.4
-1,-3,2:106.8
4,-3,2:106.1
5,-3,2:106.1
-5,-2,2:106.1
-4,-2,2:106.1
-3,-2,2:106.4
3,-2,2:106.8
6,-2,2:106.2
-6,-1,2:106.8
-4,-1,2:106.2
3,-1,2:106.8
5,-1,2:106.2
-5,0,2:106.8
0,0,2:17.0
5,0,2:106.2
-4,1,2:106.8
4,1,2:106.2
-5,2,2:106.1
-4,2,2:106.1
4,2,2:106.2
-6,3,2:106.8
0,3,2:106.2
5,3,2:106.2
-6,4,2:106.8
-3,4,2:106.4
-2,4,2:106.12
0,4,2:106.2
2,4,2:106.14
5,4,2:106.2
-5,5,2:106.4
-4,5,2:106.4
-1,5,2:106.4
2,5,2:106.2
3,5,2:106.4
4,5,2:106.4
-2,-5,3:106.1
-1,-5,3:106.8
1,-5,3:106.2
3,-5,3:106.1
-3,-4,3:106.8
-1,-4,3:106.9
1,-4,3:106.3
2,-4,3:106.1
4,-4,3:106.2
-4,-3,3:106.8
-2,-3,3:106.4
-1,-3,3:106.8
4,-3,3:106.1
5,-3,3:106.1
-5,-2,3:106.1
-4,-2,3:106.1
-3,-2,3:106.4
3,-2,3:106.8
6,-2,3:106.2
-6,-1,3:106.8
-4,-1,3:106.2
3,-1,3:106.8
5,-1,3:106.2
-5,0,3:106.8
0,0,3:17.0
5,0,3:106.2
-4,1,3:106.8
4,1,3:106.2
-5,2,3:106.1
-4,2,3:106.1
4,2,3:106.2
-6,3,3:106.8
0,3,3:106.2
5,3,3:106.2
-6,4,3:106.8
-3,4,3:106.4
-2,4,3:106.12
0,4,3:106.2
2,4,3:106.14
5,4,3:106.2
-5,5,3:106.4
-4,5,3:106.4
-1,5,3:106.4
2,5,3:106.2
3,5,3:106.4
4,5,3:106.4
-2,-5,4:106.1
-1,-5,4:106.8
0,-5,4:18
1,-5,4:106.2
3,-5,4:106.1
-3,-4,4:106.8
-1,-4,4:106.9
1,-4,4:106.3
2,-4,4:106.1
4,-4,4:106.2
-4,-3,4:106.8
-2,-3,4:106.4
-1,-3,4:106.8
4,-3,4:106.1
5,-3,4:106.1
-5,-2,4:106.1
-4,-2,4:106.1
-3,-2,4:106.4
3,-2,4:106.8
6,-2,4:106.2
-6,-1,4:106.8
-4,-1,4:106.2
3,-1,4:106.8
5,-1,4:106.2
-5,0,4:106.8
0,0,4:17.0
5,0,4:106.2
-4,1,4:106.8
4,1,4:106.2
-5,2,4:106.1
-4,2,4:106.1
4,2,4:106.2
-6,3,4:106.8
0,3,4:106.2
5,3,4:106.2
-6,4,4:106.8
-3,4,4:106.4
-2,4,4:106.12
-1,4,4:18
0,4,4:106.2
2,4,4:106.14
5,4,4:106.2
-5,5,4:106.4
-4,5,4:106.4
-1,5,4:106.4
2,5,4:106.2
3,5,4:106.4
4,5,4:106.4
-2,-5,5:106.1
-1,-5,5:106.8
0,-5,5:18
1,-5,5:106.2
3,-5,5:106.1
-3,-4,5:106.8
-2,-4,5:18
-1,-4,5:106.9
1,-4,5:106.3
2,-4,5:106.1
4,-4,5:106.2
-4,-3,5:106.8
-2,-3,5:106.4
-1,-3,5:106.8
4,-3,5:106.1
5,-3,5:106.1
-5,-2,5:106.1
-4,-2,5:106.1
-3,-2,5:106.4
-1,-2,5:106
3,-2,5:106.8
5,-2,5:18
6,-2,5:106.2
-6,-1,5:106.8
-5,-1,5:18.0
-4,-1,5:106.2
-1,-1,5:17.4
0,-1,5:17.8
1,-1,5:18.0
3,-1,5:106.8
5,-1,5:106.2
-5,0,5:106.8
0,0,5:17.0
5,0,5:106.2
-4,1,5:106.8
-3,1,5:18
-2,1,5:17.4
-1,1,5:17.4
0,1,5:17.8
4,1,5:106.2
-5,2,5:106.1
-4,2,5:106.1
-1,2,5:18.0
0,2,5:18
4,2,5:106.2
-6,3,5:106.8
-1,3,5:18
0,3,5:106.2
5,3,5:106.2
-6,4,5:106.8
-5,4,5:18.0
-3,4,5:106.4
-2,4,5:106.12
-1,4,5:18
0,4,5:106.2
2,4,5:106.14
4,4,5:18
5,4,5:106.2
-5,5,5:106.4
-4,5,5:106.4
-1,5,5:106.4
2,5,5:106.2
3,5,5:106.4
4,5,5:106.4
-2,-5,6:106.1
-1,-5,6:106.8
0,-5,6:18
1,-5,6:106.2
3,-5,6:106.1
-2,-4,6:18
-1,-4,6:106.9
0,-4,6:18
1,-4,6:106.3
2,-4,6:106.1
4,-4,6:106.2
-4,-3,6:106.8
-3,-3,6:18
-1,-3,6:106.8
0,-3,6:18
4,-3,6:106.1
5,-3,6:106.1
-5,-2,6:106.1
-4,-2,6:106.1
-3,-2,6:106.4
-1,-2,6:17.0
0,-2,6:18
3,-2,6:106.8
5,-2,6:18
6,-2,6:106.2
-6,-1,6:106.8
-5,-1,6:18.0
-4,-1,6:106.2
-1,-1,6:17.0
0,-1,6:18.0
3,-1,6:106.8
5,-1,6:106.2
-5,0,6:106.8
-3,0,6:17.0
-1,0,6:18.0
0,0,6:17.0
1,0,6:18.0
5,0,6:106.2
-4,1,6:106.8
-3,1,6:17.0
-2,1,6:17.0
-1,1,6:18.0
0,1,6:18.0
4,1,6:106.2
-5,2,6:106.1
-4,2,6:106.1
-2,2,6:18.0
-1,2,6:18.0
4,2,6:106.2
-6,3,6:106.8
-4,3,6:18.0
-1,3,6:18.0
0,3,6:106.2
5,3,6:106.2
-5,4,6:18.0
-4,4,6:18.0
-3,4,6:106.4
-2,4,6:106.12
-1,4,6:18.0
0,4,6:106.2
2,4,6:106.14
4,4,6:18
5,4,6:106.2
-5,5,6:106.4
-4,5,6:106.4
-1,5,6:106.4
2,5,6:106.2
3,5,6:106.4
4,5,6:106.4
-2,-5,7:106.1
3,-5,7:106.1
-2,-4,7:18
-1,-4,7:106.1
0,-4,7:18
1,-4,7:106.1
2,-4,7:106.1
3,-4,7:18
4,-4,7:106.2
-3,-3,7:18
-2,-3,7:17.0
-1,-3,7:18
0,-3,7:17.0
1,-3,7:18
2,-3,7:18
3,-3,7:18
4,-3,7:106.1
5,-3,7:106.1
-4,-2,7:106.1
-3,-2,7:18
-2,-2,7:18
-1,-2,7:18
0,-2,7:18
1,-2,7:18
2,-2,7:18
3,-2,7:106.8
4,-2,7:18
5,-2,7:18
6,-2,7:106.2
-6,-1,7:106.8
-5,-1,7:18.0
-4,-1,7:18.0
-3,-1,7:18.0
-1,-1,7:18.0
1,-1,7:18.0
2,-1,7:18
3,-1,7:106.8
4,-1,7:17.0
5,-1,7:106.2
-5,0,7:106.8
-4,0,7:17.0
-3,0,7:17.0
0,0,7:17.0
1,0,7:17.0
2,0,7:17.0
5,0,7:106.2
-4,1,7:106.8
-3,1,7:18.0
-2,1,7:18.0
-1,1,7:18.0
0,1,7:17.0
1,1,7:17.0
2,1,7:18
3,1,7:18
4,1,7:106.2
-5,2,7:106.1
-4,2,7:18.0
-2,2,7:18.0
-1,2,7:18.0
0,2,7:18.0
1,2,7:18.0
2,2,7:17.0
4,2,7:106.2
-6,3,7:106.8
-5,3,7:18.0
-4,3,7:17.0
-3,3,7:18.0
-2,3,7:18.0
-1,3,7:18.0
0,3,7:18.0
1,3,7:18.0
2,3,7:18
5,3,7:106.2
-4,4,7:18.0
-3,4,7:106.4
-2,4,7:106.4
-1,4,7:106.4
1,4,7:18.0
2,4,7:106.14
4,4,7:18
5,4,7:106.2
1,5,7:18.0
2,5,7:106.2
3,5,7:106.4
4,5,7:106.4
-1,-4,8:106.1
0,-4,8:106.1
3,-4,8:106.1
-3,-3,8:106.8
-2,-3,8:18
-1,-3,8:18
0,-3,8:18
1,-3,8:106.1
2,-3,8:18
3,-3,8:18
-4,-2,8:106.1
-3,-2,8:106.8
-2,-2,8:18
-1,-2,8:18
0,-2,8:18
1,-2,8:18
2,-2,8:18
3,-2,8:18
4,-2,8:18
5,-2,8:106.2
-5,-1,8:106.8
-4,-1,8:18.0
-3,-1,8:18.0
-2,-1,8:18.0
0,-1,8:18.0
1,-1,8:18.0
2,-1,8:18
3,-1,8:17.0
4,-1,8:18
-4,0,8:18.0
-3,0,8:18.0
-2,0,8:18.0
0,0,8:17.0
1,0,8:18.0
2,0,8:17.0
3,0,8:18
4,0,8:18
5,0,8:106.2
-4,1,8:106.8
-3,1,8:18.0
-2,1,8:18.0
-1,1,8:18.0
0,1,8:17.0
1,1,8:18.0
2,1,8:18
3,1,8:18
4,1,8:106.2
-4,2,8:18.0
-3,2,8:17.0
-2,2,8:18.0
-1,2,8:18.0
0,2,8:18.0
1,2,8:18.0
2,2,8:18
3,2,8:18
4,2,8:106.2
-4,3,8:18.0
-3,3,8:18.0
-2,3,8:18.0
-1,3,8:18.0
0,3,8:106.4
1,3,8:18.0
2,3,8:18
3,3,8:17.0
4,3,8:18
5,3,8:106.2
-2,4,8:106.4
-1,4,8:106.4
2,4,8:106.12
3,4,8:18
4,4,8:18
5,4,8:106.2
3,5,8:106.4
4,5,8:106.4
-1,-3,9:106.1
0,-3,9:106.1
1,-3,9:106.1
2,-3,9:106.1
3,-3,9:106.1
-1,-2,9:18
0,-2,9:18
1,-2,9:18
2,-2,9:18
3,-2,9:18
4,-2,9:106.2
-2,-1,9:18.0
-1,-1,9:18.0
0,-1,9:18.0
1,-1,9:18.0
2,-1,9:18
3,-1,9:18
4,-1,9:106.2
-4,0,9:106.8
-3,0,9:18.0
-2,0,9:18.0
-1,0,9:18.0
0,0,9:17.0
1,0,9:18.0
2,0,9:18
3,0,9:106.2
-4,1,9:106.8
-3,1,9:18.0
-2,1,9:18.0
-1,1,9:17.0
0,1,9:18.0
1,1,9:18.0
2,1,9:18
3,1,9:106.2
-4,2,9:106.8
-3,2,9:18.0
-2,2,9:17.0
-1,2,9:18.0
0,2,9:18.0
1,2,9:18.0
2,2,9:18
-3,3,9:106.8
-2,3,9:18.0
-1,3,9:18.0
0,3,9:106.4
1,3,9:106.4
2,3,9:18
3,3,9:18
4,3,9:106.2
-2,4,9:106.4
-1,4,9:106.4
2,4,9:106.4
3,4,9:106.4
-1,-2,10:106.1
0,-2,10:106.1
1,-2,10:106.1
2,-2,10:106.1
-1,-1,10:18.0
0,-1,10:18.0
1,-1,10:18.0
2,-1,10:18
-3,0,10:106.8
-2,0,10:18.0
-1,0,10:18.0
0,0,10:18.0
1,0,10:18.0
2,0,10:18
3,0,10:106.2
-3,1,10:106.8
-2,1,10:18.0
-1,1,10:18.0
0,1,10:18.0
1,1,10:18.0
2,1,10:18
3,1,10:106.2
-3,2,10:106.8
-2,2,10:18.0
-1,2,10:18.0
0,2,10:18.0
1,2,10:106.4
2,2,10:106.4
-2,3,10:106.4
-1,3,10:106.4
0,3,10:106.4
