[META]
version=2.0
spawnOnBlockType=8,9
spawnSunlight=True
spawnDarkness=True
spawnWater=True
spawnLava=False
underFill=False
randomRotation=False
dig=True
tree=True
branch=False
needsFoundation=False
rarity=100
collisionPercentage=100
spawnElevationMin=70
spawnElevationMax=79
spawnInBiome=TemperateSwampland,TemperateSwamplandBorder,TemperateWoodlandWetland
[DATA]
0,-2,-2:17.0
2,2,-2:17.0
-1,3,-2:17.0
0,-2,-1:17.0
-4,0,-1:17.0
2,2,-1:17.0
-1,3,-1:17.0
0,-2,0:17.0
-4,0,0:17.0
2,2,0:17.0
-1,3,0:17.0
0,-2,1:17.0
-4,0,1:17.0
2,2,1:17.0
-1,3,1:17.0
0,-2,2:17.0
-4,0,2:17.0
-3,0,2:17.0
-1,2,2:17.0
1,2,2:17.0
2,2,2:17.0
-1,3,2:17.0
0,-2,3:17.0
0,-1,3:17.8
-3,0,3:17.0
-2,0,3:17.4
-1,0,3:17.4
0,0,3:17.8
-1,1,3:17.8
0,1,3:17.8
-1,2,3:17.0
0,2,3:17.4
1,2,3:17.0
-1,0,4:17.0
-1,1,4:17.0
0,1,4:17.0
-1,0,5:17.0
-1,1,5:17.0
0,1,5:17.0
2,-4,6:18
3,-4,6:18
0,-3,6:18
1,-3,6:18
2,-3,6:17.4
3,-3,6:17.4
4,-3,6:18
3,-2,6:18
-1,0,6:17.0
-2,1,6:18
-1,1,6:17.0
0,1,6:17.0
-1,4,6:18
0,4,6:18
-1,5,6:18
2,-4,7:18
3,-4,7:18
-1,-3,7:18
0,-3,7:18
1,-3,7:18
2,-3,7:17.4
3,-3,7:18
4,-3,7:18
-3,-2,7:18
-2,-2,7:18
-1,-2,7:18
0,-2,7:17.4
1,-2,7:17.4
2,-2,7:17.4
3,-2,7:18
-4,-1,7:18
-3,-1,7:18
-2,-1,7:18
-1,-1,7:18
0,-1,7:17.8
1,-1,7:18
2,-1,7:18
3,-1,7:18
4,-1,7:18
-4,0,7:18
-3,0,7:17.4
-2,0,7:17.4
-1,0,7:17.0
0,0,7:17.4
1,0,7:18
2,0,7:18
3,0,7:18
4,0,7:18
-4,1,7:18
-3,1,7:18
-2,1,7:18
-1,1,7:17.8
0,1,7:17.0
1,1,7:18
2,1,7:18
3,1,7:18
4,1,7:18
-4,2,7:18
-3,2,7:18
-2,2,7:18
-1,2,7:17.8
2,2,7:18
3,2,7:18
-3,3,7:18
-2,3,7:18
-1,3,7:17.8
0,3,7:17.4
1,3,7:17.4
2,3,7:18
3,3,7:18
-2,4,7:18
-1,4,7:18
0,4,7:18
1,4,7:17.8
2,4,7:18
-2,5,7:18
-1,5,7:18
0,5,7:18
1,5,7:18
-1,6,7:18
0,6,7:18
2,-3,8:18
3,-3,8:18
-1,-2,8:18
0,-2,8:18
1,-2,8:18
2,-2,8:18
-3,-1,8:18
-2,-1,8:18
-1,-1,8:18
0,-1,8:18
1,-1,8:18
2,-1,8:18
-4,0,8:18
-3,0,8:18
-2,0,8:18
-1,0,8:17.0
0,0,8:18
1,0,8:18
2,0,8:18
3,0,8:18
-3,1,8:18
-2,1,8:18
-1,1,8:18
0,1,8:18
1,1,8:18
2,1,8:18
3,1,8:18
-3,2,8:18
-2,2,8:18
-1,2,8:18
0,2,8:18
1,2,8:18
2,2,8:18
-2,3,8:18
-1,3,8:18
0,3,8:18
1,3,8:18
-2,4,8:18
-1,4,8:18
0,4,8:18
1,4,8:18
-1,5,8:18
0,5,8:18
-2,-1,9:18
-1,-1,9:18
0,-1,9:18
1,-1,9:18
2,-1,9:18
-3,0,9:18
-2,0,9:18
-1,0,9:18
0,0,9:18
1,0,9:18
2,0,9:18
3,0,9:18
-3,1,9:18
-2,1,9:18
-1,1,9:18
0,1,9:18
1,1,9:18
2,1,9:18
-2,2,9:18
-1,2,9:18
0,2,9:18
1,2,9:18
-1,3,9:18
0,3,9:18
1,3,9:18
-1,0,10:18
0,0,10:18
1,0,10:18
0,1,10:18
