[META]
version=2.0
spawnOnBlockType=2
spawnSunlight=True
spawnDarkness=True
spawnWater=True
spawnLava=False
underFill=False
randomRotation=False
dig=True
tree=False
branch=False
needsFoundation=False
rarity=40
collisionPercentage=30
spawnElevationMin=70
spawnElevationMax=79
spawnInBiome=TemperateSwampland
[DATA]
-4,-1,-1:17.4
-3,-1,-1:17.4
-2,-1,-1:17.4
-1,-1,-1:17.4
0,-1,-1:17.4
1,-1,-1:17.4
2,-1,-1:17.4
3,-1,-1:17.4
-2,-3,0:17.8
-2,-2,0:17.8
-1,-2,0:17.4
0,-2,0:17.4
1,-2,0:17.4
2,-2,0:17.4
3,-2,0:17.4
-3,-1,0:106.8
4,-1,0:106.2
-2,0,0:17.8
-1,0,0:17.4
0,0,0:17.4
1,0,0:17.4
2,0,0:17.4
3,0,0:106.4
-2,1,0:17.8
-3,2,0:106.8
-1,2,0:106.4
-2,3,0:106.4
3,-2,1:106.1
-3,-1,1:106.8
-2,-1,1:17.0
-1,-1,1:17.4
0,-1,1:17.4
1,-1,1:17.4
2,-1,1:17.4
3,-1,1:17.4
4,-1,1:106.2
-1,0,1:17.8
3,0,1:106.4
-2,1,1:17.8
-1,1,1:17.8
-3,2,1:106.8
-2,2,1:17.8
-1,2,1:106.4
-2,3,1:106.4
-2,-1,2:17.0
