[META]
version=2.0
spawnOnBlockType=8,9
spawnSunlight=True
spawnDarkness=True
spawnWater=True
spawnLava=False
underFill=False
randomRotation=False
dig=True
tree=False
branch=False
needsFoundation=False
rarity=40
collisionPercentage=20
spawnElevationMin=70
spawnElevationMax=79
spawnInBiome=TemperateSwampland
[DATA]
0,-6,-1:17.8
0,-5,-1:17.8
0,-4,-1:17.8
0,-3,-1:17.8
0,-2,-1:17.8
0,-1,-1:17.8
0,0,-1:17.8
0,1,-1:17.8
0,2,-1:17.8
0,3,-1:17.8
-1,-7,0:17.8
0,-7,0:106.1
1,-7,0:106.1
-1,-6,0:17.8
1,-6,0:17.8
-1,-5,0:17.8
1,-5,0:17.8
-1,-4,0:17.8
1,-4,0:17.8
-1,-3,0:17.8
1,-3,0:17.8
-1,-2,0:17.8
1,-2,0:17.8
-1,-1,0:17.8
1,-1,0:17.8
-1,0,0:17.8
1,0,0:17.8
2,0,0:106.2
-4,1,0:106.1
-2,1,0:106.1
-1,1,0:17.8
1,1,0:17.8
3,1,0:106.2
-1,2,0:17.8
1,2,0:17.8
-4,3,0:106.4
-3,3,0:106.4
-2,3,0:106.4
-1,3,0:17.8
1,3,0:17.8
0,-7,1:106.1
1,-7,1:106.1
-1,-6,1:106.8
0,-6,1:17.8
1,-6,1:106.2
0,-5,1:17.8
1,-5,1:18
0,-4,1:17.8
0,-3,1:17.8
0,-2,1:17.8
1,-2,1:106.1
-1,-1,1:106.8
0,-1,1:17.8
1,-1,1:17.8
-1,0,1:17.8
1,0,1:17.8
2,0,1:106.2
-4,1,1:106.1
-2,1,1:106.1
-1,1,1:17.8
1,1,1:17.4
2,1,1:17.4
3,1,1:106.2
-1,2,1:17.0
1,2,1:17.8
-4,3,1:106.4
-3,3,1:106.4
-2,3,1:106.4
-1,3,1:106.4
0,-7,2:106.1
1,-7,2:106.1
-1,-6,2:106.8
0,-6,2:18
1,-6,2:18
-1,-5,2:18
0,-5,2:17.0
1,-5,2:18
2,-5,2:18
0,-1,2:106.1
0,0,2:17.8
1,0,2:106.2
-4,1,2:106.1
-2,1,2:106.1
-1,1,2:106.8
0,1,2:17.0
-2,2,2:17.0
-1,2,2:17.4
0,2,2:17.8
-4,3,2:106.4
-3,3,2:106.4
-2,3,2:106.4
-1,3,2:106.4
-1,-6,3:18
0,-6,3:18
-2,-5,3:18
-1,-5,3:18
0,-5,3:17.0
1,-5,3:18
0,0,3:106.1
-4,1,3:106.1
-2,1,3:106.1
-1,1,3:106.8
0,1,3:17.0
-4,2,3:17.4
-3,2,3:17.4
-2,2,3:17.4
-4,3,3:106.4
-3,3,3:106.4
-2,3,3:106.4
-1,-5,4:18
0,-5,4:18
0,1,4:17.0
