[META]
version=2.0
spawnOnBlockType=2
spawnSunlight=True
spawnDarkness=True
spawnWater=True
spawnLava=False
underFill=False
randomRotation=False
dig=True
tree=True
branch=False
needsFoundation=False
rarity=100
collisionPercentage=100
spawnElevationMin=70
spawnElevationMax=79
spawnInBiome=TemperateSwampland,TemperateSwamplandBorder,TemperateWoodlandWetland
[DATA]
0,0,-1:17.8
1,0,-1:17.4
2,0,-1:17.4
3,0,-1:17.4
0,1,-1:17.8
0,2,-1:17.8
-5,-1,0:106.1
-4,-1,0:106.1
-3,-1,0:106.1
-2,-1,0:106.1
-1,-1,0:106.1
-6,0,0:106.8
0,0,0:17.0
1,0,0:17.4
2,0,0:18
-3,1,0:106.4
-2,1,0:106.4
-1,1,0:106.4
1,1,0:18
-5,2,0:106.4
-5,-1,1:106.1
-4,-1,1:106.1
-3,-1,1:106.1
-2,-1,1:106.1
-1,-1,1:106.1
0,-1,1:18
1,-1,1:18
-6,0,1:106.8
0,0,1:17.0
1,0,1:18
-3,1,1:106.4
-2,1,1:106.4
-1,1,1:106.4
-5,2,1:106.4
-5,-1,2:106.1
-4,-1,2:106.1
-3,-1,2:106.1
-2,-1,2:106.1
-1,-1,2:106.1
-6,0,2:106.8
-5,0,2:18
-4,0,2:17.4
-3,0,2:17.4
-2,0,2:17.4
-1,0,2:17.4
0,0,2:17.0
-5,1,2:18
-4,1,2:18
-3,1,2:106.4
-2,1,2:106.4
-1,1,2:106.4
-5,2,2:106.4
-4,-1,3:18
0,-1,3:18
1,-1,3:18
-6,0,3:106.8
-5,0,3:18
-4,0,3:17.0
-1,0,3:18
0,0,3:17.0
1,0,3:18
-1,1,3:106.4
0,1,3:18
-5,-1,4:18
-4,-1,4:18
-3,-1,4:18
-6,0,4:18
-5,0,4:17.4
-4,0,4:17.4
-3,0,4:18
0,0,4:18
-5,1,4:18
-4,1,4:18
-3,1,4:18
-5,0,5:18
-4,0,5:18
