[META]
version=2.0
spawnOnBlockType=87
spawnSunlight=True
spawnDarkness=True
spawnWater=False
spawnLava=False
spawnUnderGround=True
spawnAboveGround=False
underFill=False
randomRotation=True
dig=False
tree=False
branch=False
needsFoundation=True
rarity=60
collisionPercentage=20
spawnElevationMin=84
spawnElevationMax=86
[DATA]
1,-3,0:89.0
-2,-2,0:89.0
-1,-2,0:89.0
0,-2,0:89.0
1,-2,0:89.0
2,-2,0:89.0
-2,-1,0:89.0
-1,-1,0:89.0
0,-1,0:89.0
1,-1,0:89.0
2,-1,0:89.0
-3,0,0:89.0
-2,0,0:89.0
-1,0,0:89.0
0,0,0:89.0
1,0,0:89.0
2,0,0:89.0
-2,1,0:89.0
-1,1,0:89.0
0,1,0:89.0
1,1,0:89.0
2,1,0:89.0
-1,2,0:89.0
0,2,0:89.0
1,2,0:89.0
-1,-1,1:89.0
0,-1,1:89.0
1,-1,1:89.0
-1,0,1:89.0
0,0,1:89.0
1,0,1:89.0
0,1,1:89.0
1,1,1:89.0
-1,0,2:89.0
0,0,2:89.0
0,1,2:89.0
0,0,3:89.0
0,1,3:89.0
0,0,4:89.0
0,0,5:89.0
0,0,6:89.0
0,0,7:89.0
0,0,8:89.0
0,0,9:89.0
0,0,10:89.0
0,0,11:89.0
0,0,12:89.0
0,0,13:89.0
0,0,14:89.0
0,0,15:89.0
0,1,15:89.0
0,0,16:89.0
1,0,16:89.0
0,1,16:89.0
0,-1,17:89.0
-1,0,17:89.0
0,0,17:89.0
1,0,17:89.0
0,1,17:89.0
-1,-1,18:89.0
0,-1,18:89.0
1,-1,18:89.0
-1,0,18:89.0
0,0,18:89.0
1,0,18:89.0
-1,1,18:89.0
0,1,18:89.0
1,1,18:89.0
0,2,18:89.0
1,2,18:89.0
-1,-2,19:89.0
0,-2,19:89.0
1,-2,19:89.0
-2,-1,19:89.0
-1,-1,19:89.0
0,-1,19:89.0
1,-1,19:89.0
2,-1,19:89.0
-2,0,19:89.0
-1,0,19:89.0
0,0,19:89.0
1,0,19:89.0
2,0,19:89.0
-2,1,19:89.0
-1,1,19:89.0
0,1,19:89.0
1,1,19:89.0
2,1,19:89.0
3,1,19:89.0
-1,2,19:89.0
0,2,19:89.0
1,2,19:89.0
2,2,19:89.0
0,3,19:89.0
1,3,19:89.0
