[META]
version=2.0
spawnOnBlockType=87
spawnSunlight=True
spawnDarkness=True
spawnWater=False
spawnLava=False
spawnUnderGround=True
spawnAboveGround=False
underFill=False
randomRotation=True
dig=False
tree=False
branch=False
needsFoundation=True
rarity=20
collisionPercentage=20
spawnElevationMin=84
spawnElevationMax=86
[DATA]
0,-1,17:89
-1,0,17:89
0,0,17:89
1,0,17:89
0,1,17:89
1,1,17:89
2,0,17:89
-1,-1,18:89
0,-1,18:89
1,-1,18:89
-1,0,18:89
0,0,18:89
1,0,18:89
-1,1,18:89
0,1,18:89
1,1,18:89
0,2,18:89
1,2,18:89
2,0,18:89
2,1,18:89
-1,-2,19:89
0,-2,19:89
1,-2,19:89
-2,-1,19:89
-1,-1,19:89
0,-1,19:89
1,-1,19:89
2,-1,19:89
-2,0,19:89
-1,0,19:89
0,0,19:89
1,0,19:89
2,0,19:89
-2,1,19:89
-1,1,19:89
0,1,19:89
1,1,19:89
2,1,19:89
3,1,19:89
-1,2,19:89
0,2,19:89
1,2,19:89
2,2,19:89
0,3,19:89
1,3,19:89
0,0,13:89
0,0,14:89
0,0,15:89
0,0,16:89
1,0,16:89
