[META]
version=2.0
spawnOnBlockType=49
spawnSunlight=True
spawnDarkness=True
spawnWater=False
spawnLava=False
underFill=False
randomRotation=True
dig=True
tree=True
branch=False
needsFoundation=True
rarity=100
collisionPercentage=20
spawnElevationMin=0
spawnElevationMax=200
[DATA]
0,0,0:49.0
0,0,1:49.0
-1,-2,2:89.0
0,-2,2:89.0
1,-2,2:89.0
2,-2,2:89.0
-2,-1,2:89.0
-1,-1,2:89.0
0,-1,2:89.0
1,-1,2:89.0
2,-1,2:89.0
-2,0,2:89.0
-1,0,2:89.0
0,0,2:49.0
1,0,2:89.0
2,0,2:89.0
-2,1,2:89.0
-1,1,2:89.0
0,1,2:89.0
1,1,2:89.0
2,1,2:89.0
-1,2,2:89.0
0,2,2:89.0
1,2,2:89.0
2,2,2:89.0
-1,-2,3:89.0
0,-2,3:89.0
1,-2,3:89.0
-2,-1,3:89.0
-1,-1,3:89.0
0,-1,3:89.0
1,-1,3:89.0
2,-1,3:89.0
-2,0,3:89.0
-1,0,3:89.0
0,0,3:49.0
1,0,3:89.0
2,0,3:89.0
-2,1,3:89.0
-1,1,3:89.0
0,1,3:89.0
1,1,3:89.0
2,1,3:89.0
-2,2,3:89.0
-1,2,3:89.0
0,2,3:89.0
1,2,3:89.0
0,-1,4:89.0
-1,0,4:89.0
0,0,4:49.0
1,0,4:89.0
0,1,4:89.0
1,1,4:89.0
0,-1,5:89.0
-1,0,5:89.0
0,0,5:89.0
1,0,5:89.0
0,1,5:89.0
