[META]
version=2.0
spawnOnBlockType=49,87,88
spawnSunlight=True
spawnDarkness=True
spawnWater=False
spawnLava=False
underFill=False
randomRotation=True
dig=True
tree=False
branch=False
needsFoundation=True
rarity=25
collisionPercentage=20
spawnElevationMin=0
spawnElevationMax=200
[DATA]
-2,-2,-1:112.0
-1,-2,-1:112.0
0,-2,-1:112.0
1,-2,-1:112.0
2,-2,-1:112.0
-2,-1,-1:112.0
-1,-1,-1:87.0
0,-1,-1:112.0
1,-1,-1:112.0
2,-1,-1:112.0
-2,0,-1:112.0
-1,0,-1:88.0
0,0,-1:88.0
1,0,-1:88.0
2,0,-1:112.0
-2,1,-1:112.0
-1,1,-1:112.0
0,1,-1:112.0
1,1,-1:112.0
2,1,-1:112.0
-2,-2,0:112.0
-1,-2,0:112.0
0,-2,0:112.0
1,-2,0:112.0
2,-2,0:112.0
-2,-1,0:112.0
-2,0,0:112.0
2,0,0:112.0
-2,1,0:112.0
-1,1,0:112.0
0,1,0:112.0
1,1,0:112.0
2,1,0:112.0
-2,-3,1:114.2
-1,-3,1:114.2
0,-3,1:114.2
1,-3,1:114.2
2,-3,1:114.2
-2,-2,1:112.0
-1,-2,1:112.0
0,-2,1:112.0
1,-2,1:112.0
2,-2,1:112.0
-2,-1,1:112.0
-2,0,1:112.0
2,0,1:112.0
-2,1,1:112.0
-1,1,1:112.0
0,1,1:112.0
1,1,1:112.0
2,1,1:112.0
-2,2,1:114.3
-1,2,1:114.3
0,2,1:114.3
1,2,1:114.3
2,2,1:114.3
-2,-2,2:114.2
-1,-2,2:114.2
0,-2,2:114.2
1,-2,2:114.2
2,-2,2:114.2
-2,-1,2:112.0
2,-1,2:114.5
-2,0,2:112.0
2,0,2:112.0
-2,1,2:114.3
-1,1,2:114.3
0,1,2:114.3
1,1,2:114.3
2,1,2:114.3
-2,-1,3:114.2
-1,-1,3:114.2
0,-1,3:114.2
1,-1,3:114.2
2,-1,3:114.2
-2,0,3:114.3
-1,0,3:114.3
0,0,3:114.3
1,0,3:114.3
2,0,3:114.3
3,0,2:106.2
1,0,2:106.8
-3,-1,2:106.8
-3,1,1:106.8
3,0,1:106.2
1,0,1:106.8
-3,-1,1:106.8
-3,1,0:106.8
1,0,0:115.2
0,0,0:115.0
-1,0,0:115.0
-1,-1,0:51.15
-3,-1,0:106.8
